Workbook

Sheet Blue Labels
A1: (SHT 1) CONSOLE | B1: (SHT 10) REMOTE IO BOX #3 | C1: (SHT 11) REMOTE IO BOX #4 | D1: (SHT 2) CONSOLE | E1: (SHT 3) SCS | F1: (SHT 4) LEFT SIDE PNL | G1: (SHT 5) BACK PANEL | H1: (SHT 6) RIGHT SIDE PNL | I1: (SHT 8) REMOTE IO BOX #1 | J1: (SHT 9) REMOTE IO BOX #2
A2: EL0273 | B2: UJ0134 | C2: UJ0135 | D2: AT0191 | E2: HL1753 | F2: FU0680 | G2: AR0600 | H2: AT0180 | I2: UJ0132 | J2: UJ0133
A3: HA0273 | B3: BA1031 | C3: BA1042 | D3: AT0190K | E3: HL1733 | F3: XT0680 | G3: AP0606 | H3: GR0204 | I3: BA1011 | J3: BA1021
A4: ZS0273 | B4: BA1032 | C4: BA1041 | D4: AT0190 | E4: HL1593 | F4: AT0680 | G4: AP0605 | H4: KA1246 | I4: BA1012 | J4: BA1022
A5: FG0130 | B5: FU0090 | C5: FU0100 | E5: HL1143 | F5: BA0003 | G5: AP0604 | H5: FU1202 | I5: FU0060 | J5: FU0108
B6: FU0091 | C6: FU0101 | E6: HL1773 | F6: BA0004 | G6: AP0602 | H6: FU1203 | I6: FU0061 | J6: FU0109
B7: FU0092 | C7: FU0102 | E7: HL1751 | F7: BA0011 | G7: AP0601 | H7: FU1204 | I7: FU0062 | J7: FU0110
B8: FU0094 | C8: FU0103 | E8: HL1731 | F8: BA0012 | G8: AT0600 | H8: XT1200 | I8: FU0063 | J8: FU0112
B9: FU0095 | C9: FU0104 | E9: HL1591 | F9: BA0013 | G9: UV0600 | H9: XT1201 | I9: FU0064 | J9: FU0113
B10: FU0191 | C10: FU0106 | E10: HL1141 | F10: BA0014 | G10: FU0050 | H10: XT1202 | I10: FU0160 | J10: FU0180
B11: XT0095 | C11: FU0105 | E11: HL1771 | F11: BA0015 | G11: AU0050 | H11: XT1203 | I11: XT0060 | J11: XT0080
B12: XT0090 | C12: XT0101 | E12: AU0020 | F12: BA0017 | G12: AF0051 | H12: XT1204 | I12: XT0061 | J12: XT0081
B13: XT0096 | C13: KA0106 | E13: AF0021 | F13: BA0111 | G13: AF0052 | H13: KA1201 | I13: XT0086 | J13: XT0082
B14: GR300 | C14: KA0107 | E14: AF0022 | F14: BA0112 | G14: AF0053 | H14: KA1211 | I14: GR100 | J14: GR200
B15: QS0134 | C15: KA0108 | E15: AF0023 | F15: BA0113 | G15: AF0054 | H15: KA1212 | I15: QS0132 | J15: QS0133
B16: XT0014 | C16: KA0110 | E16: GR0120 | F16: BA0114 | G16: GR0110 | H16: KA1219 | I16: XT0012 | J16: XT0013
B17: GR301 | C17: KA0111 | E17: SB1283 | F17: FU1215 | G17: AP0603 | H17: KA1220 | I17: GR101 | J17: GR201
... B31: KA0099 | C31: AU0100 | E31: HL1144 | F31: FU0273 | G31: FU0010 | H31: XT1266 | I31: KA0085 | J31: GR203
B32: KA0100 | C32: AF0101 | E32: HL1774 | F32: XT0273 | G32: FU0138 | I32: KA0086
B33: KA0101 | C33: AF0102 | E33: HL1752 | F33: XT0002 | G33: XT0138 | I33: KA0087
B34: KA0102 | C34: AF0103 | E34: HL1732 | F34: GR0133 | G34: XT0139 | I34: KA0088
B35: KA0103 | C35: AF0104 | E35: HL1592 | F35: BA2115 | G35: XT0134 | I35: KA0089
B36: KA0104 | C36: AF0105 | E36: HL1142 | F36: BA1216 | G36: XT0135 | I36: KA0090
B37: KA0105 | C37: KA1241 | E37: HL1772 | F37: IEG0130 | G37: FU0137 | I37: KA0091
B38: GR302 | C38: KA1242 | E38: SB1284 | G38: FU0136 | I38: KA0092
B39: AU0090 | C39: KA1252 | E39: SB1294 | G39: FU1201 | I39: KA0093
B40: AF0091 | C40: KA1253 | E40: SB1114 | G40: KA0001 | I40: GR102
B41: AF0092 | C41: KA1256 | E41: SB1264 | G41: KA0002 | I41: AU0060
B42: AF0093 | C42: KA1257 | E42: SB1274 | G42: KA0003 | I42: AF0061
B43: AF0094 | C43: XT0100 | E43: SB0401 | G43: KA0081 | I43: AF0062
B44: AF0095 | C44: XT1270 | E44: SB1282 | G44: KA0082 | I44: AF0063
B45: GR303 | C45: XT1273 | E45: SB1292 | G45: KA0083 | I45: AF0064
C46: XT1261 | E46: SB1112 | G46: KA7400 | I46: AF0065
C47: XT1291 | E47: SB1262 | G47: GR0131 | I47: GR103
C48: GR402 | E48: SB1272 | G48: QS0011
C49: AT0200 | E49: SB0402 | G49: XT0011
C50: KA1215 | E50: SH0418 | G50: GR0132
C51: KA1216 | E51: SA0500 | G51: UJ0131
C52: KA1227 | E52: FU0190 | G52: PEG0130
C53: KA1228 | E53: FU0023
...

Sheet White Labels
A1: (SHT 5) BACK PANEL | B1: (SHT 5) BACK PANEL - (SHT 4) LEFT SIDE PNL | C1: (SHT 4) LEFT SIDE PNL | D1: (SHT 4) LEFT SIDE PNL - (SHT 6) RIGHT SIDE PNL | E1: (SHT 4) LEFT SIDE PNL - (SHT 3) SCS | F1: (SHT 8) REMOTE IO BOX #1 | G1: (SHT 9) REMOTE IO BOX #2 | H1: (SHT 10) REMOTE IO BOX #3 | I1: (SHT 11) REMOTE IO BOX #4 | J1: (SHT 6) RIGHT SIDE PNL
A2: 0V | B2: GR0110 | C2: GR0133 | D2: GR0201 | E2: GR0120 | F2: 0VB1 | G2: 0VB2 | H2: 0VB3 | I2: 0VB4 | J2: AT0180FG
A3: UV0600G | B3: GR0111 | C3: GR0134 | D3: IEG013010 | E3: GR0121 | F3: AF0061G | G3: AF0081G | H3: AF0091G | I3: AF0101G
B4: GR0131 | F4: AF0062G | G4: GR200 | H4: AF0092G | I4: AF0102G
B5: IEG01301 | F5: GR100 | G5: GR201 | H5: GR300 | I5: AT0200FG
F6: GR101 | G6: GR202 | H6: GR301 | I6: GR400
F7: GR102 | G7: GR203 | H7: GR302 | I7: GR401
F8: GR103 | G8: IEGRB21 | H8: GR303 | I8: GR402
F9: IEGRB11 | H9: IEGRB31 | I9: GR403
I10: GR404
I11: IEGRB41

Sheet Heat Shrink Labels

Sheet Panel Errors
A1: Panel Errors
A3: Project # | B3: 4M368
A4: Project Name | B4: Los Toldos II Este
A5: Revision | B5: B
A7: Controls DE | B7: Keith Nyberg
A8: Phone:
A9: Controls ME | B9: Dennis Figueroa
A10: Phone:
A12: From | H12: To
A13: Device ID | B13: Location | C13: Cable (W) Conductor (SC) Jumper Clip (JC) | D13: Wire ID | E13: Wire No. | F13: Gauge/Size | G13: Page/Zone | H13: Device ID | I13: Location | J13: Page/Zone
A14: CCPT1A:A | B14: PANEL | C14: SC | E14: * | G14: 79.A1 | H14: CCPT1B:A | I14: PANEL | J14: 79.B1
A15: CCPT1A:B | B15: PANEL | C15: SC | E15: * | G15: 79.A1 | H15: CCPT1B:B | I15: PANEL | J15: 79.B1
A16: CCPT1A:C | B16: PANEL | C16: SC | E16: * | G16: 79.A1 | H16: CCPT1B:C | I16: PANEL | J16: 79.B1
A17: CCPT2A:A | B17: PANEL | C17: SC | E17: * | G17: 80.A1 | H17: CCPT2B:A | I17: PANEL | J17: 80.B1
A18: CCPT2A:B | B18: PANEL | C18: SC | E18: * | G18: 80.A1 | H18: CCPT2B:B | I18: PANEL | J18: 80.B1
A19: CCPT2A:C | B19: PANEL | C19: SC | E19: * | G19: 80.A1 | H19: CCPT2B:C | I19: PANEL | J19: 80.B1
A20: CCPT3A:A | B20: PANEL | C20: SC | E20: * | G20: 81.A1 | H20: CCPT3B:A | I20: PANEL | J20: 81.B1
A21: CCPT3A:B | B21: PANEL | C21: SC | E21: * | G21: 81.A1 | H21: CCPT3B:B | I21: PANEL | J21: 81.B1
A22: CCPT3A:C | B22: PANEL | C22: SC | E22: * | G22: 81.A1 | H22: CCPT3B:C | I22: PANEL | J22: 81.B1
A23: CCPT4A:A | B23: PANEL | C23: SC | E23: * | G23: 82.A1 | H23: CCPT4B:A | I23: PANEL | J23: 82.B1
A24: CCPT4A:B | B24: PANEL | C24: SC | E24: * | G24: 82.A1 | H24: CCPT4B:B | I24: PANEL | J24: 82.B1
A25: CCPT4A:C | B25: PANEL | C25: SC | E25: * | G25: 82.A1 | H25: CCPT4B:C | I25: PANEL | J25: 82.B1
A26: AP0601:L1 | B26: UNIT 1 | C26: WC0601U1 | D26: ENET | E26: * | F26: CABLE | G26: 3.A7 | H26: BA0001:RJ45 | I26: UNIT 1 | J26: 3.A6
A27: AP0601:L1 | B27: UNIT 2 | C27: WC0601U2 | D27: ENET | E27: * | F27: CABLE | G27: 3.A7 | H27: BA0001:RJ45 | I27: UNIT 2 | J27: 3.B6
A28: AP0601:L1 | B28: UNIT 3 | C28: WC0601U3 | D28: ENET | E28: * | F28: CABLE | G28: 3.B7 | H28: BA0001:RJ45 | I28: UNIT 3 | J28: 3.B6
A29: AP0601:L1 | B29: UNIT 4 | C29: WC0601U4 | D29: ENET | E29: * | F29: CABLE | G29: 3.C7 | H29: BA0001:RJ45 | I29: UNIT 4 | J29: 3.C6
E31: SolarTools ver. 24.0.84.24712 (Jul 31, 2025)
A32: Report date: 4/1/2026 10:43 AM

Sheet Cable Part Numbers
A1: Cable Part Numbers | D1: SolarTools ver. 24.0.84.24712 (Jul 31, 2025)
A2: Project # | B2: 4M368
D3: Report date: 4/1/2026 10:44 AM
A4: Project Name | B4: Los Toldos II Este
A6: Revision | B6: B
A8: Controls DE | B8: Keith Nyberg
A9: Phone:
A10: Controls ME | B10: Dennis Figueroa
A11: Phone:
A13: Device ID | C13: Part Number | E13: Description
A14: WC0001 | C14: 1302073-36 | E14: CABLE, COMMUNICATION CABLE - 36 INCHES
A15: WC0002 | C15: 1302073-36 | E15: CABLE, COMMUNICATION CABLE - 36 INCHES
A16: WC0003 | C16: 1302073-36 | E16: CABLE, ETHERNET - 36 INCHES
A17: WC0004 | C17: 1302073-36 | E17: CABLE, COMMUNICATION CABLE - 36 INCHES
A18: WC0006 | C18: 1302073-36 | E18: CABLE, ETHERNET - 36 INCHES
A19: WC0007 | C19: 1302073-36 | E19: CABLE, ETHERNET - 36 INCHES
A20: WC0011 | C20: 1302073-36 | E20: CABLE, COMMUNICATION CABLE - 36 INCHES
A21: WC0012 | C21: 1302073-36 | E21: CABLE, ETHERNET - 36 INCHES
A22: WC0013 | C22: 1302073-36 | E22: CABLE, ETHERNET - 36 INCHES
A23: WC0018 | C23: 1302073-36 | E23: CABLE, COMMUNICATION CABLE - 36 INCHES
A24: WC0031 | C24: 1302073-36 | E24: CABLE, ETHERNET - 36 INCHES
... A52: WC0601U4 | C52: 1302073-36 | E52: CABLE, ETHERNET - 36 INCHES

Sheet Part Number List
A1: Part Number List | C1: SolarTools ver. 24.0.84.24712 (Jul 31, 2025)
A2: Project # | B2: 4M368
C3: Report date: 4/1/2026 10:44 AM
A4: Project Name | B4: Los Toldos II Este
A6: Revision | B6: B
A8: Controls DE | B8: Keith Nyberg
A9: Phone:
A10: Controls ME | B10: Dennis Figueroa
A11: Phone:
A13: Device ID | B13: Part Number | C13: Description | D13: Location
A14: AF0041 | B14: 2684693-17,2684693-23 | C14: 5094-IB16XT, 16 DISCRETE INPUT | D14: BACK PANEL
A15: AF0042 | B15: 2684693-17,2684693-23 | C15: 5094-IB16XT, 16 DISCRETE INPUT | D15: BACK PANEL
A16: AF0043 | B16: 2684693-33 | C16: 5094-IY8XT, 8 ANALOG INPUT,TC/RTD/I&V | D16: BACK PANEL
A17: AF0044 | B17: 2684693-19,2684693-33 | C17: 5094-IY8XT, 8 ANALOG INPUT,TC/RTD/I&V | D17: BACK PANEL
A18: AF0045 | B18: 2684693-17,2684693-24 | C18: 5094-OB16XT, 16 DISCRETE OUTPUT | D18: BACK PANEL
A19: AP0601 | B19: 1089241-40 | C19: 1756-EN2TRXT, ETHERNET | D19: BACK PANEL
A20: AP0602 | B20: 1089241-40 | C20: 1756-EN2TRXT, ETHERNET | D20: BACK PANEL
A21: AP0603 | B21: 1089241-20,1089241-40 | C21: 1756-EN2TRXT, ETHERNET | D21: BACK PANEL
A22: AP0604 | B22: 1089241-15 | C22: MVI 56-MNETXT, ETHERNET/MODBUS | D22: BACK PANEL
A23: AP0605 | B23: 1089241-15 | C23: MVI 56-MNETXT, ETHERNET/MODBUS | D23: BACK PANEL
A24: AP0606 | B24: 1089241-20 | C24: MODULE, BLANK FILLER | D24: BACK PANEL
... A400: SH0418 | B400: 964902C1 | C400: LIGHTED SWITCH, LAMP TEST | D400: SCS
A401: WC0020 | B401: 2684693-54 | D401: SCS
A402: XT0260 | B402: 1066730-7,1067996-4 | C402: TERMINAL BLOCK, SPRING, 4 CONDUCTOR,30-12 AWG (0.05-3.31 MM2),NON-IS | D402: SCS
A403: XT0261 | B403: 1066730-7,1066730-8,1067996-4 | C403: TERMINAL BLOCK, SPRING, 4 CONDUCTOR,30-12 AWG (0.05-3.31 MM2),NON-IS | D403: SCS
A404: XT0262 | B404: 1066730-7,1066730-8,1067996-4 | C404: TERMINAL BLOCK, SPRING, 4 CONDUCTOR,30-12 AWG (0.05-3.31 MM2),NON-IS | D404: SCS
A406: AP0601 | B406: 1089241-40 | C406: 1756-EN2TRXT, ETHERNET | D406: UNIT 1
A407: BA0001 | B407: 1271449-4 | C407: MEDIA CONVERTER, ETHERNET-FIBER OPTIC | D407: UNIT 1
A409: AP0601 | B409: 1089241-40 | C409: 1756-EN2TRXT, ETHERNET | D409: UNIT 2
A410: BA0001 | B410: 1271449-4 | C410: MEDIA CONVERTER, ETHERNET-FIBER OPTIC | D410: UNIT 2
A412: AP0601 | B412: 1089241-40 | C412: 1756-EN2TRXT, ETHERNET | D412: UNIT 3
A413: BA0001 | B413: 1271449-4 | C413: MEDIA CONVERTER, ETHERNET-FIBER OPTIC | D413: UNIT 3
A415: AP0601 | B415: 1089241-40 | C415: 1756-EN2TRXT, ETHERNET | D415: UNIT 4
A416: BA0001 | B416: 1271449-4 | C416: MEDIA CONVERTER, ETHERNET-FIBER OPTIC | D416: UNIT 4

Sheet CONSOLE_S
A1: CONSOLE
A2: ASSEMBLY CONSOLE & CONSOLE DOORS ONE BAY
A3: Project # | B3: 4M368
A4: Project Name | B4: Los Toldos II Este
A5: Revision | B5: B
A7: Controls DE | B7: Keith Nyberg
A8: Phone:
A9: Controls ME | B9: Dennis Figueroa
A10: Phone:
A12: From | G12: To
A13: Device ID | B13: Wire No. | C13: Wire ID | D13: Gauge/Size | E13: Length | F13: Device ID | G13: Location | H13: Bundle Name
A14: EL0273:W1 | B14: -0V1 | C14: WHT | D14: 14 | E14: 100 | F14: XT0273:1 | G14: LEFT SIDE PNL | H14: EL/ZS-L/S
A15: ZS0273:1 | B15: FU0273 | C15: WHT | D15: 14 | E15: 100 | F15: FU0273:LD | G15: LEFT SIDE PNL

Sheet SCS_S
A1: SCS
A2: ASSEMBLY,SCS PANEL
A3: Project # | B3: 4M368
A4: Project Name | B4: Los Toldos II Este
A5: Revision | B5: B
A7: Controls DE | B7: Keith Nyberg
A8: Phone:
A9: Controls ME | B9: Dennis Figueroa
A10: Phone:
A12: From | G12: To
A13: Device ID | B13: Wire No. | C13: Wire ID | D13: Gauge/Size | E13: Length | F13: Device ID | G13: Location | H13: Bundle Name
A14: HL1141:A | B14: HL1141A | C14: WHT | D14: 20 | F14: AF0023:17 | G14: SCS
A15: HL1141:A+ | B15: HL1141AP | C15: WHT | D15: 20 | F15: AF0023:01 | G15: SCS
A17: HL1142:A | B17: HL1142A | C17: WHT | D17: 20 | F17: AF0023:23 | G17: SCS
A18: HL1142:A+ | B18: HL1142AP | C18: WHT | D18: 20 | F18: AF0023:07 | G18: SCS
A20: HL1143:A | B20: HL1143A | C20: WHT | D20: 20 | F20: AF0023:29 | G20: SCS
A21: HL1143:A+ | B21: HL1143AP | C21: WHT | D21: 20 | F21: AF0023:13 | G21: SCS
A23: HL1144:A | B23: HL1144A | C23: WHT | D23: 20 | F23: AF0024:19 | G23: SCS
A24: HL1144:A+ | B24: HL1144AP | C24: WHT | D24: 20 | F24: AF0024:03 | G24: SCS
A26: HL1591:A | B26: HL1591A | C26: WHT | D26: 20 | F26: AF0023:18 | G26: SCS
A27: HL1591:A+ | B27: HL1591AP | C27: WHT | D27: 20 | F27: AF0023:02 | G27: SCS
A29: HL1592:A | B29: HL1592A | C29: WHT | D29: 20 | F29: AF0023:24 | G29: SCS
A30: HL1592:A+ | B30: HL1592AP | C30: WHT | D30: 20 | F30: AF0023:08 | G30: SCS
... A177: FU0190:LD | B177: FU0190 | C177: WHT | D177: 14 | F177: AT0191:POS | G177: CONSOLE

Sheet LEFT SIDE PANEL_S
A1: LEFT SIDE PNL
A2: ASSY,LEFT SIDE PNL,CONSOLE
A3: Project # | B3: 4M368
A4: Project Name | B4: Los Toldos II Este
A5: Revision | B5: B
A7: Controls DE | B7: Keith Nyberg
A8: Phone:
A9: Controls ME | B9: Dennis Figueroa
A10: Phone:
A12: From | G12: To
A13: Device ID | B13: Wire No. | C13: Wire ID | D13: Gauge/Size | E13: Length | F13: Device ID | G13: Location | H13: Bundle Name
A14: AT0680:NEG | B14: -0V | C14: WHT | D14: 14 | E14: 60 | F14: XT0680:2 | G14: LEFT SIDE PNL | H14: AT0680
A15: AT0680:POS | B15: AT0680POS | C15: WHT | D15: 14 | E15: 60 | F15: XT0680:1 | G15: LEFT SIDE PNL
A17: BA0003:V1(-) | B17: -0V | C17: WHT | D17: 16 | E17: 100 | F17: XT0002:11 | G17: LEFT SIDE PNL
A18: BA0004:V1(-) | B18: -0V | C18: WHT | D18: 16 | E18: 100 | F18: XT0002:11 | G18: LEFT SIDE PNL
A19: BA0011:V1(-) | B19: -0V | C19: WHT | D19: 16 | E19: 100 | F19: XT0002:7 | G19: LEFT SIDE PNL
A20: BA0012:V1(-) | B20: -0V | C20: WHT | D20: 16 | E20: 100 | F20: XT0002:8 | G20: LEFT SIDE PNL
A21: BA0013:V1(-) | B21: -0V | C21: WHT | D21: 16 | E21: 100 | F21: XT0002:11 | G21: LEFT SIDE PNL
A22: BA0014:V1(-) | B22: -0V | C22: WHT | D22: 16 | E22: 100 | F22: XT0002:12 | G22: LEFT SIDE PNL
A23: BA0015:V1(-) | B23: -0V | C23: WHT | D23: 16 | E23: 100 | F23: XT0002:15 | G23: LEFT SIDE PNL
A24: BA0017:V1(-) | B24: -0V | C24: WHT | D24: 16 | E24: 100 | F24: XT0002:16 | G24: LEFT SIDE PNL
A25: BA0111:V1(-) | B25: -0V | C25: WHT | D25: 16 | E25: 100 | F25: XT0002:3 | G25: LEFT SIDE PNL
A26: BA0113:V1(-) | B26: -0V | C26: WHT | D26: 16 | E26: 100 | F26: XT0002:19 | G26: LEFT SIDE PNL
A27: BA0114:V1(-) | B27: -0V | C27: WHT | D27: 16 | E27: 100 | F27: XT0002:20 | G27: LEFT SIDE PNL
... A43: BA1216:24V | B43: FU1215 | C43: WHT | D43: 14 | E43: 100 | F43: FU1215:LD | G43: LEFT SIDE PNL
A45: XT0002:19 | B45: -0V | C45: WHT | D45: 16 | E45: 60 | F45: XT0002:15 | G45: LEFT SIDE PNL | H45: FU/XT-LEFT
A46: XT0002:4 | B46: -0V | C46: WHT | D46: 16 | E46: 60 | F46: XT0002:19 | G46: LEFT SIDE PNL
A47: FU0001:LI | B47: FU0137 | C47: WHT | D47: 16 | E47: 60 | F47: XT0002:2 | G47: LEFT SIDE PNL
A48: FU0002:LI | B48: FU0137 | C48: WHT | D48: 16 | E48: 60 | F48: XT0002:1 | G48: LEFT SIDE PNL
A49: FU0003:LI | B49: FU0137 | C49: WHT | D49: 16 | E49: 60 | F49: XT0002:5 | G49: LEFT SIDE PNL
A50: FU0004:LI | B50: FU0137 | C50: WHT | D50: 16 | E50: 60 | F50: XT0002:6 | G50: LEFT SIDE PNL
A51: FU0005:LI | B51: FU0137 | C51: WHT | D51: 16 | E51: 60 | F51: XT0002:9 | G51: LEFT SIDE PNL
A52: FU0006:LI | B52: FU0137 | C52: WHT | D52: 16 | E52: 60 | F52: XT0002:10 | G52: LEFT SIDE PNL
A53: FU0007:LI | B53: FU0137 | C53: WHT | D53: 16 | E53: 60 | F53: XT0002:13 | G53: LEFT SIDE PNL
A54: FU0008:LI | B54: FU0137 | C54: WHT | D54: 16 | E54: 60 | F54: XT0002:14 | G54: LEFT SIDE PNL
A55: FU0012:LI | B55: FU0137 | C55: WHT | D55: 16 | E55: 60 | F55: XT0002:17 | G55: LEFT SIDE PNL
A56: FU0013:LI | B56: FU0137 | C56: WHT | D56: 16 | E56: 06 | F56: XT0002:18 | G56: LEFT SIDE PNL
A57: FU0015:LI | B57: FU0137 | C57: WHT | D57: 16 | E57: 06 | F57: FU0016:LI | G57: LEFT SIDE PNL
... A62: XT0002:17 | B62: FU0137 | C62: WHT | D62: 16 | E62: 60 | F62: XT0002:2 | G62: LEFT SIDE PNL
A64: BA2115:+ | B64: FU0137 | C64: WHT | D64: 20 | E64: 160 | F64: XT0139:2 | G64: BACK PANEL | H64: BA-BACK
...

Sheet BACK PANEL_S
A1: BACK PANEL
A2: ASSY,BACK PANEL,CONSOLE
A3: Project # | B3: 4M368
A4: Project Name | B4: Los Toldos II Este
A5: Revision | B5: B
A7: Controls DE | B7: Keith Nyberg
A8: Phone:
A9: Controls ME | B9: Dennis Figueroa
A10: Phone:
A12: From | G12: To
A13: Device ID | B13: Wire No. | C13: Wire ID | D13: Gauge/Size | E13: Length | F13: Device ID | G13: Location | H13: Bundle Name
A14: UV0600:(-) | B14: -0V | C14: WHT | D14: 14 | E14: 60 | F14: XT0135:1 | G14: BACK PANEL | H14: UV0600
A15: UV0600:(+) | B15: FU0010 | C15: WHT | D15: 14 | E15: 60 | F15: FU0010:LD | G15: BACK PANEL
A17: UJ0131:VIN | B17: UJ0131VIN | C17: WHT | D17: 20 | E17: 120 | F17: AF0043:07 | G17: BACK PANEL | H17: UJ0131
A18: UJ0131:IOUT | B18: UJ0131IOUT | C18: WHT | D18: 20 | E18: 120 | F18: AF0043:09 | G18: BACK PANEL
A19: UJ0131:OK2 | B19: UJ0131OK2 | C19: WHT | D19: 20 | E19: 120 | F19: AF0042:10 | G19: BACK PANEL
A20: UJ0131:OK1 | B20: UJ0131OK1 | C20: WHT | D20: 20 | E20: 120 | F20: AF0042:42 | G20: BACK PANEL
A22: QS0011:LD-1 | B22: UJ0131P | C22: WHT | D22: 12 | E22: 60 | F22: UJ0131:+ | G22: BACK PANEL | H22: QS0011
A23: QS0011:LD-3 | B23: UJ0131N | C23: WHT | D23: 12 | E23: 60 | F23: UJ0131:- | G23: BACK PANEL
A24: QS0011:LI-2 | B24: -525POS | C24: WHT | D24: 12 | E24: 60 | F24: XT0011:1 | G24: BACK PANEL
A25: QS0011:LI-4 | B25: -525NEG | C25: WHT | D25: 12 | E25: 60 | F25: XT0011:2 | G25: BACK PANEL
A27: AF0041:04 | B27: -004104 | C27: WHT | D27: 20 | E27: 60 | F27: XT1264:2 | G27: BACK PANEL | H27: AU/AF
A28: AF0041:05 | B28: -004105 | C28: WHT | D28: 20 | E28: 60 | F28: XT1267:2 | G28: BACK PANEL
A29: AF0041:36 | B29: -004136 | C29: WHT | D29: 20 | E29: 60 | F29: XT1264:1 | G29: BACK PANEL
A30: AF0041:37 | B30: -004137 | C30: WHT | D30: 20 | E30: 60 | F30: XT1267:1 | G30: BACK PANEL
A31: AF0043:10 | B31: -004310 | C31: WHT | D31: 20 | E31: 60 | F31: XT0085:2 | G31: BACK PANEL
A32: AF0043:11 | B32: -004311 | C32: WHT | D32: 20 | E32: 60 | F32: XT0085:3 | G32: BACK PANEL
A34: AU0040:COM | B34: -0V | C34: WHT | D34: 16 | E34: 80 | F34: XT0135:2 | G34: BACK PANEL
A36: AF0044:COM | B36: -0V | C36: WHT | D36: 14 | E36: 100 | F36: XT0135:2 | G36: BACK PANEL
A37: AF0045:COM | B37: -0V | C37: WHT | D37: 14 | E37: 100 | F37: XT0135:2 | G37: BACK PANEL
A38: AU0040:V+ | B38: FU0040 | C38: WHT | D38: 14 | E38: 100 | F38: FU0040:LD | G38: BACK PANEL
A39: AF0044:V+ | B39: FU0041 | C39: WHT | D39: 14 | E39: 100 | F39: FU0041:LD | G39: BACK PANEL
A40: AF0045:V+ | B40: FU0042 | C40: WHT | D40: 14 | E40: 100 | F40: FU0042:LD | G40: BACK PANEL
A42: KA7400:A1 | B42: KA7400A1 | C42: WHT | D42: 20 | E42: 100 | F42: AF0045:32 | G42: BACK PANEL | H42: KA A1/A2
A43: KA0083:A1 | B43: KA0083A1 | C43: WHT | D43: 20 | E43: 100 | F43: AF0045:10 | G43: BACK PANEL
A44: KA0082:A1 | B44: KA0082A1 | C44: WHT | D44: 20 | E44: 100 | F44: AF0045:09 | G44: BACK PANEL
A45: KA0081:A1 | B45: KA0081A1 | C45: WHT | D45: 20 | E45: 100 | F45: AF0045:08 | G45: BACK PANEL
A46: KA0003:A1 | B46: KA0003A1 | C46: WHT | D46: 20 | E46: 100 | F46: AF0045:07 | G46: BACK PANEL
A47: KA0002:A1 | B47: KA0002A1 | C47: WHT | D47: 20 | E47: 100 | F47: AF0045:06 | G47: BACK PANEL
A48: KA0001:A1 | B48: KA0001A1 | C48: WHT | D48: 20 | E48: 100 | F48: AF0045:05 | G48: BACK PANEL
...

Sheet RIGHT SIDE PANEL_S
A1: RIGHT SIDE PNL
A2: ASSY,RIGHT SIDE PNL,CONSOLE
A3: Project # | B3: 4M368
A4: Project Name | B4: Los Toldos II Este
A5: Revision | B5: B
A7: Controls DE | B7: Keith Nyberg
A8: Phone:
A9: Controls ME | B9: Dennis Figueroa
A10: Phone:
A12: From | G12: To
A13: Device ID | B13: Wire No. | C13: Wire ID | D13: Gauge/Size | E13: Length | F13: Device ID | G13: Location | H13: Bundle Name
A14: AT0180:48 BAT(-) | B14: -0V | C14: WHT | D14: 14 | E14: 120 | F14: XT1202:2 | G14: RIGHT SIDE PNL | H14: AT0180
A15: AT0180:47 BAT(+) | B15: FU1202 | C15: WHT | D15: 14 | E15: 120 | F15: FU1202:LD | G15: RIGHT SIDE PNL
A17: AT0180:15 VGEN-C | B17: VGEN-C | C17: RED | D17: 16R | E17: 120 | F17: KA1212:14 | G17: RIGHT SIDE PNL | H17: AT-RED
A18: AT0180:13 VGEN-A | B18: VGEN-A | C18: RED | D18: 16R | E18: 120 | F18: KA1211:14 | G18: RIGHT SIDE PNL
A19: AT0180:14 VGEN-B | B19: VGEN-B | C19: RED | D19: 16R | E19: 120 | F19: KA1211:24 | G19: RIGHT SIDE PNL
A20: AT0180:16 VGEN-N | B20: VGEN-N | C20: RED | D20: 16R | E20: 120 | F20: KA1212:24 | G20: RIGHT SIDE PNL
A21: AT0180:17 VBUS-A | B21: VBUS-A | C21: RED | D21: 16R | E21: 120 | F21: KA1219:14 | G21: RIGHT SIDE PNL
A22: AT0180:19 VBUS-C | B22: VBUS-C | C22: RED | D22: 16R | E22: 120 | F22: KA1220:14 | G22: RIGHT SIDE PNL
A23: AT0180:18 VBUS-B | B23: VBUS-B | C23: RED | D23: 16R | E23: 120 | F23: KA1219:24 | G23: RIGHT SIDE PNL
A24: AT0180:20 VBUS-N | B24: VBUS-N | C24: RED | D24: 16R | E24: 120 | F24: KA1220:24 | G24: RIGHT SIDE PNL
A26: AF0111:COM | B26: -0V | C26: WHT | D26: 14 | E26: 60 | F26: XT1202:3 | G26: RIGHT SIDE PNL | H26: AU/AF
A27: AU0110:COM | B27: -0V | C27: WHT | D27: 14 | E27: 60 | F27: XT1202:3 | G27: RIGHT SIDE PNL
A28: AF0112:COM | B28: AU0110N | C28: WHT | D28: 14 | E28: 60 | F28: AU0110:COM | G28: RIGHT SIDE PNL
A29: AF0112:V+ | B29: AU0110P | C29: WHT | D29: 14 | E29: 60 | F29: AU0110:V+ | G29: RIGHT SIDE PNL
A30: AU0110:V+ | B30: FU1203 | C30: WHT | D30: 14 | E30: 60 | F30: FU1203:LD | G30: RIGHT SIDE PNL
A31: AF0111:V+ | B31: FU1204 | C31: WHT | D31: 14 | E31: 60 | F31: FU1204:LD | G31: RIGHT SIDE PNL
A33: KA1211:A1 | B33: KA1211A1 | C33: WHT | D33: 20 | E33: 60 | F33: AF0111:04 | G33: RIGHT SIDE PNL | H33: KA A1
A34: KA1219:A1 | B34: KA1219A1 | C34: WHT | D34: 20 | E34: 60 | F34: AF0111:05 | G34: RIGHT SIDE PNL
A35: KA1244:A1 | B35: KA1244A1 | C35: WHT | D35: 20 | E35: 80 | F35: KA1245:21 | G35: RIGHT SIDE PNL
A37: KA1211:A2 | B37: -0V | C37: WHT | D37: 20 | E37: 60 | F37: XT1200:1 | G37: RIGHT SIDE PNL | H37: KA A2
A38: KA1219:A2 | B38: -0V | C38: WHT | D38: 20 | E38: 60 | F38: XT1200:2 | G38: RIGHT SIDE PNL
A40: KA1201:A2 | B40: -0V | C40: WHT | D40: 14 | E40: 60 | F40: XT1202:1 | G40: RIGHT SIDE PNL
A41: KA1244:A2 | B41: -0V | C41: WHT | D41: 14 | E41: 60 | F41: XT1204:2 | G41: RIGHT SIDE PNL
A42: KA1248:A2 | B42: -0V | C42: WHT | D42: 14 | E42: 60 | F42: XT1204:1 | G42: RIGHT SIDE PNL
A43: KA1249:A2 | B43: -0V | C43: WHT | D43: 14 | E43: 60 | F43: XT1204:1 | G43: RIGHT SIDE PNL
A44: KA1245:A1 | B44: KA120114 | C44: WHT | D44: 14 | E44: 60 | F44: XT1203:2 | G44: RIGHT SIDE PNL
A46: KA1247:14 | B46: -0V | C46: WHT | D46: 20 | E46: 60 | F46: KA1246:14 | G46: RIGHT SIDE PNL | H46: KA
A47: KA1201:11 | B47: FU1201 | C47: WHT | D47: 20 | E47: 60 | F47: XT1201:1 | G47: RIGHT SIDE PNL
A48: KA1245:11 | B48: KA124511 | C48: WHT | D48: 20 | E48: 80 | F48: AF0112:00 | G48: RIGHT SIDE PNL
...

Sheet REMOTE IO BOX #4_S
A1: REMOTE IO BOX #4
A3: Project # | B3: 4M368
A4: Project Name | B4: Los Toldos II Este
A5: Revision | B5: B
A7: Controls DE | B7: Keith Nyberg
A8: Phone:
A9: Controls ME | B9: Dennis Figueroa
A10: Phone:
A12: From | G12: To
A13: Device ID | B13: Wire No. | C13: Wire ID | D13: Gauge/Size | E13: Length | F13: Device ID | G13: Location | H13: Bundle Name
A14: AT0200:47 BAT(+) | B14: FU0103 | C14: WHT | D14: 16 | F14: FU0103:LD | G14: REMOTE IO BOX #4
A15: AT0200:48 BAT(-) | B15: -0VB4 | C15: WHT | D15: 14 | F15: XT0100:5 | G15: REMOTE IO BOX #4
A16: AT0200:20 VBUS-N | B16: VBUS-NU | C16: RED | D16: 16 | F16: KA1228:24 | G16: REMOTE IO BOX #4
A17: AT0200:19 VBUS-C | B17: VBUS-CU | C17: RED | D17: 16 | F17: KA1228:14 | G17: REMOTE IO BOX #4
A18: AT0200:18 VBUS-B | B18: VBUS-BU | C18: RED | D18: 16 | F18: KA1227:24 | G18: REMOTE IO BOX #4
A19: AT0200:17 VBUS-A | B19: VBUS-AU | C19: RED | D19: 16 | F19: KA1227:14 | G19: REMOTE IO BOX #4
A20: AT0200:16 VGEN-N | B20: VGEN-NU | C20: RED | D20: 16 | F20: KA1216:24 | G20: REMOTE IO BOX #4
A21: AT0200:15 VGEN-C | B21: VGEN-CU | C21: RED | D21: 16 | F21: KA1216:14 | G21: REMOTE IO BOX #4
A22: AT0200:14 VGEN-B | B22: VGEN-BU | C22: RED | D22: 16 | F22: KA1215:24 | G22: REMOTE IO BOX #4
A23: AT0200:13 VGEN-A | B23: VGEN-AU | C23: RED | D23: 16 | F23: KA1215:14 | G23: REMOTE IO BOX #4
A25: QS0135:LD-1 | B25: UJ0135P | C25: WHT | D25: 12 | F25: UJ0135:+ | G25: REMOTE IO BOX #4
A26: QS0135:LD-3 | B26: UJ0135N | C26: WHT | D26: 12 | F26: UJ0135:- | G26: REMOTE IO BOX #4
... A50: AF0105:42 | B50: -010542 | C50: WHT | D50: 20 | F50: XT1261:8 | G50: REMOTE IO BOX #4
A51: AF0105:10 | B51: -010510 | F51: XT1261:9 | G51: REMOTE IO BOX #4
A52: AU0100:V+ | B52: FU0100 | C52: WHT | D52: 16 | F52: FU0100:LD | G52: REMOTE IO BOX #4
A53: AF0103:COM | B53: -0VB4 | C53: WHT | D53: 14 | F53: XT0100:4 | G53: REMOTE IO BOX #4
A54: AU0100:COM | B54: -0VB4 | C54: WHT | D54: 14 | F54: XT0100:1 | G54: REMOTE IO BOX #4
A56: KA0026:A1 | B56: KA0026A1 | C56: WHT | D56: 20 | F56: AF0103:00 | G56: REMOTE IO BOX #4 | H56: KA A1
A57: KA0027:A1 | B57: KA0027A1 | C57: WHT | D57: 20 | F57: AF0103:01 | G57: REMOTE IO BOX #4
A58: KA0028:A1 | B58: KA0028A1 | C58: WHT | D58: 20 | F58: AF0103:02 | G58: REMOTE IO BOX #4
A59: KA0029:A1 | B59: KA0029A1 | C59: WHT | D59: 20 | F59: AF0103:03 | G59: REMOTE IO BOX #4
A60: KA0030:A1 | B60: KA0030A1 | C60: WHT | D60: 20 | F60: AF0103:04 | G60: REMOTE IO BOX #4
A61: KA0106:A1 | B61: -010321 | C61: WHT | D61: 20 | F61: AF0103:21 | G61: REMOTE IO BOX #4
A62: KA0107:A1 | B62: -010322 | C62: WHT | D62: 20 | F62: AF0103:22 | G62: REMOTE IO BOX #4
A63: KA0108:A1 | B63: -010323 | C63: WHT | D63: 20 | F63: AF0103:23 | G63: REMOTE IO BOX #4
A64: KA0110:A1 | B64: -010324 | C64: WHT | D64: 20 | F64: AF0103:24 | G64: REMOTE IO BOX #4
A65: KA0111:A1 | B65: -010325 | C65: WHT | D65: 20 | F65: AF0103:25 | G65: REMOTE IO BOX #4
A66: KA1215:A1 | B66: -0VB4 | C66: WHT | D66: 20 | F66: XT0100:6 | G66: REMOTE IO BOX #4
A67: KA1216:A1 | B67: -0VB4 | C67: WHT | D67: 20 | F67: XT0100:6 | G67: REMOTE IO BOX #4
A68: KA1227:A1 | B68: KA1227A1 | C68: WHT | D68: 20 | F68: AF0104:03 | G68: REMOTE IO BOX #4
...

Sheet REMOTE IO BOX #3_S
A1: REMOTE IO BOX #3
A3: Project # | B3: 4M368
A4: Project Name | B4: Los Toldos II Este
A5: Revision | B5: B
A7: Controls DE | B7: Keith Nyberg
A8: Phone:
A9: Controls ME | B9: Dennis Figueroa
A10: Phone:
A12: From | G12: To
A13: Device ID | B13: Wire No. | C13: Wire ID | D13: Gauge/Size | E13: Length | F13: Device ID | G13: Location | H13: Bundle Name
A14: AF0091:01 | B14: -009101 | C14: WHT | D14: 20 | F14: UJ0134:VIN | G14: REMOTE IO BOX #3
A15: AF0091:03 | B15: -009103 | C15: WHT | D15: 20 | F15: UJ0134:IOUT | G15: REMOTE IO BOX #3
A16: AF0093:10 | B16: -009310 | C16: WHT | D16: 20 | F16: UJ0134:OK2 | G16: REMOTE IO BOX #3
A17: AF0093:42 | B17: -009342 | C17: WHT | D17: 20 | F17: UJ0134:OK1 | G17: REMOTE IO BOX #3
A18: UJ0134:OUT(-) | B18: -0VB3 | C18: WHT | D18: 12 | F18: XT0095:2 | G18: REMOTE IO BOX #3
A20: AF0091:04 | B20: -009104 | C20: WHT | D20: 20 | F20: XT0096:2 | G20: REMOTE IO BOX #3
A21: AF0091:05 | B21: -009105 | C21: WHT | D21: 20 | F21: XT0096:3 | G21: REMOTE IO BOX #3
A22: AF0091:COM | B22: AF0092N | C22: WHT | D22: 16 | F22: AF0092:COM | G22: REMOTE IO BOX #3
A23: AF0091:COM | B23: AF0091N | C23: WHT | D23: 16 | F23: AU0090:COM | G23: REMOTE IO BOX #3
A24: AF0091:V+ | B24: AF0092P | C24: WHT | D24: 16 | F24: AF0092:V+ | G24: REMOTE IO BOX #3
A25: AF0091:V+ | B25: AF0091P | C25: WHT | D25: 16 | F25: AU0090:V+ | G25: REMOTE IO BOX #3
A26: AF0092:COM | B26: AF0093N | C26: WHT | D26: 16 | F26: AF0093:COM | G26: REMOTE IO BOX #3
... A87: QS0134:LI-4 | B87: RB3N | C87: WHT | D87: 12 | F87: XT0014:2 | G87: REMOTE IO BOX #3

Sheet REMOTE IO BOX #2_S
A1: REMOTE IO BOX #2
A3: Project # | B3: 4M368
A4: Project Name | B4: Los Toldos II Este
A5: Revision | B5: B
A7: Controls DE | B7: Keith Nyberg
A8: Phone:
A9: Controls ME | B9: Dennis Figueroa
A10: Phone:
A12: From | G12: To
A13: Device ID | B13: Wire No. | C13: Wire ID | D13: Gauge/Size | E13: Length | F13: Device ID | G13: Location | H13: Bundle Name
A14: AF0081:01 | B14: -008101 | C14: WHT | D14: 20 | F14: UJ0133:VIN | G14: REMOTE IO BOX #2
A15: AF0081:03 | B15: -008103 | C15: WHT | D15: 20 | F15: UJ0133:IOUT | G15: REMOTE IO BOX #2
A16: AF0081:10 | B16: -008110 | C16: WHT | D16: 20 | F16: XT0082:2 | G16: REMOTE IO BOX #2
A17: AF0081:11 | B17: -008111 | C17: WHT | D17: 20 | F17: XT0082:3 | G17: REMOTE IO BOX #2
A18: AF0082:00 | B18: -008200 | C18: WHT | D18: 20 | F18: UJ0133:OK2 | G18: REMOTE IO BOX #2
A19: AF0082:32 | B19: -008232 | C19: WHT | D19: 20 | F19: UJ0133:OK1 | G19: REMOTE IO BOX #2
A20: KA0014:A1 | B20: KA0014A1 | C20: WHT | D20: 20 | F20: AF0083:00 | G20: REMOTE IO BOX #2
A21: KA0014:A2 | B21: KA0014A2 | C21: WHT | D21: 20 | F21: AF0083:16 | G21: REMOTE IO BOX #2
A22: KA0015:A1 | B22: KA0015A1 | C22: WHT | D22: 20 | F22: AF0083:01 | G22: REMOTE IO BOX #2
A23: KA0015:A2 | B23: KA0015A2 | C23: WHT | D23: 20 | F23: AF0083:17 | G23: REMOTE IO BOX #2
A24: KA0016:A1 | B24: KA0016A1 | C24: WHT | D24: 20 | F24: AF0083:02 | G24: REMOTE IO BOX #2
A25: KA0016:A2 | B25: KA0016A2 | C25: WHT | D25: 20 | F25: AF0083:18 | G25: REMOTE IO BOX #2
... A55: QS0133:LI-4 | B55: RB2N | C55: WHT | D55: 12 | F55: XT0013:2 | G55: REMOTE IO BOX #2

Sheet REMOTE IO BOX #1_S
A1: REMOTE IO BOX #1
A3: Project # | B3: 4M368
A4: Project Name | B4: Los Toldos II Este
A5: Revision | B5: B
A7: Controls DE | B7: Keith Nyberg
A8: Phone:
A9: Controls ME | B9: Dennis Figueroa
A10: Phone:
A12: From | G12: To
A13: Device ID | B13: Wire No. | C13: Wire ID | D13: Gauge/Size | E13: Length | F13: Device ID | G13: Location | H13: Bundle Name
A14: AF0061:01 | B14: -006101 | C14: WHT | D14: 20 | F14: UJ0132:VIN | G14: REMOTE IO BOX #1
A15: AF0061:09 | B15: -006109 | C15: WHT | D15: 20 | F15: UJ0132:IOUT | G15: REMOTE IO BOX #1
A16: AF0061:COM | B16: AF0061N | C16: WHT | D16: 20 | F16: AF0062:COM | G16: REMOTE IO BOX #1
A17: AF0061:COM | B17: AU0060N | C17: WHT | D17: 20 | F17: AU0060:COM | G17: REMOTE IO BOX #1
A18: AF0061:V+ | B18: AF0061P | C18: WHT | D18: 20 | F18: AF0062:V+ | G18: REMOTE IO BOX #1
A19: AF0061:V+ | B19: AU0060P | C19: WHT | D19: 20 | F19: AU0060:V+ | G19: REMOTE IO BOX #1
A20: AF0062:00 | B20: -006200 | C20: WHT | D20: 20 | F20: XT0086:2 | G20: REMOTE IO BOX #1
A21: AF0062:01 | B21: -006201 | C21: WHT | D21: 20 | F21: XT0086:3 | G21: REMOTE IO BOX #1
A22: AF0062:COM | B22: AF0062N | C22: WHT | D22: 20 | F22: AF0063:COM | G22: REMOTE IO BOX #1
A23: AF0062:V+ | B23: AF0062P | C23: WHT | D23: 20 | F23: AF0063:V+ | G23: REMOTE IO BOX #1
A24: AF0063:10 | B24: -006310 | C24: WHT | D24: 20 | F24: UJ0132:OK2 | G24: REMOTE IO BOX #1
A25: AF0063:42 | B25: -006342 | C25: WHT | D25: 20 | F25: UJ0132:OK1 | G25: REMOTE IO BOX #1
... A84: QS0132:LI-4 | B84: RB1N | C84: WHT | D84: 12 | F84: XT0012:2 | G84: REMOTE IO BOX #1
A85: KA0089:A1 | B85: * | F85: AF0064:14 | G85: REMOTE IO BOX #1
A86: KA0089:A2 | B86: * | F86: AF0064:30 | G86: REMOTE IO BOX #1

Sheet Bundle Tag Info
A1: Project Name and Unit #
A2: PD #
A3: Revision
A6: Panel Name | B6: Panel Name | C6: Panel Name | D6: Panel Name | E6: Panel Name | F6: Panel Name | G6: Panel Name | H6: Panel Name | I6: Panel Name | J6: Panel Name | K6: Panel Name | L6: Panel Name | M6: Panel Name | N6: Panel Name | O6: Panel Name | P6: Panel Name | Q6: Panel Name | R6: Panel Name | S6: Panel Name | T6: Panel Name | U6: Panel Name | V6: Panel Name | W6: Panel Name | X6: Panel Name | Y6: Panel Name | Z6: Panel Name | AA6: Panel Name | AB6: Panel Name | AC6: Panel Name | AD6: Panel Name
A7: Insert
A8: Tag Names
A9: Here

Sheet Bundle Tags2
A1: =IF('Bundle Tag Info'!A6<>"Panel Name",'Bundle Tag Info'!A6,"") | B1: =IF('Bundle Tag Info'!B6<>"Panel Name",'Bundle Tag Info'!B6,"") | C1: =IF('Bundle Tag Info'!C6<>"Panel Name",'Bundle Tag Info'!C6,"") | D1: =IF('Bundle Tag Info'!D6<>"Panel Name",'Bundle Tag Info'!D6,"") | E1: =IF('Bundle Tag Info'!E6<>"Panel Name",'Bundle Tag Info'!E6,"") | F1: =IF('Bundle Tag Info'!F6<>"Panel Name",'Bundle Tag Info'!F6,"") | G1: =IF('Bundle Tag Info'!G6<>"Panel Name",'Bundle Tag Info'!G6,"") | H1: =IF('Bundle Tag Info'!H6<>"Panel Name",'Bundle Tag Info'!H6,"") | ... AD1: =IF('Bundle Tag Info'!AD6<>"Panel Name",'Bundle Tag Info'!AD6,"")
A2: =IF('Bundle Tag Info'!A$7<>"",CONCATENATE('Bundle Tag Info'!$A$1," ",CHAR(10),'Bundle Tag Info'!$A$2," ",'Bundle Tag Info'!$A$3,CHAR(10),'Bundle Tag Info'!A$6,CHAR(10),'Bundle Tag Info'!A$7),"") -> Project Name and Unit # PD # Revision Panel Name Insert | B2: =IF('Bundle Tag Info'!B$7<>"",CONCATENATE('Bundle Tag Info'!$A$1," ",CHAR(10),'Bundle Tag Info'!$A$2," ",'Bundle Tag Info'!$A$3,CHAR(10),'Bundle Tag Info'!B$6,CHAR(10),'Bundle Tag Info'!B$7),"") | C2: =IF('Bundle Tag Info'!C$7<>"",CONCATENATE('Bundle Tag Info'!$A$1," ",CHAR(10),'Bundle Tag Info'!$A$2," ",'Bundle Tag Info'!$A$3,CHAR(10),'Bundle Tag Info'!C$6,CHAR(10),'Bundle Tag Info'!C$7),"") | D2: =IF('Bundle Tag Info'!D$7<>"",CONCATENATE('Bundle Tag Info'!$A$1," ",CHAR(10),'Bundle Tag Info'!$A$2," ",'Bundle Tag Info'!$A$3,CHAR(10),'Bundle Tag Info'!D$6,CHAR(10),'Bundle Tag Info'!D$7),"") | E2: =IF('Bundle Tag Info'!E$7<>"",CONCATENATE('Bundle Tag Info'!$A$1," ",CHAR(10),'Bundle Tag Info'!$A$2," ",'Bundle Tag Info'!$A$3,CHAR(10),'Bundle Tag Info'!E$6,CHAR(10),'Bundle Tag Info'!E$7),"") | F2: =IF('Bundle Tag Info'!F$7<>"",CONCATENATE('Bundle Tag Info'!$A$1," ",CHAR(10),'Bundle Tag Info'!$A$2," ",'Bundle Tag Info'!$A$3,CHAR(10),'Bundle Tag Info'!F$6,CHAR(10),'Bundle Tag Info'!F$7),"") | G2: =IF('Bundle Tag Info'!G$7<>"",CONCATENATE('Bundle Tag Info'!$A$1," ",CHAR(10),'Bundle Tag Info'!$A$2," ",'Bundle Tag Info'!$A$3,CHAR(10),'Bundle Tag Info'!G$6,CHAR(10),'Bundle Tag Info'!G$7),"") | H2: =IF('Bundle Tag Info'!H$7<>"",CONCATENATE('Bundle Tag Info'!$A$1," ",CHAR(10),'Bundle Tag Info'!$A$2," ",'Bundle Tag Info'!$A$3,CHAR(10),'Bundle Tag Info'!H$6,CHAR(10),'Bundle Tag Info'!H$7),"") | ... AD2: =IF('Bundle Tag Info'!AD$7<>"",CONCATENATE('Bundle Tag Info'!$A$1," ",CHAR(10),'Bundle Tag Info'!$A$2," ",'Bundle Tag Info'!$A$3,CHAR(10),'Bundle Tag Info'!AD$6,CHAR(10),'Bundle Tag Info'!AD$7),"")
A3: =IF('Bundle Tag Info'!A$8<>"",CONCATENATE('Bundle Tag Info'!$A$1," ",CHAR(10),'Bundle Tag Info'!$A$2," ",'Bundle Tag Info'!$A$3,CHAR(10),'Bundle Tag Info'!A$6,CHAR(10),'Bundle Tag Info'!A$8),"") -> Project Name and Unit # PD # Revision Panel Name Tag Names | B3: =IF('Bundle Tag Info'!B$8<>"",CONCATENATE('Bundle Tag Info'!$A$1," ",CHAR(10),'Bundle Tag Info'!$A$2," ",'Bundle Tag Info'!$A$3,CHAR(10),'Bundle Tag Info'!B$6,CHAR(10),'Bundle Tag Info'!B$8),"") | C3: =IF('Bundle Tag Info'!C$8<>"",CONCATENATE('Bundle Tag Info'!$A$1," ",CHAR(10),'Bundle Tag Info'!$A$2," ",'Bundle Tag Info'!$A$3,CHAR(10),'Bundle Tag Info'!C$6,CHAR(10),'Bundle Tag Info'!C$8),"") | D3: =IF('Bundle Tag Info'!D$8<>"",CONCATENATE('Bundle Tag Info'!$A$1," ",CHAR(10),'Bundle Tag Info'!$A$2," ",'Bundle Tag Info'!$A$3,CHAR(10),'Bundle Tag Info'!D$6,CHAR(10),'Bundle Tag Info'!D$8),"") | E3: =IF('Bundle Tag Info'!E$8<>"",CONCATENATE('Bundle Tag Info'!$A$1," ",CHAR(10),'Bundle Tag Info'!$A$2," ",'Bundle Tag Info'!$A$3,CHAR(10),'Bundle Tag Info'!E$6,CHAR(10),'Bundle Tag Info'!E$8),"") | F3: =IF('Bundle Tag Info'!F$8<>"",CONCATENATE('Bundle Tag Info'!$A$1," ",CHAR(10),'Bundle Tag Info'!$A$2," ",'Bundle Tag Info'!$A$3,CHAR(10),'Bundle Tag Info'!F$6,CHAR(10),'Bundle Tag Info'!F$8),"") | G3: =IF('Bundle Tag Info'!G$8<>"",CONCATENATE('Bundle Tag Info'!$A$1," ",CHAR(10),'Bundle Tag Info'!$A$2," ",'Bundle Tag Info'!$A$3,CHAR(10),'Bundle Tag Info'!G$6,CHAR(10),'Bundle Tag Info'!G$8),"") | H3: =IF('Bundle Tag Info'!H$8<>"",CONCATENATE('Bundle Tag Info'!$A$1," ",CHAR(10),'Bundle Tag Info'!$A$2," ",'Bundle Tag Info'!$A$3,CHAR(10),'Bundle Tag Info'!H$6,CHAR(10),'Bundle Tag Info'!H$8),"") | ... AD3: =IF('Bundle Tag Info'!AD$8<>"",CONCATENATE('Bundle Tag Info'!$A$1," ",CHAR(10),'Bundle Tag Info'!$A$2," ",'Bundle Tag Info'!$A$3,CHAR(10),'Bundle Tag Info'!AD$6,CHAR(10),'Bundle Tag Info'!AD$8),"")
A4: =IF('Bundle Tag Info'!A$9<>"",CONCATENATE('Bundle Tag Info'!$A$1," ",CHAR(10),'Bundle Tag Info'!$A$2," ",'Bundle Tag Info'!$A$3,CHAR(10),'Bundle Tag Info'!A$6,CHAR(10),'Bundle Tag Info'!A$9),"") -> Project Name and Unit # PD # Revision Panel Name Here | B4: =IF('Bundle Tag Info'!B$9<>"",CONCATENATE('Bundle Tag Info'!$A$1," ",CHAR(10),'Bundle Tag Info'!$A$2," ",'Bundle Tag Info'!$A$3,CHAR(10),'Bundle Tag Info'!B$6,CHAR(10),'Bundle Tag Info'!B$9),"") | C4: =IF('Bundle Tag Info'!C$9<>"",CONCATENATE('Bundle Tag Info'!$A$1," ",CHAR(10),'Bundle Tag Info'!$A$2," ",'Bundle Tag Info'!$A$3,CHAR(10),'Bundle Tag Info'!C$6,CHAR(10),'Bundle Tag Info'!C$9),"") | D4: =IF('Bundle Tag Info'!D$9<>"",CONCATENATE('Bundle Tag Info'!$A$1," ",CHAR(10),'Bundle Tag Info'!$A$2," ",'Bundle Tag Info'!$A$3,CHAR(10),'Bundle Tag Info'!D$6,CHAR(10),'Bundle Tag Info'!D$9),"") | E4: =IF('Bundle Tag Info'!E$9<>"",CONCATENATE('Bundle Tag Info'!$A$1," ",CHAR(10),'Bundle Tag Info'!$A$2," ",'Bundle Tag Info'!$A$3,CHAR(10),'Bundle Tag Info'!E$6,CHAR(10),'Bundle Tag Info'!E$9),"") | F4: =IF('Bundle Tag Info'!F$9<>"",CONCATENATE('Bundle Tag Info'!$A$1," ",CHAR(10),'Bundle Tag Info'!$A$2," ",'Bundle Tag Info'!$A$3,CHAR(10),'Bundle Tag Info'!F$6,CHAR(10),'Bundle Tag Info'!F$9),"") | G4: =IF('Bundle Tag Info'!G$9<>"",CONCATENATE('Bundle Tag Info'!$A$1," ",CHAR(10),'Bundle Tag Info'!$A$2," ",'Bundle Tag Info'!$A$3,CHAR(10),'Bundle Tag Info'!G$6,CHAR(10),'Bundle Tag Info'!G$9),"") | H4: =IF('Bundle Tag Info'!H$9<>"",CONCATENATE('Bundle Tag Info'!$A$1," ",CHAR(10),'Bundle Tag Info'!$A$2," ",'Bundle Tag Info'!$A$3,CHAR(10),'Bundle Tag Info'!H$6,CHAR(10),'Bundle Tag Info'!H$9),"") | ... AD4: =IF('Bundle Tag Info'!AD$9<>"",CONCATENATE('Bundle Tag Info'!$A$1," ",CHAR(10),'Bundle Tag Info'!$A$2," ",'Bundle Tag Info'!$A$3,CHAR(10),'Bundle Tag Info'!AD$6,CHAR(10),'Bundle Tag Info'!AD$9),"")
A5: =IF('Bundle Tag Info'!A$10<>"",CONCATENATE('Bundle Tag Info'!$A$1," ",CHAR(10),'Bundle Tag Info'!$A$2," ",'Bundle Tag Info'!$A$3,CHAR(10),'Bundle Tag Info'!A$6,CHAR(10),'Bundle Tag Info'!A$10),"") | B5: =IF('Bundle Tag Info'!B$10<>"",CONCATENATE('Bundle Tag Info'!$A$1," ",CHAR(10),'Bundle Tag Info'!$A$2," ",'Bundle Tag Info'!$A$3,CHAR(10),'Bundle Tag Info'!B$6,CHAR(10),'Bundle Tag Info'!B$10),"") | C5: =IF('Bundle Tag Info'!C$10<>"",CONCATENATE('Bundle Tag Info'!$A$1," ",CHAR(10),'Bundle Tag Info'!$A$2," ",'Bundle Tag Info'!$A$3,CHAR(10),'Bundle Tag Info'!C$6,CHAR(10),'Bundle Tag Info'!C$10),"") | D5: =IF('Bundle Tag Info'!D$10<>"",CONCATENATE('Bundle Tag Info'!$A$1," ",CHAR(10),'Bundle Tag Info'!$A$2," ",'Bundle Tag Info'!$A$3,CHAR(10),'Bundle Tag Info'!D$6,CHAR(10),'Bundle Tag Info'!D$10),"") | E5: =IF('Bundle Tag Info'!E$10<>"",CONCATENATE('Bundle Tag Info'!$A$1," ",CHAR(10),'Bundle Tag Info'!$A$2," ",'Bundle Tag Info'!$A$3,CHAR(10),'Bundle Tag Info'!E$6,CHAR(10),'Bundle Tag Info'!E$10),"") | F5: =IF('Bundle Tag Info'!F$10<>"",CONCATENATE('Bundle Tag Info'!$A$1," ",CHAR(10),'Bundle Tag Info'!$A$2," ",'Bundle Tag Info'!$A$3,CHAR(10),'Bundle Tag Info'!F$6,CHAR(10),'Bundle Tag Info'!F$10),"") | G5: =IF('Bundle Tag Info'!G$10<>"",CONCATENATE('Bundle Tag Info'!$A$1," ",CHAR(10),'Bundle Tag Info'!$A$2," ",'Bundle Tag Info'!$A$3,CHAR(10),'Bundle Tag Info'!G$6,CHAR(10),'Bundle Tag Info'!G$10),"") | H5: =IF('Bundle Tag Info'!H$10<>"",CONCATENATE('Bundle Tag Info'!$A$1," ",CHAR(10),'Bundle Tag Info'!$A$2," ",'Bundle Tag Info'!$A$3,CHAR(10),'Bundle Tag Info'!H$6,CHAR(10),'Bundle Tag Info'!H$10),"") | ... AD5: =IF('Bundle Tag Info'!AD$10<>"",CONCATENATE('Bundle Tag Info'!$A$1," ",CHAR(10),'Bundle Tag Info'!$A$2," ",'Bundle Tag Info'!$A$3,CHAR(10),'Bundle Tag Info'!AD$6,CHAR(10),'Bundle Tag Info'!AD$10),"")
A6: =IF('Bundle Tag Info'!A$11<>"",CONCATENATE('Bundle Tag Info'!$A$1," ",CHAR(10),'Bundle Tag Info'!$A$2," ",'Bundle Tag Info'!$A$3,CHAR(10),'Bundle Tag Info'!A$6,CHAR(10),'Bundle Tag Info'!A$11),"") | B6: =IF('Bundle Tag Info'!B$11<>"",CONCATENATE('Bundle Tag Info'!$A$1," ",CHAR(10),'Bundle Tag Info'!$A$2," ",'Bundle Tag Info'!$A$3,CHAR(10),'Bundle Tag Info'!B$6,CHAR(10),'Bundle Tag Info'!B$11),"") | C6: =IF('Bundle Tag Info'!C$11<>"",CONCATENATE('Bundle Tag Info'!$A$1," ",CHAR(10),'Bundle Tag Info'!$A$2," ",'Bundle Tag Info'!$A$3,CHAR(10),'Bundle Tag Info'!C$6,CHAR(10),'Bundle Tag Info'!C$11),"") | D6: =IF('Bundle Tag Info'!D$11<>"",CONCATENATE('Bundle Tag Info'!$A$1," ",CHAR(10),'Bundle Tag Info'!$A$2," ",'Bundle Tag Info'!$A$3,CHAR(10),'Bundle Tag Info'!D$6,CHAR(10),'Bundle Tag Info'!D$11),"") | E6: =IF('Bundle Tag Info'!E$11<>"",CONCATENATE('Bundle Tag Info'!$A$1," ",CHAR(10),'Bundle Tag Info'!$A$2," ",'Bundle Tag Info'!$A$3,CHAR(10),'Bundle Tag Info'!E$6,CHAR(10),'Bundle Tag Info'!E$11),"") | F6: =IF('Bundle Tag Info'!F$11<>"",CONCATENATE('Bundle Tag Info'!$A$1," ",CHAR(10),'Bundle Tag Info'!$A$2," ",'Bundle Tag Info'!$A$3,CHAR(10),'Bundle Tag Info'!F$6,CHAR(10),'Bundle Tag Info'!F$11),"") | G6: =IF('Bundle Tag Info'!G$11<>"",CONCATENATE('Bundle Tag Info'!$A$1," ",CHAR(10),'Bundle Tag Info'!$A$2," ",'Bundle Tag Info'!$A$3,CHAR(10),'Bundle Tag Info'!G$6,CHAR(10),'Bundle Tag Info'!G$11),"") | H6: =IF('Bundle Tag Info'!H$11<>"",CONCATENATE('Bundle Tag Info'!$A$1," ",CHAR(10),'Bundle Tag Info'!$A$2," ",'Bundle Tag Info'!$A$3,CHAR(10),'Bundle Tag Info'!H$6,CHAR(10),'Bundle Tag Info'!H$11),"") | ... AD6: =IF('Bundle Tag Info'!AD$11<>"",CONCATENATE('Bundle Tag Info'!$A$1," ",CHAR(10),'Bundle Tag Info'!$A$2," ",'Bundle Tag Info'!$A$3,CHAR(10),'Bundle Tag Info'!AD$6,CHAR(10),'Bundle Tag Info'!AD$11),"")
A7: =IF('Bundle Tag Info'!A$12<>"",CONCATENATE('Bundle Tag Info'!$A$1," ",CHAR(10),'Bundle Tag Info'!$A$2," ",'Bundle Tag Info'!$A$3,CHAR(10),'Bundle Tag Info'!A$6,CHAR(10),'Bundle Tag Info'!A$12),"") | B7: =IF('Bundle Tag Info'!B$12<>"",CONCATENATE('Bundle Tag Info'!$A$1," ",CHAR(10),'Bundle Tag Info'!$A$2," ",'Bundle Tag Info'!$A$3,CHAR(10),'Bundle Tag Info'!B$6,CHAR(10),'Bundle Tag Info'!B$12),"") | C7: =IF('Bundle Tag Info'!C$12<>"",CONCATENATE('Bundle Tag Info'!$A$1," ",CHAR(10),'Bundle Tag Info'!$A$2," ",'Bundle Tag Info'!$A$3,CHAR(10),'Bundle Tag Info'!C$6,CHAR(10),'Bundle Tag Info'!C$12),"") | D7: =IF('Bundle Tag Info'!D$12<>"",CONCATENATE('Bundle Tag Info'!$A$1," ",CHAR(10),'Bundle Tag Info'!$A$2," ",'Bundle Tag Info'!$A$3,CHAR(10),'Bundle Tag Info'!D$6,CHAR(10),'Bundle Tag Info'!D$12),"") | E7: =IF('Bundle Tag Info'!E$12<>"",CONCATENATE('Bundle Tag Info'!$A$1," ",CHAR(10),'Bundle Tag Info'!$A$2," ",'Bundle Tag Info'!$A$3,CHAR(10),'Bundle Tag Info'!E$6,CHAR(10),'Bundle Tag Info'!E$12),"") | F7: =IF('Bundle Tag Info'!F$12<>"",CONCATENATE('Bundle Tag Info'!$A$1," ",CHAR(10),'Bundle Tag Info'!$A$2," ",'Bundle Tag Info'!$A$3,CHAR(10),'Bundle Tag Info'!F$6,CHAR(10),'Bundle Tag Info'!F$12),"") | G7: =IF('Bundle Tag Info'!G$12<>"",CONCATENATE('Bundle Tag Info'!$A$1," ",CHAR(10),'Bundle Tag Info'!$A$2," ",'Bundle Tag Info'!$A$3,CHAR(10),'Bundle Tag Info'!G$6,CHAR(10),'Bundle Tag Info'!G$12),"") | H7: =IF('Bundle Tag Info'!H$12<>"",CONCATENATE('Bundle Tag Info'!$A$1," ",CHAR(10),'Bundle Tag Info'!$A$2," ",'Bundle Tag Info'!$A$3,CHAR(10),'Bundle Tag Info'!H$6,CHAR(10),'Bundle Tag Info'!H$12),"") | ... AD7: =IF('Bundle Tag Info'!AD$12<>"",CONCATENATE('Bundle Tag Info'!$A$1," ",CHAR(10),'Bundle Tag Info'!$A$2," ",'Bundle Tag Info'!$A$3,CHAR(10),'Bundle Tag Info'!AD$6,CHAR(10),'Bundle Tag Info'!AD$12),"")
A8: =IF('Bundle Tag Info'!A$13<>"",CONCATENATE('Bundle Tag Info'!$A$1," ",CHAR(10),'Bundle Tag Info'!$A$2," ",'Bundle Tag Info'!$A$3,CHAR(10),'Bundle Tag Info'!A$6,CHAR(10),'Bundle Tag Info'!A$13),"") | B8: =IF('Bundle Tag Info'!B$13<>"",CONCATENATE('Bundle Tag Info'!$A$1," ",CHAR(10),'Bundle Tag Info'!$A$2," ",'Bundle Tag Info'!$A$3,CHAR(10),'Bundle Tag Info'!B$6,CHAR(10),'Bundle Tag Info'!B$13),"") | C8: =IF('Bundle Tag Info'!C$13<>"",CONCATENATE('Bundle Tag Info'!$A$1," ",CHAR(10),'Bundle Tag Info'!$A$2," ",'Bundle Tag Info'!$A$3,CHAR(10),'Bundle Tag Info'!C$6,CHAR(10),'Bundle Tag Info'!C$13),"") | D8: =IF('Bundle Tag Info'!D$13<>"",CONCATENATE('Bundle Tag Info'!$A$1," ",CHAR(10),'Bundle Tag Info'!$A$2," ",'Bundle Tag Info'!$A$3,CHAR(10),'Bundle Tag Info'!D$6,CHAR(10),'Bundle Tag Info'!D$13),"") | E8: =IF('Bundle Tag Info'!E$13<>"",CONCATENATE('Bundle Tag Info'!$A$1," ",CHAR(10),'Bundle Tag Info'!$A$2," ",'Bundle Tag Info'!$A$3,CHAR(10),'Bundle Tag Info'!E$6,CHAR(10),'Bundle Tag Info'!E$13),"") | F8: =IF('Bundle Tag Info'!F$13<>"",CONCATENATE('Bundle Tag Info'!$A$1," ",CHAR(10),'Bundle Tag Info'!$A$2," ",'Bundle Tag Info'!$A$3,CHAR(10),'Bundle Tag Info'!F$6,CHAR(10),'Bundle Tag Info'!F$13),"") | G8: =IF('Bundle Tag Info'!G$13<>"",CONCATENATE('Bundle Tag Info'!$A$1," ",CHAR(10),'Bundle Tag Info'!$A$2," ",'Bundle Tag Info'!$A$3,CHAR(10),'Bundle Tag Info'!G$6,CHAR(10),'Bundle Tag Info'!G$13),"") | H8: =IF('Bundle Tag Info'!H$13<>"",CONCATENATE('Bundle Tag Info'!$A$1," ",CHAR(10),'Bundle Tag Info'!$A$2," ",'Bundle Tag Info'!$A$3,CHAR(10),'Bundle Tag Info'!H$6,CHAR(10),'Bundle Tag Info'!H$13),"") | ... AD8: =IF('Bundle Tag Info'!AD$13<>"",CONCATENATE('Bundle Tag Info'!$A$1," ",CHAR(10),'Bundle Tag Info'!$A$2," ",'Bundle Tag Info'!$A$3,CHAR(10),'Bundle Tag Info'!AD$6,CHAR(10),'Bundle Tag Info'!AD$13),"")
A9: =IF('Bundle Tag Info'!A$14<>"",CONCATENATE('Bundle Tag Info'!$A$1," ",CHAR(10),'Bundle Tag Info'!$A$2," ",'Bundle Tag Info'!$A$3,CHAR(10),'Bundle Tag Info'!A$6,CHAR(10),'Bundle Tag Info'!A$14),"") | B9: =IF('Bundle Tag Info'!B$14<>"",CONCATENATE('Bundle Tag Info'!$A$1," ",CHAR(10),'Bundle Tag Info'!$A$2," ",'Bundle Tag Info'!$A$3,CHAR(10),'Bundle Tag Info'!B$6,CHAR(10),'Bundle Tag Info'!B$14),"") | C9: =IF('Bundle Tag Info'!C$14<>"",CONCATENATE('Bundle Tag Info'!$A$1," ",CHAR(10),'Bundle Tag Info'!$A$2," ",'Bundle Tag Info'!$A$3,CHAR(10),'Bundle Tag Info'!C$6,CHAR(10),'Bundle Tag Info'!C$14),"") | D9: =IF('Bundle Tag Info'!D$14<>"",CONCATENATE('Bundle Tag Info'!$A$1," ",CHAR(10),'Bundle Tag Info'!$A$2," ",'Bundle Tag Info'!$A$3,CHAR(10),'Bundle Tag Info'!D$6,CHAR(10),'Bundle Tag Info'!D$14),"") | E9: =IF('Bundle Tag Info'!E$14<>"",CONCATENATE('Bundle Tag Info'!$A$1," ",CHAR(10),'Bundle Tag Info'!$A$2," ",'Bundle Tag Info'!$A$3,CHAR(10),'Bundle Tag Info'!E$6,CHAR(10),'Bundle Tag Info'!E$14),"") | F9: =IF('Bundle Tag Info'!F$14<>"",CONCATENATE('Bundle Tag Info'!$A$1," ",CHAR(10),'Bundle Tag Info'!$A$2," ",'Bundle Tag Info'!$A$3,CHAR(10),'Bundle Tag Info'!F$6,CHAR(10),'Bundle Tag Info'!F$14),"") | G9: =IF('Bundle Tag Info'!G$14<>"",CONCATENATE('Bundle Tag Info'!$A$1," ",CHAR(10),'Bundle Tag Info'!$A$2," ",'Bundle Tag Info'!$A$3,CHAR(10),'Bundle Tag Info'!G$6,CHAR(10),'Bundle Tag Info'!G$14),"") | H9: =IF('Bundle Tag Info'!H$14<>"",CONCATENATE('Bundle Tag Info'!$A$1," ",CHAR(10),'Bundle Tag Info'!$A$2," ",'Bundle Tag Info'!$A$3,CHAR(10),'Bundle Tag Info'!H$6,CHAR(10),'Bundle Tag Info'!H$14),"") | ... AD9: =IF('Bundle Tag Info'!AD$14<>"",CONCATENATE('Bundle Tag Info'!$A$1," ",CHAR(10),'Bundle Tag Info'!$A$2," ",'Bundle Tag Info'!$A$3,CHAR(10),'Bundle Tag Info'!AD$6,CHAR(10),'Bundle Tag Info'!AD$14),"")
A10: =IF('Bundle Tag Info'!A$15<>"",CONCATENATE('Bundle Tag Info'!$A$1," ",CHAR(10),'Bundle Tag Info'!$A$2," ",'Bundle Tag Info'!$A$3,CHAR(10),'Bundle Tag Info'!A$6,CHAR(10),'Bundle Tag Info'!A$15),"") | B10: =IF('Bundle Tag Info'!B$15<>"",CONCATENATE('Bundle Tag Info'!$A$1," ",CHAR(10),'Bundle Tag Info'!$A$2," ",'Bundle Tag Info'!$A$3,CHAR(10),'Bundle Tag Info'!B$6,CHAR(10),'Bundle Tag Info'!B$15),"") | C10: =IF('Bundle Tag Info'!C$15<>"",CONCATENATE('Bundle Tag Info'!$A$1," ",CHAR(10),'Bundle Tag Info'!$A$2," ",'Bundle Tag Info'!$A$3,CHAR(10),'Bundle Tag Info'!C$6,CHAR(10),'Bundle Tag Info'!C$15),"") | D10: =IF('Bundle Tag Info'!D$15<>"",CONCATENATE('Bundle Tag Info'!$A$1," ",CHAR(10),'Bundle Tag Info'!$A$2," ",'Bundle Tag Info'!$A$3,CHAR(10),'Bundle Tag Info'!D$6,CHAR(10),'Bundle Tag Info'!D$15),"") | E10: =IF('Bundle Tag Info'!E$15<>"",CONCATENATE('Bundle Tag Info'!$A$1," ",CHAR(10),'Bundle Tag Info'!$A$2," ",'Bundle Tag Info'!$A$3,CHAR(10),'Bundle Tag Info'!E$6,CHAR(10),'Bundle Tag Info'!E$15),"") | F10: =IF('Bundle Tag Info'!F$15<>"",CONCATENATE('Bundle Tag Info'!$A$1," ",CHAR(10),'Bundle Tag Info'!$A$2," ",'Bundle Tag Info'!$A$3,CHAR(10),'Bundle Tag Info'!F$6,CHAR(10),'Bundle Tag Info'!F$15),"") | G10: =IF('Bundle Tag Info'!G$15<>"",CONCATENATE('Bundle Tag Info'!$A$1," ",CHAR(10),'Bundle Tag Info'!$A$2," ",'Bundle Tag Info'!$A$3,CHAR(10),'Bundle Tag Info'!G$6,CHAR(10),'Bundle Tag Info'!G$15),"") | H10: =IF('Bundle Tag Info'!H$15<>"",CONCATENATE('Bundle Tag Info'!$A$1," ",CHAR(10),'Bundle Tag Info'!$A$2," ",'Bundle Tag Info'!$A$3,CHAR(10),'Bundle Tag Info'!H$6,CHAR(10),'Bundle Tag Info'!H$15),"") | ... AD10: =IF('Bundle Tag Info'!AD$15<>"",CONCATENATE('Bundle Tag Info'!$A$1," ",CHAR(10),'Bundle Tag Info'!$A$2," ",'Bundle Tag Info'!$A$3,CHAR(10),'Bundle Tag Info'!AD$6,CHAR(10),'Bundle Tag Info'!AD$15),"")
A11: =IF('Bundle Tag Info'!A$16<>"",CONCATENATE('Bundle Tag Info'!$A$1," ",CHAR(10),'Bundle Tag Info'!$A$2," ",'Bundle Tag Info'!$A$3,CHAR(10),'Bundle Tag Info'!A$6,CHAR(10),'Bundle Tag Info'!A$16),"") | B11: =IF('Bundle Tag Info'!B$16<>"",CONCATENATE('Bundle Tag Info'!$A$1," ",CHAR(10),'Bundle Tag Info'!$A$2," ",'Bundle Tag Info'!$A$3,CHAR(10),'Bundle Tag Info'!B$6,CHAR(10),'Bundle Tag Info'!B$16),"") | C11: =IF('Bundle Tag Info'!C$16<>"",CONCATENATE('Bundle Tag Info'!$A$1," ",CHAR(10),'Bundle Tag Info'!$A$2," ",'Bundle Tag Info'!$A$3,CHAR(10),'Bundle Tag Info'!C$6,CHAR(10),'Bundle Tag Info'!C$16),"") | D11: =IF('Bundle Tag Info'!D$16<>"",CONCATENATE('Bundle Tag Info'!$A$1," ",CHAR(10),'Bundle Tag Info'!$A$2," ",'Bundle Tag Info'!$A$3,CHAR(10),'Bundle Tag Info'!D$6,CHAR(10),'Bundle Tag Info'!D$16),"") | E11: =IF('Bundle Tag Info'!E$16<>"",CONCATENATE('Bundle Tag Info'!$A$1," ",CHAR(10),'Bundle Tag Info'!$A$2," ",'Bundle Tag Info'!$A$3,CHAR(10),'Bundle Tag Info'!E$6,CHAR(10),'Bundle Tag Info'!E$16),"") | F11: =IF('Bundle Tag Info'!F$16<>"",CONCATENATE('Bundle Tag Info'!$A$1," ",CHAR(10),'Bundle Tag Info'!$A$2," ",'Bundle Tag Info'!$A$3,CHAR(10),'Bundle Tag Info'!F$6,CHAR(10),'Bundle Tag Info'!F$16),"") | G11: =IF('Bundle Tag Info'!G$16<>"",CONCATENATE('Bundle Tag Info'!$A$1," ",CHAR(10),'Bundle Tag Info'!$A$2," ",'Bundle Tag Info'!$A$3,CHAR(10),'Bundle Tag Info'!G$6,CHAR(10),'Bundle Tag Info'!G$16),"") | H11: =IF('Bundle Tag Info'!H$16<>"",CONCATENATE('Bundle Tag Info'!$A$1," ",CHAR(10),'Bundle Tag Info'!$A$2," ",'Bundle Tag Info'!$A$3,CHAR(10),'Bundle Tag Info'!H$6,CHAR(10),'Bundle Tag Info'!H$16),"") | ... AD11: =IF('Bundle Tag Info'!AD$16<>"",CONCATENATE('Bundle Tag Info'!$A$1," ",CHAR(10),'Bundle Tag Info'!$A$2," ",'Bundle Tag Info'!$A$3,CHAR(10),'Bundle Tag Info'!AD$6,CHAR(10),'Bundle Tag Info'!AD$16),"")
A12: =IF('Bundle Tag Info'!A$17<>"",CONCATENATE('Bundle Tag Info'!$A$1," ",CHAR(10),'Bundle Tag Info'!$A$2," ",'Bundle Tag Info'!$A$3,CHAR(10),'Bundle Tag Info'!A$6,CHAR(10),'Bundle Tag Info'!A$17),"") | B12: =IF('Bundle Tag Info'!B$17<>"",CONCATENATE('Bundle Tag Info'!$A$1," ",CHAR(10),'Bundle Tag Info'!$A$2," ",'Bundle Tag Info'!$A$3,CHAR(10),'Bundle Tag Info'!B$6,CHAR(10),'Bundle Tag Info'!B$17),"") | C12: =IF('Bundle Tag Info'!C$17<>"",CONCATENATE('Bundle Tag Info'!$A$1," ",CHAR(10),'Bundle Tag Info'!$A$2," ",'Bundle Tag Info'!$A$3,CHAR(10),'Bundle Tag Info'!C$6,CHAR(10),'Bundle Tag Info'!C$17),"") | D12: =IF('Bundle Tag Info'!D$17<>"",CONCATENATE('Bundle Tag Info'!$A$1," ",CHAR(10),'Bundle Tag Info'!$A$2," ",'Bundle Tag Info'!$A$3,CHAR(10),'Bundle Tag Info'!D$6,CHAR(10),'Bundle Tag Info'!D$17),"") | E12: =IF('Bundle Tag Info'!E$17<>"",CONCATENATE('Bundle Tag Info'!$A$1," ",CHAR(10),'Bundle Tag Info'!$A$2," ",'Bundle Tag Info'!$A$3,CHAR(10),'Bundle Tag Info'!E$6,CHAR(10),'Bundle Tag Info'!E$17),"") | F12: =IF('Bundle Tag Info'!F$17<>"",CONCATENATE('Bundle Tag Info'!$A$1," ",CHAR(10),'Bundle Tag Info'!$A$2," ",'Bundle Tag Info'!$A$3,CHAR(10),'Bundle Tag Info'!F$6,CHAR(10),'Bundle Tag Info'!F$17),"") | G12: =IF('Bundle Tag Info'!G$17<>"",CONCATENATE('Bundle Tag Info'!$A$1," ",CHAR(10),'Bundle Tag Info'!$A$2," ",'Bundle Tag Info'!$A$3,CHAR(10),'Bundle Tag Info'!G$6,CHAR(10),'Bundle Tag Info'!G$17),"") | H12: =IF('Bundle Tag Info'!H$17<>"",CONCATENATE('Bundle Tag Info'!$A$1," ",CHAR(10),'Bundle Tag Info'!$A$2," ",'Bundle Tag Info'!$A$3,CHAR(10),'Bundle Tag Info'!H$6,CHAR(10),'Bundle Tag Info'!H$17),"") | ... AD12: =IF('Bundle Tag Info'!AD$17<>"",CONCATENATE('Bundle Tag Info'!$A$1," ",CHAR(10),'Bundle Tag Info'!$A$2," ",'Bundle Tag Info'!$A$3,CHAR(10),'Bundle Tag Info'!AD$6,CHAR(10),'Bundle Tag Info'!AD$17),"")
A13: =IF('Bundle Tag Info'!A$18<>"",CONCATENATE('Bundle Tag Info'!$A$1," ",CHAR(10),'Bundle Tag Info'!$A$2," ",'Bundle Tag Info'!$A$3,CHAR(10),'Bundle Tag Info'!A$6,CHAR(10),'Bundle Tag Info'!A$18),"") | B13: =IF('Bundle Tag Info'!B$18<>"",CONCATENATE('Bundle Tag Info'!$A$1," ",CHAR(10),'Bundle Tag Info'!$A$2," ",'Bundle Tag Info'!$A$3,CHAR(10),'Bundle Tag Info'!B$6,CHAR(10),'Bundle Tag Info'!B$18),"") | C13: =IF('Bundle Tag Info'!C$18<>"",CONCATENATE('Bundle Tag Info'!$A$1," ",CHAR(10),'Bundle Tag Info'!$A$2," ",'Bundle Tag Info'!$A$3,CHAR(10),'Bundle Tag Info'!C$6,CHAR(10),'Bundle Tag Info'!C$18),"") | D13: =IF('Bundle Tag Info'!D$18<>"",CONCATENATE('Bundle Tag Info'!$A$1," ",CHAR(10),'Bundle Tag Info'!$A$2," ",'Bundle Tag Info'!$A$3,CHAR(10),'Bundle Tag Info'!D$6,CHAR(10),'Bundle Tag Info'!D$18),"") | E13: =IF('Bundle Tag Info'!E$18<>"",CONCATENATE('Bundle Tag Info'!$A$1," ",CHAR(10),'Bundle Tag Info'!$A$2," ",'Bundle Tag Info'!$A$3,CHAR(10),'Bundle Tag Info'!E$6,CHAR(10),'Bundle Tag Info'!E$18),"") | F13: =IF('Bundle Tag Info'!F$18<>"",CONCATENATE('Bundle Tag Info'!$A$1," ",CHAR(10),'Bundle Tag Info'!$A$2," ",'Bundle Tag Info'!$A$3,CHAR(10),'Bundle Tag Info'!F$6,CHAR(10),'Bundle Tag Info'!F$18),"") | G13: =IF('Bundle Tag Info'!G$18<>"",CONCATENATE('Bundle Tag Info'!$A$1," ",CHAR(10),'Bundle Tag Info'!$A$2," ",'Bundle Tag Info'!$A$3,CHAR(10),'Bundle Tag Info'!G$6,CHAR(10),'Bundle Tag Info'!G$18),"") | H13: =IF('Bundle Tag Info'!H$18<>"",CONCATENATE('Bundle Tag Info'!$A$1," ",CHAR(10),'Bundle Tag Info'!$A$2," ",'Bundle Tag Info'!$A$3,CHAR(10),'Bundle Tag Info'!H$6,CHAR(10),'Bundle Tag Info'!H$18),"") | ... AD13: =IF('Bundle Tag Info'!AD$18<>"",CONCATENATE('Bundle Tag Info'!$A$1," ",CHAR(10),'Bundle Tag Info'!$A$2," ",'Bundle Tag Info'!$A$3,CHAR(10),'Bundle Tag Info'!AD$6,CHAR(10),'Bundle Tag Info'!AD$18),"")
A14: =IF('Bundle Tag Info'!A$19<>"",CONCATENATE('Bundle Tag Info'!$A$1," ",CHAR(10),'Bundle Tag Info'!$A$2," ",'Bundle Tag Info'!$A$3,CHAR(10),'Bundle Tag Info'!A$6,CHAR(10),'Bundle Tag Info'!A$19),"") | B14: =IF('Bundle Tag Info'!B$19<>"",CONCATENATE('Bundle Tag Info'!$A$1," ",CHAR(10),'Bundle Tag Info'!$A$2," ",'Bundle Tag Info'!$A$3,CHAR(10),'Bundle Tag Info'!B$6,CHAR(10),'Bundle Tag Info'!B$19),"") | C14: =IF('Bundle Tag Info'!C$19<>"",CONCATENATE('Bundle Tag Info'!$A$1," ",CHAR(10),'Bundle Tag Info'!$A$2," ",'Bundle Tag Info'!$A$3,CHAR(10),'Bundle Tag Info'!C$6,CHAR(10),'Bundle Tag Info'!C$19),"") | D14: =IF('Bundle Tag Info'!D$19<>"",CONCATENATE('Bundle Tag Info'!$A$1," ",CHAR(10),'Bundle Tag Info'!$A$2," ",'Bundle Tag Info'!$A$3,CHAR(10),'Bundle Tag Info'!D$6,CHAR(10),'Bundle Tag Info'!D$19),"") | E14: =IF('Bundle Tag Info'!E$19<>"",CONCATENATE('Bundle Tag Info'!$A$1," ",CHAR(10),'Bundle Tag Info'!$A$2," ",'Bundle Tag Info'!$A$3,CHAR(10),'Bundle Tag Info'!E$6,CHAR(10),'Bundle Tag Info'!E$19),"") | F14: =IF('Bundle Tag Info'!F$19<>"",CONCATENATE('Bundle Tag Info'!$A$1," ",CHAR(10),'Bundle Tag Info'!$A$2," ",'Bundle Tag Info'!$A$3,CHAR(10),'Bundle Tag Info'!F$6,CHAR(10),'Bundle Tag Info'!F$19),"") | G14: =IF('Bundle Tag Info'!G$19<>"",CONCATENATE('Bundle Tag Info'!$A$1," ",CHAR(10),'Bundle Tag Info'!$A$2," ",'Bundle Tag Info'!$A$3,CHAR(10),'Bundle Tag Info'!G$6,CHAR(10),'Bundle Tag Info'!G$19),"") | H14: =IF('Bundle Tag Info'!H$19<>"",CONCATENATE('Bundle Tag Info'!$A$1," ",CHAR(10),'Bundle Tag Info'!$A$2," ",'Bundle Tag Info'!$A$3,CHAR(10),'Bundle Tag Info'!H$6,CHAR(10),'Bundle Tag Info'!H$19),"") | ... AD14: =IF('Bundle Tag Info'!AD$19<>"",CONCATENATE('Bundle Tag Info'!$A$1," ",CHAR(10),'Bundle Tag Info'!$A$2," ",'Bundle Tag Info'!$A$3,CHAR(10),'Bundle Tag Info'!AD$6,CHAR(10),'Bundle Tag Info'!AD$19),"")
A15: =IF('Bundle Tag Info'!A$20<>"",CONCATENATE('Bundle Tag Info'!$A$1," ",CHAR(10),'Bundle Tag Info'!$A$2," ",'Bundle Tag Info'!$A$3,CHAR(10),'Bundle Tag Info'!A$6,CHAR(10),'Bundle Tag Info'!A$20),"") | B15: =IF('Bundle Tag Info'!B$20<>"",CONCATENATE('Bundle Tag Info'!$A$1," ",CHAR(10),'Bundle Tag Info'!$A$2," ",'Bundle Tag Info'!$A$3,CHAR(10),'Bundle Tag Info'!B$6,CHAR(10),'Bundle Tag Info'!B$20),"") | C15: =IF('Bundle Tag Info'!C$20<>"",CONCATENATE('Bundle Tag Info'!$A$1," ",CHAR(10),'Bundle Tag Info'!$A$2," ",'Bundle Tag Info'!$A$3,CHAR(10),'Bundle Tag Info'!C$6,CHAR(10),'Bundle Tag Info'!C$20),"") | D15: =IF('Bundle Tag Info'!D$20<>"",CONCATENATE('Bundle Tag Info'!$A$1," ",CHAR(10),'Bundle Tag Info'!$A$2," ",'Bundle Tag Info'!$A$3,CHAR(10),'Bundle Tag Info'!D$6,CHAR(10),'Bundle Tag Info'!D$20),"") | E15: =IF('Bundle Tag Info'!E$20<>"",CONCATENATE('Bundle Tag Info'!$A$1," ",CHAR(10),'Bundle Tag Info'!$A$2," ",'Bundle Tag Info'!$A$3,CHAR(10),'Bundle Tag Info'!E$6,CHAR(10),'Bundle Tag Info'!E$20),"") | F15: =IF('Bundle Tag Info'!F$20<>"",CONCATENATE('Bundle Tag Info'!$A$1," ",CHAR(10),'Bundle Tag Info'!$A$2," ",'Bundle Tag Info'!$A$3,CHAR(10),'Bundle Tag Info'!F$6,CHAR(10),'Bundle Tag Info'!F$20),"") | G15: =IF('Bundle Tag Info'!G$20<>"",CONCATENATE('Bundle Tag Info'!$A$1," ",CHAR(10),'Bundle Tag Info'!$A$2," ",'Bundle Tag Info'!$A$3,CHAR(10),'Bundle Tag Info'!G$6,CHAR(10),'Bundle Tag Info'!G$20),"") | H15: =IF('Bundle Tag Info'!H$20<>"",CONCATENATE('Bundle Tag Info'!$A$1," ",CHAR(10),'Bundle Tag Info'!$A$2," ",'Bundle Tag Info'!$A$3,CHAR(10),'Bundle Tag Info'!H$6,CHAR(10),'Bundle Tag Info'!H$20),"") | ... AD15: =IF('Bundle Tag Info'!AD$20<>"",CONCATENATE('Bundle Tag Info'!$A$1," ",CHAR(10),'Bundle Tag Info'!$A$2," ",'Bundle Tag Info'!$A$3,CHAR(10),'Bundle Tag Info'!AD$6,CHAR(10),'Bundle Tag Info'!AD$20),"")
A16: =IF('Bundle Tag Info'!A$21<>"",CONCATENATE('Bundle Tag Info'!$A$1," ",CHAR(10),'Bundle Tag Info'!$A$2," ",'Bundle Tag Info'!$A$3,CHAR(10),'Bundle Tag Info'!A$6,CHAR(10),'Bundle Tag Info'!A$21),"") | B16: =IF('Bundle Tag Info'!B$21<>"",CONCATENATE('Bundle Tag Info'!$A$1," ",CHAR(10),'Bundle Tag Info'!$A$2," ",'Bundle Tag Info'!$A$3,CHAR(10),'Bundle Tag Info'!B$6,CHAR(10),'Bundle Tag Info'!B$21),"") | C16: =IF('Bundle Tag Info'!C$21<>"",CONCATENATE('Bundle Tag Info'!$A$1," ",CHAR(10),'Bundle Tag Info'!$A$2," ",'Bundle Tag Info'!$A$3,CHAR(10),'Bundle Tag Info'!C$6,CHAR(10),'Bundle Tag Info'!C$21),"") | D16: =IF('Bundle Tag Info'!D$21<>"",CONCATENATE('Bundle Tag Info'!$A$1," ",CHAR(10),'Bundle Tag Info'!$A$2," ",'Bundle Tag Info'!$A$3,CHAR(10),'Bundle Tag Info'!D$6,CHAR(10),'Bundle Tag Info'!D$21),"") | E16: =IF('Bundle Tag Info'!E$21<>"",CONCATENATE('Bundle Tag Info'!$A$1," ",CHAR(10),'Bundle Tag Info'!$A$2," ",'Bundle Tag Info'!$A$3,CHAR(10),'Bundle Tag Info'!E$6,CHAR(10),'Bundle Tag Info'!E$21),"") | F16: =IF('Bundle Tag Info'!F$21<>"",CONCATENATE('Bundle Tag Info'!$A$1," ",CHAR(10),'Bundle Tag Info'!$A$2," ",'Bundle Tag Info'!$A$3,CHAR(10),'Bundle Tag Info'!F$6,CHAR(10),'Bundle Tag Info'!F$21),"") | G16: =IF('Bundle Tag Info'!G$21<>"",CONCATENATE('Bundle Tag Info'!$A$1," ",CHAR(10),'Bundle Tag Info'!$A$2," ",'Bundle Tag Info'!$A$3,CHAR(10),'Bundle Tag Info'!G$6,CHAR(10),'Bundle Tag Info'!G$21),"") | H16: =IF('Bundle Tag Info'!H$21<>"",CONCATENATE('Bundle Tag Info'!$A$1," ",CHAR(10),'Bundle Tag Info'!$A$2," ",'Bundle Tag Info'!$A$3,CHAR(10),'Bundle Tag Info'!H$6,CHAR(10),'Bundle Tag Info'!H$21),"") | ... AD16: =IF('Bundle Tag Info'!AD$21<>"",CONCATENATE('Bundle Tag Info'!$A$1," ",CHAR(10),'Bundle Tag Info'!$A$2," ",'Bundle Tag Info'!$A$3,CHAR(10),'Bundle Tag Info'!AD$6,CHAR(10),'Bundle Tag Info'!AD$21),"")
