Workbook

Sheet Blue Labels
A1: (SHT 1) JB70 | B1: (SHT 10) GENERATOR PANEL | C1: (SHT 11) MEDIA CONVERTER | D1: (SHT 2) LEFT SIDE RAIL^JB70 | E1: (SHT 3) RIGHT SIDE RAIL^JB70 | F1: (SHT 4) PLC PANEL^JB70 | G1: (SHT 5) TURBINE PANEL A^JB70 | H1: (SHT 6) TURBINE PANEL B^JB70 | I1: (SHT 8) LEFT SIDE RAIL^JB72 | J1: (SHT 9) RIGHT SIDE RAIL^JB72
A2: UV0170 | B2: FU0113 | C2: GR1123 | D2: AT0178 | E2: FU1100 | F2: UV0600 | G2: FU0080 | H2: XT0240 | I2: FU0332 | J2: AF0184
A3: AT0170 | B3: XT0130 | C3: BA0005 | D3: AT0176 | E3: XTFGB | F3: AT0600 | G3: XT0080 | H3: FU0070 | I3: FU0333 | J3: AF0183
A4: HA0472 | B4: FU0313 | C4: BA0006 | D4: AT0175 | E4: GR1100 | F4: AP0601 | G4: XT0081 | H4: FU0071 | I4: FU0334 | J4: AF0182
A5: HL0171 | B5: FU0314 | C5: FU0005 | D5: KA0172 | F5: AP0602 | G5: XT0085 | H5: AU0070 | I5: FU0335 | J5: AF0181
A6: HL0172 | B6: XT0360 | C6: FU0006 | D6: KA0174 | F6: AP0603 | G6: AU0080 | H6: AF0071 | I6: FU0120 | J6: AU0180
A7: HL0173 | B7: XT0370 | C7: XT0003 | D7: KA0176 | F7: AP0604 | G7: AF0081 | H7: AF0072 | I7: FU0121 | J7: GR0180
A8: SA0170 | B8: FU0180 | C8: GR1125 | D8: KA0178 | F8: AP0605 | G8: AF0082 | H8: AF0073 | I8: FU0122
A9: SB0170 | B9: FU0181 | C9: IEG1123 | D9: KA0875 | F9: AP0606 | G9: AF0083 | H9: AF0074 | I9: KA2162
A10: AT1100 | B10: FU0182 | D10: KA6510 | F10: AP0607 | G10: AF0084 | H10: AF0075 | I10: XT0120
A11: SB0471 | B11: FU0183 | D11: KA6511 | F11: AP0608 | G11: AF0085 | H11: AF0076 | I11: AU0120
A12: SB0473 | B12: FU0184 | D12: FU0170 | F12: AP0609 | G12: AF0086 | H12: AF0077 | I12: AF0121
A13: SB0474 | B13: FU0185 | D13: XT0170 | F13: AR0600 | G13: AF0087 | H13: FU0009 | I13: AF0122
A14: SA0471 | B14: XTFGC | D14: XT0171 | F14: XT0001 | G14: XT0136 | H14: BA0009 | I14: AF0123
A15: SA0473 | B15: GR0110 | D15: XT0172 | F15: FU0001 | G15: XT0137 | H15: KA0222 | I15: GR0120
A16: SH0470 | B16: KA0121 | D16: XTFGA | F16: FU0002 | G16: XT0050 | H16: KA0124
A17: SB0472 | B17: KA0123 | D17: GR0170 | F17: BA0002 | G17: GR0134 | H17: XT0089
A18: SA0472 | B18: KA0128 | F18: BA0001 | G18: AU0090 | H18: GR0233
A19: SH0471 | B19: KA0310 | F19: AT0680 | G19: AF0091 | H19: KA0235
A20: SH0472 | B20: KA0330 | F20: FU0680 | G20: AF0092 | H20: KA0236
B21: KA0331 | F21: XT0680 | G21: AF0093 | H21: KA0237
B22: KA0332 | F22: GR0234 | G22: AF0094 | H22: KA0238
B23: KA0333 | G23: AF0095 | H23: KA0239
B24: KA0335 | G24: KA1440 | H24: KA0240
B25: KA0336 | G25: KA1441 | H25: KA0248
B26: XT0332 | G26: KA1442 | H26: KA0250
B27: XT0334 | G27: KA1443 | H27: KA0241
B28: XT0335 | G28: KA0130 | H28: KA0242
B29: XT0336 | G29: KA0131 | H29: KA0243
B30: XT0337 | G30: KA0132 | H30: KA0244
B31: GR0140 | G31: KA0141 | H31: KA0246
B32: IEG0130 | G32: KA0133 | H32: KA0247
B33: AF0400 | G33: KA0134 | H33: KA0245
B34: AF0410 | G34: KA0144 | H34: KA0249
... B67: AT0140 | G67: XT0071 | H67: XT0291
G68: FU0116 | H68: FU0291
G69: GR0131 | H69: UV0291
G70: FU0011 | H70: GR0231
G71: FU0012 | H71: UA1200
G72: FU0013 | H72: IEG0230
...

Sheet White Labels
A1: (SHT 10) GENERATOR PANEL | B1: (SHT 10) GENERATOR PANEL - (SHT 8) LEFT SIDE RAIL^JB72 | C1: (SHT 10) GENERATOR PANEL - (SHT 9) RIGHT SIDE RAIL^JB72 | D1: (SHT 1) JB70 - (SHT 5) TURBINE PANEL A^JB70 | E1: (SHT 11) MEDIA CONVERTER | F1: (SHT 4) PLC PANEL^JB70 | G1: (SHT 4) PLC PANEL^JB70 - (SHT 6) TURBINE PANEL B^JB70 | H1: (SHT 9) RIGHT SIDE RAIL^JB72 | I1: (SHT 5) TURBINE PANEL A^JB70 | J1: (SHT 5) TURBINE PANEL A^JB70 - (SHT 6) TURBINE PANEL B^JB70 | K1: (SHT 6) TURBINE PANEL B^JB70
A2: AT0140LS(S) | B2: IEG01302 | C2: GR0180 | D2: PEG01304 | E2: GR1125 | F2: UV0600G | G2: GR0234 | H2: AF0184SH | I2: 0V | J2: GR0134 | K2: AF0064G
A3: EXCS | B3: IEG01303 | C3: IEG01305 | G3: IEG02301 | I3: AF0083G | J3: IEG02303 | K3: AF0065G
A4: GR0143 | I4: AF0084G | K4: AF0066G
A5: IEG01301 | I5: AF0085G | K5: AF0071G
A6: PEG01405 | I6: IEG023011 | K6: AF0072G
A7: PMGS | I7: IEG02302 | K7: AF0073G
A8: WC8101 | K8: AF0074G
A9: WC8102 | K9: AF0075G
A10: WC8201 | K10: GR0233
A11: WC8301 | K11: IEG02304
A12: XT04001 | K12: IEG02305
A13: XT04002 | K13: IEG02306
K14: IEG02308

Sheet Heat Shrink Labels
A1: (SHT 10) GENERATOR PANEL | B1: (SHT 1) JB70 - (SHT 2) LEFT SIDE RAIL^JB70 | C1: (SHT 2) LEFT SIDE RAIL^JB70 | D1: (SHT 6) TURBINE PANEL B^JB70
A2: WC1228 | B2: WC5018 | C2: WC5500 | D2: WC4524
A3: WC1229 | B3: WC8069 | C3: WC8066
A4: WC1230 | C4: WC8067
A5: WC1231
A6: WC1232
A7: WC1233
A8: WC1234
A9: WC1235
A10: WC4749
A11: WC8009

Sheet GENERATOR PANEL
A1: GENERATOR PANEL
A2: JB72
A3: Project # | B3: 4K911
A4: Project Name | B4: ERGON REFINING INC
A5: Revision | B5: A
A7: Controls DE | B7: A. MADDI
A8: Phone: | B8: 0
A9: Controls ME
A10: Phone:
A12: From | G12: To
A13: Device ID | B13: Cable (W) Conductor (SC) Jumper Clip (JC) | C13: Wire No. | D13: Wire ID | E13: Gauge/Size | F13: Page/Zone | G13: Device ID | H13: Location | I13: Page/Zone
A14: XT0130:3 | B14: JC | C14: 0V | D14: CLIP | E14: --- | F14: 20.A5 | G14: XT0130:2 | H14: GENERATOR PANEL | I14: 20.A5 | M14: USED
A15: XT0180:1 | B15: JC | C15: 0V | D15: CLIP | E15: --- | F15: 21.B1 | G15: XT0180:2 | H15: GENERATOR PANEL | I15: 21.B1 | M15: USED
A16: XT0336:2 | B16: JC | C16: 0V | D16: CLIP | E16: --- | F16: 19.C4 | G16: XT0336:3 | H16: GENERATOR PANEL | I16: 19.C4 | M16: USED
A17: XT0336:3 | B17: JC | C17: 0V | D17: CLIP | E17: --- | F17: 19.C4 | G17: XT0336:4 | H17: GENERATOR PANEL | I17: 19.D4 | M17: USED
A18: XT0350:2 | B18: JC | C18: CCT1(+) | D18: CLIP | E18: --- | F18: 83.A4 | G18: XT0350:1 | H18: GENERATOR PANEL | I18: 83.A4 | M18: USED
A19: XT0350:4 | B19: JC | C19: CCT1(-) | D19: CLIP | E19: --- | F19: 83.A4 | G19: XT0350:3 | H19: GENERATOR PANEL | I19: 83.A4 | M19: USED
A20: XT0351:1 | B20: JC | C20: VBUSA | D20: CLIP | E20: --- | F20: 81.B4 | G20: XT0351:2 | H20: GENERATOR PANEL | I20: 81.B4 | M20: USED
A21: XT0351:11 | B21: JC | C21: VGENC | D21: CLIP | E21: --- | F21: 81.D4 | G21: XT0351:12 | H21: GENERATOR PANEL | I21: 81.D4 | M21: USED
A22: XT0351:3 | B22: JC | C22: VBUSB | D22: CLIP | E22: --- | F22: 81.B4 | G22: XT0351:4 | H22: GENERATOR PANEL | I22: 81.B4 | M22: USED
A23: XT0351:5 | B23: JC | C23: VBUSC | D23: CLIP | E23: --- | F23: 81.B4 | G23: XT0351:6 | H23: GENERATOR PANEL | I23: 81.B4 | M23: USED
A24: XT0351:7 | B24: JC | C24: VGENA | D24: CLIP | E24: --- | F24: 81.D4 | G24: XT0351:8 | H24: GENERATOR PANEL | I24: 81.D4 | M24: USED
A25: XT0351:9 | B25: JC | C25: VGENB | D25: CLIP | E25: --- | F25: 81.D4 | G25: XT0351:10 | H25: GENERATOR PANEL | I25: 81.D4 | M25: USED
... A236: XT0336:1 | B236: WC8019 | C236: ESTOP | D236: 1 | E236: 12 | F236: 19.C4 | G236: XT0240:5 | H236: TURBINE PANEL B^JB70 | I236: 15.B3 | M236: USED
F238: SolarTools ver. 24.0.84.24712 (Jul 31, 2025)
A239: Report date: 1/9/2026 11:42 AM

Sheet JB70
A1: JB70
A3: Project # | B3: 4K911
A4: Project Name | B4: ERGON REFINING INC
A5: Revision | B5: A
A7: Controls DE | B7: A. MADDI
A8: Phone: | B8: 0
A9: Controls ME
A10: Phone:
A12: From | G12: To
A13: Device ID | B13: Cable (W) Conductor (SC) Jumper Clip (JC) | C13: Wire No. | D13: Wire ID | E13: Gauge/Size | F13: Page/Zone | G13: Device ID | H13: Location | I13: Page/Zone
A14: AT0170:1 | B14: SC | C14: UV01705 | D14: WHT | E14: 14 | F14: 11.A5 | G14: UV0170:5(+) | H14: JB70 | I14: 11.A3 | M14: USED
A15: AT0170:2 | B15: SC | C15: UV01706 | D15: WHT | E15: 14 | F15: 11.A5 | G15: UV0170:6(-) | H15: JB70 | I15: 11.A3 | M15: USED
A16: AT0170:3 | B16: SC | C16: UV01707 | D16: WHT | E16: 14 | F16: 11.A5 | G16: UV0170:7(+) | H16: JB70 | I16: 11.A3 | M16: USED
A17: AT0170:4 | B17: SC | C17: UV01708 | D17: WHT | E17: 14 | F17: 11.A5 | G17: UV0170:8(-) | H17: JB70 | I17: 11.A3 | M17: USED
A18: AT0170:GND | B18: SC | C18: AT0170G | D18: GRN/YEL | E18: 14 | F18: 11.A5 | G18: FRAME | H18: JB70 | I18: 11.B6 | M18: USED
A19: UV0170:GND | B19: SC | C19: UV0170G | D19: GRN/YEL | E19: 14 | F19: 11.A3 | G19: FRAME | H19: JB70 | I19: 11.B4 | M19: USED
A20: AT0170:11 | B20: SC | C20: SA0170B113 | D20: WHT | E20: 20 | F20: 27.A6 | G20: XT0170:11 | H20: LEFT SIDE RAIL^JB70 | I20: 27.A6 | M20: USED
A21: AT0170:12 | B21: SC | C21: SA0170B114 | D21: WHT | E21: 20 | F21: 27.A6 | G21: XT0170:12 | H21: LEFT SIDE RAIL^JB70 | I21: 27.A6 | M21: USED
A22: AT0170:25 | B22: SC | C22: AT017025 | D22: WHT | E22: 20 | F22: 11.B3 | G22: KA0172:A1 | H22: LEFT SIDE RAIL^JB70 | I22: 11.B2 | M22: USED
A23: AT0170:31 | B23: SC | C23: AT017031 | D23: WHT | E23: 20 | F23: 11.C3 | G23: KA0174:A1 | H23: LEFT SIDE RAIL^JB70 | I23: 11.C2 | M23: USED
A24: AT0170:45 | B24: SC | C24: AT017045 | D24: WHT | E24: 20 | F24: 85.D6 | G24: XT0170:5 | H24: LEFT SIDE RAIL^JB70 | I24: 85.D5 | M24: USED
A25: AT0170:46 | B25: SC | C25: AT017046 | D25: WHT | E25: 20 | F25: 85.D6 | G25: XT0170:6 | H25: LEFT SIDE RAIL^JB70 | I25: 85.D5 | M25: USED
... A74: AT1100:L1 | B74: WC0101 | C74: BA1100DEVICE | D74: ENET | E74: CABLE | F74: 31.D3 | G74: BA1100:DEVICE | H74: TURBINE PANEL B^JB70 | I74: 31.D1 | M74: USED
F76: SolarTools ver. 24.0.84.24712 (Jul 31, 2025)
A77: Report date: 1/9/2026 11:42 AM

Sheet LEFT SIDE RAIL^JB70
A1: LEFT SIDE RAIL^JB70
A3: Project # | B3: 4K911
A4: Project Name | B4: ERGON REFINING INC
A5: Revision | B5: A
A7: Controls DE | B7: A. MADDI
A8: Phone: | B8: 0
A9: Controls ME
A10: Phone:
A12: From | G12: To
A13: Device ID | B13: Cable (W) Conductor (SC) Jumper Clip (JC) | C13: Wire No. | D13: Wire ID | E13: Gauge/Size | F13: Page/Zone | G13: Device ID | H13: Location | I13: Page/Zone
A14: XT0170:1 | B14: JC | C14: FU0170 | D14: CLIP | E14: --- | F14: 11.A2 | G14: XT0170:2 | H14: LEFT SIDE RAIL^JB70 | I14: 11.A2 | M14: USED
A15: XT0170:3 | B15: JC | C15: 0V | D15: CLIP | E15: --- | F15: 11.A2 | G15: XT0170:4 | H15: LEFT SIDE RAIL^JB70 | I15: 11.A2 | M15: USED
A16: KA6510:12 | B16: SC | C16: KA651012 | D16: WHT | E16: 20 | F16: 88.A6 | G16: AT0175:11 | H16: LEFT SIDE RAIL^JB70 | I16: 88.A6 | M16: USED
A17: AT0175:14 | B17: SC | C17: AT017514 | D17: LEAD | E17: --- | F17: 88.A6 | G17: RR0175S5: -10K OHM | H17: LEFT SIDE RAIL^JB70 | I17: 88.A6 | M17: USED
A18: AT0175:15 | B18: SC | C18: AT017515 | D18: LEAD | E18: --- | F18: 88.A6 | G18: RR0175S5: -10K OHM | H18: LEFT SIDE RAIL^JB70 | I18: 88.A6 | M18: USED
A19: AT0175:17 | B19: SC | C19: VD0175A | D19: WHT | E19: 20 | F19: 27.B6 | G19: XT0171:8 | H19: LEFT SIDE RAIL^JB70 | I19: 27.B6 | M19: USED
A20: AT0175:18 | B20: SC | C20: HL0171X1 | D20: WHT | E20: 20 | F20: 27.B6 | G20: XT0171:9 | H20: LEFT SIDE RAIL^JB70 | I20: 27.B6 | M20: USED
A21: AT0175:2 | B21: SC | C21: SB017013 | D21: WHT | E21: 20 | F21: 27.B6 | G21: XT0171:5 | H21: LEFT SIDE RAIL^JB70 | I21: 27.B6 | M21: USED
A22: AT0175:20 | B22: SC | C22: VD0175I | D22: WHT | E22: 20 | F22: 27.C6 | G22: XT0171:11 | H22: LEFT SIDE RAIL^JB70 | I22: 27.C6 | M22: USED
A23: AT0175:21 | B23: SC | C23: HL0172X1 | D23: WHT | E23: 20 | F23: 27.C6 | G23: XT0171:12 | H23: LEFT SIDE RAIL^JB70 | I23: 27.C6 | M23: USED
A24: AT0175:23 | B24: SC | C24: VD0175D | D24: WHT | E24: 20 | F24: 27.C6 | G24: XT0171:14 | H24: LEFT SIDE RAIL^JB70 | I24: 27.C6 | M24: USED
A25: AT0175:24 | B25: SC | C25: HL0173X1 | D25: WHT | E25: 20 | F25: 27.C6 | G25: XT0171:15 | H25: LEFT SIDE RAIL^JB70 | I25: 27.C6 | M25: USED
... A153: XT0171:3 | B153: SC | C153: KA017621 | D153: WHT | E153: 20 | F153: 97.C5 | G153: KA0244:21 | H153: TURBINE PANEL B^JB70 | I153: 97.C5 | M153: USED
F155: SolarTools ver. 24.0.84.24712 (Jul 31, 2025)
A156: Report date: 1/9/2026 11:42 AM

Sheet LEFT SIDE RAIL^JB72
A1: LEFT SIDE RAIL^JB72
A3: Project # | B3: 4K911
A4: Project Name | B4: ERGON REFINING INC
A5: Revision | B5: A
A7: Controls DE | B7: A. MADDI
A8: Phone: | B8: 0
A9: Controls ME
A10: Phone:
A12: From | G12: To
A13: Device ID | B13: Cable (W) Conductor (SC) Jumper Clip (JC) | C13: Wire No. | D13: Wire ID | E13: Gauge/Size | F13: Page/Zone | G13: Device ID | H13: Location | I13: Page/Zone
A14: XT0120:1 | B14: JC | C14: 0V | D14: CLIP | E14: --- | F14: 20.D1 | G14: XT0120:2 | H14: LEFT SIDE RAIL^JB72 | I14: 20.D1 | M14: USED
A15: AF0122:06 | B15: SC | C15: JP1 | D15: VIO | E15: 20 | F15: 24.C7 | G15: AF0122:38 | H15: LEFT SIDE RAIL^JB72 | I15: 24.C7 | M15: USED
A16: AF0121:COM | B16: SC | C16: 0V | D16: WHT | E16: 14 | F16: 20.D2 | G16: XT0120:2 | H16: LEFT SIDE RAIL^JB72 | I16: 20.D1 | M16: USED
A17: AF0121:J | B17: SC | C17: * | F17: 20.D2 | G17: AF0122:P | H17: LEFT SIDE RAIL^JB72 | I17: 20.D3 | M17: USED
A18: AF0121:P | B18: SC | C18: * | F18: 20.D2 | G18: AU0120: | H18: LEFT SIDE RAIL^JB72 | I18: 20.C1 | M18: USED
A19: AF0121:V+ | B19: SC | C19: FU0121 | D19: WHT | E19: 14 | F19: 20.D2 | G19: FU0121:LD | H19: LEFT SIDE RAIL^JB72 | I19: 20.D1 | M19: USED
A20: AF0122:09 | B20: SC | C20: 012209 | D20: WHT | E20: 20 | F20: 26.A6 | G20: XT0120:4 | H20: LEFT SIDE RAIL^JB72 | I20: 26.A6 | M20: USED
A21: AF0122:41 | B21: SC | C21: 012241 | D21: WHT | E21: 20 | F21: 26.A6 | G21: XT0120:3 | H21: LEFT SIDE RAIL^JB72 | I21: 26.A6 | M21: USED
A22: AF0122:COM | B22: SC | C22: AF0122N | D22: WHT | E22: 20 | F22: 20.D3 | G22: AF0123:COM | H22: LEFT SIDE RAIL^JB72 | I22: 20.D3 | M22: USED
A23: AF0122:COM | B23: SC | C23: AU0120N | D23: WHT | E23: 20 | F23: 20.D3 | G23: AU0120:COM | H23: LEFT SIDE RAIL^JB72 | I23: 20.C1 | M23: USED
A24: AF0122:J | B24: SC | C24: * | F24: 20.D3 | G24: AF0123:P | H24: LEFT SIDE RAIL^JB72 | I24: 20.D3 | M24: USED
A25: AF0122:V+ | B25: SC | C25: AF0122P | D25: WHT | E25: 20 | F25: 20.D3 | G25: AF0123:V+ | H25: LEFT SIDE RAIL^JB72 | I25: 20.D3 | M25: USED
A26: AF0122:V+ | B26: SC | C26: AU0120P | D26: WHT | E26: 20 | F26: 20.D3 | G26: AU0120:V+ | H26: LEFT SIDE RAIL^JB72 | I26: 20.C1 | M26: USED
A27: AU0120:COM | B27: SC | C27: 0V | D27: WHT | E27: 14 | F27: 20.C1 | G27: XT0120:1 | H27: LEFT SIDE RAIL^JB72 | I27: 20.D1 | M27: USED
A28: AU0120:V+ | B28: SC | C28: FU0120 | D28: WHT | E28: 14 | F28: 20.C1 | G28: FU0120:LD | H28: LEFT SIDE RAIL^JB72 | I28: 20.D1 | M28: USED
A29: FU0120:LI | B29: SC | C29: FU0332 | D29: WHT | E29: 14 | F29: 20.D1 | G29: FU0121:LI | H29: LEFT SIDE RAIL^JB72 | I29: 20.D1 | M29: USED
A30: FU0332:LD | B30: SC | C30: FU0332 | D30: WHT | E30: 14 | F30: 19.B3 | G30: FU0333:LI | H30: LEFT SIDE RAIL^JB72 | I30: 19.B3 | M30: USED
A31: FU0333:LI | B31: SC | C31: FU0332 | D31: WHT | E31: 14 | F31: 19.B3 | G31: FU0334:LI | H31: LEFT SIDE RAIL^JB72 | I31: 19.B3 | M31: USED
A32: FU0334:LI | B32: SC | C32: FU0332 | D32: WHT | E32: 14 | F32: 19.B3 | G32: FU0335:LI | H32: LEFT SIDE RAIL^JB72 | I32: 19.A3 | M32: USED
A33: AF0121:01 | B33: SC | C33: 012101 | D33: WHT | E33: 20 | F33: 22.A7 | G33: KA0121:A1 | H33: GENERATOR PANEL | I33: 22.A5 | M33: USED
A34: AF0121:02 | B34: SC | C34: 012102 | D34: WHT | E34: 20 | F34: 67.A6 | G34: KA0336:21 | H34: GENERATOR PANEL | I34: 67.A5 | M34: USED
A35: AF0121:03 | B35: SC | C35: 012103 | D35: WHT | E35: 20 | F35: 22.A7 | G35: KA0123:A1 | H35: GENERATOR PANEL | I35: 22.A5 | M35: USED
A36: AF0121:08 | B36: SC | C36: 012108 | D36: WHT | E36: 20 | F36: 22.B7 | G36: KA0128:A1 | H36: GENERATOR PANEL | I36: 22.B5 | M36: USED
... A62: KA2162:A2 | B62: SC | C62: 009216 | D62: WHT | E62: 20 | F62: 100.C5 | G62: AF0092:16 | H62: TURBINE PANEL A^JB70 | I62: 100.C6 | M62: USED
F64: SolarTools ver. 24.0.84.24712 (Jul 31, 2025)
A65: Report date: 1/9/2026 11:42 AM

Sheet MEDIA CONVERTER
A1: MEDIA CONVERTER
A3: Project # | B3: 4K911
A4: Project Name | B4: ERGON REFINING INC
A5: Revision | B5: A
A7: Controls DE | B7: A. MADDI
A8: Phone: | B8: 0
A9: Controls ME
A10: Phone:
A12: From | G12: To
A13: Device ID | B13: Cable (W) Conductor (SC) Jumper Clip (JC) | C13: Wire No. | D13: Wire ID | E13: Gauge/Size | F13: Page/Zone | G13: Device ID | H13: Location | I13: Page/Zone
A14: BA0005:V1(-) | B14: SC | C14: 0V | D14: WHT | E14: 16 | F14: 3.A6 | G14: XT0003:2 | H14: MEDIA CONVERTER | I14: 3.A5 | M14: USED
A15: BA0005:V1(+) | B15: SC | C15: FU0005 | D15: WHT | E15: 16 | F15: 3.A6 | G15: FU0005:LD | H15: MEDIA CONVERTER | I15: 3.A5 | M15: USED
A16: BA0006:V1(-) | B16: SC | C16: 0V | D16: WHT | E16: 16 | F16: 3.B6 | G16: XT0003:4 | H16: MEDIA CONVERTER | I16: 3.B5 | M16: USED
A17: BA0006:V1(+) | B17: SC | C17: FU0006 | D17: WHT | E17: 16 | F17: 3.B6 | G17: FU0006:LD | H17: MEDIA CONVERTER | I17: 3.B5 | M17: USED
A18: FU0005:LI | B18: SC | C18: FU0210 | D18: WHT | E18: 16 | F18: 3.A5 | G18: XT0003:1 | H18: MEDIA CONVERTER | I18: 3.A5 | M18: USED
A19: FU0006:LI | B19: SC | C19: FU0210 | D19: WHT | E19: 16 | F19: 3.B5 | G19: XT0003:3 | H19: MEDIA CONVERTER | I19: 3.B5 | M19: USED
A20: GR1125: | B20: SC | C20: GR1125 | D20: GRN/YEL | E20: 14 | F20: 5.D4 | G20: FG1125:1 | H20: MEDIA CONVERTER | I20: 5.D4 | M20: USED
F22: SolarTools ver. 24.0.84.24712 (Jul 31, 2025)
A23: Report date: 1/9/2026 11:42 AM

Sheet PLC PANEL^JB70
A1: PLC PANEL^JB70
A3: Project # | B3: 4K911
A4: Project Name | B4: ERGON REFINING INC
A5: Revision | B5: A
A7: Controls DE | B7: A. MADDI
A8: Phone: | B8: 0
A9: Controls ME
A10: Phone:
A12: From | G12: To
A13: Device ID | B13: Cable (W) Conductor (SC) Jumper Clip (JC) | C13: Wire No. | D13: Wire ID | E13: Gauge/Size | F13: Page/Zone | G13: Device ID | H13: Location | I13: Page/Zone
A14: XT0001:3 | B14: JC | C14: FU0210 | D14: CLIP | E14: --- | F14: 3.B3 | G14: XT0001:4 | H14: PLC PANEL^JB70 | I14: 3.B3 | M14: USED
A15: XT0001:5 | B15: JC | C15: 0V | D15: CLIP | E15: --- | F15: 3.B3 | G15: XT0001:6 | H15: PLC PANEL^JB70 | I15: 3.B3 | M15: USED
A16: AR0600:IE1 | B16: SC | C16: UV0600G | D16: GRN | E16: 14 | F16: 6.A1 | G16: UV0600:GND | H16: PLC PANEL^JB70 | I16: 6.B2 | M16: USED
A17: AT0680:NEG | B17: SC | C17: 0V | D17: WHT | E17: 14 | F17: 8.B4 | G17: XT0680:2 | H17: PLC PANEL^JB70 | I17: 8.B3 | M17: USED
A18: AT0680:POS | B18: SC | C18: AT0680POS | D18: WHT | E18: 14 | F18: 8.B4 | G18: XT0680:1 | H18: PLC PANEL^JB70 | I18: 8.B3 | M18: USED
A19: BA0001:V1(-) | B19: SC | C19: 0V | D19: WHT | E19: 16 | F19: 3.A2 | G19: XT0001:2 | H19: PLC PANEL^JB70 | I19: 3.A3 | M19: USED
A20: BA0001:V1(+) | B20: SC | C20: FU0001 | D20: WHT | E20: 16 | F20: 3.A2 | G20: FU0001:LD | H20: PLC PANEL^JB70 | I20: 3.A3 | M20: USED
A21: BA0002:V1(-) | B21: SC | C21: 0V | D21: WHT | E21: 16 | F21: 3.B2 | G21: XT0001:5 | H21: PLC PANEL^JB70 | I21: 3.B3 | M21: USED
A22: BA0002:V1(+) | B22: SC | C22: FU0002 | D22: WHT | E22: 16 | F22: 3.B2 | G22: FU0002:LD | H22: PLC PANEL^JB70 | I22: 3.B3 | M22: USED
A23: FU0001:LI | B23: SC | C23: FU0210 | D23: WHT | E23: 16 | F23: 3.A3 | G23: XT0001:1 | H23: PLC PANEL^JB70 | I23: 3.A3 | M23: USED
A24: FU0002:LI | B24: SC | C24: FU0210 | D24: WHT | E24: 16 | F24: 3.B3 | G24: XT0001:4 | H24: PLC PANEL^JB70 | I24: 3.B3 | M24: USED
A25: FU0680:LD | B25: SC | C25: AT0680POS | D25: WHT | E25: 14 | F25: 8.B2 | G25: XT0680:1 | H25: PLC PANEL^JB70 | I25: 8.B3 | M25: USED
... A44: AT0680:LAN2 | B44: WC9019 | C44: BA0009RJ45 | D44: ENET | E44: CABLE | F44: 8.B4 | G44: BA0009:RJ45 | H44: TURBINE PANEL B^JB70 | I44: 4.A2 | M44: USED
F46: SolarTools ver. 24.0.84.24712 (Jul 31, 2025)
A47: Report date: 1/9/2026 11:42 AM

Sheet RIGHT SIDE RAIL^JB70
A1: RIGHT SIDE RAIL^JB70
A3: Project # | B3: 4K911
A4: Project Name | B4: ERGON REFINING INC
A5: Revision | B5: A
A7: Controls DE | B7: A. MADDI
A8: Phone: | B8: 0
A9: Controls ME
A10: Phone:
A12: From | G12: To
A13: Device ID | B13: Cable (W) Conductor (SC) Jumper Clip (JC) | C13: Wire No. | D13: Wire ID | E13: Gauge/Size | F13: Page/Zone | G13: Device ID | H13: Location | I13: Page/Zone
A14: GR1100: | B14: SC | C14: GR1100 | D14: GRN/YEL | E14: 14 | F14: 5.A5 | G14: FRAME | H14: RIGHT SIDE RAIL^JB70 | I14: 5.A4 | M14: USED
A16: Report date: 1/9/2026 11:42 AM | F16: SolarTools ver. 24.0.84.24712 (Jul 31, 2025)

Sheet RIGHT SIDE RAIL^JB72
A1: RIGHT SIDE RAIL^JB72
A3: Project # | B3: 4K911
A4: Project Name | B4: ERGON REFINING INC
A5: Revision | B5: A
A7: Controls DE | B7: A. MADDI
A8: Phone: | B8: 0
A9: Controls ME
A10: Phone:
A12: From | G12: To
A13: Device ID | B13: Cable (W) Conductor (SC) Jumper Clip (JC) | C13: Wire No. | D13: Wire ID | E13: Gauge/Size | F13: Page/Zone | G13: Device ID | H13: Location | I13: Page/Zone
A14: AF0182:01 | B14: SC | C14: JP3 | D14: VIO | E14: 20 | F14: 32.A7 | G14: AF0182:33 | H14: RIGHT SIDE RAIL^JB72 | I14: 32.A7 | M14: USED
A15: AF0182:07 | B15: SC | C15: JP4 | D15: VIO | E15: 20 | F15: 101.A7 | G15: AF0182:39 | H15: RIGHT SIDE RAIL^JB72 | I15: 101.A7 | M15: USED
A16: AF0182:15 | B16: SC | C16: JP6 | D16: VIO | E16: 20 | F16: 101.B7 | G16: AF0182:47 | H16: RIGHT SIDE RAIL^JB72 | I16: 101.B7 | M16: USED
A17: AF0181:J | B17: SC | C17: * | F17: 21.B2 | G17: AF0182:P | H17: RIGHT SIDE RAIL^JB72 | I17: 21.B3 | M17: USED
A18: AF0182:COM | B18: SC | C18: AF0182N | D18: WHT | E18: 16 | F18: 21.B3 | G18: AF0183:COM | H18: RIGHT SIDE RAIL^JB72 | I18: 21.A3 | M18: USED
A19: AF0182:J | B19: SC | C19: * | F19: 21.B3 | G19: AF0183:P | H19: RIGHT SIDE RAIL^JB72 | I19: 21.A3 | M19: USED
A20: AF0182:V+ | B20: SC | C20: AF0182P | D20: WHT | E20: 16 | F20: 21.B3 | G20: AF0183:V+ | H20: RIGHT SIDE RAIL^JB72 | I20: 21.A3 | M20: USED
A21: AF0183:COM | B21: SC | C21: AF0183N | D21: WHT | E21: 16 | F21: 21.A3 | G21: AF0184:COM | H21: RIGHT SIDE RAIL^JB72 | I21: 21.B4 | M21: USED
A22: AF0183:J | B22: SC | C22: * | F22: 21.A3 | G22: AF0184:P | H22: RIGHT SIDE RAIL^JB72 | I22: 21.B4 | M22: USED
A23: AF0183:V+ | B23: SC | C23: AF0183P | D23: WHT | E23: 16 | F23: 21.A3 | G23: AF0184:V+ | H23: RIGHT SIDE RAIL^JB72 | I23: 21.B4 | M23: USED
A24: AF0184:SH | B24: SC | C24: AF0184SH | D24: GRN | E24: 14 | F24: 21.B4 | G24: AU0180:GND | H24: RIGHT SIDE RAIL^JB72 | I24: 21.A2 | M24: USED
A25: AF0181:00 | B25: SC | C25: 018100 | D25: WHT | E25: 20 | F25: 25.A7 | G25: KA0180:A1 | H25: GENERATOR PANEL | I25: 25.A5 | M25: USED
A26: AF0181:02 | B26: SC | C26: 018102 | D26: WHT | E26: 20 | F26: 101.C7 | G26: KA0181:A1 | H26: GENERATOR PANEL | I26: 101.C5 | M26: USED
A27: AF0181:10 | B27: SC | C27: 018110 | D27: WHT | E27: 20 | F27: 25.A7 | G27: KA0185:A1 | H27: GENERATOR PANEL | I27: 25.A5 | M27: USED
A28: AF0181:16 | B28: SC | C28: 018116 | D28: WHT | E28: 20 | F28: 25.A7 | G28: KA0180:A2 | H28: GENERATOR PANEL | I28: 25.A5 | M28: USED
A29: AF0181:18 | B29: SC | C29: 018118 | D29: WHT | E29: 20 | F29: 101.C7 | G29: KA0181:A2 | H29: GENERATOR PANEL | I29: 101.C5 | M29: USED
A30: AF0181:26 | B30: SC | C30: 018126 | D30: WHT | E30: 20 | F30: 25.A7 | G30: XT0338:2 | H30: GENERATOR PANEL | I30: 25.A5 | M30: USED
A31: AF0181:COM | B31: SC | C31: 0V | D31: WHT | E31: 16 | F31: 21.B2 | G31: XT0180:2 | H31: GENERATOR PANEL | I31: 21.B1 | M31: USED
A32: AF0181:V+ | B32: SC | C32: FU0181 | D32: WHT | E32: 16 | F32: 21.B2 | G32: FU0181:LD | H32: GENERATOR PANEL | I32: 21.B1 | M32: USED
A33: AF0182:COM | B33: SC | C33: 0V | D33: WHT | E33: 16 | F33: 21.B3 | G33: XT0180:2 | H33: GENERATOR PANEL | I33: 21.B1 | M33: USED
A34: AF0182:V+ | B34: SC | C34: FU0182 | D34: WHT | E34: 16 | F34: 21.B3 | G34: FU0182:LD | H34: GENERATOR PANEL | I34: 21.B1 | M34: USED
... A40: AU0180:L2 | B40: WC0018 | C40: AU0180L2 | D40: ENET | E40: CABLE | F40: 21.A2 | G40: BA0002:RJ45 | H40: PLC PANEL^JB70 | I40: 3.B2 | M40: USED
F42: SolarTools ver. 24.0.84.24712 (Jul 31, 2025)
A43: Report date: 1/9/2026 11:42 AM

Sheet TURBINE PANEL A^JB70
A1: TURBINE PANEL A^JB70
A3: Project # | B3: 4K911
A4: Project Name | B4: ERGON REFINING INC
A5: Revision | B5: A
A7: Controls DE | B7: A. MADDI
A8: Phone: | B8: 0
A9: Controls ME
A10: Phone:
A12: From | G12: To
A13: Device ID | B13: Cable (W) Conductor (SC) Jumper Clip (JC) | C13: Wire No. | D13: Wire ID | E13: Gauge/Size | F13: Page/Zone | G13: Device ID | H13: Location | I13: Page/Zone
A14: XT0011:2 | B14: JC | C14: 523NEG | D14: CLIP | E14: --- | F14: 12.C3 | G14: XT0011:3 | H14: TURBINE PANEL A^JB70 | I14: 12.C3 | M14: USED
A15: XT0011:3 | B15: JC | C15: 523NEG | D15: CLIP | E15: --- | F15: 12.C3 | G15: XT0011:4 | H15: TURBINE PANEL A^JB70 | I15: 12.C3 | M15: USED
A16: XT0011:4 | B16: JC | C16: 523NEG | D16: CLIP | E16: --- | F16: 12.C3 | G16: XT0011:5 | H16: TURBINE PANEL A^JB70 | I16: 12.C3 | M16: USED
A17: XT0080:1 | B17: JC | C17: 0V | D17: CLIP | E17: --- | F17: 9.B1 | G17: XT0080:2 | H17: TURBINE PANEL A^JB70 | I17: 9.B1 | M17: USED
A18: XT0080:2 | B18: JC | C18: 0V | D18: CLIP | E18: --- | F18: 9.B1 | G18: XT0080:3 | H18: TURBINE PANEL A^JB70 | I18: 9.B1 | M18: USED
A19: XT0081:1 | B19: JC | C19: 0V | D19: CLIP | E19: --- | F19: 9.D1 | G19: XT0081:2 | H19: TURBINE PANEL A^JB70 | I19: 9.D1 | M19: USED
A20: XT0134:1 | B20: JC | C20: 0V | D20: CLIP | E20: --- | F20: 13.B3 | G20: XT0134:2 | H20: TURBINE PANEL A^JB70 | I20: 13.B3 | M20: USED
A21: XT0134:2 | B21: JC | C21: 0V | D21: CLIP | E21: --- | F21: 13.B3 | G21: XT0134:3 | H21: TURBINE PANEL A^JB70 | I21: 13.B3 | M21: USED
A22: XT0134:3 | B22: JC | C22: 0V | D22: CLIP | E22: --- | F22: 13.B3 | G22: XT0134:4 | H22: TURBINE PANEL A^JB70 | I22: 13.B3 | M22: USED
A23: XT0135:1 | B23: JC | C23: 0V | D23: CLIP | E23: --- | F23: 13.B4 | G23: XT0135:2 | H23: TURBINE PANEL A^JB70 | I23: 13.B4 | M23: USED
A24: XT0135:2 | B24: JC | C24: 0V | D24: CLIP | E24: --- | F24: 13.B4 | G24: XT0135:3 | H24: TURBINE PANEL A^JB70 | I24: 13.B4 | M24: USED
A25: XT0135:3 | B25: JC | C25: 0V | D25: CLIP | E25: --- | F25: 13.B4 | G25: XT0135:4 | H25: TURBINE PANEL A^JB70 | I25: 13.C4 | M25: USED
... A39: AF0082:COM | B39: SC | C39: AF0082N | D39: WHT | E39: 16 | F39: 9.B3 | G39: AF0083:COM | H39: TURBINE PANEL A^JB70 | I39: 9.B3 | M39: USED
A40: AF0082:J | B40: SC | C40: * | F40: 9.B3 | G40: AF0083:P | H40: TURBINE PANEL A^JB70 | I40: 9.B3 | M40: USED
A41: AF0082:V+ | B41: SC | C41: AF0082P | D41: WHT | E41: 16 | F41: 9.B3 | G41: AF0083:V+ | H41: TURBINE PANEL A^JB70 | I41: 9.B3 | M41: USED
A42: AF0083:COM | B42: SC | C42: AF0083N | D42: WHT | E42: 16 | F42: 9.B3 | G42: AF0084:COM | H42: TURBINE PANEL A^JB70 | I42: 9.B4 | M42: USED
A43: AF0083:J | B43: SC | C43: * | F43: 9.B3 | G43: AF0084:P | H43: TURBINE PANEL A^JB70 | I43: 9.B4 | M43: USED
A44: AF0083:SH | B44: SC | C44: AF0083G | D44: GRN | E44: 14 | F44: 9.B3 | G44: AF0084:SH | H44: TURBINE PANEL A^JB70 | I44: 9.B4 | M44: USED
A45: AF0083:SH | B45: SC | C45: IEG023011 | D45: GRN | E45: 14 | F45: 9.B3 | G45: AU0080:GND | H45: TURBINE PANEL A^JB70 | I45: 9.A1 | M45: USED
A46: AF0083:V+ | B46: SC | C46: AF0083P | D46: WHT | E46: 16 | F46: 9.B3 | G46: AF0084:V+ | H46: TURBINE PANEL A^JB70 | I46: 9.B4 | M46: USED
A47: AF0084:COM | B47: SC | C47: AF0084N | D47: WHT | E47: 16 | F47: 9.B4 | G47: AF0085:COM | H47: TURBINE PANEL A^JB70 | I47: 9.B4 | M47: USED
A48: AF0084:J | B48: SC | C48: * | F48: 9.B4 | G48: AF0085:P | H48: TURBINE PANEL A^JB70 | I48: 9.B4 | M48: USED
A49: AF0084:SH | B49: SC | C49: AF0084G | D49: GRN | E49: 14 | F49: 9.B4 | G49: AF0085:SH | H49: TURBINE PANEL A^JB70 | I49: 9.B4 | M49: USED
A50: AF0084:V+ | B50: SC | C50: AF0084P | D50: WHT | E50: 16 | F50: 9.B4 | G50: AF0085:V+ | H50: TURBINE PANEL A^JB70 | I50: 9.B4 | M50: USED
A51: AF0085:COM | B51: SC | C51: AF0085N | D51: WHT | E51: 16 | F51: 9.B4 | G51: AF0086:COM | H51: TURBINE PANEL A^JB70 | I51: 9.B5 | M51: USED
A52: AF0085:J | B52: SC | C52: * | F52: 9.B4 | G52: AF0086:P | H52: TURBINE PANEL A^JB70 | I52: 9.B5 | M52: USED
A53: AF0085:SH | B53: SC | C53: AF0085G | D53: GRN | E53: 14 | F53: 9.B4 | G53: AF0086:SH | H53: TURBINE PANEL A^JB70 | I53: 9.B5 | M53: USED
A54: AF0085:V+ | B54: SC | C54: AF0085P | D54: WHT | E54: 16 | F54: 9.B4 | G54: AF0086:V+ | H54: TURBINE PANEL A^JB70 | I54: 9.B5 | M54: USED
A55: AF0086:28 | B55: SC | C55: 0V | D55: WHT | E55: 14 | F55: 58.C7 | G55: XT0050:2 | H55: TURBINE PANEL A^JB70 | I55: 58.C5 | M55: USED
A56: AF0086:COM | B56: SC | C56: AF0086N | D56: WHT | E56: 16 | F56: 9.B5 | G56: AF0087:COM | H56: TURBINE PANEL A^JB70 | I56: 9.B6 | M56: USED
...

Sheet TURBINE PANEL B^JB70
A1: TURBINE PANEL B^JB70
A3: Project # | B3: 4K911
A4: Project Name | B4: ERGON REFINING INC
A5: Revision | B5: A
A7: Controls DE | B7: A. MADDI
A8: Phone: | B8: 0
A9: Controls ME
A10: Phone:
A12: From | G12: To
A13: Device ID | B13: Cable (W) Conductor (SC) Jumper Clip (JC) | C13: Wire No. | D13: Wire ID | E13: Gauge/Size | F13: Page/Zone | G13: Device ID | H13: Location | I13: Page/Zone
A14: XT0060:1 | B14: JC | C14: 0V | D14: CLIP | E14: --- | F14: 10.D1 | G14: XT0060:2 | H14: TURBINE PANEL B^JB70 | I14: 10.D1 | M14: USED
A15: XT0233:1 | B15: JC | C15: FU0210 | D15: CLIP | E15: --- | F15: 13.C4 | G15: XT0233:2 | H15: TURBINE PANEL B^JB70 | I15: 13.C4 | M15: USED
A16: XT0233:2 | B16: JC | C16: FU0210 | D16: CLIP | E16: --- | F16: 13.C4 | G16: XT0233:3 | H16: TURBINE PANEL B^JB70 | I16: 13.C4 | M16: USED
A17: XT0235:1 | B17: JC | C17: 0V | D17: CLIP | E17: --- | F17: 13.D4 | G17: XT0235:2 | H17: TURBINE PANEL B^JB70 | I17: 13.D4 | M17: USED
A18: XT0235:2 | B18: JC | C18: 0V | D18: CLIP | E18: --- | F18: 13.D4 | G18: XT0235:3 | H18: TURBINE PANEL B^JB70 | I18: 13.D4 | M18: USED
A19: XT0240:11 | B19: JC | C19: FU0139 | D19: CLIP | E19: --- | F19: 15.C4 | G19: XT0240:12 | H19: TURBINE PANEL B^JB70 | I19: 15.C4 | M19: USED
A20: XT0240:9 | B20: JC | C20: 0V | D20: CLIP | E20: --- | F20: 15.D3 | G20: XT0240:10 | H20: TURBINE PANEL B^JB70 | I20: 15.D3 | M20: USED
A21: KA0233:14 | B21: SC | C21: 006102 | D21: WHT | E21: 20 | F21: 36.B7 | G21: AF0061:02 | H21: TURBINE PANEL B^JB70 | I21: 36.B5 | M21: USED
A22: KA0234:14 | B22: SC | C22: 006114 | D22: WHT | E22: 20 | F22: 37.B7 | G22: AF0061:14 | H22: TURBINE PANEL B^JB70 | I22: 37.B5 | M22: USED
A23: AF0061:COM | B23: SC | C23: 0V | D23: WHT | E23: 14 | F23: 10.C2 | G23: XT0060:2 | H23: TURBINE PANEL B^JB70 | I23: 10.D1 | M23: USED
A24: AF0061:J | B24: SC | C24: * | F24: 10.C2 | G24: AF0062:P | H24: TURBINE PANEL B^JB70 | I24: 10.C3 | M24: USED
A25: AF0061:V+ | B25: SC | C25: FU0061 | D25: WHT | E25: 14 | F25: 10.C2 | G25: FU0061:LD | H25: TURBINE PANEL B^JB70 | I25: 10.D1 | M25: USED
A26: KA0222:14 | B26: SC | C26: 006200 | D26: WHT | E26: 20 | F26: 53.A7 | G26: AF0062:00 | H26: TURBINE PANEL B^JB70 | I26: 53.A6 | M26: USED
A27: AF0062:16 | B27: SC | C27: SV21242 | D27: WHT | E27: 20 | F27: 53.A7 | G27: XT0060:5 | H27: TURBINE PANEL B^JB70 | I27: 53.A5 | M27: USED
A28: AF0062:COM | B28: SC | C28: 0V | D28: WHT | E28: 14 | F28: 10.C3 | G28: XT0060:2 | H28: TURBINE PANEL B^JB70 | I28: 10.D1 | M28: USED
A29: AF0062:J | B29: SC | C29: * | F29: 10.C3 | G29: AF0063:P | H29: TURBINE PANEL B^JB70 | I29: 10.C3 | M29: USED
A30: AF0062:V+ | B30: SC | C30: FU0062 | D30: WHT | E30: 14 | F30: 10.C3 | G30: FU0062:LD | H30: TURBINE PANEL B^JB70 | I30: 10.D1 | M30: USED
A31: AF0063:COM | B31: SC | C31: AF0063N | D31: WHT | E31: 16 | F31: 10.C3 | G31: AF0064:COM | H31: TURBINE PANEL B^JB70 | I31: 10.C4 | M31: USED
A32: AF0063:COM | B32: SC | C32: AU0060N | D32: WHT | E32: 16 | F32: 10.C3 | G32: AU0060:COM | H32: TURBINE PANEL B^JB70 | I32: 10.C2 | M32: USED
A33: AF0063:J | B33: SC | C33: * | F33: 10.C3 | G33: AF0064:P | H33: TURBINE PANEL B^JB70 | I33: 10.C4 | M33: USED
A34: AF0063:V+ | B34: SC | C34: AF0063P | D34: WHT | E34: 16 | F34: 10.C3 | G34: AF0064:V+ | H34: TURBINE PANEL B^JB70 | I34: 10.C4 | M34: USED
A35: AF0063:V+ | B35: SC | C35: AU0060P | D35: WHT | E35: 16 | F35: 10.C3 | G35: AU0060:V+ | H35: TURBINE PANEL B^JB70 | I35: 10.C2 | M35: USED
A36: AF0064:COM | B36: SC | C36: AF0064N | D36: WHT | E36: 16 | F36: 10.C4 | G36: AF0065:COM | H36: TURBINE PANEL B^JB70 | I36: 10.C5 | M36: USED
A37: AF0064:J | B37: SC | C37: * | F37: 10.C4 | G37: AF0065:P | H37: TURBINE PANEL B^JB70 | I37: 10.C5 | M37: USED
A38: AF0064:SH | B38: SC | C38: AF0064G | D38: GRN | E38: 14 | F38: 10.C4 | G38: AF0065:SH | H38: TURBINE PANEL B^JB70 | I38: 10.C5 | M38: USED
A39: AF0064:SH | B39: SC | C39: IEG02304 | D39: GRN | E39: 14 | F39: 10.C4 | G39: AU0060:GND | H39: TURBINE PANEL B^JB70 | I39: 10.C2 | M39: USED
A40: AF0064:V+ | B40: SC | C40: AF0064P | D40: WHT | E40: 16 | F40: 10.C4 | G40: AF0065:V+ | H40: TURBINE PANEL B^JB70 | I40: 10.C5 | M40: USED
A41: AF0065:COM | B41: SC | C41: AF0065N | D41: WHT | E41: 16 | F41: 10.C5 | G41: AF0068:COM | H41: TURBINE PANEL B^JB70 | I41: 10.C6 | M41: USED
A42: AF0065:J | B42: SC | C42: * | F42: 10.C5 | G42: AF0066:P | H42: TURBINE PANEL B^JB70 | I42: 10.C5 | M42: USED
A43: AF0065:SH | B43: SC | C43: AF0065G | D43: GRN | E43: 14 | F43: 10.C5 | G43: AF0066:SH | H43: TURBINE PANEL B^JB70 | I43: 10.C5 | M43: USED
...

Sheet Panel Errors
A1: Panel Errors
A3: Project # | B3: 4K911
A4: Project Name | B4: ERGON REFINING INC
A5: Revision | B5: A
A7: Controls DE | B7: A. MADDI
A8: Phone: | B8: 0
A9: Controls ME
A10: Phone:
A12: From | H12: To
A13: Device ID | B13: Location | C13: Cable (W) Conductor (SC) Jumper Clip (JC) | D13: Wire ID | E13: Wire No. | F13: Gauge/Size | G13: Page/Zone | H13: Device ID | I13: Location | J13: Page/Zone
A16: Report date: 1/9/2026 11:42 AM | E16: SolarTools ver. 24.0.84.24712 (Jul 31, 2025)

Sheet Cable Part Numbers
A1: Cable Part Numbers | D1: SolarTools ver. 24.0.84.24712 (Jul 31, 2025)
A2: Project # | B2: 4K911
D3: Report date: 1/9/2026 11:43 AM
A4: Project Name | B4: ERGON REFINING INC
A6: Revision | B6: A
A8: Controls DE | B8: A. MADDI
A9: Phone: | B9: 0
A10: Controls ME
A11: Phone:
A13: Device ID | C13: Part Number | E13: Description
A14: WC5072 | C14: PART OF 1103208-100 | E14: CABLE, 2 CONDUCTOR UNSHIELDED PART OF HORN
A16: WC0001 | C16: 1302073-36 | E16: CABLE, ETHERNET - 36 INCHES
A17: WC0003 | C17: 1302073-36 | E17: CABLE, ETHERNET - 36 INCHES
A18: WC0007 | C18: 1302073-36 | E18: CABLE, ETHERNET - 36 INCHES
A19: WC0008 | C19: 1302073-36 | E19: CABLE, ETHERNET - 36 INCHES
A20: WC0009 | C20: 1302073-36 | E20: CABLE, ETHERNET - 36 INCHES
A21: WC0010 | C21: 1302073-36 | E21: CABLE, ETHERNET - 36 INCHES
A22: WC0012 | C22: 1302073-36 | E22: CABLE, ETHERNET - 36 INCHES
A23: WC0014 | C23: 1302073-36 | E23: CABLE, ETHERNET - 36 INCHES
A24: WC0041 | C24: 1302073-36 | E24: CABLE, COMMUNICATION CABLE - 36 INCHES
A25: WC0042 | C25: 1302073-36 | E25: CABLE, COMMUNICATION CABLE - 36 INCHES
... A56: WC9019 | C56: 1302073-36 | E56: CABLE, ETHERNET - 36 INCHES

Sheet Part Number List
A1: Part Number List | C1: SolarTools ver. 24.0.84.24712 (Jul 31, 2025)
A2: Project # | B2: 4K911
C3: Report date: 1/9/2026 11:43 AM
A4: Project Name | B4: ERGON REFINING INC
A6: Revision | B6: A
A8: Controls DE | B8: A. MADDI
A9: Phone: | B9: 0
A10: Controls ME
A11: Phone:
A13: Device ID | B13: Part Number | C13: Description | D13: Location
A14: CCAT0170 | B14: CUSTOMER DEFINED | C14: CUSTOMER CONNECTION, TROUBLE ALARM SIGNAL | D14: CUSTOMER FIRE AND GAS SIGNALS
A15: CCKA0982 | B15: CUSTOMER DEFINED | C15: CUSTOMER CONNECTION, FIRE DETECTED SIGNAL | D15: CUSTOMER FIRE AND GAS SIGNALS
A16: CCKA0984 | B16: CUSTOMER DEFINED | C16: CUSTOMER CONNECTION, GAS DETECTED SIGNAL | D16: CUSTOMER FIRE AND GAS SIGNALS
A18: CCKA2160 | B18: CUSTOMER DEFINED | C18: CUSTOMER CONNECTION, CLOSE GAS BLOCK VALVE | D18: GAS FUEL BLOCK BLEED VALVE
A19: CCKA2161 | B19: CUSTOMER DEFINED | C19: CUSTOMER CONNECTION, OPEN GAS BLEED VALVE | D19: GAS FUEL BLOCK BLEED VALVE
A21: AF0400 | B21: 1322418-31,1322418-40,1322418-72,1322418-73 | C21: 1444-TSCX02-02RB, 2-CH TACHOMETER INPUT^DYNAMIX 1444 VIBRATION | D21: GENERATOR PANEL
A22: AF0410 | B22: 1322418-11,1322418-20,1322418-70,1322418-71 | C22: 1444-DYN04-01RA, 4-CH VIBRATION INPUT^DYNAMIX 1444 VIBRATION | D22: GENERATOR PANEL
A23: AF0420 | B23: 1322418-11,1322418-20,1322418-70,1322418-71 | C23: 1444-DYN04-01RA, 4-CH VIBRATION INPUT^DYNAMIX 1444 VIBRATION | D23: GENERATOR PANEL
A24: AF0440 | B24: 1322418-11,1322418-20,1322418-70,1322418-71 | C24: 1444-DYN04-01RA, 4-CH VIBRATION INPUT^DYNAMIX 1444 VIBRATION | D24: GENERATOR PANEL
A25: AF0450 | B25: 1322418-11,1322418-20,1322418-70,1322418-71 | C25: 1444-DYN04-01RA, 4-CH VIBRATION INPUT^DYNAMIX 1444 VIBRATION | D25: GENERATOR PANEL
A26: AT0140 | B26: 2769310-1,2769310-4 | C26: MODULE, DESC-250 | D26: GENERATOR PANEL
... A344: XT0291 | B344: 1066730-7 | C344: TERMINAL BLOCK, SPRING, 4 CONDUCTOR,30-12 AWG (0.05-3.31 MM2),NON-IS | D344: TURBINE PANEL B^JB70

Sheet JB70_S
A1: JB70
A3: Project # | B3: 4K911
A4: Project Name | B4: ERGON REFINING INC
A5: Revision | B5: A
A7: Controls DE | B7: A. MADDI
A8: Phone: | B8: 0
A9: Controls ME
A10: Phone:
A12: From | G12: To
A13: Device ID | B13: Wire No. | C13: Wire ID | D13: Gauge/Size | E13: Length | F13: Device ID | G13: Location | H13: Bundle Name
A14: AT1100:NEG | B14: -0V | C14: WHT | D14: 14 | E14: 220 | F14: XT0291:2 | G14: B PANEL | H14: AT1100
A15: AT1100:POS | B15: FU1100 | C15: WHT | D15: 14 | E15: 160 | F15: FU1100:LD | G15: JB70 RIGHT RAIL
A17: AT0170:1 | B17: UV01705 | C17: WHT | D17: 14 | E17: 60 | F17: UV0170:5(+) | G17: JB70 | H17: AT0170
A18: AT0170:2 | B18: UV01706 | C18: WHT | D18: 14 | E18: 60 | F18: UV0170:6(-) | G18: JB70
A19: AT0170:3 | B19: UV01707 | C19: WHT | D19: 14 | E19: 60 | F19: UV0170:7(+) | G19: JB70
A20: AT0170:4 | B20: UV01708 | C20: WHT | D20: 14 | E20: 60 | F20: UV0170:8(-) | G20: JB70
A22: SA0472:B1-13 | B22: SA0472B113 | C22: WHT | D22: 20 | E22: 240 | F22: AF0091:47 | G22: A PANEL | H22: SA0472
A23: SA0472:B1-14 | B23: SA0472B114 | C23: WHT | D23: 20 | E23: 240 | F23: AF0091:15 | G23: A PANEL
A24: SA0472:B2-13 | B24: SA0472B213 | C24: WHT | D24: 20 | E24: 240 | F24: AF0091:46 | G24: A PANEL
A25: SA0472:B2-14 | B25: SA0472B214 | C25: WHT | D25: 20 | E25: 240 | F25: AF0091:14 | G25: A PANEL
A27: SA0473:14 | B27: SA0473B-B1 | C27: WHT | D27: 20 | E27: 240 | F27: AF0087:14 | G27: A PANEL | H27: SA0473
A28: SA0473:13 | B28: SA0473B-B2 | C28: WHT | D28: 20 | E28: 240 | F28: AF0087:46 | G28: A PANEL
A29: SA0473:12 | B29: SA0473W-B1 | C29: WHT | D29: 20 | E29: 240 | F29: AF0087:13 | G29: A PANEL
A30: SA0473:11 | B30: SA0473W-B2 | C30: WHT | D30: 20 | E30: 240 | F30: AF0087:45 | G30: A PANEL
A32: SB0472:B1-12 | B32: ESTOP | C32: WHT | D32: 20 | E32: 240 | F32: XT0137:2 | G32: A PANEL | H32: SB0472
A33: SB0472:B1-11 | B33: ESTOPA | C33: WHT | D33: 20 | E33: 240 | F33: XT0137:1 | G33: A PANEL
A34: SB0472:B2-11 | B34: SB0472B211 | C34: WHT | D34: 20 | E34: 240 | F34: AF0081:36 | G34: A PANEL
A35: SB0472:B2-12 | B35: SB0472B212 | C35: WHT | D35: 20 | E35: 240 | F35: AF0081:04 | G35: A PANEL
A37: SA0471:B1-13 | B37: SA0471B113 | C37: WHT | D37: 20 | E37: 240 | F37: AF0087:40 | G37: A PANEL | H37: SA0471
A38: SA0471:B1-14 | B38: SA0471B114 | C38: WHT | D38: 20 | E38: 240 | F38: AF0087:08 | G38: A PANEL
A39: SA0471:B2-13 | B39: SA0471B213 | C39: WHT | D39: 20 | E39: 240 | F39: AF0087:39 | G39: A PANEL
A40: SA0471:B2-14 | B40: SA0471B214 | C40: WHT | D40: 20 | E40: 240 | F40: AF0087:07 | G40: A PANEL
A42: SB0471:11 | B42: SB047111 | C42: WHT | D42: 20 | E42: 240 | F42: AF0087:34 | G42: A PANEL | H42: SB0471
A43: SB0471:12 | B43: SB047112 | C43: WHT | D43: 20 | E43: 240 | F43: AF0087:02 | G43: A PANEL
A45: SB0473:13 | B45: SB047313 | C45: WHT | D45: 20 | E45: 240 | F45: AF0087:35 | G45: A PANEL | H45: SB0473
A46: SB0473:14 | B46: SB047314 | C46: WHT | D46: 20 | E46: 240 | F46: AF0087:03 | G46: A PANEL
A48: SB0474:13 | B48: SB047413 | C48: WHT | D48: 20 | E48: 240 | F48: AF0087:36 | G48: A PANEL | H48: SB0474
A49: SB0474:14 | B49: SB047414 | C49: WHT | D49: 20 | E49: 240 | F49: AF0087:04 | G49: A PANEL
A51: SH0470:11 | B51: SH047011 | C51: WHT | D51: 20 | E51: 240 | F51: AF0087:33 | G51: A PANEL | H51: SH0470
A52: SH0470:12 | B52: SH047012 | C52: WHT | D52: 20 | E52: 240 | F52: AF0087:01 | G52: A PANEL
...

Sheet LEFT SIDE RAIL^JB70_S
A1: LEFT SIDE RAIL^JB70
A3: Project # | B3: 4K911
A4: Project Name | B4: ERGON REFINING INC
A5: Revision | B5: A
A7: Controls DE | B7: A. MADDI
A8: Phone: | B8: 0
A9: Controls ME
A10: Phone:
A12: From | G12: To
A13: Device ID | B13: Wire No. | C13: Wire ID | D13: Gauge/Size | E13: Length | F13: Device ID | G13: Location | H13: Bundle Name
A14: AT0175:18 | B14: HL0171X1 | C14: WHT | D14: 20 | E14: 120 | F14: XT0171:9 | G14: LEFT SIDE RAIL^JB70 | H14: AT0175
A15: AT0175:21 | B15: HL0172X1 | C15: WHT | D15: 20 | E15: 120 | F15: XT0171:12 | G15: LEFT SIDE RAIL^JB70
A16: AT0175:24 | B16: HL0173X1 | C16: WHT | D16: 20 | E16: 120 | F16: XT0171:15 | G16: LEFT SIDE RAIL^JB70
A17: AT0175:2 | B17: SB017013 | C17: WHT | D17: 20 | E17: 120 | F17: XT0171:5 | G17: LEFT SIDE RAIL^JB70
A18: AT0175:3 | B18: SB017014 | C18: WHT | D18: 20 | E18: 120 | F18: XT0171:6 | G18: LEFT SIDE RAIL^JB70
A19: AT0175:17 | B19: VD0175A | C19: WHT | D19: 20 | E19: 120 | F19: XT0171:8 | G19: LEFT SIDE RAIL^JB70
A20: AT0175:23 | B20: VD0175D | C20: WHT | D20: 20 | E20: 120 | F20: XT0171:14 | G20: LEFT SIDE RAIL^JB70
A21: AT0175:20 | B21: VD0175I | C21: WHT | D21: 20 | E21: 120 | F21: XT0171:11 | G21: LEFT SIDE RAIL^JB70
A23: AT0176:4P1 | B23: AT01764P1 | C23: WHT | D23: 14 | E23: 60 | F23: AT0178:1P1 | G23: LEFT SIDE RAIL^JB70 | H23: AT0176
A24: AT0176:5P1 | B24: AT01765P1 | C24: WHT | D24: 14 | E24: 60 | F24: AT0178:2P1 | G24: LEFT SIDE RAIL^JB70
A26: AT0178:24 | B26: KA0178A2 | C26: WHT | D26: 20 | E26: 120 | F26: XT0170:17 | G26: LEFT SIDE RAIL^JB70 | H26: AT0178
A27: AT0178:23 | B27: VD0178 | C27: WHT | D27: 20 | E27: 120 | F27: XT0170:16 | G27: LEFT SIDE RAIL^JB70
A28: AT0178:20 | B28: ZS61P | C28: WHT | D28: 20 | E28: 120 | F28: XT0170:24 | G28: LEFT SIDE RAIL^JB70
A29: AT0178:21 | B29: ZS61S | C29: WHT | D29: 20 | E29: 120 | F29: XT0170:25 | G29: LEFT SIDE RAIL^JB70
A31: KA0178:A1 | B31: KA0178A1 | C31: WHT | D31: 20 | E31: 100 | F31: XT0170:15 | G31: LEFT SIDE RAIL^JB70 | H31: KA A1/A2
A33: KA0172:A2 | B33: -0V | C33: WHT | D33: 20 | E33: 100 | F33: XT0170:4 | G33: LEFT SIDE RAIL^JB70
A34: KA0176:A2 | B34: -0V | C34: WHT | D34: 20 | E34: 100 | F34: XT0170:3 | G34: LEFT SIDE RAIL^JB70
A35: KA0178:A2 | B35: KA0178A2 | C35: WHT | D35: 20 | E35: 100 | F35: XT0170:17 | G35: LEFT SIDE RAIL^JB70
A36: KA6510:A2 | B36: KA6510A2 | C36: WHT | D36: 20 | E36: 140 | F36: AT0175:5P1 | G36: LEFT SIDE RAIL^JB70
A38: KA0875:14 | B38: FU0170 | C38: WHT | D38: 20 | E38: 60 | F38: XT0170:1 | G38: LEFT SIDE RAIL^JB70 | H38: KA
A39: KA0875:11 | B39: HA04722 | C39: WHT | D39: 20 | E39: 60 | F39: KA0178:11 | G39: LEFT SIDE RAIL^JB70
A40: KA0875:11 | B40: HA04722 | C40: WHT | D40: 20 | E40: 60 | F40: XT0170:13 | G40: LEFT SIDE RAIL^JB70
A41: KA0172:11 | B41: KA017211 | C41: WHT | D41: 20 | E41: 60 | F41: XT0170:7 | G41: LEFT SIDE RAIL^JB70
A42: KA0172:12 | B42: KA017212 | C42: WHT | D42: 20 | E42: 60 | F42: XT0170:8 | G42: LEFT SIDE RAIL^JB70
A43: KA0174:11 | B43: KA017411 | C43: WHT | D43: 20 | E43: 60 | F43: XT0170:9 | G43: LEFT SIDE RAIL^JB70
A44: KA0174:12 | B44: KA017412 | C44: WHT | D44: 20 | E44: 60 | F44: XT0170:10 | G44: LEFT SIDE RAIL^JB70
A45: KA0176:11 | B45: KA017611 | C45: WHT | D45: 20 | E45: 60 | F45: XT0171:1 | G45: LEFT SIDE RAIL^JB70
A46: KA0176:21 | B46: KA017621 | C46: WHT | D46: 20 | E46: 60 | F46: XT0171:3 | G46: LEFT SIDE RAIL^JB70
A47: KA6510:12 | B47: KA651012 | C47: WHT | D47: 20 | E47: 140 | F47: AT0175:11 | G47: LEFT SIDE RAIL^JB70
A48: KA6511:22 | B48: KA651122 | C48: WHT | D48: 20 | E48: 140 | F48: AT0176:17 | G48: LEFT SIDE RAIL^JB70
...

Sheet PLC PANEL^JB70_S
A1: PLC PANEL^JB70
A3: Project # | B3: 4K911
A4: Project Name | B4: ERGON REFINING INC
A5: Revision | B5: A
A7: Controls DE | B7: A. MADDI
A8: Phone: | B8: 0
A9: Controls ME
A10: Phone:
A12: From | G12: To
A13: Device ID | B13: Wire No. | C13: Wire ID | D13: Gauge/Size | E13: Length | F13: Device ID | G13: Location | H13: Bundle Name
A14: BA0001:V1(-) | B14: -0V | C14: WHT | D14: 16 | E14: 60 | F14: XT0001:2 | G14: PLC PANEL | H14: BA
A15: BA0002:V1(-) | B15: -0V | C15: WHT | D15: 16 | E15: 60 | F15: XT0001:5 | G15: PLC PANEL
A16: BA0001:V1(+) | B16: FU0001 | C16: WHT | D16: 16 | E16: 60 | F16: FU0001:LD | G16: PLC PANEL
A17: BA0002:V1(+) | B17: FU0002 | C17: WHT | D17: 16 | E17: 60 | F17: FU0002:LD | G17: PLC PANEL
A19: AT0680:NEG | B19: -0V | C19: WHT | D19: 14 | E19: 60 | F19: XT0680:2 | G19: PLC PANEL | H19: AT0680
A20: AT0680:POS | B20: AT0680POS | C20: WHT | D20: 14 | E20: 60 | F20: XT0680:1 | G20: PLC PANEL
A22: FU0001:LI | B22: FU0210 | C22: WHT | D22: 16 | E22: 60 | F22: XT0001:1 | G22: PLC PANEL | H22: FU
A23: FU0002:LI | B23: FU0210 | C23: WHT | D23: 16 | E23: 60 | F23: XT0001:4 | G23: PLC PANEL
A25: FU0680:LD | B25: AT0680POS | C25: WHT | D25: 14 | E25: 60 | F25: XT0680:1 | G25: PLC PANEL
A27: UV0600:(-) | B27: -0V | C27: WHT | D27: 14 | E27: 120 | F27: XT0135:1 | G27: A PANEL | H27: UV-A
A28: UV0600:(+) | B28: FU0010 | C28: WHT | D28: 14 | E28: 120 | F28: FU0010:LD | G28: A PANEL
A30: FU0680:LI | B30: FU0210 | C30: WHT | D30: 14 | E30: 120 | F30: XT0233:3 | G30: B PANEL | H30: FU/XT-B
A32: XT0001:6 | B32: -0V | C32: WHT | D32: 16 | E32: 120 | F32: XT0005:2 | G32: B PANEL
A33: XT0001:3 | B33: FU0210 | C33: WHT | D33: 16 | E33: 120 | F33: XT0005:1 | G33: B PANEL
A35: XT0680:2 | B35: -0V | C35: WHT | D35: 14 | E35: 120 | F35: XT0235:3 | G35: B PANEL
A37: XT0001:2 | B37: -0V | C37: WHT | D37: 12 | E37: 120 | F37: XT0235:3 | G37: B PANEL
A38: XT0001:5 | B38: -0V | C38: WHT | D38: 12 | E38: 120 | F38: XT0235:3 | G38: B PANEL
A39: XT0001:1 | B39: FU0210 | C39: WHT | D39: 12 | E39: 120 | F39: XT0233:3 | G39: B PANEL
A40: XT0001:4 | B40: FU0210 | C40: WHT | D40: 12 | E40: 120 | F40: XT0233:3 | G40: B PANEL

Sheet TURBINE PANEL A^JB70_S
A1: TURBINE PANEL A^JB70
A3: Project # | B3: 4K911
A4: Project Name | B4: ERGON REFINING INC
A5: Revision | B5: A
A7: Controls DE | B7: A. MADDI
A8: Phone: | B8: 0
A9: Controls ME
A10: Phone:
A12: From | G12: To
A13: Device ID | B13: Wire No. | C13: Wire ID | D13: Gauge/Size | E13: Length | F13: Device ID | G13: Location | H13: Bundle Name
A14: PC0470:INP_A | B14: -009312 | C14: WHT | D14: 20 | E14: 60 | F14: AF0093:12 | G14: A PANEL | H14: PC0470
A15: PC0470:-PWR | B15: -009328 | C15: WHT | D15: 20 | E15: 60 | F15: AF0093:28 | G15: A PANEL
A16: PC0470:+PWR | B16: -009344 | C16: WHT | D16: 20 | E16: 60 | F16: AF0093:44 | G16: A PANEL
A18: AU0080:COM | B18: -0V | C18: WHT | D18: 14 | E18: 60 | F18: XT0080:1 | G18: A PANEL | H18: AU
A19: AU0090:COM | B19: -0V | C19: WHT | D19: 14 | E19: 60 | F19: XT0081:1 | G19: A PANEL
A20: AU0080:V+ | B20: FU0080 | C20: WHT | D20: 14 | E20: 60 | F20: FU0080:LD | G20: A PANEL
A21: AU0090:V+ | B21: FU0090 | C21: WHT | D21: 14 | E21: 60 | F21: FU0090:LD | G21: A PANEL
A23: AF0094:05 | B23: -0V | C23: WHT | D23: 20 | E23: 60 | F23: XT0135:4 | G23: A PANEL | H23: AF
A24: AF0094:07 | B24: -0V | C24: WHT | D24: 20 | E24: 60 | F24: XT0135:4 | G24: A PANEL
A26: AF0092:COM | B26: -0V | C26: WHT | D26: 14 | E26: 80 | F26: XT0081:1 | G26: A PANEL
A27: AF0093:COM | B27: -0V | C27: WHT | D27: 14 | E27: 80 | F27: XT0081:2 | G27: A PANEL
A28: AF0095:COM | B28: -0V | C28: WHT | D28: 14 | E28: 80 | F28: XT0081:2 | G28: A PANEL
A29: AF0091:COM | B29: AF0091N | C29: WHT | D29: 14 | E29: 60 | F29: AF0094:COM | G29: A PANEL
A30: AF0091:V+ | B30: AF0091P | C30: WHT | D30: 14 | E30: 60 | F30: AF0094:V+ | G30: A PANEL
A31: AF0092:V+ | B31: FU0091 | C31: WHT | D31: 14 | E31: 60 | F31: FU0091:LD | G31: A PANEL
A32: AF0093:V+ | B32: FU0092 | C32: WHT | D32: 14 | E32: 60 | F32: FU0092:LD | G32: A PANEL
A33: AF0095:V+ | B33: FU0093 | C33: WHT | D33: 14 | E33: 60 | F33: FU0093:LD | G33: A PANEL
A35: AF0086:28 | B35: -0V | C35: WHT | D35: 14 | E35: 60 | F35: XT0050:2 | G35: A PANEL
A37: KA0130:A1 | B37: -008135 | C37: WHT | D37: 20 | E37: 80 | F37: AF0081:35 | G37: A PANEL | H37: KA A1
A38: KA0130:A1 | B38: -008135 | C38: WHT | D38: 20 | E38: 100 | F38: KA0130:11 | G38: A PANEL
A39: KA2160:A1 | B39: -009204 | C39: WHT | D39: 20 | E39: 60 | F39: AF0092:04 | G39: A PANEL
A40: KA2161:A1 | B40: -009207 | C40: WHT | D40: 20 | E40: 60 | F40: AF0092:07 | G40: A PANEL
A41: KA3103:A1 | B41: -009208 | C41: WHT | D41: 20 | E41: 80 | F41: AF0092:08 | G41: A PANEL
A42: KA0133:A1 | B42: KA0133A1 | C42: WHT | D42: 20 | E42: 60 | F42: AF0092:02 | G42: A PANEL
A43: KA0134:A1 | B43: KA0134A1 | C43: WHT | D43: 20 | E43: 60 | F43: AF0091:12 | G43: A PANEL
A44: KA0135:A1 | B44: KA0135A1 | C44: WHT | D44: 20 | E44: 60 | F44: KA0144:A1 | G44: A PANEL
A45: KA0137:A1 | B45: KA0137A1 | C45: WHT | D45: 20 | E45: 60 | F45: KT0142:18 | G45: A PANEL
A46: KA0131:A1 | B46: KA0231A1 | C46: WHT | D46: 20 | E46: 120 | F46: XT0136:10 | G46: A PANEL
A47: KA0136:A1 | B47: PS32002 | C47: WHT | D47: 20 | E47: 120 | F47: XT0136:5 | G47: A PANEL
A49: KA2160:A2 | B49: -009220 | C49: WHT | D49: 20 | E49: 60 | F49: AF0092:20 | G49: A PANEL | H49: KA A2
...

Sheet TURBINE PANEL B^JB70_S
A1: TURBINE PANEL B^JB70
A3: Project # | B3: 4K911
A4: Project Name | B4: ERGON REFINING INC
A5: Revision | B5: A
A7: Controls DE | B7: A. MADDI
A8: Phone: | B8: 0
A9: Controls ME
A10: Phone:
A12: From | G12: To
A13: Device ID | B13: Wire No. | C13: Wire ID | D13: Gauge/Size | E13: Length | F13: Device ID | G13: Location | H13: Bundle Name
A14: AU0060:COM | B14: -0V | C14: WHT | D14: 14 | E14: 60 | F14: XT0060:1 | G14: B PANEL | H14: AU
A15: AU0070:COM | B15: -0V | C15: WHT | D15: 14 | E15: 60 | F15: XT0070:1 | G15: B PANEL
A16: AU0060:V+ | B16: FU0060 | C16: WHT | D16: 14 | E16: 80 | F16: FU0060:LD | G16: B PANEL
A17: AU0070:V+ | B17: FU0070 | C17: WHT | D17: 14 | E17: 60 | F17: FU0070:LD | G17: B PANEL
A19: AF0062:16 | B19: SV21242 | C19: WHT | D19: 20 | E19: 60 | F19: XT0060:5 | G19: B PANEL | H19: AF0060'S
A21: AF0065:COM | B21: AF0065N | C21: WHT | D21: 16 | E21: 60 | F21: AF0068:COM | G21: B PANEL
A22: AF0065:V+ | B22: AF0065P | C22: WHT | D22: 16 | E22: 60 | F22: AF0068:V+ | G22: B PANEL
A23: AF0063:COM | B23: AU0060N | C23: WHT | D23: 16 | E23: 60 | F23: AU0060:COM | G23: B PANEL
A24: AF0063:V+ | B24: AU0060P | C24: WHT | D24: 16 | E24: 60 | F24: AU0060:V+ | G24: B PANEL
A25: AF0066:V+ | B25: FU0063 | C25: WHT | D25: 16 | E25: 60 | F25: FU0063:LD | G25: B PANEL
A26: AF0067:V+ | B26: FU0064 | C26: WHT | D26: 16 | E26: 60 | F26: FU0064:LD | G26: B PANEL
A28: AF0061:COM | B28: -0V | C28: WHT | D28: 14 | E28: 60 | F28: XT0060:2 | G28: B PANEL
A29: AF0062:COM | B29: -0V | C29: WHT | D29: 14 | E29: 60 | F29: XT0060:2 | G29: B PANEL
A30: AF0066:COM | B30: -0V | C30: WHT | D30: 14 | E30: 60 | F30: XT0060:2 | G30: B PANEL
A31: AF0067:COM | B31: -0V | C31: WHT | D31: 14 | E31: 60 | F31: XT0060:2 | G31: B PANEL
A32: AF0061:V+ | B32: FU0061 | C32: WHT | D32: 14 | E32: 60 | F32: FU0061:LD | G32: B PANEL
A33: AF0062:V+ | B33: FU0062 | C33: WHT | D33: 14 | E33: 60 | F33: FU0062:LD | G33: B PANEL
A35: AF0074:05 | B35: -007405 | C35: WHT | D35: 20 | E35: 60 | F35: XT0089:2 | G35: B PANEL | H35: AF0070'S
A36: AF0076:12 | B36: -007612 | C36: WHT | D36: 20 | E36: 100 | F36: XT0237:1 B2 | G36: B PANEL
A37: AF0074:21 | B37: -0V | C37: WHT | D37: 20 | E37: 60 | F37: XT0089:3 | G37: B PANEL
A39: AF0075:COM | B39: AF0075N | C39: WHT | D39: 16 | E39: 60 | F39: AF0077:COM | G39: B PANEL
A40: AF0075:V+ | B40: AF0075P | C40: WHT | D40: 16 | E40: 60 | F40: AF0077:V+ | G40: B PANEL
A42: AF0076:COM | B42: -0V | C42: WHT | D42: 14 | E42: 60 | F42: XT0070:1 | G42: B PANEL
A43: AF0076:V+ | B43: FU0071 | C43: WHT | D43: 14 | E43: 60 | F43: FU0071:LD | G43: B PANEL
A45: KA0222:A1 | B45: -007604 | C45: WHT | D45: 20 | E45: 60 | F45: AF0076:04 | G45: B PANEL | H45: KA A1
A46: KA1020:A1 | B46: -007608 | C46: WHT | D46: 20 | E46: 100 | F46: AF0076:08 | G46: B PANEL
A47: KA0124:A1 | B47: -007609 | C47: WHT | D47: 20 | E47: 60 | F47: AF0076:09 | G47: B PANEL
A48: KA0235:A1 | B48: ESTOP | C48: WHT | D48: 20 | E48: 60 | F48: XT0240:4 | G48: B PANEL
A49: KA0241:A1 | B49: KA0241A1 | C49: WHT | D49: 20 | E49: 80 | F49: XT0240:6 | G49: B PANEL
A50: KA0243:A1 | B50: KA0243A1 | C50: WHT | D50: 20 | E50: 80 | F50: XT0240:7 | G50: B PANEL
...

Sheet LEFT SIDE RAIL^JB72_S
A1: LEFT SIDE RAIL^JB72
A3: Project # | B3: 4K911
A4: Project Name | B4: ERGON REFINING INC
A5: Revision | B5: A
A7: Controls DE | B7: A. MADDI
A8: Phone: | B8: 0
A9: Controls ME
A10: Phone:
A12: From | G12: To
A13: Device ID | B13: Wire No. | C13: Wire ID | D13: Gauge/Size | E13: Length | F13: Device ID | G13: Location | H13: Bundle Name
A14: AF0122:09 | B14: -012209 | C14: WHT | D14: 20 | E14: 60 | F14: XT0120:4 | G14: JB72 L/RAIL | H14: AF/FU
A15: AF0122:41 | B15: -012241 | C15: WHT | D15: 20 | E15: 60 | F15: XT0120:3 | G15: JB72 L/RAIL
A16: AU0120:COM | B16: -0V | C16: WHT | D16: 14 | E16: 60 | F16: XT0120:1 | G16: JB72 L/RAIL
A17: AF0121:COM | B17: -0V | C17: WHT | D17: 14 | E17: 60 | F17: XT0120:2 | G17: JB72 L/RAIL
A18: AF0122:COM | B18: AU0120N | C18: WHT | D18: 20 | E18: 60 | F18: AU0120:COM | G18: JB72 L/RAIL
A19: AF0122:V+ | B19: AU0120P | C19: WHT | D19: 20 | E19: 60 | F19: AU0120:V+ | G19: JB72 L/RAIL
A20: AU0120:V+ | B20: FU0120 | C20: WHT | D20: 14 | E20: 60 | F20: FU0120:LD | G20: JB72 L/RAIL
A21: AF0121:V+ | B21: FU0121 | C21: WHT | D21: 14 | E21: 60 | F21: FU0121:LD | G21: JB72 L/RAIL
A23: FU0332:LD | B23: FU0332 | C23: WHT | D23: 14 | E23: 60 | F23: FU0333:LI | G23: JB72 L/RAIL
A25: AF0121:01 | B25: -012101 | C25: WHT | D25: 20 | E25: 160 | F25: KA0121:A1 | G25: GENERATOR PANEL | H25: AF-GEN
A26: AF0121:02 | B26: -012102 | C26: WHT | D26: 20 | E26: 160 | F26: KA0336:21 | G26: GENERATOR PANEL
A27: AF0121:03 | B27: -012103 | C27: WHT | D27: 20 | E27: 160 | F27: KA0123:A1 | G27: GENERATOR PANEL
A28: AF0121:08 | B28: -012108 | C28: WHT | D28: 20 | E28: 160 | F28: KA0128:A1 | G28: GENERATOR PANEL
A29: AF0121:14 | B29: -012114 | C29: WHT | D29: 20 | E29: 160 | F29: KA0336:11 | G29: GENERATOR PANEL
A30: AF0121:17 | B30: -012117 | C30: WHT | D30: 20 | E30: 160 | F30: KA0121:A2 | G30: GENERATOR PANEL
A31: AF0121:18 | B31: -012118 | C31: WHT | D31: 20 | E31: 160 | F31: KA4300:A2 | G31: GENERATOR PANEL
A32: AF0121:19 | B32: -012119 | C32: WHT | D32: 20 | E32: 160 | F32: KA0123:A2 | G32: GENERATOR PANEL
A33: AF0121:24 | B33: -012124 | C33: WHT | D33: 20 | E33: 160 | F33: KA0128:A2 | G33: GENERATOR PANEL
A34: AF0121:30 | B34: -012130 | C34: WHT | D34: 20 | E34: 160 | F34: KA4100:A2 | G34: GENERATOR PANEL
A35: AF0122:00 | B35: -012200 | C35: WHT | D35: 20 | E35: 160 | F35: KA0330:11 | G35: GENERATOR PANEL
A36: AF0122:01 | B36: -012201 | C36: WHT | D36: 20 | E36: 160 | F36: KA0331:11 | G36: GENERATOR PANEL
A37: AF0122:02 | B37: -012202 | C37: WHT | D37: 20 | E37: 160 | F37: KA0310:11 | G37: GENERATOR PANEL
... A40: AF0122:34 | B40: -012234 | C40: WHT | D40: 20 | E40: 160 | F40: KA0310:14 | G40: GENERATOR PANEL
A42: FU0333:LD | B42: FU0333 | C42: WHT | D42: 16 | E42: 160 | F42: XT0335:1 | G42: GENERATOR PANEL | H42: FU/XT-GEN
A44: FU0120:LI | B44: FU0332 | C44: WHT | D44: 14 | E44: 160 | F44: XT0130:1 | G44: GENERATOR PANEL
A45: FU0332:LD | B45: FU0332 | C45: WHT | D45: 14 | E45: 160 | F45: XT0130:1 | G45: GENERATOR PANEL
A46: FU0335:LI | B46: FU0332 | C46: WHT | D46: 14 | E46: 160 | F46: FU0113:LI | G46: GENERATOR PANEL
A47: FU0334:LD | B47: FU0334 | C47: WHT | D47: 14 | E47: 160 | F47: XT0335:2 | G47: GENERATOR PANEL
A48: FU0335:LD | B48: FU0335 | C48: WHT | D48: 14 | E48: 160 | F48: XT0335:3 | G48: GENERATOR PANEL
A50: FU0332:LI | B50: FU0136 | C50: WHT | D50: 12 | E50: 160 | F50: XT0332:1 | G50: GENERATOR PANEL
...

Sheet RIGHT SIDE RAIL^JB72_S
A1: RIGHT SIDE RAIL^JB72
A3: Project # | B3: 4K911
A4: Project Name | B4: ERGON REFINING INC
A5: Revision | B5: A
A7: Controls DE | B7: A. MADDI
A8: Phone: | B8: 0
A9: Controls ME
A10: Phone:
A12: From | G12: To
A13: Device ID | B13: Wire No. | C13: Wire ID | D13: Gauge/Size | E13: Length | F13: Device ID | G13: Location | H13: Bundle Name
A14: AF0181:00 | B14: -018100 | C14: WHT | D14: 20 | E14: 160 | F14: KA0180:A1 | G14: GENERATOR PANEL | H14: AF-GEN
A15: AF0181:02 | B15: -018102 | C15: WHT | D15: 20 | E15: 160 | F15: KA0181:A1 | G15: GENERATOR PANEL
A16: AF0181:10 | B16: -018110 | C16: WHT | D16: 20 | E16: 160 | F16: KA0185:A1 | G16: GENERATOR PANEL
A17: AF0181:16 | B17: -018116 | C17: WHT | D17: 20 | E17: 160 | F17: KA0180:A2 | G17: GENERATOR PANEL
A18: AF0181:18 | B18: -018118 | C18: WHT | D18: 20 | E18: 160 | F18: KA0181:A2 | G18: GENERATOR PANEL
A19: AF0181:26 | B19: -018126 | C19: WHT | D19: 20 | E19: 160 | F19: XT0338:2 | G19: GENERATOR PANEL
A21: AF0181:COM | B21: -0V | C21: WHT | D21: 16 | E21: 160 | F21: XT0180:2 | G21: GENERATOR PANEL
A22: AF0182:COM | B22: -0V | C22: WHT | D22: 16 | E22: 160 | F22: XT0180:2 | G22: GENERATOR PANEL
A23: AU0180:COM | B23: -0V | C23: WHT | D23: 16 | E23: 160 | F23: XT0180:1 | G23: GENERATOR PANEL
A24: AU0180:V+ | B24: FU0180 | C24: WHT | D24: 16 | E24: 160 | F24: FU0180:LD | G24: GENERATOR PANEL
A25: AF0181:V+ | B25: FU0181 | C25: WHT | D25: 16 | E25: 160 | F25: FU0181:LD | G25: GENERATOR PANEL
A26: AF0182:V+ | B26: FU0182 | C26: WHT | D26: 16 | E26: 160 | F26: FU0182:LD | G26: GENERATOR PANEL

Sheet GENERATOR PANEL_S
A1: GENERATOR PANEL
A2: JB72
A3: Project # | B3: 4K911
A4: Project Name | B4: ERGON REFINING INC
A5: Revision | B5: A
A7: Controls DE | B7: A. MADDI
A8: Phone: | B8: 0
A9: Controls ME
A10: Phone:
A12: From | G12: To
A13: Device ID | B13: Wire No. | C13: Wire ID | D13: Gauge/Size | E13: Length | F13: Device ID | G13: Location | H13: Bundle Name
A14: AF0410:53 | B14: -0V | C14: WHT | D14: 16 | E14: 60 | F14: XT0130:4 | G14: GEN PANEL | H14: AF
A15: AF0410:54 | B15: AF0410N | C15: WHT | D15: 16 | E15: 60 | F15: AF0420:53 | G15: GEN PANEL
A16: AF0410:56 | B16: AF0410P | C16: WHT | D16: 16 | E16: 60 | F16: AF0420:55 | G16: GEN PANEL
A17: AF0420:54 | B17: AF0420N | C17: WHT | D17: 16 | E17: 60 | F17: AF0440:53 | G17: GEN PANEL
A18: AF0420:56 | B18: AF0420P | C18: WHT | D18: 16 | E18: 60 | F18: AF0440:55 | G18: GEN PANEL
A19: AF0440:54 | B19: AF0440N | C19: WHT | D19: 16 | E19: 60 | F19: AF0450:53 | G19: GEN PANEL
A20: AF0440:56 | B20: AF0440P | C20: WHT | D20: 16 | E20: 60 | F20: AF0450:55 | G20: GEN PANEL
A21: AF0410:55 | B21: FU0113 | C21: WHT | D21: 16 | E21: 60 | F21: FU0113:LD | G21: GEN PANEL
A23: KA0123:A1 | B23: -012103 | C23: WHT | D23: 20 | E23: 80 | F23: KA0313:2 | G23: GEN PANEL | H23: KA A1
A24: KA0335:A1 | B24: ESTOP | C24: WHT | D24: 20 | E24: 60 | F24: XT0336:1 | G24: GEN PANEL
A25: KA0310:A1 | B25: FU0334 | C25: WHT | D25: 20 | E25: 80 | F25: KA0123:11 | G25: GEN PANEL
A26: KA0310:A1 | B26: FU0334 | C26: WHT | D26: 20 | E26: 60 | F26: XT0335:2 | G26: GEN PANEL
A27: KA0330:A1 | B27: KA0330A1 | C27: WHT | D27: 20 | E27: 60 | F27: XT0337:9 | G27: GEN PANEL
A28: KA0331:A1 | B28: KA0331A1 | C28: WHT | D28: 20 | E28: 60 | F28: XT0337:11 | G28: GEN PANEL
A29: KA0332:A1 | B29: KA0332A1 | C29: WHT | D29: 20 | E29: 60 | F29: XT0337:14 | G29: GEN PANEL
A30: KA0333:A1 | B30: KA0333A1 | C30: WHT | D30: 20 | E30: 60 | F30: XT0337:8 | G30: GEN PANEL
A32: KA0336:A1 | B32: KA0231A1 | C32: WHT | D32: 14 | E32: 60 | F32: XT0334:2 | G32: GEN PANEL
A34: KA0123:A2 | B34: -012119 | C34: WHT | D34: 20 | E34: 80 | F34: KA0313:7 | G34: GEN PANEL | H34: KA A2
A35: KA0330:A2 | B35: -0V | C35: WHT | D35: 20 | E35: 60 | F35: KA0333:A2 | G35: GEN PANEL
A36: KA0332:A2 | B36: -0V | C36: WHT | D36: 20 | E36: 60 | F36: XT0337:15 | G36: GEN PANEL
A37: KA0335:A2 | B37: -0V | C37: WHT | D37: 20 | E37: 60 | F37: XT0336:2 | G37: GEN PANEL
A38: KA0185:A2 | B38: KA0185A2 | C38: WHT | D38: 20 | E38: 80 | F38: XT0338:1 | G38: GEN PANEL
A40: KA0336:A2 | B40: -0V | C40: WHT | D40: 14 | E40: 60 | F40: XT0336:2 | G40: GEN PANEL
A42: KA0336:24 | B42: -033624 | C42: WHT | D42: 20 | E42: 120 | F42: KA4300:A1 | G42: GEN PANEL | H42: KA
A43: KA0121:14 | B43: FU0333 | C43: WHT | D43: 20 | E43: 60 | F43: XT0337:12 | G43: GEN PANEL
A44: KA0128:14 | B44: FU0333 | C44: WHT | D44: 20 | E44: 60 | F44: KA0335:22 | G44: GEN PANEL
A45: KA0128:14 | B45: FU0333 | C45: WHT | D45: 20 | E45: 60 | F45: XT0337:7 | G45: GEN PANEL
A46: KA0310:24 | B46: FU0333 | C46: WHT | D46: 20 | E46: 60 | F46: KA0335:22 | G46: GEN PANEL
A47: KA0128:21 | B47: KA012821 | C47: WHT | D47: 20 | E47: 60 | F47: XT0337:1 | G47: GEN PANEL
...

Sheet MEDIA CONVERTER_S
A1: MEDIA CONVERTER
A3: Project # | B3: 4K911
A4: Project Name | B4: ERGON REFINING INC
A5: Revision | B5: A
A7: Controls DE | B7: A. MADDI
A8: Phone: | B8: 0
A9: Controls ME
A10: Phone:
A12: From | G12: To
A13: Device ID | B13: Wire No. | C13: Wire ID | D13: Gauge/Size | E13: Length | F13: Device ID | G13: Location | H13: Bundle Name
