Workbook

Sheet Blue Labels

Sheet White Labels
A1: - 250-01 | B1: - 250-01 - 251-01 | C1: - 250-01 - 251-01 - 300-00J0980 | D1: - 250-01 - 251-01 - 300-00J0980 - 500-06 | F1: - 500-06 | G1: - 256-L2
A2: GYZ101 | B2: GYIE251 | C2: IE250 | D2: GYIE250 | E2: GY213 | F2: GYIE252 | G2: GY220
A3: GY205 | D3: GY211 | E3: GYIE2521 | G3: GYIE256
A4: GY206 | D4: GY215 | E4: IE2130 | G4: GYPE256
A5: GY209 | D5: IE2110 | G5: GY218
A6: GYIE206 | D6: IE2150 | G6: GY257
A7: GYIE207 | G7: GYIE2571
A8: GYIE208 | G8: GYIE2572
A9: GYIE2504 | G9: GYIE257
A10: GYPS200
A11: GYPS2010

Sheet Heat Shrink Labels

Sheet 100-00 
A1: 100-00
A2: UPGRADE
A3: Project # | B3: 75751
A4: Project Name
A5: Revision | B5: D
A7: Controls DE
A8: Phone:
A9: Controls ME
A10: Phone:
A12: From | G12: To
A13: Device ID | B13: Cable (W) Conductor (SC) Jumper Clip (JC) | C13: Wire No. | D13: Wire ID | E13: Gauge/Size | F13: Page/Zone | G13: Device ID | H13: Location | I13: Page/Zone
A14: CR341-1:- | B14: SC | C14: L3411 | D14: LEAD | E14: --- | F14: 16.C7 | G14: TS311:2 | H14: 301-05 | I14: 16.C7 | M14: USED
A15: CR341-1:+ | B15: SC | C15: 3411 | D15: LEAD | E15: --- | F15: 16.C7 | G15: TS311:3 | H15: 301-05 | I15: 16.C7 | M15: USED
A16: CR342-1:- | B16: SC | C16: L3421 | D16: LEAD | E16: --- | F16: 17.E7 | G16: TS311:19 | H16: 301-05 | I16: 17.E7 | M16: USED
A17: CR342-1:+ | B17: SC | C17: 3421 | D17: LEAD | E17: --- | F17: 17.E7 | G17: TS311:20 | H17: 301-05 | I17: 17.E7 | M17: USED
A18: CR293A:- | B18: SC | C18: K2931A11 | D18: LEAD | E18: --- | F18: 53.G4 | G18: TS293C:5 | H18: 257-01 | I18: 53.G4 | M18: USED
A19: CR293A:+ | B19: SC | C19: K29302 | D19: LEAD | E19: --- | F19: 53.G4 | G19: TS293C:4 | H19: 257-01 | I19: 53.G5 | M19: USED
A20: CR293C11:- | B20: SC | C20: L5622P | D20: LEAD | E20: --- | F20: 53.F7 | G20: TS293C:22 | H20: 257-01 | I20: 53.F7 | M20: USED
A21: CR293C11:+ | B21: SC | C21: K29302B | D21: LEAD | E21: --- | F21: 53.F7 | G21: TS293C:21 | H21: 257-01 | I21: 53.F8 | M21: USED
A22: CR293C5:- | B22: SC | C22: K29302B21 | D22: LEAD | E22: --- | F22: 53.F4 | G22: TS293C:8 | H22: 257-01 | I22: 53.F4 | M22: USED
A23: CR293C5:+ | B23: SC | C23: K29302 | D23: LEAD | E23: --- | F23: 53.F4 | G23: TS293C:7 | H23: 257-01 | I23: 53.F5 | M23: USED
A24: CR293C7:- | B24: SC | C24: L5642P | D24: LEAD | E24: --- | F24: 53.F4 | G24: TS293C:11 | H24: 257-01 | I24: 53.F4 | M24: USED
A25: CR293C7:+ | B25: SC | C25: K29302 | D25: LEAD | E25: --- | F25: 53.F4 | G25: TS293C:10 | H25: 257-01 | I25: 53.F5 | M25: USED
... A27: CR293C9:+ | B27: SC | C27: K29302 | D27: LEAD | E27: --- | F27: 53.E4 | G27: TS293C:13 | H27: 257-01 | I27: 53.E5 | M27: USED
F29: SolarTools ver. 24.0.84.24712 (Jul 31, 2025)
A30: Report date: 1/16/2026 11:44 PM

Sheet 100-00J0980 
A1: 100-00J0980
A2: UPGRADE
A3: Project # | B3: 75751
A4: Project Name
A5: Revision | B5: D
A7: Controls DE
A8: Phone:
A9: Controls ME
A10: Phone:
A12: From | G12: To
A13: Device ID | B13: Cable (W) Conductor (SC) Jumper Clip (JC) | C13: Wire No. | D13: Wire ID | E13: Gauge/Size | F13: Page/Zone | G13: Device ID | H13: Location | I13: Page/Zone
A14: AT1100:V- | B14: SC | C14: 0V10 | E14: 12GA | F14: 9.F8 | G14: TS1100:3 | H14: 100-00J0980 | I14: 9.E7 | M14: USED
A15: AT1100:V+ | B15: SC | C15: F2100 | E15: 14GA | F15: 9.F8 | G15: TS1100:2 | H15: 100-00J0980 | I15: 9.E7 | M15: USED
A16: AT1100:GND | B16: SC | C16: GYZ101 | D16: GRN/YEL | E16: 16GA | F16: 9.F8 | G16: FGZ101:1 | H16: 250-01 | I16: 9.E7 | M16: USED
A17: DS111:X1 | B17: SC | C17: DS111 | E17: 20GA | F17: 8.C8 | G17: ZF2087:13 | H17: 250-01 | I17: 8.D6 | M17: USED
A18: DS111:X2 | B18: SC | C18: DS111N | E18: 20GA | F18: 8.C8 | G18: ZF2087:COM30 | H18: 250-01 | I18: 8.D6 | M18: USED
A19: S112:11 | B19: SC | C19: S212BP | E19: 20GA | F19: 8.B8 | G19: ZF2087:V44 | H19: 250-01 | I19: 8.B6 | M19: USED
A20: S112:12 | B20: SC | C20: S212BN | E20: 20GA | F20: 8.B8 | G20: ZF2087:09 | H20: 250-01 | I20: 8.B6 | M20: USED
A21: S112:21 | B21: SC | C21: ESTOP | E21: 20GA | F21: 8.B8 | G21: TS295:14 | H21: 250-01 | I21: 11.G4 | M21: USED
A22: S112:22 | B22: SC | C22: S1012R | E22: 20GA | F22: 8.B8 | G22: TS295:13 | H22: 250-01 | I22: 11.G4 | M22: USED
A23: S114:23 | B23: SC | C23: S1141AP | E23: 20GA | F23: 8.E4 | G23: ZF2087:V39 | H23: 250-01 | I23: 8.E3 | M23: USED
A24: S114:24 | B24: SC | C24: S1141A | E24: 20GA | F24: 8.E4 | G24: ZF2087:04 | H24: 250-01 | I24: 8.E3 | M24: USED
A25: S117:23 | B25: SC | C25: S1171AP | E25: 20GA | F25: 8.F4 | G25: ZF2087:V38 | H25: 250-01 | I25: 8.F3 | M25: USED
A26: S117:24 | B26: SC | C26: S1171A | E26: 20GA | F26: 8.F4 | G26: ZF2087:03 | H26: 250-01 | I26: 8.F3 | M26: USED
A27: S120:11 | B27: SC | C27: S1201A | E27: 20GA | F27: 8.A8 | G27: ZF2082:02 | H27: 250-01 | I27: 8.A6 | M27: USED
A28: S120:12 | B28: SC | C28: S1201AP | E28: 20GA | F28: 8.A8 | G28: ZF2082:V37 | H28: 250-01 | I28: 8.A6 | M28: USED
... A38: TS1100:3 | B38: SC | C38: 0V10 | E38: 12GA | F38: 9.E7 | G38: TS250D:6 | H38: 250-01 | I38: 7.E7 | M38: USED
A39: DS110:13 | B39: WDS110 | C39: S1101AP | D39: 3 | E39: 20 GA | F39: 8.H8 | G39: ZF2087:V35 | H39: 250-01 | I39: 8.H6 | M39: USED
A40: DS110:14 | B40: WDS110 | C40: S1101A | D40: 4 | E40: 20 GA | F40: 8.H8 | G40: ZF2087:00 | H40: 250-01 | I40: 8.H6 | M40: USED
A41: DS110:X1 | B41: WDS110 | C41: DS110 | D41: 5 | E41: 20 GA | F41: 8.G8 | G41: ZF2087:10 | H41: 250-01 | I41: 8.G6 | M41: USED
A42: DS110:X2 | B42: WDS110 | C42: DS110N | D42: 6 | E42: 20 GA | F42: 8.G8 | G42: ZF2087:COM27 | H42: 250-01 | I42: 8.G6 | M42: USED
A43: DS111:11 | B43: WDS111 | C43: S1111BP | D43: 1 | E43: 20 GA | F43: 8.D8 | G43: ZF2087:V36 | H43: 250-01 | I43: 8.D6 | M43: USED
A44: DS111:12 | B44: WDS111 | C44: S1111B | D44: 2 | E44: 20 GA | F44: 8.D8 | G44: ZF2087:01 | H44: 250-01 | I44: 8.D6 | M44: USED
A45: DS124:14 | B45: WDS124 | C45: K29521A1 | D45: 3 | E45: 20 GA | F45: 8.A4 | G45: TS295:10 | H45: 250-01 | I45: 11.E4 | M45: USED
A46: DS124:13 | B46: WDS124 | C46: F295 | D46: 4 | E46: 20 GA | F46: 8.A4 | G46: TS295:5 | H46: 250-01 | I46: 11.E5 | M46: USED
A47: DS124:X1 | B47: WDS124 | C47: DS124 | D47: 5 | E47: 20 GA | F47: 8.B4 | G47: TS208D:1 | H47: 250-01 | I47: 8.B4 | M47: USED
A48: DS124:X2 | B48: WDS124 | C48: 0V95 | D48: 6 | E48: 20 GA | F48: 8.B4 | G48: TS295:4 | H48: 250-01 | I48: 11.C2 | M48: USED
A49: AT1100:ENET1 | B49: WC1100 | C49: CABLE-2 | D49: ENET | E49: CABLE | F49: 9.F8 | G49: BA1100:ETHERNET A | H49: 300-00J0980 | I49: 9.C8 | M49: USED
A50: DS110:12 | B50: WDS110 | C50: DS1101 | D50: 1 | E50: 20 GA | F50: 8.H8 | G50: TS100:1 | H50: 300-00J0980 | I50: 8.H7 | M50: USED
... A55: DS124:11 | B55: WDS124 | C55: DS1241 | D55: 2 | E55: 20 GA | F55: 8.C4 | G55: TS100:6 | H55: 300-00J0980 | I55: 8.C4 | M55: USED
...

Sheet 200-T1 
A1: 200-T1
A2: CONSOLE CEILING
A3: Project # | B3: 75751
A4: Project Name
A5: Revision | B5: D
A7: Controls DE
A8: Phone:
A9: Controls ME
A10: Phone:
A12: From | G12: To
A13: Device ID | B13: Cable (W) Conductor (SC) Jumper Clip (JC) | C13: Wire No. | D13: Wire ID | E13: Gauge/Size | F13: Page/Zone | G13: Device ID | H13: Location | I13: Page/Zone
A14: DS273-1:1W | B14: SC | C14: S2731 | E14: 16GA | F14: 62.B6 | G14: S273-1:2 | H14: 200-T1 | I14: 62.B7 | M14: USED
A15: DS273-1:1B | B15: SC | C15: 0V73 | E15: 12GA | F15: 62.B6 | G15: TS256D:4 | H15: 256-01 | I15: 62.D7 | M15: USED
A16: S273-1:1 | B16: SC | C16: 24V73 | E16: 16GA | F16: 62.B7 | G16: TS256C:4 | H16: 256-01 | I16: 62.D4 | M16: USED
A17: AH272:1 | B17: SC | C17: AH272 | E17: 16GA | F17: 64.H4 | G17: ZF2201:10 | H17: 256-L2 | I17: 64.H3 | M17: USED
A18: AH272:2 | B18: SC | C18: AH272N | E18: 16GA | F18: 64.H4 | G18: ZF2201:COM27 | H18: 256-L2 | I18: 64.H3 | M18: USED
F20: SolarTools ver. 24.0.84.24712 (Jul 31, 2025)
A21: Report date: 1/16/2026 11:44 PM

Sheet 250-01 
A1: 250-01
A2: CONTROL CONSOLE
A3: Project # | B3: 75751
A4: Project Name
A5: Revision | B5: D
A7: Controls DE
A8: Phone:
A9: Controls ME
A10: Phone:
A12: From | G12: To
A13: Device ID | B13: Cable (W) Conductor (SC) Jumper Clip (JC) | C13: Wire No. | D13: Wire ID | E13: Gauge/Size | F13: Page/Zone | G13: Device ID | H13: Location | I13: Page/Zone
A14: AH172:1 | B14: SC | C14: AH172P | E14: 16GA | F14: 8.H4 | G14: ZF2087:15 | H14: 250-01 | I14: 8.H3 | M14: USED
A15: AH172:2 | B15: SC | C15: AH172N | E15: 16GA | F15: 8.H4 | G15: ZF2087:COM32 | H15: 250-01 | I15: 8.H3 | M15: USED
A16: BT2010:1 | B16: SC | C16: BT2010 | E16: CABLE | F16: 2.E6 | G16: U2010:bat | H16: 250-01 | I16: 2.F7 | M16: USED
A17: CH2010:1 | B17: SC | C17: GYPS2010 | D17: GRN/YEL | E17: 12GA | F17: 2.G6 | G17: PS2010:GND | H17: 250-01 | I17: 2.E8 | M17: USED
A18: CH2010:1 | B18: SC | C18: GYPS2010 | D18: GRN/YEL | E18: 12GA | F18: 2.G6 | G18: IE250:1 | H18: 250-01 | I18: 2.E6 | M18: USED
A19: CR422:1 | B19: SC | C19: K422P | D19: LEAD | E19: --- | F19: 35.D6 | G19: TS291:7 | H19: 250-01 | I19: 35.D5 | M19: USED
A20: F200:LD | B20: SC | C20: 24V | E20: 10GA | F20: 6.F4 | G20: TS250A:1 | H20: 250-01 | I20: 7.H5 | M20: USED
A21: F200:LI | B21: SC | C21: F2001 | E21: 10GA | F21: 6.F4 | G21: PS200:1POS | H21: 250-01 | I21: 6.E5 | M21: USED
A22: F200-1:LD | B22: SC | C22: PS200P | E22: 12GA | F22: 6.G6 | G22: PS200:3 | H22: 250-01 | I22: 6.E5 | M22: USED
A23: F200-3:LI | B23: SC | C23: 52005 | E23: COMB | F23: 6.C5 | G23: F200-2:LI | H23: 250-01 | I23: 6.C5 | M23: USED
A24: F200-3:LI | B24: SC | C24: 52005 | E24: COMB | F24: 6.C5 | G24: F200-4:LI | H24: 250-01 | I24: 6.B5 | M24: USED
A25: F200-4:LI | B25: SC | C25: 52005 | E25: COMB | F25: 6.B5 | G25: F200-5:LI | H25: 250-01 | I25: 6.B5 | M25: USED
A26: F2010:LD | B26: SC | C26: F2010A | E26: 14GA | F26: 7.E3 | G26: PS2010:POS | H26: 250-01 | I26: 2.E8 | M26: USED
A27: F2010:LI | B27: SC | C27: 24V01 | E27: 12GA | F27: 7.E3 | G27: TS250C:5 | H27: 250-01 | I27: 7.E4 | M27: USED
A28: F2060A:LI | B28: SC | C28: F2060A | E28: 14GA | F28: 7.D3 | G28: UF2060:24V-1 | H28: 250-01 | I28: 3.E7 | M28: USED
A29: F2061:LD | B29: SC | C29: 24V06 | F29: 7.C3 | G29: F2060A:LD | H29: 250-01 | I29: 7.D3 | M29: USED
A30: F2061:LD | B30: SC | C30: 24V06 | F30: 7.C3 | G30: F2061A:LD | H30: 250-01 | I30: 7.C3 | M30: USED
A31: F2061:LI | B31: SC | C31: F2061 | E31: 14GA | F31: 7.C3 | G31: ZF2061:V34 | H31: 250-01 | I31: 3.E6 | M31: USED
A32: F2061A:LD | B32: SC | C32: 24V06 | F32: 7.C3 | G32: F2062:LD | H32: 250-01 | I32: 7.C3 | M32: USED
A33: F2061A:LI | B33: SC | C33: F2061A | E33: 14GA | F33: 7.C3 | G33: K2061-0:14 | H33: 250-01 | I33: 18.F5 | M33: USED
A34: F2062:LD | B34: SC | C34: 24V06 | F34: 7.C3 | G34: F2063:LD | H34: 250-01 | I34: 7.C3 | M34: USED
A35: F2062:LI | B35: SC | C35: F2062 | E35: 14GA | F35: 7.C3 | G35: ZF2062:V34 | H35: 250-01 | I35: 3.E5 | M35: USED
A36: F2063:LD | B36: SC | C36: 24V06 | E36: COMB | F36: 7.C3 | G36: TS250E:3 | H36: 250-01 | I36: 7.D4 | M36: USED
A37: F2063:LI | B37: SC | C37: F2063 | E37: 14GA | F37: 7.C3 | G37: ZF2063:V34 | H37: 250-01 | I37: 3.E5 | M37: USED
A38: F2070A:LD | B38: SC | C38: F2070A | E38: 14GA | F38: 7.D3 | G38: UF2070:24V-1 | H38: 250-01 | I38: 3.C7 | M38: USED
A39: F2070A:LI | B39: SC | C39: 24V07 | E39: 12GA | F39: 7.D3 | G39: TS250E:2 | H39: 250-01 | I39: 7.D4 | M39: USED
A40: F2080:LD | B40: SC | C40: F2080A | E40: 14GA | F40: 7.G3 | G40: UF2080:24V-1 | H40: 250-01 | I40: 4.G7 | M40: USED
A41: F2080:LI | B41: SC | C41: 24V08 | E41: COMB | F41: 7.G3 | G41: TS250C:3 | H41: 250-01 | I41: 7.G4 | M41: USED
A42: F2080:LI | B42: SC | C42: 24V08 | E42: COMB | F42: 7.G3 | G42: F2081:LI | H42: 250-01 | I42: 7.G3 | M42: USED
...

Sheet 251-01 
A1: 251-01
A2: TURBINE VIBRATION PANEL
A3: Project # | B3: 75751
A4: Project Name
A5: Revision | B5: D
A7: Controls DE
A8: Phone:
A9: Controls ME
A10: Phone:
A12: From | G12: To
A13: Device ID | B13: Cable (W) Conductor (SC) Jumper Clip (JC) | C13: Wire No. | D13: Wire ID | E13: Gauge/Size | F13: Page/Zone | G13: Device ID | H13: Location | I13: Page/Zone
A14: F251:LD | B14: SC | C14: 24V51 | E14: 12GA | F14: 38.H4 | G14: TS251C:1 | H14: 251-01 | I14: 38.H4 | M14: USED
A15: F251A:LD | B15: SC | C15: F251A | E15: 22GA | F15: 38.H3 | G15: TB251:1 | H15: 251-01 | I15: 38.D1 | M15: USED
A16: F251A:LI | B16: SC | C16: 24V51 | E16: 14GA | F16: 38.H3 | G16: TS251C:1 | H16: 251-01 | I16: 38.H4 | M16: USED
A17: FA251:1 | B17: SC | C17: F251A | D17: RED | E17: 22GA | F17: 38.D1 | G17: TB251:1 | H17: 251-01 | I17: 38.D1 | M17: USED
A18: FA251:2 | B18: SC | C18: 0V | D18: BLK | E18: 22GA | F18: 38.D1 | G18: TB251:2 | H18: 251-01 | I18: 38.D1 | M18: USED
A19: HY2110A/B:BNC-A1 | B19: SC | C19: WA1115 | E19: CNET | F19: 5.F7 | G19: HY2150A/B:BNC-A2 | H19: 251-01 | I19: 5.F8 | M19: USED
A20: HY2110A/B:BNC-B1 | B20: SC | C20: WB1115 | E20: CNET | F20: 5.F7 | G20: HY2150A/B:BNC-B2 | H20: 251-01 | I20: 5.F8 | M20: USED
A21: HY2110A/B:TAP-A | B21: SC | C21: HY2110A | E21: 24GA | F21: 5.F7 | G21: UF2110:A | H21: 251-01 | I21: 37.F7 | M21: USED
A22: HY2110A/B:TAP-B | B22: SC | C22: HY2110B | E22: 24GA | F22: 5.F7 | G22: UF2110:B | H22: 251-01 | I22: 37.F7 | M22: USED
A23: HY2150A/B:TAP-A | B23: SC | C23: HY2150A | E23: 24GA | F23: 5.F8 | G23: UF2150:A | H23: 251-01 | I23: 37.C7 | M23: USED
A24: HY2150A/B:TAP-B | B24: SC | C24: HY2150B | E24: 24GA | F24: 5.F8 | G24: UF2150:B | H24: 251-01 | I24: 37.C7 | M24: USED
A25: IE251:1 | B25: SC | C25: IE2110 | D25: GRN/YEL | E25: 12GA | F25: 37.H7 | G25: CH2110:GND | H25: 251-01 | I25: 37.F5 | M25: USED
A26: IE251:1 | B26: SC | C26: IE2150 | D26: GRN/YEL | E26: 12GA | F26: 37.E7 | G26: CH2150:GND | H26: 251-01 | I26: 37.C5 | M26: USED
A27: IE251:1 | B27: SC | C27: GY211 | D27: GRN/YEL | E27: 12GA | F27: 38.F1 | G27: TSIE211:2 | H27: 251-01 | I27: 38.F1 | M27: USED
A28: IE251:1 | B28: SC | C28: GY215 | D28: GRN/YEL | E28: 12GA | F28: 38.F1 | G28: TSIE215:2 | H28: 251-01 | I28: 38.F1 | M28: USED
A29: PS2110:NEG | B29: SC | C29: UF2110N | E29: 16GA | F29: 37.F7 | G29: UF2110:COM-2 | H29: 251-01 | I29: 37.F7 | M29: USED
A30: PS2110:POS | B30: SC | C30: UF2110P | E30: 16GA | F30: 37.F7 | G30: UF2110:24V-2 | H30: 251-01 | I30: 37.F7 | M30: USED
A31: PS2150:NEG | B31: SC | C31: UF2150N | E31: 16GA | F31: 37.C7 | G31: UF2150:COM-2 | H31: 251-01 | I31: 37.C7 | M31: USED
A32: PS2150:POS | B32: SC | C32: UF2150P | E32: 16GA | F32: 37.C7 | G32: UF2150:24V-2 | H32: 251-01 | I32: 37.C7 | M32: USED
A33: TB251:2 | B33: SC | C33: 0V | E33: 8GA | F33: 38.D1 | G33: TS251D:1 | H33: 251-01 | I33: 38.H6 | M33: USED
A34: UF2110:24V-1 | B34: SC | C34: 24V11 | E34: 16GA | F34: 37.F7 | G34: TS251C:2 | H34: 251-01 | I34: 38.H4 | M34: USED
A35: UF2110:COM-1 | B35: SC | C35: 0V11 | E35: 16GA | F35: 37.F7 | G35: TS251D:2 | H35: 251-01 | I35: 38.H6 | M35: USED
A36: UF2150:24V-1 | B36: SC | C36: 24V15 | E36: 16GA | F36: 37.C7 | G36: TS251C:3 | H36: 251-01 | I36: 38.F4 | M36: USED
A37: UF2150:COM-1 | B37: SC | C37: 0V15 | E37: 16GA | F37: 37.C7 | G37: TS251D:3 | H37: 251-01 | I37: 38.F6 | M37: USED
A38: TS251C:2 | B38: SC | C38: JA51 | D38: VIO | E38: 12GA | F38: 38.H4 | G38: TS251C:1 | H38: 251-01 | I38: 38.H4 | M38: USED
A39: TS251C:3 | B39: SC | C39: JA11 | D39: VIO | E39: 12GA | F39: 38.F4 | G39: TS251C:2 | H39: 251-01 | I39: 38.H4 | M39: USED
A40: TS251D:2 | B40: SC | C40: JB51 | D40: VIO | E40: 12GA | F40: 38.H6 | G40: TS251D:1 | H40: 251-01 | I40: 38.H6 | M40: USED
A41: TS251D:3 | B41: SC | C41: JB11 | D41: VIO | E41: 12GA | F41: 38.F6 | G41: TS251D:2 | H41: 251-01 | I41: 38.H6 | M41: USED
A42: ZZ2110:A | B42: SC | C42: 350K | D42: COAX | E42: 20GA | F42: 39.H3 | G42: TV350K:1 | H42: 305-02 | I42: 39.H8 | M42: USED
...

Sheet 252-01 
A1: 252-01
A2: HP COMPRESSOR PANEL
A3: Project # | B3: 75751
A4: Project Name
A5: Revision | B5: D
A7: Controls DE
A8: Phone:
A9: Controls ME
A10: Phone:
A12: From | G12: To
A13: Device ID | B13: Cable (W) Conductor (SC) Jumper Clip (JC) | C13: Wire No. | D13: Wire ID | E13: Gauge/Size | F13: Page/Zone | G13: Device ID | H13: Location | I13: Page/Zone
A14: F2120A:LD | B14: SC | C14: F2120A | E14: 14GA | F14: 42.H3 | G14: UF2120:24V-1 | H14: 252-01 | I14: 41.C7 | M14: USED
A15: F2120A:LI | B15: SC | C15: 24V12 | E15: 12GA | F15: 42.H3 | G15: TS252C:2 | H15: 252-01 | I15: 42.H4 | M15: USED
A16: F2120A:LI | B16: SC | C16: 24V12 | E16: 12GA | F16: 42.H3 | G16: F2121:LI | H16: 252-01 | I16: 42.G3 | M16: USED
A17: F2121:LD | B17: SC | C17: F2121 | E17: 14GA | F17: 42.G3 | G17: ZF2121:V34 | H17: 252-01 | I17: 41.C6 | M17: USED
A18: F2130A:LD | B18: SC | C18: F2130A | E18: 14GA | F18: 42.F3 | G18: UF2130:24V-1 | H18: 252-01 | I18: 41.F7 | M18: USED
A19: F2130A:LI | B19: SC | C19: 24V13 | E19: 14GA | F19: 42.F3 | G19: TS252C:3 | H19: 252-01 | I19: 42.F4 | M19: USED
A20: F252:LD | B20: SC | C20: 24V52 | E20: 12GA | F20: 42.H4 | G20: TS252C:1 | H20: 252-01 | I20: 42.H4 | M20: USED
A21: F252:LI | B21: SC | C21: 24V | E21: 12GA | F21: 42.H4 | G21: TS252A:1 | H21: 252-01 | I21: 42.H4 | M21: USED
A22: F252A:LD | B22: SC | C22: F252A | E22: 14GA | F22: 42.H3 | G22: TB252:1 | H22: 252-01 | I22: 42.D1 | M22: USED
A23: F252A:LI | B23: SC | C23: 24V52 | E23: 14GA | F23: 42.H3 | G23: TS252C:1 | H23: 252-01 | I23: 42.H4 | M23: USED
A24: FA252:1 | B24: SC | C24: F252A | D24: RED | E24: 22GA | F24: 42.D1 | G24: TB252:1 | H24: 252-01 | I24: 42.D1 | M24: USED
A25: FA252:2 | B25: SC | C25: 0V | D25: BLK | E25: 22GA | F25: 42.D1 | G25: TB252:2 | H25: 252-01 | I25: 42.D1 | M25: USED
A26: HY2120A/B:BNC-A2 | B26: SC | C26: WA1213 | E26: CNET | F26: 5.E2 | G26: HY2130A/B:BNC-A1 | H26: 252-01 | I26: 5.E1 | M26: USED
A27: HY2120A/B:BNC-B2 | B27: SC | C27: WB1213 | E27: CNET | F27: 5.E2 | G27: HY2130A/B:BNC-B1 | H27: 252-01 | I27: 5.E1 | M27: USED
A28: HY2120A/B:TAP-A | B28: SC | C28: HY2120A | E28: 24GA | F28: 5.E2 | G28: UF2120:A | H28: 252-01 | I28: 41.C7 | M28: USED
A29: HY2120A/B:TAP-B | B29: SC | C29: HY2120B | E29: 24GA | F29: 5.E2 | G29: UF2120:B | H29: 252-01 | I29: 41.C7 | M29: USED
A30: HY2130A/B:TAP-A | B30: SC | C30: HY2130A | E30: 24GA | F30: 5.E1 | G30: UF2130:A | H30: 252-01 | I30: 41.F7 | M30: USED
A31: HY2130A/B:TAP-B | B31: SC | C31: HY2130B | E31: 24GA | F31: 5.E1 | G31: UF2130:B | H31: 252-01 | I31: 41.F7 | M31: USED
A32: IE212:2 | B32: SC | C32: GYIE2521 | D32: GRN/YEL | E32: 14GA | F32: 42.E1 | G32: IE252:1 | H32: 252-01 | I32: 42.E1 | M32: USED
A33: IE252:1 | B33: SC | C33: IE2130 | D33: GRN/YEL | E33: 12GA | F33: 41.H7 | G33: CH2130:GND | H33: 252-01 | I33: 41.F5 | M33: USED
A34: IE252:1 | B34: SC | C34: GY213 | D34: GRN/YEL | E34: 12GA | F34: 42.E2 | G34: TSIE213:2 | H34: 252-01 | I34: 42.E1 | M34: USED
A35: K2121-10:14 | B35: SC | C35: K212110A14 | E35: 20GA | F35: 47.H3 | G35: ZF2121:10 | H35: 252-01 | I35: 47.H3 | M35: USED
A36: K2121-10:21 | B36: SC | C36: K29401A12 | E36: 20GA | F36: 47.C3 | G36: K2940-1:12 | H36: 252-01 | I36: 47.C4 | M36: USED
A37: K2121-10:24 | B37: SC | C37: K212110B | E37: 20GA | F37: 47.C3 | G37: ZF2120:V35 | H37: 252-01 | I37: 47.C3 | M37: USED
A38: K2121-10:A1 | B38: SC | C38: K212110A1 | F38: 47.H3 | G38: ZF2121:V45 | H38: 252-01 | I38: 47.H3 | M38: USED
A39: K2940-1:14 | B39: SC | C39: K29401A14 | E39: 20GA | F39: 47.C4 | G39: ZF2120:00 | H39: 252-01 | I39: 47.C3 | M39: USED
A40: K2940-1:A2 | B40: SC | C40: 0V94 | E40: 14GA | F40: 47.D4 | G40: TS252D:4 | H40: 252-01 | I40: 42.F7 | M40: USED
A41: P112:1 | B41: SC | C41: P112 | D41: CABLE | E41: 20GA | F41: 41.C8 | G41: UF2120:NAP | H41: 252-01 | I41: 41.C7 | M41: USED
A42: PS2130:NEG | B42: SC | C42: UF2130N | E42: 16GA | F42: 41.F7 | G42: UF2130:COM-2 | H42: 252-01 | I42: 41.F7 | M42: USED
...

Sheet 256-01 
A1: 256-01
A2: POWER DISTRIBUTION PANEL
A3: Project # | B3: 75751
A4: Project Name
A5: Revision | B5: D
A7: Controls DE
A8: Phone:
A9: Controls ME
A10: Phone:
A12: From | G12: To
A13: Device ID | B13: Cable (W) Conductor (SC) Jumper Clip (JC) | C13: Wire No. | D13: Wire ID | E13: Gauge/Size | F13: Page/Zone | G13: Device ID | H13: Location | I13: Page/Zone
A14: F256:LD | B14: SC | C14: 24V56 | E14: 12GA | F14: 62.E4 | G14: TS256C:1 | H14: 256-01 | I14: 62.E4 | M14: USED
A15: F256:LI | B15: SC | C15: 24V | E15: 12GA | F15: 62.E4 | G15: TS256A:1 | H15: 256-01 | I15: 62.E5 | M15: USED
A16: TS256D:1 | B16: SC | C16: 0V | E16: 12GA | F16: 62.E7 | G16: TS256B:1 | H16: 256-01 | I16: 62.E7 | M16: USED
A17: TS256C:2 | B17: SC | C17: JA56 | D17: VIO | E17: 12GA | F17: 62.E4 | G17: TS256C:1 | H17: 256-01 | I17: 62.E4 | M17: USED
A18: TS256C:3 | B18: SC | C18: JA20 | D18: VIO | E18: 12GA | F18: 62.D4 | G18: TS256C:2 | H18: 256-01 | I18: 62.E4 | M18: USED
A19: TS256C:4 | B19: SC | C19: JA19 | D19: VIO | E19: 12GA | F19: 62.D4 | G19: TS256C:3 | H19: 256-01 | I19: 62.D4 | M19: USED
A20: TS256C:5 | B20: SC | C20: JA18 | D20: VIO | E20: 12GA | F20: 62.C4 | G20: TS256C:4 | H20: 256-01 | I20: 62.D4 | M20: USED
A21: TS256D:2 | B21: SC | C21: JB56 | D21: VIO | E21: 12GA | F21: 62.E7 | G21: TS256D:1 | H21: 256-01 | I21: 62.E7 | M21: USED
A22: TS256D:3 | B22: SC | C22: JB20 | D22: VIO | E22: 12GA | F22: 62.D7 | G22: TS256D:2 | H22: 256-01 | I22: 62.E7 | M22: USED
A23: TS256D:4 | B23: SC | C23: JB19 | D23: VIO | E23: 12GA | F23: 62.D7 | G23: TS256D:3 | H23: 256-01 | I23: 62.D7 | M23: USED
A24: TS256D:5 | B24: SC | C24: JB18 | D24: VIO | E24: 12GA | F24: 62.C7 | G24: TS256D:4 | H24: 256-01 | I24: 62.D7 | M24: USED
A25: TS256C:4 | B25: SC | C25: 24V73 | E25: 16GA | F25: 62.D4 | G25: S273-1:1 | H25: 200-T1 | I25: 62.B7 | M25: USED
A26: TS256D:4 | B26: SC | C26: 0V73 | E26: 12GA | F26: 62.D7 | G26: DS273-1:1B | H26: 200-T1 | I26: 62.B6 | M26: USED
A27: HY2290A/B:BNC-A2 | B27: SC | C27: WA2909 | E27: CNET | F27: 5.H3 | G27: HY2090A/B:BNC-A2 | H27: 250-01 | I27: 5.F1 | M27: USED
A28: HY2290A/B:BNC-B2 | B28: SC | C28: WB2909 | E28: CNET | F28: 5.H3 | G28: HY2090A/B:BNC-B2 | H28: 250-01 | I28: 5.F1 | M28: USED
A29: TS256A:1 | B29: SC | C29: 24V | E29: 12GA | F29: 62.E5 | G29: TS256F:2 | H29: 256-02 | I29: 62.G5 | M29: USED
A30: TS256B:1 | B30: SC | C30: 0V | E30: 12GA | F30: 62.E7 | G30: TS256G:2 | H30: 256-02 | I30: 62.G7 | M30: USED
A31: TS256E:1 | B31: SC | C31: S1012 | E31: 20GA | F31: 66.D3 | G31: TS256J:1 | H31: 256-02 | I31: 66.D3 | M31: USED
A32: TS256E:2 | B32: SC | C32: S1012R | E32: 20GA | F32: 66.D3 | G32: TS256J:2 | H32: 256-02 | I32: 66.D3 | M32: USED
A33: TS256E:3 | B33: SC | C33: K29512B24 | E33: 20GA | F33: 66.B3 | G33: TS256J:3 | H33: 256-02 | I33: 66.B3 | M33: USED
A34: TS256E:4 | B34: SC | C34: 0V95 | E34: 20GA | F34: 66.B3 | G34: TS256J:4 | H34: 256-02 | I34: 66.B3 | M34: USED
A35: TS256E:5 | B35: SC | C35: F295 | E35: 20GA | F35: 66.A3 | G35: TS256J:5 | H35: 256-02 | I35: 66.A3 | M35: USED
A36: TS256E:6 | B36: SC | C36: K29521A1 | E36: 20GA | F36: 66.A3 | G36: TS256J:6 | H36: 256-02 | I36: 66.A3 | M36: USED
... A48: TS256E:6 | B48: SC | C48: K29521A1 | E48: 20GA | F48: 66.A3 | G48: S1024:1 | H48: 256-L2 | I48: 66.A5 | M48: USED
F50: SolarTools ver. 24.0.84.24712 (Jul 31, 2025)
A51: Report date: 1/16/2026 11:44 PM

Sheet 256-02 
A1: 256-02
A2: CONTROL CONSOLE, LEFT SIDE PANEL
A3: Project # | B3: 75751
A4: Project Name
A5: Revision | B5: D
A7: Controls DE
A8: Phone:
A9: Controls ME
A10: Phone:
A12: From | G12: To
A13: Device ID | B13: Cable (W) Conductor (SC) Jumper Clip (JC) | C13: Wire No. | D13: Wire ID | E13: Gauge/Size | F13: Page/Zone | G13: Device ID | H13: Location | I13: Page/Zone
A14: F256A:LD | B14: SC | C14: 24V56A | E14: 12GA | F14: 62.H4 | G14: TS256H:1 | H14: 256-02 | I14: 62.H4 | M14: USED
A15: F256A:LI | B15: SC | C15: 24V | E15: 12GA | F15: 62.H4 | G15: TS256F:1 | H15: 256-02 | I15: 62.H5 | M15: USED
A16: HY2210A/B:TAP-A | B16: SC | C16: HY2210A | E16: 24GA | F16: 5.H5 | G16: UF2210:A | H16: 256-02 | I16: 60.D7 | M16: USED
A17: HY2210A/B:TAP-B | B17: SC | C17: HY2210B | E17: 24GA | F17: 5.H5 | G17: UF2210:B | H17: 256-02 | I17: 60.D7 | M17: USED
A18: RG256A:1 | B18: SC | C18: TS256I3 | E18: 12GA | F18: 62.F1 | G18: TS256I:3 | H18: 256-02 | I18: 62.F7 | M18: USED
A19: TS256F:2 | B19: SC | C19: 24V | E19: 12GA | F19: 62.G5 | G19: TS256F:1 | H19: 256-02 | I19: 62.H5 | M19: USED
A20: TS256G:2 | B20: SC | C20: 0V | E20: 12GA | F20: 62.G7 | G20: TS256G:1 | H20: 256-02 | I20: 62.H7 | M20: USED
A21: TS256I:1 | B21: SC | C21: 0V | E21: 12GA | F21: 62.H7 | G21: TS256G:1 | H21: 256-02 | I21: 62.H7 | M21: USED
A22: UF2210:24V-1 | B22: SC | C22: 24V21 | E22: 16GA | F22: 60.D7 | G22: TS256H:4 | H22: 256-02 | I22: 62.F4 | M22: USED
A23: UF2210:24V-2 | B23: SC | C23: UF2210P | E23: 20GA | F23: 60.D7 | G23: ZF2210:V34 | H23: 256-02 | I23: 60.D7 | M23: USED
A24: UF2210:COM-1 | B24: SC | C24: 0V21 | E24: 16GA | F24: 60.D7 | G24: TS256I:4 | H24: 256-02 | I24: 62.F7 | M24: USED
A25: UF2210:COM-2 | B25: SC | C25: UF2210N | E25: 20GA | F25: 60.D7 | G25: ZF2210:COM16 | H25: 256-02 | I25: 60.D7 | M25: USED
A26: TS256H:2 | B26: SC | C26: JH56 | D26: VIO | E26: 12GA | F26: 62.G4 | G26: TS256H:1 | H26: 256-02 | I26: 62.H4 | M26: USED
A27: TS256H:3 | B27: SC | C27: JH56A | D27: VIO | E27: 12GA | F27: 62.F4 | G27: TS256H:2 | H27: 256-02 | I27: 62.G4 | M27: USED
A28: TS256H:4 | B28: SC | C28: JH56B | D28: VIO | E28: 12GA | F28: 62.F4 | G28: TS256H:3 | H28: 256-02 | I28: 62.F4 | M28: USED
A29: TS256I:2 | B29: SC | C29: JI56 | D29: VIO | E29: 12GA | F29: 62.G7 | G29: TS256I:1 | H29: 256-02 | I29: 62.H7 | M29: USED
A30: TS256I:3 | B30: SC | C30: JI56A | D30: VIO | E30: 12GA | F30: 62.F7 | G30: TS256I:2 | H30: 256-02 | I30: 62.G7 | M30: USED
A31: TS256I:4 | B31: SC | C31: JI56B | D31: VIO | E31: 12GA | F31: 62.F7 | G31: TS256I:3 | H31: 256-02 | I31: 62.F7 | M31: USED
A32: ZF2210:COM33 | B32: SC | C32: ZF2210N | E32: 20GA | F32: 60.D7 | G32: ZF2211:35 | H32: 256-02 | I32: 60.D6 | M32: USED
A33: ZF2210:V51 | B33: SC | C33: ZF2210P | E33: 20GA | F33: 60.D7 | G33: ZF2211:34 | H33: 256-02 | I33: 60.D6 | M33: USED
A34: IE:1 | B34: W084 | C34: * | D34: SH2 | F34: 69.D3 | G34: SHLD:2 | H34: 256-02 | I34: 69.D3 | M34: USED
A35: ZF2211:40 | B35: W085 | C35: * | D35: SH2 | F35: 69.C3 | G35: SHLD:2 | H35: 256-02 | I35: 69.C3 | M35: USED
A36: ZF2210:00 | B36: W083 | C36: CUSTISOLP | D36: RED | E36: 16GA | F36: 68.E3 | G36: CUST-ISOL:3 | H36: 500-03 | I36: 68.E6 | M36: USED
A37: ZF2210:COM17 | B37: W083 | C37: CUSTISOLN | D37: BLK | E37: 16GA | F37: 68.E3 | G37: CUST-ISOL:4 | H37: 500-03 | I37: 68.E6 | M37: USED
A38: ZF2210:02 | B38: W084 | C38: TH586P | D38: RED | F38: 69.D3 | G38: TH586:1 | H38: 500-04 | I38: 69.D6 | M38: USED
A39: ZF2210:COM19 | B39: W084 | C39: TH586N | D39: BLK | F39: 69.D3 | G39: TH586:2 | H39: 500-04 | I39: 69.D6 | M39: USED
A40: ZF2211:04 | B40: W085 | C40: RT5611 | D40: RED | F40: 69.C3 | G40: RT561:RED1 | H40: 500-05 | I40: 69.C6 | M40: USED
A41: ZF2211:06 | B41: W085 | C41: RT5612 | D41: WHT | F41: 69.C3 | G41: RT561:RED2 | H41: 500-05 | I41: 69.C6 | M41: USED
A42: ZF2211:07 | B42: W085 | C42: RT5613 | D42: BLK | F42: 69.C3 | G42: RT561:WHT1 | H42: 500-05 | I42: 69.C6 | M42: USED
...

Sheet 256-03 
A1: 256-03
A2: HMI PANEL
A3: Project # | B3: 75751
A4: Project Name
A5: Revision | B5: D
A7: Controls DE
A8: Phone:
A9: Controls ME
A10: Phone:
A12: From | G12: To
A13: Device ID | B13: Cable (W) Conductor (SC) Jumper Clip (JC) | C13: Wire No. | D13: Wire ID | E13: Gauge/Size | F13: Page/Zone | G13: Device ID | H13: Location | I13: Page/Zone
A14: HY2190A/B:BNC-A2 | B14: SC | C14: WA1909 | E14: CNET | F14: 5.H4 | G14: HY2290A/B:BNC-A1 | H14: 256-01 | I14: 5.H3 | M14: USED
A15: HY2190A/B:BNC-B2 | B15: SC | C15: WB1909 | E15: CNET | F15: 5.H4 | G15: HY2290A/B:BNC-B1 | H15: 256-01 | I15: 5.H3 | M15: USED
A16: HY2190A/B:BNC-A1 | B16: SC | C16: WA2019 | E16: CNET | F16: 5.H4 | G16: HY2200A/B:BNC-A2 | H16: 256-L2 | I16: 5.H4 | M16: USED
A17: HY2190A/B:BNC-B1 | B17: SC | C17: WB2019 | E17: CNET | F17: 5.H4 | G17: HY2200A/B:BNC-B2 | H17: 256-L2 | I17: 5.H4 | M17: USED
F19: SolarTools ver. 24.0.84.24712 (Jul 31, 2025)
A20: Report date: 1/16/2026 11:44 PM

Sheet 256-L2 
A1: 256-L2
A2: LEFT DOOR
A3: Project # | B3: 75751
A4: Project Name
A5: Revision | B5: D
A7: Controls DE
A8: Phone:
A9: Controls ME
A10: Phone:
A12: From | G12: To
A13: Device ID | B13: Cable (W) Conductor (SC) Jumper Clip (JC) | C13: Wire No. | D13: Wire ID | E13: Gauge/Size | F13: Page/Zone | G13: Device ID | H13: Location | I13: Page/Zone
A14: DS1001:4a | B14: SC | C14: TCP06AP | E14: 20GA | F14: 65.E4 | G14: ZF2200:05 | H14: 256-L2 | I14: 65.F3 | M14: USED
A15: DS1001:4b | B15: SC | C15: TCP06BP | E15: 20GA | F15: 65.E4 | G15: ZF2200:06 | H15: 256-L2 | I15: 65.E3 | M15: USED
A16: DS1001:5a | B16: SC | C16: TCP06A | E16: 20GA | F16: 65.E4 | G16: ZF2200:COM22 | H16: 256-L2 | I16: 65.F3 | M16: USED
A17: DS1001:5b | B17: SC | C17: TCP06B | E17: 20GA | F17: 65.E4 | G17: ZF2200:COM23 | H17: 256-L2 | I17: 65.E3 | M17: USED
A18: DS1011:4a | B18: SC | C18: TCP09AP | E18: 20GA | F18: 66.E4 | G18: DS1011:4b | H18: 256-L2 | I18: 66.E4 | M18: USED
A19: DS1011:4a | B19: SC | C19: TCP09AP | E19: 20GA | F19: 66.E4 | G19: ZF2200:13 | H19: 256-L2 | I19: 66.F3 | M19: USED
A20: DS1011:5a | B20: SC | C20: TCP09A | F20: 66.E4 | G20: DS1011:5b | H20: 256-L2 | I20: 66.E4 | M20: USED
A21: DS1011:5b | B21: SC | C21: TCP09A | E21: 20GA | F21: 66.E4 | G21: ZF2200:COM30 | H21: 256-L2 | I21: 66.F3 | M21: USED
A22: DS1013:4a | B22: SC | C22: TCP08AP | E22: 20GA | F22: 66.F4 | G22: DS1013:4b | H22: 256-L2 | I22: 66.F4 | M22: USED
A23: DS1013:4a | B23: SC | C23: TCP08AP | E23: 20GA | F23: 66.F4 | G23: ZF2200:12 | H23: 256-L2 | I23: 66.G3 | M23: USED
A24: DS1013:5a | B24: SC | C24: TCP08A | F24: 66.F4 | G24: DS1013:5b | H24: 256-L2 | I24: 66.F4 | M24: USED
A25: DS1013:5b | B25: SC | C25: TCP08A | E25: 20GA | F25: 66.F4 | G25: ZF2200:COM29 | H25: 256-L2 | I25: 66.G3 | M25: USED
A26: DS1014:4a | B26: SC | C26: TCP02AP | E26: 20GA | F26: 65.B4 | G26: DS1014:4b | H26: 256-L2 | I26: 65.B4 | M26: USED
A27: DS1014:4a | B27: SC | C27: TCP02AP | E27: 20GA | F27: 65.B4 | G27: ZF2200:01 | H27: 256-L2 | I27: 65.B3 | M27: USED
A28: DS1014:5a | B28: SC | C28: TCP02A | F28: 65.B4 | G28: DS1014:5b | H28: 256-L2 | I28: 65.B4 | M28: USED
A29: DS1014:5b | B29: SC | C29: TCP02A | E29: 20GA | F29: 65.B4 | G29: ZF2200:COM18 | H29: 256-L2 | I29: 65.B3 | M29: USED
A30: DS1024:4a | B30: SC | C30: TCP12AP | E30: 20GA | F30: 66.B5 | G30: DS1024:4b | H30: 256-L2 | I30: 66.B5 | M30: USED
A31: DS1024:4a | B31: SC | C31: TCP12AP | E31: 20GA | F31: 66.B5 | G31: TS220:1 | H31: 256-L2 | I31: 66.B4 | M31: USED
A32: DS1024:5a | B32: SC | C32: 0V95 | F32: 66.B5 | G32: DS1024:5b | H32: 256-L2 | I32: 66.B5 | M32: USED
A33: DS1059:4a | B33: SC | C33: TCP04AP | F33: 67.G4 | G33: DS1059:4b | H33: 256-L2 | I33: 67.G4 | M33: USED
A34: DS1059:4b | B34: SC | C34: TCP04AP | E34: 20GA | F34: 67.G4 | G34: ZF2200:03 | H34: 256-L2 | I34: 67.G3 | M34: USED
A35: DS1059:5a | B35: SC | C35: TCP04A | F35: 67.G4 | G35: DS1059:5b | H35: 256-L2 | I35: 67.G4 | M35: USED
A36: DS1059:5b | B36: SC | C36: TCP04A | E36: 20GA | F36: 67.G4 | G36: ZF2200:COM20 | H36: 256-L2 | I36: 67.G3 | M36: USED
A37: DS1073:4a | B37: SC | C37: TCP10AP | E37: 20GA | F37: 64.D4 | G37: DS1073:4b | H37: 256-L2 | I37: 64.D4 | M37: USED
A38: DS1073:4a | B38: SC | C38: TCP10AP | E38: 20GA | F38: 64.D4 | G38: ZF2200:14 | H38: 256-L2 | I38: 64.D3 | M38: USED
A39: DS1073:5a | B39: SC | C39: TCP10A | F39: 64.D4 | G39: DS1073:5b | H39: 256-L2 | I39: 64.D4 | M39: USED
A40: DS1073:5b | B40: SC | C40: TCP10A | E40: 20GA | F40: 64.D4 | G40: ZF2200:COM31 | H40: 256-L2 | I40: 64.D3 | M40: USED
A41: DS1075:4a | B41: SC | C41: TCP11AP | F41: 64.C4 | G41: DS1075:4b | H41: 256-L2 | I41: 64.C4 | M41: USED
A42: DS1075:4b | B42: SC | C42: TCP11AP | E42: 20GA | F42: 64.C4 | G42: ZF2200:15 | H42: 256-L2 | I42: 64.D3 | M42: USED
...

Sheet 257-01 
A1: 257-01
A2: YARD VALVE & BOP PANEL
A3: Project # | B3: 75751
A4: Project Name
A5: Revision | B5: D
A7: Controls DE
A8: Phone:
A9: Controls ME
A10: Phone:
A12: From | G12: To
A13: Device ID | B13: Cable (W) Conductor (SC) Jumper Clip (JC) | C13: Wire No. | D13: Wire ID | E13: Gauge/Size | F13: Page/Zone | G13: Device ID | H13: Location | I13: Page/Zone
A14: CR293B:1 | B14: SC | C14: K2931A11 | D14: LEAD | E14: --- | F14: 53.G4 | G14: TS293C:5 | H14: 257-01 | I14: 53.G4 | M14: USED
A15: CR293B:2 | B15: SC | C15: L5602 | D15: LEAD | E15: --- | F15: 53.G4 | G15: TS293C:6 | H15: 257-01 | I15: 53.G3 | M15: USED
A16: CR293C10:1 | B16: SC | C16: L5612P | D16: LEAD | E16: --- | F16: 53.E4 | G16: TS293C:14 | H16: 257-01 | I16: 53.E4 | M16: USED
A17: CR293C10:2 | B17: SC | C17: L5612 | D17: LEAD | E17: --- | F17: 53.E4 | G17: TS293C:15 | H17: 257-01 | I17: 53.E3 | M17: USED
A18: CR293C12:1 | B18: SC | C18: L5622P | D18: LEAD | E18: --- | F18: 53.F7 | G18: TS293C:22 | H18: 257-01 | I18: 53.F7 | M18: USED
A19: CR293C12:2 | B19: SC | C19: L5622 | D19: LEAD | E19: --- | F19: 53.F7 | G19: TS293C:23 | H19: 257-01 | I19: 53.F6 | M19: USED
A20: CR293C6:1 | B20: SC | C20: K29302B21 | D20: LEAD | E20: --- | F20: 53.F4 | G20: TS293C:8 | H20: 257-01 | I20: 53.F4 | M20: USED
A21: CR293C6:2 | B21: SC | C21: L5622B | D21: LEAD | E21: --- | F21: 53.F4 | G21: TS293C:9 | H21: 257-01 | I21: 53.F3 | M21: USED
A22: CR293C8:1 | B22: SC | C22: L5642P | D22: LEAD | E22: --- | F22: 53.F4 | G22: TS293C:11 | H22: 257-01 | I22: 53.F4 | M22: USED
A23: CR293C8:2 | B23: SC | C23: L5642 | D23: LEAD | E23: --- | F23: 53.F4 | G23: TS293C:12 | H23: 257-01 | I23: 53.F3 | M23: USED
A24: F2140A:LD | B24: SC | C24: F2140A | E24: 14GA | F24: 52.H3 | G24: UF2140:24V-1 | H24: 257-01 | I24: 51.G7 | M24: USED
A25: F2140A:LI | B25: SC | C25: 24V14 | E25: 14GA | F25: 52.H3 | G25: TS257C:2 | H25: 257-01 | I25: 52.H4 | M25: USED
A26: F2140A:LI | B26: SC | C26: 24V14 | E26: 14GA | F26: 52.H3 | G26: F2141:LI | H26: 257-01 | I26: 52.G3 | M26: USED
A27: F2141:LD | B27: SC | C27: F2141 | E27: 14GA | F27: 52.G3 | G27: ZF2141:V34 | H27: 257-01 | I27: 51.G6 | M27: USED
A28: F2180A:LD | B28: SC | C28: F2180A | E28: 14GA | F28: 52.F3 | G28: UF2180:24V-1 | H28: 257-01 | I28: 51.E7 | M28: USED
A29: F2180A:LI | B29: SC | C29: 24V18 | E29: 14GA | F29: 52.F3 | G29: TS257C:4 | H29: 257-01 | I29: 52.F4 | M29: USED
A30: F2180A:LI | B30: SC | C30: 24V18 | E30: 14GA | F30: 52.F3 | G30: F2181:LI | H30: 257-01 | I30: 52.E3 | M30: USED
A31: F2181:LD | B31: SC | C31: F2181 | E31: 14GA | F31: 52.E3 | G31: ZF2181:V34 | H31: 257-01 | I31: 51.E6 | M31: USED
A32: F257:LD | B32: SC | C32: 24V57 | E32: 12GA | F32: 52.H4 | G32: TS257C:1 | H32: 257-01 | I32: 52.H4 | M32: USED
A33: F257A:LD | B33: SC | C33: F257A | E33: 22GA | F33: 52.H3 | G33: TB257:1 | H33: 257-01 | I33: 52.D1 | M33: USED
A34: F257A:LI | B34: SC | C34: 24V57 | E34: 14GA | F34: 52.H3 | G34: TS257C:1 | H34: 257-01 | I34: 52.H4 | M34: USED
A35: F2930:LD | B35: SC | C35: F2930 | E35: 14GA | F35: 52.G3 | G35: TS293A:1 | H35: 257-01 | I35: 52.G3 | M35: USED
A36: F2930:LI | B36: SC | C36: 24V93 | E36: 14GA | F36: 52.G3 | G36: TS257C:3 | H36: 257-01 | I36: 52.G4 | M36: USED
A37: FA257:1 | B37: SC | C37: F257A | D37: RED | E37: 22GA | F37: 52.D1 | G37: TB257:1 | H37: 257-01 | I37: 52.D1 | M37: USED
A38: FA257:2 | B38: SC | C38: 0V | D38: BLK | E38: 22GA | F38: 52.D1 | G38: TB257:2 | H38: 257-01 | I38: 52.D1 | M38: USED
A39: FT586:LD | B39: SC | C39: FT586 | E39: 14GA | F39: 52.D3 | G39: TS296A:1 | H39: 257-01 | I39: 52.D3 | M39: USED
A40: FT586:LI | B40: SC | C40: 24V586 | E40: 16GA | F40: 52.D3 | G40: TS257C:5 | H40: 257-01 | I40: 52.D4 | M40: USED
A41: HY2140A/B:BNC-A2 | B41: SC | C41: WA1418 | E41: CNET | F41: 5.B6 | G41: HY2180A/B:BNC-A | H41: 257-01 | I41: 5.B5 | M41: USED
A42: HY2140A/B:BNC-B2 | B42: SC | C42: WB1418 | E42: CNET | F42: 5.B6 | G42: HY2180A/B:BNC-B | H42: 257-01 | I42: 5.B5 | M42: USED
...

Sheet Panel Errors
A1: Panel Errors
A3: Project # | B3: 75751
A4: Project Name
A5: Revision | B5: D
A7: Controls DE
A8: Phone:
A9: Controls ME
A10: Phone:
A12: From | H12: To
A13: Device ID | B13: Location | C13: Cable (W) Conductor (SC) Jumper Clip (JC) | D13: Wire ID | E13: Wire No. | F13: Gauge/Size | G13: Page/Zone | H13: Device ID | I13: Location | J13: Page/Zone
A14: FRAME | B14: PANEL | C14: SC | D14: GRN/YEL | E14: GY250 | F14: 12GA | G14: 7.F1 | H14: RG250:1 | I14: 250-01 | J14: 7.F1
A15: FRAME | B15: PANEL | C15: SC | D15: GRN/YEL | E15: GY200 | F15: 12GA | G15: 7.F2 | H15: RG200:1 | I15: 250-01 | J15: 7.F2
A16: FRAME | B16: PANEL | C16: SC | E16: GYPE250 | F16: 8GA | G16: 6.D1 | H16: PE250:1 | I16: 250-01 | J16: 6.D1
A17: FRAME | B17: PANEL | C17: SC | D17: GRN/YEL | E17: GY256B | F17: 12GA | G17: 62.F2 | H17: RG256B:1 | I17: 256-02 | J17: 62.F2
A18: FRAME | B18: PANEL | C18: SC | D18: GRN/YEL | E18: GYPE256 | F18: 8GA | G18: 62.D1 | H18: PE256:1 | I18: 256-02 | J18: 62.D1
A19: FRAME | B19: PANEL | C19: SC | D19: GRN/YEL | E19: GY252A | F19: 12GA | G19: 42.F1 | H19: RG252A:1 | I19: 252-01 | J19: 42.F1
A20: FRAME | B20: PANEL | C20: SC | D20: GRN/YEL | E20: GY252B | F20: 12GA | G20: 42.F2 | H20: RG252B:1 | I20: 252-01 | J20: 42.F2
A21: FRAME | B21: PANEL | C21: SC | D21: GRN/YEL | E21: GY251 | F21: 12GA | G21: 38.F2 | H21: RG251:1 | I21: 251-01 | J21: 38.F2
E23: SolarTools ver. 24.0.84.24712 (Jul 31, 2025)
A24: Report date: 1/16/2026 11:44 PM

Sheet Cable Part Numbers
A1: Cable Part Numbers | D1: SolarTools ver. 24.0.84.24712 (Jul 31, 2025)
A2: Project # | B2: 75751
D3: Report date: 1/16/2026 11:45 PM
A4: Project Name
A6: Revision | B6: D
A8: Controls DE
A9: Phone:
A10: Controls ME
A11: Phone:
A13: Device ID | C13: Part Number | E13: Description
A14: W001 | C14: IDA NOT DEFINED | E14: 3 CONDUCTOR SHIELDED, SYTSTEM FUNCTION
A15: W002 | C15: IDA NOT DEFINED | E15: 2 CONDUCTOR SHIELDED, SYTSTEM FUNCTION
A16: W003 | C16: IDA NOT DEFINED | E16: 2 CONDUCTOR SHIELDED, SYTSTEM FUNCTION
A17: W004 | C17: IDA NOT DEFINED | E17: 2 CONDUCTOR SHIELDED, SYTSTEM FUNCTION
A18: W005 | C18: IDA NOT DEFINED | E18: 2 CONDUCTOR SHIELDED, SYTSTEM FUNCTION
A19: W006 | C19: IDA NOT DEFINED | E19: 2 CONDUCTOR SHIELDED, SYTSTEM FUNCTION
A20: W007 | C20: IDA NOT DEFINED | E20: 3 CONDUCTOR SHIELDED, SYTSTEM FUNCTION
A21: W008 | C21: IDA NOT DEFINED | E21: 2 CONDUCTOR SHIELDED, SYTSTEM FUNCTION
A22: W011 | C22: IDA NOT DEFINED | E22: 2 CONDUCTOR SHIELDED, SYTSTEM FUNCTION
A23: W012 | C23: IDA NOT DEFINED | E23: 2 CONDUCTOR SHIELDED, SYTSTEM FUNCTION
A24: W013 | C24: IDA NOT DEFINED | E24: 2 CONDUCTOR SHIELDED, SYTSTEM FUNCTION
... A92: WDS124 | C92: PART OF 1064851-4 | E92: CABLE, 6 CONDUCTOR UNSHIELDED PART OF SWITCH

Sheet Part Number List
A1: Part Number List | C1: SolarTools ver. 24.0.84.24712 (Jul 31, 2025)
A2: Project # | B2: 75751
C3: Report date: 1/16/2026 11:44 PM
A4: Project Name
A6: Revision | B6: D
A8: Controls DE
A9: Phone:
A10: Controls ME
A11: Phone:
A13: Device ID | B13: Part Number | C13: Description | D13: Location
A14: CR293A | B14: IDA NOT DEFINED | C14: DIODE | D14: 100-00
A15: CR293C11 | B15: IDA NOT DEFINED | C15: DIODE | D15: 100-00
A16: CR293C5 | B16: IDA NOT DEFINED | C16: DIODE | D16: 100-00
A17: CR293C7 | B17: IDA NOT DEFINED | C17: DIODE | D17: 100-00
A18: CR293C9 | B18: IDA NOT DEFINED | C18: DIODE | D18: 100-00
A19: CR341-1 | B19: IDA NOT DEFINED | C19: DIODE | D19: 100-00
A20: CR342-1 | B20: IDA NOT DEFINED | C20: DIODE | D20: 100-00
A22: AT1100 | B22: 1577354-4502 | C22: WORKSTATION, VERSAVIEW 1200XT | D22: 100-00J0980
A23: S112 | B23: 2380746-4,2380746-6 | C23: PUSHBUTTON SWITCH, EMERGENCY STOP SKID^(RED BUTTON) | D23: 100-00J0980
A24: S120 | B24: 2380746-1 | C24: PUSHBUTTON SWITCH, CASE DEPRESSURIZE | D24: 100-00J0980
A25: S155A | B25: 2380746-9 | C25: SELECTOR SWITCH, CONTROL | D25: 100-00J0980
... A121: RT2075-1 | B121: IDA NOT DEFINED | C121: THERMISTOR | D121: 250-01
A122: TB250 | B122: IDA NOT DEFINED | D122: 250-01
A123: TS200 | B123: IDA NOT DEFINED | D123: 250-01
A124: TS206 | B124: 701707C1 | D124: 250-01
A125: TS206A | B125: 701707C1 | D125: 250-01
A126: TS206B | B126: IDA NOT DEFINED | C126: TERMINAL STRIP, DOUBLE DIODE | D126: 250-01
A127: TS207 | B127: 701707C1 | D127: 250-01
A128: TS208 | B128: 701707C1 | D128: 250-01
A129: TS208C | B129: 701707C1 | D129: 250-01
A130: TS208D | B130: IDA NOT DEFINED | C130: TERMINAL STRIP, DOUBLE DIODE | D130: 250-01
A131: TS209 | B131: 701707C1 | D131: 250-01
A132: TS250A | B132: IDA NOT DEFINED | D132: 250-01
A133: TS250B | B133: IDA NOT DEFINED | D133: 250-01
A134: TS250C | B134: 701707C1 | D134: 250-01
A135: TS250D | B135: 701707C1 | D135: 250-01
A136: TS250E | B136: 701707C1 | D136: 250-01
A137: TS250F | B137: 701707C1 | D137: 250-01
A138: TS291 | B138: 701707C1 | D138: 250-01
A139: TS295 | B139: 701707C1 | D139: 250-01
...

Sheet 257-01 _S
A1: 257-01
A2: YARD VALVE & BOP PANEL
A3: Project # | B3: 75751
A4: Project Name
A5: Revision | B5: D
A7: Controls DE
A8: Phone:
A9: Controls ME
A10: Phone:
A12: From | G12: To
A13: Device ID | B13: Wire No. | C13: Wire ID | D13: Gauge/Size | E13: Length | F13: Device ID | G13: Location | H13: Bundle Name
A14: F2140A:LD | B14: F2140A | D14: 14GA | F14: UF2140:24V-1 | G14: 257-01
A15: F2140A:LI | B15: -24V14 | D15: 14GA | F15: TS257C:2 | G15: 257-01
A16: F2140A:LI | B16: -24V14 | D16: 14GA | F16: F2141:LI | G16: 257-01
A17: F2141:LD | B17: F2141 | D17: 14GA | F17: ZF2141:V34 | G17: 257-01
A18: F2180A:LD | B18: F2180A | D18: 14GA | F18: UF2180:24V-1 | G18: 257-01
A19: F2180A:LI | B19: -24V18 | D19: 14GA | F19: TS257C:4 | G19: 257-01
A20: F2180A:LI | B20: -24V18 | D20: 14GA | F20: F2181:LI | G20: 257-01
A21: F2181:LD | B21: F2181 | D21: 14GA | F21: ZF2181:V34 | G21: 257-01
A22: F257:LD | B22: -24V57 | D22: 12GA | F22: TS257C:1 | G22: 257-01
A23: F257A:LD | B23: F257A | D23: 22GA | F23: TB257:1 | G23: 257-01
A24: F257A:LI | B24: -24V57 | D24: 14GA | F24: TS257C:1 | G24: 257-01
A25: F2930:LD | B25: F2930 | D25: 14GA | F25: TS293A:1 | G25: 257-01
A26: F2930:LI | B26: -24V93 | D26: 14GA | F26: TS257C:3 | G26: 257-01
A27: FA257:1 | B27: F257A | C27: RED | D27: 22GA | F27: TB257:1 | G27: 257-01
A28: FA257:2 | B28: -0V | C28: BLK | D28: 22GA | F28: TB257:2 | G28: 257-01
A29: FT586:LD | B29: FT586 | D29: 14GA | F29: TS296A:1 | G29: 257-01
A30: FT586:LI | B30: -24V586 | D30: 16GA | F30: TS257C:5 | G30: 257-01
A31: HY2140A/B:BNC-A2 | B31: WA1418 | D31: CNET | F31: HY2180A/B:BNC-A | G31: 257-01
A32: HY2140A/B:BNC-B2 | B32: WB1418 | D32: CNET | F32: HY2180A/B:BNC-B | G32: 257-01
A33: HY2140A/B:TAP-A | B33: HY2140A | D33: 24GA | F33: UF2140:A | G33: 257-01
A34: HY2140A/B:TAP-B | B34: HY2140B | D34: 24GA | F34: UF2140:B | G34: 257-01
A35: HY2180A/B:TAP-A | B35: HY2180B | D35: 24GA | F35: UF2180:B | G35: 257-01
A36: HY2180A/B:TAP-B | B36: HY2180A | D36: 24GA | F36: UF2180:A | G36: 257-01
A37: K2930-1:11 | B37: DVFC564P | D37: 20GA | F37: TS293C:2 | G37: 257-01
A38: K2930-1:12 | B38: SVFC562 | D38: 20GA | F38: TS293C:1 | G38: 257-01
A39: K2930-1:14 | B39: F2930 | D39: 20GA | F39: TS293C:20 | G39: 257-01
A40: K2930-1:21 | B40: DVFC564 | D40: 20GA | F40: TS293C:3 | G40: 257-01
... A72: TS218B:1 | B72: -0V18 | D72: 12GA | F72: TS257D:4 | G72: 257-01
A73: TS218C:10 | B73: S511A | F73: TS218C:11 | G73: 257-01
...

Sheet 256-L2 _S
A1: 256-L2
A2: LEFT DOOR
A3: Project # | B3: 75751
A4: Project Name
A5: Revision | B5: D
A7: Controls DE
A8: Phone:
A9: Controls ME
A10: Phone:
A12: From | G12: To
A13: Device ID | B13: Wire No. | C13: Wire ID | D13: Gauge/Size | E13: Length | F13: Device ID | G13: Location | H13: Bundle Name
A14: DS1001:4a | B14: TCP06AP | D14: 20GA | F14: ZF2200:05 | G14: 256-L2
A15: DS1001:4b | B15: TCP06BP | D15: 20GA | F15: ZF2200:06 | G15: 256-L2
A16: DS1001:5a | B16: TCP06A | D16: 20GA | F16: ZF2200:COM22 | G16: 256-L2
A17: DS1001:5b | B17: TCP06B | D17: 20GA | F17: ZF2200:COM23 | G17: 256-L2
A18: DS1011:4a | B18: TCP09AP | D18: 20GA | F18: DS1011:4b | G18: 256-L2
A19: DS1011:4a | B19: TCP09AP | D19: 20GA | F19: ZF2200:13 | G19: 256-L2
A20: DS1011:5a | B20: TCP09A | F20: DS1011:5b | G20: 256-L2
A21: DS1011:5b | B21: TCP09A | D21: 20GA | F21: ZF2200:COM30 | G21: 256-L2
A22: DS1013:4a | B22: TCP08AP | D22: 20GA | F22: DS1013:4b | G22: 256-L2
A23: DS1013:4a | B23: TCP08AP | D23: 20GA | F23: ZF2200:12 | G23: 256-L2
A24: DS1013:5a | B24: TCP08A | F24: DS1013:5b | G24: 256-L2
A25: DS1013:5b | B25: TCP08A | D25: 20GA | F25: ZF2200:COM29 | G25: 256-L2
A26: DS1014:4a | B26: TCP02AP | D26: 20GA | F26: DS1014:4b | G26: 256-L2
A27: DS1014:4a | B27: TCP02AP | D27: 20GA | F27: ZF2200:01 | G27: 256-L2
A28: DS1014:5a | B28: TCP02A | F28: DS1014:5b | G28: 256-L2
A29: DS1014:5b | B29: TCP02A | D29: 20GA | F29: ZF2200:COM18 | G29: 256-L2
A30: DS1024:4a | B30: TCP12AP | D30: 20GA | F30: DS1024:4b | G30: 256-L2
A31: DS1024:4a | B31: TCP12AP | D31: 20GA | F31: TS220:1 | G31: 256-L2
A32: DS1024:5a | B32: -0V95 | F32: DS1024:5b | G32: 256-L2
A33: DS1059:4a | B33: TCP04AP | F33: DS1059:4b | G33: 256-L2
A34: DS1059:4b | B34: TCP04AP | D34: 20GA | F34: ZF2200:03 | G34: 256-L2
A35: DS1059:5a | B35: TCP04A | F35: DS1059:5b | G35: 256-L2
A36: DS1059:5b | B36: TCP04A | D36: 20GA | F36: ZF2200:COM20 | G36: 256-L2
A37: DS1073:4a | B37: TCP10AP | D37: 20GA | F37: DS1073:4b | G37: 256-L2
A38: DS1073:4a | B38: TCP10AP | D38: 20GA | F38: ZF2200:14 | G38: 256-L2
A39: DS1073:5a | B39: TCP10A | F39: DS1073:5b | G39: 256-L2
A40: DS1073:5b | B40: TCP10A | D40: 20GA | F40: ZF2200:COM31 | G40: 256-L2
A41: DS1075:4a | B41: TCP11AP | F41: DS1075:4b | G41: 256-L2
A42: DS1075:4b | B42: TCP11AP | D42: 20GA | F42: ZF2200:15 | G42: 256-L2
...

Sheet 256-03 _S
A1: 256-03
A2: HMI PANEL
A3: Project # | B3: 75751
A4: Project Name
A5: Revision | B5: D
A7: Controls DE
A8: Phone:
A9: Controls ME
A10: Phone:
A12: From | G12: To
A13: Device ID | B13: Wire No. | C13: Wire ID | D13: Gauge/Size | E13: Length | F13: Device ID | G13: Location | H13: Bundle Name
A14: HY2190A/B:BNC-A2 | B14: WA1909 | D14: CNET | F14: HY2290A/B:BNC-A1 | G14: 256-01
A15: HY2190A/B:BNC-B2 | B15: WB1909 | D15: CNET | F15: HY2290A/B:BNC-B1 | G15: 256-01
A16: HY2190A/B:BNC-A1 | B16: WA2019 | D16: CNET | F16: HY2200A/B:BNC-A2 | G16: 256-L2
A17: HY2190A/B:BNC-B1 | B17: WB2019 | D17: CNET | F17: HY2200A/B:BNC-B2 | G17: 256-L2

Sheet 256-02 _S
A1: 256-02
A2: CONTROL CONSOLE, LEFT SIDE PANEL
A3: Project # | B3: 75751
A4: Project Name
A5: Revision | B5: D
A7: Controls DE
A8: Phone:
A9: Controls ME
A10: Phone:
A12: From | G12: To
A13: Device ID | B13: Wire No. | C13: Wire ID | D13: Gauge/Size | E13: Length | F13: Device ID | G13: Location | H13: Bundle Name
A14: F256A:LD | B14: -24V56A | D14: 12GA | F14: TS256H:1 | G14: 256-02
A15: F256A:LI | B15: -24V | D15: 12GA | F15: TS256F:1 | G15: 256-02
A16: HY2210A/B:TAP-A | B16: HY2210A | D16: 24GA | F16: UF2210:A | G16: 256-02
A17: HY2210A/B:TAP-B | B17: HY2210B | D17: 24GA | F17: UF2210:B | G17: 256-02
A18: RG256A:1 | B18: TS256I3 | D18: 12GA | F18: TS256I:3 | G18: 256-02
A19: TS256F:2 | B19: -24V | D19: 12GA | F19: TS256F:1 | G19: 256-02
A20: TS256G:2 | B20: -0V | D20: 12GA | F20: TS256G:1 | G20: 256-02
A21: TS256I:1 | B21: -0V | D21: 12GA | F21: TS256G:1 | G21: 256-02
A22: UF2210:24V-1 | B22: -24V21 | D22: 16GA | F22: TS256H:4 | G22: 256-02
A23: UF2210:24V-2 | B23: UF2210P | D23: 20GA | F23: ZF2210:V34 | G23: 256-02
A24: UF2210:COM-1 | B24: -0V21 | D24: 16GA | F24: TS256I:4 | G24: 256-02
A25: UF2210:COM-2 | B25: UF2210N | D25: 20GA | F25: ZF2210:COM16 | G25: 256-02
... A47: M210:2 | B47: M210N | D47: 20GA | F47: ZF2201:COM28 | G47: 256-L2

Sheet 256-01 _S
A1: 256-01
A2: POWER DISTRIBUTION PANEL
A3: Project # | B3: 75751
A4: Project Name
A5: Revision | B5: D
A7: Controls DE
A8: Phone:
A9: Controls ME
A10: Phone:
A12: From | G12: To
A13: Device ID | B13: Wire No. | C13: Wire ID | D13: Gauge/Size | E13: Length | F13: Device ID | G13: Location | H13: Bundle Name
A14: F256:LD | B14: -24V56 | D14: 12GA | F14: TS256C:1 | G14: 256-01
A15: F256:LI | B15: -24V | D15: 12GA | F15: TS256A:1 | G15: 256-01
A16: TS256D:1 | B16: -0V | D16: 12GA | F16: TS256B:1 | G16: 256-01
A17: TS256C:4 | B17: -24V73 | D17: 16GA | F17: S273-1:1 | G17: 200-T1
A18: TS256D:4 | B18: -0V73 | D18: 12GA | F18: DS273-1:1B | G18: 200-T1
A19: HY2290A/B:BNC-A2 | B19: WA2909 | D19: CNET | F19: HY2090A/B:BNC-A2 | G19: 250-01
A20: HY2290A/B:BNC-B2 | B20: WB2909 | D20: CNET | F20: HY2090A/B:BNC-B2 | G20: 250-01
A21: TS256A:1 | B21: -24V | D21: 12GA | F21: TS256F:2 | G21: 256-02
A22: TS256B:1 | B22: -0V | D22: 12GA | F22: TS256G:2 | G22: 256-02
A23: TS256E:1 | B23: S1012 | D23: 20GA | F23: TS256J:1 | G23: 256-02
A24: TS256E:2 | B24: S1012R | D24: 20GA | F24: TS256J:2 | G24: 256-02
A25: TS256E:3 | B25: K29512B24 | D25: 20GA | F25: TS256J:3 | G25: 256-02
... A40: TS256E:6 | B40: K29521A1 | D40: 20GA | F40: S1024:1 | G40: 256-L2

Sheet 252-01 _S
A1: 252-01
A2: HP COMPRESSOR PANEL
A3: Project # | B3: 75751
A4: Project Name
A5: Revision | B5: D
A7: Controls DE
A8: Phone:
A9: Controls ME
A10: Phone:
A12: From | G12: To
A13: Device ID | B13: Wire No. | C13: Wire ID | D13: Gauge/Size | E13: Length | F13: Device ID | G13: Location | H13: Bundle Name
A14: F2120A:LD | B14: F2120A | D14: 14GA | F14: UF2120:24V-1 | G14: 252-01
A15: F2120A:LI | B15: -24V12 | D15: 12GA | F15: TS252C:2 | G15: 252-01
A16: F2120A:LI | B16: -24V12 | D16: 12GA | F16: F2121:LI | G16: 252-01
A17: F2121:LD | B17: F2121 | D17: 14GA | F17: ZF2121:V34 | G17: 252-01
A18: F2130A:LD | B18: F2130A | D18: 14GA | F18: UF2130:24V-1 | G18: 252-01
A19: F2130A:LI | B19: -24V13 | D19: 14GA | F19: TS252C:3 | G19: 252-01
A20: F252:LD | B20: -24V52 | D20: 12GA | F20: TS252C:1 | G20: 252-01
A21: F252:LI | B21: -24V | D21: 12GA | F21: TS252A:1 | G21: 252-01
A22: F252A:LD | B22: F252A | D22: 14GA | F22: TB252:1 | G22: 252-01
A23: F252A:LI | B23: -24V52 | D23: 14GA | F23: TS252C:1 | G23: 252-01
A24: FA252:1 | B24: F252A | C24: RED | D24: 22GA | F24: TB252:1 | G24: 252-01
A25: FA252:2 | B25: -0V | C25: BLK | D25: 22GA | F25: TB252:2 | G25: 252-01
A26: HY2120A/B:BNC-A2 | B26: WA1213 | D26: CNET | F26: HY2130A/B:BNC-A1 | G26: 252-01
A27: HY2120A/B:BNC-B2 | B27: WB1213 | D27: CNET | F27: HY2130A/B:BNC-B1 | G27: 252-01
A28: HY2120A/B:TAP-A | B28: HY2120A | D28: 24GA | F28: UF2120:A | G28: 252-01
A29: HY2120A/B:TAP-B | B29: HY2120B | D29: 24GA | F29: UF2120:B | G29: 252-01
A30: HY2130A/B:TAP-A | B30: HY2130A | D30: 24GA | F30: UF2130:A | G30: 252-01
A31: HY2130A/B:TAP-B | B31: HY2130B | D31: 24GA | F31: UF2130:B | G31: 252-01
A32: K2121-10:14 | B32: K212110A14 | D32: 20GA | F32: ZF2121:10 | G32: 252-01
A33: K2121-10:21 | B33: K29401A12 | D33: 20GA | F33: K2940-1:12 | G33: 252-01
A34: K2121-10:24 | B34: K212110B | D34: 20GA | F34: ZF2120:V35 | G34: 252-01
A35: K2121-10:A1 | B35: K212110A1 | F35: ZF2121:V45 | G35: 252-01
A36: K2940-1:14 | B36: K29401A14 | D36: 20GA | F36: ZF2120:00 | G36: 252-01
A37: K2940-1:A2 | B37: -0V94 | D37: 14GA | F37: TS252D:4 | G37: 252-01
A38: PS2130:NEG | B38: UF2130N | D38: 16GA | F38: UF2130:COM-2 | G38: 252-01
A39: PS2130:POS | B39: UF2130P | D39: 16GA | F39: UF2130:24V-2 | G39: 252-01
A40: RG212:1 | B40: -0V12 | D40: 14GA | F40: TS212:2 | G40: 252-01
A41: TB252:2 | B41: -0V | D41: 12GA | F41: TS252D:1 | G41: 252-01
A42: TS212:1 | B42: -0V12 | D42: 12GA | F42: TS252D:2 | G42: 252-01
...

Sheet 251-01 _S
A1: 251-01
A2: TURBINE VIBRATION PANEL
A3: Project # | B3: 75751
A4: Project Name
A5: Revision | B5: D
A7: Controls DE
A8: Phone:
A9: Controls ME
A10: Phone:
A12: From | G12: To
A13: Device ID | B13: Wire No. | C13: Wire ID | D13: Gauge/Size | E13: Length | F13: Device ID | G13: Location | H13: Bundle Name
A14: F251:LD | B14: -24V51 | D14: 12GA | F14: TS251C:1 | G14: 251-01
A15: F251A:LD | B15: F251A | D15: 22GA | F15: TB251:1 | G15: 251-01
A16: F251A:LI | B16: -24V51 | D16: 14GA | F16: TS251C:1 | G16: 251-01
A17: FA251:1 | B17: F251A | C17: RED | D17: 22GA | F17: TB251:1 | G17: 251-01
A18: FA251:2 | B18: -0V | C18: BLK | D18: 22GA | F18: TB251:2 | G18: 251-01
A19: HY2110A/B:BNC-A1 | B19: WA1115 | D19: CNET | F19: HY2150A/B:BNC-A2 | G19: 251-01
A20: HY2110A/B:BNC-B1 | B20: WB1115 | D20: CNET | F20: HY2150A/B:BNC-B2 | G20: 251-01
A21: HY2110A/B:TAP-A | B21: HY2110A | D21: 24GA | F21: UF2110:A | G21: 251-01
A22: HY2110A/B:TAP-B | B22: HY2110B | D22: 24GA | F22: UF2110:B | G22: 251-01
A23: HY2150A/B:TAP-A | B23: HY2150A | D23: 24GA | F23: UF2150:A | G23: 251-01
A24: HY2150A/B:TAP-B | B24: HY2150B | D24: 24GA | F24: UF2150:B | G24: 251-01
A25: PS2110:NEG | B25: UF2110N | D25: 16GA | F25: UF2110:COM-2 | G25: 251-01
A26: PS2110:POS | B26: UF2110P | D26: 16GA | F26: UF2110:24V-2 | G26: 251-01
A27: PS2150:NEG | B27: UF2150N | D27: 16GA | F27: UF2150:COM-2 | G27: 251-01
A28: PS2150:POS | B28: UF2150P | D28: 16GA | F28: UF2150:24V-2 | G28: 251-01
A29: TB251:2 | B29: -0V | D29: 8GA | F29: TS251D:1 | G29: 251-01
A30: UF2110:24V-1 | B30: -24V11 | D30: 16GA | F30: TS251C:2 | G30: 251-01
... A33: UF2150:COM-1 | B33: -0V15 | D33: 16GA | F33: TS251D:3 | G33: 251-01
A34: ZZ2110:A | B34: -350K | C34: COAX | D34: 20GA | F34: TV350K:1 | G34: 305-02
A35: ZZ2111T:A | B35: -351Y | C35: COAX | D35: 20GA | F35: TV351Y:1 | G35: 305-02
A36: ZZ2111T:B | B36: -351X | C36: COAX | D36: 20GA | F36: TV351X:1 | G36: 305-02
A37: ZZ2112T:A | B37: -352Y | C37: COAX | D37: 20GA | F37: TV352Y:1 | G37: 305-02
A38: ZZ2112T:B | B38: -352X | C38: COAX | D38: 20GA | F38: TV352X:1 | G38: 305-02
A39: ZZ2113T:A | B39: -353Y | C39: COAX | D39: 20GA | F39: TV353Y:1 | G39: 305-02
A40: ZZ2113T:B | B40: -353X | C40: COAX | D40: 20GA | F40: TV353X:1 | G40: 305-02
A41: ZZ2114T:A | B41: -351Z | C41: COAX | D41: 20GA | F41: TV351Z:1 | G41: 305-02
A42: ZZ2150:A | B42: -360K | C42: COAX | D42: 20GA | F42: TV355K:1 | G42: 305-02
A43: ZZ2151T:A | B43: -354Y | C43: COAX | D43: 20GA | F43: TV354Y:1 | G43: 305-02
A44: ZZ2151T:B | B44: -354X | C44: COAX | D44: 20GA | F44: TV354X:1 | G44: 305-02
...

Sheet 250-01 _S
A1: 250-01
A2: CONTROL CONSOLE
A3: Project # | B3: 75751
A4: Project Name
A5: Revision | B5: D
A7: Controls DE
A8: Phone:
A9: Controls ME
A10: Phone:
A12: From | G12: To
A13: Device ID | B13: Wire No. | C13: Wire ID | D13: Gauge/Size | E13: Length | F13: Device ID | G13: Location | H13: Bundle Name
A14: AH172:1 | B14: AH172P | D14: 16GA | F14: ZF2087:15 | G14: 250-01
A15: AH172:2 | B15: AH172N | D15: 16GA | F15: ZF2087:COM32 | G15: 250-01
A16: BT2010:1 | B16: BT2010 | D16: CABLE | F16: U2010:bat | G16: 250-01
A17: F200:LD | B17: -24V | D17: 10GA | F17: TS250A:1 | G17: 250-01
A18: F200:LI | B18: F2001 | D18: 10GA | F18: PS200:1POS | G18: 250-01
A19: F200-1:LD | B19: PS200P | D19: 12GA | F19: PS200:3 | G19: 250-01
A20: F200-3:LI | B20: -52005 | D20: COMB | F20: F200-2:LI | G20: 250-01
A21: F200-3:LI | B21: -52005 | D21: COMB | F21: F200-4:LI | G21: 250-01
A22: F200-4:LI | B22: -52005 | D22: COMB | F22: F200-5:LI | G22: 250-01
A23: F2010:LD | B23: F2010A | D23: 14GA | F23: PS2010:POS | G23: 250-01
A24: F2010:LI | B24: -24V01 | D24: 12GA | F24: TS250C:5 | G24: 250-01
A25: F2060A:LI | B25: F2060A | D25: 14GA | F25: UF2060:24V-1 | G25: 250-01
A26: F2061:LD | B26: -24V06 | F26: F2060A:LD | G26: 250-01
A27: F2061:LD | B27: -24V06 | F27: F2061A:LD | G27: 250-01
A28: F2061:LI | B28: F2061 | D28: 14GA | F28: ZF2061:V34 | G28: 250-01
A29: F2061A:LD | B29: -24V06 | F29: F2062:LD | G29: 250-01
A30: F2061A:LI | B30: F2061A | D30: 14GA | F30: K2061-0:14 | G30: 250-01
A31: F2062:LD | B31: -24V06 | F31: F2063:LD | G31: 250-01
A32: F2062:LI | B32: F2062 | D32: 14GA | F32: ZF2062:V34 | G32: 250-01
A33: F2063:LD | B33: -24V06 | D33: COMB | F33: TS250E:3 | G33: 250-01
A34: F2063:LI | B34: F2063 | D34: 14GA | F34: ZF2063:V34 | G34: 250-01
A35: F2070A:LD | B35: F2070A | D35: 14GA | F35: UF2070:24V-1 | G35: 250-01
A36: F2070A:LI | B36: -24V07 | D36: 12GA | F36: TS250E:2 | G36: 250-01
A37: F2080:LD | B37: F2080A | D37: 14GA | F37: UF2080:24V-1 | G37: 250-01
A38: F2080:LI | B38: -24V08 | D38: COMB | F38: TS250C:3 | G38: 250-01
A39: F2080:LI | B39: -24V08 | D39: COMB | F39: F2081:LI | G39: 250-01
A40: F2081:LD | B40: F2081 | D40: 14GA | F40: ZF2081:V34 | G40: 250-01
A41: F2081:LI | B41: -24V08 | D41: COMB | F41: F2082A:LI | G41: 250-01
A42: F2090A:LD | B42: F2090A | D42: 14GA | F42: UF2090:24V-1 | G42: 250-01
...

Sheet 200-T1 _S
A1: 200-T1
A2: CONSOLE CEILING
A3: Project # | B3: 75751
A4: Project Name
A5: Revision | B5: D
A7: Controls DE
A8: Phone:
A9: Controls ME
A10: Phone:
A12: From | G12: To
A13: Device ID | B13: Wire No. | C13: Wire ID | D13: Gauge/Size | E13: Length | F13: Device ID | G13: Location | H13: Bundle Name
A14: DS273-1:1W | B14: S2731 | D14: 16GA | F14: S273-1:2 | G14: 200-T1
A15: DS273-1:1B | B15: -0V73 | D15: 12GA | F15: TS256D:4 | G15: 256-01
A16: S273-1:1 | B16: -24V73 | D16: 16GA | F16: TS256C:4 | G16: 256-01
A17: AH272:1 | B17: AH272 | D17: 16GA | F17: ZF2201:10 | G17: 256-L2
A18: AH272:2 | B18: AH272N | D18: 16GA | F18: ZF2201:COM27 | G18: 256-L2

Sheet 100-00J0980 _S
A1: 100-00J0980
A2: UPGRADE
A3: Project # | B3: 75751
A4: Project Name
A5: Revision | B5: D
A7: Controls DE
A8: Phone:
A9: Controls ME
A10: Phone:
A12: From | G12: To
A13: Device ID | B13: Wire No. | C13: Wire ID | D13: Gauge/Size | E13: Length | F13: Device ID | G13: Location | H13: Bundle Name
A14: AT1100:V- | B14: -0V10 | C14: WHT | D14: 14 | E14: 240 | F14: TS1100:3 | G14: 100-00J0980 | H14: AT1100
A15: AT1100:V+ | B15: F2100 | C15: WHT | D15: 14 | E15: 240 | F15: TS1100:2 | G15: 100-00J0980
A17: DS111:X1 | B17: DS111 | C17: WHT | D17: 20 | E17: 240 | F17: ZF2087:13 | G17: 250-01 | H17: DS111
A18: DS111:X2 | B18: DS111N | C18: WHT | D18: 20 | E18: 240 | F18: ZF2087:COM30 | G18: 250-01
A20: S112:21 | B20: ESTOP | C20: WHT | D20: 20 | E20: 240 | F20: TS295:14 | G20: 250-01 | H20: S112
A21: S112:22 | B21: S1012R | C21: WHT | D21: 20 | E21: 240 | F21: TS295:13 | G21: 250-01
A22: S112:12 | B22: S212BN | C22: WHT | D22: 20 | E22: 240 | F22: ZF2087:09 | G22: 250-01
A23: S112:11 | B23: S212BP | C23: WHT | D23: 20 | E23: 240 | F23: ZF2087:V44 | G23: 250-01
A25: S114:24 | B25: S1141A | C25: WHT | D25: 20 | E25: 240 | F25: ZF2087:04 | G25: 250-01 | H25: S114
A26: S114:23 | B26: S1141AP | C26: WHT | D26: 20 | E26: 240 | F26: ZF2087:V39 | G26: 250-01
A28: S117:24 | B28: S1171A | C28: WHT | D28: 20 | E28: 240 | F28: ZF2087:03 | G28: 250-01 | H28: S117
A29: S117:23 | B29: S1171AP | C29: WHT | D29: 20 | E29: 240 | F29: ZF2087:V38 | G29: 250-01
A31: S120:11 | B31: S1201A | C31: WHT | D31: 20 | E31: 240 | F31: ZF2082:02 | G31: 250-01 | H31: S120
A32: S120:12 | B32: S1201AP | C32: WHT | D32: 20 | E32: 240 | F32: ZF2082:V37 | G32: 250-01
A34: S154:14-B2 | B34: S1541A | C34: WHT | D34: 20 | E34: 240 | F34: ZF2087:08 | G34: 250-01 | H34: S154
A35: S154:13-B2 | B35: S1541AP | C35: WHT | D35: 20 | E35: 240 | F35: ZF2087:V43 | G35: 250-01
A36: S154:14-B1 | B36: S1541B | C36: WHT | D36: 20 | E36: 240 | F36: ZF2087:07 | G36: 250-01
A37: S154:13-B1 | B37: S1541BP | C37: WHT | D37: 20 | E37: 240 | F37: ZF2087:V42 | G37: 250-01
A39: S155A:14-B1 | B39: S1551B | C39: WHT | D39: 20 | E39: 240 | F39: ZF2082:01 | G39: 250-01 | H39: S155
A40: S155A:13-B1 | B40: S1551BP | C40: WHT | D40: 20 | E40: 240 | F40: ZF2082:V36 | G40: 250-01
A42: S172:12 | B42: S1721B | C42: WHT | D42: 20 | E42: 240 | F42: ZF2087:02 | G42: 250-01 | H42: S172
A43: S172:11 | B43: S1721BP | C43: WHT | D43: 20 | E43: 240 | F43: ZF2087:V37 | G43: 250-01
A45: TS1100:2 | B45: F2100 | C45: WHT | D45: 14 | E45: 240 | F45: F2100:LD | G45: 250-01 | H45: TS1100
A47: TS1100:3 | B47: -0V10 | C47: WHT | D47: 12 | E47: 240 | F47: TS250D:6 | G47: 250-01

Sheet 100-00 _S
A1: 100-00
A2: UPGRADE
A3: Project # | B3: 75751
A4: Project Name
A5: Revision | B5: D
A7: Controls DE
A8: Phone:
A9: Controls ME
A10: Phone:
A12: From | G12: To
A13: Device ID | B13: Wire No. | C13: Wire ID | D13: Gauge/Size | E13: Length | F13: Device ID | G13: Location | H13: Bundle Name

Sheet Bundle Tag Info
A1: TX GAS TRANS #2
A2: J0980CB
A3: Rev D.1
