Workbook

Sheet LIGHTS_S
A1: JB71 B,BOX CONTROL
A2: LIGHTS
A3: Project # | B3: 4N621
A4: Project Name | B4: Perenco CLZ - Power Units
A5: Revision | B5: 0.1
A7: Controls DE
A8: Phone:
A9: Controls ME
A10: Phone:
A12: From | G12: To
A13: Device ID | B13: Wire No. | C13: Wire ID | D13: Gauge/Size | E13: Length | F13: Device ID | G13: Location | H13: Bundle Name
A14: EL0100:2- | B14: -0V | C14: WHT | D14: 16 | E14: 220 | F14: XT0005:4 | G14: DC | H14: EL0
A15: EL0101:2- | B15: -0V | C15: WHT | D15: 16 | E15: 120 | F15: XT0005:3 | G15: DC
A16: EL0100:1+ | B16: FU0005 | C16: WHT | D16: 16 | E16: 220 | F16: XT0005:2 | G16: DC
A17: EL0101:1+ | B17: FU0005 | C17: WHT | D17: 16 | E17: 120 | F17: XT0005:1 | G17: DC

Sheet GPP FULL(C)_S
A1: JB71 C,PNL GPP FULL
A3: Project # | B3: 4N621
A4: Project Name | B4: Perenco CLZ - Power Units
A5: Revision | B5: 0.1
A7: Controls DE
A8: Phone:
A9: Controls ME
A10: Phone:
A12: From | G12: To
A13: Device ID | B13: Wire No. | C13: Wire ID | D13: Gauge/Size | E13: Length | F13: Device ID | G13: Location | H13: Bundle Name
A14: AT4000:X6-2 | B14: XT07864 | C14: RED | D14: 16R | E14: 60 | F14: AT4000:X6-4 | G14: GPP FULL | H14: AT RED
A15: AT4000:X6-4 | B15: XT07864 | C15: RED | D15: 16R | E15: 60 | F15: AT4000:X6-6 | G15: GPP FULL
A17: AT4000:X4-3 | B17: XT07814 | C17: BLU | D17: 12B | E17: 60 | F17: AT4000:X4-6 | G17: GPP FULL | H17: AT BLU
A18: AT4000:X4-6 | B18: XT07814 | C18: BLU | D18: 12B | E18: 60 | F18: AT4000:X4-9 | G18: GPP FULL
A19: AT4000:X3-3 | B19: XT07841 | C19: BLU | D19: 12B | E19: 60 | F19: AT4000:X3-6 | G19: GPP FULL
A20: AT4000:X3-6 | B20: XT07841 | C20: BLU | D20: 12B | E20: 60 | F20: AT4000:X3-9 | G20: GPP FULL
A22: AT4000:X6-5 | B22: XT07861 | C22: RED | D22: 16R | E22: 300 | F22: XT0786:1 | G22: DC | H22: AT RED-DC
A23: AT4000:X6-3 | B23: XT07862 | C23: RED | D23: 16R | E23: 300 | F23: XT0786:2 | G23: DC
A24: AT4000:X6-1 | B24: XT07863 | C24: RED | D24: 16R | E24: 300 | F24: XT0786:3 | G24: DC
A25: AT4000:X6-2 | B25: XT07864 | C25: RED | D25: 16R | E25: 300 | F25: XT0786:4 | G25: DC
A26: AT4000:X6-7 | B26: XT07865 | C26: RED | D26: 16R | E26: 300 | F26: XT0786:5 | G26: DC
A27: AT4000:X6-8 | B27: XT07867 | C27: RED | D27: 16R | E27: 300 | F27: XT0786:6 | G27: DC
A29: AT4000:X4-2 | B29: XT07811 | C29: BLU | D29: 12B | E29: 300 | F29: XT0781:1 | G29: DC | H29: AT BLU-DC
A30: AT4000:X4-5 | B30: XT07812 | C30: BLU | D30: 12B | E30: 300 | F30: XT0781:2 | G30: DC
A31: AT4000:X4-8 | B31: XT07813 | C31: BLU | D31: 12B | E31: 300 | F31: XT0781:3 | G31: DC
A32: AT4000:X4-9 | B32: XT07814 | C32: BLU | D32: 12B | E32: 300 | F32: XT0781:4 | G32: DC
A33: AT4000:X3-9 | B33: XT07841 | C33: BLU | D33: 12B | E33: 300 | F33: XT0784:1 | G33: DC
A34: AT4000:X3-8 | B34: XT07842 | C34: BLU | D34: 12B | E34: 300 | F34: XT0784:2 | G34: DC
A35: AT4000:X3-5 | B35: XT07843 | C35: BLU | D35: 12B | E35: 300 | F35: XT0784:3 | G35: DC
A36: AT4000:X3-2 | B36: XT07844 | C36: BLU | D36: 12B | E36: 300 | F36: XT0784:4 | G36: DC
A37: AT4000:X3-10 | B37: XT07851 | C37: BLU | D37: 12B | E37: 300 | F37: XT0785:1 | G37: DC
A38: AT4000:X3-11 | B38: XT07852 | C38: BLU | D38: 12B | E38: 300 | F38: XT0785:2 | G38: DC
A39: AT4000:X3-12 | B39: XT07853 | C39: BLU | D39: 12B | E39: 300 | F39: XT0785:3 | G39: DC
A41: AT4000:X104-4 | B41: AT4000X1044 | C41: WHT | D41: 20 | E41: 260 | F41: XT4002:10 | G41: GEN CTRL | H41: AT-GEN
A42: AT4000:X104-5 | B42: AT4000X1045 | C42: WHT | D42: 20 | E42: 260 | F42: XT4002:11 | G42: GEN CTRL
A43: AT4000:X1-10 | B43: AT4000X110 | C43: WHT | D43: 20 | E43: 260 | F43: XT4001:3 | G43: GEN CTRL
A44: AT4000:X1-11 | B44: AT4000X111 | C44: WHT | D44: 20 | E44: 260 | F44: XT4001:4 | G44: GEN CTRL
A45: AT4000:X1-12 | B45: AT4000X112 | C45: WHT | D45: 20 | E45: 260 | F45: XT4001:5 | G45: GEN CTRL
A46: AT4000:X1-13 | B46: AT4000X113 | C46: WHT | D46: 20 | E46: 260 | F46: XT4001:6 | G46: GEN CTRL
A47: AT4000:X1-14 | B47: AT4000X114 | C47: WHT | D47: 20 | E47: 260 | F47: XT4001:7 | G47: GEN CTRL
...

Sheet DOOR CTRL(B)_S
A1: JB71 B,DOOR CTRL
A3: Project # | B3: 4N621
A4: Project Name | B4: Perenco CLZ - Power Units
A5: Revision | B5: 0.1
A7: Controls DE
A8: Phone:
A9: Controls ME
A10: Phone:
A12: From | G12: To
A13: Device ID | B13: Wire No. | C13: Wire ID | D13: Gauge/Size | E13: Length | F13: Device ID | G13: Location | H13: Bundle Name
A14: AT1100:NEG | B14: -0V | C14: WHT | D14: 14 | E14: 220 | F14: XT0070:12 | G14: CTRL1 | H14: AT
A15: AT1100:POS | B15: FU1100 | C15: WHT | D15: 14 | E15: 220 | F15: FU1100:LD | G15: CTRL1

Sheet DOOR OPR(B)_S
A1: JB71 B,DOOR OPR
A3: Project # | B3: 4N621
A4: Project Name | B4: Perenco CLZ - Power Units
A5: Revision | B5: 0.1
A7: Controls DE
A8: Phone:
A9: Controls ME
A10: Phone:
A12: From | G12: To
A13: Device ID | B13: Wire No. | C13: Wire ID | D13: Gauge/Size | E13: Length | F13: Device ID | G13: Location | H13: Bundle Name
A14: HA0472:N | B14: -0V | C14: WHT | D14: 20 | E14: 360 | F14: XT0070:11 | G14: CTRL1 | H14: HA0472
A15: HA0472:Lb | B15: KA087511 | C15: WHT | D15: 20 | E15: 360 | F15: KA0875:11 | G15: CTRL1
A17: SA0471:13 | B17: SA047113 | C17: WHT | D17: 20 | E17: 360 | F17: AF0091:36 | G17: CTRL1 | H17: SA0471
A18: SA0471:14 | B18: SA047114 | C18: WHT | D18: 20 | E18: 360 | F18: AF0091:04 | G18: CTRL1
A19: SA0471:23 | B19: SA047123 | C19: WHT | D19: 20 | E19: 360 | F19: AF0091:35 | G19: CTRL1
A20: SA0471:24 | B20: SA047124 | C20: WHT | D20: 20 | E20: 360 | F20: AF0091:03 | G20: CTRL1
A22: SA0473:13 | B22: SA047313 | C22: WHT | D22: 20 | E22: 360 | F22: AF0091:40 | G22: CTRL1 | H22: SA0473
A23: SA0473:14 | B23: SA047314 | C23: WHT | D23: 20 | E23: 360 | F23: AF0091:08 | G23: CTRL1
A24: SA0473:21 | B24: SA047321 | C24: WHT | D24: 20 | E24: 360 | F24: AF0091:39 | G24: CTRL1
A25: SA0473:22 | B25: SA047322 | C25: WHT | D25: 20 | E25: 360 | F25: AF0091:07 | G25: CTRL1
A27: SA0475:13 | B27: SA047513 | C27: WHT | D27: 20 | E27: 360 | F27: AF0091:38 | G27: CTRL1 | H27: SA0475
A28: SA0475:14 | B28: SA047514 | C28: WHT | D28: 20 | E28: 360 | F28: AF0091:06 | G28: CTRL1
A29: SA0475:23 | B29: SA047523 | C29: WHT | D29: 20 | E29: 360 | F29: AF0091:37 | G29: CTRL1
A30: SA0475:24 | B30: SA047524 | C30: WHT | D30: 20 | E30: 360 | F30: AF0091:05 | G30: CTRL1
A32: SB0333:11 | B32: FU0125 | C32: WHT | D32: 20 | E32: 360 | F32: XT0091:9 | G32: CTRL1 | H32: SB0333
A33: SB0333:12 | B33: SB033312 | C33: WHT | D33: 20 | E33: 360 | F33: XT0091:10 | G33: CTRL1
A34: SB0333:21 | B34: SB033321 | C34: WHT | D34: 20 | E34: 360 | F34: AF0091:43 | G34: CTRL1
A35: SB0333:22 | B35: SB033322 | C35: WHT | D35: 20 | E35: 360 | F35: AF0091:11 | G35: CTRL1
A37: SB0471:1 | B37: SB04711 | C37: WHT | D37: 20 | E37: 360 | F37: AF0091:32 | G37: CTRL1 | H37: SB0471
A38: SB0471:2 | B38: SB04712 | C38: WHT | D38: 20 | E38: 360 | F38: AF0091:00 | G38: CTRL1
A40: SB0472:11 | B40: ESTOPA | C40: WHT | D40: 20 | E40: 360 | F40: XT0091:7 | G40: CTRL1 | H40: SB0472
A41: SB0472:12 | B41: SB047212 | C41: WHT | D41: 20 | E41: 360 | F41: XT0091:8 | G41: CTRL1
A43: SB0472:21 | B43: SB047221 | C43: WHT | D43: 20 | E43: 360 | F43: AF0381:38 | G43: CTRL2
A44: SB0472:22 | B44: SB047222 | C44: WHT | D44: 20 | E44: 360 | F44: AF0381:06 | G44: CTRL2
A46: SB0473:3 | B46: SB04733 | C46: WHT | D46: 20 | E46: 360 | F46: AF0091:33 | G46: CTRL1 | H46: SB0473
A47: SB0473:4 | B47: SB04734 | C47: WHT | D47: 20 | E47: 360 | F47: AF0091:01 | G47: CTRL1
A49: SB0474:3 | B49: SB04743 | C49: WHT | D49: 20 | E49: 360 | F49: AF0091:34 | G49: CTRL1 | H49: SB0474
A50: SB0474:4 | B50: SB04744 | C50: WHT | D50: 20 | E50: 360 | F50: AF0091:02 | G50: CTRL1
A52: SH0470:1 | B52: SH04701 | C52: WHT | D52: 20 | E52: 360 | F52: AF0091:42 | G52: CTRL1 | H52: SH0470
A53: SH0470:2 | B53: SH04702 | C53: WHT | D53: 20 | E53: 360 | F53: AF0091:10 | G53: CTRL1
...

Sheet EQP DOOR(C)_S
A1: JB71 C,DOOR PNL EQP
A3: Project # | B3: 4N621
A4: Project Name | B4: Perenco CLZ - Power Units
A5: Revision | B5: 0.1
A7: Controls DE
A8: Phone:
A9: Controls ME
A10: Phone:
A12: From | G12: To
A13: Device ID | B13: Wire No. | C13: Wire ID | D13: Gauge/Size | E13: Length | F13: Device ID | G13: Location | H13: Bundle Name
A14: HL0171:X1 | B14: HL0171X1 | C14: WHT | D14: 16 | E14: 60 | F14: HL0171:X4(-) | G14: DOOR EQP | H14: HL0171
A16: HL0171:X2 | B16: HL0171X2 | C16: WHT | D16: 16 | E16: 260 | F16: XT0171:38 | G16: EQP CTRL
A17: HL0171:X2 | B17: HL0171X2 | C17: WHT | D17: 16 | E17: 260 | F17: XT0171:37 | G17: EQP CTRL
A18: HL0171:X3(+) | B18: HL0171X3 | C18: WHT | D18: 16 | E18: 260 | F18: XT0171:36 | G18: EQP CTRL
A19: HL0171:X3(+) | B19: HL0171X3 | C19: WHT | D19: 16 | E19: 260 | F19: XT0171:35 | G19: EQP CTRL
A21: HL0172:X1 | B21: HL0172X1 | C21: WHT | D21: 16 | E21: 60 | F21: HL0172:X4(-) | G21: DOOR EQP | H21: HL0172
A23: HL0172:X2 | B23: HL0172X2 | C23: WHT | D23: 16 | E23: 260 | F23: XT0171:42 | G23: EQP CTRL
A24: HL0172:X2 | B24: HL0172X2 | C24: WHT | D24: 16 | E24: 260 | F24: XT0171:41 | G24: EQP CTRL
A25: HL0172:X3(+) | B25: HL0172X3 | C25: WHT | D25: 16 | E25: 260 | F25: XT0171:40 | G25: EQP CTRL
A26: HL0172:X3(+) | B26: HL0172X3 | C26: WHT | D26: 16 | E26: 260 | F26: XT0171:39 | G26: EQP CTRL
A28: SA0170:13 | B28: SA017013 | C28: WHT | D28: 16 | E28: 260 | F28: AT0170:11 | G28: EQP CTRL | H28: SA0170
A29: SA0170:14 | B29: SA017014 | C29: WHT | D29: 16 | E29: 260 | F29: AT0170:12 | G29: EQP CTRL
A30: SA0170:21 | B30: SA01702C | C30: WHT | D30: 16 | E30: 260 | F30: AT0175:11 | G30: EQP CTRL
A31: SA0170:22 | B31: SV66111 | C31: WHT | D31: 16 | E31: 260 | F31: XT0171:1 | G31: EQP CTRL
A32: SA0170:31 | B32: SA01703C | C32: WHT | D32: 16 | E32: 260 | F32: AT0176:17 | G32: EQP CTRL
A33: SA0170:32 | B33: SV66121 | C33: WHT | D33: 16 | E33: 260 | F33: XT0171:3 | G33: EQP CTRL
A35: SH6500:1 | B35: FU0172 | C35: WHT | D35: 20 | E35: 280 | F35: XT0175:7 | G35: EQP PWR | H35: SH6500
A37: SH6500:2 | B37: SH65002 | C37: WHT | D37: 20 | E37: 260 | F37: XT0171:13 | G37: EQP CTRL
A39: SH6500:X1 | B39: SH6500X1 | C39: WHT | D39: 20 | E39: 260 | F39: AF0182:11 | G39: CUSTOMER
A40: SH6500:X2 | B40: SH6500X2 | C40: WHT | D40: 20 | E40: 260 | F40: AF0182:27 | G40: CUSTOMER

Sheet CTRL2(B)_S
A1: JB71 B,PNL CTRL2
A3: Project # | B3: 4N621
A4: Project Name | B4: Perenco CLZ - Power Units
A5: Revision | B5: 0.1
A7: Controls DE
A8: Phone:
A9: Controls ME
A10: Phone:
A12: From | G12: To
A13: Device ID | B13: Wire No. | C13: Wire ID | D13: Gauge/Size | E13: Length | F13: Device ID | G13: Location | H13: Bundle Name
A14: AF0066:28 | B14: SV21132 | C14: WHT | D14: 20 | E14: 60 | F14: XT0069:3 | G14: CTRL2 | H14: AF/AU060s
A15: AF0066:20 | B15: SV21202 | C15: WHT | D15: 20 | E15: 60 | F15: XT0069:1 | G15: CTRL2
A17: AF0066:COM | B17: -0V | C17: WHT | D17: 16 | E17: 80 | F17: XT0060:3 | G17: CTRL2
A18: AU0060:COM | B18: -0V | C18: WHT | D18: 16 | E18: 100 | F18: XT0060:2 | G18: CTRL2
A19: AU0060:V+ | B19: FU0061 | C19: WHT | D19: 16 | E19: 100 | F19: FU0061:LD | G19: CTRL2
A20: AF0066:V+ | B20: FU0062 | C20: WHT | D20: 16 | E20: 80 | F20: FU0062:LD | G20: CTRL2
A22: AF0385:05 | B22: -038505 | C22: WHT | D22: 20 | E22: 60 | F22: XT0087:2 | G22: CTRL2 | H22: AF/AU380s
A23: AF0385:21 | B23: -0V | C23: WHT | D23: 20 | E23: 60 | F23: XT0087:3 | G23: CTRL2
A24: AF0385:25 | B24: -0V | C24: WHT | D24: 20 | E24: 60 | F24: XT0080:6 | G24: CTRL2
A25: AF0381:35 | B25: SB647221 | C25: WHT | D25: 20 | E25: 60 | F25: XT0089:18 | G25: CTRL2
A26: AF0381:03 | B26: SB647222 | C26: WHT | D26: 20 | E26: 60 | F26: XT0089:19 | G26: CTRL2
A27: AF0381:00 | B27: SB75122 | C27: WHT | D27: 20 | E27: 60 | F27: XT0089:15 | G27: CTRL2
A28: AF0381:32 | B28: SB7512C1 | C28: WHT | D28: 20 | E28: 60 | F28: XT0089:14 | G28: CTRL2
A29: AF0384:30 | B29: SV21242 | C29: WHT | D29: 20 | E29: 60 | F29: XT0069:2 | G29: CTRL2
A30: AF0383:09 | B30: UA1200J14 | C30: WHT | D30: 20 | E30: 60 | F30: XT1200:11 | G30: CTRL2
A31: AF0381:20 | B31: UA1200J27 | C31: WHT | D31: 20 | E31: 60 | F31: XT1200:14 | G31: CTRL2
A33: AF0383:COM | B33: -0V | C33: WHT | D33: 16 | E33: 60 | F33: XT0060:5 | G33: CTRL2
A34: AF0384:COM | B34: -0V | C34: WHT | D34: 16 | E34: 60 | F34: XT0060:6 | G34: CTRL2
A35: AU0380:COM | B35: -0V | C35: WHT | D35: 16 | E35: 60 | F35: XT0060:4 | G35: CTRL2
... A40: AF0384:V+ | B40: FU0382 | C40: WHT | D40: 16 | E40: 60 | F40: FU0382:LD | G40: CTRL2
A42: FU0387:LD | B42: FU0387 | C42: WHT | D42: 16 | E42: 60 | F42: XT0081:1 | G42: CTRL2 | H42: FU
A43: FU0388:LD | B43: FU0388 | C43: WHT | D43: 16 | E43: 60 | F43: XT0060:11 | G43: CTRL2
A44: FU0389:LD | B44: FU0389 | C44: WHT | D44: 16 | E44: 80 | F44: XT1200:16 | G44: CTRL2
A45: FU2108:LD | B45: FU2108 | C45: WHT | D45: 16 | E45: 60 | F45: XT0060:12 | G45: CTRL2
A47: FU0061:LI | B47: FU0060 | C47: WHT | D47: 14 | E47: 60 | F47: FU0060:LD | G47: CTRL2
A49: KA0060:14(-) | B49: -0V | C49: WHT | D49: 20 | E49: 60 | F49: KA0242:A2 | G49: CTRL2 | H49: KA LRG
A50: KA0243:14(-) | B50: -0V | C50: WHT | D50: 20 | E50: 80 | F50: XT0080:3 | G50: CTRL2
A51: KA0245:12(-) | B51: -0V | C51: WHT | D51: 20 | E51: 80 | F51: KA0249:A2 | G51: CTRL2
A52: KA0243:2 | B52: ESTOPC | C52: WHT | D52: 20 | E52: 60 | F52: XT0089:12 | G52: CTRL2
A53: KA0060:6 | B53: KA00701 | C53: WHT | D53: 20 | E53: 60 | F53: KA0070:1 | G53: CTRL2
...

Sheet CTRL1(B)_S
A1: JB71 B,PNL CTRL1
A3: Project # | B3: 4N621
A4: Project Name | B4: Perenco CLZ - Power Units
A5: Revision | B5: 0.1
A7: Controls DE
A8: Phone:
A9: Controls ME
A10: Phone:
A12: From | G12: To
A13: Device ID | B13: Wire No. | C13: Wire ID | D13: Gauge/Size | E13: Length | F13: Device ID | G13: Location | H13: Bundle Name
A14: AU0070:COM | B14: -0V | C14: WHT | D14: 16 | E14: 100 | F14: XT0070:3 | G14: CTRL1 | H14: AF/AU070s
A15: AU0070:V+ | B15: FU0070 | C15: WHT | D15: 16 | E15: 100 | F15: FU0070:LD | G15: CTRL1
A16: AF0073:V+ | B16: FU0071 | C16: WHT | D16: 16 | E16: 100 | F16: XT0070:4 | G16: CTRL1
A17: AF0074:V+ | B17: FU0072 | C17: WHT | D17: 16 | E17: 100 | F17: FU0072:LD | G17: CTRL1
A19: AF0074:COM | B19: -0V | C19: WHT | D19: 14 | E19: 100 | F19: XT0070:6 | G19: CTRL1
A21: AF0092:02 | B21: KA023822 | C21: WHT | D21: 20 | E21: 60 | F21: XT0091:3 | G21: CTRL1 | H21: AF/AU090s
A23: AF0092:COM | B23: -0V | C23: WHT | D23: 16 | E23: 120 | F23: XT0070:7 | G23: CTRL1
A24: AF0093:COM | B24: -0V | C24: WHT | D24: 16 | E24: 120 | F24: XT0070:9 | G24: CTRL1
A25: AU0090:COM | B25: -0V | C25: WHT | D25: 16 | E25: 120 | F25: XT0070:7 | G25: CTRL1
A26: AU0090:V+ | B26: FU0091 | C26: WHT | D26: 16 | E26: 120 | F26: FU0091:LD | G26: CTRL1
A27: AF0092:V+ | B27: FU0092 | C27: WHT | D27: 16 | E27: 120 | F27: FU0092:LD | G27: CTRL1
A28: AF0093:V+ | B28: FU0093 | C28: WHT | D28: 16 | E28: 120 | F28: XT0070:8 | G28: CTRL1
A30: FU0071:LD | B30: FU0071 | C30: WHT | D30: 16 | E30: 60 | F30: XT0070:4 | G30: CTRL1 | H30: FU
A31: FU0093:LD | B31: FU0093 | C31: WHT | D31: 16 | E31: 60 | F31: XT0070:8 | G31: CTRL1
A32: FU0094:LD | B32: FU0094 | C32: WHT | D32: 16 | E32: 60 | F32: XT0070:13 | G32: CTRL1
A33: FU0099:LD | B33: FU0099 | C33: WHT | D33: 16 | E33: 120 | F33: XT0091:5 | G33: CTRL1
A35: FU0070:LI | B35: FU0210 | C35: WHT | D35: 14 | E35: 60 | F35: FU0210:LD | G35: CTRL1
A36: FU0072:LI | B36: FU0210 | C36: WHT | D36: 14 | E36: 60 | F36: FU0091:LI | G36: CTRL1
A38: FU0010:LI | B38: FU0136 | C38: WHT | D38: 12 | E38: 60 | F38: XT0070:1 | G38: CTRL1
A39: FU0100:LI | B39: FU0136 | C39: WHT | D39: 12 | E39: 60 | F39: XT0070:1 | G39: CTRL1
A40: FU0210:LI | B40: FU0136 | C40: WHT | D40: 12 | E40: 60 | F40: XT0070:1 | G40: CTRL1
A42: KA0234:A1 | B42: KA0131A1 | C42: WHT | D42: 20 | E42: 60 | F42: XT0091:11 | G42: CTRL1 | H42: KA A1/A2
A43: KA0875:A1 | B43: KA0875A1 | C43: WHT | D43: 20 | E43: 60 | F43: AF0092:03 | G43: CTRL1
A44: KA1020:A1 | B44: KA1020A1 | C44: WHT | D44: 20 | E44: 60 | F44: AF0073:00 | G44: CTRL1
A46: KA0234:A2 | B46: KA0131A2 | C46: WHT | D46: 20 | E46: 60 | F46: XT0091:12 | G46: CTRL1
A47: KA0875:A2 | B47: KA0875A2 | C47: WHT | D47: 20 | E47: 60 | F47: AF0092:19 | G47: CTRL1
A48: KA1020:A2 | B48: KA1020A2 | C48: WHT | D48: 20 | E48: 60 | F48: AF0073:16 | G48: CTRL1
A50: KA0875:14 | B50: FU0099 | C50: WHT | D50: 20 | E50: 60 | F50: XT0091:5 | G50: CTRL1 | H50: KA
A51: KA0233:14 | B51: KA023314 | C51: WHT | D51: 20 | E51: 60 | F51: AF0092:06 | G51: CTRL1
A52: KA0234:14 | B52: KA023414 | C52: WHT | D52: 20 | E52: 60 | F52: AF0092:08 | G52: CTRL1
...

Sheet EQP CTRL(C)_S
A1: JB71 C,PNL EQP CTRL
A3: Project # | B3: 4N621
A4: Project Name | B4: Perenco CLZ - Power Units
A5: Revision | B5: 0.1
A7: Controls DE
A8: Phone:
A9: Controls ME
A10: Phone:
A12: From | G12: To
A13: Device ID | B13: Wire No. | C13: Wire ID | D13: Gauge/Size | E13: Length | F13: Device ID | G13: Location | H13: Bundle Name
A14: AT0170:45 | B14: AT017045 | C14: WHT | D14: 20 | E14: 60 | F14: XT0170:12 | G14: EQP CTRL | H14: AT0170
A15: AT0170:46 | B15: AT017046 | C15: WHT | D15: 20 | E15: 60 | F15: XT0170:13 | G15: EQP CTRL
A16: AT0170:24 | B16: FU0387 | C16: WHT | D16: 20 | E16: 60 | F16: XT0170:1 | G16: EQP CTRL
A17: AT0170:30 | B17: FU0387 | C17: WHT | D17: 20 | E17: 60 | F17: XT0170:1 | G17: EQP CTRL
A18: AT0170:26 | B18: KA024313 | C18: WHT | D18: 20 | E18: 60 | F18: XT0170:2 | G18: EQP CTRL
A19: AT0170:32 | B19: KA024513 | C19: WHT | D19: 20 | E19: 60 | F19: XT0170:4 | G19: EQP CTRL
A21: AT0175:18 | B21: HL0171X2 | C21: WHT | D21: 20 | E21: 60 | F21: XT0171:37 | G21: EQP CTRL | H21: AT0176
A22: AT0175:17 | B22: HL0171X3 | C22: WHT | D22: 20 | E22: 60 | F22: XT0171:36 | G22: EQP CTRL
A23: AT0175:21 | B23: HL0172X2 | C23: WHT | D23: 20 | E23: 60 | F23: XT0171:41 | G23: EQP CTRL
A24: AT0175:20 | B24: HL0172X3 | C24: WHT | D24: 20 | E24: 60 | F24: XT0171:40 | G24: EQP CTRL
A26: AT0175:24 | B26: HL6173N | C26: WHT | D26: 16 | E26: 60 | F26: XT0171:44 | G26: EQP CTRL
A27: AT0175:3 | B27: SB6170N | C27: WHT | D27: 16 | E27: 60 | F27: XT0171:46 | G27: EQP CTRL
A28: AT0175:2 | B28: SB6170P | C28: WHT | D28: 16 | E28: 60 | F28: XT0171:45 | G28: EQP CTRL
A29: AT0175:12 | B29: SV66112 | C29: WHT | D29: 16 | E29: 60 | F29: XT0171:2 | G29: EQP CTRL
A30: AT0175:5 | B30: TS65431 | C30: WHT | D30: 16 | E30: 60 | F30: XT0171:17 | G30: EQP CTRL
A31: AT0175:6 | B31: TS65432 | C31: WHT | D31: 16 | E31: 60 | F31: XT0171:18 | G31: EQP CTRL
A32: AT0175:23 | B32: VD6173P | C32: WHT | D32: 16 | E32: 60 | F32: XT0171:43 | G32: EQP CTRL
A34: AT0176:8 | B34: DT65001 | C34: WHT | D34: 16 | E34: 60 | F34: XT0171:15 | G34: EQP CTRL | H34: AT0176
A35: AT0176:9 | B35: DT65002 | C35: WHT | D35: 16 | E35: 60 | F35: XT0171:16 | G35: EQP CTRL
A36: AT0176:23 | B36: HAL67101 | C36: WHT | D36: 16 | E36: 60 | F36: XT0171:5 | G36: EQP CTRL
A37: AT0176:24 | B37: HAL67102 | C37: WHT | D37: 16 | E37: 60 | F37: XT0171:6 | G37: EQP CTRL
A38: AT0176:2 | B38: HAL67103 | C38: WHT | D38: 16 | E38: 60 | F38: XT0171:7 | G38: EQP CTRL
A39: AT0176:3 | B39: HAL67104 | C39: WHT | D39: 16 | E39: 60 | F39: XT0171:8 | G39: EQP CTRL
A40: AT0176:18 | B40: SV66122 | C40: WHT | D40: 16 | E40: 60 | F40: XT0171:4 | G40: EQP CTRL
A41: AT0176:11 | B41: WS66111 | C41: WHT | D41: 16 | E41: 60 | F41: XT0171:31 | G41: EQP CTRL
A42: AT0176:12 | B42: WS66112 | C42: WHT | D42: 16 | E42: 60 | F42: XT0171:32 | G42: EQP CTRL
A44: AT0176:4P1 | B44: AT01764P1 | C44: WHT | D44: 14 | E44: 60 | F44: AT0178:1P1 | G44: EQP CTRL
A45: AT0176:5P1 | B45: AT01765P1 | C45: WHT | D45: 14 | E45: 60 | F45: AT0178:2P1 | G45: EQP CTRL
A47: AT0178:24 | B47: KA0178A2 | C47: WHT | D47: 20 | E47: 60 | F47: XT0173:3 | G47: EQP CTRL | H47: AT0178
A48: AT0178:23 | B48: VD0178 | C48: WHT | D48: 20 | E48: 60 | F48: XT0173:2 | G48: EQP CTRL
...

Sheet CUSTOMER(B)_S
A1: JB71 B,PNL CUSTOMER
A3: Project # | B3: 4N621
A4: Project Name | B4: Perenco CLZ - Power Units
A5: Revision | B5: 0.1
A7: Controls DE
A8: Phone:
A9: Controls ME
A10: Phone:
A12: From | G12: To
A13: Device ID | B13: Wire No. | C13: Wire ID | D13: Gauge/Size | E13: Length | F13: Device ID | G13: Location | H13: Bundle Name
A14: AF0182:08 | B14: -018208 | C14: WHT | D14: 20 | E14: 60 | F14: XT0188:8 | G14: CUSTOMER | H14: AF/AU180s
A15: AF0182:40 | B15: -018240 | C15: WHT | D15: 20 | E15: 60 | F15: XT0188:7 | G15: CUSTOMER
A16: AF0181:32 | B16: KA71701 | C16: WHT | D16: 20 | E16: 60 | F16: XT0189:53 | G16: CUSTOMER
A17: AF0181:00 | B17: KA71702 | C17: WHT | D17: 20 | E17: 60 | F17: XT0189:54 | G17: CUSTOMER
A18: AF0181:33 | B18: KA71721 | C18: WHT | D18: 20 | E18: 60 | F18: XT0189:59 | G18: CUSTOMER
A19: AF0181:01 | B19: KA71722 | C19: WHT | D19: 20 | E19: 60 | F19: XT0189:60 | G19: CUSTOMER
A20: AF0181:34 | B20: SB75101 | C20: WHT | D20: 20 | E20: 60 | F20: XT0189:1 | G20: CUSTOMER
A21: AF0181:02 | B21: SB75102 | C21: WHT | D21: 20 | E21: 60 | F21: XT0189:2 | G21: CUSTOMER
A22: AF0181:35 | B22: SB75111 | C22: WHT | D22: 20 | E22: 60 | F22: XT0189:3 | G22: CUSTOMER
A23: AF0181:03 | B23: SB75112 | C23: WHT | D23: 20 | E23: 60 | F23: XT0189:4 | G23: CUSTOMER
A24: AF0181:41 | B24: SB75511 | C24: WHT | D24: 20 | E24: 60 | F24: XT0189:9 | G24: CUSTOMER
A25: AF0181:09 | B25: SB75512 | C25: WHT | D25: 20 | E25: 60 | F25: XT0189:10 | G25: CUSTOMER
A26: AF0181:42 | B26: SB75521 | C26: WHT | D26: 20 | E26: 60 | F26: XT0189:11 | G26: CUSTOMER
... A52: AF0183:V+ | B52: FU0183 | C52: WHT | D52: 16 | E52: 80 | F52: FU0183:LD | G52: CUSTOMER
A54: AF0651:00 | B54: -065100 | C54: WHT | D54: 20 | E54: 60 | F54: XT0188:2 | G54: CUSTOMER | H54: AF/AU650s
A55: AF0651:01 | B55: -065101 | C55: WHT | D55: 20 | E55: 60 | F55: XT0188:4 | G55: CUSTOMER
A56: AF0651:02 | B56: -065102 | C56: WHT | D56: 20 | E56: 60 | F56: XT0188:6 | G56: CUSTOMER
A57: AF0651:32 | B57: -065132 | C57: WHT | D57: 20 | E57: 60 | F57: XT0188:1 | G57: CUSTOMER
A58: AF0651:33 | B58: -065133 | C58: WHT | D58: 20 | E58: 60 | F58: XT0188:3 | G58: CUSTOMER
A59: AF0651:34 | B59: -065134 | C59: WHT | D59: 20 | E59: 60 | F59: XT0188:5 | G59: CUSTOMER
A60: AF0653:00 | B60: -065300 | C60: WHT | D60: 20 | E60: 60 | F60: XT0291:3 | G60: CUSTOMER
A61: AF0653:02 | B61: -065302 | C61: WHT | D61: 20 | E61: 60 | F61: XT0291:4 | G61: CUSTOMER
A62: AF0653:04 | B62: -065304 | C62: WHT | D62: 20 | E62: 60 | F62: XT0291:5 | G62: CUSTOMER
A63: AF0653:36 | B63: -065336 | C63: WHT | D63: 20 | E63: 60 | F63: XT0291:8 | G63: CUSTOMER
A64: AF0651:36 | B64: KA71801 | C64: WHT | D64: 20 | E64: 60 | F64: XT0189:19 | G64: CUSTOMER
A65: AF0651:04 | B65: KA71802 | C65: WHT | D65: 20 | E65: 60 | F65: XT0189:20 | G65: CUSTOMER
A66: AF0651:37 | B66: KA71811 | C66: WHT | D66: 20 | E66: 60 | F66: XT0189:21 | G66: CUSTOMER
... A94: AF0654:V+ | B94: FU0652 | C94: WHT | D94: 14 | E94: 80 | F94: FU0652:LD | G94: CUSTOMER
A96: FU0659:LD | B96: FU0659 | C96: WHT | D96: 14 | E96: 60 | F96: XT0180:8 | G96: CUSTOMER | H96: FU
A97: FU0181:LI | B97: FU0180 | C97: WHT | D97: 14 | E97: 60 | F97: FU0180:LD | G97: CUSTOMER
...

Sheet VIB(B)_S
A1: JB71 B,PNL VIBRATION
A3: Project # | B3: 4N621
A4: Project Name | B4: Perenco CLZ - Power Units
A5: Revision | B5: 0.1
A7: Controls DE
A8: Phone:
A9: Controls ME
A10: Phone:
A12: From | G12: To
A13: Device ID | B13: Wire No. | C13: Wire ID | D13: Gauge/Size | E13: Length | F13: Device ID | G13: Location | H13: Bundle Name
A14: AF0420:09 | B14: -042009 | C14: WHT | D14: 20 | E14: 60 | F14: AF0420:10 | G14: VIBRATION | H14: 1444s
A15: AF0420:13 | B15: -042013 | C15: WHT | D15: 20 | E15: 60 | F15: AF0420:14 | G15: VIBRATION
A17: AF0410:53 | B17: -0V | C17: WHT | D17: 16 | E17: 60 | F17: XT0401:1 | G17: VIBRATION
A18: AF0410:54 | B18: AF0410N | C18: WHT | D18: 16 | E18: 60 | F18: AF0420:53 | G18: VIBRATION
A19: AF0410:56 | B19: AF0410P | C19: WHT | D19: 16 | E19: 60 | F19: AF0420:55 | G19: VIBRATION
A20: AF0420:54 | B20: AF0420N | C20: WHT | D20: 16 | E20: 60 | F20: AF0450:53 | G20: VIBRATION
A21: AF0420:56 | B21: AF0420P | C21: WHT | D21: 16 | E21: 60 | F21: AF0450:55 | G21: VIBRATION
A22: AF0410:55 | B22: FU0400 | C22: WHT | D22: 16 | E22: 60 | F22: FU0400:LD | G22: VIBRATION
A24: AT0680:NEG | B24: -0V | C24: WHT | D24: 14 | E24: 60 | F24: XT0401:5 | G24: VIBRATION | H24: AT
A25: AT0680:POS | B25: FU0680 | C25: WHT | D25: 14 | E25: 60 | F25: XT0401:6 | G25: VIBRATION
A27: FU0680:LD | B27: FU0680 | C27: WHT | D27: 14 | E27: 60 | F27: XT0401:6 | G27: VIBRATION | H27: FU
A29: XT0401:1 | B29: -0V | C29: WHT | D29: 12 | E29: 160 | F29: XT0003:3 | G29: DC | H29: FU/XT-DC
A30: FU0400:LI | B30: FU0136 | C30: WHT | D30: 12 | E30: 160 | F30: XT0002:3 | G30: DC
A32: XT0400:2 | B32: XT04002 | C32: GRN | D32: 14 | E32: 160 | F32: IEG0010:2 | G32: DC | H32: EXTERNAL
H33: GROUNDS

Sheet GEN CTRL(B)_S
A1: JB71 B,PNL GEN CTRL
A3: Project # | B3: 4N621
A4: Project Name | B4: Perenco CLZ - Power Units
A5: Revision | B5: 0.1
A7: Controls DE
A8: Phone:
A9: Controls ME
A10: Phone:
A12: From | G12: To
A13: Device ID | B13: Wire No. | C13: Wire ID | D13: Gauge/Size | E13: Length | F13: Device ID | G13: Location | H13: Bundle Name
A14: AF0121:02 | B14: -012102 | C14: WHT | D14: 20 | E14: 60 | F14: XT0144:2 | G14: GEN CTRL | H14: AF/AU120s
A15: AF0121:03 | B15: -012103 | C15: WHT | D15: 20 | E15: 60 | F15: XT0125:7 | G15: GEN CTRL
A16: AF0121:07 | B16: -012107 | C16: WHT | D16: 20 | E16: 60 | F16: XT0124:2 | G16: GEN CTRL
A17: AF0121:08 | B17: -012108 | C17: WHT | D17: 20 | E17: 60 | F17: XT0121:7 | G17: GEN CTRL
A18: AF0121:11 | B18: -012111 | C18: WHT | D18: 20 | E18: 60 | F18: XT0124:5 | G18: GEN CTRL
A19: AF0121:12 | B19: -012112 | C19: WHT | D19: 20 | E19: 60 | F19: XT0124:6 | G19: GEN CTRL
A20: AF0121:34 | B20: -012134 | C20: WHT | D20: 20 | E20: 60 | F20: XT0144:1 | G20: GEN CTRL
A21: AF0121:40 | B21: -012140 | C21: WHT | D21: 20 | E21: 60 | F21: XT0121:6 | G21: GEN CTRL
A22: AF0122:11 | B22: -012211 | C22: WHT | D22: 20 | E22: 60 | F22: XT0128:2 | G22: GEN CTRL
A23: AF0122:12 | B23: -012212 | C23: WHT | D23: 20 | E23: 60 | F23: XT0128:4 | G23: GEN CTRL
A24: AF0122:13 | B24: -012213 | C24: WHT | D24: 20 | E24: 60 | F24: XT0128:6 | G24: GEN CTRL
A25: AF0122:43 | B25: -012243 | C25: WHT | D25: 20 | E25: 60 | F25: XT0128:1 | G25: GEN CTRL
A26: AF0122:44 | B26: -012244 | C26: WHT | D26: 20 | E26: 60 | F26: XT0128:3 | G26: GEN CTRL
... A54: AF0124:V+ | B54: FU0123 | C54: WHT | D54: 16 | E54: 80 | F54: FU0123:LD | G54: GEN CTRL
A56: AT0140:3 EX-D(-) | B56: -0V | C56: WHT | D56: 16 | E56: 100 | F56: XT0120:10 | G56: GEN CTRL | H56: AT
A57: AT0140:30 FLT | B57: -0V | C57: WHT | D57: 16 | E57: 60 | F57: AT0140:48 BAT(-) | G57: GEN CTRL
A58: AT0140:30 FLT | B58: -0V | C58: WHT | D58: 16 | E58: 100 | F58: XT0120:9 | G58: GEN CTRL
A59: AT0140:34 ID RES(-) | B59: AT014034 | C59: WHT | D59: 16 | E59: 60 | F59: AT0140:42 ID(+) | G59: GEN CTRL
A60: AT0140:47 BAT(+) | B60: FU0124 | C60: WHT | D60: 16 | E60: 100 | F60: XT0120:8 | G60: GEN CTRL
A61: AT0140:29 FLT | B61: KA0310A2 | C61: WHT | D61: 16 | E61: 100 | F61: KA0310:A2 | G61: GEN CTRL
A62: AT0140:4 EX-D(+) | B62: KA012314 | C62: WHT | D62: 16 | E62: 100 | F62: KA0123:14 | G62: GEN CTRL
A64: AT0140:20 VBUS-N | B64: BUSPTN | C64: RED | D64: 16R | E64: 120 | F64: XT0780:5 | G64: GEN CTRL | H64: AT RED
A65: AT0140:18 VBUS-B | B65: QF07812 | C65: RED | D65: 16R | E65: 120 | F65: XT0122:1 | G65: GEN CTRL
A66: AT0140:17 VBUS-A | B66: QF07822 | C66: RED | D66: 16R | E66: 120 | F66: XT0122:3 | G66: GEN CTRL
A67: AT0140:15 VGEN-C | B67: XT07822 | C67: RED | D67: 16R | E67: 120 | F67: XT0782:2 | G67: GEN CTRL
A68: AT0140:14 VGEN-B | B68: XT07823 | C68: RED | D68: 16R | E68: 120 | F68: XT0782:3 | G68: GEN CTRL
A69: AT0140:13 VGEN-A | B69: XT07825 | C69: RED | D69: 16R | E69: 120 | F69: XT0782:5 | G69: GEN CTRL
A70: AT0140:16 VGEN-N | B70: XT07827 | C70: RED | D70: 16R | E70: 120 | F70: XT0122:11 | G70: GEN CTRL
A72: AT0140:28 ID RLY | B72: XT01411 | C72: BLU | D72: 12B | E72: 120 | F72: XT0141:1 | G72: GEN CTRL | H72: AT BLU
A73: AT0140:43 ID(-) | B73: XT01412 | C73: BLU | D73: 12B | E73: 120 | F73: XT0141:2 | G73: GEN CTRL
...

Sheet EQP PWR(C)_S
A1: JB71 C,PNL EQP PWR
A3: Project # | B3: 4N621
A4: Project Name | B4: Perenco CLZ - Power Units
A5: Revision | B5: 0.1
A7: Controls DE
A8: Phone:
A9: Controls ME
A10: Phone:
A12: From | G12: To
A13: Device ID | B13: Wire No. | C13: Wire ID | D13: Gauge/Size | E13: Length | F13: Device ID | G13: Location | H13: Bundle Name
A14: FU0171:LD | B14: FU0171 | C14: WHT | D14: 14 | E14: 60 | F14: XT0175:6 | G14: EQP PWR | H14: FU
A15: FU0172:LD | B15: FU0172 | C15: WHT | D15: 14 | E15: 60 | F15: XT0175:7 | G15: EQP PWR
A17: FU0170:LD | B17: FU0170 | C17: WHT | D17: 12 | E17: 60 | F17: XT0175:5 | G17: EQP PWR
A18: FU0171:LI | B18: FU0170 | C18: WHT | D18: 12 | E18: 60 | F18: XT0175:5 | G18: EQP PWR
A20: UV0170:2(-) | B20: -0V | C20: WHT | D20: 14 | E20: 60 | F20: XT0175:1 | G20: EQP PWR | H20: UV
A21: UV0170:4(-) | B21: -0V | C21: WHT | D21: 14 | E21: 60 | F21: XT0175:1 | G21: EQP PWR
A22: UV0170:1(+) | B22: FU0170 | C22: WHT | D22: 14 | E22: 60 | F22: XT0175:5 | G22: EQP PWR
A23: UV0170:3(+) | B23: FU0170 | C23: WHT | D23: 14 | E23: 60 | F23: XT0175:5 | G23: EQP PWR
A25: XT0175:1 | B25: -0V | C25: WHT | D25: 12 | E25: 120 | F25: XT0003:3 | G25: DC | H25: FU/XT-DC
A26: FU0170:LI | B26: FU0136 | C26: WHT | D26: 12 | E26: 120 | F26: XT0002:3 | G26: DC

Sheet DC(B)_S
A1: JB71 B,PNL DC PWR
A3: Project # | B3: 4N621
A4: Project Name | B4: Perenco CLZ - Power Units
A5: Revision | B5: 0.1
A7: Controls DE
A8: Phone:
A9: Controls ME
A10: Phone:
A12: From | G12: To
A13: Device ID | B13: Wire No. | C13: Wire ID | D13: Gauge/Size | E13: Length | F13: Device ID | G13: Location | H13: Bundle Name
A14: XT0003:7 | B14: -0V | C14: WHT | D14: 14 | E14: 60 | F14: XT0004:3 | G14: DC | H14: FU/XT
A15: XT0005:3 | B15: -0V | C15: WHT | D15: 14 | E15: 60 | F15: XT0003:7 | G15: DC
A16: FU0004:LD | B16: FU0004 | C16: WHT | D16: 14 | E16: 60 | F16: XT0004:1 | G16: DC
A17: FU0005:LD | B17: FU0005 | C17: WHT | D17: 14 | E17: 60 | F17: XT0005:1 | G17: DC
A18: FU0004:LI | B18: FU0136 | C18: WHT | D18: 14 | E18: 60 | F18: XT0002:7 | G18: DC
A19: FU0005:LI | B19: FU0136 | C19: WHT | D19: 14 | E19: 60 | F19: XT0002:7 | G19: DC
A21: FU0011:LI | B21: QF7752POS | C21: WHT | D21: 12 | E21: 60 | F21: XT0011:1 | G21: DC
A23: UJ0131:+ | B23: FU0011 | C23: WHT | D23: 12 | E23: 60 | F23: FU0011:LD | G23: DC | H23: UJ
A24: UJ0131:- | B24: QF7752NEG | C24: WHT | D24: 12 | E24: 60 | F24: XT0011:2 | G24: DC

Sheet Bundle Tag Info
A1: PER-PGM #3
A2: 4N621
A3: 0.1
A6: LIGHTS | B6: GPP | C6: DOOR CTRL | D6: DOOR OPR | E6: EQP DOOR | F6: CTRL2 | G6: CTRL1 | H6: EQP CTRL | I6: CUSTOMER | J6: VIB | K6: GEN | L6: EQP PWR | M6: DC | N6: Panel Name | O6: Panel Name | P6: Panel Name | Q6: Panel Name | R6: Panel Name | S6: Panel Name | T6: Panel Name | U6: Panel Name | V6: Panel Name | W6: Panel Name | X6: Panel Name | Y6: Panel Name | Z6: Panel Name | AA6: Panel Name | AB6: Panel Name | AC6: Panel Name | AD6: Panel Name
A7: EL0 | B7: AT RED | C7: AT | D7: HA0472 | E7: HL0171 | F7: AF/AU060s | G7: AF/AU070s | H7: AT0170 | I7: AF/AU180s | J7: 1444s | K7: AF/AU120s | L7: FU | M7: FU/XT
B8: AT BLU | D8: SA0471 | E8: HL0172 | F8: AF/AU380s | G8: AF/AU090s | H8: AT0176 | I8: AF/AU650s | J8: AT | K8: AT | L8: UV | M8: UJ
B9: AT RED-DC | D9: SA0473 | E9: SA0170 | F9: FU | G9: FU | H9: AT0176 | I9: FU | J9: FU | K9: AT RED | L9: FU/XT-DC
B10: AT BLU-DC | D10: SA0475 | E10: SH6500 | F10: KA LRG | G10: KA A1/A2 | H10: AT0178 | I10: KA LRG | J10: FU/XT-DC | K10: AT BLU
B11: AT-GEN | D11: SB0333 | F11: KA A1 | G11: KA | H11: KA A1/A2 | I11: KA A1 | J11: EXTERNAL GROUNDS | K11: FU
D12: SB0471 | F12: KA A2 | G12: PC | H12: KA | I12: KA A2 | K12: FV
D13: SB0472 | F13: KA | G13: UV | H13: XT | I13: KA | K13: FV RED
D14: SB0473 | F14: KT L/S | G14: AF-CUST | H14: XT-CUST | I14: UAI | K14: KA LRG
D15: SB0474 | F15: KT R/S | G15: XT-DC | H15: AT-EQP PWR | I15: FU/XT-DC | K15: KA A1
D16: SH0470 | F16: SA | G16: XT-GEN | H16: XT-EQP PWR | I16: KA/XT-GEN | K16: KA A2
D17: SH0471 | F17: UA | G17: XT-EQP CTRL | I17: EXTERNAL GROUNDS | K17: KA
D18: SH0472 | F18: UAI | G18: EXTERNAL GROUNDS | K18: KA RED
F19: XT | K19: QF
F20: KA-CTRL1 | K20: QF RED
F21: KT-CTRL1 | K21: XT
F22: XT-CTRL1 | K22: XT
F23: AF-CUST | K23: FU/XT-DC
F24: XT-CUST | K24: EXTERNAL GROUNDS
F25: AF-DC
F26: FU/XT-DC
F27: XT-EQP CTRL
F28: XT-GEN
F29: EXTERNAL GROUNDS

Sheet Bundle Tags2
A1: =IF('Bundle Tag Info'!A6<>"Panel Name",'Bundle Tag Info'!A6,"") -> LIGHTS | B1: =IF('Bundle Tag Info'!B6<>"Panel Name",'Bundle Tag Info'!B6,"") -> GPP | C1: =IF('Bundle Tag Info'!C6<>"Panel Name",'Bundle Tag Info'!C6,"") -> DOOR CTRL | D1: =IF('Bundle Tag Info'!D6<>"Panel Name",'Bundle Tag Info'!D6,"") -> DOOR OPR | E1: =IF('Bundle Tag Info'!E6<>"Panel Name",'Bundle Tag Info'!E6,"") -> EQP DOOR | F1: =IF('Bundle Tag Info'!F6<>"Panel Name",'Bundle Tag Info'!F6,"") -> CTRL2 | G1: =IF('Bundle Tag Info'!G6<>"Panel Name",'Bundle Tag Info'!G6,"") -> CTRL1 | H1: =IF('Bundle Tag Info'!H6<>"Panel Name",'Bundle Tag Info'!H6,"") -> EQP CTRL | ... AD1: =IF('Bundle Tag Info'!AD6<>"Panel Name",'Bundle Tag Info'!AD6,"")
A2: =IF('Bundle Tag Info'!A$7<>"",CONCATENATE('Bundle Tag Info'!$A$1," ",CHAR(10),'Bundle Tag Info'!$A$2," ",'Bundle Tag Info'!$A$3,CHAR(10),'Bundle Tag Info'!A$6,CHAR(10),'Bundle Tag Info'!A$7),"") -> PER-PGM #3 4N621 0.1 LIGHTS EL0 | B2: =IF('Bundle Tag Info'!B$7<>"",CONCATENATE('Bundle Tag Info'!$A$1," ",CHAR(10),'Bundle Tag Info'!$A$2," ",'Bundle Tag Info'!$A$3,CHAR(10),'Bundle Tag Info'!B$6,CHAR(10),'Bundle Tag Info'!B$7),"") -> PER-PGM #3 4N621 0.1 GPP AT RED | C2: =IF('Bundle Tag Info'!C$7<>"",CONCATENATE('Bundle Tag Info'!$A$1," ",CHAR(10),'Bundle Tag Info'!$A$2," ",'Bundle Tag Info'!$A$3,CHAR(10),'Bundle Tag Info'!C$6,CHAR(10),'Bundle Tag Info'!C$7),"") -> PER-PGM #3 4N621 0.1 DOOR CTRL AT | D2: =IF('Bundle Tag Info'!D$7<>"",CONCATENATE('Bundle Tag Info'!$A$1," ",CHAR(10),'Bundle Tag Info'!$A$2," ",'Bundle Tag Info'!$A$3,CHAR(10),'Bundle Tag Info'!D$6,CHAR(10),'Bundle Tag Info'!D$7),"") -> PER-PGM #3 4N621 0.1 DOOR OPR HA0472 | E2: =IF('Bundle Tag Info'!E$7<>"",CONCATENATE('Bundle Tag Info'!$A$1," ",CHAR(10),'Bundle Tag Info'!$A$2," ",'Bundle Tag Info'!$A$3,CHAR(10),'Bundle Tag Info'!E$6,CHAR(10),'Bundle Tag Info'!E$7),"") -> PER-PGM #3 4N621 0.1 EQP DOOR HL0171 | F2: =IF('Bundle Tag Info'!F$7<>"",CONCATENATE('Bundle Tag Info'!$A$1," ",CHAR(10),'Bundle Tag Info'!$A$2," ",'Bundle Tag Info'!$A$3,CHAR(10),'Bundle Tag Info'!F$6,CHAR(10),'Bundle Tag Info'!F$7),"") -> PER-PGM #3 4N621 0.1 CTRL2 AF/AU060s | G2: =IF('Bundle Tag Info'!G$7<>"",CONCATENATE('Bundle Tag Info'!$A$1," ",CHAR(10),'Bundle Tag Info'!$A$2," ",'Bundle Tag Info'!$A$3,CHAR(10),'Bundle Tag Info'!G$6,CHAR(10),'Bundle Tag Info'!G$7),"") -> PER-PGM #3 4N621 0.1 CTRL1 AF/AU070s | H2: =IF('Bundle Tag Info'!H$7<>"",CONCATENATE('Bundle Tag Info'!$A$1," ",CHAR(10),'Bundle Tag Info'!$A$2," ",'Bundle Tag Info'!$A$3,CHAR(10),'Bundle Tag Info'!H$6,CHAR(10),'Bundle Tag Info'!H$7),"") -> PER-PGM #3 4N621 0.1 EQP CTRL AT0170 | ... AD2: =IF('Bundle Tag Info'!AD$7<>"",CONCATENATE('Bundle Tag Info'!$A$1," ",CHAR(10),'Bundle Tag Info'!$A$2," ",'Bundle Tag Info'!$A$3,CHAR(10),'Bundle Tag Info'!AD$6,CHAR(10),'Bundle Tag Info'!AD$7),"")
A3: =IF('Bundle Tag Info'!A$8<>"",CONCATENATE('Bundle Tag Info'!$A$1," ",CHAR(10),'Bundle Tag Info'!$A$2," ",'Bundle Tag Info'!$A$3,CHAR(10),'Bundle Tag Info'!A$6,CHAR(10),'Bundle Tag Info'!A$8),"") | B3: =IF('Bundle Tag Info'!B$8<>"",CONCATENATE('Bundle Tag Info'!$A$1," ",CHAR(10),'Bundle Tag Info'!$A$2," ",'Bundle Tag Info'!$A$3,CHAR(10),'Bundle Tag Info'!B$6,CHAR(10),'Bundle Tag Info'!B$8),"") -> PER-PGM #3 4N621 0.1 GPP AT BLU | C3: =IF('Bundle Tag Info'!C$8<>"",CONCATENATE('Bundle Tag Info'!$A$1," ",CHAR(10),'Bundle Tag Info'!$A$2," ",'Bundle Tag Info'!$A$3,CHAR(10),'Bundle Tag Info'!C$6,CHAR(10),'Bundle Tag Info'!C$8),"") | D3: =IF('Bundle Tag Info'!D$8<>"",CONCATENATE('Bundle Tag Info'!$A$1," ",CHAR(10),'Bundle Tag Info'!$A$2," ",'Bundle Tag Info'!$A$3,CHAR(10),'Bundle Tag Info'!D$6,CHAR(10),'Bundle Tag Info'!D$8),"") -> PER-PGM #3 4N621 0.1 DOOR OPR SA0471 | E3: =IF('Bundle Tag Info'!E$8<>"",CONCATENATE('Bundle Tag Info'!$A$1," ",CHAR(10),'Bundle Tag Info'!$A$2," ",'Bundle Tag Info'!$A$3,CHAR(10),'Bundle Tag Info'!E$6,CHAR(10),'Bundle Tag Info'!E$8),"") -> PER-PGM #3 4N621 0.1 EQP DOOR HL0172 | F3: =IF('Bundle Tag Info'!F$8<>"",CONCATENATE('Bundle Tag Info'!$A$1," ",CHAR(10),'Bundle Tag Info'!$A$2," ",'Bundle Tag Info'!$A$3,CHAR(10),'Bundle Tag Info'!F$6,CHAR(10),'Bundle Tag Info'!F$8),"") -> PER-PGM #3 4N621 0.1 CTRL2 AF/AU380s | G3: =IF('Bundle Tag Info'!G$8<>"",CONCATENATE('Bundle Tag Info'!$A$1," ",CHAR(10),'Bundle Tag Info'!$A$2," ",'Bundle Tag Info'!$A$3,CHAR(10),'Bundle Tag Info'!G$6,CHAR(10),'Bundle Tag Info'!G$8),"") -> PER-PGM #3 4N621 0.1 CTRL1 AF/AU090s | H3: =IF('Bundle Tag Info'!H$8<>"",CONCATENATE('Bundle Tag Info'!$A$1," ",CHAR(10),'Bundle Tag Info'!$A$2," ",'Bundle Tag Info'!$A$3,CHAR(10),'Bundle Tag Info'!H$6,CHAR(10),'Bundle Tag Info'!H$8),"") -> PER-PGM #3 4N621 0.1 EQP CTRL AT0176 | ... AD3: =IF('Bundle Tag Info'!AD$8<>"",CONCATENATE('Bundle Tag Info'!$A$1," ",CHAR(10),'Bundle Tag Info'!$A$2," ",'Bundle Tag Info'!$A$3,CHAR(10),'Bundle Tag Info'!AD$6,CHAR(10),'Bundle Tag Info'!AD$8),"")
A4: =IF('Bundle Tag Info'!A$9<>"",CONCATENATE('Bundle Tag Info'!$A$1," ",CHAR(10),'Bundle Tag Info'!$A$2," ",'Bundle Tag Info'!$A$3,CHAR(10),'Bundle Tag Info'!A$6,CHAR(10),'Bundle Tag Info'!A$9),"") | B4: =IF('Bundle Tag Info'!B$9<>"",CONCATENATE('Bundle Tag Info'!$A$1," ",CHAR(10),'Bundle Tag Info'!$A$2," ",'Bundle Tag Info'!$A$3,CHAR(10),'Bundle Tag Info'!B$6,CHAR(10),'Bundle Tag Info'!B$9),"") -> PER-PGM #3 4N621 0.1 GPP AT RED-DC | C4: =IF('Bundle Tag Info'!C$9<>"",CONCATENATE('Bundle Tag Info'!$A$1," ",CHAR(10),'Bundle Tag Info'!$A$2," ",'Bundle Tag Info'!$A$3,CHAR(10),'Bundle Tag Info'!C$6,CHAR(10),'Bundle Tag Info'!C$9),"") | D4: =IF('Bundle Tag Info'!D$9<>"",CONCATENATE('Bundle Tag Info'!$A$1," ",CHAR(10),'Bundle Tag Info'!$A$2," ",'Bundle Tag Info'!$A$3,CHAR(10),'Bundle Tag Info'!D$6,CHAR(10),'Bundle Tag Info'!D$9),"") -> PER-PGM #3 4N621 0.1 DOOR OPR SA0473 | E4: =IF('Bundle Tag Info'!E$9<>"",CONCATENATE('Bundle Tag Info'!$A$1," ",CHAR(10),'Bundle Tag Info'!$A$2," ",'Bundle Tag Info'!$A$3,CHAR(10),'Bundle Tag Info'!E$6,CHAR(10),'Bundle Tag Info'!E$9),"") -> PER-PGM #3 4N621 0.1 EQP DOOR SA0170 | F4: =IF('Bundle Tag Info'!F$9<>"",CONCATENATE('Bundle Tag Info'!$A$1," ",CHAR(10),'Bundle Tag Info'!$A$2," ",'Bundle Tag Info'!$A$3,CHAR(10),'Bundle Tag Info'!F$6,CHAR(10),'Bundle Tag Info'!F$9),"") -> PER-PGM #3 4N621 0.1 CTRL2 FU | G4: =IF('Bundle Tag Info'!G$9<>"",CONCATENATE('Bundle Tag Info'!$A$1," ",CHAR(10),'Bundle Tag Info'!$A$2," ",'Bundle Tag Info'!$A$3,CHAR(10),'Bundle Tag Info'!G$6,CHAR(10),'Bundle Tag Info'!G$9),"") -> PER-PGM #3 4N621 0.1 CTRL1 FU | H4: =IF('Bundle Tag Info'!H$9<>"",CONCATENATE('Bundle Tag Info'!$A$1," ",CHAR(10),'Bundle Tag Info'!$A$2," ",'Bundle Tag Info'!$A$3,CHAR(10),'Bundle Tag Info'!H$6,CHAR(10),'Bundle Tag Info'!H$9),"") -> PER-PGM #3 4N621 0.1 EQP CTRL AT0176 | ... AD4: =IF('Bundle Tag Info'!AD$9<>"",CONCATENATE('Bundle Tag Info'!$A$1," ",CHAR(10),'Bundle Tag Info'!$A$2," ",'Bundle Tag Info'!$A$3,CHAR(10),'Bundle Tag Info'!AD$6,CHAR(10),'Bundle Tag Info'!AD$9),"")
A5: =IF('Bundle Tag Info'!A$10<>"",CONCATENATE('Bundle Tag Info'!$A$1," ",CHAR(10),'Bundle Tag Info'!$A$2," ",'Bundle Tag Info'!$A$3,CHAR(10),'Bundle Tag Info'!A$6,CHAR(10),'Bundle Tag Info'!A$10),"") | B5: =IF('Bundle Tag Info'!B$10<>"",CONCATENATE('Bundle Tag Info'!$A$1," ",CHAR(10),'Bundle Tag Info'!$A$2," ",'Bundle Tag Info'!$A$3,CHAR(10),'Bundle Tag Info'!B$6,CHAR(10),'Bundle Tag Info'!B$10),"") -> PER-PGM #3 4N621 0.1 GPP AT BLU-DC | C5: =IF('Bundle Tag Info'!C$10<>"",CONCATENATE('Bundle Tag Info'!$A$1," ",CHAR(10),'Bundle Tag Info'!$A$2," ",'Bundle Tag Info'!$A$3,CHAR(10),'Bundle Tag Info'!C$6,CHAR(10),'Bundle Tag Info'!C$10),"") | D5: =IF('Bundle Tag Info'!D$10<>"",CONCATENATE('Bundle Tag Info'!$A$1," ",CHAR(10),'Bundle Tag Info'!$A$2," ",'Bundle Tag Info'!$A$3,CHAR(10),'Bundle Tag Info'!D$6,CHAR(10),'Bundle Tag Info'!D$10),"") -> PER-PGM #3 4N621 0.1 DOOR OPR SA0475 | E5: =IF('Bundle Tag Info'!E$10<>"",CONCATENATE('Bundle Tag Info'!$A$1," ",CHAR(10),'Bundle Tag Info'!$A$2," ",'Bundle Tag Info'!$A$3,CHAR(10),'Bundle Tag Info'!E$6,CHAR(10),'Bundle Tag Info'!E$10),"") -> PER-PGM #3 4N621 0.1 EQP DOOR SH6500 | F5: =IF('Bundle Tag Info'!F$10<>"",CONCATENATE('Bundle Tag Info'!$A$1," ",CHAR(10),'Bundle Tag Info'!$A$2," ",'Bundle Tag Info'!$A$3,CHAR(10),'Bundle Tag Info'!F$6,CHAR(10),'Bundle Tag Info'!F$10),"") -> PER-PGM #3 4N621 0.1 CTRL2 KA LRG | G5: =IF('Bundle Tag Info'!G$10<>"",CONCATENATE('Bundle Tag Info'!$A$1," ",CHAR(10),'Bundle Tag Info'!$A$2," ",'Bundle Tag Info'!$A$3,CHAR(10),'Bundle Tag Info'!G$6,CHAR(10),'Bundle Tag Info'!G$10),"") -> PER-PGM #3 4N621 0.1 CTRL1 KA A1/A2 | H5: =IF('Bundle Tag Info'!H$10<>"",CONCATENATE('Bundle Tag Info'!$A$1," ",CHAR(10),'Bundle Tag Info'!$A$2," ",'Bundle Tag Info'!$A$3,CHAR(10),'Bundle Tag Info'!H$6,CHAR(10),'Bundle Tag Info'!H$10),"") -> PER-PGM #3 4N621 0.1 EQP CTRL AT0178 | ... AD5: =IF('Bundle Tag Info'!AD$10<>"",CONCATENATE('Bundle Tag Info'!$A$1," ",CHAR(10),'Bundle Tag Info'!$A$2," ",'Bundle Tag Info'!$A$3,CHAR(10),'Bundle Tag Info'!AD$6,CHAR(10),'Bundle Tag Info'!AD$10),"")
A6: =IF('Bundle Tag Info'!A$11<>"",CONCATENATE('Bundle Tag Info'!$A$1," ",CHAR(10),'Bundle Tag Info'!$A$2," ",'Bundle Tag Info'!$A$3,CHAR(10),'Bundle Tag Info'!A$6,CHAR(10),'Bundle Tag Info'!A$11),"") | B6: =IF('Bundle Tag Info'!B$11<>"",CONCATENATE('Bundle Tag Info'!$A$1," ",CHAR(10),'Bundle Tag Info'!$A$2," ",'Bundle Tag Info'!$A$3,CHAR(10),'Bundle Tag Info'!B$6,CHAR(10),'Bundle Tag Info'!B$11),"") -> PER-PGM #3 4N621 0.1 GPP AT-GEN | C6: =IF('Bundle Tag Info'!C$11<>"",CONCATENATE('Bundle Tag Info'!$A$1," ",CHAR(10),'Bundle Tag Info'!$A$2," ",'Bundle Tag Info'!$A$3,CHAR(10),'Bundle Tag Info'!C$6,CHAR(10),'Bundle Tag Info'!C$11),"") | D6: =IF('Bundle Tag Info'!D$11<>"",CONCATENATE('Bundle Tag Info'!$A$1," ",CHAR(10),'Bundle Tag Info'!$A$2," ",'Bundle Tag Info'!$A$3,CHAR(10),'Bundle Tag Info'!D$6,CHAR(10),'Bundle Tag Info'!D$11),"") -> PER-PGM #3 4N621 0.1 DOOR OPR SB0333 | E6: =IF('Bundle Tag Info'!E$11<>"",CONCATENATE('Bundle Tag Info'!$A$1," ",CHAR(10),'Bundle Tag Info'!$A$2," ",'Bundle Tag Info'!$A$3,CHAR(10),'Bundle Tag Info'!E$6,CHAR(10),'Bundle Tag Info'!E$11),"") | F6: =IF('Bundle Tag Info'!F$11<>"",CONCATENATE('Bundle Tag Info'!$A$1," ",CHAR(10),'Bundle Tag Info'!$A$2," ",'Bundle Tag Info'!$A$3,CHAR(10),'Bundle Tag Info'!F$6,CHAR(10),'Bundle Tag Info'!F$11),"") -> PER-PGM #3 4N621 0.1 CTRL2 KA A1 | G6: =IF('Bundle Tag Info'!G$11<>"",CONCATENATE('Bundle Tag Info'!$A$1," ",CHAR(10),'Bundle Tag Info'!$A$2," ",'Bundle Tag Info'!$A$3,CHAR(10),'Bundle Tag Info'!G$6,CHAR(10),'Bundle Tag Info'!G$11),"") -> PER-PGM #3 4N621 0.1 CTRL1 KA | H6: =IF('Bundle Tag Info'!H$11<>"",CONCATENATE('Bundle Tag Info'!$A$1," ",CHAR(10),'Bundle Tag Info'!$A$2," ",'Bundle Tag Info'!$A$3,CHAR(10),'Bundle Tag Info'!H$6,CHAR(10),'Bundle Tag Info'!H$11),"") -> PER-PGM #3 4N621 0.1 EQP CTRL KA A1/A2 | ... AD6: =IF('Bundle Tag Info'!AD$11<>"",CONCATENATE('Bundle Tag Info'!$A$1," ",CHAR(10),'Bundle Tag Info'!$A$2," ",'Bundle Tag Info'!$A$3,CHAR(10),'Bundle Tag Info'!AD$6,CHAR(10),'Bundle Tag Info'!AD$11),"")
A7: =IF('Bundle Tag Info'!A$12<>"",CONCATENATE('Bundle Tag Info'!$A$1," ",CHAR(10),'Bundle Tag Info'!$A$2," ",'Bundle Tag Info'!$A$3,CHAR(10),'Bundle Tag Info'!A$6,CHAR(10),'Bundle Tag Info'!A$12),"") | B7: =IF('Bundle Tag Info'!B$12<>"",CONCATENATE('Bundle Tag Info'!$A$1," ",CHAR(10),'Bundle Tag Info'!$A$2," ",'Bundle Tag Info'!$A$3,CHAR(10),'Bundle Tag Info'!B$6,CHAR(10),'Bundle Tag Info'!B$12),"") | C7: =IF('Bundle Tag Info'!C$12<>"",CONCATENATE('Bundle Tag Info'!$A$1," ",CHAR(10),'Bundle Tag Info'!$A$2," ",'Bundle Tag Info'!$A$3,CHAR(10),'Bundle Tag Info'!C$6,CHAR(10),'Bundle Tag Info'!C$12),"") | D7: =IF('Bundle Tag Info'!D$12<>"",CONCATENATE('Bundle Tag Info'!$A$1," ",CHAR(10),'Bundle Tag Info'!$A$2," ",'Bundle Tag Info'!$A$3,CHAR(10),'Bundle Tag Info'!D$6,CHAR(10),'Bundle Tag Info'!D$12),"") -> PER-PGM #3 4N621 0.1 DOOR OPR SB0471 | E7: =IF('Bundle Tag Info'!E$12<>"",CONCATENATE('Bundle Tag Info'!$A$1," ",CHAR(10),'Bundle Tag Info'!$A$2," ",'Bundle Tag Info'!$A$3,CHAR(10),'Bundle Tag Info'!E$6,CHAR(10),'Bundle Tag Info'!E$12),"") | F7: =IF('Bundle Tag Info'!F$12<>"",CONCATENATE('Bundle Tag Info'!$A$1," ",CHAR(10),'Bundle Tag Info'!$A$2," ",'Bundle Tag Info'!$A$3,CHAR(10),'Bundle Tag Info'!F$6,CHAR(10),'Bundle Tag Info'!F$12),"") -> PER-PGM #3 4N621 0.1 CTRL2 KA A2 | G7: =IF('Bundle Tag Info'!G$12<>"",CONCATENATE('Bundle Tag Info'!$A$1," ",CHAR(10),'Bundle Tag Info'!$A$2," ",'Bundle Tag Info'!$A$3,CHAR(10),'Bundle Tag Info'!G$6,CHAR(10),'Bundle Tag Info'!G$12),"") -> PER-PGM #3 4N621 0.1 CTRL1 PC | H7: =IF('Bundle Tag Info'!H$12<>"",CONCATENATE('Bundle Tag Info'!$A$1," ",CHAR(10),'Bundle Tag Info'!$A$2," ",'Bundle Tag Info'!$A$3,CHAR(10),'Bundle Tag Info'!H$6,CHAR(10),'Bundle Tag Info'!H$12),"") -> PER-PGM #3 4N621 0.1 EQP CTRL KA | ... AD7: =IF('Bundle Tag Info'!AD$12<>"",CONCATENATE('Bundle Tag Info'!$A$1," ",CHAR(10),'Bundle Tag Info'!$A$2," ",'Bundle Tag Info'!$A$3,CHAR(10),'Bundle Tag Info'!AD$6,CHAR(10),'Bundle Tag Info'!AD$12),"")
A8: =IF('Bundle Tag Info'!A$13<>"",CONCATENATE('Bundle Tag Info'!$A$1," ",CHAR(10),'Bundle Tag Info'!$A$2," ",'Bundle Tag Info'!$A$3,CHAR(10),'Bundle Tag Info'!A$6,CHAR(10),'Bundle Tag Info'!A$13),"") | B8: =IF('Bundle Tag Info'!B$13<>"",CONCATENATE('Bundle Tag Info'!$A$1," ",CHAR(10),'Bundle Tag Info'!$A$2," ",'Bundle Tag Info'!$A$3,CHAR(10),'Bundle Tag Info'!B$6,CHAR(10),'Bundle Tag Info'!B$13),"") | C8: =IF('Bundle Tag Info'!C$13<>"",CONCATENATE('Bundle Tag Info'!$A$1," ",CHAR(10),'Bundle Tag Info'!$A$2," ",'Bundle Tag Info'!$A$3,CHAR(10),'Bundle Tag Info'!C$6,CHAR(10),'Bundle Tag Info'!C$13),"") | D8: =IF('Bundle Tag Info'!D$13<>"",CONCATENATE('Bundle Tag Info'!$A$1," ",CHAR(10),'Bundle Tag Info'!$A$2," ",'Bundle Tag Info'!$A$3,CHAR(10),'Bundle Tag Info'!D$6,CHAR(10),'Bundle Tag Info'!D$13),"") -> PER-PGM #3 4N621 0.1 DOOR OPR SB0472 | E8: =IF('Bundle Tag Info'!E$13<>"",CONCATENATE('Bundle Tag Info'!$A$1," ",CHAR(10),'Bundle Tag Info'!$A$2," ",'Bundle Tag Info'!$A$3,CHAR(10),'Bundle Tag Info'!E$6,CHAR(10),'Bundle Tag Info'!E$13),"") | F8: =IF('Bundle Tag Info'!F$13<>"",CONCATENATE('Bundle Tag Info'!$A$1," ",CHAR(10),'Bundle Tag Info'!$A$2," ",'Bundle Tag Info'!$A$3,CHAR(10),'Bundle Tag Info'!F$6,CHAR(10),'Bundle Tag Info'!F$13),"") -> PER-PGM #3 4N621 0.1 CTRL2 KA | G8: =IF('Bundle Tag Info'!G$13<>"",CONCATENATE('Bundle Tag Info'!$A$1," ",CHAR(10),'Bundle Tag Info'!$A$2," ",'Bundle Tag Info'!$A$3,CHAR(10),'Bundle Tag Info'!G$6,CHAR(10),'Bundle Tag Info'!G$13),"") -> PER-PGM #3 4N621 0.1 CTRL1 UV | H8: =IF('Bundle Tag Info'!H$13<>"",CONCATENATE('Bundle Tag Info'!$A$1," ",CHAR(10),'Bundle Tag Info'!$A$2," ",'Bundle Tag Info'!$A$3,CHAR(10),'Bundle Tag Info'!H$6,CHAR(10),'Bundle Tag Info'!H$13),"") -> PER-PGM #3 4N621 0.1 EQP CTRL XT | ... AD8: =IF('Bundle Tag Info'!AD$13<>"",CONCATENATE('Bundle Tag Info'!$A$1," ",CHAR(10),'Bundle Tag Info'!$A$2," ",'Bundle Tag Info'!$A$3,CHAR(10),'Bundle Tag Info'!AD$6,CHAR(10),'Bundle Tag Info'!AD$13),"")
A9: =IF('Bundle Tag Info'!A$14<>"",CONCATENATE('Bundle Tag Info'!$A$1," ",CHAR(10),'Bundle Tag Info'!$A$2," ",'Bundle Tag Info'!$A$3,CHAR(10),'Bundle Tag Info'!A$6,CHAR(10),'Bundle Tag Info'!A$14),"") | B9: =IF('Bundle Tag Info'!B$14<>"",CONCATENATE('Bundle Tag Info'!$A$1," ",CHAR(10),'Bundle Tag Info'!$A$2," ",'Bundle Tag Info'!$A$3,CHAR(10),'Bundle Tag Info'!B$6,CHAR(10),'Bundle Tag Info'!B$14),"") | C9: =IF('Bundle Tag Info'!C$14<>"",CONCATENATE('Bundle Tag Info'!$A$1," ",CHAR(10),'Bundle Tag Info'!$A$2," ",'Bundle Tag Info'!$A$3,CHAR(10),'Bundle Tag Info'!C$6,CHAR(10),'Bundle Tag Info'!C$14),"") | D9: =IF('Bundle Tag Info'!D$14<>"",CONCATENATE('Bundle Tag Info'!$A$1," ",CHAR(10),'Bundle Tag Info'!$A$2," ",'Bundle Tag Info'!$A$3,CHAR(10),'Bundle Tag Info'!D$6,CHAR(10),'Bundle Tag Info'!D$14),"") -> PER-PGM #3 4N621 0.1 DOOR OPR SB0473 | E9: =IF('Bundle Tag Info'!E$14<>"",CONCATENATE('Bundle Tag Info'!$A$1," ",CHAR(10),'Bundle Tag Info'!$A$2," ",'Bundle Tag Info'!$A$3,CHAR(10),'Bundle Tag Info'!E$6,CHAR(10),'Bundle Tag Info'!E$14),"") | F9: =IF('Bundle Tag Info'!F$14<>"",CONCATENATE('Bundle Tag Info'!$A$1," ",CHAR(10),'Bundle Tag Info'!$A$2," ",'Bundle Tag Info'!$A$3,CHAR(10),'Bundle Tag Info'!F$6,CHAR(10),'Bundle Tag Info'!F$14),"") -> PER-PGM #3 4N621 0.1 CTRL2 KT L/S | G9: =IF('Bundle Tag Info'!G$14<>"",CONCATENATE('Bundle Tag Info'!$A$1," ",CHAR(10),'Bundle Tag Info'!$A$2," ",'Bundle Tag Info'!$A$3,CHAR(10),'Bundle Tag Info'!G$6,CHAR(10),'Bundle Tag Info'!G$14),"") -> PER-PGM #3 4N621 0.1 CTRL1 AF-CUST | H9: =IF('Bundle Tag Info'!H$14<>"",CONCATENATE('Bundle Tag Info'!$A$1," ",CHAR(10),'Bundle Tag Info'!$A$2," ",'Bundle Tag Info'!$A$3,CHAR(10),'Bundle Tag Info'!H$6,CHAR(10),'Bundle Tag Info'!H$14),"") -> PER-PGM #3 4N621 0.1 EQP CTRL XT-CUST | ... AD9: =IF('Bundle Tag Info'!AD$14<>"",CONCATENATE('Bundle Tag Info'!$A$1," ",CHAR(10),'Bundle Tag Info'!$A$2," ",'Bundle Tag Info'!$A$3,CHAR(10),'Bundle Tag Info'!AD$6,CHAR(10),'Bundle Tag Info'!AD$14),"")
A10: =IF('Bundle Tag Info'!A$15<>"",CONCATENATE('Bundle Tag Info'!$A$1," ",CHAR(10),'Bundle Tag Info'!$A$2," ",'Bundle Tag Info'!$A$3,CHAR(10),'Bundle Tag Info'!A$6,CHAR(10),'Bundle Tag Info'!A$15),"") | B10: =IF('Bundle Tag Info'!B$15<>"",CONCATENATE('Bundle Tag Info'!$A$1," ",CHAR(10),'Bundle Tag Info'!$A$2," ",'Bundle Tag Info'!$A$3,CHAR(10),'Bundle Tag Info'!B$6,CHAR(10),'Bundle Tag Info'!B$15),"") | C10: =IF('Bundle Tag Info'!C$15<>"",CONCATENATE('Bundle Tag Info'!$A$1," ",CHAR(10),'Bundle Tag Info'!$A$2," ",'Bundle Tag Info'!$A$3,CHAR(10),'Bundle Tag Info'!C$6,CHAR(10),'Bundle Tag Info'!C$15),"") | D10: =IF('Bundle Tag Info'!D$15<>"",CONCATENATE('Bundle Tag Info'!$A$1," ",CHAR(10),'Bundle Tag Info'!$A$2," ",'Bundle Tag Info'!$A$3,CHAR(10),'Bundle Tag Info'!D$6,CHAR(10),'Bundle Tag Info'!D$15),"") -> PER-PGM #3 4N621 0.1 DOOR OPR SB0474 | E10: =IF('Bundle Tag Info'!E$15<>"",CONCATENATE('Bundle Tag Info'!$A$1," ",CHAR(10),'Bundle Tag Info'!$A$2," ",'Bundle Tag Info'!$A$3,CHAR(10),'Bundle Tag Info'!E$6,CHAR(10),'Bundle Tag Info'!E$15),"") | F10: =IF('Bundle Tag Info'!F$15<>"",CONCATENATE('Bundle Tag Info'!$A$1," ",CHAR(10),'Bundle Tag Info'!$A$2," ",'Bundle Tag Info'!$A$3,CHAR(10),'Bundle Tag Info'!F$6,CHAR(10),'Bundle Tag Info'!F$15),"") -> PER-PGM #3 4N621 0.1 CTRL2 KT R/S | G10: =IF('Bundle Tag Info'!G$15<>"",CONCATENATE('Bundle Tag Info'!$A$1," ",CHAR(10),'Bundle Tag Info'!$A$2," ",'Bundle Tag Info'!$A$3,CHAR(10),'Bundle Tag Info'!G$6,CHAR(10),'Bundle Tag Info'!G$15),"") -> PER-PGM #3 4N621 0.1 CTRL1 XT-DC | H10: =IF('Bundle Tag Info'!H$15<>"",CONCATENATE('Bundle Tag Info'!$A$1," ",CHAR(10),'Bundle Tag Info'!$A$2," ",'Bundle Tag Info'!$A$3,CHAR(10),'Bundle Tag Info'!H$6,CHAR(10),'Bundle Tag Info'!H$15),"") -> PER-PGM #3 4N621 0.1 EQP CTRL AT-EQP PWR | ... AD10: =IF('Bundle Tag Info'!AD$15<>"",CONCATENATE('Bundle Tag Info'!$A$1," ",CHAR(10),'Bundle Tag Info'!$A$2," ",'Bundle Tag Info'!$A$3,CHAR(10),'Bundle Tag Info'!AD$6,CHAR(10),'Bundle Tag Info'!AD$15),"")
A11: =IF('Bundle Tag Info'!A$16<>"",CONCATENATE('Bundle Tag Info'!$A$1," ",CHAR(10),'Bundle Tag Info'!$A$2," ",'Bundle Tag Info'!$A$3,CHAR(10),'Bundle Tag Info'!A$6,CHAR(10),'Bundle Tag Info'!A$16),"") | B11: =IF('Bundle Tag Info'!B$16<>"",CONCATENATE('Bundle Tag Info'!$A$1," ",CHAR(10),'Bundle Tag Info'!$A$2," ",'Bundle Tag Info'!$A$3,CHAR(10),'Bundle Tag Info'!B$6,CHAR(10),'Bundle Tag Info'!B$16),"") | C11: =IF('Bundle Tag Info'!C$16<>"",CONCATENATE('Bundle Tag Info'!$A$1," ",CHAR(10),'Bundle Tag Info'!$A$2," ",'Bundle Tag Info'!$A$3,CHAR(10),'Bundle Tag Info'!C$6,CHAR(10),'Bundle Tag Info'!C$16),"") | D11: =IF('Bundle Tag Info'!D$16<>"",CONCATENATE('Bundle Tag Info'!$A$1," ",CHAR(10),'Bundle Tag Info'!$A$2," ",'Bundle Tag Info'!$A$3,CHAR(10),'Bundle Tag Info'!D$6,CHAR(10),'Bundle Tag Info'!D$16),"") -> PER-PGM #3 4N621 0.1 DOOR OPR SH0470 | E11: =IF('Bundle Tag Info'!E$16<>"",CONCATENATE('Bundle Tag Info'!$A$1," ",CHAR(10),'Bundle Tag Info'!$A$2," ",'Bundle Tag Info'!$A$3,CHAR(10),'Bundle Tag Info'!E$6,CHAR(10),'Bundle Tag Info'!E$16),"") | F11: =IF('Bundle Tag Info'!F$16<>"",CONCATENATE('Bundle Tag Info'!$A$1," ",CHAR(10),'Bundle Tag Info'!$A$2," ",'Bundle Tag Info'!$A$3,CHAR(10),'Bundle Tag Info'!F$6,CHAR(10),'Bundle Tag Info'!F$16),"") -> PER-PGM #3 4N621 0.1 CTRL2 SA | G11: =IF('Bundle Tag Info'!G$16<>"",CONCATENATE('Bundle Tag Info'!$A$1," ",CHAR(10),'Bundle Tag Info'!$A$2," ",'Bundle Tag Info'!$A$3,CHAR(10),'Bundle Tag Info'!G$6,CHAR(10),'Bundle Tag Info'!G$16),"") -> PER-PGM #3 4N621 0.1 CTRL1 XT-GEN | H11: =IF('Bundle Tag Info'!H$16<>"",CONCATENATE('Bundle Tag Info'!$A$1," ",CHAR(10),'Bundle Tag Info'!$A$2," ",'Bundle Tag Info'!$A$3,CHAR(10),'Bundle Tag Info'!H$6,CHAR(10),'Bundle Tag Info'!H$16),"") -> PER-PGM #3 4N621 0.1 EQP CTRL XT-EQP PWR | ... AD11: =IF('Bundle Tag Info'!AD$16<>"",CONCATENATE('Bundle Tag Info'!$A$1," ",CHAR(10),'Bundle Tag Info'!$A$2," ",'Bundle Tag Info'!$A$3,CHAR(10),'Bundle Tag Info'!AD$6,CHAR(10),'Bundle Tag Info'!AD$16),"")
A12: =IF('Bundle Tag Info'!A$17<>"",CONCATENATE('Bundle Tag Info'!$A$1," ",CHAR(10),'Bundle Tag Info'!$A$2," ",'Bundle Tag Info'!$A$3,CHAR(10),'Bundle Tag Info'!A$6,CHAR(10),'Bundle Tag Info'!A$17),"") | B12: =IF('Bundle Tag Info'!B$17<>"",CONCATENATE('Bundle Tag Info'!$A$1," ",CHAR(10),'Bundle Tag Info'!$A$2," ",'Bundle Tag Info'!$A$3,CHAR(10),'Bundle Tag Info'!B$6,CHAR(10),'Bundle Tag Info'!B$17),"") | C12: =IF('Bundle Tag Info'!C$17<>"",CONCATENATE('Bundle Tag Info'!$A$1," ",CHAR(10),'Bundle Tag Info'!$A$2," ",'Bundle Tag Info'!$A$3,CHAR(10),'Bundle Tag Info'!C$6,CHAR(10),'Bundle Tag Info'!C$17),"") | D12: =IF('Bundle Tag Info'!D$17<>"",CONCATENATE('Bundle Tag Info'!$A$1," ",CHAR(10),'Bundle Tag Info'!$A$2," ",'Bundle Tag Info'!$A$3,CHAR(10),'Bundle Tag Info'!D$6,CHAR(10),'Bundle Tag Info'!D$17),"") -> PER-PGM #3 4N621 0.1 DOOR OPR SH0471 | E12: =IF('Bundle Tag Info'!E$17<>"",CONCATENATE('Bundle Tag Info'!$A$1," ",CHAR(10),'Bundle Tag Info'!$A$2," ",'Bundle Tag Info'!$A$3,CHAR(10),'Bundle Tag Info'!E$6,CHAR(10),'Bundle Tag Info'!E$17),"") | F12: =IF('Bundle Tag Info'!F$17<>"",CONCATENATE('Bundle Tag Info'!$A$1," ",CHAR(10),'Bundle Tag Info'!$A$2," ",'Bundle Tag Info'!$A$3,CHAR(10),'Bundle Tag Info'!F$6,CHAR(10),'Bundle Tag Info'!F$17),"") -> PER-PGM #3 4N621 0.1 CTRL2 UA | G12: =IF('Bundle Tag Info'!G$17<>"",CONCATENATE('Bundle Tag Info'!$A$1," ",CHAR(10),'Bundle Tag Info'!$A$2," ",'Bundle Tag Info'!$A$3,CHAR(10),'Bundle Tag Info'!G$6,CHAR(10),'Bundle Tag Info'!G$17),"") -> PER-PGM #3 4N621 0.1 CTRL1 XT-EQP CTRL | H12: =IF('Bundle Tag Info'!H$17<>"",CONCATENATE('Bundle Tag Info'!$A$1," ",CHAR(10),'Bundle Tag Info'!$A$2," ",'Bundle Tag Info'!$A$3,CHAR(10),'Bundle Tag Info'!H$6,CHAR(10),'Bundle Tag Info'!H$17),"") | ... AD12: =IF('Bundle Tag Info'!AD$17<>"",CONCATENATE('Bundle Tag Info'!$A$1," ",CHAR(10),'Bundle Tag Info'!$A$2," ",'Bundle Tag Info'!$A$3,CHAR(10),'Bundle Tag Info'!AD$6,CHAR(10),'Bundle Tag Info'!AD$17),"")
A13: =IF('Bundle Tag Info'!A$18<>"",CONCATENATE('Bundle Tag Info'!$A$1," ",CHAR(10),'Bundle Tag Info'!$A$2," ",'Bundle Tag Info'!$A$3,CHAR(10),'Bundle Tag Info'!A$6,CHAR(10),'Bundle Tag Info'!A$18),"") | B13: =IF('Bundle Tag Info'!B$18<>"",CONCATENATE('Bundle Tag Info'!$A$1," ",CHAR(10),'Bundle Tag Info'!$A$2," ",'Bundle Tag Info'!$A$3,CHAR(10),'Bundle Tag Info'!B$6,CHAR(10),'Bundle Tag Info'!B$18),"") | C13: =IF('Bundle Tag Info'!C$18<>"",CONCATENATE('Bundle Tag Info'!$A$1," ",CHAR(10),'Bundle Tag Info'!$A$2," ",'Bundle Tag Info'!$A$3,CHAR(10),'Bundle Tag Info'!C$6,CHAR(10),'Bundle Tag Info'!C$18),"") | D13: =IF('Bundle Tag Info'!D$18<>"",CONCATENATE('Bundle Tag Info'!$A$1," ",CHAR(10),'Bundle Tag Info'!$A$2," ",'Bundle Tag Info'!$A$3,CHAR(10),'Bundle Tag Info'!D$6,CHAR(10),'Bundle Tag Info'!D$18),"") -> PER-PGM #3 4N621 0.1 DOOR OPR SH0472 | E13: =IF('Bundle Tag Info'!E$18<>"",CONCATENATE('Bundle Tag Info'!$A$1," ",CHAR(10),'Bundle Tag Info'!$A$2," ",'Bundle Tag Info'!$A$3,CHAR(10),'Bundle Tag Info'!E$6,CHAR(10),'Bundle Tag Info'!E$18),"") | F13: =IF('Bundle Tag Info'!F$18<>"",CONCATENATE('Bundle Tag Info'!$A$1," ",CHAR(10),'Bundle Tag Info'!$A$2," ",'Bundle Tag Info'!$A$3,CHAR(10),'Bundle Tag Info'!F$6,CHAR(10),'Bundle Tag Info'!F$18),"") -> PER-PGM #3 4N621 0.1 CTRL2 UAI | G13: =IF('Bundle Tag Info'!G$18<>"",CONCATENATE('Bundle Tag Info'!$A$1," ",CHAR(10),'Bundle Tag Info'!$A$2," ",'Bundle Tag Info'!$A$3,CHAR(10),'Bundle Tag Info'!G$6,CHAR(10),'Bundle Tag Info'!G$18),"") -> PER-PGM #3 4N621 0.1 CTRL1 EXTERNAL GROUNDS | H13: =IF('Bundle Tag Info'!H$18<>"",CONCATENATE('Bundle Tag Info'!$A$1," ",CHAR(10),'Bundle Tag Info'!$A$2," ",'Bundle Tag Info'!$A$3,CHAR(10),'Bundle Tag Info'!H$6,CHAR(10),'Bundle Tag Info'!H$18),"") | ... AD13: =IF('Bundle Tag Info'!AD$18<>"",CONCATENATE('Bundle Tag Info'!$A$1," ",CHAR(10),'Bundle Tag Info'!$A$2," ",'Bundle Tag Info'!$A$3,CHAR(10),'Bundle Tag Info'!AD$6,CHAR(10),'Bundle Tag Info'!AD$18),"")
A14: =IF('Bundle Tag Info'!A$19<>"",CONCATENATE('Bundle Tag Info'!$A$1," ",CHAR(10),'Bundle Tag Info'!$A$2," ",'Bundle Tag Info'!$A$3,CHAR(10),'Bundle Tag Info'!A$6,CHAR(10),'Bundle Tag Info'!A$19),"") | B14: =IF('Bundle Tag Info'!B$19<>"",CONCATENATE('Bundle Tag Info'!$A$1," ",CHAR(10),'Bundle Tag Info'!$A$2," ",'Bundle Tag Info'!$A$3,CHAR(10),'Bundle Tag Info'!B$6,CHAR(10),'Bundle Tag Info'!B$19),"") | C14: =IF('Bundle Tag Info'!C$19<>"",CONCATENATE('Bundle Tag Info'!$A$1," ",CHAR(10),'Bundle Tag Info'!$A$2," ",'Bundle Tag Info'!$A$3,CHAR(10),'Bundle Tag Info'!C$6,CHAR(10),'Bundle Tag Info'!C$19),"") | D14: =IF('Bundle Tag Info'!D$19<>"",CONCATENATE('Bundle Tag Info'!$A$1," ",CHAR(10),'Bundle Tag Info'!$A$2," ",'Bundle Tag Info'!$A$3,CHAR(10),'Bundle Tag Info'!D$6,CHAR(10),'Bundle Tag Info'!D$19),"") | E14: =IF('Bundle Tag Info'!E$19<>"",CONCATENATE('Bundle Tag Info'!$A$1," ",CHAR(10),'Bundle Tag Info'!$A$2," ",'Bundle Tag Info'!$A$3,CHAR(10),'Bundle Tag Info'!E$6,CHAR(10),'Bundle Tag Info'!E$19),"") | F14: =IF('Bundle Tag Info'!F$19<>"",CONCATENATE('Bundle Tag Info'!$A$1," ",CHAR(10),'Bundle Tag Info'!$A$2," ",'Bundle Tag Info'!$A$3,CHAR(10),'Bundle Tag Info'!F$6,CHAR(10),'Bundle Tag Info'!F$19),"") -> PER-PGM #3 4N621 0.1 CTRL2 XT | G14: =IF('Bundle Tag Info'!G$19<>"",CONCATENATE('Bundle Tag Info'!$A$1," ",CHAR(10),'Bundle Tag Info'!$A$2," ",'Bundle Tag Info'!$A$3,CHAR(10),'Bundle Tag Info'!G$6,CHAR(10),'Bundle Tag Info'!G$19),"") | H14: =IF('Bundle Tag Info'!H$19<>"",CONCATENATE('Bundle Tag Info'!$A$1," ",CHAR(10),'Bundle Tag Info'!$A$2," ",'Bundle Tag Info'!$A$3,CHAR(10),'Bundle Tag Info'!H$6,CHAR(10),'Bundle Tag Info'!H$19),"") | ... AD14: =IF('Bundle Tag Info'!AD$19<>"",CONCATENATE('Bundle Tag Info'!$A$1," ",CHAR(10),'Bundle Tag Info'!$A$2," ",'Bundle Tag Info'!$A$3,CHAR(10),'Bundle Tag Info'!AD$6,CHAR(10),'Bundle Tag Info'!AD$19),"")
