Workbook

Sheet Blue Labels
A1: (SHT 1) CONTROL,JB70 | B1: (SHT 10) FG&E CTRL,SMT130 | C1: (SHT 11) POWERDIST, PANEL | D1: (SHT 12) MCC PNL,SMT130 | E1: (SHT 13) GEN CMPNT | F1: (SHT 14) PROX,TURB | G1: (SHT 2) PNL A,SMT130 | H1: (SHT 3) PNL B,SMT130 | I1: (SHT 4) PNL,DOOR,2-BAY | J1: (SHT 5) CONTROL,2-BAY | K1: (SHT 6) BECKWITH RELAY,SMT130 | L1: (SHT 7) TCP, SMT130 | M1: (SHT 8) PWR DST,DR,SMT130 | N1: (SHT 9) PLC, PANEL
A2: XTFGA | B2: UV0170 | C2: FU2700 | D2: FU0290 | E2: AT0140 | F2: UA1263 | G2: FU0081 | H2: FU0110 | I2: AT0190K | J2: EL0273 | K2: KA0460 | L2: HL0411 | M2: XT2930 | N2: UV0600
A3: GR1100 | B3: AT0170 | C3: FU2701 | D3: FU0291 | E3: KA0313 | F3: UA1211 | G3: FU0082 | H3: XT0110 | I3: SB6500 | L3: HL0410 | M3: XT0563 | N3: AR0600
A4: GR1000 | B4: FU0171 | C4: FU2703 | D4: FU0294 | E4: FU0332 | F4: UA1210 | G4: XT0082 | H4: XT0400 | I4: AT0190 | L4: HL0409 | M4: FU0560 | N4: AT0600
A5: HA0472 | B5: FU0172 | C5: XT0027 | D5: FU0295 | E5: FU0333 | F5: UA1262 | G5: AU0080 | H5: AF0400 | I5: HA0273 | L5: HL0408 | M5: FU0200 | N5: AP0601
B6: XT0170 | C6: BA0700 | D6: XT0295 | E6: FU0334 | F6: UA1221 | G6: AF0081 | H6: AF0410 | I6: KA0461 | L6: HL0407 | M6: FU0201 | N6: AP0602
B7: XT0171 | C7: BA0703 | D7: XT0290 | E7: FU0335 | F7: UA1220 | G7: AF0082 | H7: AF0420 | L7: SB0400 | M7: FU0273 | N7: AP0603
B8: XT0172 | C8: BA0701 | D8: XT2920 | E8: FU0336 | F8: UA1231 | G8: AF0083 | H8: AF0450 | L8: HL0406 | M8: FU0190 | N8: AP0604
B9: KA0172 | C9: GR0146 | D9: XT0292 | E9: XT0130 | F9: UA1230 | G9: AF0084 | H9: FU0210 | L9: HL0405 | M9: FU0701 | N9: AP0605
B10: KA0174 | C10: FU0136 | D10: KA2960 | E10: XT0190 | F10: GR1210 | G10: AF0085 | H10: FU0060 | L10: HL0404 | M10: FU6500 | N10: AP0606
B11: KA0179 | C11: XT0102 | D11: KA2970 | E11: KA0121 | F11: UA1520 | G11: AF0086 | H11: FU0211 | L11: HL0403 | M11: XT0562 | N11: AP0607
B12: KA6510 | C12: FU0010 | D12: AU0290 | E12: KA0128 | F12: XT1521 | G12: XT0137 | H12: FU0212 | L12: HL0402 | N12: AP0608
B13: XT0173 | C13: FU0460 | D13: AF0291 | E13: KA0185 | F13: XTFGH | G13: XT0237 | H13: FU0213 | L13: HL0401 | N13: AP0609
B14: UAI6611 | C14: XT0104 | D14: AF0292 | E14: KA0310 | F14: GR1211 | G14: XT0233 | H14: FU0214 | L14: HL0400
B15: UAI6621 | C15: GR0145 | D15: AF0293 | E15: KA0330 | G15: KA0130 | H15: XT0235 | L15: SH0412
B16: XT0550 | C16: UJ0131 | D16: AF0294 | E16: KA0331 | G16: KA0178 | H16: XT0240 | L16: SH0411
B17: GR0170 | C17: XT0011 | D17: AF0295 | E17: KA0332 | G17: KA0875 | H17: KA0233 | L17: SH0405
B18: AT0171 | C18: FU0011 | D18: AF0296 | E18: KA0333 | G18: XT0089 | H18: KA0234 | L18: SH0404
B19: AT0175 | C19: XTFGP | D19: AF0297 | E19: KA0334 | G19: XT1135 | H19: KA0221 | L19: SA0400
B20: AT0176 | C20: GR0144 | D20: GR0290 | E20: KA0335 | G20: KA0135 | H20: KA0222 | L20: SH0410
B21: AT0178 | C21: IEG2240 | D21: GR0291 | E21: KA0336 | G21: KA6211 | H21: KA0240 | L21: SH0409
B22: GR0172 | D22: PEG2240 | E22: XT0332 | G22: KA6212 | H22: KA0251 | L22: SH0401
B23: FU0510 | E23: XT0334 | G23: KA6221 | H23: GR0233 | L23: SH0400
B24: XT0510 | E24: XT0335 | G24: KA6222 | H24: FU0070 | L24: SB0408
B25: AF0510 | E25: XT0120 | G25: GR0111 | H25: FU0071 | L25: SB0407
B26: AF0500 | E26: FU0120 | G26: FU0090 | H26: XT0070 | L26: SH0408
B27: XT0500 | E27: FU0121 | G27: FU0091 | H27: AU0070 | L27: SB0405
B28: IEG0356 | E28: FU0180 | G28: XT0090 | H28: AF0071 | L28: SB0406
E29: FU0181 | G29: AU0090 | H29: AF0072 | L29: SA0401
E30: XT0180 | G30: AF0091 | H30: AF0073 | L30: SB0404
E31: XT0181 | G31: AF0092 | H31: AF0074 | L31: SB0403
E32: XT0183 | G32: AF0093 | H32: AF0075 | L32: SB0402
E33: XT0460 | G33: KA1020 | H33: GR0244 | L33: SB0401
E34: XT0337 | G34: KA0133 | H34: AF0068 | L34: XT0201
E35: XT0336 | G35: KA0136 | H35: AF0067 | L35: XT0564
E36: XT0370 | G36: KA0138 | H36: AF0066 | L36: AU0200
E37: GR0139 | G37: KA0134 | H37: AF0065 | L37: AF0201
E38: IEG0140 | G38: KA0137 | H38: AF0064 | L38: AF0202
E39: KA0314 | G39: KA0131 | H39: AF0063 | L39: GR0200
E40: XT0313 | G40: KA0132 | H40: AF0062
...

Sheet White Labels
A1: (SHT 6) BECKWITH RELAY,SMT130 - (SHT 13) GEN CMPNT | B1: (SHT 10) FG&E CTRL,SMT130 | C1: (SHT 10) FG&E CTRL,SMT130 - (SHT 11) POWERDIST, PANEL | D1: (SHT 13) GEN CMPNT | E1: (SHT 13) GEN CMPNT - (SHT 12) MCC PNL,SMT130 | F1: (SHT 13) GEN CMPNT - (SHT 9) PLC, PANEL | G1: (SHT 13) GEN CMPNT - (SHT 11) POWERDIST, PANEL | H1: (SHT 12) MCC PNL,SMT130 | I1: (SHT 12) MCC PNL,SMT130 - (SHT 11) POWERDIST, PANEL | J1: (SHT 9) PLC, PANEL | K1: (SHT 2) PNL A,SMT130 | L1: (SHT 2) PNL A,SMT130 - (SHT 3) PNL B,SMT130 | M1: (SHT 3) PNL B,SMT130 | N1: (SHT 11) POWERDIST, PANEL | O1: (SHT 11) POWERDIST, PANEL - (SHT 7) TCP, SMT130 | P1: (SHT 7) TCP, SMT130
A2: VGENN | B2: IEG03562 | C2: IEG224013 | D2: AT0140LS(S) | E2: PEG224014 | F2: IEG01407 | G2: IEG224014 | H2: AF0294G | I2: 0V | J2: UV0600G | K2: AF0083G | L2: IEG02303 | M2: AF0065G | N2: GR0146 | O2: IEG22404 | P2: AU0200G
B3: XT05002 | D3: AU0120G | H3: AF0295G | I3: GR0290 | K3: AF0084G | L3: IEG02304 | M3: AF0066G
D4: AU0180G | H4: AU0290G | I4: IEG22403 | K4: AF0085G | L4: IEG02305 | M4: AF0067G
D5: EXCS | K5: AU0080G | L5: IEG02307 | M5: AF0071G
D6: IEG01401 | M6: AF0072G
D7: IEG01402 | M7: AF0073G
D8: IEG01404 | M8: AF045032
D9: PEG0140 | M9: AU0060G
D10: PEG01404 | M10: AU0070G
D11: PMGS | M11: IEG02301
D12: VBUSN | M12: IEG023011
D13: WC8101 | M13: IEG02302
D14: WC8102 | M14: IEG02306
D15: WC8201 | M15: IEG02308
D16: WC8301 | M16: IEG02309
M17: XT04001

Sheet Heat Shrink Labels
A1: (SHT 10) FG&E CTRL,SMT130 | B1: (SHT 13) GEN CMPNT | C1: (SHT 13) GEN CMPNT - (SHT 12) MCC PNL,SMT130 | D1: (SHT 3) PNL B,SMT130
A2: WC1242 | B2: WC8009 | C2: WC7622 | D2: WC4524
A3: WC1243
A4: WC1244
A5: WC1245
A6: WC1246
A7: WC8066
A8: WC8067
A9: WC8069
A10: WC8071

Sheet BECKWITH RELAY,SMT130
A1: BECKWITH RELAY,SMT130
A3: Project # | B3: 4L341
A4: Project Name | B4: SMT130 Stock Units October 2024
A5: Revision | B5: 0.5
A7: Controls DE
A8: Phone:
A9: Controls ME
A10: Phone:
A12: From | G12: To
A13: Device ID | B13: Cable (W) Conductor (SC) Jumper Clip (JC) | C13: Wire No. | D13: Wire ID | E13: Gauge/Size | F13: Page/Zone | G13: Device ID | H13: Location | I13: Page/Zone
A14: KA0460:10 | B14: SC | C14: KA046010 | D14: WHT | E14: 20 | F14: 45.A3 | G14: KA0330:22 | H14: GEN CMPNT | I14: 45.A2 | M14: USED
A15: KA0460:11 | B15: SC | C15: KA046011 | D15: WHT | E15: 20 | F15: 45.A3 | G15: KA2672:11 | H15: GEN CMPNT | I15: 45.A2 | M15: USED
A16: KA0460:12 | B16: SC | C16: KA046012 | D16: WHT | E16: 20 | F16: 45.A3 | G16: AF0181:39 | H16: GEN CMPNT | I16: 45.A6 | M16: USED
A17: KA0460:13 | B17: SC | C17: KA046013 | D17: WHT | E17: 20 | F17: 45.A3 | G17: AF0181:07 | H17: GEN CMPNT | I17: 45.A6 | M17: USED
A18: KA0460:15 | B18: SC | C18: KA046015 | D18: WHT | E18: 20 | F18: 45.A3 | G18: AF0181:40 | H18: GEN CMPNT | I18: 45.B6 | M18: USED
A19: KA0460:16 | B19: SC | C19: KA046016 | D19: WHT | E19: 20 | F19: 45.A3 | G19: AF0181:08 | H19: GEN CMPNT | I19: 45.B6 | M19: USED
A20: KA0460:18 | B20: SC | C20: KA046018 | D20: WHT | E20: 20 | F20: 45.A3 | G20: AF0181:41 | H20: GEN CMPNT | I20: 45.B6 | M20: USED
A21: KA0460:19 | B21: SC | C21: KA046019 | D21: WHT | E21: 20 | F21: 45.A3 | G21: AF0181:09 | H21: GEN CMPNT | I21: 45.B6 | M21: USED
A22: KA0460:23 | B22: SC | C22: KA046023 | D22: WHT | E22: 20 | F22: 45.A3 | G22: AF0122:09 | H22: GEN CMPNT | I22: 45.C6 | M22: USED
A23: KA0460:24 | B23: SC | C23: KA046024 | D23: WHT | E23: 20 | F23: 45.A3 | G23: AF0122:41 | H23: GEN CMPNT | I23: 45.C6 | M23: USED
A24: KA0460:29 | B24: SC | C24: KA046029 | D24: WHT | E24: 20 | F24: 45.A3 | G24: AF0181:10 | H24: GEN CMPNT | I24: 45.C6 | M24: USED
A25: KA0460:30 | B25: SC | C25: KA046030 | D25: WHT | E25: 20 | F25: 45.A3 | G25: AF0181:42 | H25: GEN CMPNT | I25: 45.C6 | M25: USED
... A53: KA0460:63 | B53: SC | C53: 0V | D53: WHT | E53: 14 | F53: 45.A3 | G53: XT0104:5 | H53: POWERDIST, PANEL | I53: 19.B4 | M53: USED
F55: SolarTools ver. 24.0.84.24712 (Jul 31, 2025)
A56: Report date: 2/13/2026 2:20 PM

Sheet CONTROL,2-BAY
A1: CONTROL,2-BAY
A3: Project # | B3: 4L341
A4: Project Name | B4: SMT130 Stock Units October 2024
A5: Revision | B5: 0.5
A7: Controls DE
A8: Phone:
A9: Controls ME
A10: Phone:
A12: From | G12: To
A13: Device ID | B13: Cable (W) Conductor (SC) Jumper Clip (JC) | C13: Wire No. | D13: Wire ID | E13: Gauge/Size | F13: Page/Zone | G13: Device ID | H13: Location | I13: Page/Zone
A14: EL0273:B1 | B14: SC | C14: FU0273 | D14: WHT | E14: 16 | F14: 41.B4 | G14: FU0273:LD | H14: PWR DST,DR,SMT130 | I14: 41.B3 | M14: USED
A15: EL0273:W1 | B15: SC | C15: 0V | D15: WHT | E15: 16 | F15: 41.B4 | G15: XT0562:2 | H15: PWR DST,DR,SMT130 | I15: 41.B2 | M15: USED
F17: SolarTools ver. 24.0.84.24712 (Jul 31, 2025)
A18: Report date: 2/13/2026 2:20 PM

Sheet CONTROL,JB70
A1: CONTROL,JB70
A3: Project # | B3: 4L341
A4: Project Name | B4: SMT130 Stock Units October 2024
A5: Revision | B5: 0.5
A7: Controls DE
A8: Phone:
A9: Controls ME
A10: Phone:
A12: From | G12: To
A13: Device ID | B13: Cable (W) Conductor (SC) Jumper Clip (JC) | C13: Wire No. | D13: Wire ID | E13: Gauge/Size | F13: Page/Zone | G13: Device ID | H13: Location | I13: Page/Zone
A14: GR1000: | B14: SC | C14: GR1000 | D14: GRN/YEL | E14: 14 | F14: 31.B4 | G14: FRAME | H14: CONTROL,JB70 | I14: 31.B4 | M14: USED
A15: GR1100: | B15: SC | C15: GR1100 | D15: GRN/YEL | E15: 14 | F15: 31.B4 | G15: FRAME | H15: CONTROL,JB70 | I15: 31.B4 | M15: USED
A16: HA0472:BLK-2 | B16: WC5072 | C16: KA087511 | D16: BLK | E16: 16 | F16: 34.A1 | G16: XT0136:1 | H16: PNL A,SMT130 | I16: 34.A5 | M16: USED
A17: HA0472:BLK-1 | B17: WC5072 | C17: KA0875A2 | D17: WHT | E17: 16 | F17: 34.A1 | G17: XT0136:2 | H17: PNL A,SMT130 | I17: 34.A5 | M17: USED
F19: SolarTools ver. 24.0.84.24712 (Jul 31, 2025)
A20: Report date: 2/13/2026 2:20 PM

Sheet FG&E CTRL,SMT130
A1: FG&E CTRL,SMT130
A3: Project # | B3: 4L341
A4: Project Name | B4: SMT130 Stock Units October 2024
A5: Revision | B5: 0.5
A7: Controls DE
A8: Phone:
A9: Controls ME
A10: Phone:
A12: From | G12: To
A13: Device ID | B13: Cable (W) Conductor (SC) Jumper Clip (JC) | C13: Wire No. | D13: Wire ID | E13: Gauge/Size | F13: Page/Zone | G13: Device ID | H13: Location | I13: Page/Zone
A14: XT0170:1 | B14: JC | C14: 0V | D14: CLIP | E14: --- | F14: 40.A2 | G14: XT0170:2 | H14: FG&E CTRL,SMT130 | I14: 40.A2 | M14: USED
A15: XT0171:1 | B15: JC | C15: FU0172 | D15: CLIP | E15: --- | F15: 40.B3 | G15: XT0171:2 | H15: FG&E CTRL,SMT130 | I15: 40.C3 | M15: USED
A16: XT0173:2 | B16: JC | C16: FU0171 | D16: CLIP | E16: --- | F16: 40.A2 | G16: XT0173:1 | H16: FG&E CTRL,SMT130 | I16: 40.A2 | M16: USED
A17: XT0510:2 | B17: JC | C17: FU0136 | D17: CLIP | E17: --- | F17: 39.A5 | G17: XT0510:1 | H17: FG&E CTRL,SMT130 | I17: 39.A5 | M17: USED
A18: XT0510:3 | B18: JC | C18: 0V | D18: CLIP | E18: --- | F18: 39.A5 | G18: XT0510:4 | H18: FG&E CTRL,SMT130 | I18: 39.A5 | M18: USED
A19: AF0500:12 | B19: SC | C19: XT05002 | D19: GRN | E19: 16 | F19: 39.B5 | G19: XT0500:2 | H19: FG&E CTRL,SMT130 | I19: 39.C5 | M19: USED
A20: AF0510:32 | B20: SC | C20: XT05002 | D20: GRN | E20: 16 | F20: 39.B4 | G20: XT0500:2 | H20: FG&E CTRL,SMT130 | I20: 39.C5 | M20: USED
A21: AF0510:53 | B21: SC | C21: 0V | D21: WHT | E21: 16 | F21: 39.B4 | G21: XT0510:3 | H21: FG&E CTRL,SMT130 | I21: 39.A5 | M21: USED
A22: AF0510:55 | B22: SC | C22: FU0510 | D22: WHT | E22: 16 | F22: 39.B4 | G22: FU0510:LD | H22: FG&E CTRL,SMT130 | I22: 39.A4 | M22: USED
A23: AT0170:1 | B23: SC | C23: UV01705 | D23: WHT | E23: 14 | F23: 40.A5 | G23: UV0170:5(+) | H23: FG&E CTRL,SMT130 | I23: 40.A3 | M23: USED
A24: AT0170:11 | B24: SC | C24: SA017023 | D24: WHT | E24: 20 | F24: 52.A6 | G24: XT0171:3 | H24: FG&E CTRL,SMT130 | I24: 52.A6 | M24: USED
A25: AT0170:12 | B25: SC | C25: SA017024 | D25: WHT | E25: 20 | F25: 52.A6 | G25: XT0171:4 | H25: FG&E CTRL,SMT130 | I25: 52.A6 | M25: USED
... A173: XT0510:3 | B173: SC | C173: 0V | D173: WHT | E173: 14 | F173: 39.A5 | G173: XT0104:5 | H173: POWERDIST, PANEL | I173: 19.B4 | M173: USED
F175: SolarTools ver. 24.0.84.24712 (Jul 31, 2025)
A176: Report date: 2/13/2026 2:20 PM

Sheet GEN CMPNT
A1: GEN CMPNT
A3: Project # | B3: 4L341
A4: Project Name | B4: SMT130 Stock Units October 2024
A5: Revision | B5: 0.5
A7: Controls DE
A8: Phone:
A9: Controls ME
A10: Phone:
A12: From | G12: To
A13: Device ID | B13: Cable (W) Conductor (SC) Jumper Clip (JC) | C13: Wire No. | D13: Wire ID | E13: Gauge/Size | F13: Page/Zone | G13: Device ID | H13: Location | I13: Page/Zone
A14: XT0120:1 | B14: JC | C14: 0V | D14: CLIP | E14: --- | F14: 36.B1 | G14: XT0120:2 | H14: GEN CMPNT | I14: 36.B1 | M14: USED
A15: XT0180:1 | B15: JC | C15: 0V | D15: CLIP | E15: --- | F15: 36.D1 | G15: XT0180:2 | H15: GEN CMPNT | I15: 36.D1 | M15: USED
A16: XT0335:1 | B16: JC | C16: FU0332 | D16: CLIP | E16: --- | F16: 20.A4 | G16: XT0335:2 | H16: GEN CMPNT | I16: 20.A4 | M16: USED
A17: XT0335:2 | B17: JC | C17: FU0332 | D17: CLIP | E17: --- | F17: 20.A4 | G17: XT0335:3 | H17: GEN CMPNT | I17: 20.B4 | M17: USED
A18: XT0335:3 | B18: JC | C18: FU0332 | D18: CLIP | E18: --- | F18: 20.B4 | G18: XT0335:4 | H18: GEN CMPNT | I18: 20.B4 | M18: USED
A19: XT0336:1 | B19: JC | C19: 0V | D19: CLIP | E19: --- | F19: 20.A4 | G19: XT0336:2 | H19: GEN CMPNT | I19: 20.B4 | M19: USED
A20: XT0336:2 | B20: JC | C20: 0V | D20: CLIP | E20: --- | F20: 20.B4 | G20: XT0336:3 | H20: GEN CMPNT | I20: 20.B4 | M20: USED
A21: XT0336:3 | B21: JC | C21: 0V | D21: CLIP | E21: --- | F21: 20.B4 | G21: XT0336:4 | H21: GEN CMPNT | I21: 20.B4 | M21: USED
A22: XT0337:11 | B22: JC | C22: FU0333 | D22: CLIP | E22: --- | F22: 37.A3 | G22: XT0337:12 | H22: GEN CMPNT | I22: 37.B5 | M22: USED
A23: XT0337:16 | B23: JC | C23: 0V | D23: CLIP | E23: --- | F23: 37.A6 | G23: XT0337:17 | H23: GEN CMPNT | I23: 37.A6 | M23: USED
A24: XT0350:2 | B24: JC | C24: CCT1(+) | D24: CLIP | E24: --- | F24: 110.A4 | G24: XT0350:1 | H24: GEN CMPNT | I24: 110.A4 | M24: USED
A25: XT0350:4 | B25: JC | C25: CCT1(-) | D25: CLIP | E25: --- | F25: 110.A4 | G25: XT0350:3 | H25: GEN CMPNT | I25: 110.A4 | M25: USED
... A54: AF0121:COM | B54: SC | C54: 0V | D54: WHT | E54: 16 | F54: 36.B2 | G54: XT0120:2 | H54: GEN CMPNT | I54: 36.B1 | M54: USED
A55: AF0121:J | B55: SC | C55: * | F55: 36.B2 | G55: AF0122:P | H55: GEN CMPNT | I55: 36.B3 | M55: USED
A56: AF0121:V+ | B56: SC | C56: FU0121 | D56: WHT | E56: 16 | F56: 36.B2 | G56: FU0121:LD | H56: GEN CMPNT | I56: 36.B1 | M56: USED
A57: KA0330:11 | B57: SC | C57: 012200 | D57: WHT | E57: 20 | F57: 37.D6 | G57: AF0122:00 | H57: GEN CMPNT | I57: 37.D5 | M57: USED
A58: KA0331:11 | B58: SC | C58: 012201 | D58: WHT | E58: 20 | F58: 37.D6 | G58: AF0122:01 | H58: GEN CMPNT | I58: 37.D5 | M58: USED
A59: KA0310:11 | B59: SC | C59: 012202 | D59: WHT | E59: 20 | F59: 35.B7 | G59: AF0122:02 | H59: GEN CMPNT | I59: 35.B6 | M59: USED
A60: AF0122:10 | B60: SC | C60: KA046111 | D60: WHT | E60: 20 | F60: 45.D6 | G60: XT0460:8 | H60: GEN CMPNT | I60: 45.D5 | M60: USED
A61: KA0330:14 | B61: SC | C61: 012232 | D61: WHT | E61: 20 | F61: 37.D6 | G61: AF0122:32 | H61: GEN CMPNT | I61: 37.D5 | M61: USED
A62: KA0331:14 | B62: SC | C62: 012233 | D62: WHT | E62: 20 | F62: 37.D6 | G62: AF0122:33 | H62: GEN CMPNT | I62: 37.D5 | M62: USED
A63: KA0310:14 | B63: SC | C63: 012234 | D63: WHT | E63: 20 | F63: 35.B7 | G63: AF0122:34 | H63: GEN CMPNT | I63: 35.B6 | M63: USED
A64: XT0352:4 | B64: SC | C64: JW03524 | D64: CLIP | E64: -- | F64: 110.B4 | G64: XT0352:5 | H64: GEN CMPNT | I64: 110.B4 | M64: USED
A65: XT0352:5 | B65: SC | C65: JW03525 | D65: CLIP | E65: -- | F65: 110.B4 | G65: XT0352:6 | H65: GEN CMPNT | I65: 110.B4 | M65: USED
A66: XT0352:6 | B66: SC | C66: JW03526 | D66: CLIP | E66: -- | F66: 110.B4 | G66: XT0352:7 | H66: GEN CMPNT | I66: 110.B4 | M66: USED
A67: AF0122:05 | B67: SC | C67: JW012205 | D67: VIO | E67: 20 | F67: 107.D7 | G67: AF0122:37 | H67: GEN CMPNT | I67: 107.D7 | M67: USED
... A70: AF0122:COM | B70: SC | C70: AU0120N | D70: WHT | E70: 16 | F70: 36.B3 | G70: AU0120:COM | H70: GEN CMPNT | I70: 36.A2 | M70: USED
A71: AF0122:J | B71: SC | C71: * | F71: 36.B3 | G71: AF0123:P | H71: GEN CMPNT | I71: 36.B3 | M71: USED
A72: AF0122:V+ | B72: SC | C72: AF0123P | D72: WHT | E72: 16 | F72: 36.B3 | G72: AF0123:V+ | H72: GEN CMPNT | I72: 36.B3 | M72: USED
A73: AF0122:V+ | B73: SC | C73: AU0120P | D73: WHT | E73: 16 | F73: 36.B3 | G73: AU0120:V+ | H73: GEN CMPNT | I73: 36.A2 | M73: USED
...

Sheet MCC PNL,SMT130
A1: MCC PNL,SMT130
A3: Project # | B3: 4L341
A4: Project Name | B4: SMT130 Stock Units October 2024
A5: Revision | B5: 0.5
A7: Controls DE
A8: Phone:
A9: Controls ME
A10: Phone:
A12: From | G12: To
A13: Device ID | B13: Cable (W) Conductor (SC) Jumper Clip (JC) | C13: Wire No. | D13: Wire ID | E13: Gauge/Size | F13: Page/Zone | G13: Device ID | H13: Location | I13: Page/Zone
A14: XT0295:1 | B14: JC | C14: 0V | D14: CLIP | E14: --- | F14: 46.B1 | G14: XT0295:2 | H14: MCC PNL,SMT130 | I14: 46.B1 | M14: USED
A15: XT0295:2 | B15: JC | C15: 0V | D15: CLIP | E15: --- | F15: 46.B1 | G15: XT0295:3 | H15: MCC PNL,SMT130 | I15: 46.C1 | M15: USED
A16: XT2920:6 | B16: SC | C16: JW29205 | D16: VIO | E16: 20 | F16: 144.B5 | G16: XT2920:5 | H16: MCC PNL,SMT130 | I16: 144.B5 | M16: USED
A17: XT2920:8 | B17: SC | C17: JW2920 | D17: VIO | E17: 20 | F17: 144.B5 | G17: XT2920:7 | H17: MCC PNL,SMT130 | I17: 144.B5 | M17: USED
A18: KA2970:A1 | B18: SC | C18: KA2970A1 | D18: WHT | E18: 20 | F18: 100.B7 | G18: AF0291:01 | H18: MCC PNL,SMT130 | I18: 100.B6 | M18: USED
A19: KA2960:A1 | B19: SC | C19: KA2960A1 | D19: WHT | E19: 20 | F19: 112.B6 | G19: AF0291:03 | H19: MCC PNL,SMT130 | I19: 112.B6 | M19: USED
A20: AF0291:07 | B20: SC | C20: SH04715 | D20: WHT | E20: 20 | F20: 50.A7 | G20: XT0292:8 | H20: MCC PNL,SMT130 | I20: 50.A5 | M20: USED
A21: AF0291:08 | B21: SC | C21: SH04705 | D21: WHT | E21: 20 | F21: 50.B7 | G21: XT0292:14 | H21: MCC PNL,SMT130 | I21: 50.B5 | M21: USED
A22: AF0291:09 | B22: SC | C22: SH04755 | D22: WHT | E22: 20 | F22: 49.A6 | G22: XT0292:26 | H22: MCC PNL,SMT130 | I22: 49.A5 | M22: USED
A23: AF0291:10 | B23: SC | C23: HL0409BA | D23: WHT | E23: 20 | F23: 50.C7 | G23: XT0292:18 | H23: MCC PNL,SMT130 | I23: 50.C5 | M23: USED
A24: AF0291:11 | B24: SC | C24: HL0411BA | D24: WHT | E24: 20 | F24: 50.D7 | G24: XT0292:20 | H24: MCC PNL,SMT130 | I24: 50.D5 | M24: USED
A25: KA2970:A2 | B25: SC | C25: KA2970A2 | D25: WHT | E25: 20 | F25: 100.B7 | G25: AF0291:17 | H25: MCC PNL,SMT130 | I25: 100.B6 | M25: USED
... A32: AF0291:COM | B32: SC | C32: 0V | D32: WHT | E32: 16 | F32: 46.B2 | G32: XT0295:1 | H32: MCC PNL,SMT130 | I32: 46.B1 | M32: USED
A33: AF0291:P | B33: SC | C33: * | F33: 46.B2 | G33: AU0290:J | H33: MCC PNL,SMT130 | I33: 46.A2 | M33: USED
A34: AF0291:V+ | B34: SC | C34: FU0291 | D34: WHT | E34: 16 | F34: 46.B2 | G34: FU0291:LD | H34: MCC PNL,SMT130 | I34: 46.B1 | M34: USED
A35: AF0292:COM | B35: SC | C35: AF0292N | D35: WHT | E35: 16 | F35: 46.B3 | G35: AF0293:COM | H35: MCC PNL,SMT130 | I35: 46.B3 | M35: USED
A36: AF0292:COM | B36: SC | C36: 0V | D36: WHT | E36: 16 | F36: 46.B3 | G36: XT0295:2 | H36: MCC PNL,SMT130 | I36: 46.B1 | M36: USED
A37: AF0292:V+ | B37: SC | C37: AF0292P | D37: WHT | E37: 16 | F37: 46.B3 | G37: AF0293:V+ | H37: MCC PNL,SMT130 | I37: 46.B3 | M37: USED
A38: AF0292:V+ | B38: SC | C38: FU0294 | D38: WHT | E38: 16 | F38: 46.B3 | G38: FU0294:LD | H38: MCC PNL,SMT130 | I38: 46.B1 | M38: USED
A39: AF0293:01 | B39: SC | C39: 0V | D39: WHT | E39: 20 | F39: 18.A7 | G39: XT0295:3 | H39: MCC PNL,SMT130 | I39: 46.C1 | M39: USED
A40: AF0293:03 | B40: SC | C40: 0V | D40: WHT | E40: 16 | F40: 18.A7 | G40: XT0295:3 | H40: MCC PNL,SMT130 | I40: 46.C1 | M40: USED
A41: AF0293:COM | B41: SC | C41: AF0293N | D41: WHT | E41: 16 | F41: 46.B3 | G41: AF0294:COM | H41: MCC PNL,SMT130 | I41: 46.A4 | M41: USED
A42: AF0293:SH | B42: SC | C42: AF0294G | D42: GRN | E42: 14 | F42: 46.B3 | G42: AF0294:SH | H42: MCC PNL,SMT130 | I42: 46.A4 | M42: USED
A43: AF0293:SH | B43: SC | C43: AU0290G | D43: GRN | E43: 14 | F43: 46.B3 | G43: AU0290:GND | H43: MCC PNL,SMT130 | I43: 46.A2 | M43: USED
A44: AF0293:V+ | B44: SC | C44: AF0293P | D44: WHT | E44: 16 | F44: 46.B3 | G44: AF0294:V+ | H44: MCC PNL,SMT130 | I44: 46.A4 | M44: USED
A45: AF0294:COM | B45: SC | C45: AF0294N | D45: WHT | E45: 16 | F45: 46.A4 | G45: AF0295:COM | H45: MCC PNL,SMT130 | I45: 46.A5 | M45: USED
... A129: AU0290:L2 | B129: WC0029 | C129: AU0290L2 | D129: ENET | E129: CABLE | F129: 2.B4 | G129: AU0200:L1 | H129: TCP, SMT130 | I129: 2.B5 | M129: USED
F131: SolarTools ver. 24.0.84.24712 (Jul 31, 2025)
A132: Report date: 2/13/2026 2:19 PM

Sheet PLC, PANEL
A1: PLC, PANEL
A3: Project # | B3: 4L341
A4: Project Name | B4: SMT130 Stock Units October 2024
A5: Revision | B5: 0.5
A7: Controls DE
A8: Phone:
A9: Controls ME
A10: Phone:
A12: From | G12: To
A13: Device ID | B13: Cable (W) Conductor (SC) Jumper Clip (JC) | C13: Wire No. | D13: Wire ID | E13: Gauge/Size | F13: Page/Zone | G13: Device ID | H13: Location | I13: Page/Zone
A14: AR0600:IE1 | B14: SC | C14: UV0600G | D14: GRN | E14: 14 | F14: 4.A1 | G14: UV0600:GND | H14: PLC, PANEL | I14: 4.B2 | M14: USED
A15: AP0602:L2 | B15: WC0602 | C15: AP0602L2 | D15: ENET | E15: CABLE | F15: 2.B3 | G15: AP0603:L1 | H15: PLC, PANEL | I15: 2.B4 | M15: USED
A16: AP0606:L1 | B16: WC0606 | C16: AP0606L1 | D16: ENET | E16: CABLE | F16: 4.C3 | G16: LSENET1:1 | H16: JB774 | I16: 4.C2 | M16: USED
A17: AP0606:L2 | B17: WC0607 | C17: AP0606L2 | D17: ENET | E17: CABLE | F17: 4.C3 | G17: LSENET2:1 | H17: JB774 | I17: 4.C2 | M17: USED
A18: AP0609:L1 | B18: WC0609 | C18: AP0609L1 | D18: ENET | E18: CABLE | F18: 4.D3 | G18: CCAP0609:1 | H18: JB774 | I18: 4.D2 | M18: USED
A19: AP0602:L1 | B19: WC0017 | C19: AT0170L2 | D19: ENET | E19: CABLE | F19: 2.B3 | G19: AT0170:L2 | H19: FG&E CTRL,SMT130 | I19: 2.B2 | M19: USED
A20: AR0600:IE2 | B20: SC | C20: IEG01407 | D20: GRN | E20: 12 | F20: 4.A1 | G20: IEG0140:7 | H20: GEN CMPNT | I20: 4.B6 | M20: USED
A21: AP0603:L2 | B21: WC0603 | C21: AP0603L2 | D21: ENET | E21: CABLE | F21: 2.B4 | G21: AU0290:L1 | H21: MCC PNL,SMT130 | I21: 2.B4 | M21: USED
A22: UV0600:(-) | B22: SC | C22: 0V | D22: WHT | E22: 14 | F22: 4.B2 | G22: XT0104:3 | H22: POWERDIST, PANEL | I22: 19.B4 | M22: USED
A23: UV0600:(+) | B23: SC | C23: FU0010 | D23: WHT | E23: 16 | F23: 4.B2 | G23: FU0010:LD | H23: POWERDIST, PANEL | I23: 4.B1 | M23: USED
A24: AP0607:L2 | B24: WC7028 | C24: BA0701ENET | D24: ENET | E24: CABLE | F24: 4.A5 | G24: BA0701:ENET | H24: POWERDIST, PANEL | I24: 5.B3 | M24: USED
A25: AP0607:L1 | B25: WC7071 | C25: AP0607L1 | D25: ENET | E25: CABLE | F25: 4.A5 | G25: BA0700:2 | H25: POWERDIST, PANEL | I25: 5.A4 | M25: USED
F27: SolarTools ver. 24.0.84.24712 (Jul 31, 2025)
A28: Report date: 2/13/2026 2:19 PM

Sheet PNL A,SMT130
A1: PNL A,SMT130
A3: Project # | B3: 4L341
A4: Project Name | B4: SMT130 Stock Units October 2024
A5: Revision | B5: 0.5
A7: Controls DE
A8: Phone:
A9: Controls ME
A10: Phone:
A12: From | G12: To
A13: Device ID | B13: Cable (W) Conductor (SC) Jumper Clip (JC) | C13: Wire No. | D13: Wire ID | E13: Gauge/Size | F13: Page/Zone | G13: Device ID | H13: Location | I13: Page/Zone
A14: XT0080:1 | B14: JC | C14: 0V | D14: CLIP | E14: --- | F14: 22.A6 | G14: XT0080:2 | H14: PNL A,SMT130 | I14: 23.A6 | M14: USED
A15: XT0080:2 | B15: JC | C15: 0V | D15: CLIP | E15: --- | F15: 23.A6 | G15: XT0080:3 | H15: PNL A,SMT130 | I15: 28.A6 | M15: USED
A16: XT0080:3 | B16: JC | C16: 0V | D16: CLIP | E16: --- | F16: 28.A6 | G16: XT0080:4 | H16: PNL A,SMT130 | I16: 29.A6 | M16: USED
A17: XT0081:2 | B17: JC | C17: FU0139 | D17: CLIP | E17: --- | F17: 23.A2 | G17: XT0081:3 | H17: PNL A,SMT130 | I17: 28.A2 | M17: USED
A18: XT0081:3 | B18: JC | C18: FU0139 | D18: CLIP | E18: --- | F18: 28.A2 | G18: XT0081:4 | H18: PNL A,SMT130 | I18: 29.A3 | M18: USED
A19: XT0081:4 | B19: JC | C19: FU0139 | D19: CLIP | E19: --- | F19: 29.A3 | G19: XT0081:5 | H19: PNL A,SMT130 | I19: 29.A3 | M19: USED
A20: XT0081:5 | B20: JC | C20: FU0139 | D20: CLIP | E20: --- | F20: 29.A3 | G20: XT0081:6 | H20: PNL A,SMT130 | I20: 29.A3 | M20: USED
A21: XT0082:1 | B21: JC | C21: 0V | D21: CLIP | E21: --- | F21: 25.A1 | G21: XT0082:2 | H21: PNL A,SMT130 | I21: 25.B1 | M21: USED
A22: XT0082:2 | B22: JC | C22: 0V | D22: CLIP | E22: --- | F22: 25.B1 | G22: XT0082:3 | H22: PNL A,SMT130 | I22: 25.B1 | M22: USED
A23: XT0089:1 | B23: JC | C23: KA0131A1 | D23: CLIP | E23: --- | F23: 24.D4 | G23: XT0089:2 | H23: PNL A,SMT130 | I23: 24.D4 | M23: USED
A24: XT0090:1 | B24: JC | C24: 0V | D24: CLIP | E24: --- | F24: 25.D1 | G24: XT0090:2 | H24: PNL A,SMT130 | I24: 25.D1 | M24: USED
A25: XT0134:1 | B25: JC | C25: 0V | D25: CLIP | E25: --- | F25: 26.A4 | G25: XT0134:2 | H25: PNL A,SMT130 | I25: 26.A4 | M25: USED
... A33: AF0081:COM | B33: SC | C33: 0V | D33: WHT | E33: 16 | F33: 25.B2 | G33: XT0082:3 | H33: PNL A,SMT130 | I33: 25.B1 | M33: USED
A34: AF0081:J | B34: SC | C34: * | F34: 25.B2 | G34: AF0082:P | H34: PNL A,SMT130 | I34: 25.B3 | M34: USED
A35: AF0081:V+ | B35: SC | C35: FU0082 | D35: WHT | E35: 16 | F35: 25.B2 | G35: FU0082:LD | H35: PNL A,SMT130 | I35: 25.B1 | M35: USED
A36: AF0082:COM | B36: SC | C36: AF0082N | D36: WHT | E36: 16 | F36: 25.B3 | G36: AF0083:COM | H36: PNL A,SMT130 | I36: 25.B3 | M36: USED
A37: AF0082:COM | B37: SC | C37: AU0080N | D37: WHT | E37: 16 | F37: 25.B3 | G37: AU0080:COM | H37: PNL A,SMT130 | I37: 25.A2 | M37: USED
A38: AF0082:J | B38: SC | C38: * | F38: 25.B3 | G38: AF0083:P | H38: PNL A,SMT130 | I38: 25.B3 | M38: USED
A39: AF0082:V+ | B39: SC | C39: AF0082P | D39: WHT | E39: 16 | F39: 25.B3 | G39: AF0083:V+ | H39: PNL A,SMT130 | I39: 25.B3 | M39: USED
A40: AF0082:V+ | B40: SC | C40: AU0080P | D40: WHT | E40: 16 | F40: 25.B3 | G40: AU0080:V+ | H40: PNL A,SMT130 | I40: 25.A2 | M40: USED
A41: AF0083:COM | B41: SC | C41: AF0083N | D41: WHT | E41: 16 | F41: 25.B3 | G41: AF0084:COM | H41: PNL A,SMT130 | I41: 25.B4 | M41: USED
A42: AF0083:J | B42: SC | C42: * | F42: 25.B3 | G42: AF0084:P | H42: PNL A,SMT130 | I42: 25.B4 | M42: USED
A43: AF0083:SH | B43: SC | C43: AF0083G | D43: GRN | E43: 14 | F43: 25.B3 | G43: AF0084:SH | H43: PNL A,SMT130 | I43: 25.B4 | M43: USED
A44: AF0083:SH | B44: SC | C44: AU0080G | D44: GRN | E44: 14 | F44: 25.B3 | G44: AU0080:GND | H44: PNL A,SMT130 | I44: 25.A2 | M44: USED
A45: AF0083:V+ | B45: SC | C45: AF0083P | D45: WHT | E45: 16 | F45: 25.B3 | G45: AF0084:V+ | H45: PNL A,SMT130 | I45: 25.B4 | M45: USED
A46: AF0084:COM | B46: SC | C46: AF0084N | D46: WHT | E46: 16 | F46: 25.B4 | G46: AF0085:COM | H46: PNL A,SMT130 | I46: 25.B5 | M46: USED
A47: AF0084:J | B47: SC | C47: * | F47: 25.B4 | G47: AF0085:P | H47: PNL A,SMT130 | I47: 25.B5 | M47: USED
A48: AF0084:SH | B48: SC | C48: AF0084G | D48: GRN | E48: 14 | F48: 25.B4 | G48: AF0085:SH | H48: PNL A,SMT130 | I48: 25.B5 | M48: USED
A49: AF0084:V+ | B49: SC | C49: AF0084P | D49: WHT | E49: 16 | F49: 25.B4 | G49: AF0085:V+ | H49: PNL A,SMT130 | I49: 25.B5 | M49: USED
A50: AF0085:COM | B50: SC | C50: AF0085N | D50: WHT | E50: 16 | F50: 25.B5 | G50: AF0086:COM | H50: PNL A,SMT130 | I50: 25.B5 | M50: USED
...

Sheet PNL B,SMT130
A1: PNL B,SMT130
A3: Project # | B3: 4L341
A4: Project Name | B4: SMT130 Stock Units October 2024
A5: Revision | B5: 0.5
A7: Controls DE
A8: Phone:
A9: Controls ME
A10: Phone:
A12: From | G12: To
A13: Device ID | B13: Cable (W) Conductor (SC) Jumper Clip (JC) | C13: Wire No. | D13: Wire ID | E13: Gauge/Size | F13: Page/Zone | G13: Device ID | H13: Location | I13: Page/Zone
A14: XT0060:1 | B14: JC | C14: 0V | D14: CLIP | E14: --- | F14: 30.A1 | G14: XT0060:2 | H14: PNL B,SMT130 | I14: 30.B1 | M14: USED
A15: XT0060:2 | B15: JC | C15: 0V | D15: CLIP | E15: --- | F15: 30.B1 | G15: XT0060:3 | H15: PNL B,SMT130 | I15: 30.B1 | M15: USED
A16: XT0070:1 | B16: JC | C16: 0V | D16: CLIP | E16: --- | F16: 30.D1 | G16: XT0070:2 | H16: PNL B,SMT130 | I16: 30.D1 | M16: USED
A17: XT0235:1 | B17: JC | C17: 0V | D17: CLIP | E17: --- | F17: 27.A1 | G17: XT0235:2 | H17: PNL B,SMT130 | I17: 27.A1 | M17: USED
A18: XT0235:2 | B18: JC | C18: 0V | D18: CLIP | E18: --- | F18: 27.A1 | G18: XT0235:3 | H18: PNL B,SMT130 | I18: 27.B1 | M18: USED
A19: KA0233:14 | B19: SC | C19: 006102 | D19: WHT | E19: 20 | F19: 65.B7 | G19: AF0061:02 | H19: PNL B,SMT130 | I19: 65.B5 | M19: USED
A20: KA0234:14 | B20: SC | C20: 006114 | D20: WHT | E20: 20 | F20: 63.B7 | G20: AF0061:14 | H20: PNL B,SMT130 | I20: 63.B5 | M20: USED
A21: AF0061:COM | B21: SC | C21: 0V | D21: WHT | E21: 16 | F21: 30.B2 | G21: XT0060:2 | H21: PNL B,SMT130 | I21: 30.B1 | M21: USED
A22: AF0061:V+ | B22: SC | C22: FU0062 | D22: WHT | E22: 16 | F22: 30.B2 | G22: FU0062:LD | H22: PNL B,SMT130 | I22: 30.B1 | M22: USED
A23: AF0062:COM | B23: SC | C23: 0V | D23: WHT | E23: 16 | F23: 30.B3 | G23: XT0060:3 | H23: PNL B,SMT130 | I23: 30.B1 | M23: USED
A24: AF0062:V+ | B24: SC | C24: FU0063 | D24: WHT | E24: 16 | F24: 30.B3 | G24: FU0063:LD | H24: PNL B,SMT130 | I24: 30.B1 | M24: USED
A25: KA0222:14 | B25: SC | C25: 006306 | D25: WHT | E25: 20 | F25: 72.C7 | G25: AF0063:06 | H25: PNL B,SMT130 | I25: 72.C6 | M25: USED
... A33: AF0065:COM | B33: SC | C33: AF0065N | D33: WHT | E33: 16 | F33: 30.A5 | G33: AF0066:COM | H33: PNL B,SMT130 | I33: 30.B5 | M33: USED
A34: AF0065:J | B34: SC | C34: * | F34: 30.A5 | G34: AF0066:P | H34: PNL B,SMT130 | I34: 30.B5 | M34: USED
A35: AF0065:SH | B35: SC | C35: AF0065G | D35: GRN | E35: 14 | F35: 30.A5 | G35: AF0066:SH | H35: PNL B,SMT130 | I35: 30.B5 | M35: USED
A36: AF0065:SH | B36: SC | C36: AU0060G | D36: GRN | E36: 14 | F36: 30.A5 | G36: AU0060:GND | H36: PNL B,SMT130 | I36: 30.A2 | M36: USED
A37: AF0065:V+ | B37: SC | C37: AF0065P | D37: WHT | E37: 16 | F37: 30.A5 | G37: AF0066:V+ | H37: PNL B,SMT130 | I37: 30.B5 | M37: USED
A38: AF0066:COM | B38: SC | C38: AF0066N | D38: WHT | E38: 16 | F38: 30.B5 | G38: AF0067:COM | H38: PNL B,SMT130 | I38: 30.A6 | M38: USED
A39: AF0066:SH | B39: SC | C39: AF0066G | D39: GRN | E39: 14 | F39: 30.B5 | G39: AF0067:SH | H39: PNL B,SMT130 | I39: 30.A6 | M39: USED
A40: AF0066:V+ | B40: SC | C40: AF0066P | D40: WHT | E40: 16 | F40: 30.B5 | G40: AF0067:V+ | H40: PNL B,SMT130 | I40: 30.A6 | M40: USED
A41: AF0067:COM | B41: SC | C41: AF0067N | D41: WHT | E41: 16 | F41: 30.A6 | G41: AF0068:COM | H41: PNL B,SMT130 | I41: 30.B6 | M41: USED
A42: AF0067:J | B42: SC | C42: * | F42: 30.A6 | G42: AF0068:P | H42: PNL B,SMT130 | I42: 30.B6 | M42: USED
A43: AF0067:SH | B43: SC | C43: AF0067G | D43: GRN | E43: 14 | F43: 30.A6 | G43: AF0068:SH | H43: PNL B,SMT130 | I43: 30.B6 | M43: USED
A44: AF0067:V+ | B44: SC | C44: AF0067P | D44: WHT | E44: 16 | F44: 30.A6 | G44: AF0068:V+ | H44: PNL B,SMT130 | I44: 30.B6 | M44: USED
A45: AF0068:SH | B45: SC | C45: IEG02302 | D45: GRN | E45: 14 | F45: 30.B6 | G45: IEG0230:2 | H45: PNL B,SMT130 | I45: 30.B6 | M45: USED
A46: AF0071:COM | B46: SC | C46: AF0071N | D46: WHT | E46: 16 | F46: 30.D2 | G46: AF0072:COM | H46: PNL B,SMT130 | I46: 30.D3 | M46: USED
A47: AF0071:COM | B47: SC | C47: AU0070N | D47: WHT | E47: 16 | F47: 30.D2 | G47: AU0070:COM | H47: PNL B,SMT130 | I47: 30.C2 | M47: USED
A48: AF0071:J | B48: SC | C48: * | F48: 30.D2 | G48: AF0072:P | H48: PNL B,SMT130 | I48: 30.D3 | M48: USED
A49: AF0071:SH | B49: SC | C49: AF0071G | D49: GRN | E49: 14 | F49: 30.D2 | G49: AF0072:SH | H49: PNL B,SMT130 | I49: 30.D3 | M49: USED
A50: AF0071:SH | B50: SC | C50: AU0070G | D50: GRN | E50: 14 | F50: 30.D2 | G50: AU0070:GND | H50: PNL B,SMT130 | I50: 30.C2 | M50: USED
...

Sheet PNL,DOOR,2-BAY
A1: PNL,DOOR,2-BAY
A3: Project # | B3: 4L341
A4: Project Name | B4: SMT130 Stock Units October 2024
A5: Revision | B5: 0.5
A7: Controls DE
A8: Phone:
A9: Controls ME
A10: Phone:
A12: From | G12: To
A13: Device ID | B13: Cable (W) Conductor (SC) Jumper Clip (JC) | C13: Wire No. | D13: Wire ID | E13: Gauge/Size | F13: Page/Zone | G13: Device ID | H13: Location | I13: Page/Zone
A14: AT0190:GND | B14: SC | C14: AT0190G | D14: GRN/YEL | E14: 14 | F14: 41.C4 | G14: FRAME | H14: PNL,DOOR,2-BAY | I14: 41.C3 | M14: USED
A15: AT0190:USB | B15: SC | C15: AT0190K | D15: CABLE | E15: USB | F15: 41.C4 | G15: AT0190K:KI | H15: PNL,DOOR,2-BAY | I15: 41.C5 | M15: USED
A16: KA0461:11 | B16: SC | C16: KA046111 | D16: WHT | E16: 20 | F16: 45.D3 | G16: XT0460:8 | H16: GEN CMPNT | I16: 45.D5 | M16: USED
A17: KA0461:13 | B17: SC | C17: KA046113 | D17: WHT | E17: 20 | F17: 45.D3 | G17: XT0460:7 | H17: GEN CMPNT | I17: 45.D5 | M17: USED
A18: KA0461:14 | B18: SC | C18: FU0460 | D18: WHT | E18: 14 | F18: 45.D3 | G18: XT0460:2 | H18: GEN CMPNT | I18: 45.C3 | M18: USED
A19: KA0461:16 | B19: SC | C19: KA0333A1 | D19: WHT | E19: 20 | F19: 45.D3 | G19: XT0460:5 | H19: GEN CMPNT | I19: 45.D3 | M19: USED
A20: KA0461:16 | B20: SC | C20: KA0333A1 | D20: WHT | E20: 20 | F20: 45.D3 | G20: XT0337:18 | H20: GEN CMPNT | I20: 37.A5 | M20: USED
A21: KA0461:B | B21: SC | C21: 0V | D21: WHT | E21: 20 | F21: 45.D3 | G21: XT0460:6 | H21: GEN CMPNT | I21: 45.D5 | M21: USED
A22: KA0461:G | B22: SC | C22: KA046032 | D22: WHT | E22: 14 | F22: 45.D3 | G22: XT0460:4 | H22: GEN CMPNT | I22: 45.C3 | M22: USED
A23: AT0190:ENET2 | B23: WC0019 | C23: AT0190ENET2 | D23: ENET | E23: CABLE | F23: 41.C4 | G23: BA0703:LAN | H23: POWERDIST, PANEL | I23: 5.C4 | M23: USED
A24: AT0190:ENET1 | B24: WC7024 | C24: AT0190ENET1 | D24: ENET | E24: CABLE | F24: 41.C4 | G24: BA0700:1 | H24: POWERDIST, PANEL | I24: 5.A4 | M24: USED
A25: AT0190:NEG | B25: SC | C25: 0V | D25: WHT | E25: 14 | F25: 41.C4 | G25: XT0562:3 | H25: PWR DST,DR,SMT130 | I25: 41.C2 | M25: USED
... A30: HA0273:(-) | B30: WC5540 | C30: HA0273N | D30: WHT | E30: 16 | F30: 43.D4 | G30: AF0202:55 | H30: TCP, SMT130 | I30: 43.D6 | M30: USED
F32: SolarTools ver. 24.0.84.24712 (Jul 31, 2025)
A33: Report date: 2/13/2026 2:19 PM

Sheet POWERDIST, PANEL
A1: h
A3: Project # | B3: 4L341
A4: Project Name | B4: SMT130 Stock Units October 2024
A5: Revision | B5: 0.5
A7: Controls DE
A8: Phone:
A9: Controls ME
A10: Phone:
A12: From | G12: To
A13: Device ID | B13: Cable (W) Conductor (SC) Jumper Clip (JC) | C13: Wire No. | D13: Wire ID | E13: Gauge/Size | F13: Page/Zone | G13: Device ID | H13: Location | I13: Page/Zone
A14: XT0027:1 | B14: JC | C14: 0V | D14: CLIP | E14: --- | F14: 5.A2 | G14: XT0027:2 | H14: POWERDIST, PANEL | I14: 5.B2 | M14: USED
A15: XT0027:2 | B15: JC | C15: 0V | D15: CLIP | E15: --- | F15: 5.B2 | G15: XT0027:3 | H15: POWERDIST, PANEL | I15: 5.C2 | M15: USED
A16: XT0102:1 | B16: JC | C16: FU0136 | D16: CLIP | E16: --- | F16: 19.A4 | G16: XT0102:2 | H16: POWERDIST, PANEL | I16: 19.A4 | M16: USED
A17: XT0102:2 | B17: JC | C17: FU0136 | D17: CLIP | E17: --- | F17: 19.A4 | G17: XT0102:3 | H17: POWERDIST, PANEL | I17: 19.B4 | M17: USED
A18: XT0102:3 | B18: JC | C18: FU0136 | D18: CLIP | E18: --- | F18: 19.B4 | G18: XT0102:4 | H18: POWERDIST, PANEL | I18: 19.B4 | M18: USED
A19: XT0102:4 | B19: JC | C19: FU0136 | D19: CLIP | E19: --- | F19: 19.B4 | G19: XT0102:5 | H19: POWERDIST, PANEL | I19: 19.B4 | M19: USED
A20: XT0102:5 | B20: JC | C20: FU0136 | D20: CLIP | E20: --- | F20: 19.B4 | G20: XT0102:6 | H20: POWERDIST, PANEL | I20: 19.B4 | M20: USED
A21: XT0104:1 | B21: JC | C21: 0V | D21: CLIP | E21: --- | F21: 19.A4 | G21: XT0104:2 | H21: POWERDIST, PANEL | I21: 19.B4 | M21: USED
A22: XT0104:2 | B22: JC | C22: 0V | D22: CLIP | E22: --- | F22: 19.B4 | G22: XT0104:3 | H22: POWERDIST, PANEL | I22: 19.B4 | M22: USED
A23: XT0104:3 | B23: JC | C23: 0V | D23: CLIP | E23: --- | F23: 19.B4 | G23: XT0104:4 | H23: POWERDIST, PANEL | I23: 19.B4 | M23: USED
A24: XT0104:4 | B24: JC | C24: 0V | D24: CLIP | E24: --- | F24: 19.B4 | G24: XT0104:5 | H24: POWERDIST, PANEL | I24: 19.B4 | M24: USED
A25: XT0104:5 | B25: JC | C25: 0V | D25: CLIP | E25: --- | F25: 19.B4 | G25: XT0104:6 | H25: POWERDIST, PANEL | I25: 19.C4 | M25: USED
... A77: IEG2240:4 | B77: SC | C77: IEG22404 | D77: GRN | E77: 14 | F77: 41.A3 | G77: GR0200: | H77: TCP, SMT130 | I77: 41.A3 | M77: USED
F79: SolarTools ver. 24.0.84.24712 (Jul 31, 2025)
A80: Report date: 2/13/2026 2:19 PM

Sheet PROX,TURB
A1: PROX,TURB
A3: Project # | B3: 4L341
A4: Project Name | B4: SMT130 Stock Units October 2024
A5: Revision | B5: 0.5
A7: Controls DE
A8: Phone:
A9: Controls ME
A10: Phone:
A12: From | G12: To
A13: Device ID | B13: Cable (W) Conductor (SC) Jumper Clip (JC) | C13: Wire No. | D13: Wire ID | E13: Gauge/Size | F13: Page/Zone | G13: Device ID | H13: Location | I13: Page/Zone
A14: GR1210: | B14: SC | C14: GR1210 | D14: GRN/YEL | E14: 14 | F14: 31.A6 | G14: FRAME | H14: PROX,TURB | I14: 31.A6 | M14: USED
A15: GR1211: | B15: SC | C15: GR1211 | D15: GRN/YEL | E15: 14 | F15: 31.A6 | G15: FRAME | H15: PROX,TURB | I15: 31.A6 | M15: USED
F17: SolarTools ver. 24.0.84.24712 (Jul 31, 2025)
A18: Report date: 2/13/2026 2:19 PM

Sheet PWR DST,DR,SMT130
A1: PWR DST,DR,SMT130
A3: Project # | B3: 4L341
A4: Project Name | B4: SMT130 Stock Units October 2024
A5: Revision | B5: 0.5
A7: Controls DE
A8: Phone:
A9: Controls ME
A10: Phone:
A12: From | G12: To
A13: Device ID | B13: Cable (W) Conductor (SC) Jumper Clip (JC) | C13: Wire No. | D13: Wire ID | E13: Gauge/Size | F13: Page/Zone | G13: Device ID | H13: Location | I13: Page/Zone
A14: XT0562:1 | B14: JC | C14: 0V | D14: CLIP | E14: --- | F14: 41.B2 | G14: XT0562:2 | H14: PWR DST,DR,SMT130 | I14: 41.B2 | M14: USED
A15: XT0562:2 | B15: JC | C15: 0V | D15: CLIP | E15: --- | F15: 41.B2 | G15: XT0562:3 | H15: PWR DST,DR,SMT130 | I15: 41.C2 | M15: USED
A16: XT0562:3 | B16: JC | C16: 0V | D16: CLIP | E16: --- | F16: 41.C2 | G16: XT0562:4 | H16: PWR DST,DR,SMT130 | I16: 41.D2 | M16: USED
A17: XT2930:1 | B17: JC | C17: SB650011 | D17: CLIP | E17: --- | F17: 120.A5 | G17: XT2930:2 | H17: PWR DST,DR,SMT130 | I17: 120.A5 | M17: USED
A18: XT2930:3 | B18: JC | C18: 0V | D18: CLIP | E18: --- | F18: 120.A5 | G18: XT2930:4 | H18: PWR DST,DR,SMT130 | I18: 120.A5 | M18: USED
A19: FU0190:LI | B19: SC | C19: FU0560 | D19: WHT | E19: 12 | F19: 41.C3 | G19: FU0701:LI | H19: PWR DST,DR,SMT130 | I19: 41.D3 | M19: USED
A20: FU0190:LI | B20: SC | C20: FU0560 | D20: WHT | E20: 12 | F20: 41.C3 | G20: FU0273:LI | H20: PWR DST,DR,SMT130 | I20: 41.B3 | M20: USED
A21: FU0200:LI | B21: SC | C21: FU0560 | D21: WHT | E21: 12 | F21: 41.A3 | G21: FU0201:LI | H21: PWR DST,DR,SMT130 | I21: 41.B3 | M21: USED
A22: FU0200:LI | B22: SC | C22: FU0560 | D22: WHT | E22: 12 | F22: 41.A3 | G22: FU0560:LD | H22: PWR DST,DR,SMT130 | I22: 41.A2 | M22: USED
A23: FU0201:LI | B23: SC | C23: FU0560 | D23: WHT | E23: 12 | F23: 41.B3 | G23: FU0273:LI | H23: PWR DST,DR,SMT130 | I23: 41.B3 | M23: USED
A24: FU0701:LI | B24: SC | C24: FU0560 | D24: WHT | E24: 12 | F24: 41.D3 | G24: FU6500:LI | H24: PWR DST,DR,SMT130 | I24: 41.D3 | M24: USED
A25: XT0562:3 | B25: SC | C25: 0V | D25: WHT | E25: 20 | F25: 41.C2 | G25: XT0563:4 | H25: PWR DST,DR,SMT130 | I25: 43.B6 | M25: USED
... A49: XT0563:6 | B49: SC | C49: FU0139 | D49: WHT | E49: 20 | F49: 43.C6 | G49: SA0401:2 | H49: TCP, SMT130 | I49: 43.C5 | M49: USED
F51: SolarTools ver. 24.0.84.24712 (Jul 31, 2025)
A52: Report date: 2/13/2026 2:19 PM

Sheet TCP, SMT130
A1: h
A3: Project # | B3: 4L341
A4: Project Name | B4: SMT130 Stock Units October 2024
A5: Revision | B5: 0.5
A7: Controls DE
A8: Phone:
A9: Controls ME
A10: Phone:
A12: From | G12: To
A13: Device ID | B13: Cable (W) Conductor (SC) Jumper Clip (JC) | C13: Wire No. | D13: Wire ID | E13: Gauge/Size | F13: Page/Zone | G13: Device ID | H13: Location | I13: Page/Zone
A14: AF0201:00 | B14: SC | C14: TCP13NO | D14: WHT | E14: 20 | F14: 43.A3 | G14: SH0400:NO | H14: TCP, SMT130 | I14: 43.A1 | M14: USED
A15: AF0201:01 | B15: SC | C15: TCP14NO | D15: WHT | E15: 20 | F15: 43.A3 | G15: SH0401:NO | H15: TCP, SMT130 | I15: 43.A1 | M15: USED
A16: AF0201:02 | B16: SC | C16: TCP15NO | D16: WHT | E16: 20 | F16: 43.B3 | G16: SH0409:NO | H16: TCP, SMT130 | I16: 43.B1 | M16: USED
A17: AF0201:03 | B17: SC | C17: TCP16NO | D17: WHT | E17: 20 | F17: 43.B3 | G17: SH0410:NO | H17: TCP, SMT130 | I17: 43.B1 | M17: USED
A18: AF0201:04 | B18: SC | C18: TCP17A2 | D18: WHT | E18: 20 | F18: 43.C3 | G18: SA0400:B2-14 | H18: TCP, SMT130 | I18: 43.C1 | M18: USED
A19: AF0201:05 | B19: SC | C19: TCP17B2 | D19: WHT | E19: 20 | F19: 43.C3 | G19: SA0400:B1-12 | H19: TCP, SMT130 | I19: 43.C1 | M19: USED
A20: AF0201:08 | B20: SC | C20: TCP23NC | D20: WHT | E20: 20 | F20: 43.D3 | G20: SB0401:NC | H20: TCP, SMT130 | I20: 43.D1 | M20: USED
A21: AF0201:09 | B21: SC | C21: TCP24NO | D21: WHT | E21: 20 | F21: 43.D3 | G21: SB0402:NO | H21: TCP, SMT130 | I21: 43.D1 | M21: USED
A22: AF0201:10 | B22: SC | C22: TCP25NO | D22: WHT | E22: 20 | F22: 43.A7 | G22: SB0403:NO | H22: TCP, SMT130 | I22: 43.A5 | M22: USED
A23: AF0201:11 | B23: SC | C23: TCP26NO | D23: WHT | E23: 20 | F23: 43.A7 | G23: SB0404:NO | H23: TCP, SMT130 | I23: 43.A5 | M23: USED
A24: AF0201:12 | B24: SC | C24: TCP29NO | D24: WHT | E24: 20 | F24: 44.C3 | G24: SB0405:NO | H24: TCP, SMT130 | I24: 44.C1 | M24: USED
A25: AF0201:13 | B25: SC | C25: TCP28NC | D25: WHT | E25: 20 | F25: 44.D3 | G25: SB0406:NC | H25: TCP, SMT130 | I25: 44.D1 | M25: USED
... A52: AF0201:COM | B52: SC | C52: AU0200N | D52: WHT | E52: 16 | F52: 41.A5 | G52: AU0200:COM | H52: TCP, SMT130 | I52: 41.A4 | M52: USED
A53: AF0201:J | B53: SC | C53: * | F53: 41.A5 | G53: AF0202:P | H53: TCP, SMT130 | I53: 41.A6 | M53: USED
A54: AF0201:SHLD | B54: SC | C54: AF0201V+ | D54: WHT | E54: 16 | F54: 41.D6 | G54: AF0201:V+ | H54: TCP, SMT130 | I54: 41.D6 | M54: USED
A55: AF0201:V+ | B55: SC | C55: AU0200P | D55: WHT | E55: 16 | F55: 41.A5 | G55: AU0200:V+ | H55: TCP, SMT130 | I55: 41.A4 | M55: USED
A56: AF0202:00 | B56: SC | C56: TCP01AP | D56: WHT | E56: 20 | F56: 42.A3 | G56: HL0400:A+ | H56: TCP, SMT130 | I56: 42.A1 | M56: USED
A57: AF0202:01 | B57: SC | C57: TCP02AP | D57: WHT | E57: 20 | F57: 42.A3 | G57: HL0401:A+ | H57: TCP, SMT130 | I57: 42.A1 | M57: USED
A58: AF0202:02 | B58: SC | C58: TCP03AP | D58: WHT | E58: 20 | F58: 42.B3 | G58: HL0402:A+ | H58: TCP, SMT130 | I58: 42.B1 | M58: USED
A59: AF0202:03 | B59: SC | C59: TCP04AP | D59: WHT | E59: 20 | F59: 42.B3 | G59: HL0403:A+ | H59: TCP, SMT130 | I59: 42.B1 | M59: USED
A60: AF0202:04 | B60: SC | C60: TCP05AP | D60: WHT | E60: 20 | F60: 42.C3 | G60: HL0404:A+ | H60: TCP, SMT130 | I60: 42.C1 | M60: USED
A61: AF0202:05 | B61: SC | C61: TCP06AP | D61: WHT | E61: 20 | F61: 42.C3 | G61: HL0405:A+ | H61: TCP, SMT130 | I61: 42.C1 | M61: USED
A62: AF0202:06 | B62: SC | C62: TCP06BP | D62: WHT | E62: 20 | F62: 42.D3 | G62: HL0405:B+ | H62: TCP, SMT130 | I62: 42.D1 | M62: USED
A63: AF0202:08 | B63: SC | C63: TCP07AP | D63: WHT | E63: 20 | F63: 42.D3 | G63: HL0406:A+ | H63: TCP, SMT130 | I63: 42.D1 | M63: USED
A64: AF0202:09 | B64: SC | C64: TCP08AP | D64: WHT | E64: 20 | F64: 42.A7 | G64: HL0407:A+ | H64: TCP, SMT130 | I64: 42.A5 | M64: USED
A65: AF0202:10 | B65: SC | C65: TCP09AP | D65: WHT | E65: 20 | F65: 42.A7 | G65: HL0408:A+ | H65: TCP, SMT130 | I65: 42.A5 | M65: USED
... A162: XT0564:1 B2 | B162: SC | C162: KA033412 | D162: WHT | E162: 20 | F162: 43.B5 | G162: XT0563:3 | H162: PWR DST,DR,SMT130 | I162: 43.B6 | M162: USED
F164: SolarTools ver. 24.0.84.24712 (Jul 31, 2025)
A165: Report date: 2/13/2026 2:19 PM

Sheet Panel Errors
A1: Panel Errors
A3: Project # | B3: 4L341
A4: Project Name | B4: SMT130 Stock Units October 2024
A5: Revision | B5: 0.5
A7: Controls DE
A8: Phone:
A9: Controls ME
A10: Phone:
A12: From | H12: To
A13: Device ID | B13: Location | C13: Cable (W) Conductor (SC) Jumper Clip (JC) | D13: Wire ID | E13: Wire No. | F13: Gauge/Size | G13: Page/Zone | H13: Device ID | I13: Location | J13: Page/Zone
A16: Report date: 2/13/2026 2:19 PM | E16: SolarTools ver. 24.0.84.24712 (Jul 31, 2025)

Sheet Cable Part Numbers
A1: Cable Part Numbers | D1: SolarTools ver. 24.0.84.24712 (Jul 31, 2025)
A2: Project # | B2: 4L341
D3: Report date: 2/13/2026 2:21 PM
A4: Project Name | B4: SMT130 Stock Units October 2024
A6: Revision | B6: 0.5
A8: Controls DE
A9: Phone:
A10: Controls ME
A11: Phone:
A13: Device ID | C13: Part Number | E13: Description
A14: WC0006 | C14: 1302073-36 | E14: CABLE, ETHERNET - 36 INCHES
A15: WC0007 | C15: 1302073-36 | E15: CABLE, ETHERNET - 36 INCHES
A16: WC0008 | C16: 1302073-36 | E16: CABLE, ETHERNET - 36 INCHES
A17: WC0009 | C17: 1302073-36 | E17: CABLE, ETHERNET - 36 INCHES
A18: WC0012 | C18: 1302073-36 | E18: CABLE, ETHERNET - 36 INCHES
A19: WC0014 | C19: 1302073-36 | E19: CABLE, ETHERNET - 36 INCHES
A20: WC0017 | C20: 1302073-36 | E20: CABLE, ETHERNET - 36 INCHES
A21: WC0018 | C21: 1302073-36 | E21: CABLE, ETHERNET - 36 INCHES
A22: WC0019 | C22: 1302073-36 | E22: CABLE, ETHERNET - 36 INCHES
A23: WC0020 | C23: 1302073-36 | E23: CABLE, ETHERNET - 36 INCHES
A24: WC0029 | C24: 1302073-36 | E24: CABLE, ETHERNET - 36 INCHES
... A53: WC8301 | C53: 1022941-33 | E53: TPE, 1 TRIAD TWISTED SHIELDED

Sheet Part Number List
A1: Part Number List | C1: SolarTools ver. 24.0.84.24712 (Jul 31, 2025)
A2: Project # | B2: 4L341
C3: Report date: 2/13/2026 2:21 PM
A4: Project Name | B4: SMT130 Stock Units October 2024
A6: Revision | B6: 0.5
A8: Controls DE
A9: Phone:
A10: Controls ME
A11: Phone:
A13: Device ID | B13: Part Number | C13: Description | D13: Location
A14: KA0460 | B14: 1062941-400 | C14: RELAY, BECKWITH, M3425-A GENERATOR PROTECTION | D14: BECKWITH RELAY,SMT130
A16: EL0273 | B16: 2403630-1 | C16: LIGHT, LED, CONSOLE FLUORESCENT, WHITE | D16: CONTROL,2-BAY
A18: GR1000 | B18: 903849C1 | C18: RAIL GROUND, DIN RAIL GROUNDING | D18: CONTROL,JB70
A19: GR1100 | B19: 903849C1 | C19: RAIL GROUND, DIN RAIL GROUNDING | D19: CONTROL,JB70
A20: HA0472 | B20: 1103208-101 | C20: HORN, CONTROL SYSTEM ALARM | D20: CONTROL,JB70
A22: AF0500 | B22: 1322418-31,1322418-40,1322418-72,1322418-73 | C22: 1444-TSCX02-02RB, 2-CH TACHOMETER INPUT^DYNAMIX 1444 VIBRATION | D22: FG&E CTRL,SMT130
A23: AF0510 | B23: 1322418-11,1322418-20,1322418-70,1322418-71 | C23: 1444-DYN04-01RA, 4-CH VIBRATION INPUT^DYNAMIX 1444 VIBRATION | D23: FG&E CTRL,SMT130
A24: AT0170 | B24: 1056244-29 | C24: CONTROLLER, EAGLE QUANTUM PREMIER | D24: FG&E CTRL,SMT130
A25: AT0171 | B25: 1056244-5 | C25: 8 CHANNEL ED I/O, EAGLE QUANTUM PREMIER | D25: FG&E CTRL,SMT130
A26: AT0175 | B26: 1056244-5 | C26: 8 CHANNEL ED I/O, EAGLE QUANTUM PREMIER | D26: FG&E CTRL,SMT130
A27: AT0176 | B27: 1056244-5 | C27: 8 CHANNEL ED I/O, EAGLE QUANTUM PREMIER | D27: FG&E CTRL,SMT130
... A383: XT0564 | B383: PARTOFTCPASSY | C383: TERMINAL STRIP, SYSTEM FUNCTION (USE) | D383: TCP, SMT130

Sheet A_S
A1: PNL A
A3: Project # | B3: 4M011
A4: Project Name | B4: SMT130 Stock Units October 2024
A5: Revision | B5: 0.5
A7: Controls DE
A8: Phone:
A9: Controls ME
A10: Phone:
A12: From | G12: To
A13: Device ID | B13: Wire No. | C13: Wire ID | D13: Gauge/Size | E13: Length | F13: Device ID | G13: Location | H13: Bundle Name
A14: PC0470:INP_A | B14: -009207 | C14: WHT | D14: 20 | E14: 60 | F14: AF0092:07 | G14: PNL A | H14: PC0470
A15: PC0470:-PWR | B15: -009223 | C15: WHT | D15: 20 | E15: 60 | F15: AF0092:23 | G15: PNL A
A16: PC0470:+PWR | B16: -009239 | C16: WHT | D16: 20 | E16: 60 | F16: AF0092:39 | G16: PNL A
A18: AF0092:04 | B18: -009204 | C18: WHT | D18: 20 | E18: 100 | F18: XT0137:2 | G18: PNL A | H18: AF0090'S
A19: AF0092:13 | B19: -009213 | C19: WHT | D19: 20 | E19: 100 | F19: XT0137:4 | G19: PNL A
A20: AF0092:31 | B20: HL62001 | C20: WHT | D20: 20 | E20: 60 | F20: XT0139:6 | G20: PNL A
A21: AF0092:15 | B21: HL62002 | C21: WHT | D21: 20 | E21: 60 | F21: XT0139:5 | G21: PNL A
A22: AF0092:24 | B22: KA0875A2 | C22: WHT | D22: 20 | E22: 60 | F22: XT0136:2 | G22: PNL A
A23: AF0093:42 | B23: SB047311 | C23: WHT | D23: 20 | E23: 60 | F23: XT0139:1 | G23: PNL A
A24: AF0093:10 | B24: SB047312 | C24: WHT | D24: 20 | E24: 60 | F24: XT0139:2 | G24: PNL A
A25: AF0091:15 | B25: SB6200C | C25: WHT | D25: 20 | E25: 60 | F25: XT0139:8 | G25: PNL A
A26: AF0091:47 | B26: SB6200NO | C26: WHT | D26: 20 | E26: 60 | F26: XT0139:7 | G26: PNL A
A27: AF0093:00 | B27: UA1200J21 | C27: WHT | D27: 20 | E27: 100 | F27: XT0233:1 | G27: PNL A
A29: AU0090:COM | B29: -0V | C29: WHT | D29: 16 | E29: 60 | F29: XT0090:1 | G29: PNL A
A30: AF0092:COM | B30: -0V | C30: WHT | D30: 16 | E30: 60 | F30: XT0090:2 | G30: PNL A
A31: AF0091:COM | B31: AF0091N | C31: WHT | D31: 16 | E31: 60 | F31: AF0093:COM | G31: PNL A
... A36: AF0093:11 | B36: SB751212 | C36: WHT | D36: 16 | E36: 60 | F36: XT0139:10 | G36: PNL A
A38: AU0080:COM | B38: -0V | C38: WHT | D38: 16 | E38: 60 | F38: XT0082:2 | G38: PNL A | H38: AF0080'S
A39: AF0081:COM | B39: -0V | C39: WHT | D39: 16 | E39: 60 | F39: XT0082:3 | G39: PNL A
A40: AU0080:COM | B40: AU0080N | C40: WHT | D40: 16 | E40: 60 | F40: AF0082:COM | G40: PNL A
A41: AU0080:V+ | B41: AU0080P | C41: WHT | D41: 16 | E41: 60 | F41: AF0082:V+ | G41: PNL A
A42: AU0080:V+ | B42: FU0081 | C42: WHT | D42: 16 | E42: 60 | F42: FU0081:LD | G42: PNL A
A43: AF0081:V+ | B43: FU0082 | C43: WHT | D43: 16 | E43: 60 | F43: FU0082:LD | G43: PNL A
A45: FU0139:LD | B45: FU0139 | C45: WHT | D45: 16 | E45: 60 | F45: XT0081:1 | G45: PNL A | H45: FU
A47: FU0081:LI | B47: FU0080 | C47: WHT | D47: 14 | E47: 60 | F47: FU0080:LD | G47: PNL A
A48: FU0082:LI | B48: FU0080 | C48: WHT | D48: 14 | E48: 60 | F48: FU0090:LI | G48: PNL A
A49: FU0137:LI | B49: FU0136 | C49: WHT | D49: 14 | E49: 100 | F49: XT0138:2 | G49: PNL A
A50: FU0080:LI | B50: FU0137 | C50: WHT | D50: 14 | E50: 60 | F50: FU0137:LD | G50: PNL A
A52: KA0875:A1 | B52: -009208 | C52: WHT | D52: 20 | E52: 100 | F52: AF0092:08 | G52: PNL A | H52: KA/A1
A53: KA0130:A1 | B53: -009338 | C53: WHT | D53: 20 | E53: 100 | F53: AF0093:38 | G53: PNL A
...

Sheet B_S
A1: PNL B,SMT130
A3: Project # | B3: 4M011
A4: Project Name | B4: SMT130 Stock Units October 2024
A5: Revision | B5: 0.5
A7: Controls DE
A8: Phone:
A9: Controls ME
A10: Phone:
A12: From | G12: To
A13: Device ID | B13: Wire No. | C13: Wire ID | D13: Gauge/Size | E13: Length | F13: Device ID | G13: Location | H13: Bundle Name
A14: UA1200:J1-8 | B14: UA1200J | C14: WHT | D14: 20 | E14: 60 | F14: UA1200:J3-5 | G14: PNL B | H14: UA1200'S
A15: UA1200:J1-4 | B15: UA1200J14 | C15: WHT | D15: 20 | E15: 120 | F15: AF0075:10 | G15: PNL B
A17: AF0063:22 | B17: SV21242 | C17: WHT | D17: 20 | E17: 80 | F17: XT0240:2 | G17: PNL B | H17: AF/AU0060'S
A19: AF0061:COM | B19: -0V | C19: WHT | D19: 16 | E19: 60 | F19: XT0060:2 | G19: PNL B
A20: AF0062:COM | B20: -0V | C20: WHT | D20: 16 | E20: 60 | F20: XT0060:3 | G20: PNL B
A21: AF0063:COM | B21: -0V | C21: WHT | D21: 16 | E21: 60 | F21: XT0060:3 | G21: PNL B
A22: AU0060:COM | B22: -0V | C22: WHT | D22: 16 | E22: 60 | F22: XT0060:2 | G22: PNL B
A23: AF0064:COM | B23: AU0060N | C23: WHT | D23: 16 | E23: 60 | F23: AU0060:COM | G23: PNL B
A24: AF0064:V+ | B24: AU0060P | C24: WHT | D24: 16 | E24: 60 | F24: AU0060:V+ | G24: PNL B
A25: AU0060:V+ | B25: FU0061 | C25: WHT | D25: 16 | E25: 60 | F25: FU0061:LD | G25: PNL B
A26: AF0061:V+ | B26: FU0062 | C26: WHT | D26: 16 | E26: 60 | F26: FU0062:LD | G26: PNL B
A27: AF0062:V+ | B27: FU0063 | C27: WHT | D27: 16 | E27: 60 | F27: FU0063:LD | G27: PNL B
A28: AF0063:V+ | B28: FU0064 | C28: WHT | D28: 16 | E28: 60 | F28: FU0064:LD | G28: PNL B
A30: AF0075:COM | B30: -0V | C30: WHT | D30: 16 | E30: 60 | F30: XT0070:2 | G30: PNL B | H30: AF/AU0070'S
A31: AU0070:COM | B31: -0V | C31: WHT | D31: 16 | E31: 60 | F31: XT0070:1 | G31: PNL B
A32: AU0070:V+ | B32: FU0070 | C32: WHT | D32: 16 | E32: 60 | F32: FU0070:LD | G32: PNL B
A33: AF0075:V+ | B33: FU0071 | C33: WHT | D33: 16 | E33: 80 | F33: FU0071:LD | G33: PNL B
A35: AF0410:53 | B35: -0V | C35: WHT | D35: 16 | E35: 60 | F35: XT0110:1 | G35: PNL B | H35: 1444'S
A36: AF0410:54 | B36: -0V | C36: WHT | D36: 16 | E36: 60 | F36: AF0420:53 | G36: PNL B
A37: AF0420:54 | B37: -0V | C37: WHT | D37: 16 | E37: 60 | F37: AF0450:53 | G37: PNL B
A38: AF0410:55 | B38: FU0110 | C38: WHT | D38: 16 | E38: 60 | F38: FU0110:LD | G38: PNL B
A39: AF0410:56 | B39: FU0110 | C39: WHT | D39: 16 | E39: 60 | F39: AF0420:55 | G39: PNL B
A40: AF0420:56 | B40: FU0110 | C40: WHT | D40: 16 | E40: 60 | F40: AF0450:55 | G40: PNL B
A42: FU0214:LD | B42: FU0214 | C42: WHT | D42: 16 | E42: 60 | F42: XT0240:6 | G42: PNL B | H42: FU
A44: FU0061:LI | B44: FU0060 | C44: WHT | D44: 14 | E44: 60 | F44: FU0060:LD | G44: PNL B
A45: FU0064:LI | B45: FU0060 | C45: WHT | D45: 14 | E45: 80 | F45: FU0070:LI | G45: PNL B
A46: FU0060:LI | B46: FU0210 | C46: WHT | D46: 14 | E46: 60 | F46: FU0210:LD | G46: PNL B
A48: KA0221:A1 | B48: KA0221A1 | C48: WHT | D48: 20 | E48: 80 | F48: AF0075:03 | G48: PNL B | H48: KA A1/A2
A49: KA0222:A1 | B49: KA0222A1 | C49: WHT | D49: 20 | E49: 80 | F49: AF0075:04 | G49: PNL B
A51: KA0221:A2 | B51: KA0221A2 | C51: WHT | D51: 20 | E51: 80 | F51: AF0075:19 | G51: PNL B
...

Sheet Lights_S
A1: CONTROL,2-BAY
A3: Project # | B3: 4M011
A4: Project Name | B4: SMT130 Stock Units October 2024
A5: Revision | B5: 0.5
A7: Controls DE
A8: Phone:
A9: Controls ME
A10: Phone:
A12: From | G12: To
A13: Device ID | B13: Wire No. | C13: Wire ID | D13: Gauge/Size | E13: Length | F13: Device ID | G13: Location | H13: Bundle Name
A14: EL0273:W1 | B14: -0V | C14: WHT | D14: 16 | E14: 100 | F14: XT0562:2 | G14: PWR DST RAIL | H14: EL0
A15: EL0273:B1 | B15: FU0273 | C15: WHT | D15: 16 | E15: 100 | F15: FU0273:LD | G15: PWR DST RAIL

Sheet BECKWITH_S
A1: BECKWITH RELAY,SMT130
A3: Project # | B3: 4M011
A4: Project Name | B4: SMT130 Stock Units October 2024
A5: Revision | B5: 0.5
A7: Controls DE
A8: Phone:
A9: Controls ME
A10: Phone:
A12: From | G12: To
A13: Device ID | B13: Wire No. | C13: Wire ID | D13: Gauge/Size | E13: Length | F13: Device ID | G13: Location | H13: Bundle Name
A14: KA0460:34 | B14: KA0333A1 | C14: WHT | D14: 20 | E14: 280 | F14: XT0460:5 | G14: GEN CMPNT | H14: KA - GEN
A15: KA0460:10 | B15: KA046010 | C15: WHT | D15: 20 | E15: 300 | F15: KA0330:22 | G15: GEN CMPNT
A16: KA0460:11 | B16: KA046011 | C16: WHT | D16: 20 | E16: 300 | F16: KA2672:11 | G16: GEN CMPNT
A17: KA0460:12 | B17: KA046012 | C17: WHT | D17: 20 | E17: 300 | F17: AF0181:39 | G17: GEN CMPNT
A18: KA0460:13 | B18: KA046013 | C18: WHT | D18: 20 | E18: 300 | F18: AF0181:07 | G18: GEN CMPNT
A19: KA0460:15 | B19: KA046015 | C19: WHT | D19: 20 | E19: 300 | F19: AF0181:40 | G19: GEN CMPNT
A20: KA0460:16 | B20: KA046016 | C20: WHT | D20: 20 | E20: 300 | F20: AF0181:08 | G20: GEN CMPNT
A21: KA0460:18 | B21: KA046018 | C21: WHT | D21: 20 | E21: 300 | F21: AF0181:41 | G21: GEN CMPNT
A22: KA0460:19 | B22: KA046019 | C22: WHT | D22: 20 | E22: 300 | F22: AF0181:09 | G22: GEN CMPNT
A23: KA0460:23 | B23: KA046023 | C23: WHT | D23: 20 | E23: 300 | F23: AF0122:09 | G23: GEN CMPNT
A24: KA0460:24 | B24: KA046024 | C24: WHT | D24: 20 | E24: 300 | F24: AF0122:41 | G24: GEN CMPNT
A25: KA0460:29 | B25: KA046029 | C25: WHT | D25: 20 | E25: 300 | F25: AF0181:10 | G25: GEN CMPNT
A26: KA0460:30 | B26: KA046030 | C26: WHT | D26: 20 | E26: 300 | F26: AF0181:42 | G26: GEN CMPNT
... A33: KA0460:32 | B33: KA046032 | C33: WHT | D33: 14 | E33: 280 | F33: XT0460:4 | G33: GEN CMPNT
A35: KA0460:65 | B35: VBUSA | C35: RED | D35: 16R | E35: 280 | F35: XT0351:1 | G35: GEN CMPNT | H35: KA RED
A36: KA0460:64 | B36: VBUSB | C36: RED | D36: 16R | E36: 280 | F36: XT0351:3 | G36: GEN CMPNT
A37: KA0460:39 | B37: VGENA | C37: RED | D37: 16R | E37: 280 | F37: XT0351:9 | G37: GEN CMPNT
A38: KA0460:41 | B38: VGENB | C38: RED | D38: 16R | E38: 280 | F38: XT0351:10 | G38: GEN CMPNT
A39: KA0460:43 | B39: VGENC | C39: RED | D39: 16R | E39: 280 | F39: XT0351:11 | G39: GEN CMPNT
A41: KA0460:54 | B41: DCT01 | C41: BLU | D41: 12B | E41: 280 | F41: XT0454:4 | G41: GEN CMPNT | H41: KA BLU
A42: KA0460:56 | B42: DCT01 | C42: BLU | D42: 12B | E42: 280 | F42: XT0454:5 | G42: GEN CMPNT
A43: KA0460:58 | B43: DCT01 | C43: BLU | D43: 12B | E43: 280 | F43: XT0454:6 | G43: GEN CMPNT
A44: KA0460:55 | B44: DCT02 | C44: BLU | D44: 12B | E44: 280 | F44: XT0454:1 | G44: GEN CMPNT
A45: KA0460:57 | B45: DCT03 | C45: BLU | D45: 12B | E45: 280 | F45: XT0454:2 | G45: GEN CMPNT
A46: KA0460:59 | B46: DCT06 | C46: BLU | D46: 12B | E46: 280 | F46: XT0454:3 | G46: GEN CMPNT
A47: KA0460:46 | B47: DCTAX1 | C47: BLU | D47: 12B | E47: 280 | F47: XT0353:1 | G47: GEN CMPNT
A48: KA0460:48 | B48: DCTBX1 | C48: BLU | D48: 12B | E48: 280 | F48: XT0353:2 | G48: GEN CMPNT
A49: KA0460:50 | B49: DCTCX1 | C49: BLU | D49: 12B | E49: 280 | F49: XT0353:3 | G49: GEN CMPNT
A50: KA0460:47 | B50: DCTX2N | C50: BLU | D50: 12B | E50: 280 | F50: XT0353:4 | G50: GEN CMPNT
A51: KA0460:49 | B51: DCTX2N | C51: BLU | D51: 12B | E51: 280 | F51: XT0353:5 | G51: GEN CMPNT
...

Sheet PNL,DOOR,2-BAY_S
A1: PNL,DOOR,2-BAY
A3: Project # | B3: 4M011
A4: Project Name | B4: SMT130 Stock Units October 2024
A5: Revision | B5: 0.5
A7: Controls DE
A8: Phone:
A9: Controls ME
A10: Phone:
A12: From | G12: To
A13: Device ID | B13: Wire No. | C13: Wire ID | D13: Gauge/Size | E13: Length | F13: Device ID | G13: Location | H13: Bundle Name
A14: AT0190:NEG | B14: -0V | C14: WHT | D14: 14 | E14: 80 | F14: XT0562:3 | G14: PWR DST RAIL | H14: AT0190
A15: AT0190:POS | B15: FU0190 | C15: WHT | D15: 14 | E15: 80 | F15: FU0190:LD | G15: PWR DST RAIL
A17: SB6500:11 | B17: SB650011 | C17: WHT | D17: 20 | E17: 80 | F17: XT2930:2 | G17: PWR DST RAIL | H17: SB6500
A19: SB6500:12 | B19: FU6500 | C19: WHT | D19: 16 | E19: 80 | F19: FU6500:LD | G19: PWR DST RAIL
A21: KA0461:B | B21: -0V | C21: WHT | D21: 20 | E21: 160 | F21: XT0460:6 | G21: GEN CMPNT | H21: KA0461
A22: KA0461:16 | B22: KA0333A1 | C22: WHT | D22: 20 | E22: 160 | F22: XT0337:18 | G22: GEN CMPNT
A23: KA0461:16 | B23: KA0333A1 | C23: WHT | D23: 20 | E23: 160 | F23: XT0460:5 | G23: GEN CMPNT
A24: KA0461:11 | B24: KA046111 | C24: WHT | D24: 20 | E24: 160 | F24: XT0460:8 | G24: GEN CMPNT
A25: KA0461:13 | B25: KA046113 | C25: WHT | D25: 20 | E25: 160 | F25: XT0460:7 | G25: GEN CMPNT
A27: KA0461:14 | B27: FU0460 | C27: WHT | D27: 14 | E27: 160 | F27: XT0460:2 | G27: GEN CMPNT
A28: KA0461:G | B28: KA046032 | C28: WHT | D28: 14 | E28: 160 | F28: XT0460:4 | G28: GEN CMPNT

Sheet PWR DST RAIL_S
A1: PWR DST,DR,SMT130
A3: Project # | B3: 4M011
A4: Project Name | B4: SMT130 Stock Units October 2024
A5: Revision | B5: 0.5
A7: Controls DE
A8: Phone:
A9: Controls ME
A10: Phone:
A12: From | G12: To
A13: Device ID | B13: Wire No. | C13: Wire ID | D13: Gauge/Size | E13: Length | F13: Device ID | G13: Location | H13: Bundle Name
A14: XT0562:3 | B14: -0V | C14: WHT | D14: 20 | E14: 60 | F14: XT0563:4 | G14: PWR DST RAIL | H14: XT/FU
A15: XT0562:4 | B15: -0V | C15: WHT | D15: 20 | E15: 60 | F15: XT2930:3 | G15: PWR DST RAIL
A17: FU0200:LI | B17: FU0560 | C17: WHT | D17: 12 | E17: 60 | F17: FU0560:LD | G17: PWR DST RAIL
A19: XT0563:2 | B19: ESTOPC | C19: WHT | D19: 20 | E19: 220 | F19: XT0290:8 | G19: MCC | H19: XT-MCC
A20: XT0563:1 | B20: ESTOPD | C20: WHT | D20: 20 | E20: 220 | F20: XT2920:4 | G20: MCC
A22: XT0562:1 | B22: -0V | C22: WHT | D22: 14 | E22: 80 | F22: XT0104:2 | G22: POWERDIST PNL | H22: FU/XT-PWR PNL
A24: FU0560:LI | B24: FU0136 | C24: WHT | D24: 14 | E24: 80 | F24: XT0102:2 | G24: POWERDIST PNL
A26: XT0563:3 | B26: KA033412 | C26: WHT | D26: 20 | E26: 260 | F26: KA0334:12 | G26: GEN CMPNT | H26: FU/XT-GEN
A28: FU0701:LD | B28: FU0701 | C28: WHT | D28: 16 | E28: 260 | F28: KA0334:11 | G28: GEN CMPNT

Sheet FG&E CTRL,SMT130_S
A1: FG&E CTRL,SMT130
A3: Project # | B3: 4M011
A4: Project Name | B4: SMT130 Stock Units October 2024
A5: Revision | B5: 0.5
A7: Controls DE
A8: Phone:
A9: Controls ME
A10: Phone:
A12: From | G12: To
A13: Device ID | B13: Wire No. | C13: Wire ID | D13: Gauge/Size | E13: Length | F13: Device ID | G13: Location | H13: Bundle Name
A14: AF0510:53 | B14: -0V | C14: WHT | D14: 16 | E14: 60 | F14: XT0510:3 | G14: FG&E CTRL | H14: 1444s
A15: AF0510:55 | B15: FU0510 | C15: WHT | D15: 16 | E15: 60 | F15: FU0510:LD | G15: FG&E CTRL
A17: AT0170:24 | B17: FU0172 | C17: WHT | D17: 20 | E17: 80 | F17: XT0171:1 | G17: FG&E CTRL | H17: AT170
A18: AT0170:30 | B18: FU0172 | C18: WHT | D18: 20 | E18: 80 | F18: XT0171:2 | G18: FG&E CTRL
