Workbook

Sheet Panel Errors
A1: Panel Errors
A3: Project # | B3: 4M093_CORE
A4: Project Name | B4: PGMATO3
A5: Revision | B5: A.4
A7: Controls DE | B7: Poovarasan M
A8: Phone:
A9: Controls ME
A10: Phone:
A12: From | H12: To
A13: Device ID | B13: Location | C13: Cable (W) Conductor (SC) Jumper Clip (JC) | D13: Wire ID | E13: Wire No. | F13: Gauge/Size | G13: Page/Zone | H13: Device ID | I13: Location | J13: Page/Zone
A14: QF0782:14 | B14: GEN | C14: SC | D14: WHT | E14: QF078311 | F14: 20 | G14: 64.A5 | H14: QF0783:11 | I14: PANEL | J14: 64.A5
A15: XT0780:5 | B15: GEN | C15: SC | D15: RED | E15: BUSPTA | F15: 16 | G15: 58.B3 | H15: QF0783:1 | I15: PANEL | J15: 58.B4
A16: XT0780:6 | B16: GEN | C16: SC | D16: RED | E16: BUSPTB | F16: 16 | G16: 58.B3 | H16: QF0783:3 | I16: PANEL | J16: 58.B4
A17: XT0780:7 | B17: GEN | C17: SC | D17: RED | E17: BUSPTC | F17: 16 | G17: 58.B3 | H17: QF0783:5 | I17: PANEL | J17: 58.B4
A18: XT0140:3 | B18: GEN | C18: WC8009 | D18: SH | E18: XT01403 | F18: 16 | G18: 20.D2 | H18: FWAT0140:3 | I18: PANEL | J18: 20.D6
A19: QF0783:14 | B19: PANEL | C19: SC | D19: WHT | E19: QF078411 | F19: 20 | G19: 64.A5 | H19: QF0784:11 | I19: GEN | J19: 64.A6
A20: QF0783:2 | B20: PANEL | C20: SC | D20: RED | E20: QF07832 | F20: 16 | G20: 58.B4 | H20: KA0189:33 | I20: GEN | J20: 58.D6
A21: QF0783:4 | B21: PANEL | C21: SC | D21: RED | E21: QF07834 | F21: 16 | G21: 58.B4 | H21: KA0189:43 | I21: GEN | J21: 58.D6
E23: SolarTools ver. 24.0.84.24712 (Jul 31, 2025)
A24: Report date: 3/2/2026 4:24 AM
A26: XT0140:3 | B26: XT01403 | F26: IEG0010:9 | G26: DC
A27: XT0142:3 | B27: EXCS | F27: PEG0130:2 | G27: DC | J27: gen to dc pwr
A28: XT0313:2 | B28: * | F28: PEG0130:3 | G28: DC

Sheet LIGHTS_S
A1: JB71 B,BOX CONTROL
A3: Project # | B3: ANG02
A4: Project Name | B4: STOCK2
A5: Revision | B5: A.4
A7: Controls DE | B7: Poovarasan M
A8: Phone:
A9: Controls ME
A10: Phone:
A12: From | G12: To
A13: Device ID | B13: Wire No. | C13: Wire ID | D13: Gauge/Size | E13: Length | F13: Device ID | G13: Location | H13: Bundle Name
A14: EL0100:2- | B14: -0V | C14: WHT | D14: 16 | E14: 220 | F14: XT0005:4 | G14: DC | H14: EL0
A15: EL0101:2- | B15: -0V | C15: WHT | D15: 16 | E15: 120 | F15: XT0005:3 | G15: DC
A16: EL0100:1+ | B16: FU0005 | C16: WHT | D16: 16 | E16: 220 | F16: XT0005:2 | G16: DC
A17: EL0101:1+ | B17: FU0005 | C17: WHT | D17: 16 | E17: 120 | F17: XT0005:1 | G17: DC

Sheet DOOR CTRL(B)_S
A1: JB71 B,DOOR CTRL
A3: Project # | B3: ANG02
A4: Project Name | B4: STOCK2
A5: Revision | B5: A.4
A7: Controls DE | B7: Poovarasan M
A8: Phone:
A9: Controls ME
A10: Phone:
A12: From | G12: To
A13: Device ID | B13: Wire No. | C13: Wire ID | D13: Gauge/Size | E13: Length | F13: Device ID | G13: Location | H13: Bundle Name
A14: AT1100:NEG | B14: -0V | C14: WHT | D14: 14 | E14: 220 | F14: XT0070:12 | G14: CTRL1 | H14: AT
A15: AT1100:POS | B15: FU1100 | C15: WHT | D15: 14 | E15: 220 | F15: FU1100:LD | G15: CTRL1

Sheet DOOR OPR(B)_S
A1: JB71 B,DOOR OPR
A3: Project # | B3: ANG02
A4: Project Name | B4: STOCK2
A5: Revision | B5: A.4
A7: Controls DE | B7: Poovarasan M
A8: Phone:
A9: Controls ME
A10: Phone:
A12: From | G12: To
A13: Device ID | B13: Wire No. | C13: Wire ID | D13: Gauge/Size | E13: Length | F13: Device ID | G13: Location | H13: Bundle Name
A14: HA0472:N | B14: -0V | C14: WHT | D14: 20 | E14: 280 | F14: XT0070:11 | G14: CTRL1 | H14: HA0472
A15: HA0472:Lb | B15: KA087511 | C15: WHT | D15: 20 | E15: 280 | F15: KA0875:11 | G15: CTRL1
E16: 280
A17: SA0471:13 | B17: SA047113 | C17: WHT | D17: 20 | E17: 280 | F17: AF0091:36 | G17: CTRL1 | H17: SA0471
A18: SA0471:14 | B18: SA047114 | C18: WHT | D18: 20 | E18: 280 | F18: AF0091:04 | G18: CTRL1
A19: SA0471:23 | B19: SA047123 | C19: WHT | D19: 20 | E19: 280 | F19: AF0091:35 | G19: CTRL1
A20: SA0471:24 | B20: SA047124 | C20: WHT | D20: 20 | E20: 280 | F20: AF0091:03 | G20: CTRL1
E21: 280
A22: SA0473:13 | B22: SA047313 | C22: WHT | D22: 20 | E22: 280 | F22: AF0091:40 | G22: CTRL1 | H22: SA0473
A23: SA0473:14 | B23: SA047314 | C23: WHT | D23: 20 | E23: 280 | F23: AF0091:08 | G23: CTRL1
A24: SA0473:21 | B24: SA047321 | C24: WHT | D24: 20 | E24: 280 | F24: AF0091:39 | G24: CTRL1
A25: SA0473:22 | B25: SA047322 | C25: WHT | D25: 20 | E25: 280 | F25: AF0091:07 | G25: CTRL1
E26: 280
A27: SA0475:13 | B27: SA047513 | C27: WHT | D27: 20 | E27: 280 | F27: AF0091:38 | G27: CTRL1 | H27: SA0475
A28: SA0475:14 | B28: SA047514 | C28: WHT | D28: 20 | E28: 280 | F28: AF0091:06 | G28: CTRL1
A29: SA0475:23 | B29: SA047523 | C29: WHT | D29: 20 | E29: 280 | F29: AF0091:37 | G29: CTRL1
A30: SA0475:24 | B30: SA047524 | C30: WHT | D30: 20 | E30: 280 | F30: AF0091:05 | G30: CTRL1
E31: 280
A32: SB0333:11 | B32: FU0125 | C32: WHT | D32: 20 | E32: 280 | F32: XT0091:9 | G32: CTRL1 | H32: SB0333
A33: SB0333:12 | B33: SB033312 | C33: WHT | D33: 20 | E33: 280 | F33: XT0091:10 | G33: CTRL1
A34: SB0333:21 | B34: SB033321 | C34: WHT | D34: 20 | E34: 280 | F34: AF0091:43 | G34: CTRL1
A35: SB0333:22 | B35: SB033322 | C35: WHT | D35: 20 | E35: 280 | F35: AF0091:11 | G35: CTRL1
E36: 280
A37: SB0471:1 | B37: SB04711 | C37: WHT | D37: 20 | E37: 280 | F37: AF0091:32 | G37: CTRL1 | H37: SB0471
A38: SB0471:2 | B38: SB04712 | C38: WHT | D38: 20 | E38: 280 | F38: AF0091:00 | G38: CTRL1
E39: 280
A40: SB0472:11 | B40: ESTOPA | C40: WHT | D40: 20 | E40: 280 | F40: XT0091:7 | G40: CTRL1 | H40: SB0472
A41: SB0472:12 | B41: SB047212 | C41: WHT | D41: 20 | E41: 280 | F41: XT0091:8 | G41: CTRL1
A43: SB0472:21 | B43: SB047221 | C43: WHT | D43: 20 | E43: 160 | F43: AF0381:38 | G43: CTRL2
A44: SB0472:22 | B44: SB047222 | C44: WHT | D44: 20 | E44: 160 | F44: AF0381:06 | G44: CTRL2
...

Sheet DOOR EQP(C)_S
A1: JB71 C,DOOR PNL EQP
A3: Project # | B3: ANG02
A4: Project Name | B4: STOCK2
A5: Revision | B5: A.4
A7: Controls DE | B7: Poovarasan M
A8: Phone:
A9: Controls ME
A10: Phone:
A12: From | G12: To
A13: Device ID | B13: Wire No. | C13: Wire ID | D13: Gauge/Size | E13: Length | F13: Device ID | G13: Location | H13: Bundle Name
A14: HL0171:X2 | B14: HL0171X2 | C14: WHT | D14: 16 | E14: 260 | F14: XT0171:38 | G14: EQP CTRL | H14: HL0171
A15: HL0171:X2 | B15: HL0171X2 | C15: WHT | D15: 16 | E15: 260 | F15: XT0171:37 | G15: EQP CTRL
A16: HL0171:X3(+) | B16: HL0171X3 | C16: WHT | D16: 16 | E16: 260 | F16: XT0171:36 | G16: EQP CTRL
A17: HL0171:X3(+) | B17: HL0171X3 | C17: WHT | D17: 16 | E17: 260 | F17: XT0171:35 | G17: EQP CTRL
A19: HL0172:X2 | B19: HL0172X2 | C19: WHT | D19: 16 | E19: 260 | F19: XT0171:42 | G19: EQP CTRL | H19: HL0172
A20: HL0172:X2 | B20: HL0172X2 | C20: WHT | D20: 16 | E20: 260 | F20: XT0171:41 | G20: EQP CTRL
A21: HL0172:X3(+) | B21: HL0172X3 | C21: WHT | D21: 16 | E21: 260 | F21: XT0171:40 | G21: EQP CTRL
A22: HL0172:X3(+) | B22: HL0172X3 | C22: WHT | D22: 16 | E22: 260 | F22: XT0171:39 | G22: EQP CTRL
A24: SA0170:13 | B24: SA017013 | C24: WHT | D24: 16 | E24: 260 | F24: AT0170:11 | G24: EQP CTRL | H24: SA0170
A25: SA0170:14 | B25: SA017014 | C25: WHT | D25: 16 | E25: 260 | F25: AT0170:12 | G25: EQP CTRL
A26: SA0170:21 | B26: SA01702C | C26: WHT | D26: 16 | E26: 260 | F26: AT0175:11 | G26: EQP CTRL
A27: SA0170:22 | B27: SV66111 | C27: WHT | D27: 16 | E27: 260 | F27: XT0171:1 | G27: EQP CTRL
A28: SA0170:31 | B28: SA01703C | C28: WHT | D28: 16 | E28: 260 | F28: AT0176:17 | G28: EQP CTRL
A29: SA0170:32 | B29: SV66121 | C29: WHT | D29: 16 | E29: 260 | F29: XT0171:3 | G29: EQP CTRL
A31: SH6500:1 | B31: FU0172 | C31: WHT | D31: 20 | E31: 300 | F31: XT0175:7 | G31: EQP PWR | H31: SH6500
A33: SH6500:2 | B33: SH65002 | C33: WHT | D33: 20 | E33: 260 | F33: XT0171:13 | G33: EQP CTRL
A35: SH6500:X1 | B35: SH6500X1 | C35: WHT | D35: 20 | E35: 300 | F35: AF0182:11 | G35: CUST
A36: SH6500:X2 | B36: SH6500X2 | C36: WHT | D36: 20 | E36: 300 | F36: AF0182:27 | G36: CUST

Sheet CTRL2(B)_S
A1: JB71 B,PNL CTRL2
A3: Project # | B3: ANG02
A4: Project Name | B4: STOCK2
A5: Revision | B5: A.4
A7: Controls DE | B7: Poovarasan M
A8: Phone:
A9: Controls ME
A10: Phone:
A12: From | G12: To
A13: Device ID | B13: Wire No. | C13: Wire ID | D13: Gauge/Size | E13: Length | F13: Device ID | G13: Location | H13: Bundle Name
A14: UA1200:J1-8 | B14: UA1200J | C14: WHT | D14: 20 | E14: 60 | F14: UA1200:J3-5 | G14: CTRL2 | H14: UA1200
A15: UA1200:J1-10 | B15: FU0389 | C15: WHT | D15: 20 | E15: 60 | F15: XT1200:16 | G15: CTRL2
A16: UA1200:J1-4 | B16: UA1200J14 | C16: WHT | D16: 20 | E16: 60 | F16: XT1200:11 | G16: CTRL2
A17: UA1200:J1-5 | B17: UA1200J15 | C17: WHT | D17: 20 | E17: 60 | F17: XT1200:12 | G17: CTRL2
A18: UA1200:J1-9 | B18: -0V | C18: WHT | D18: 20 | E18: 60 | F18: XT1200:17 | G18: CTRL2
A19: UA1200:J2-1 | B19: UA1200J21 | C19: WHT | D19: 20 | E19: 60 | F19: XT1200:15 | G19: CTRL2
A20: UA1200:J2-2 | B20: FU0389 | C20: WHT | D20: 20 | E20: 60 | F20: XT1200:16 | G20: CTRL2
A21: UA1200:J2-6 | B21: UA1200J26 | C21: WHT | D21: 20 | E21: 60 | F21: XT1200:13 | G21: CTRL2
A22: UA1200:J2-7 | B22: UA1200J27 | C22: WHT | D22: 20 | E22: 60 | F22: XT1200:14 | G22: CTRL2
A24: AF0061:08 | B24: SA047222 | C24: WHT | D24: 20 | E24: 80 | F24: SA0472:22 | G24: CTRL2 | H24: AU/AF0060's
A25: AF0061:40 | B25: SA047221 | C25: WHT | D25: 20 | E25: 80 | F25: SA0472:21 | G25: CTRL2
A26: AF0066:20 | B26: SV21202 | C26: WHT | D26: 20 | E26: 60 | F26: XT0069:1 | G26: CTRL2
A27: AF0066:28 | B27: SV21132 | C27: WHT | D27: 20 | E27: 60 | F27: XT0069:3 | G27: CTRL2
A29: AU0060:COM | B29: -0V | C29: WHT | D29: 16 | E29: 80 | F29: XT0060:2 | G29: CTRL2
A30: AF0066:COM | B30: -0V | C30: WHT | D30: 16 | E30: 80 | F30: XT0060:3 | G30: CTRL2
A31: AU0060:V+ | B31: FU0061 | C31: WHT | D31: 16 | E31: 100 | F31: FU0061:LD | G31: CTRL2
A32: AF0066:V+ | B32: FU0062 | C32: WHT | D32: 16 | E32: 100 | F32: FU0062:LD | G32: CTRL2
A34: AF0381:00 | B34: SB75122 | C34: WHT | D34: 20 | E34: 60 | F34: XT0089:15 | G34: CTRL2 | H34: AU/AF0380's
A35: AF0381:03 | B35: SB647222 | C35: WHT | D35: 20 | E35: 60 | F35: XT0089:19 | G35: CTRL2
A36: AF0381:20 | B36: UA1200J27 | C36: WHT | D36: 20 | E36: 60 | F36: XT1200:14 | G36: CTRL2
A37: AF0381:32 | B37: SB7512C1 | C37: WHT | D37: 20 | E37: 60 | F37: XT0089:14 | G37: CTRL2
A38: AF0381:35 | B38: SB647221 | C38: WHT | D38: 20 | E38: 60 | F38: XT0089:18 | G38: CTRL2
A40: AF0383:09 | B40: UA1200J14 | C40: WHT | D40: 20 | E40: 60 | F40: XT1200:11 | G40: CTRL2
A41: AF0384:30 | B41: SV21242 | C41: WHT | D41: 20 | E41: 60 | F41: XT0069:2 | G41: CTRL2
A42: AF0385:05 | B42: -038505 | C42: WHT | D42: 20 | E42: 60 | F42: XT0087:2 | G42: CTRL2
A43: AF0385:21 | B43: -0V | C43: WHT | D43: 20 | E43: 60 | F43: XT0087:3 | G43: CTRL2
A44: AF0385:25 | B44: -0V | C44: WHT | D44: 20 | E44: 60 | F44: XT0080:6 | G44: CTRL2
A45: AF0385:28 | B45: -0V | C45: WHT | D45: 20 | E45: 60 | F45: XT0060:10 | G45: CTRL2
A47: AF0383:COM | B47: -0V | C47: WHT | D47: 16 | E47: 60 | F47: XT0060:5 | G47: CTRL2
A48: AF0384:COM | B48: -0V | C48: WHT | D48: 16 | E48: 60 | F48: XT0060:6 | G48: CTRL2
...

Sheet CTRL1(B)_S
A1: JB71 B,PNL CTRL1
A3: Project # | B3: ANG02
A4: Project Name | B4: STOCK2
A5: Revision | B5: A.4
A7: Controls DE | B7: Poovarasan M
A8: Phone:
A9: Controls ME
A10: Phone:
A12: From | G12: To
A13: Device ID | B13: Wire No. | C13: Wire ID | D13: Gauge/Size | E13: Length | F13: Device ID | G13: Location | H13: Bundle Name
A14: PC0470:+PWR | B14: -009243 | C14: WHT | D14: 20 | E14: 120 | F14: AF0092:43 | G14: CTRL1 | H14: PC0470
A15: PC0470:INP A | B15: -009211 | C15: WHT | D15: 20 | E15: 120 | F15: AF0092:11 | G15: CTRL1
A16: PC0470:-PWR | B16: -009227 | C16: WHT | D16: 20 | E16: 120 | F16: AF0092:27 | G16: CTRL1
A18: PC0472:+PWR | B18: -009245 | C18: WHT | D18: 20 | E18: 120 | F18: AF0092:45 | G18: CTRL1
A19: PC0472:INP_A | B19: -009213 | C19: WHT | D19: 20 | E19: 120 | F19: AF0092:13 | G19: CTRL1
A20: PC0472:-PWR | B20: -009229 | C20: WHT | D20: 20 | E20: 120 | F20: AF0092:29 | G20: CTRL1
A22: AF0092:02 | B22: KA023822 | C22: WHT | D22: 20 | E22: 60 | F22: XT0091:3 | G22: CTRL1 | H22: AU / AF
A24: AF0073:COM | B24: -0V | C24: WHT | D24: 16 | E24: 100 | F24: XT0070:5 | G24: CTRL1
A25: AF0092:COM | B25: -0V | C25: WHT | D25: 16 | E25: 120 | F25: XT0070:7 | G25: CTRL1
A26: AF0093:COM | B26: -0V | C26: WHT | D26: 16 | E26: 120 | F26: XT0070:9 | G26: CTRL1
A27: AU0070:COM | B27: -0V | C27: WHT | D27: 16 | E27: 80 | F27: XT0070:3 | G27: CTRL1
A28: AU0090:COM | B28: -0V | C28: WHT | D28: 16 | E28: 120 | F28: XT0070:7 | G28: CTRL1
A29: AF0093:COM | B29: AF0093N | C29: WHT | D29: 16 | E29: 60 | F29: AF0094:COM | G29: CTRL1
A30: AF0093:V+ | B30: AF0093P | C30: WHT | D30: 16 | E30: 60 | F30: AF0094:V+ | G30: CTRL1
A31: AU0070:V+ | B31: FU0070 | C31: WHT | D31: 16 | E31: 100 | F31: FU0070:LD | G31: CTRL1
A32: AF0073:V+ | B32: FU0071 | C32: WHT | D32: 16 | E32: 100 | F32: XT0070:4 | G32: CTRL1
A33: AF0074:V+ | B33: FU0072 | C33: WHT | D33: 16 | E33: 100 | F33: FU0072:LD | G33: CTRL1
A34: AU0090:V+ | B34: FU0091 | C34: WHT | D34: 16 | E34: 120 | F34: FU0091:LD | G34: CTRL1
A35: AF0092:V+ | B35: FU0092 | C35: WHT | D35: 16 | E35: 120 | F35: FU0092:LD | G35: CTRL1
... A38: AF0074:COM | B38: -0V | C38: WHT | D38: 14 | E38: 100 | F38: XT0070:6 | G38: CTRL1
A40: UV0600:(+) | B40: FU0010 | C40: WHT | D40: 14 | E40: 120 | F40: FU0010:LD | G40: CTRL1 | H40: UV0600
A41: UV0600:(-) | B41: -0V | C41: WHT | D41: 14 | E41: 120 | F41: XT0070:2 | G41: CTRL1
A43: FU0071:LD | B43: FU0071 | C43: WHT | D43: 16 | E43: 60 | F43: XT0070:4 | G43: CTRL1 | H43: FU
A44: FU0093:LD | B44: FU0093 | C44: WHT | D44: 16 | E44: 60 | F44: XT0070:8 | G44: CTRL1
A45: FU0094:LD | B45: FU0094 | C45: WHT | D45: 16 | E45: 60 | F45: XT0070:13 | G45: CTRL1
A46: FU0099:LD | B46: FU0099 | C46: WHT | D46: 16 | E46: 120 | F46: XT0091:5 | G46: CTRL1
A48: FU0070:LI | B48: FU0210 | C48: WHT | D48: 14 | E48: 60 | F48: FU0210:LD | G48: CTRL1
A49: FU0072:LI | B49: FU0210 | C49: WHT | D49: 14 | E49: 60 | F49: FU0091:LI | G49: CTRL1
A51: FU0010:LI | B51: FU0136 | C51: WHT | D51: 12 | E51: 60 | F51: XT0070:1 | G51: CTRL1
A52: FU0100:LI | B52: FU0136 | C52: WHT | D52: 12 | E52: 60 | F52: XT0070:1 | G52: CTRL1
...

Sheet EQP CTRL(C)_S
A1: JB71 C,PNL EQP CTRL
A3: Project # | B3: ANG02
A4: Project Name | B4: STOCK2
A5: Revision | B5: A.4
A7: Controls DE | B7: Poovarasan M
A8: Phone:
A9: Controls ME
A10: Phone:
A12: From | G12: To
A13: Device ID | B13: Wire No. | C13: Wire ID | D13: Gauge/Size | E13: Length | F13: Device ID | G13: Location | H13: Bundle Name
A14: AT0170:45 | B14: AT017045 | C14: WHT | D14: 20 | E14: 60 | F14: XT0170:12 | G14: EQP CTRL | H14: AT0170
A15: AT0170:46 | B15: AT017046 | C15: WHT | D15: 20 | E15: 60 | F15: XT0170:13 | G15: EQP CTRL
A16: AT0170:24 | B16: FU0387 | C16: WHT | D16: 20 | E16: 60 | F16: XT0170:1 | G16: EQP CTRL
A17: AT0170:30 | B17: FU0387 | C17: WHT | D17: 20 | E17: 60 | F17: XT0170:1 | G17: EQP CTRL
A18: AT0170:26 | B18: KA0243A1 | C18: WHT | D18: 20 | E18: 60 | F18: XT0170:2 | G18: EQP CTRL
A19: AT0170:32 | B19: KA0245A1 | C19: WHT | D19: 20 | E19: 60 | F19: XT0170:4 | G19: EQP CTRL
A21: AT0175:18 | B21: HL0171X2 | C21: WHT | D21: 20 | E21: 60 | F21: XT0171:37 | G21: EQP CTRL | H21: AT0175
A22: AT0175:17 | B22: HL0171X3 | C22: WHT | D22: 20 | E22: 60 | F22: XT0171:36 | G22: EQP CTRL
A23: AT0175:21 | B23: HL0172X2 | C23: WHT | D23: 20 | E23: 60 | F23: XT0171:41 | G23: EQP CTRL
A24: AT0175:20 | B24: HL0172X3 | C24: WHT | D24: 20 | E24: 60 | F24: XT0171:40 | G24: EQP CTRL
A26: AT0175:24 | B26: HL6173N | C26: WHT | D26: 16 | E26: 60 | F26: XT0171:44 | G26: EQP CTRL
A27: AT0175:3 | B27: SB6170N | C27: WHT | D27: 16 | E27: 60 | F27: XT0171:46 | G27: EQP CTRL
A28: AT0175:2 | B28: SB6170P | C28: WHT | D28: 16 | E28: 60 | F28: XT0171:45 | G28: EQP CTRL
A29: AT0175:12 | B29: SV66112 | C29: WHT | D29: 16 | E29: 60 | F29: XT0171:2 | G29: EQP CTRL
A30: AT0175:5 | B30: TS65431 | C30: WHT | D30: 16 | E30: 60 | F30: XT0171:17 | G30: EQP CTRL
A31: AT0175:6 | B31: TS65432 | C31: WHT | D31: 16 | E31: 60 | F31: XT0171:18 | G31: EQP CTRL
A32: AT0175:23 | B32: VD6173P | C32: WHT | D32: 16 | E32: 60 | F32: XT0171:43 | G32: EQP CTRL
A34: AT0176:8 | B34: DT65001 | C34: WHT | D34: 16 | E34: 60 | F34: XT0171:15 | G34: EQP CTRL | H34: AT0176
A35: AT0176:9 | B35: DT65002 | C35: WHT | D35: 16 | E35: 60 | F35: XT0171:16 | G35: EQP CTRL
A36: AT0176:23 | B36: HAL67101 | C36: WHT | D36: 16 | E36: 60 | F36: XT0171:5 | G36: EQP CTRL
A37: AT0176:24 | B37: HAL67102 | C37: WHT | D37: 16 | E37: 60 | F37: XT0171:6 | G37: EQP CTRL
A38: AT0176:2 | B38: HAL67103 | C38: WHT | D38: 16 | E38: 60 | F38: XT0171:7 | G38: EQP CTRL
A39: AT0176:3 | B39: HAL67104 | C39: WHT | D39: 16 | E39: 60 | F39: XT0171:8 | G39: EQP CTRL
A40: AT0176:18 | B40: SV66122 | C40: WHT | D40: 16 | E40: 60 | F40: XT0171:4 | G40: EQP CTRL
A42: AT0176:4P1 | B42: AT01764P1 | C42: WHT | D42: 14 | E42: 60 | F42: AT0178:1P1 | G42: EQP CTRL
A43: AT0176:5P1 | B43: AT01765P1 | C43: WHT | D43: 14 | E43: 60 | F43: AT0178:2P1 | G43: EQP CTRL
A45: AT0178:23 | B45: VD0178 | C45: WHT | D45: 20 | E45: 60 | F45: XT0173:2 | G45: EQP CTRL | H45: AT0178
A46: AT0178:24 | B46: KA0178A2 | C46: WHT | D46: 20 | E46: 60 | F46: XT0173:3 | G46: EQP CTRL
A48: AT0178:14 | B48: PS66111 | C48: WHT | D48: 16 | E48: 60 | F48: XT0171:19 | G48: EQP CTRL
A49: AT0178:15 | B49: PS66112 | C49: WHT | D49: 16 | E49: 60 | F49: XT0171:20 | G49: EQP CTRL
...

Sheet CUST(B)_S
A1: JB71 B,PNL CUST
A3: Project # | B3: ANG02
A4: Project Name | B4: STOCK2
A5: Revision | B5: A.4
A7: Controls DE | B7: Poovarasan M
A8: Phone:
A9: Controls ME
A10: Phone:
A12: From | G12: To
A13: Device ID | B13: Wire No. | C13: Wire ID | D13: Gauge/Size | E13: Length | F13: Device ID | G13: Location | H13: Bundle Name
A14: AF0181:00 | B14: KA71702 | C14: WHT | D14: 20 | E14: 60 | F14: XT0189:54 | G14: CUST | H14: AF0180'S
A15: AF0181:01 | B15: KA71722 | C15: WHT | D15: 20 | E15: 60 | F15: XT0189:60 | G15: CUST
A16: AF0181:02 | B16: SB75102 | C16: WHT | D16: 20 | E16: 60 | F16: XT0189:2 | G16: CUST
A17: AF0181:03 | B17: SB75112 | C17: WHT | D17: 20 | E17: 60 | F17: XT0189:4 | G17: CUST
A18: AF0181:04 | B18: SB75562 | C18: WHT | D18: 20 | E18: 60 | F18: XT0189:14 | G18: CUST
A19: AF0181:05 | B19: SB75572 | C19: WHT | D19: 20 | E19: 60 | F19: XT0189:16 | G19: CUST
A20: AF0181:06 | B20: SB75582 | C20: WHT | D20: 20 | E20: 60 | F20: XT0189:18 | G20: CUST
A21: AF0181:07 | B21: SB75542 | C21: WHT | D21: 20 | E21: 60 | F21: XT0189:6 | G21: CUST
A22: AF0181:08 | B22: SB75552 | C22: WHT | D22: 20 | E22: 60 | F22: XT0189:8 | G22: CUST
A23: AF0181:09 | B23: SB75512 | C23: WHT | D23: 20 | E23: 60 | F23: XT0189:10 | G23: CUST
A24: AF0181:10 | B24: SB75522 | C24: WHT | D24: 20 | E24: 60 | F24: XT0189:12 | G24: CUST
A25: AF0181:11 | B25: ZS628124 | C25: WHT | D25: 20 | E25: 60 | F25: XT0299:35 | G25: CUST
A26: AF0181:12 | B26: ZS626124 | C26: WHT | D26: 20 | E26: 60 | F26: XT0299:31 | G26: CUST
... A54: AF0184:V+ | B54: FU0184 | C54: WHT | D54: 16 | E54: 80 | F54: FU0184:LD | G54: CUST
A56: AF0651:00 | B56: -065100 | C56: WHT | D56: 20 | E56: 60 | F56: XT0188:2 | G56: CUST | H56: AF0650'S
A57: AF0651:01 | B57: -065101 | C57: WHT | D57: 20 | E57: 60 | F57: XT0188:4 | G57: CUST
A58: AF0651:02 | B58: -065102 | C58: WHT | D58: 20 | E58: 60 | F58: XT0188:6 | G58: CUST
A59: AF0651:32 | B59: -065132 | C59: WHT | D59: 20 | E59: 60 | F59: XT0188:1 | G59: CUST
A60: AF0651:33 | B60: -065133 | C60: WHT | D60: 20 | E60: 60 | F60: XT0188:3 | G60: CUST
A61: AF0651:34 | B61: -065134 | C61: WHT | D61: 20 | E61: 60 | F61: XT0188:5 | G61: CUST
A62: AF0653:00 | B62: -065300 | C62: WHT | D62: 20 | E62: 60 | F62: XT0291:3 | G62: CUST
A63: AF0653:02 | B63: -065302 | C63: WHT | D63: 20 | E63: 60 | F63: XT0291:4 | G63: CUST
A64: AF0653:04 | B64: -065304 | C64: WHT | D64: 20 | E64: 60 | F64: XT0291:5 | G64: CUST
A65: AF0653:36 | B65: -065336 | C65: WHT | D65: 20 | E65: 60 | F65: XT0291:8 | G65: CUST
A66: AF0651:35 | B66: H6210A31 | C66: WHT | D66: 20 | E66: 120 | F66: XT6210:26 | G66: CUST
A67: AF0651:09 | B67: H6210A310 | C67: WHT | D67: 20 | E67: 120 | F67: XT6210:35 | G67: CUST
A68: AF0651:03 | B68: H6210A32 | C68: WHT | D68: 20 | E68: 120 | F68: XT6210:27 | G68: CUST
... A100: AF0654:V+ | B100: FU0652 | C100: WHT | D100: 12 | E100: 80 | F100: FU0652:LD | G100: CUST
A102: KA0180:A1 | B102: KA0180A1 | C102: WHT | D102: 20 | E102: 60 | F102: AF0182:01 | G102: CUST | H102: KA A1
A103: KA0181:A1 | B103: KA0181A1 | C103: WHT | D103: 20 | E103: 60 | F103: AF0182:00 | G103: CUST
...

Sheet VIB(B)_S
A1: JB71 B,PNL VIB
A3: Project # | B3: ANG02
A4: Project Name | B4: STOCK2
A5: Revision | B5: A.4
A7: Controls DE | B7: Poovarasan M
A8: Phone:
A9: Controls ME
A10: Phone:
A12: From | G12: To
A13: Device ID | B13: Wire No. | C13: Wire ID | D13: Gauge/Size | E13: Length | F13: Device ID | G13: Location | H13: Bundle Name
A14: AF0410:53 | B14: -0V | C14: WHT | D14: 16 | E14: 60 | F14: XT0401:1 | G14: VIB | H14: AF0400's
A15: AF0410:54 | B15: AF0410N | C15: WHT | D15: 16 | E15: 60 | F15: AF0420:53 | G15: VIB
A16: AF0410:55 | B16: FU0400 | C16: WHT | D16: 16 | E16: 60 | F16: FU0400:LD | G16: VIB
A17: AF0410:56 | B17: AF0410P | C17: WHT | D17: 16 | E17: 60 | F17: AF0420:55 | G17: VIB
A18: AF0420:54 | B18: AF0420N | C18: WHT | D18: 16 | E18: 60 | F18: AF0450:53 | G18: VIB
A19: AF0420:56 | B19: AF0420P | C19: WHT | D19: 16 | E19: 60 | F19: AF0450:55 | G19: VIB
A20: AF0450:54 | B20: AF0450N | C20: WHT | D20: 16 | E20: 60 | F20: AF0510:53 | G20: VIB
A21: AF0450:56 | B21: AF0450P | C21: WHT | D21: 16 | E21: 60 | F21: AF0510:55 | G21: VIB
A23: AT0680:NEG | B23: -0V | C23: WHT | D23: 14 | E23: 60 | F23: XT0401:7 | G23: VIB | H23: AT0680
A24: AT0680:POS | B24: FU0680 | C24: WHT | D24: 14 | E24: 60 | F24: XT0401:8 | G24: VIB
A26: FU0680:LD | B26: FU0680 | C26: WHT | D26: 14 | E26: 60 | F26: XT0401:8 | G26: VIB | H26: FU
A28: FU0412:LI | B28: FU0136 | C28: WHT | D28: 12 | E28: 60 | F28: FU0413:LI | G28: VIB
A29: FU0414:LI | B29: FU0136 | C29: WHT | D29: 12 | E29: 60 | F29: FU0680:LI | G29: VIB
A31: FU0400:LI | B31: FU0136 | C31: WHT | D31: 12 | E31: 180 | F31: XT0002:3 | G31: DC | H31: FU/XT - DC
A32: XT0401:1 | B32: -0V | C32: WHT | D32: 12 | E32: 180 | F32: XT0003:3 | G32: DC

Sheet GEN(B)_S
A1: JB71 B,PNL GEN CTRL
A3: Project # | B3: ANG02
A4: Project Name | B4: STOCK2
A5: Revision | B5: A.4
A7: Controls DE | B7: Poovarasan M
A8: Phone:
A9: Controls ME
A10: Phone:
A12: From | G12: To
A13: Device ID | B13: Wire No. | C13: Wire ID | D13: Gauge/Size | E13: Length | F13: Device ID | G13: Location | H13: Bundle Name
A14: AF0121:02 | B14: -012102 | C14: WHT | D14: 20 | E14: 60 | F14: XT0144:2 | G14: GEN | H14: AU/AF
A15: AF0121:03 | B15: -012103 | C15: WHT | D15: 20 | E15: 60 | F15: XT0125:7 | G15: GEN
A16: AF0121:07 | B16: -012107 | C16: WHT | D16: 20 | E16: 60 | F16: XT0124:2 | G16: GEN
A17: AF0121:08 | B17: -012108 | C17: WHT | D17: 20 | E17: 60 | F17: XT0121:7 | G17: GEN
A18: AF0121:11 | B18: -012111 | C18: WHT | D18: 20 | E18: 60 | F18: XT0124:5 | G18: GEN
A19: AF0121:12 | B19: -012112 | C19: WHT | D19: 20 | E19: 60 | F19: XT0124:6 | G19: GEN
A20: AF0121:34 | B20: -012134 | C20: WHT | D20: 20 | E20: 60 | F20: XT0144:1 | G20: GEN
A21: AF0121:40 | B21: -012140 | C21: WHT | D21: 20 | E21: 60 | F21: XT0121:6 | G21: GEN
A22: AF0122:04 | B22: -012204 | C22: WHT | D22: 20 | E22: 60 | F22: XT4002:2 | G22: GEN
A23: AF0122:05 | B23: -012205 | C23: WHT | D23: 20 | E23: 60 | F23: XT4002:4 | G23: GEN
A24: AF0122:06 | B24: -012206 | C24: WHT | D24: 20 | E24: 60 | F24: XT4002:6 | G24: GEN
A25: AF0122:09 | B25: -012209 | C25: WHT | D25: 20 | E25: 60 | F25: XT4002:11 | G25: GEN
A26: AF0122:11 | B26: -012211 | C26: WHT | D26: 20 | E26: 60 | F26: XT0128:2 | G26: GEN
... A47: AF0124:V+ | B47: FU0123 | C47: WHT | D47: 16 | E47: 60 | F47: FU0123:LD | G47: GEN
A49: FV0721:21 | B49: FV072121 | C49: WHT | D49: 20 | E49: 80 | F49: AF0121:42 | G49: GEN | H49: FV
A50: FV0721:14 | B50: FV072114 | C50: WHT | D50: 20 | E50: 80 | F50: AF0121:10 | G50: GEN
A51: FV0722:14 | B51: FV072214 | C51: WHT | D51: 20 | E51: 80 | F51: AF0121:13 | G51: GEN
A52: FV0722:21 | B52: FV072221 | C52: WHT | D52: 20 | E52: 80 | F52: AF0121:45 | G52: GEN
A54: QF0781:11 | B54: QF078111 | C54: WHT | D54: 20 | E54: 60 | F54: AF0121:37 | G54: GEN | H54: QF
A55: QF0784:14 | B55: QF078414 | C55: WHT | D55: 20 | E55: 60 | F55: AF0121:05 | G55: GEN
A56: QF0781:14 | B56: QF078211 | C56: WHT | D56: 20 | E56: 60 | F56: QF0782:11 | G56: GEN
A57: QF0782:14 | B57: QF078311 | C57: WHT | D57: 20 | E57: 60 | F57: QF0783:11 | G57: GEN
A58: QF0783:14 | B58: QF078411 | C58: WHT | D58: 20 | E58: 60 | F58: QF0784:11
A60: KA0123:A1 | B60: KA0123A1 | C60: WHT | D60: 20 | E60: 80 | F60: KA0313:A1 | G60: GEN | H60: KA A1
A61: KA0123:A1 | B61: KA0123A1 | C61: WHT | D61: 20 | E61: 60 | F61: AF0123:03 | G61: GEN
A62: KA0128:A1 | B62: KA0128A1 | C62: WHT | D62: 20 | E62: 60 | F62: AF0123:02 | G62: GEN
A63: KA0185:A1 | B63: KA0185A1 | C63: WHT | D63: 20 | E63: 60 | F63: KA0365:14 | G63: GEN
A64: KA0186:A1 | B64: KA0186A1 | C64: WHT | D64: 20 | E64: 60 | F64: KA0365:24 | G64: GEN
A65: KA0330:A1 | B65: KA0330A1 | C65: WHT | D65: 20 | E65: 60 | F65: XT0125:3 | G65: GEN
A66: KA0336:A1 | B66: KA0336A1 | C66: WHT | D66: 20 | E66: 60 | F66: XT0125:4 | G66: GEN
...

Sheet EQP PWR(C)_S
A1: JB71 C,PNL EQP PWR
A3: Project # | B3: ANG02
A4: Project Name | B4: STOCK2
A5: Revision | B5: A.4
A7: Controls DE | B7: Poovarasan M
A8: Phone:
A9: Controls ME
A10: Phone:
A12: From | G12: To
A13: Device ID | B13: Wire No. | C13: Wire ID | D13: Gauge/Size | E13: Length | F13: Device ID | G13: Location | H13: Bundle Name
A14: UV0170:2(-) | B14: -0V | C14: WHT | D14: 14 | E14: 60 | F14: XT0175:1 | G14: EQP PWR | H14: UV
A15: UV0170:4(-) | B15: -0V | C15: WHT | D15: 14 | E15: 60 | F15: XT0175:1 | G15: EQP PWR
A16: UV0170:1(+) | B16: FU0170 | C16: WHT | D16: 14 | E16: 60 | F16: XT0175:5 | G16: EQP PWR
A17: UV0170:3(+) | B17: FU0170 | C17: WHT | D17: 14 | E17: 60 | F17: XT0175:5 | G17: EQP PWR
A19: FU0171:LD | B19: FU0171 | C19: WHT | D19: 14 | E19: 60 | F19: XT0175:6 | G19: EQP PWR | H19: FU
A20: FU0172:LD | B20: FU0172 | C20: WHT | D20: 14 | E20: 60 | F20: XT0175:7 | G20: EQP PWR
A22: FU0170:LD | B22: FU0170 | C22: WHT | D22: 12 | E22: 60 | F22: XT0175:5 | G22: EQP PWR
A23: FU0171:LI | B23: FU0170 | C23: WHT | D23: 12 | E23: 60 | F23: FU0172:LI | G23: EQP PWR
A24: FU0171:LI | B24: FU0170 | C24: WHT | D24: 12 | E24: 60 | F24: XT0175:5 | G24: EQP PWR
A26: FU0170:LI | B26: FU0136 | C26: WHT | D26: 12 | E26: 120 | F26: XT0002:3 | G26: DC | H26: FU/XT - DC
A27: XT0175:1 | B27: -0V | C27: WHT | D27: 12 | E27: 120 | F27: XT0003:3 | G27: DC

Sheet DC(B)_S
A1: JB71 B,PNL DC PWR
A3: Project # | B3: ANG02
A4: Project Name | B4: STOCK2
A5: Revision | B5: A.4
A7: Controls DE | B7: Poovarasan M
A8: Phone:
A9: Controls ME
A10: Phone:
A12: From | G12: To
A13: Device ID | B13: Wire No. | C13: Wire ID | D13: Gauge/Size | E13: Length | F13: Device ID | G13: Location | H13: Bundle Name
A14: XT0003:7 | B14: -0V | C14: WHT | D14: 14 | E14: 60 | F14: XT0004:3 | G14: DC | H14: XT / FU
A15: XT0005:3 | B15: -0V | C15: WHT | D15: 14 | E15: 60 | F15: XT0003:7 | G15: DC
A16: FU0004:LD | B16: FU0004 | C16: WHT | D16: 14 | E16: 60 | F16: XT0004:1 | G16: DC
A17: FU0005:LD | B17: FU0005 | C17: WHT | D17: 14 | E17: 60 | F17: XT0005:1 | G17: DC
A18: FU0004:LI | B18: FU0136 | C18: WHT | D18: 14 | E18: 60 | F18: XT0002:7 | G18: DC
A19: FU0005:LI | B19: FU0136 | C19: WHT | D19: 14 | E19: 60 | F19: XT0002:7 | G19: DC
A21: FU0011:LD | B21: FU0011 | C21: WHT | D21: 12 | E21: 60 | F21: UJ0131:+ | G21: DC
A22: UJ0131:- | B22: QF7752NEG | C22: WHT | D22: 12 | E22: 60 | F22: XT0011:2 | G22: DC
A23: FU0011:LI | B23: QF7752POS | C23: WHT | D23: 12 | E23: 60 | F23: XT0011:1 | G23: DC

Sheet Bundle Tag Info 
A1: STOCK 2
A2: ANG02
A3: A.4
A6: LIGHTS | B6: DOOR CTRL | C6: DOOR OPR | D6: DOOR EQP | E6: CTRL 2 | F6: CTRL 1 | G6: EQP CTRL | H6: CUST | I6: VIB | J6: GEN | K6: EQP PWR | L6: DC | M6: Panel Name | N6: Panel Name | O6: Panel Name | P6: Panel Name | Q6: Panel Name | R6: Panel Name | S6: Panel Name | T6: Panel Name | U6: Panel Name | V6: Panel Name | W6: Panel Name | X6: Panel Name | Y6: Panel Name | Z6: Panel Name | AA6: Panel Name | AB6: Panel Name | AC6: Panel Name | AD6: Panel Name
A7: EL0 | B7: AT | C7: HA0472 | D7: HL0171 | E7: UA1200 | F7: PC0470 | G7: AT0170 | H7: AF0180'S | I7: AF0400's | J7: AU/AF | K7: UV | L7: XT / FU
C8: SA0471 | D8: HL0172 | E8: AU/AF0060's | F8: AU / AF | G8: AT0175 | H8: AF0650'S | I8: AT0680 | J8: FV | K8: FU
C9: SA0473 | D9: SA0170 | E9: AU/AF0380's | F9: UV0600 | G9: AT0176 | H9: KA A1 | I9: FU | J9: QF | K9: FU/XT - DC
C10: SA0475 | D10: SH6500 | E10: KA A1 | F10: FU | G10: AT0178 | H10: KA A2 | I10: FU/XT - DC | J10: KA A1
C11: SB0333 | E11: KA A2 | F11: AF - CUST | G11: KA | H11: KA | J11: KA A2
C12: SB0471 | E12: KA ICE CUBE | F12: XT - DC | G12: XT | H12: FU/XT | J12: KA
C13: SB0472 | E13: KA Doubles | F13: XT - GEN | G13: XT - CUST | H13: FU/XT - DC | J13: KA LRG
C14: SB0473 | E14: KA | F14: XT - EQP CTRL | G14: AT - EQP PWR | H14: AF-GEN | J14: FU/XT
C15: SB0474 | E15: KT | G15: XT - EQP PWR | H15: KA/XT - GEN | J15: AT0140
C16: SH0470 | E16: XT/FU | J16: AT RED
C17: SH0471 | E17: KA/KT - CTRL1 | J17: AT BLU
C18: SH0472 | E18: XT - CTRL1 | J18: FV RD
E19: AF - CUST | J19: QF RD
E20: KA/XT - CUST | J20: KA RD
E21: AF/FU/XT - DC | J21: XT RD
E22: XT - GEN | J22: FU/XT - DC
E23: XT - EQP CTRL

Sheet Bundle Tags2
A1: =IF('Bundle Tag Info '!A6<>"Panel Name",'Bundle Tag Info '!A6,"") -> LIGHTS | B1: =IF('Bundle Tag Info '!B6<>"Panel Name",'Bundle Tag Info '!B6,"") -> DOOR CTRL | C1: =IF('Bundle Tag Info '!C6<>"Panel Name",'Bundle Tag Info '!C6,"") -> DOOR OPR | D1: =IF('Bundle Tag Info '!D6<>"Panel Name",'Bundle Tag Info '!D6,"") -> DOOR EQP | E1: =IF('Bundle Tag Info '!E6<>"Panel Name",'Bundle Tag Info '!E6,"") -> CTRL 2 | F1: =IF('Bundle Tag Info '!F6<>"Panel Name",'Bundle Tag Info '!F6,"") -> CTRL 1 | G1: =IF('Bundle Tag Info '!G6<>"Panel Name",'Bundle Tag Info '!G6,"") -> EQP CTRL | H1: =IF('Bundle Tag Info '!H6<>"Panel Name",'Bundle Tag Info '!H6,"") -> CUST | ... AD1: =IF('Bundle Tag Info '!AD6<>"Panel Name",'Bundle Tag Info '!AD6,"")
A2: =IF('Bundle Tag Info '!A$7<>"",CONCATENATE('Bundle Tag Info '!$A$1," ",CHAR(10),'Bundle Tag Info '!$A$2," ",'Bundle Tag Info '!$A$3,CHAR(10),'Bundle Tag Info '!A$6,CHAR(10),'Bundle Tag Info '!A$7),"") -> STOCK 2 ANG02 A.4 LIGHTS EL0 | B2: =IF('Bundle Tag Info '!B$7<>"",CONCATENATE('Bundle Tag Info '!$A$1," ",CHAR(10),'Bundle Tag Info '!$A$2," ",'Bundle Tag Info '!$A$3,CHAR(10),'Bundle Tag Info '!B$6,CHAR(10),'Bundle Tag Info '!B$7),"") -> STOCK 2 ANG02 A.4 DOOR CTRL AT | C2: =IF('Bundle Tag Info '!C$7<>"",CONCATENATE('Bundle Tag Info '!$A$1," ",CHAR(10),'Bundle Tag Info '!$A$2," ",'Bundle Tag Info '!$A$3,CHAR(10),'Bundle Tag Info '!C$6,CHAR(10),'Bundle Tag Info '!C$7),"") -> STOCK 2 ANG02 A.4 DOOR OPR HA0472 | D2: =IF('Bundle Tag Info '!D$7<>"",CONCATENATE('Bundle Tag Info '!$A$1," ",CHAR(10),'Bundle Tag Info '!$A$2," ",'Bundle Tag Info '!$A$3,CHAR(10),'Bundle Tag Info '!D$6,CHAR(10),'Bundle Tag Info '!D$7),"") -> STOCK 2 ANG02 A.4 DOOR EQP HL0171 | E2: =IF('Bundle Tag Info '!E$7<>"",CONCATENATE('Bundle Tag Info '!$A$1," ",CHAR(10),'Bundle Tag Info '!$A$2," ",'Bundle Tag Info '!$A$3,CHAR(10),'Bundle Tag Info '!E$6,CHAR(10),'Bundle Tag Info '!E$7),"") -> STOCK 2 ANG02 A.4 CTRL 2 UA1200 | F2: =IF('Bundle Tag Info '!F$7<>"",CONCATENATE('Bundle Tag Info '!$A$1," ",CHAR(10),'Bundle Tag Info '!$A$2," ",'Bundle Tag Info '!$A$3,CHAR(10),'Bundle Tag Info '!F$6,CHAR(10),'Bundle Tag Info '!F$7),"") -> STOCK 2 ANG02 A.4 CTRL 1 PC0470 | G2: =IF('Bundle Tag Info '!G$7<>"",CONCATENATE('Bundle Tag Info '!$A$1," ",CHAR(10),'Bundle Tag Info '!$A$2," ",'Bundle Tag Info '!$A$3,CHAR(10),'Bundle Tag Info '!G$6,CHAR(10),'Bundle Tag Info '!G$7),"") -> STOCK 2 ANG02 A.4 EQP CTRL AT0170 | H2: =IF('Bundle Tag Info '!H$7<>"",CONCATENATE('Bundle Tag Info '!$A$1," ",CHAR(10),'Bundle Tag Info '!$A$2," ",'Bundle Tag Info '!$A$3,CHAR(10),'Bundle Tag Info '!H$6,CHAR(10),'Bundle Tag Info '!H$7),"") -> STOCK 2 ANG02 A.4 CUST AF0180'S | ... AD2: =IF('Bundle Tag Info '!AD$7<>"",CONCATENATE('Bundle Tag Info '!$A$1," ",CHAR(10),'Bundle Tag Info '!$A$2," ",'Bundle Tag Info '!$A$3,CHAR(10),'Bundle Tag Info '!AD$6,CHAR(10),'Bundle Tag Info '!AD$7),"")
A3: =IF('Bundle Tag Info '!A$8<>"",CONCATENATE('Bundle Tag Info '!$A$1," ",CHAR(10),'Bundle Tag Info '!$A$2," ",'Bundle Tag Info '!$A$3,CHAR(10),'Bundle Tag Info '!A$6,CHAR(10),'Bundle Tag Info '!A$8),"") | B3: =IF('Bundle Tag Info '!B$8<>"",CONCATENATE('Bundle Tag Info '!$A$1," ",CHAR(10),'Bundle Tag Info '!$A$2," ",'Bundle Tag Info '!$A$3,CHAR(10),'Bundle Tag Info '!B$6,CHAR(10),'Bundle Tag Info '!B$8),"") | C3: =IF('Bundle Tag Info '!C$8<>"",CONCATENATE('Bundle Tag Info '!$A$1," ",CHAR(10),'Bundle Tag Info '!$A$2," ",'Bundle Tag Info '!$A$3,CHAR(10),'Bundle Tag Info '!C$6,CHAR(10),'Bundle Tag Info '!C$8),"") -> STOCK 2 ANG02 A.4 DOOR OPR SA0471 | D3: =IF('Bundle Tag Info '!D$8<>"",CONCATENATE('Bundle Tag Info '!$A$1," ",CHAR(10),'Bundle Tag Info '!$A$2," ",'Bundle Tag Info '!$A$3,CHAR(10),'Bundle Tag Info '!D$6,CHAR(10),'Bundle Tag Info '!D$8),"") -> STOCK 2 ANG02 A.4 DOOR EQP HL0172 | E3: =IF('Bundle Tag Info '!E$8<>"",CONCATENATE('Bundle Tag Info '!$A$1," ",CHAR(10),'Bundle Tag Info '!$A$2," ",'Bundle Tag Info '!$A$3,CHAR(10),'Bundle Tag Info '!E$6,CHAR(10),'Bundle Tag Info '!E$8),"") -> STOCK 2 ANG02 A.4 CTRL 2 AU/AF0060's | F3: =IF('Bundle Tag Info '!F$8<>"",CONCATENATE('Bundle Tag Info '!$A$1," ",CHAR(10),'Bundle Tag Info '!$A$2," ",'Bundle Tag Info '!$A$3,CHAR(10),'Bundle Tag Info '!F$6,CHAR(10),'Bundle Tag Info '!F$8),"") -> STOCK 2 ANG02 A.4 CTRL 1 AU / AF | G3: =IF('Bundle Tag Info '!G$8<>"",CONCATENATE('Bundle Tag Info '!$A$1," ",CHAR(10),'Bundle Tag Info '!$A$2," ",'Bundle Tag Info '!$A$3,CHAR(10),'Bundle Tag Info '!G$6,CHAR(10),'Bundle Tag Info '!G$8),"") -> STOCK 2 ANG02 A.4 EQP CTRL AT0175 | H3: =IF('Bundle Tag Info '!H$8<>"",CONCATENATE('Bundle Tag Info '!$A$1," ",CHAR(10),'Bundle Tag Info '!$A$2," ",'Bundle Tag Info '!$A$3,CHAR(10),'Bundle Tag Info '!H$6,CHAR(10),'Bundle Tag Info '!H$8),"") -> STOCK 2 ANG02 A.4 CUST AF0650'S | ... AD3: =IF('Bundle Tag Info '!AD$8<>"",CONCATENATE('Bundle Tag Info '!$A$1," ",CHAR(10),'Bundle Tag Info '!$A$2," ",'Bundle Tag Info '!$A$3,CHAR(10),'Bundle Tag Info '!AD$6,CHAR(10),'Bundle Tag Info '!AD$8),"")
A4: =IF('Bundle Tag Info '!A$9<>"",CONCATENATE('Bundle Tag Info '!$A$1," ",CHAR(10),'Bundle Tag Info '!$A$2," ",'Bundle Tag Info '!$A$3,CHAR(10),'Bundle Tag Info '!A$6,CHAR(10),'Bundle Tag Info '!A$9),"") | B4: =IF('Bundle Tag Info '!B$9<>"",CONCATENATE('Bundle Tag Info '!$A$1," ",CHAR(10),'Bundle Tag Info '!$A$2," ",'Bundle Tag Info '!$A$3,CHAR(10),'Bundle Tag Info '!B$6,CHAR(10),'Bundle Tag Info '!B$9),"") | C4: =IF('Bundle Tag Info '!C$9<>"",CONCATENATE('Bundle Tag Info '!$A$1," ",CHAR(10),'Bundle Tag Info '!$A$2," ",'Bundle Tag Info '!$A$3,CHAR(10),'Bundle Tag Info '!C$6,CHAR(10),'Bundle Tag Info '!C$9),"") -> STOCK 2 ANG02 A.4 DOOR OPR SA0473 | D4: =IF('Bundle Tag Info '!D$9<>"",CONCATENATE('Bundle Tag Info '!$A$1," ",CHAR(10),'Bundle Tag Info '!$A$2," ",'Bundle Tag Info '!$A$3,CHAR(10),'Bundle Tag Info '!D$6,CHAR(10),'Bundle Tag Info '!D$9),"") -> STOCK 2 ANG02 A.4 DOOR EQP SA0170 | E4: =IF('Bundle Tag Info '!E$9<>"",CONCATENATE('Bundle Tag Info '!$A$1," ",CHAR(10),'Bundle Tag Info '!$A$2," ",'Bundle Tag Info '!$A$3,CHAR(10),'Bundle Tag Info '!E$6,CHAR(10),'Bundle Tag Info '!E$9),"") -> STOCK 2 ANG02 A.4 CTRL 2 AU/AF0380's | F4: =IF('Bundle Tag Info '!F$9<>"",CONCATENATE('Bundle Tag Info '!$A$1," ",CHAR(10),'Bundle Tag Info '!$A$2," ",'Bundle Tag Info '!$A$3,CHAR(10),'Bundle Tag Info '!F$6,CHAR(10),'Bundle Tag Info '!F$9),"") -> STOCK 2 ANG02 A.4 CTRL 1 UV0600 | G4: =IF('Bundle Tag Info '!G$9<>"",CONCATENATE('Bundle Tag Info '!$A$1," ",CHAR(10),'Bundle Tag Info '!$A$2," ",'Bundle Tag Info '!$A$3,CHAR(10),'Bundle Tag Info '!G$6,CHAR(10),'Bundle Tag Info '!G$9),"") -> STOCK 2 ANG02 A.4 EQP CTRL AT0176 | H4: =IF('Bundle Tag Info '!H$9<>"",CONCATENATE('Bundle Tag Info '!$A$1," ",CHAR(10),'Bundle Tag Info '!$A$2," ",'Bundle Tag Info '!$A$3,CHAR(10),'Bundle Tag Info '!H$6,CHAR(10),'Bundle Tag Info '!H$9),"") -> STOCK 2 ANG02 A.4 CUST KA A1 | ... AD4: =IF('Bundle Tag Info '!AD$9<>"",CONCATENATE('Bundle Tag Info '!$A$1," ",CHAR(10),'Bundle Tag Info '!$A$2," ",'Bundle Tag Info '!$A$3,CHAR(10),'Bundle Tag Info '!AD$6,CHAR(10),'Bundle Tag Info '!AD$9),"")
A5: =IF('Bundle Tag Info '!A$10<>"",CONCATENATE('Bundle Tag Info '!$A$1," ",CHAR(10),'Bundle Tag Info '!$A$2," ",'Bundle Tag Info '!$A$3,CHAR(10),'Bundle Tag Info '!A$6,CHAR(10),'Bundle Tag Info '!A$10),"") | B5: =IF('Bundle Tag Info '!B$10<>"",CONCATENATE('Bundle Tag Info '!$A$1," ",CHAR(10),'Bundle Tag Info '!$A$2," ",'Bundle Tag Info '!$A$3,CHAR(10),'Bundle Tag Info '!B$6,CHAR(10),'Bundle Tag Info '!B$10),"") | C5: =IF('Bundle Tag Info '!C$10<>"",CONCATENATE('Bundle Tag Info '!$A$1," ",CHAR(10),'Bundle Tag Info '!$A$2," ",'Bundle Tag Info '!$A$3,CHAR(10),'Bundle Tag Info '!C$6,CHAR(10),'Bundle Tag Info '!C$10),"") -> STOCK 2 ANG02 A.4 DOOR OPR SA0475 | D5: =IF('Bundle Tag Info '!D$10<>"",CONCATENATE('Bundle Tag Info '!$A$1," ",CHAR(10),'Bundle Tag Info '!$A$2," ",'Bundle Tag Info '!$A$3,CHAR(10),'Bundle Tag Info '!D$6,CHAR(10),'Bundle Tag Info '!D$10),"") -> STOCK 2 ANG02 A.4 DOOR EQP SH6500 | E5: =IF('Bundle Tag Info '!E$10<>"",CONCATENATE('Bundle Tag Info '!$A$1," ",CHAR(10),'Bundle Tag Info '!$A$2," ",'Bundle Tag Info '!$A$3,CHAR(10),'Bundle Tag Info '!E$6,CHAR(10),'Bundle Tag Info '!E$10),"") -> STOCK 2 ANG02 A.4 CTRL 2 KA A1 | F5: =IF('Bundle Tag Info '!F$10<>"",CONCATENATE('Bundle Tag Info '!$A$1," ",CHAR(10),'Bundle Tag Info '!$A$2," ",'Bundle Tag Info '!$A$3,CHAR(10),'Bundle Tag Info '!F$6,CHAR(10),'Bundle Tag Info '!F$10),"") -> STOCK 2 ANG02 A.4 CTRL 1 FU | G5: =IF('Bundle Tag Info '!G$10<>"",CONCATENATE('Bundle Tag Info '!$A$1," ",CHAR(10),'Bundle Tag Info '!$A$2," ",'Bundle Tag Info '!$A$3,CHAR(10),'Bundle Tag Info '!G$6,CHAR(10),'Bundle Tag Info '!G$10),"") -> STOCK 2 ANG02 A.4 EQP CTRL AT0178 | H5: =IF('Bundle Tag Info '!H$10<>"",CONCATENATE('Bundle Tag Info '!$A$1," ",CHAR(10),'Bundle Tag Info '!$A$2," ",'Bundle Tag Info '!$A$3,CHAR(10),'Bundle Tag Info '!H$6,CHAR(10),'Bundle Tag Info '!H$10),"") -> STOCK 2 ANG02 A.4 CUST KA A2 | ... AD5: =IF('Bundle Tag Info '!AD$10<>"",CONCATENATE('Bundle Tag Info '!$A$1," ",CHAR(10),'Bundle Tag Info '!$A$2," ",'Bundle Tag Info '!$A$3,CHAR(10),'Bundle Tag Info '!AD$6,CHAR(10),'Bundle Tag Info '!AD$10),"")
A6: =IF('Bundle Tag Info '!A$11<>"",CONCATENATE('Bundle Tag Info '!$A$1," ",CHAR(10),'Bundle Tag Info '!$A$2," ",'Bundle Tag Info '!$A$3,CHAR(10),'Bundle Tag Info '!A$6,CHAR(10),'Bundle Tag Info '!A$11),"") | B6: =IF('Bundle Tag Info '!B$11<>"",CONCATENATE('Bundle Tag Info '!$A$1," ",CHAR(10),'Bundle Tag Info '!$A$2," ",'Bundle Tag Info '!$A$3,CHAR(10),'Bundle Tag Info '!B$6,CHAR(10),'Bundle Tag Info '!B$11),"") | C6: =IF('Bundle Tag Info '!C$11<>"",CONCATENATE('Bundle Tag Info '!$A$1," ",CHAR(10),'Bundle Tag Info '!$A$2," ",'Bundle Tag Info '!$A$3,CHAR(10),'Bundle Tag Info '!C$6,CHAR(10),'Bundle Tag Info '!C$11),"") -> STOCK 2 ANG02 A.4 DOOR OPR SB0333 | D6: =IF('Bundle Tag Info '!D$11<>"",CONCATENATE('Bundle Tag Info '!$A$1," ",CHAR(10),'Bundle Tag Info '!$A$2," ",'Bundle Tag Info '!$A$3,CHAR(10),'Bundle Tag Info '!D$6,CHAR(10),'Bundle Tag Info '!D$11),"") | E6: =IF('Bundle Tag Info '!E$11<>"",CONCATENATE('Bundle Tag Info '!$A$1," ",CHAR(10),'Bundle Tag Info '!$A$2," ",'Bundle Tag Info '!$A$3,CHAR(10),'Bundle Tag Info '!E$6,CHAR(10),'Bundle Tag Info '!E$11),"") -> STOCK 2 ANG02 A.4 CTRL 2 KA A2 | F6: =IF('Bundle Tag Info '!F$11<>"",CONCATENATE('Bundle Tag Info '!$A$1," ",CHAR(10),'Bundle Tag Info '!$A$2," ",'Bundle Tag Info '!$A$3,CHAR(10),'Bundle Tag Info '!F$6,CHAR(10),'Bundle Tag Info '!F$11),"") -> STOCK 2 ANG02 A.4 CTRL 1 AF - CUST | G6: =IF('Bundle Tag Info '!G$11<>"",CONCATENATE('Bundle Tag Info '!$A$1," ",CHAR(10),'Bundle Tag Info '!$A$2," ",'Bundle Tag Info '!$A$3,CHAR(10),'Bundle Tag Info '!G$6,CHAR(10),'Bundle Tag Info '!G$11),"") -> STOCK 2 ANG02 A.4 EQP CTRL KA | H6: =IF('Bundle Tag Info '!H$11<>"",CONCATENATE('Bundle Tag Info '!$A$1," ",CHAR(10),'Bundle Tag Info '!$A$2," ",'Bundle Tag Info '!$A$3,CHAR(10),'Bundle Tag Info '!H$6,CHAR(10),'Bundle Tag Info '!H$11),"") -> STOCK 2 ANG02 A.4 CUST KA | ... AD6: =IF('Bundle Tag Info '!AD$11<>"",CONCATENATE('Bundle Tag Info '!$A$1," ",CHAR(10),'Bundle Tag Info '!$A$2," ",'Bundle Tag Info '!$A$3,CHAR(10),'Bundle Tag Info '!AD$6,CHAR(10),'Bundle Tag Info '!AD$11),"")
A7: =IF('Bundle Tag Info '!A$12<>"",CONCATENATE('Bundle Tag Info '!$A$1," ",CHAR(10),'Bundle Tag Info '!$A$2," ",'Bundle Tag Info '!$A$3,CHAR(10),'Bundle Tag Info '!A$6,CHAR(10),'Bundle Tag Info '!A$12),"") | B7: =IF('Bundle Tag Info '!B$12<>"",CONCATENATE('Bundle Tag Info '!$A$1," ",CHAR(10),'Bundle Tag Info '!$A$2," ",'Bundle Tag Info '!$A$3,CHAR(10),'Bundle Tag Info '!B$6,CHAR(10),'Bundle Tag Info '!B$12),"") | C7: =IF('Bundle Tag Info '!C$12<>"",CONCATENATE('Bundle Tag Info '!$A$1," ",CHAR(10),'Bundle Tag Info '!$A$2," ",'Bundle Tag Info '!$A$3,CHAR(10),'Bundle Tag Info '!C$6,CHAR(10),'Bundle Tag Info '!C$12),"") -> STOCK 2 ANG02 A.4 DOOR OPR SB0471 | D7: =IF('Bundle Tag Info '!D$12<>"",CONCATENATE('Bundle Tag Info '!$A$1," ",CHAR(10),'Bundle Tag Info '!$A$2," ",'Bundle Tag Info '!$A$3,CHAR(10),'Bundle Tag Info '!D$6,CHAR(10),'Bundle Tag Info '!D$12),"") | E7: =IF('Bundle Tag Info '!E$12<>"",CONCATENATE('Bundle Tag Info '!$A$1," ",CHAR(10),'Bundle Tag Info '!$A$2," ",'Bundle Tag Info '!$A$3,CHAR(10),'Bundle Tag Info '!E$6,CHAR(10),'Bundle Tag Info '!E$12),"") -> STOCK 2 ANG02 A.4 CTRL 2 KA ICE CUBE | F7: =IF('Bundle Tag Info '!F$12<>"",CONCATENATE('Bundle Tag Info '!$A$1," ",CHAR(10),'Bundle Tag Info '!$A$2," ",'Bundle Tag Info '!$A$3,CHAR(10),'Bundle Tag Info '!F$6,CHAR(10),'Bundle Tag Info '!F$12),"") -> STOCK 2 ANG02 A.4 CTRL 1 XT - DC | G7: =IF('Bundle Tag Info '!G$12<>"",CONCATENATE('Bundle Tag Info '!$A$1," ",CHAR(10),'Bundle Tag Info '!$A$2," ",'Bundle Tag Info '!$A$3,CHAR(10),'Bundle Tag Info '!G$6,CHAR(10),'Bundle Tag Info '!G$12),"") -> STOCK 2 ANG02 A.4 EQP CTRL XT | H7: =IF('Bundle Tag Info '!H$12<>"",CONCATENATE('Bundle Tag Info '!$A$1," ",CHAR(10),'Bundle Tag Info '!$A$2," ",'Bundle Tag Info '!$A$3,CHAR(10),'Bundle Tag Info '!H$6,CHAR(10),'Bundle Tag Info '!H$12),"") -> STOCK 2 ANG02 A.4 CUST FU/XT | ... AD7: =IF('Bundle Tag Info '!AD$12<>"",CONCATENATE('Bundle Tag Info '!$A$1," ",CHAR(10),'Bundle Tag Info '!$A$2," ",'Bundle Tag Info '!$A$3,CHAR(10),'Bundle Tag Info '!AD$6,CHAR(10),'Bundle Tag Info '!AD$12),"")
A8: =IF('Bundle Tag Info '!A$13<>"",CONCATENATE('Bundle Tag Info '!$A$1," ",CHAR(10),'Bundle Tag Info '!$A$2," ",'Bundle Tag Info '!$A$3,CHAR(10),'Bundle Tag Info '!A$6,CHAR(10),'Bundle Tag Info '!A$13),"") | B8: =IF('Bundle Tag Info '!B$13<>"",CONCATENATE('Bundle Tag Info '!$A$1," ",CHAR(10),'Bundle Tag Info '!$A$2," ",'Bundle Tag Info '!$A$3,CHAR(10),'Bundle Tag Info '!B$6,CHAR(10),'Bundle Tag Info '!B$13),"") | C8: =IF('Bundle Tag Info '!C$13<>"",CONCATENATE('Bundle Tag Info '!$A$1," ",CHAR(10),'Bundle Tag Info '!$A$2," ",'Bundle Tag Info '!$A$3,CHAR(10),'Bundle Tag Info '!C$6,CHAR(10),'Bundle Tag Info '!C$13),"") -> STOCK 2 ANG02 A.4 DOOR OPR SB0472 | D8: =IF('Bundle Tag Info '!D$13<>"",CONCATENATE('Bundle Tag Info '!$A$1," ",CHAR(10),'Bundle Tag Info '!$A$2," ",'Bundle Tag Info '!$A$3,CHAR(10),'Bundle Tag Info '!D$6,CHAR(10),'Bundle Tag Info '!D$13),"") | E8: =IF('Bundle Tag Info '!E$13<>"",CONCATENATE('Bundle Tag Info '!$A$1," ",CHAR(10),'Bundle Tag Info '!$A$2," ",'Bundle Tag Info '!$A$3,CHAR(10),'Bundle Tag Info '!E$6,CHAR(10),'Bundle Tag Info '!E$13),"") -> STOCK 2 ANG02 A.4 CTRL 2 KA Doubles | F8: =IF('Bundle Tag Info '!F$13<>"",CONCATENATE('Bundle Tag Info '!$A$1," ",CHAR(10),'Bundle Tag Info '!$A$2," ",'Bundle Tag Info '!$A$3,CHAR(10),'Bundle Tag Info '!F$6,CHAR(10),'Bundle Tag Info '!F$13),"") -> STOCK 2 ANG02 A.4 CTRL 1 XT - GEN | G8: =IF('Bundle Tag Info '!G$13<>"",CONCATENATE('Bundle Tag Info '!$A$1," ",CHAR(10),'Bundle Tag Info '!$A$2," ",'Bundle Tag Info '!$A$3,CHAR(10),'Bundle Tag Info '!G$6,CHAR(10),'Bundle Tag Info '!G$13),"") -> STOCK 2 ANG02 A.4 EQP CTRL XT - CUST | H8: =IF('Bundle Tag Info '!H$13<>"",CONCATENATE('Bundle Tag Info '!$A$1," ",CHAR(10),'Bundle Tag Info '!$A$2," ",'Bundle Tag Info '!$A$3,CHAR(10),'Bundle Tag Info '!H$6,CHAR(10),'Bundle Tag Info '!H$13),"") -> STOCK 2 ANG02 A.4 CUST FU/XT - DC | ... AD8: =IF('Bundle Tag Info '!AD$13<>"",CONCATENATE('Bundle Tag Info '!$A$1," ",CHAR(10),'Bundle Tag Info '!$A$2," ",'Bundle Tag Info '!$A$3,CHAR(10),'Bundle Tag Info '!AD$6,CHAR(10),'Bundle Tag Info '!AD$13),"")
A9: =IF('Bundle Tag Info '!A$14<>"",CONCATENATE('Bundle Tag Info '!$A$1," ",CHAR(10),'Bundle Tag Info '!$A$2," ",'Bundle Tag Info '!$A$3,CHAR(10),'Bundle Tag Info '!A$6,CHAR(10),'Bundle Tag Info '!A$14),"") | B9: =IF('Bundle Tag Info '!B$14<>"",CONCATENATE('Bundle Tag Info '!$A$1," ",CHAR(10),'Bundle Tag Info '!$A$2," ",'Bundle Tag Info '!$A$3,CHAR(10),'Bundle Tag Info '!B$6,CHAR(10),'Bundle Tag Info '!B$14),"") | C9: =IF('Bundle Tag Info '!C$14<>"",CONCATENATE('Bundle Tag Info '!$A$1," ",CHAR(10),'Bundle Tag Info '!$A$2," ",'Bundle Tag Info '!$A$3,CHAR(10),'Bundle Tag Info '!C$6,CHAR(10),'Bundle Tag Info '!C$14),"") -> STOCK 2 ANG02 A.4 DOOR OPR SB0473 | D9: =IF('Bundle Tag Info '!D$14<>"",CONCATENATE('Bundle Tag Info '!$A$1," ",CHAR(10),'Bundle Tag Info '!$A$2," ",'Bundle Tag Info '!$A$3,CHAR(10),'Bundle Tag Info '!D$6,CHAR(10),'Bundle Tag Info '!D$14),"") | E9: =IF('Bundle Tag Info '!E$14<>"",CONCATENATE('Bundle Tag Info '!$A$1," ",CHAR(10),'Bundle Tag Info '!$A$2," ",'Bundle Tag Info '!$A$3,CHAR(10),'Bundle Tag Info '!E$6,CHAR(10),'Bundle Tag Info '!E$14),"") -> STOCK 2 ANG02 A.4 CTRL 2 KA | F9: =IF('Bundle Tag Info '!F$14<>"",CONCATENATE('Bundle Tag Info '!$A$1," ",CHAR(10),'Bundle Tag Info '!$A$2," ",'Bundle Tag Info '!$A$3,CHAR(10),'Bundle Tag Info '!F$6,CHAR(10),'Bundle Tag Info '!F$14),"") -> STOCK 2 ANG02 A.4 CTRL 1 XT - EQP CTRL | G9: =IF('Bundle Tag Info '!G$14<>"",CONCATENATE('Bundle Tag Info '!$A$1," ",CHAR(10),'Bundle Tag Info '!$A$2," ",'Bundle Tag Info '!$A$3,CHAR(10),'Bundle Tag Info '!G$6,CHAR(10),'Bundle Tag Info '!G$14),"") -> STOCK 2 ANG02 A.4 EQP CTRL AT - EQP PWR | H9: =IF('Bundle Tag Info '!H$14<>"",CONCATENATE('Bundle Tag Info '!$A$1," ",CHAR(10),'Bundle Tag Info '!$A$2," ",'Bundle Tag Info '!$A$3,CHAR(10),'Bundle Tag Info '!H$6,CHAR(10),'Bundle Tag Info '!H$14),"") -> STOCK 2 ANG02 A.4 CUST AF-GEN | ... AD9: =IF('Bundle Tag Info '!AD$14<>"",CONCATENATE('Bundle Tag Info '!$A$1," ",CHAR(10),'Bundle Tag Info '!$A$2," ",'Bundle Tag Info '!$A$3,CHAR(10),'Bundle Tag Info '!AD$6,CHAR(10),'Bundle Tag Info '!AD$14),"")
A10: =IF('Bundle Tag Info '!A$15<>"",CONCATENATE('Bundle Tag Info '!$A$1," ",CHAR(10),'Bundle Tag Info '!$A$2," ",'Bundle Tag Info '!$A$3,CHAR(10),'Bundle Tag Info '!A$6,CHAR(10),'Bundle Tag Info '!A$15),"") | B10: =IF('Bundle Tag Info '!B$15<>"",CONCATENATE('Bundle Tag Info '!$A$1," ",CHAR(10),'Bundle Tag Info '!$A$2," ",'Bundle Tag Info '!$A$3,CHAR(10),'Bundle Tag Info '!B$6,CHAR(10),'Bundle Tag Info '!B$15),"") | C10: =IF('Bundle Tag Info '!C$15<>"",CONCATENATE('Bundle Tag Info '!$A$1," ",CHAR(10),'Bundle Tag Info '!$A$2," ",'Bundle Tag Info '!$A$3,CHAR(10),'Bundle Tag Info '!C$6,CHAR(10),'Bundle Tag Info '!C$15),"") -> STOCK 2 ANG02 A.4 DOOR OPR SB0474 | D10: =IF('Bundle Tag Info '!D$15<>"",CONCATENATE('Bundle Tag Info '!$A$1," ",CHAR(10),'Bundle Tag Info '!$A$2," ",'Bundle Tag Info '!$A$3,CHAR(10),'Bundle Tag Info '!D$6,CHAR(10),'Bundle Tag Info '!D$15),"") | E10: =IF('Bundle Tag Info '!E$15<>"",CONCATENATE('Bundle Tag Info '!$A$1," ",CHAR(10),'Bundle Tag Info '!$A$2," ",'Bundle Tag Info '!$A$3,CHAR(10),'Bundle Tag Info '!E$6,CHAR(10),'Bundle Tag Info '!E$15),"") -> STOCK 2 ANG02 A.4 CTRL 2 KT | F10: =IF('Bundle Tag Info '!F$15<>"",CONCATENATE('Bundle Tag Info '!$A$1," ",CHAR(10),'Bundle Tag Info '!$A$2," ",'Bundle Tag Info '!$A$3,CHAR(10),'Bundle Tag Info '!F$6,CHAR(10),'Bundle Tag Info '!F$15),"") | G10: =IF('Bundle Tag Info '!G$15<>"",CONCATENATE('Bundle Tag Info '!$A$1," ",CHAR(10),'Bundle Tag Info '!$A$2," ",'Bundle Tag Info '!$A$3,CHAR(10),'Bundle Tag Info '!G$6,CHAR(10),'Bundle Tag Info '!G$15),"") -> STOCK 2 ANG02 A.4 EQP CTRL XT - EQP PWR | H10: =IF('Bundle Tag Info '!H$15<>"",CONCATENATE('Bundle Tag Info '!$A$1," ",CHAR(10),'Bundle Tag Info '!$A$2," ",'Bundle Tag Info '!$A$3,CHAR(10),'Bundle Tag Info '!H$6,CHAR(10),'Bundle Tag Info '!H$15),"") -> STOCK 2 ANG02 A.4 CUST KA/XT - GEN | ... AD10: =IF('Bundle Tag Info '!AD$15<>"",CONCATENATE('Bundle Tag Info '!$A$1," ",CHAR(10),'Bundle Tag Info '!$A$2," ",'Bundle Tag Info '!$A$3,CHAR(10),'Bundle Tag Info '!AD$6,CHAR(10),'Bundle Tag Info '!AD$15),"")
A11: =IF('Bundle Tag Info '!A$16<>"",CONCATENATE('Bundle Tag Info '!$A$1," ",CHAR(10),'Bundle Tag Info '!$A$2," ",'Bundle Tag Info '!$A$3,CHAR(10),'Bundle Tag Info '!A$6,CHAR(10),'Bundle Tag Info '!A$16),"") | B11: =IF('Bundle Tag Info '!B$16<>"",CONCATENATE('Bundle Tag Info '!$A$1," ",CHAR(10),'Bundle Tag Info '!$A$2," ",'Bundle Tag Info '!$A$3,CHAR(10),'Bundle Tag Info '!B$6,CHAR(10),'Bundle Tag Info '!B$16),"") | C11: =IF('Bundle Tag Info '!C$16<>"",CONCATENATE('Bundle Tag Info '!$A$1," ",CHAR(10),'Bundle Tag Info '!$A$2," ",'Bundle Tag Info '!$A$3,CHAR(10),'Bundle Tag Info '!C$6,CHAR(10),'Bundle Tag Info '!C$16),"") -> STOCK 2 ANG02 A.4 DOOR OPR SH0470 | D11: =IF('Bundle Tag Info '!D$16<>"",CONCATENATE('Bundle Tag Info '!$A$1," ",CHAR(10),'Bundle Tag Info '!$A$2," ",'Bundle Tag Info '!$A$3,CHAR(10),'Bundle Tag Info '!D$6,CHAR(10),'Bundle Tag Info '!D$16),"") | E11: =IF('Bundle Tag Info '!E$16<>"",CONCATENATE('Bundle Tag Info '!$A$1," ",CHAR(10),'Bundle Tag Info '!$A$2," ",'Bundle Tag Info '!$A$3,CHAR(10),'Bundle Tag Info '!E$6,CHAR(10),'Bundle Tag Info '!E$16),"") -> STOCK 2 ANG02 A.4 CTRL 2 XT/FU | F11: =IF('Bundle Tag Info '!F$16<>"",CONCATENATE('Bundle Tag Info '!$A$1," ",CHAR(10),'Bundle Tag Info '!$A$2," ",'Bundle Tag Info '!$A$3,CHAR(10),'Bundle Tag Info '!F$6,CHAR(10),'Bundle Tag Info '!F$16),"") | G11: =IF('Bundle Tag Info '!G$16<>"",CONCATENATE('Bundle Tag Info '!$A$1," ",CHAR(10),'Bundle Tag Info '!$A$2," ",'Bundle Tag Info '!$A$3,CHAR(10),'Bundle Tag Info '!G$6,CHAR(10),'Bundle Tag Info '!G$16),"") | H11: =IF('Bundle Tag Info '!H$16<>"",CONCATENATE('Bundle Tag Info '!$A$1," ",CHAR(10),'Bundle Tag Info '!$A$2," ",'Bundle Tag Info '!$A$3,CHAR(10),'Bundle Tag Info '!H$6,CHAR(10),'Bundle Tag Info '!H$16),"") | ... AD11: =IF('Bundle Tag Info '!AD$16<>"",CONCATENATE('Bundle Tag Info '!$A$1," ",CHAR(10),'Bundle Tag Info '!$A$2," ",'Bundle Tag Info '!$A$3,CHAR(10),'Bundle Tag Info '!AD$6,CHAR(10),'Bundle Tag Info '!AD$16),"")
A12: =IF('Bundle Tag Info '!A$17<>"",CONCATENATE('Bundle Tag Info '!$A$1," ",CHAR(10),'Bundle Tag Info '!$A$2," ",'Bundle Tag Info '!$A$3,CHAR(10),'Bundle Tag Info '!A$6,CHAR(10),'Bundle Tag Info '!A$17),"") | B12: =IF('Bundle Tag Info '!B$17<>"",CONCATENATE('Bundle Tag Info '!$A$1," ",CHAR(10),'Bundle Tag Info '!$A$2," ",'Bundle Tag Info '!$A$3,CHAR(10),'Bundle Tag Info '!B$6,CHAR(10),'Bundle Tag Info '!B$17),"") | C12: =IF('Bundle Tag Info '!C$17<>"",CONCATENATE('Bundle Tag Info '!$A$1," ",CHAR(10),'Bundle Tag Info '!$A$2," ",'Bundle Tag Info '!$A$3,CHAR(10),'Bundle Tag Info '!C$6,CHAR(10),'Bundle Tag Info '!C$17),"") -> STOCK 2 ANG02 A.4 DOOR OPR SH0471 | D12: =IF('Bundle Tag Info '!D$17<>"",CONCATENATE('Bundle Tag Info '!$A$1," ",CHAR(10),'Bundle Tag Info '!$A$2," ",'Bundle Tag Info '!$A$3,CHAR(10),'Bundle Tag Info '!D$6,CHAR(10),'Bundle Tag Info '!D$17),"") | E12: =IF('Bundle Tag Info '!E$17<>"",CONCATENATE('Bundle Tag Info '!$A$1," ",CHAR(10),'Bundle Tag Info '!$A$2," ",'Bundle Tag Info '!$A$3,CHAR(10),'Bundle Tag Info '!E$6,CHAR(10),'Bundle Tag Info '!E$17),"") -> STOCK 2 ANG02 A.4 CTRL 2 KA/KT - CTRL1 | F12: =IF('Bundle Tag Info '!F$17<>"",CONCATENATE('Bundle Tag Info '!$A$1," ",CHAR(10),'Bundle Tag Info '!$A$2," ",'Bundle Tag Info '!$A$3,CHAR(10),'Bundle Tag Info '!F$6,CHAR(10),'Bundle Tag Info '!F$17),"") | G12: =IF('Bundle Tag Info '!G$17<>"",CONCATENATE('Bundle Tag Info '!$A$1," ",CHAR(10),'Bundle Tag Info '!$A$2," ",'Bundle Tag Info '!$A$3,CHAR(10),'Bundle Tag Info '!G$6,CHAR(10),'Bundle Tag Info '!G$17),"") | H12: =IF('Bundle Tag Info '!H$17<>"",CONCATENATE('Bundle Tag Info '!$A$1," ",CHAR(10),'Bundle Tag Info '!$A$2," ",'Bundle Tag Info '!$A$3,CHAR(10),'Bundle Tag Info '!H$6,CHAR(10),'Bundle Tag Info '!H$17),"") | ... AD12: =IF('Bundle Tag Info '!AD$17<>"",CONCATENATE('Bundle Tag Info '!$A$1," ",CHAR(10),'Bundle Tag Info '!$A$2," ",'Bundle Tag Info '!$A$3,CHAR(10),'Bundle Tag Info '!AD$6,CHAR(10),'Bundle Tag Info '!AD$17),"")
A13: =IF('Bundle Tag Info '!A$18<>"",CONCATENATE('Bundle Tag Info '!$A$1," ",CHAR(10),'Bundle Tag Info '!$A$2," ",'Bundle Tag Info '!$A$3,CHAR(10),'Bundle Tag Info '!A$6,CHAR(10),'Bundle Tag Info '!A$18),"") | B13: =IF('Bundle Tag Info '!B$18<>"",CONCATENATE('Bundle Tag Info '!$A$1," ",CHAR(10),'Bundle Tag Info '!$A$2," ",'Bundle Tag Info '!$A$3,CHAR(10),'Bundle Tag Info '!B$6,CHAR(10),'Bundle Tag Info '!B$18),"") | C13: =IF('Bundle Tag Info '!C$18<>"",CONCATENATE('Bundle Tag Info '!$A$1," ",CHAR(10),'Bundle Tag Info '!$A$2," ",'Bundle Tag Info '!$A$3,CHAR(10),'Bundle Tag Info '!C$6,CHAR(10),'Bundle Tag Info '!C$18),"") -> STOCK 2 ANG02 A.4 DOOR OPR SH0472 | D13: =IF('Bundle Tag Info '!D$18<>"",CONCATENATE('Bundle Tag Info '!$A$1," ",CHAR(10),'Bundle Tag Info '!$A$2," ",'Bundle Tag Info '!$A$3,CHAR(10),'Bundle Tag Info '!D$6,CHAR(10),'Bundle Tag Info '!D$18),"") | E13: =IF('Bundle Tag Info '!E$18<>"",CONCATENATE('Bundle Tag Info '!$A$1," ",CHAR(10),'Bundle Tag Info '!$A$2," ",'Bundle Tag Info '!$A$3,CHAR(10),'Bundle Tag Info '!E$6,CHAR(10),'Bundle Tag Info '!E$18),"") -> STOCK 2 ANG02 A.4 CTRL 2 XT - CTRL1 | F13: =IF('Bundle Tag Info '!F$18<>"",CONCATENATE('Bundle Tag Info '!$A$1," ",CHAR(10),'Bundle Tag Info '!$A$2," ",'Bundle Tag Info '!$A$3,CHAR(10),'Bundle Tag Info '!F$6,CHAR(10),'Bundle Tag Info '!F$18),"") | G13: =IF('Bundle Tag Info '!G$18<>"",CONCATENATE('Bundle Tag Info '!$A$1," ",CHAR(10),'Bundle Tag Info '!$A$2," ",'Bundle Tag Info '!$A$3,CHAR(10),'Bundle Tag Info '!G$6,CHAR(10),'Bundle Tag Info '!G$18),"") | H13: =IF('Bundle Tag Info '!H$18<>"",CONCATENATE('Bundle Tag Info '!$A$1," ",CHAR(10),'Bundle Tag Info '!$A$2," ",'Bundle Tag Info '!$A$3,CHAR(10),'Bundle Tag Info '!H$6,CHAR(10),'Bundle Tag Info '!H$18),"") | ... AD13: =IF('Bundle Tag Info '!AD$18<>"",CONCATENATE('Bundle Tag Info '!$A$1," ",CHAR(10),'Bundle Tag Info '!$A$2," ",'Bundle Tag Info '!$A$3,CHAR(10),'Bundle Tag Info '!AD$6,CHAR(10),'Bundle Tag Info '!AD$18),"")
A14: =IF('Bundle Tag Info '!A$19<>"",CONCATENATE('Bundle Tag Info '!$A$1," ",CHAR(10),'Bundle Tag Info '!$A$2," ",'Bundle Tag Info '!$A$3,CHAR(10),'Bundle Tag Info '!A$6,CHAR(10),'Bundle Tag Info '!A$19),"") | B14: =IF('Bundle Tag Info '!B$19<>"",CONCATENATE('Bundle Tag Info '!$A$1," ",CHAR(10),'Bundle Tag Info '!$A$2," ",'Bundle Tag Info '!$A$3,CHAR(10),'Bundle Tag Info '!B$6,CHAR(10),'Bundle Tag Info '!B$19),"") | C14: =IF('Bundle Tag Info '!C$19<>"",CONCATENATE('Bundle Tag Info '!$A$1," ",CHAR(10),'Bundle Tag Info '!$A$2," ",'Bundle Tag Info '!$A$3,CHAR(10),'Bundle Tag Info '!C$6,CHAR(10),'Bundle Tag Info '!C$19),"") | D14: =IF('Bundle Tag Info '!D$19<>"",CONCATENATE('Bundle Tag Info '!$A$1," ",CHAR(10),'Bundle Tag Info '!$A$2," ",'Bundle Tag Info '!$A$3,CHAR(10),'Bundle Tag Info '!D$6,CHAR(10),'Bundle Tag Info '!D$19),"") | E14: =IF('Bundle Tag Info '!E$19<>"",CONCATENATE('Bundle Tag Info '!$A$1," ",CHAR(10),'Bundle Tag Info '!$A$2," ",'Bundle Tag Info '!$A$3,CHAR(10),'Bundle Tag Info '!E$6,CHAR(10),'Bundle Tag Info '!E$19),"") -> STOCK 2 ANG02 A.4 CTRL 2 AF - CUST | F14: =IF('Bundle Tag Info '!F$19<>"",CONCATENATE('Bundle Tag Info '!$A$1," ",CHAR(10),'Bundle Tag Info '!$A$2," ",'Bundle Tag Info '!$A$3,CHAR(10),'Bundle Tag Info '!F$6,CHAR(10),'Bundle Tag Info '!F$19),"") | G14: =IF('Bundle Tag Info '!G$19<>"",CONCATENATE('Bundle Tag Info '!$A$1," ",CHAR(10),'Bundle Tag Info '!$A$2," ",'Bundle Tag Info '!$A$3,CHAR(10),'Bundle Tag Info '!G$6,CHAR(10),'Bundle Tag Info '!G$19),"") | H14: =IF('Bundle Tag Info '!H$19<>"",CONCATENATE('Bundle Tag Info '!$A$1," ",CHAR(10),'Bundle Tag Info '!$A$2," ",'Bundle Tag Info '!$A$3,CHAR(10),'Bundle Tag Info '!H$6,CHAR(10),'Bundle Tag Info '!H$19),"") | ... AD14: =IF('Bundle Tag Info '!AD$19<>"",CONCATENATE('Bundle Tag Info '!$A$1," ",CHAR(10),'Bundle Tag Info '!$A$2," ",'Bundle Tag Info '!$A$3,CHAR(10),'Bundle Tag Info '!AD$6,CHAR(10),'Bundle Tag Info '!AD$19),"")
A15: =IF('Bundle Tag Info '!A$20<>"",CONCATENATE('Bundle Tag Info '!$A$1," ",CHAR(10),'Bundle Tag Info '!$A$2," ",'Bundle Tag Info '!$A$3,CHAR(10),'Bundle Tag Info '!A$6,CHAR(10),'Bundle Tag Info '!A$20),"") | B15: =IF('Bundle Tag Info '!B$20<>"",CONCATENATE('Bundle Tag Info '!$A$1," ",CHAR(10),'Bundle Tag Info '!$A$2," ",'Bundle Tag Info '!$A$3,CHAR(10),'Bundle Tag Info '!B$6,CHAR(10),'Bundle Tag Info '!B$20),"") | C15: =IF('Bundle Tag Info '!C$20<>"",CONCATENATE('Bundle Tag Info '!$A$1," ",CHAR(10),'Bundle Tag Info '!$A$2," ",'Bundle Tag Info '!$A$3,CHAR(10),'Bundle Tag Info '!C$6,CHAR(10),'Bundle Tag Info '!C$20),"") | D15: =IF('Bundle Tag Info '!D$20<>"",CONCATENATE('Bundle Tag Info '!$A$1," ",CHAR(10),'Bundle Tag Info '!$A$2," ",'Bundle Tag Info '!$A$3,CHAR(10),'Bundle Tag Info '!D$6,CHAR(10),'Bundle Tag Info '!D$20),"") | E15: =IF('Bundle Tag Info '!E$20<>"",CONCATENATE('Bundle Tag Info '!$A$1," ",CHAR(10),'Bundle Tag Info '!$A$2," ",'Bundle Tag Info '!$A$3,CHAR(10),'Bundle Tag Info '!E$6,CHAR(10),'Bundle Tag Info '!E$20),"") -> STOCK 2 ANG02 A.4 CTRL 2 KA/XT - CUST | F15: =IF('Bundle Tag Info '!F$20<>"",CONCATENATE('Bundle Tag Info '!$A$1," ",CHAR(10),'Bundle Tag Info '!$A$2," ",'Bundle Tag Info '!$A$3,CHAR(10),'Bundle Tag Info '!F$6,CHAR(10),'Bundle Tag Info '!F$20),"") | G15: =IF('Bundle Tag Info '!G$20<>"",CONCATENATE('Bundle Tag Info '!$A$1," ",CHAR(10),'Bundle Tag Info '!$A$2," ",'Bundle Tag Info '!$A$3,CHAR(10),'Bundle Tag Info '!G$6,CHAR(10),'Bundle Tag Info '!G$20),"") | H15: =IF('Bundle Tag Info '!H$20<>"",CONCATENATE('Bundle Tag Info '!$A$1," ",CHAR(10),'Bundle Tag Info '!$A$2," ",'Bundle Tag Info '!$A$3,CHAR(10),'Bundle Tag Info '!H$6,CHAR(10),'Bundle Tag Info '!H$20),"") | ... AD15: =IF('Bundle Tag Info '!AD$20<>"",CONCATENATE('Bundle Tag Info '!$A$1," ",CHAR(10),'Bundle Tag Info '!$A$2," ",'Bundle Tag Info '!$A$3,CHAR(10),'Bundle Tag Info '!AD$6,CHAR(10),'Bundle Tag Info '!AD$20),"")
