Workbook

Sheet JB70_S
A1: JB70
A3: Project # | B3: 4K932
A4: Project Name | B4: NORTHERN NATURAL GAS COMPANY
A5: Revision | B5: B.2
A7: Controls DE | B7: S. LOPEZ
A8: Phone:
A9: Controls ME | B9: H. MEDRANO
A10: Phone:
A12: From | G12: To
A13: Device ID | B13: Wire No. | C13: Wire ID | D13: Gauge/Size | E13: Length | F13: Device ID | G13: Location | H13: Bundle Name
A14: SA0471:B1-13 | B14: SA0471B113 | C14: WHT | D14: 20 | E14: 220 | F14: AF0087:40 | G14: A | H14: SA0471
A15: SA0471:B1-14 | B15: SA0471B114 | C15: WHT | D15: 20 | E15: 220 | F15: AF0087:08 | G15: A
A16: SA0471:B2-13 | B16: SA0471B213 | C16: WHT | D16: 20 | E16: 220 | F16: AF0087:39 | G16: A
A17: SA0471:B2-14 | B17: SA0471B214 | C17: WHT | D17: 20 | E17: 220 | F17: AF0087:07 | G17: A
A19: SA0473:11 | B19: SA047311 | C19: WHT | D19: 20 | E19: 220 | F19: AF0087:37 | G19: A | H19: SA0473
A20: SA0473:12 | B20: SA047312 | C20: WHT | D20: 20 | E20: 220 | F20: AF0087:05 | G20: A
A21: SA0473:13 | B21: SA047313 | C21: WHT | D21: 20 | E21: 220 | F21: AF0087:38 | G21: A
A22: SA0473:14 | B22: SA047314 | C22: WHT | D22: 20 | E22: 220 | F22: AF0087:06 | G22: A
A24: SA0474:B1-13 | B24: SA0474B113 | C24: WHT | D24: 20 | E24: 220 | F24: AF0087:45 | G24: A | H24: SA0474
A25: SA0474:B1-14 | B25: SA0474B114 | C25: WHT | D25: 20 | E25: 220 | F25: AF0087:13 | G25: A
A26: SA0474:B2-13 | B26: SA0474B213 | C26: WHT | D26: 20 | E26: 220 | F26: AF0087:44 | G26: A
A27: SA0474:B2-14 | B27: SA0474B214 | C27: WHT | D27: 20 | E27: 220 | F27: AF0087:12 | G27: A
A29: SB0471:11 | B29: SB047111 | C29: WHT | D29: 20 | E29: 220 | F29: AF0087:34 | G29: A | H29: SB0471
A30: SB0471:12 | B30: SB047112 | C30: WHT | D30: 20 | E30: 220 | F30: AF0087:02 | G30: A
A32: SB0472:B1-12 | B32: ESTOPA | C32: WHT | D32: 20 | E32: 180 | F32: XT0111:20 | G32: JB70 R RAIL | H32: SB0472
A33: SB0472:B1-11 | B33: ESTOPB | C33: WHT | D33: 20 | E33: 180 | F33: XT0111:19 | G33: JB70 R RAIL
A34: SB0472:B2-11 | B34: SB0472B211 | C34: WHT | D34: 20 | E34: 220 | F34: AF0081:36 | G34: A
A35: SB0472:B2-12 | B35: SB0472B212 | C35: WHT | D35: 20 | E35: 220 | F35: AF0081:04 | G35: A
A37: SB0473:13 | B37: SB047313 | C37: WHT | D37: 20 | E37: 220 | F37: AF0087:35 | G37: A | H37: SB0473
A38: SB0473:14 | B38: SB047314 | C38: WHT | D38: 20 | E38: 220 | F38: AF0087:03 | G38: A
A40: SB0474:13 | B40: SB047413 | C40: WHT | D40: 20 | E40: 220 | F40: AF0087:36 | G40: A | H40: SB0474
A41: SB0474:14 | B41: SB047414 | C41: WHT | D41: 20 | E41: 220 | F41: AF0087:04 | G41: A
A43: SH0470:11 | B43: SH047011 | C43: WHT | D43: 20 | E43: 180 | F43: XT0111:7 | G43: JB70 R RAIL | H43: SH0470
A44: SH0470:12 | B44: SH047012 | C44: WHT | D44: 20 | E44: 180 | F44: XT0111:8 | G44: JB70 R RAIL
A45: SH0470:13 | B45: SH047013 | C45: WHT | D45: 20 | E45: 180 | F45: XT0111:9 | G45: JB70 R RAIL
A46: SH0470:14 | B46: SH047014 | C46: WHT | D46: 20 | E46: 180 | F46: XT0111:10 | G46: JB70 R RAIL
A47: SH0470:X1 | B47: SH0470X1 | C47: WHT | D47: 20 | E47: 180 | F47: XT0111:12 | G47: JB70 R RAIL
A48: SH0470:X2 | B48: SH0470X2 | C48: WHT | D48: 20 | E48: 180 | F48: XT0111:11 | G48: JB70 R RAIL
A50: SH0471:11 | B50: SH047111 | C50: WHT | D50: 20 | E50: 180 | F50: XT0111:1 | G50: JB70 R RAIL | H50: SH0471
A51: SH0471:12 | B51: SH047112 | C51: WHT | D51: 20 | E51: 180 | F51: XT0111:2 | G51: JB70 R RAIL
...

Sheet JB70 RIGHT RAIL_S
A1: JB70 R RAIL
A2: TURBINE CONTROL BOX, RIGHT RAIL
A3: Project # | B3: 4K932
A4: Project Name | B4: NORTHERN NATURAL GAS COMPANY
A5: Revision | B5: B.2
A7: Controls DE | B7: S. LOPEZ
A8: Phone:
A9: Controls ME | B9: H. MEDRANO
A10: Phone:
A12: From | G12: To
A13: Device ID | B13: Wire No. | C13: Wire ID | D13: Gauge/Size | E13: Length | F13: Device ID | G13: Location | H13: Bundle Name
A15: XT0111:22 | B15: -0V | C15: WHT | D15: 16 | E15: 60 | F15: UJ0231:24V(-) | G15: JB70 R RAIL | H15: FU/XT
A17: FU1101:LI | B17: FU0131 | C17: WHT | D17: 14 | E17: 80 | F17: XT0111:21 | G17: JB70 R RAIL
A18: FU1101:LD | B18: FU1101 | C18: WHT | D18: 14 | E18: 80 | F18: UJ0231:24V(+) | G18: JB70 R RAIL
A20: XT0111:20 | B20: ESTOPA | C20: WHT | D20: 20 | E20: 160 | F20: XT0089:4 | G20: A | H20: XT
A21: XT0111:19 | B21: ESTOPB | C21: WHT | D21: 20 | E21: 160 | F21: XT0089:3 | G21: A
A22: XT0111:15 | B22: FU0139 | C22: WHT | D22: 20 | E22: 160 | F22: XT0081:6 | G22: A
A23: XT0111:24 | B23: HA047201 | C23: WHT | D23: 20 | E23: 160 | F23: AF0092:28 | G23: A
A24: XT0111:23 | B24: HA047202 | C24: WHT | D24: 20 | E24: 160 | F24: AF0092:12 | G24: A
A25: XT0111:16 | B25: KA0241A1 | C25: WHT | D25: 20 | E25: 160 | F25: XT0081:7 | G25: A
A26: XT0111:7 | B26: SH047011 | C26: WHT | D26: 20 | E26: 160 | F26: AF0087:33 | G26: A
A27: XT0111:8 | B27: SH047012 | C27: WHT | D27: 20 | E27: 160 | F27: AF0087:01 | G27: A
A28: XT0111:12 | B28: SH0470X1 | C28: WHT | D28: 20 | E28: 160 | F28: AF0093:22 | G28: A
A29: XT0111:11 | B29: SH0470X2 | C29: WHT | D29: 20 | E29: 160 | F29: AF0093:06 | G29: A
A30: XT0111:3 | B30: SH047113 | C30: WHT | D30: 20 | E30: 160 | F30: AF0087:32 | G30: A
A31: XT0111:4 | B31: SH047114 | C31: WHT | D31: 20 | E31: 160 | F31: AF0087:00 | G31: A
A32: XT0111:6 | B32: SH0471X1 | C32: WHT | D32: 20 | E32: 160 | F32: AF0093:31 | G32: A
... A38: XT0111:21 | B38: FU0131 | C38: WHT | D38: 14 | E38: 160 | F38: XT0002:6 | G38: A
A40: BA0001:V1(-) | B40: -0V | C40: WHT | D40: 16 | E40: 100 | F40: XT0051:5 | G40: B | H40: BA-B
A41: BA0002:V1(-) | B41: -0V | C41: WHT | D41: 16 | E41: 100 | F41: XT0051:6 | G41: B
A42: BA0009:V1(-) | B42: -0V | C42: WHT | D42: 16 | E42: 100 | F42: XT0051:7 | G42: B
A43: BA0001:V1(+) | B43: FU0021 | C43: WHT | D43: 16 | E43: 100 | F43: FU0021:LD | G43: B
A44: BA0002:V1(+) | B44: FU0022 | C44: WHT | D44: 16 | E44: 100 | F44: FU0022:LD | G44: B
A45: BA0009:V1(+) | B45: FU0029 | C45: WHT | D45: 16 | E45: 100 | F45: FU0029:LD | G45: B
A47: XT0111:17 | B47: SH0472X2 | C47: WHT | D47: 20 | E47: 120 | F47: KA0240:21 | G47: B | H47: XT-B

Sheet PLC_S
A1: PLC
A2: PLC PANEL,JB70
A3: Project # | B3: 4K932
A4: Project Name | B4: NORTHERN NATURAL GAS COMPANY
A5: Revision | B5: B.2
A7: Controls DE | B7: S. LOPEZ
A8: Phone:
A9: Controls ME | B9: H. MEDRANO
A10: Phone:
A12: From | G12: To
A13: Device ID | B13: Wire No. | C13: Wire ID | D13: Gauge/Size | E13: Length | F13: Device ID | G13: Location | H13: Bundle Name
A14: FU0680:LD | B14: AT0680POS | C14: WHT | D14: 14 | E14: 60 | F14: XT0680:1 | G14: PLC
A16: UV0600:(-) | B16: -0V | C16: WHT | D16: 14 | E16: 80 | F16: XT0003:4 | G16: A | H16: UV-A
A17: UV0600:(+) | B17: FU0010 | C17: WHT | D17: 14 | E17: 80 | F17: FU0010:LD | G17: A
A19: XT0680:2 | B19: -0V | C19: WHT | D19: 14 | E19: 80 | F19: XT0051:8 | G19: B | H19: FU/XT-A
A20: FU0680:LI | B20: FU0131 | C20: WHT | D20: 14 | E20: 80 | F20: XT0051:4 | G20: B

Sheet A_S
A1: PANEL A
A2: CONTROL A,JB70
A3: Project # | B3: 4K932
A4: Project Name | B4: NORTHERN NATURAL GAS COMPANY
A5: Revision | B5: B.2
A7: Controls DE | B7: S. LOPEZ
A8: Phone:
A9: Controls ME | B9: H. MEDRANO
A10: Phone:
A12: From | G12: To
A13: Device ID | B13: Wire No. | C13: Wire ID | D13: Gauge/Size | E13: Length | F13: Device ID | G13: Location | H13: Bundle Name
A14: AU0080:COM | B14: -0V | C14: WHT | D14: 16 | E14: 60 | F14: XT0080:1 | G14: A
A15: AU0080:V+ | B15: FU0081 | C15: WHT | D15: 16 | E15: 60 | F15: FU0081:LD | G15: A
A17: AF0094:01 | B17: -0V | C17: WHT | D17: 20 | E17: 60 | F17: XT0082:6 | G17: A | H17: AF090s
A18: AF0094:03 | B18: -0V | C18: WHT | D18: 20 | E18: 60 | F18: XT0082:6 | G18: A
A19: AF0094:05 | B19: -0V | C19: WHT | D19: 20 | E19: 60 | F19: XT0082:7 | G19: A
A20: AF0094:07 | B20: -0V | C20: WHT | D20: 20 | E20: 60 | F20: XT0082:7 | G20: A
A22: AF0092:COM | B22: -0V | C22: WHT | D22: 16 | E22: 60 | F22: XT0080:2 | G22: A
A23: AF0093:COM | B23: -0V | C23: WHT | D23: 16 | E23: 60 | F23: XT0080:3 | G23: A
A24: AF0095:COM | B24: -0V | C24: WHT | D24: 16 | E24: 80 | F24: XT0080:4 | G24: A
A25: AU0090:COM | B25: -0V | C25: WHT | D25: 16 | E25: 60 | F25: XT0080:2 | G25: A
A26: AF0091:COM | B26: AF0091N | C26: WHT | D26: 16 | E26: 60 | F26: AF0094:COM | G26: A
A27: AF0091:V+ | B27: AF0091P | C27: WHT | D27: 16 | E27: 60 | F27: AF0094:V+ | G27: A
A28: AU0090:V+ | B28: FU0090 | C28: WHT | D28: 16 | E28: 60 | F28: FU0090:LD | G28: A
A29: AF0092:V+ | B29: FU0091 | C29: WHT | D29: 16 | E29: 60 | F29: FU0091:LD | G29: A
A30: AF0093:V+ | B30: FU0092 | C30: WHT | D30: 16 | E30: 60 | F30: FU0092:LD | G30: A
A32: FU0139:LD | B32: FU0139 | C32: WHT | D32: 16 | E32: 60 | F32: XT0081:1 | G32: A | H32: FU
A33: FU0340:LD | B33: FU0340 | C33: WHT | D33: 16 | E33: 60 | F33: XT0089:17 | G33: A
A34: FU0389:LD | B34: FU0389 | C34: WHT | D34: 16 | E34: 60 | F34: XT0089:21 | G34: A
A36: FU0081:LI | B36: FU0080 | C36: WHT | D36: 14 | E36: 60 | F36: FU0080:LD | G36: A
A37: FU0081:LI | B37: FU0080 | C37: WHT | D37: 14 | E37: 60 | F37: FU0090:LI | G37: A
A38: FU0010:LI | B38: FU0131 | C38: WHT | D38: 14 | E38: 80 | F38: XT0002:4 | G38: A
A40: FU0137:LI | B40: FU0131 | C40: WHT | D40: 12 | E40: 80 | F40: XT0002:2 | G40: A
A41: FU0080:LI | B41: FU0137 | C41: WHT | D41: 12 | E41: 60 | F41: FU0137:LD | G41: A
A43: KA0910:A1 | B43: -009200 | C43: WHT | D43: 20 | E43: 60 | F43: AF0092:00 | G43: A | H43: KA A1
A44: KA0130:A1 | B44: KA0130A1 | C44: WHT | D44: 20 | E44: 60 | F44: AF0081:35 | G44: A
A45: KA0130:A1 | B45: KA0130A1 | C45: WHT | D45: 20 | E45: 60 | F45: KA0130:11 | G45: A
A46: KA0234:A1 | B46: KA0131A1 | C46: WHT | D46: 20 | E46: 60 | F46: XT0089:8 | G46: A
A47: KA0133:A1 | B47: KA0133A1 | C47: WHT | D47: 20 | E47: 100 | F47: AF0092:02 | G47: A
A48: KA0134:A1 | B48: KA0134A1 | C48: WHT | D48: 20 | E48: 100 | F48: AF0091:12 | G48: A
...

Sheet B_S
A1: PANEL B
A2: CONTROL B,JB70
A3: Project # | B3: 4K932
A4: Project Name | B4: NORTHERN NATURAL GAS COMPANY
A5: Revision | B5: B.2
A7: Controls DE | B7: S. LOPEZ
A8: Phone:
A9: Controls ME | B9: H. MEDRANO
A10: Phone:
A12: From | G12: To
A13: Device ID | B13: Wire No. | C13: Wire ID | D13: Gauge/Size | E13: Length | F13: Device ID | G13: Location | H13: Bundle Name
A14: AU0060:COM | B14: -0V | C14: WHT | D14: 16 | E14: 80 | F14: XT0060:2 | G14: B
A15: AF0066:COM | B15: AF0066N | C15: WHT | D15: 16 | E15: 60 | F15: AF0068:COM | G15: B
A16: AF0066:V+ | B16: AF0066P | C16: WHT | D16: 16 | E16: 60 | F16: AF0068:V+ | G16: B
A17: AF0063:COM | B17: AU0060N | C17: WHT | D17: 16 | E17: 60 | F17: AU0060:COM | G17: B
A18: AF0063:V+ | B18: AU0060P | C18: WHT | D18: 16 | E18: 60 | F18: AU0060:V+ | G18: B
A19: AU0060:V+ | B19: FU0061 | C19: WHT | D19: 16 | E19: 80 | F19: FU0061:LD | G19: B
A20: AF0061:V+ | B20: FU0062 | C20: WHT | D20: 16 | E20: 80 | F20: FU0062:LD | G20: B
A21: AF0062:V+ | B21: FU0063 | C21: WHT | D21: 16 | E21: 80 | F21: FU0063:LD | G21: B
A22: AF0067:V+ | B22: FU0064 | C22: WHT | D22: 16 | E22: 60 | F22: FU0064:LD | G22: B
A24: AF0076:12 | B24: -007612 | C24: WHT | D24: 20 | E24: 120 | F24: XT0237:1 B2 | G24: B | H24: AF070s
A26: AU0070:COM | B26: -0V | C26: WHT | D26: 16 | E26: 100 | F26: XT0060:4 | G26: B
A27: AF0075:COM | B27: AF0075N | C27: WHT | D27: 16 | E27: 60 | F27: AF0077:COM | G27: B
A28: AF0075:V+ | B28: AF0075P | C28: WHT | D28: 16 | E28: 60 | F28: AF0077:V+ | G28: B
A29: AU0070:V+ | B29: FU0070 | C29: WHT | D29: 16 | E29: 60 | F29: FU0070:LD | G29: B
A30: AF0076:V+ | B30: FU0076 | C30: WHT | D30: 16 | E30: 80 | F30: FU0076:LD | G30: B
A32: AF0410:53 | B32: -0V | C32: WHT | D32: 16 | E32: 60 | F32: XT0401:2 | G32: B | H32: 1444s
A33: AF0410:54 | B33: -0V | C33: WHT | D33: 16 | E33: 60 | F33: AF0420:53 | G33: B
A34: AF0420:54 | B34: -0V | C34: WHT | D34: 16 | E34: 60 | F34: AF0430:53 | G34: B
A35: AF0430:54 | B35: -0V | C35: WHT | D35: 16 | E35: 60 | F35: AF0450:53 | G35: B
A36: AF0410:55 | B36: FU0410 | C36: WHT | D36: 16 | E36: 60 | F36: FU0410:LD | G36: B
A37: AF0410:56 | B37: FU0410 | C37: WHT | D37: 16 | E37: 60 | F37: AF0420:55 | G37: B
A38: AF0420:56 | B38: FU0410 | C38: WHT | D38: 16 | E38: 60 | F38: AF0430:55 | G38: B
A39: AF0430:56 | B39: FU0410 | C39: WHT | D39: 16 | E39: 60 | F39: AF0450:55 | G39: B
A41: FU0021:LI | B41: FU0131 | C41: WHT | D41: 16 | E41: 60 | F41: XT0051:1 | G41: B | H41: FU/XT
A42: FU0022:LI | B42: FU0131 | C42: WHT | D42: 16 | E42: 60 | F42: XT0051:2 | G42: B
A43: FU0029:LI | B43: FU0131 | C43: WHT | D43: 16 | E43: 60 | F43: XT0051:3 | G43: B
A45: XT0060:1 | B45: -0V | C45: WHT | D45: 14 | E45: 60 | F45: XT0062:2 | G45: B
A46: FU0061:LI | B46: FU0060 | C46: WHT | D46: 14 | E46: 60 | F46: FU0060:LD | G46: B
A47: FU0064:LI | B47: FU0060 | C47: WHT | D47: 14 | E47: 60 | F47: FU0070:LI | G47: B
...

Sheet MEDIA CONVERTER_S
A1: MEDIA CONVERTER
A2: MCC CABINET (ASSY1100)
A3: Project # | B3: 4K932
A4: Project Name | B4: NORTHERN NATURAL GAS COMPANY
A5: Revision | B5: B.2
A7: Controls DE | B7: S. LOPEZ
A8: Phone:
A9: Controls ME | B9: H. MEDRANO
A10: Phone:
A12: From | G12: To
A13: Device ID | B13: Wire No. | C13: Wire ID | D13: Gauge/Size | E13: Length | F13: Device ID | G13: Location | H13: Bundle Name
A14: BA0010:V1(+) | B14: FU1125 | C14: WHT | D14: 16 | E14: 60 | F14: FU1125:LD | G14: MEDIA CONVERTER

Sheet PWR_S
A1: JB130
A2: POWER SUPPLY BOX (JB130)
A3: Project # | B3: 4K932
A4: Project Name | B4: NORTHERN NATURAL GAS COMPANY
A5: Revision | B5: B.2
A7: Controls DE | B7: S. LOPEZ
A8: Phone:
A9: Controls ME | B9: H. MEDRANO
A10: Phone:
A12: From | G12: To
A13: Device ID | B13: Wire No. | C13: Wire ID | D13: Gauge/Size | E13: Length | F13: Device ID | G13: Location | H13: Bundle Name
A14: UJ0031:- | B14: UJ0031N | C14: WHT | D14: 12 | E14: 60 | F14: XT0011:2 | G14: PWR
A15: UJ0031:+ | B15: UJ0031P | C15: WHT | D15: 12 | E15: 60 | F15: FU0019:LD | G15: PWR
A17: UJ0131:- | B17: -521NEG | C17: WHT | D17: 12 | E17: 80 | F17: XT0011:1 | G17: PWR | H17: UJ0131
A18: UJ0131:+ | B18: UJ0131P | C18: WHT | D18: 12 | E18: 60 | F18: FU0011:LD | G18: PWR

Sheet JB73 LEFT RAIL_S
A1: RAIL,LEFT,JB73
A2: 0
A3: Project # | B3: 4K932
A4: Project Name | B4: NORTHERN NATURAL GAS COMPANY
A5: Revision | B5: B.2
A7: Controls DE | B7: S. LOPEZ
A8: Phone:
A9: Controls ME | B9: H. MEDRANO
A10: Phone:
A12: From | G12: To
A13: Device ID | B13: Wire No. | C13: Wire ID | D13: Gauge/Size | E13: Length | F13: Device ID | G13: Location | H13: Bundle Name
A14: XT0121:4 | B14: -0V | C14: WHT | D14: 14 | E14: 60 | F14: XT0121:6 | G14: JB73 L RAIL
A15: XT0121:2 | B15: FU0122 | C15: WHT | D15: 14 | E15: 60 | F15: XT0121:5 | G15: JB73 L RAIL
A17: FU0332:LD | B17: FU0332 | C17: WHT | D17: 12 | E17: 60 | F17: XT0335:1 | G17: JB73 L RAIL
A18: FU2108:LI | B18: FU0332 | C18: WHT | D18: 12 | E18: 60 | F18: XT0335:3 | G18: JB73 L RAIL
A20: FU1212:LD | B20: FU1212 | C20: WHT | D20: 16 | E20: 180 | F20: BA1212:POS | G20: BOP | H20: FU/XT-BOP
A21: XT0007:2 | B21: UJ0231N2 | C21: WHT | D21: 16 | E21: 180 | F21: BA1212:NEG | G21: BOP
A23: XT0336:1 | B23: -0V | C23: WHT | D23: 14 | E23: 180 | F23: XT0140:1 | G23: BOP
A25: XT0335:1 | B25: FU0332 | C25: WHT | D25: 12 | E25: 180 | F25: FU0146:LI | G25: BOP
A27: XT0121:3 | B27: -0V | C27: WHT | D27: 14 | E27: 220 | F27: XT0510:2 | G27: HPC | H27: XT-HPC
A28: XT0121:1 | B28: FU0122 | C28: WHT | D28: 14 | E28: 220 | F28: FU0510:LI | G28: HPC
A30: XT0336:2 | B30: -0V | C30: WHT | D30: 12 | E30: 220 | F30: XT0120:1 | G30: HPC
A31: XT0335:2 | B31: FU0332 | C31: WHT | D31: 12 | E31: 220 | F31: FU0122:LI | G31: HPC

Sheet BOP_S
A1: BOP
A2: BALANCE OF PLANT PANEL, JB73
A3: Project # | B3: 4K932
A4: Project Name | B4: NORTHERN NATURAL GAS COMPANY
A5: Revision | B5: B.2
A7: Controls DE | B7: S. LOPEZ
A8: Phone:
A9: Controls ME | B9: H. MEDRANO
A10: Phone:
A12: From | G12: To
A13: Device ID | B13: Wire No. | C13: Wire ID | D13: Gauge/Size | E13: Length | F13: Device ID | G13: Location | H13: Bundle Name
A14: AF0142:07 | B14: ZSC76112 | C14: WHT | D14: 20 | E14: 60 | F14: XT0572:2 | G14: BOP
A15: AF0142:06 | B15: ZSO76012 | C15: WHT | D15: 20 | E15: 60 | F15: XT0572:7 | G15: BOP
A16: AF0141:COM | B16: -0V | C16: WHT | D16: 16 | E16: 60 | F16: XT0140:2 | G16: BOP
A17: AU0140:COM | B17: -0V | C17: WHT | D17: 16 | E17: 60 | F17: XT0140:2 | G17: BOP
A18: AF0142:COM | B18: AU0140N | C18: WHT | D18: 16 | E18: 60 | F18: AU0140:COM | G18: BOP
A19: AF0142:V+ | B19: AU0140P | C19: WHT | D19: 16 | E19: 60 | F19: AU0140:V+ | G19: BOP
A20: AU0140:V+ | B20: FU0140 | C20: WHT | D20: 16 | E20: 60 | F20: FU0140:LD | G20: BOP
A21: AF0141:V+ | B21: FU0141 | C21: WHT | D21: 16 | E21: 60 | F21: FU0141:LD | G21: BOP
A22: AF0146:V+ | B22: FU0142 | C22: WHT | D22: 16 | E22: 80 | F22: FU0142:LD | G22: BOP
A24: AF0181:18 | B24: SV76232 | C24: WHT | D24: 20 | E24: 60 | F24: XT0572:10 | G24: BOP | H24: AF/AU180s
A25: AF0181:22 | B25: SV76432 | C25: WHT | D25: 20 | E25: 60 | F25: XT0572:12 | G25: BOP
A26: AF0182:05 | B26: ZSC76122 | C26: WHT | D26: 20 | E26: 80 | F26: XT0572:9 | G26: BOP
A27: AF0183:04 | B27: ZSC76212 | C27: WHT | D27: 20 | E27: 80 | F27: XT0572:4 | G27: BOP
A28: AF0182:12 | B28: ZSC76232 | C28: WHT | D28: 20 | E28: 80 | F28: XT0572:11 | G28: BOP
A29: AF0183:05 | B29: ZSC76412 | C29: WHT | D29: 20 | E29: 80 | F29: XT0572:6 | G29: BOP
A30: AF0182:08 | B30: ZSC76432 | C30: WHT | D30: 20 | E30: 80 | F30: XT0572:13 | G30: BOP
A32: AF0181:COM | B32: -0V | C32: WHT | D32: 16 | E32: 60 | F32: XT0140:4 | G32: BOP
A33: AF0184:COM | B33: -0V | C33: WHT | D33: 16 | E33: 80 | F33: XT0140:5 | G33: BOP
A34: AU0180:COM | B34: -0V | C34: WHT | D34: 16 | E34: 60 | F34: XT0140:4 | G34: BOP
A35: AF0183:COM | B35: AF0183N | C35: WHT | D35: 16 | E35: 60 | F35: AF0185:COM | G35: BOP
A36: AF0183:V+ | B36: AF0183P | C36: WHT | D36: 16 | E36: 60 | F36: AF0185:V+ | G36: BOP
A37: AF0182:COM | B37: AU0180N | C37: WHT | D37: 16 | E37: 60 | F37: AU0180:COM | G37: BOP
... A40: AF0181:V+ | B40: FU0181 | C40: WHT | D40: 16 | E40: 60 | F40: FU0181:LD | G40: BOP
A42: FU0143:LD | B42: FU0143 | C42: WHT | D42: 16 | E42: 60 | F42: XT0140:9 | G42: BOP | H42: FU
A44: FU0143:LI | B44: FU0146 | C44: WHT | D44: 14 | E44: 60 | F44: FU0180:LI | G44: BOP
A45: FU0181:LI | B45: FU0146 | C45: WHT | D45: 14 | E45: 60 | F45: FU0182:LI | G45: BOP
A47: KA0558:A1 | B47: -018406 | C47: WHT | D47: 20 | E47: 100 | F47: AF0184:06 | G47: BOP | H47: KA A1
A48: KA0560:A1 | B48: -018407 | C48: WHT | D48: 20 | E48: 100 | F48: AF0184:07 | G48: BOP
A49: KA0557:A1 | B49: -018408 | C49: WHT | D49: 20 | E49: 100 | F49: AF0184:08 | G49: BOP
...

Sheet HPC_S
A1: HPC
A2: HP COMPRESSOR PANEL,JB73
A3: Project # | B3: 4K932
A4: Project Name | B4: NORTHERN NATURAL GAS COMPANY
A5: Revision | B5: B.2
A7: Controls DE | B7: S. LOPEZ
A8: Phone:
A9: Controls ME | B9: H. MEDRANO
A10: Phone:
A12: From | G12: To
A13: Device ID | B13: Wire No. | C13: Wire ID | D13: Gauge/Size | E13: Length | F13: Device ID | G13: Location | H13: Bundle Name
A14: AF0510:55 | B14: FU0510 | C14: WHT | D14: 16 | E14: 60 | F14: FU0510:LD | G14: HPC
A15: AF0510:56 | B15: FU0510 | C15: WHT | D15: 16 | E15: 60 | F15: AF0520:55 | G15: HPC
A17: AF1207:32 | B17: PS74302 | C17: WHT | D17: 20 | E17: 80 | F17: XT0240:1 | G17: HPC | H17: AF/AU
A18: AF1207:00 | B18: PS74303 | C18: WHT | D18: 20 | E18: 80 | F18: XT0240:2 | G18: HPC
A19: AF1207:40 | B19: PS74312 | C19: WHT | D19: 20 | E19: 80 | F19: XT0240:3 | G19: HPC
A20: AF1207:08 | B20: PS74313 | C20: WHT | D20: 20 | E20: 80 | F20: XT0240:4 | G20: HPC
A22: AF1201:COM | B22: -0V | C22: WHT | D22: 16 | E22: 100 | F22: XT0120:2 | G22: HPC
A23: AU1200:COM | B23: -0V | C23: WHT | D23: 16 | E23: 100 | F23: XT0120:2 | G23: HPC
A24: AF1202:COM | B24: AF1202N | C24: WHT | D24: 16 | E24: 60 | F24: AU1200:COM | G24: HPC
A25: AF1202:V+ | B25: AF1202P | C25: WHT | D25: 16 | E25: 60 | F25: AU1200:V+ | G25: HPC
A26: AF1206:COM | B26: AF1207N | C26: WHT | D26: 16 | E26: 60 | F26: AF1207:COM | G26: HPC
A27: AF1206:V+ | B27: AF1207P | C27: WHT | D27: 16 | E27: 60 | F27: AF1207:V+ | G27: HPC
A28: AU1200:V+ | B28: FU0120 | C28: WHT | D28: 16 | E28: 100 | F28: FU0120:LD | G28: HPC
A29: AF1201:V+ | B29: FU0121 | C29: WHT | D29: 16 | E29: 100 | F29: FU0121:LD | G29: HPC
A31: KA0120:A1 | B31: KA0131A1 | C31: WHT | D31: 20 | E31: 60 | F31: XT0120:4 | G31: HPC | H31: KA A1/A2
A33: KA0120:A2 | B33: -0V | C33: WHT | D33: 20 | E33: 60 | F33: XT0120:3 | G33: HPC
A34: KA4401:A2 | B34: -120718 | C34: WHT | D34: 20 | E34: 80 | F34: AF1207:18 | G34: HPC
E35: .
A36: KA4401:14 | B36: -120702 | C36: WHT | D36: 20 | E36: 60 | F36: AF1207:02 | G36: HPC | H36: KA
A37: KA4401:11 | B37: PS44012 | C37: WHT | D37: 20 | E37: 60 | F37: AF1207:34 | G37: HPC
A38: KA4401:11 | B38: PS44012 | C38: WHT | D38: 20 | E38: 60 | F38: XT0120:5 | G38: HPC
A40: XT0120:3 | B40: -0V | C40: WHT | D40: 14 | E40: 60 | F40: XT0510:1 | G40: HPC | H40: FU/XT
A41: FU0120:LI | B41: FU0122 | C41: WHT | D41: 14 | E41: 60 | F41: FU0122:LD | G41: HPC
A42: FU0121:LI | B42: FU0122 | C42: WHT | D42: 14 | E42: 60 | F42: FU0510:LI | G42: HPC

Sheet Bundle Tag Info
A1: NNG-BUL
A2: 4K932
A3: B.2
A6: JB70 | B6: JB70 R RAIL | C6: PLC | D6: A | E6: B | F6: MED CONV | G6: PWR | H6: JB73 R RAIL | I6: BOP | J6: HPC | K6: Panel Name | L6: Panel Name | M6: Panel Name | N6: Panel Name | O6: Panel Name | P6: Panel Name | Q6: Panel Name | R6: Panel Name | S6: Panel Name | T6: Panel Name | U6: Panel Name | V6: Panel Name | W6: Panel Name | X6: Panel Name | Y6: Panel Name | Z6: Panel Name | AA6: Panel Name | AB6: Panel Name | AC6: Panel Name | AD6: Panel Name
A7: AT100 | B7: BA | C7: AT/FU | D7: AF080s | E7: AF060s | F7: BA | G7: UJ0031 | H7: FU/XT | I7: AF/AU140s | J7: 1444s
A8: SA0471 | B8: FU/XT | C8: UV-A | D8: AF090s | E8: AF070s | G8: UJ0131 | H8: FU/XT-BOP | I8: AF/AU180s | J8: AF/AU
A9: SA0473 | B9: XT | C9: FU/XT-A | D9: FU | E9: 1444s | H9: XT-HPC | I9: FU | J9: KA A1/A2
A10: SA0474 | B10: BA-B | D10: KA A1 | E10: FU/XT | I10: KA A1 | J10: KA
A11: SB0471 | B11: XT-B | D11: KA A2 | E11: KA A1 | I11: KA A2 | J11: FU/XT
A12: SB0472 | D12: KA | E12: KA A2 | I12: KA
A13: SB0473 | D13: KT L/S | E13: KA | I13: KT L/S
A14: SB0474 | D14: KT R/S | I14: KT R/S
A15: SH0470 | D15: UA | I15: XT
A16: SH0471 | D16: XT | I16: KA-HPC
A17: SH0472 | D17: AF-B | I17: KT-HPC
D18: KA A1-B | I18: XT-HPC
D19: KA-B
D20: KT L/S-B
D21: KT R/S-B
D22: UA-B
D23: FU/XT-B

Sheet Bundle Tags2
A1: =IF('Bundle Tag Info'!A6<>"Panel Name",'Bundle Tag Info'!A6,"") -> JB70 | B1: =IF('Bundle Tag Info'!B6<>"Panel Name",'Bundle Tag Info'!B6,"") -> JB70 R RAIL | C1: =IF('Bundle Tag Info'!C6<>"Panel Name",'Bundle Tag Info'!C6,"") -> PLC | D1: =IF('Bundle Tag Info'!D6<>"Panel Name",'Bundle Tag Info'!D6,"") -> A | E1: =IF('Bundle Tag Info'!E6<>"Panel Name",'Bundle Tag Info'!E6,"") -> B | F1: =IF('Bundle Tag Info'!F6<>"Panel Name",'Bundle Tag Info'!F6,"") -> MED CONV | G1: =IF('Bundle Tag Info'!G6<>"Panel Name",'Bundle Tag Info'!G6,"") -> PWR | H1: =IF('Bundle Tag Info'!H6<>"Panel Name",'Bundle Tag Info'!H6,"") -> JB73 R RAIL | ... AD1: =IF('Bundle Tag Info'!AD6<>"Panel Name",'Bundle Tag Info'!AD6,"")
A2: =IF('Bundle Tag Info'!A$7<>"",CONCATENATE('Bundle Tag Info'!$A$1," ",CHAR(10),'Bundle Tag Info'!$A$2," ",'Bundle Tag Info'!$A$3,CHAR(10),'Bundle Tag Info'!A$6,CHAR(10),'Bundle Tag Info'!A$7),"") -> NNG-BUL 4K932 B.2 JB70 AT100 | B2: =IF('Bundle Tag Info'!B$7<>"",CONCATENATE('Bundle Tag Info'!$A$1," ",CHAR(10),'Bundle Tag Info'!$A$2," ",'Bundle Tag Info'!$A$3,CHAR(10),'Bundle Tag Info'!B$6,CHAR(10),'Bundle Tag Info'!B$7),"") -> NNG-BUL 4K932 B.2 JB70 R RAIL BA | C2: =IF('Bundle Tag Info'!C$7<>"",CONCATENATE('Bundle Tag Info'!$A$1," ",CHAR(10),'Bundle Tag Info'!$A$2," ",'Bundle Tag Info'!$A$3,CHAR(10),'Bundle Tag Info'!C$6,CHAR(10),'Bundle Tag Info'!C$7),"") -> NNG-BUL 4K932 B.2 PLC AT/FU | D2: =IF('Bundle Tag Info'!D$7<>"",CONCATENATE('Bundle Tag Info'!$A$1," ",CHAR(10),'Bundle Tag Info'!$A$2," ",'Bundle Tag Info'!$A$3,CHAR(10),'Bundle Tag Info'!D$6,CHAR(10),'Bundle Tag Info'!D$7),"") -> NNG-BUL 4K932 B.2 A AF080s | E2: =IF('Bundle Tag Info'!E$7<>"",CONCATENATE('Bundle Tag Info'!$A$1," ",CHAR(10),'Bundle Tag Info'!$A$2," ",'Bundle Tag Info'!$A$3,CHAR(10),'Bundle Tag Info'!E$6,CHAR(10),'Bundle Tag Info'!E$7),"") -> NNG-BUL 4K932 B.2 B AF060s | F2: =IF('Bundle Tag Info'!F$7<>"",CONCATENATE('Bundle Tag Info'!$A$1," ",CHAR(10),'Bundle Tag Info'!$A$2," ",'Bundle Tag Info'!$A$3,CHAR(10),'Bundle Tag Info'!F$6,CHAR(10),'Bundle Tag Info'!F$7),"") -> NNG-BUL 4K932 B.2 MED CONV BA | G2: =IF('Bundle Tag Info'!G$7<>"",CONCATENATE('Bundle Tag Info'!$A$1," ",CHAR(10),'Bundle Tag Info'!$A$2," ",'Bundle Tag Info'!$A$3,CHAR(10),'Bundle Tag Info'!G$6,CHAR(10),'Bundle Tag Info'!G$7),"") -> NNG-BUL 4K932 B.2 PWR UJ0031 | H2: =IF('Bundle Tag Info'!H$7<>"",CONCATENATE('Bundle Tag Info'!$A$1," ",CHAR(10),'Bundle Tag Info'!$A$2," ",'Bundle Tag Info'!$A$3,CHAR(10),'Bundle Tag Info'!H$6,CHAR(10),'Bundle Tag Info'!H$7),"") -> NNG-BUL 4K932 B.2 JB73 R RAIL FU/XT | ... AD2: =IF('Bundle Tag Info'!AD$7<>"",CONCATENATE('Bundle Tag Info'!$A$1," ",CHAR(10),'Bundle Tag Info'!$A$2," ",'Bundle Tag Info'!$A$3,CHAR(10),'Bundle Tag Info'!AD$6,CHAR(10),'Bundle Tag Info'!AD$7),"")
A3: =IF('Bundle Tag Info'!A$8<>"",CONCATENATE('Bundle Tag Info'!$A$1," ",CHAR(10),'Bundle Tag Info'!$A$2," ",'Bundle Tag Info'!$A$3,CHAR(10),'Bundle Tag Info'!A$6,CHAR(10),'Bundle Tag Info'!A$8),"") -> NNG-BUL 4K932 B.2 JB70 SA0471 | B3: =IF('Bundle Tag Info'!B$8<>"",CONCATENATE('Bundle Tag Info'!$A$1," ",CHAR(10),'Bundle Tag Info'!$A$2," ",'Bundle Tag Info'!$A$3,CHAR(10),'Bundle Tag Info'!B$6,CHAR(10),'Bundle Tag Info'!B$8),"") -> NNG-BUL 4K932 B.2 JB70 R RAIL FU/XT | C3: =IF('Bundle Tag Info'!C$8<>"",CONCATENATE('Bundle Tag Info'!$A$1," ",CHAR(10),'Bundle Tag Info'!$A$2," ",'Bundle Tag Info'!$A$3,CHAR(10),'Bundle Tag Info'!C$6,CHAR(10),'Bundle Tag Info'!C$8),"") -> NNG-BUL 4K932 B.2 PLC UV-A | D3: =IF('Bundle Tag Info'!D$8<>"",CONCATENATE('Bundle Tag Info'!$A$1," ",CHAR(10),'Bundle Tag Info'!$A$2," ",'Bundle Tag Info'!$A$3,CHAR(10),'Bundle Tag Info'!D$6,CHAR(10),'Bundle Tag Info'!D$8),"") -> NNG-BUL 4K932 B.2 A AF090s | E3: =IF('Bundle Tag Info'!E$8<>"",CONCATENATE('Bundle Tag Info'!$A$1," ",CHAR(10),'Bundle Tag Info'!$A$2," ",'Bundle Tag Info'!$A$3,CHAR(10),'Bundle Tag Info'!E$6,CHAR(10),'Bundle Tag Info'!E$8),"") -> NNG-BUL 4K932 B.2 B AF070s | F3: =IF('Bundle Tag Info'!F$8<>"",CONCATENATE('Bundle Tag Info'!$A$1," ",CHAR(10),'Bundle Tag Info'!$A$2," ",'Bundle Tag Info'!$A$3,CHAR(10),'Bundle Tag Info'!F$6,CHAR(10),'Bundle Tag Info'!F$8),"") | G3: =IF('Bundle Tag Info'!G$8<>"",CONCATENATE('Bundle Tag Info'!$A$1," ",CHAR(10),'Bundle Tag Info'!$A$2," ",'Bundle Tag Info'!$A$3,CHAR(10),'Bundle Tag Info'!G$6,CHAR(10),'Bundle Tag Info'!G$8),"") -> NNG-BUL 4K932 B.2 PWR UJ0131 | H3: =IF('Bundle Tag Info'!H$8<>"",CONCATENATE('Bundle Tag Info'!$A$1," ",CHAR(10),'Bundle Tag Info'!$A$2," ",'Bundle Tag Info'!$A$3,CHAR(10),'Bundle Tag Info'!H$6,CHAR(10),'Bundle Tag Info'!H$8),"") -> NNG-BUL 4K932 B.2 JB73 R RAIL FU/XT-BOP | ... AD3: =IF('Bundle Tag Info'!AD$8<>"",CONCATENATE('Bundle Tag Info'!$A$1," ",CHAR(10),'Bundle Tag Info'!$A$2," ",'Bundle Tag Info'!$A$3,CHAR(10),'Bundle Tag Info'!AD$6,CHAR(10),'Bundle Tag Info'!AD$8),"")
A4: =IF('Bundle Tag Info'!A$9<>"",CONCATENATE('Bundle Tag Info'!$A$1," ",CHAR(10),'Bundle Tag Info'!$A$2," ",'Bundle Tag Info'!$A$3,CHAR(10),'Bundle Tag Info'!A$6,CHAR(10),'Bundle Tag Info'!A$9),"") -> NNG-BUL 4K932 B.2 JB70 SA0473 | B4: =IF('Bundle Tag Info'!B$9<>"",CONCATENATE('Bundle Tag Info'!$A$1," ",CHAR(10),'Bundle Tag Info'!$A$2," ",'Bundle Tag Info'!$A$3,CHAR(10),'Bundle Tag Info'!B$6,CHAR(10),'Bundle Tag Info'!B$9),"") -> NNG-BUL 4K932 B.2 JB70 R RAIL XT | C4: =IF('Bundle Tag Info'!C$9<>"",CONCATENATE('Bundle Tag Info'!$A$1," ",CHAR(10),'Bundle Tag Info'!$A$2," ",'Bundle Tag Info'!$A$3,CHAR(10),'Bundle Tag Info'!C$6,CHAR(10),'Bundle Tag Info'!C$9),"") -> NNG-BUL 4K932 B.2 PLC FU/XT-A | D4: =IF('Bundle Tag Info'!D$9<>"",CONCATENATE('Bundle Tag Info'!$A$1," ",CHAR(10),'Bundle Tag Info'!$A$2," ",'Bundle Tag Info'!$A$3,CHAR(10),'Bundle Tag Info'!D$6,CHAR(10),'Bundle Tag Info'!D$9),"") -> NNG-BUL 4K932 B.2 A FU | E4: =IF('Bundle Tag Info'!E$9<>"",CONCATENATE('Bundle Tag Info'!$A$1," ",CHAR(10),'Bundle Tag Info'!$A$2," ",'Bundle Tag Info'!$A$3,CHAR(10),'Bundle Tag Info'!E$6,CHAR(10),'Bundle Tag Info'!E$9),"") -> NNG-BUL 4K932 B.2 B 1444s | F4: =IF('Bundle Tag Info'!F$9<>"",CONCATENATE('Bundle Tag Info'!$A$1," ",CHAR(10),'Bundle Tag Info'!$A$2," ",'Bundle Tag Info'!$A$3,CHAR(10),'Bundle Tag Info'!F$6,CHAR(10),'Bundle Tag Info'!F$9),"") | G4: =IF('Bundle Tag Info'!G$9<>"",CONCATENATE('Bundle Tag Info'!$A$1," ",CHAR(10),'Bundle Tag Info'!$A$2," ",'Bundle Tag Info'!$A$3,CHAR(10),'Bundle Tag Info'!G$6,CHAR(10),'Bundle Tag Info'!G$9),"") | H4: =IF('Bundle Tag Info'!H$9<>"",CONCATENATE('Bundle Tag Info'!$A$1," ",CHAR(10),'Bundle Tag Info'!$A$2," ",'Bundle Tag Info'!$A$3,CHAR(10),'Bundle Tag Info'!H$6,CHAR(10),'Bundle Tag Info'!H$9),"") -> NNG-BUL 4K932 B.2 JB73 R RAIL XT-HPC | ... AD4: =IF('Bundle Tag Info'!AD$9<>"",CONCATENATE('Bundle Tag Info'!$A$1," ",CHAR(10),'Bundle Tag Info'!$A$2," ",'Bundle Tag Info'!$A$3,CHAR(10),'Bundle Tag Info'!AD$6,CHAR(10),'Bundle Tag Info'!AD$9),"")
A5: =IF('Bundle Tag Info'!A$10<>"",CONCATENATE('Bundle Tag Info'!$A$1," ",CHAR(10),'Bundle Tag Info'!$A$2," ",'Bundle Tag Info'!$A$3,CHAR(10),'Bundle Tag Info'!A$6,CHAR(10),'Bundle Tag Info'!A$10),"") -> NNG-BUL 4K932 B.2 JB70 SA0474 | B5: =IF('Bundle Tag Info'!B$10<>"",CONCATENATE('Bundle Tag Info'!$A$1," ",CHAR(10),'Bundle Tag Info'!$A$2," ",'Bundle Tag Info'!$A$3,CHAR(10),'Bundle Tag Info'!B$6,CHAR(10),'Bundle Tag Info'!B$10),"") -> NNG-BUL 4K932 B.2 JB70 R RAIL BA-B | C5: =IF('Bundle Tag Info'!C$10<>"",CONCATENATE('Bundle Tag Info'!$A$1," ",CHAR(10),'Bundle Tag Info'!$A$2," ",'Bundle Tag Info'!$A$3,CHAR(10),'Bundle Tag Info'!C$6,CHAR(10),'Bundle Tag Info'!C$10),"") | D5: =IF('Bundle Tag Info'!D$10<>"",CONCATENATE('Bundle Tag Info'!$A$1," ",CHAR(10),'Bundle Tag Info'!$A$2," ",'Bundle Tag Info'!$A$3,CHAR(10),'Bundle Tag Info'!D$6,CHAR(10),'Bundle Tag Info'!D$10),"") -> NNG-BUL 4K932 B.2 A KA A1 | E5: =IF('Bundle Tag Info'!E$10<>"",CONCATENATE('Bundle Tag Info'!$A$1," ",CHAR(10),'Bundle Tag Info'!$A$2," ",'Bundle Tag Info'!$A$3,CHAR(10),'Bundle Tag Info'!E$6,CHAR(10),'Bundle Tag Info'!E$10),"") -> NNG-BUL 4K932 B.2 B FU/XT | F5: =IF('Bundle Tag Info'!F$10<>"",CONCATENATE('Bundle Tag Info'!$A$1," ",CHAR(10),'Bundle Tag Info'!$A$2," ",'Bundle Tag Info'!$A$3,CHAR(10),'Bundle Tag Info'!F$6,CHAR(10),'Bundle Tag Info'!F$10),"") | G5: =IF('Bundle Tag Info'!G$10<>"",CONCATENATE('Bundle Tag Info'!$A$1," ",CHAR(10),'Bundle Tag Info'!$A$2," ",'Bundle Tag Info'!$A$3,CHAR(10),'Bundle Tag Info'!G$6,CHAR(10),'Bundle Tag Info'!G$10),"") | H5: =IF('Bundle Tag Info'!H$10<>"",CONCATENATE('Bundle Tag Info'!$A$1," ",CHAR(10),'Bundle Tag Info'!$A$2," ",'Bundle Tag Info'!$A$3,CHAR(10),'Bundle Tag Info'!H$6,CHAR(10),'Bundle Tag Info'!H$10),"") | ... AD5: =IF('Bundle Tag Info'!AD$10<>"",CONCATENATE('Bundle Tag Info'!$A$1," ",CHAR(10),'Bundle Tag Info'!$A$2," ",'Bundle Tag Info'!$A$3,CHAR(10),'Bundle Tag Info'!AD$6,CHAR(10),'Bundle Tag Info'!AD$10),"")
A6: =IF('Bundle Tag Info'!A$11<>"",CONCATENATE('Bundle Tag Info'!$A$1," ",CHAR(10),'Bundle Tag Info'!$A$2," ",'Bundle Tag Info'!$A$3,CHAR(10),'Bundle Tag Info'!A$6,CHAR(10),'Bundle Tag Info'!A$11),"") -> NNG-BUL 4K932 B.2 JB70 SB0471 | B6: =IF('Bundle Tag Info'!B$11<>"",CONCATENATE('Bundle Tag Info'!$A$1," ",CHAR(10),'Bundle Tag Info'!$A$2," ",'Bundle Tag Info'!$A$3,CHAR(10),'Bundle Tag Info'!B$6,CHAR(10),'Bundle Tag Info'!B$11),"") -> NNG-BUL 4K932 B.2 JB70 R RAIL XT-B | C6: =IF('Bundle Tag Info'!C$11<>"",CONCATENATE('Bundle Tag Info'!$A$1," ",CHAR(10),'Bundle Tag Info'!$A$2," ",'Bundle Tag Info'!$A$3,CHAR(10),'Bundle Tag Info'!C$6,CHAR(10),'Bundle Tag Info'!C$11),"") | D6: =IF('Bundle Tag Info'!D$11<>"",CONCATENATE('Bundle Tag Info'!$A$1," ",CHAR(10),'Bundle Tag Info'!$A$2," ",'Bundle Tag Info'!$A$3,CHAR(10),'Bundle Tag Info'!D$6,CHAR(10),'Bundle Tag Info'!D$11),"") -> NNG-BUL 4K932 B.2 A KA A2 | E6: =IF('Bundle Tag Info'!E$11<>"",CONCATENATE('Bundle Tag Info'!$A$1," ",CHAR(10),'Bundle Tag Info'!$A$2," ",'Bundle Tag Info'!$A$3,CHAR(10),'Bundle Tag Info'!E$6,CHAR(10),'Bundle Tag Info'!E$11),"") -> NNG-BUL 4K932 B.2 B KA A1 | F6: =IF('Bundle Tag Info'!F$11<>"",CONCATENATE('Bundle Tag Info'!$A$1," ",CHAR(10),'Bundle Tag Info'!$A$2," ",'Bundle Tag Info'!$A$3,CHAR(10),'Bundle Tag Info'!F$6,CHAR(10),'Bundle Tag Info'!F$11),"") | G6: =IF('Bundle Tag Info'!G$11<>"",CONCATENATE('Bundle Tag Info'!$A$1," ",CHAR(10),'Bundle Tag Info'!$A$2," ",'Bundle Tag Info'!$A$3,CHAR(10),'Bundle Tag Info'!G$6,CHAR(10),'Bundle Tag Info'!G$11),"") | H6: =IF('Bundle Tag Info'!H$11<>"",CONCATENATE('Bundle Tag Info'!$A$1," ",CHAR(10),'Bundle Tag Info'!$A$2," ",'Bundle Tag Info'!$A$3,CHAR(10),'Bundle Tag Info'!H$6,CHAR(10),'Bundle Tag Info'!H$11),"") | ... AD6: =IF('Bundle Tag Info'!AD$11<>"",CONCATENATE('Bundle Tag Info'!$A$1," ",CHAR(10),'Bundle Tag Info'!$A$2," ",'Bundle Tag Info'!$A$3,CHAR(10),'Bundle Tag Info'!AD$6,CHAR(10),'Bundle Tag Info'!AD$11),"")
A7: =IF('Bundle Tag Info'!A$12<>"",CONCATENATE('Bundle Tag Info'!$A$1," ",CHAR(10),'Bundle Tag Info'!$A$2," ",'Bundle Tag Info'!$A$3,CHAR(10),'Bundle Tag Info'!A$6,CHAR(10),'Bundle Tag Info'!A$12),"") -> NNG-BUL 4K932 B.2 JB70 SB0472 | B7: =IF('Bundle Tag Info'!B$12<>"",CONCATENATE('Bundle Tag Info'!$A$1," ",CHAR(10),'Bundle Tag Info'!$A$2," ",'Bundle Tag Info'!$A$3,CHAR(10),'Bundle Tag Info'!B$6,CHAR(10),'Bundle Tag Info'!B$12),"") | C7: =IF('Bundle Tag Info'!C$12<>"",CONCATENATE('Bundle Tag Info'!$A$1," ",CHAR(10),'Bundle Tag Info'!$A$2," ",'Bundle Tag Info'!$A$3,CHAR(10),'Bundle Tag Info'!C$6,CHAR(10),'Bundle Tag Info'!C$12),"") | D7: =IF('Bundle Tag Info'!D$12<>"",CONCATENATE('Bundle Tag Info'!$A$1," ",CHAR(10),'Bundle Tag Info'!$A$2," ",'Bundle Tag Info'!$A$3,CHAR(10),'Bundle Tag Info'!D$6,CHAR(10),'Bundle Tag Info'!D$12),"") -> NNG-BUL 4K932 B.2 A KA | E7: =IF('Bundle Tag Info'!E$12<>"",CONCATENATE('Bundle Tag Info'!$A$1," ",CHAR(10),'Bundle Tag Info'!$A$2," ",'Bundle Tag Info'!$A$3,CHAR(10),'Bundle Tag Info'!E$6,CHAR(10),'Bundle Tag Info'!E$12),"") -> NNG-BUL 4K932 B.2 B KA A2 | F7: =IF('Bundle Tag Info'!F$12<>"",CONCATENATE('Bundle Tag Info'!$A$1," ",CHAR(10),'Bundle Tag Info'!$A$2," ",'Bundle Tag Info'!$A$3,CHAR(10),'Bundle Tag Info'!F$6,CHAR(10),'Bundle Tag Info'!F$12),"") | G7: =IF('Bundle Tag Info'!G$12<>"",CONCATENATE('Bundle Tag Info'!$A$1," ",CHAR(10),'Bundle Tag Info'!$A$2," ",'Bundle Tag Info'!$A$3,CHAR(10),'Bundle Tag Info'!G$6,CHAR(10),'Bundle Tag Info'!G$12),"") | H7: =IF('Bundle Tag Info'!H$12<>"",CONCATENATE('Bundle Tag Info'!$A$1," ",CHAR(10),'Bundle Tag Info'!$A$2," ",'Bundle Tag Info'!$A$3,CHAR(10),'Bundle Tag Info'!H$6,CHAR(10),'Bundle Tag Info'!H$12),"") | ... AD7: =IF('Bundle Tag Info'!AD$12<>"",CONCATENATE('Bundle Tag Info'!$A$1," ",CHAR(10),'Bundle Tag Info'!$A$2," ",'Bundle Tag Info'!$A$3,CHAR(10),'Bundle Tag Info'!AD$6,CHAR(10),'Bundle Tag Info'!AD$12),"")
A8: =IF('Bundle Tag Info'!A$13<>"",CONCATENATE('Bundle Tag Info'!$A$1," ",CHAR(10),'Bundle Tag Info'!$A$2," ",'Bundle Tag Info'!$A$3,CHAR(10),'Bundle Tag Info'!A$6,CHAR(10),'Bundle Tag Info'!A$13),"") -> NNG-BUL 4K932 B.2 JB70 SB0473 | B8: =IF('Bundle Tag Info'!B$13<>"",CONCATENATE('Bundle Tag Info'!$A$1," ",CHAR(10),'Bundle Tag Info'!$A$2," ",'Bundle Tag Info'!$A$3,CHAR(10),'Bundle Tag Info'!B$6,CHAR(10),'Bundle Tag Info'!B$13),"") | C8: =IF('Bundle Tag Info'!C$13<>"",CONCATENATE('Bundle Tag Info'!$A$1," ",CHAR(10),'Bundle Tag Info'!$A$2," ",'Bundle Tag Info'!$A$3,CHAR(10),'Bundle Tag Info'!C$6,CHAR(10),'Bundle Tag Info'!C$13),"") | D8: =IF('Bundle Tag Info'!D$13<>"",CONCATENATE('Bundle Tag Info'!$A$1," ",CHAR(10),'Bundle Tag Info'!$A$2," ",'Bundle Tag Info'!$A$3,CHAR(10),'Bundle Tag Info'!D$6,CHAR(10),'Bundle Tag Info'!D$13),"") -> NNG-BUL 4K932 B.2 A KT L/S | E8: =IF('Bundle Tag Info'!E$13<>"",CONCATENATE('Bundle Tag Info'!$A$1," ",CHAR(10),'Bundle Tag Info'!$A$2," ",'Bundle Tag Info'!$A$3,CHAR(10),'Bundle Tag Info'!E$6,CHAR(10),'Bundle Tag Info'!E$13),"") -> NNG-BUL 4K932 B.2 B KA | F8: =IF('Bundle Tag Info'!F$13<>"",CONCATENATE('Bundle Tag Info'!$A$1," ",CHAR(10),'Bundle Tag Info'!$A$2," ",'Bundle Tag Info'!$A$3,CHAR(10),'Bundle Tag Info'!F$6,CHAR(10),'Bundle Tag Info'!F$13),"") | G8: =IF('Bundle Tag Info'!G$13<>"",CONCATENATE('Bundle Tag Info'!$A$1," ",CHAR(10),'Bundle Tag Info'!$A$2," ",'Bundle Tag Info'!$A$3,CHAR(10),'Bundle Tag Info'!G$6,CHAR(10),'Bundle Tag Info'!G$13),"") | H8: =IF('Bundle Tag Info'!H$13<>"",CONCATENATE('Bundle Tag Info'!$A$1," ",CHAR(10),'Bundle Tag Info'!$A$2," ",'Bundle Tag Info'!$A$3,CHAR(10),'Bundle Tag Info'!H$6,CHAR(10),'Bundle Tag Info'!H$13),"") | ... AD8: =IF('Bundle Tag Info'!AD$13<>"",CONCATENATE('Bundle Tag Info'!$A$1," ",CHAR(10),'Bundle Tag Info'!$A$2," ",'Bundle Tag Info'!$A$3,CHAR(10),'Bundle Tag Info'!AD$6,CHAR(10),'Bundle Tag Info'!AD$13),"")
A9: =IF('Bundle Tag Info'!A$14<>"",CONCATENATE('Bundle Tag Info'!$A$1," ",CHAR(10),'Bundle Tag Info'!$A$2," ",'Bundle Tag Info'!$A$3,CHAR(10),'Bundle Tag Info'!A$6,CHAR(10),'Bundle Tag Info'!A$14),"") -> NNG-BUL 4K932 B.2 JB70 SB0474 | B9: =IF('Bundle Tag Info'!B$14<>"",CONCATENATE('Bundle Tag Info'!$A$1," ",CHAR(10),'Bundle Tag Info'!$A$2," ",'Bundle Tag Info'!$A$3,CHAR(10),'Bundle Tag Info'!B$6,CHAR(10),'Bundle Tag Info'!B$14),"") | C9: =IF('Bundle Tag Info'!C$14<>"",CONCATENATE('Bundle Tag Info'!$A$1," ",CHAR(10),'Bundle Tag Info'!$A$2," ",'Bundle Tag Info'!$A$3,CHAR(10),'Bundle Tag Info'!C$6,CHAR(10),'Bundle Tag Info'!C$14),"") | D9: =IF('Bundle Tag Info'!D$14<>"",CONCATENATE('Bundle Tag Info'!$A$1," ",CHAR(10),'Bundle Tag Info'!$A$2," ",'Bundle Tag Info'!$A$3,CHAR(10),'Bundle Tag Info'!D$6,CHAR(10),'Bundle Tag Info'!D$14),"") -> NNG-BUL 4K932 B.2 A KT R/S | E9: =IF('Bundle Tag Info'!E$14<>"",CONCATENATE('Bundle Tag Info'!$A$1," ",CHAR(10),'Bundle Tag Info'!$A$2," ",'Bundle Tag Info'!$A$3,CHAR(10),'Bundle Tag Info'!E$6,CHAR(10),'Bundle Tag Info'!E$14),"") | F9: =IF('Bundle Tag Info'!F$14<>"",CONCATENATE('Bundle Tag Info'!$A$1," ",CHAR(10),'Bundle Tag Info'!$A$2," ",'Bundle Tag Info'!$A$3,CHAR(10),'Bundle Tag Info'!F$6,CHAR(10),'Bundle Tag Info'!F$14),"") | G9: =IF('Bundle Tag Info'!G$14<>"",CONCATENATE('Bundle Tag Info'!$A$1," ",CHAR(10),'Bundle Tag Info'!$A$2," ",'Bundle Tag Info'!$A$3,CHAR(10),'Bundle Tag Info'!G$6,CHAR(10),'Bundle Tag Info'!G$14),"") | H9: =IF('Bundle Tag Info'!H$14<>"",CONCATENATE('Bundle Tag Info'!$A$1," ",CHAR(10),'Bundle Tag Info'!$A$2," ",'Bundle Tag Info'!$A$3,CHAR(10),'Bundle Tag Info'!H$6,CHAR(10),'Bundle Tag Info'!H$14),"") | ... AD9: =IF('Bundle Tag Info'!AD$14<>"",CONCATENATE('Bundle Tag Info'!$A$1," ",CHAR(10),'Bundle Tag Info'!$A$2," ",'Bundle Tag Info'!$A$3,CHAR(10),'Bundle Tag Info'!AD$6,CHAR(10),'Bundle Tag Info'!AD$14),"")
A10: =IF('Bundle Tag Info'!A$15<>"",CONCATENATE('Bundle Tag Info'!$A$1," ",CHAR(10),'Bundle Tag Info'!$A$2," ",'Bundle Tag Info'!$A$3,CHAR(10),'Bundle Tag Info'!A$6,CHAR(10),'Bundle Tag Info'!A$15),"") -> NNG-BUL 4K932 B.2 JB70 SH0470 | B10: =IF('Bundle Tag Info'!B$15<>"",CONCATENATE('Bundle Tag Info'!$A$1," ",CHAR(10),'Bundle Tag Info'!$A$2," ",'Bundle Tag Info'!$A$3,CHAR(10),'Bundle Tag Info'!B$6,CHAR(10),'Bundle Tag Info'!B$15),"") | C10: =IF('Bundle Tag Info'!C$15<>"",CONCATENATE('Bundle Tag Info'!$A$1," ",CHAR(10),'Bundle Tag Info'!$A$2," ",'Bundle Tag Info'!$A$3,CHAR(10),'Bundle Tag Info'!C$6,CHAR(10),'Bundle Tag Info'!C$15),"") | D10: =IF('Bundle Tag Info'!D$15<>"",CONCATENATE('Bundle Tag Info'!$A$1," ",CHAR(10),'Bundle Tag Info'!$A$2," ",'Bundle Tag Info'!$A$3,CHAR(10),'Bundle Tag Info'!D$6,CHAR(10),'Bundle Tag Info'!D$15),"") -> NNG-BUL 4K932 B.2 A UA | E10: =IF('Bundle Tag Info'!E$15<>"",CONCATENATE('Bundle Tag Info'!$A$1," ",CHAR(10),'Bundle Tag Info'!$A$2," ",'Bundle Tag Info'!$A$3,CHAR(10),'Bundle Tag Info'!E$6,CHAR(10),'Bundle Tag Info'!E$15),"") | F10: =IF('Bundle Tag Info'!F$15<>"",CONCATENATE('Bundle Tag Info'!$A$1," ",CHAR(10),'Bundle Tag Info'!$A$2," ",'Bundle Tag Info'!$A$3,CHAR(10),'Bundle Tag Info'!F$6,CHAR(10),'Bundle Tag Info'!F$15),"") | G10: =IF('Bundle Tag Info'!G$15<>"",CONCATENATE('Bundle Tag Info'!$A$1," ",CHAR(10),'Bundle Tag Info'!$A$2," ",'Bundle Tag Info'!$A$3,CHAR(10),'Bundle Tag Info'!G$6,CHAR(10),'Bundle Tag Info'!G$15),"") | H10: =IF('Bundle Tag Info'!H$15<>"",CONCATENATE('Bundle Tag Info'!$A$1," ",CHAR(10),'Bundle Tag Info'!$A$2," ",'Bundle Tag Info'!$A$3,CHAR(10),'Bundle Tag Info'!H$6,CHAR(10),'Bundle Tag Info'!H$15),"") | ... AD10: =IF('Bundle Tag Info'!AD$15<>"",CONCATENATE('Bundle Tag Info'!$A$1," ",CHAR(10),'Bundle Tag Info'!$A$2," ",'Bundle Tag Info'!$A$3,CHAR(10),'Bundle Tag Info'!AD$6,CHAR(10),'Bundle Tag Info'!AD$15),"")
A11: =IF('Bundle Tag Info'!A$16<>"",CONCATENATE('Bundle Tag Info'!$A$1," ",CHAR(10),'Bundle Tag Info'!$A$2," ",'Bundle Tag Info'!$A$3,CHAR(10),'Bundle Tag Info'!A$6,CHAR(10),'Bundle Tag Info'!A$16),"") -> NNG-BUL 4K932 B.2 JB70 SH0471 | B11: =IF('Bundle Tag Info'!B$16<>"",CONCATENATE('Bundle Tag Info'!$A$1," ",CHAR(10),'Bundle Tag Info'!$A$2," ",'Bundle Tag Info'!$A$3,CHAR(10),'Bundle Tag Info'!B$6,CHAR(10),'Bundle Tag Info'!B$16),"") | C11: =IF('Bundle Tag Info'!C$16<>"",CONCATENATE('Bundle Tag Info'!$A$1," ",CHAR(10),'Bundle Tag Info'!$A$2," ",'Bundle Tag Info'!$A$3,CHAR(10),'Bundle Tag Info'!C$6,CHAR(10),'Bundle Tag Info'!C$16),"") | D11: =IF('Bundle Tag Info'!D$16<>"",CONCATENATE('Bundle Tag Info'!$A$1," ",CHAR(10),'Bundle Tag Info'!$A$2," ",'Bundle Tag Info'!$A$3,CHAR(10),'Bundle Tag Info'!D$6,CHAR(10),'Bundle Tag Info'!D$16),"") -> NNG-BUL 4K932 B.2 A XT | E11: =IF('Bundle Tag Info'!E$16<>"",CONCATENATE('Bundle Tag Info'!$A$1," ",CHAR(10),'Bundle Tag Info'!$A$2," ",'Bundle Tag Info'!$A$3,CHAR(10),'Bundle Tag Info'!E$6,CHAR(10),'Bundle Tag Info'!E$16),"") | F11: =IF('Bundle Tag Info'!F$16<>"",CONCATENATE('Bundle Tag Info'!$A$1," ",CHAR(10),'Bundle Tag Info'!$A$2," ",'Bundle Tag Info'!$A$3,CHAR(10),'Bundle Tag Info'!F$6,CHAR(10),'Bundle Tag Info'!F$16),"") | G11: =IF('Bundle Tag Info'!G$16<>"",CONCATENATE('Bundle Tag Info'!$A$1," ",CHAR(10),'Bundle Tag Info'!$A$2," ",'Bundle Tag Info'!$A$3,CHAR(10),'Bundle Tag Info'!G$6,CHAR(10),'Bundle Tag Info'!G$16),"") | H11: =IF('Bundle Tag Info'!H$16<>"",CONCATENATE('Bundle Tag Info'!$A$1," ",CHAR(10),'Bundle Tag Info'!$A$2," ",'Bundle Tag Info'!$A$3,CHAR(10),'Bundle Tag Info'!H$6,CHAR(10),'Bundle Tag Info'!H$16),"") | ... AD11: =IF('Bundle Tag Info'!AD$16<>"",CONCATENATE('Bundle Tag Info'!$A$1," ",CHAR(10),'Bundle Tag Info'!$A$2," ",'Bundle Tag Info'!$A$3,CHAR(10),'Bundle Tag Info'!AD$6,CHAR(10),'Bundle Tag Info'!AD$16),"")
A12: =IF('Bundle Tag Info'!A$17<>"",CONCATENATE('Bundle Tag Info'!$A$1," ",CHAR(10),'Bundle Tag Info'!$A$2," ",'Bundle Tag Info'!$A$3,CHAR(10),'Bundle Tag Info'!A$6,CHAR(10),'Bundle Tag Info'!A$17),"") -> NNG-BUL 4K932 B.2 JB70 SH0472 | B12: =IF('Bundle Tag Info'!B$17<>"",CONCATENATE('Bundle Tag Info'!$A$1," ",CHAR(10),'Bundle Tag Info'!$A$2," ",'Bundle Tag Info'!$A$3,CHAR(10),'Bundle Tag Info'!B$6,CHAR(10),'Bundle Tag Info'!B$17),"") | C12: =IF('Bundle Tag Info'!C$17<>"",CONCATENATE('Bundle Tag Info'!$A$1," ",CHAR(10),'Bundle Tag Info'!$A$2," ",'Bundle Tag Info'!$A$3,CHAR(10),'Bundle Tag Info'!C$6,CHAR(10),'Bundle Tag Info'!C$17),"") | D12: =IF('Bundle Tag Info'!D$17<>"",CONCATENATE('Bundle Tag Info'!$A$1," ",CHAR(10),'Bundle Tag Info'!$A$2," ",'Bundle Tag Info'!$A$3,CHAR(10),'Bundle Tag Info'!D$6,CHAR(10),'Bundle Tag Info'!D$17),"") -> NNG-BUL 4K932 B.2 A AF-B | E12: =IF('Bundle Tag Info'!E$17<>"",CONCATENATE('Bundle Tag Info'!$A$1," ",CHAR(10),'Bundle Tag Info'!$A$2," ",'Bundle Tag Info'!$A$3,CHAR(10),'Bundle Tag Info'!E$6,CHAR(10),'Bundle Tag Info'!E$17),"") | F12: =IF('Bundle Tag Info'!F$17<>"",CONCATENATE('Bundle Tag Info'!$A$1," ",CHAR(10),'Bundle Tag Info'!$A$2," ",'Bundle Tag Info'!$A$3,CHAR(10),'Bundle Tag Info'!F$6,CHAR(10),'Bundle Tag Info'!F$17),"") | G12: =IF('Bundle Tag Info'!G$17<>"",CONCATENATE('Bundle Tag Info'!$A$1," ",CHAR(10),'Bundle Tag Info'!$A$2," ",'Bundle Tag Info'!$A$3,CHAR(10),'Bundle Tag Info'!G$6,CHAR(10),'Bundle Tag Info'!G$17),"") | H12: =IF('Bundle Tag Info'!H$17<>"",CONCATENATE('Bundle Tag Info'!$A$1," ",CHAR(10),'Bundle Tag Info'!$A$2," ",'Bundle Tag Info'!$A$3,CHAR(10),'Bundle Tag Info'!H$6,CHAR(10),'Bundle Tag Info'!H$17),"") | ... AD12: =IF('Bundle Tag Info'!AD$17<>"",CONCATENATE('Bundle Tag Info'!$A$1," ",CHAR(10),'Bundle Tag Info'!$A$2," ",'Bundle Tag Info'!$A$3,CHAR(10),'Bundle Tag Info'!AD$6,CHAR(10),'Bundle Tag Info'!AD$17),"")
A13: =IF('Bundle Tag Info'!A$18<>"",CONCATENATE('Bundle Tag Info'!$A$1," ",CHAR(10),'Bundle Tag Info'!$A$2," ",'Bundle Tag Info'!$A$3,CHAR(10),'Bundle Tag Info'!A$6,CHAR(10),'Bundle Tag Info'!A$18),"") | B13: =IF('Bundle Tag Info'!B$18<>"",CONCATENATE('Bundle Tag Info'!$A$1," ",CHAR(10),'Bundle Tag Info'!$A$2," ",'Bundle Tag Info'!$A$3,CHAR(10),'Bundle Tag Info'!B$6,CHAR(10),'Bundle Tag Info'!B$18),"") | C13: =IF('Bundle Tag Info'!C$18<>"",CONCATENATE('Bundle Tag Info'!$A$1," ",CHAR(10),'Bundle Tag Info'!$A$2," ",'Bundle Tag Info'!$A$3,CHAR(10),'Bundle Tag Info'!C$6,CHAR(10),'Bundle Tag Info'!C$18),"") | D13: =IF('Bundle Tag Info'!D$18<>"",CONCATENATE('Bundle Tag Info'!$A$1," ",CHAR(10),'Bundle Tag Info'!$A$2," ",'Bundle Tag Info'!$A$3,CHAR(10),'Bundle Tag Info'!D$6,CHAR(10),'Bundle Tag Info'!D$18),"") -> NNG-BUL 4K932 B.2 A KA A1-B | E13: =IF('Bundle Tag Info'!E$18<>"",CONCATENATE('Bundle Tag Info'!$A$1," ",CHAR(10),'Bundle Tag Info'!$A$2," ",'Bundle Tag Info'!$A$3,CHAR(10),'Bundle Tag Info'!E$6,CHAR(10),'Bundle Tag Info'!E$18),"") | F13: =IF('Bundle Tag Info'!F$18<>"",CONCATENATE('Bundle Tag Info'!$A$1," ",CHAR(10),'Bundle Tag Info'!$A$2," ",'Bundle Tag Info'!$A$3,CHAR(10),'Bundle Tag Info'!F$6,CHAR(10),'Bundle Tag Info'!F$18),"") | G13: =IF('Bundle Tag Info'!G$18<>"",CONCATENATE('Bundle Tag Info'!$A$1," ",CHAR(10),'Bundle Tag Info'!$A$2," ",'Bundle Tag Info'!$A$3,CHAR(10),'Bundle Tag Info'!G$6,CHAR(10),'Bundle Tag Info'!G$18),"") | H13: =IF('Bundle Tag Info'!H$18<>"",CONCATENATE('Bundle Tag Info'!$A$1," ",CHAR(10),'Bundle Tag Info'!$A$2," ",'Bundle Tag Info'!$A$3,CHAR(10),'Bundle Tag Info'!H$6,CHAR(10),'Bundle Tag Info'!H$18),"") | ... AD13: =IF('Bundle Tag Info'!AD$18<>"",CONCATENATE('Bundle Tag Info'!$A$1," ",CHAR(10),'Bundle Tag Info'!$A$2," ",'Bundle Tag Info'!$A$3,CHAR(10),'Bundle Tag Info'!AD$6,CHAR(10),'Bundle Tag Info'!AD$18),"")
A14: =IF('Bundle Tag Info'!A$19<>"",CONCATENATE('Bundle Tag Info'!$A$1," ",CHAR(10),'Bundle Tag Info'!$A$2," ",'Bundle Tag Info'!$A$3,CHAR(10),'Bundle Tag Info'!A$6,CHAR(10),'Bundle Tag Info'!A$19),"") | B14: =IF('Bundle Tag Info'!B$19<>"",CONCATENATE('Bundle Tag Info'!$A$1," ",CHAR(10),'Bundle Tag Info'!$A$2," ",'Bundle Tag Info'!$A$3,CHAR(10),'Bundle Tag Info'!B$6,CHAR(10),'Bundle Tag Info'!B$19),"") | C14: =IF('Bundle Tag Info'!C$19<>"",CONCATENATE('Bundle Tag Info'!$A$1," ",CHAR(10),'Bundle Tag Info'!$A$2," ",'Bundle Tag Info'!$A$3,CHAR(10),'Bundle Tag Info'!C$6,CHAR(10),'Bundle Tag Info'!C$19),"") | D14: =IF('Bundle Tag Info'!D$19<>"",CONCATENATE('Bundle Tag Info'!$A$1," ",CHAR(10),'Bundle Tag Info'!$A$2," ",'Bundle Tag Info'!$A$3,CHAR(10),'Bundle Tag Info'!D$6,CHAR(10),'Bundle Tag Info'!D$19),"") -> NNG-BUL 4K932 B.2 A KA-B | E14: =IF('Bundle Tag Info'!E$19<>"",CONCATENATE('Bundle Tag Info'!$A$1," ",CHAR(10),'Bundle Tag Info'!$A$2," ",'Bundle Tag Info'!$A$3,CHAR(10),'Bundle Tag Info'!E$6,CHAR(10),'Bundle Tag Info'!E$19),"") | F14: =IF('Bundle Tag Info'!F$19<>"",CONCATENATE('Bundle Tag Info'!$A$1," ",CHAR(10),'Bundle Tag Info'!$A$2," ",'Bundle Tag Info'!$A$3,CHAR(10),'Bundle Tag Info'!F$6,CHAR(10),'Bundle Tag Info'!F$19),"") | G14: =IF('Bundle Tag Info'!G$19<>"",CONCATENATE('Bundle Tag Info'!$A$1," ",CHAR(10),'Bundle Tag Info'!$A$2," ",'Bundle Tag Info'!$A$3,CHAR(10),'Bundle Tag Info'!G$6,CHAR(10),'Bundle Tag Info'!G$19),"") | H14: =IF('Bundle Tag Info'!H$19<>"",CONCATENATE('Bundle Tag Info'!$A$1," ",CHAR(10),'Bundle Tag Info'!$A$2," ",'Bundle Tag Info'!$A$3,CHAR(10),'Bundle Tag Info'!H$6,CHAR(10),'Bundle Tag Info'!H$19),"") | ... AD14: =IF('Bundle Tag Info'!AD$19<>"",CONCATENATE('Bundle Tag Info'!$A$1," ",CHAR(10),'Bundle Tag Info'!$A$2," ",'Bundle Tag Info'!$A$3,CHAR(10),'Bundle Tag Info'!AD$6,CHAR(10),'Bundle Tag Info'!AD$19),"")
A15: =IF('Bundle Tag Info'!A$20<>"",CONCATENATE('Bundle Tag Info'!$A$1," ",CHAR(10),'Bundle Tag Info'!$A$2," ",'Bundle Tag Info'!$A$3,CHAR(10),'Bundle Tag Info'!A$6,CHAR(10),'Bundle Tag Info'!A$20),"") | B15: =IF('Bundle Tag Info'!B$20<>"",CONCATENATE('Bundle Tag Info'!$A$1," ",CHAR(10),'Bundle Tag Info'!$A$2," ",'Bundle Tag Info'!$A$3,CHAR(10),'Bundle Tag Info'!B$6,CHAR(10),'Bundle Tag Info'!B$20),"") | C15: =IF('Bundle Tag Info'!C$20<>"",CONCATENATE('Bundle Tag Info'!$A$1," ",CHAR(10),'Bundle Tag Info'!$A$2," ",'Bundle Tag Info'!$A$3,CHAR(10),'Bundle Tag Info'!C$6,CHAR(10),'Bundle Tag Info'!C$20),"") | D15: =IF('Bundle Tag Info'!D$20<>"",CONCATENATE('Bundle Tag Info'!$A$1," ",CHAR(10),'Bundle Tag Info'!$A$2," ",'Bundle Tag Info'!$A$3,CHAR(10),'Bundle Tag Info'!D$6,CHAR(10),'Bundle Tag Info'!D$20),"") -> NNG-BUL 4K932 B.2 A KT L/S-B | E15: =IF('Bundle Tag Info'!E$20<>"",CONCATENATE('Bundle Tag Info'!$A$1," ",CHAR(10),'Bundle Tag Info'!$A$2," ",'Bundle Tag Info'!$A$3,CHAR(10),'Bundle Tag Info'!E$6,CHAR(10),'Bundle Tag Info'!E$20),"") | F15: =IF('Bundle Tag Info'!F$20<>"",CONCATENATE('Bundle Tag Info'!$A$1," ",CHAR(10),'Bundle Tag Info'!$A$2," ",'Bundle Tag Info'!$A$3,CHAR(10),'Bundle Tag Info'!F$6,CHAR(10),'Bundle Tag Info'!F$20),"") | G15: =IF('Bundle Tag Info'!G$20<>"",CONCATENATE('Bundle Tag Info'!$A$1," ",CHAR(10),'Bundle Tag Info'!$A$2," ",'Bundle Tag Info'!$A$3,CHAR(10),'Bundle Tag Info'!G$6,CHAR(10),'Bundle Tag Info'!G$20),"") | H15: =IF('Bundle Tag Info'!H$20<>"",CONCATENATE('Bundle Tag Info'!$A$1," ",CHAR(10),'Bundle Tag Info'!$A$2," ",'Bundle Tag Info'!$A$3,CHAR(10),'Bundle Tag Info'!H$6,CHAR(10),'Bundle Tag Info'!H$20),"") | ... AD15: =IF('Bundle Tag Info'!AD$20<>"",CONCATENATE('Bundle Tag Info'!$A$1," ",CHAR(10),'Bundle Tag Info'!$A$2," ",'Bundle Tag Info'!$A$3,CHAR(10),'Bundle Tag Info'!AD$6,CHAR(10),'Bundle Tag Info'!AD$20),"")
A16: =IF('Bundle Tag Info'!A$21<>"",CONCATENATE('Bundle Tag Info'!$A$1," ",CHAR(10),'Bundle Tag Info'!$A$2," ",'Bundle Tag Info'!$A$3,CHAR(10),'Bundle Tag Info'!A$6,CHAR(10),'Bundle Tag Info'!A$21),"") | B16: =IF('Bundle Tag Info'!B$21<>"",CONCATENATE('Bundle Tag Info'!$A$1," ",CHAR(10),'Bundle Tag Info'!$A$2," ",'Bundle Tag Info'!$A$3,CHAR(10),'Bundle Tag Info'!B$6,CHAR(10),'Bundle Tag Info'!B$21),"") | C16: =IF('Bundle Tag Info'!C$21<>"",CONCATENATE('Bundle Tag Info'!$A$1," ",CHAR(10),'Bundle Tag Info'!$A$2," ",'Bundle Tag Info'!$A$3,CHAR(10),'Bundle Tag Info'!C$6,CHAR(10),'Bundle Tag Info'!C$21),"") | D16: =IF('Bundle Tag Info'!D$21<>"",CONCATENATE('Bundle Tag Info'!$A$1," ",CHAR(10),'Bundle Tag Info'!$A$2," ",'Bundle Tag Info'!$A$3,CHAR(10),'Bundle Tag Info'!D$6,CHAR(10),'Bundle Tag Info'!D$21),"") -> NNG-BUL 4K932 B.2 A KT R/S-B | E16: =IF('Bundle Tag Info'!E$21<>"",CONCATENATE('Bundle Tag Info'!$A$1," ",CHAR(10),'Bundle Tag Info'!$A$2," ",'Bundle Tag Info'!$A$3,CHAR(10),'Bundle Tag Info'!E$6,CHAR(10),'Bundle Tag Info'!E$21),"") | F16: =IF('Bundle Tag Info'!F$21<>"",CONCATENATE('Bundle Tag Info'!$A$1," ",CHAR(10),'Bundle Tag Info'!$A$2," ",'Bundle Tag Info'!$A$3,CHAR(10),'Bundle Tag Info'!F$6,CHAR(10),'Bundle Tag Info'!F$21),"") | G16: =IF('Bundle Tag Info'!G$21<>"",CONCATENATE('Bundle Tag Info'!$A$1," ",CHAR(10),'Bundle Tag Info'!$A$2," ",'Bundle Tag Info'!$A$3,CHAR(10),'Bundle Tag Info'!G$6,CHAR(10),'Bundle Tag Info'!G$21),"") | H16: =IF('Bundle Tag Info'!H$21<>"",CONCATENATE('Bundle Tag Info'!$A$1," ",CHAR(10),'Bundle Tag Info'!$A$2," ",'Bundle Tag Info'!$A$3,CHAR(10),'Bundle Tag Info'!H$6,CHAR(10),'Bundle Tag Info'!H$21),"") | ... AD16: =IF('Bundle Tag Info'!AD$21<>"",CONCATENATE('Bundle Tag Info'!$A$1," ",CHAR(10),'Bundle Tag Info'!$A$2," ",'Bundle Tag Info'!$A$3,CHAR(10),'Bundle Tag Info'!AD$6,CHAR(10),'Bundle Tag Info'!AD$21),"")
A17: =IF('Bundle Tag Info'!A$22<>"",CONCATENATE('Bundle Tag Info'!$A$1," ",CHAR(10),'Bundle Tag Info'!$A$2," ",'Bundle Tag Info'!$A$3,CHAR(10),'Bundle Tag Info'!A$6,CHAR(10),'Bundle Tag Info'!A$22),"") | B17: =IF('Bundle Tag Info'!B$22<>"",CONCATENATE('Bundle Tag Info'!$A$1," ",CHAR(10),'Bundle Tag Info'!$A$2," ",'Bundle Tag Info'!$A$3,CHAR(10),'Bundle Tag Info'!B$6,CHAR(10),'Bundle Tag Info'!B$22),"") | C17: =IF('Bundle Tag Info'!C$22<>"",CONCATENATE('Bundle Tag Info'!$A$1," ",CHAR(10),'Bundle Tag Info'!$A$2," ",'Bundle Tag Info'!$A$3,CHAR(10),'Bundle Tag Info'!C$6,CHAR(10),'Bundle Tag Info'!C$22),"") | D17: =IF('Bundle Tag Info'!D$22<>"",CONCATENATE('Bundle Tag Info'!$A$1," ",CHAR(10),'Bundle Tag Info'!$A$2," ",'Bundle Tag Info'!$A$3,CHAR(10),'Bundle Tag Info'!D$6,CHAR(10),'Bundle Tag Info'!D$22),"") -> NNG-BUL 4K932 B.2 A UA-B | E17: =IF('Bundle Tag Info'!E$22<>"",CONCATENATE('Bundle Tag Info'!$A$1," ",CHAR(10),'Bundle Tag Info'!$A$2," ",'Bundle Tag Info'!$A$3,CHAR(10),'Bundle Tag Info'!E$6,CHAR(10),'Bundle Tag Info'!E$22),"") | F17: =IF('Bundle Tag Info'!F$22<>"",CONCATENATE('Bundle Tag Info'!$A$1," ",CHAR(10),'Bundle Tag Info'!$A$2," ",'Bundle Tag Info'!$A$3,CHAR(10),'Bundle Tag Info'!F$6,CHAR(10),'Bundle Tag Info'!F$22),"") | G17: =IF('Bundle Tag Info'!G$22<>"",CONCATENATE('Bundle Tag Info'!$A$1," ",CHAR(10),'Bundle Tag Info'!$A$2," ",'Bundle Tag Info'!$A$3,CHAR(10),'Bundle Tag Info'!G$6,CHAR(10),'Bundle Tag Info'!G$22),"") | H17: =IF('Bundle Tag Info'!H$22<>"",CONCATENATE('Bundle Tag Info'!$A$1," ",CHAR(10),'Bundle Tag Info'!$A$2," ",'Bundle Tag Info'!$A$3,CHAR(10),'Bundle Tag Info'!H$6,CHAR(10),'Bundle Tag Info'!H$22),"") | ... AD17: =IF('Bundle Tag Info'!AD$22<>"",CONCATENATE('Bundle Tag Info'!$A$1," ",CHAR(10),'Bundle Tag Info'!$A$2," ",'Bundle Tag Info'!$A$3,CHAR(10),'Bundle Tag Info'!AD$6,CHAR(10),'Bundle Tag Info'!AD$22),"")
A18: =IF('Bundle Tag Info'!A$23<>"",CONCATENATE('Bundle Tag Info'!$A$1," ",CHAR(10),'Bundle Tag Info'!$A$2," ",'Bundle Tag Info'!$A$3,CHAR(10),'Bundle Tag Info'!A$6,CHAR(10),'Bundle Tag Info'!A$23),"") | B18: =IF('Bundle Tag Info'!B$23<>"",CONCATENATE('Bundle Tag Info'!$A$1," ",CHAR(10),'Bundle Tag Info'!$A$2," ",'Bundle Tag Info'!$A$3,CHAR(10),'Bundle Tag Info'!B$6,CHAR(10),'Bundle Tag Info'!B$23),"") | C18: =IF('Bundle Tag Info'!C$23<>"",CONCATENATE('Bundle Tag Info'!$A$1," ",CHAR(10),'Bundle Tag Info'!$A$2," ",'Bundle Tag Info'!$A$3,CHAR(10),'Bundle Tag Info'!C$6,CHAR(10),'Bundle Tag Info'!C$23),"") | D18: =IF('Bundle Tag Info'!D$23<>"",CONCATENATE('Bundle Tag Info'!$A$1," ",CHAR(10),'Bundle Tag Info'!$A$2," ",'Bundle Tag Info'!$A$3,CHAR(10),'Bundle Tag Info'!D$6,CHAR(10),'Bundle Tag Info'!D$23),"") -> NNG-BUL 4K932 B.2 A FU/XT-B | E18: =IF('Bundle Tag Info'!E$23<>"",CONCATENATE('Bundle Tag Info'!$A$1," ",CHAR(10),'Bundle Tag Info'!$A$2," ",'Bundle Tag Info'!$A$3,CHAR(10),'Bundle Tag Info'!E$6,CHAR(10),'Bundle Tag Info'!E$23),"") | F18: =IF('Bundle Tag Info'!F$23<>"",CONCATENATE('Bundle Tag Info'!$A$1," ",CHAR(10),'Bundle Tag Info'!$A$2," ",'Bundle Tag Info'!$A$3,CHAR(10),'Bundle Tag Info'!F$6,CHAR(10),'Bundle Tag Info'!F$23),"") | G18: =IF('Bundle Tag Info'!G$23<>"",CONCATENATE('Bundle Tag Info'!$A$1," ",CHAR(10),'Bundle Tag Info'!$A$2," ",'Bundle Tag Info'!$A$3,CHAR(10),'Bundle Tag Info'!G$6,CHAR(10),'Bundle Tag Info'!G$23),"") | H18: =IF('Bundle Tag Info'!H$23<>"",CONCATENATE('Bundle Tag Info'!$A$1," ",CHAR(10),'Bundle Tag Info'!$A$2," ",'Bundle Tag Info'!$A$3,CHAR(10),'Bundle Tag Info'!H$6,CHAR(10),'Bundle Tag Info'!H$23),"") | ... AD18: =IF('Bundle Tag Info'!AD$23<>"",CONCATENATE('Bundle Tag Info'!$A$1," ",CHAR(10),'Bundle Tag Info'!$A$2," ",'Bundle Tag Info'!$A$3,CHAR(10),'Bundle Tag Info'!AD$6,CHAR(10),'Bundle Tag Info'!AD$23),"")
A19: =IF('Bundle Tag Info'!A$24<>"",CONCATENATE('Bundle Tag Info'!$A$1," ",CHAR(10),'Bundle Tag Info'!$A$2," ",'Bundle Tag Info'!$A$3,CHAR(10),'Bundle Tag Info'!A$6,CHAR(10),'Bundle Tag Info'!A$24),"") | B19: =IF('Bundle Tag Info'!B$24<>"",CONCATENATE('Bundle Tag Info'!$A$1," ",CHAR(10),'Bundle Tag Info'!$A$2," ",'Bundle Tag Info'!$A$3,CHAR(10),'Bundle Tag Info'!B$6,CHAR(10),'Bundle Tag Info'!B$24),"") | C19: =IF('Bundle Tag Info'!C$24<>"",CONCATENATE('Bundle Tag Info'!$A$1," ",CHAR(10),'Bundle Tag Info'!$A$2," ",'Bundle Tag Info'!$A$3,CHAR(10),'Bundle Tag Info'!C$6,CHAR(10),'Bundle Tag Info'!C$24),"") | D19: =IF('Bundle Tag Info'!D$24<>"",CONCATENATE('Bundle Tag Info'!$A$1," ",CHAR(10),'Bundle Tag Info'!$A$2," ",'Bundle Tag Info'!$A$3,CHAR(10),'Bundle Tag Info'!D$6,CHAR(10),'Bundle Tag Info'!D$24),"") | E19: =IF('Bundle Tag Info'!E$24<>"",CONCATENATE('Bundle Tag Info'!$A$1," ",CHAR(10),'Bundle Tag Info'!$A$2," ",'Bundle Tag Info'!$A$3,CHAR(10),'Bundle Tag Info'!E$6,CHAR(10),'Bundle Tag Info'!E$24),"") | F19: =IF('Bundle Tag Info'!F$24<>"",CONCATENATE('Bundle Tag Info'!$A$1," ",CHAR(10),'Bundle Tag Info'!$A$2," ",'Bundle Tag Info'!$A$3,CHAR(10),'Bundle Tag Info'!F$6,CHAR(10),'Bundle Tag Info'!F$24),"") | G19: =IF('Bundle Tag Info'!G$24<>"",CONCATENATE('Bundle Tag Info'!$A$1," ",CHAR(10),'Bundle Tag Info'!$A$2," ",'Bundle Tag Info'!$A$3,CHAR(10),'Bundle Tag Info'!G$6,CHAR(10),'Bundle Tag Info'!G$24),"") | H19: =IF('Bundle Tag Info'!H$24<>"",CONCATENATE('Bundle Tag Info'!$A$1," ",CHAR(10),'Bundle Tag Info'!$A$2," ",'Bundle Tag Info'!$A$3,CHAR(10),'Bundle Tag Info'!H$6,CHAR(10),'Bundle Tag Info'!H$24),"") | ... AD19: =IF('Bundle Tag Info'!AD$24<>"",CONCATENATE('Bundle Tag Info'!$A$1," ",CHAR(10),'Bundle Tag Info'!$A$2," ",'Bundle Tag Info'!$A$3,CHAR(10),'Bundle Tag Info'!AD$6,CHAR(10),'Bundle Tag Info'!AD$24),"")
A20: =IF('Bundle Tag Info'!A$25<>"",CONCATENATE('Bundle Tag Info'!$A$1," ",CHAR(10),'Bundle Tag Info'!$A$2," ",'Bundle Tag Info'!$A$3,CHAR(10),'Bundle Tag Info'!A$6,CHAR(10),'Bundle Tag Info'!A$25),"") | B20: =IF('Bundle Tag Info'!B$25<>"",CONCATENATE('Bundle Tag Info'!$A$1," ",CHAR(10),'Bundle Tag Info'!$A$2," ",'Bundle Tag Info'!$A$3,CHAR(10),'Bundle Tag Info'!B$6,CHAR(10),'Bundle Tag Info'!B$25),"") | C20: =IF('Bundle Tag Info'!C$25<>"",CONCATENATE('Bundle Tag Info'!$A$1," ",CHAR(10),'Bundle Tag Info'!$A$2," ",'Bundle Tag Info'!$A$3,CHAR(10),'Bundle Tag Info'!C$6,CHAR(10),'Bundle Tag Info'!C$25),"") | D20: =IF('Bundle Tag Info'!D$25<>"",CONCATENATE('Bundle Tag Info'!$A$1," ",CHAR(10),'Bundle Tag Info'!$A$2," ",'Bundle Tag Info'!$A$3,CHAR(10),'Bundle Tag Info'!D$6,CHAR(10),'Bundle Tag Info'!D$25),"") | E20: =IF('Bundle Tag Info'!E$25<>"",CONCATENATE('Bundle Tag Info'!$A$1," ",CHAR(10),'Bundle Tag Info'!$A$2," ",'Bundle Tag Info'!$A$3,CHAR(10),'Bundle Tag Info'!E$6,CHAR(10),'Bundle Tag Info'!E$25),"") | F20: =IF('Bundle Tag Info'!F$25<>"",CONCATENATE('Bundle Tag Info'!$A$1," ",CHAR(10),'Bundle Tag Info'!$A$2," ",'Bundle Tag Info'!$A$3,CHAR(10),'Bundle Tag Info'!F$6,CHAR(10),'Bundle Tag Info'!F$25),"") | G20: =IF('Bundle Tag Info'!G$25<>"",CONCATENATE('Bundle Tag Info'!$A$1," ",CHAR(10),'Bundle Tag Info'!$A$2," ",'Bundle Tag Info'!$A$3,CHAR(10),'Bundle Tag Info'!G$6,CHAR(10),'Bundle Tag Info'!G$25),"") | H20: =IF('Bundle Tag Info'!H$25<>"",CONCATENATE('Bundle Tag Info'!$A$1," ",CHAR(10),'Bundle Tag Info'!$A$2," ",'Bundle Tag Info'!$A$3,CHAR(10),'Bundle Tag Info'!H$6,CHAR(10),'Bundle Tag Info'!H$25),"") | ... AD20: =IF('Bundle Tag Info'!AD$25<>"",CONCATENATE('Bundle Tag Info'!$A$1," ",CHAR(10),'Bundle Tag Info'!$A$2," ",'Bundle Tag Info'!$A$3,CHAR(10),'Bundle Tag Info'!AD$6,CHAR(10),'Bundle Tag Info'!AD$25),"")
