Workbook

Sheet JB70_S
A1: JB70
A2: CONTROL,JB70
A3: Project # | B3: 4P441
A4: Project Name | B4: Pallette Compressor Station
A5: Revision | B5: B
A7: Controls DE | B7: A. CHEN
A8: Phone:
A9: Controls ME | B9: A. PLVAN
A10: Phone:
A12: From | G12: To
A13: Device ID | B13: Wire No. | C13: Wire ID | D13: Gauge/Size | E13: Length | F13: Device ID | G13: Location | H13: Bundle Name
A14: AT1100:NEG | B14: -0V | C14: WHT | D14: 14 | E14: 120 | F14: XT0111:22 | G14: JB70 RIGHT RAIL | H14: AT
A15: AT1100:POS | B15: FU1100 | C15: WHT | D15: 14 | E15: 120 | F15: FU1100:LD | G15: JB70 RIGHT RAIL
A17: SA0474:B1-13 | B17: SA0474B113 | C17: WHT | D17: 20 | E17: 180 | F17: AF0087:45 | G17: PANEL A | H17: SA0474
A18: SA0474:B1-14 | B18: SA0474B114 | C18: WHT | D18: 20 | E18: 180 | F18: AF0087:13 | G18: PANEL A
A19: SA0474:B2-13 | B19: SA0474B213 | C19: WHT | D19: 20 | E19: 180 | F19: AF0087:44 | G19: PANEL A
A20: SA0474:B2-14 | B20: SA0474B214 | C20: WHT | D20: 20 | E20: 180 | F20: AF0087:12 | G20: PANEL A
A22: SA0471:B1-13 | B22: SA0471B113 | C22: WHT | D22: 20 | E22: 180 | F22: AF0087:40 | G22: PANEL A | H22: SA0471
A23: SA0471:B1-14 | B23: SA0471B114 | C23: WHT | D23: 20 | E23: 180 | F23: AF0087:08 | G23: PANEL A
A24: SA0471:B2-13 | B24: SA0471B213 | C24: WHT | D24: 20 | E24: 180 | F24: AF0087:39 | G24: PANEL A
A25: SA0471:B2-14 | B25: SA0471B214 | C25: WHT | D25: 20 | E25: 180 | F25: AF0087:07 | G25: PANEL A
A27: SA0473:11 | B27: SA047311 | C27: WHT | D27: 20 | E27: 180 | F27: AF0087:37 | G27: PANEL A | H27: SA0473
A28: SA0473:12 | B28: SA047312 | C28: WHT | D28: 20 | E28: 180 | F28: AF0087:05 | G28: PANEL A
A29: SA0473:13 | B29: SA047313 | C29: WHT | D29: 20 | E29: 180 | F29: AF0087:38 | G29: PANEL A
A30: SA0473:14 | B30: SA047314 | C30: WHT | D30: 20 | E30: 180 | F30: AF0087:06 | G30: PANEL A
A32: SH0472:11 | B32: SH047211 | C32: WHT | D32: 20 | E32: 140 | F32: XT0111:13 | G32: JB70 RIGHT RAIL | H32: SH0472
A33: SH0472:12 | B33: SH047212 | C33: WHT | D33: 20 | E33: 140 | F33: XT0111:14 | G33: JB70 RIGHT RAIL
A34: SH0472:13 | B34: FU0139 | C34: WHT | D34: 20 | E34: 140 | F34: XT0111:15 | G34: JB70 RIGHT RAIL
A35: SH0472:14 | B35: KA0241A1 | C35: WHT | D35: 20 | E35: 140 | F35: XT0111:16 | G35: JB70 RIGHT RAIL
A36: SH0472:X1 | B36: SH0472X1 | C36: WHT | D36: 20 | E36: 140 | F36: XT0111:18 | G36: JB70 RIGHT RAIL
A37: SH0472:X2 | B37: SH0472X2 | C37: WHT | D37: 20 | E37: 140 | F37: XT0111:17 | G37: JB70 RIGHT RAIL
A39: SH0471:11 | B39: SH047111 | C39: WHT | D39: 20 | E39: 140 | F39: XT0111:1 | G39: JB70 RIGHT RAIL | H39: SH0471
A40: SH0471:12 | B40: SH047112 | C40: WHT | D40: 20 | E40: 140 | F40: XT0111:2 | G40: JB70 RIGHT RAIL
A41: SH0471:13 | B41: SH047113 | C41: WHT | D41: 20 | E41: 140 | F41: XT0111:3 | G41: JB70 RIGHT RAIL
A42: SH0471:14 | B42: SH047114 | C42: WHT | D42: 20 | E42: 140 | F42: XT0111:4 | G42: JB70 RIGHT RAIL
A43: SH0471:X1 | B43: SH0471X1 | C43: WHT | D43: 20 | E43: 140 | F43: XT0111:6 | G43: JB70 RIGHT RAIL
A44: SH0471:X2 | B44: SH0471X2 | C44: WHT | D44: 20 | E44: 140 | F44: XT0111:5 | G44: JB70 RIGHT RAIL
A46: SH0470:11 | B46: SH047011 | C46: WHT | D46: 20 | E46: 140 | F46: XT0111:7 | G46: JB70 RIGHT RAIL | H46: SH0470
A47: SH0470:12 | B47: SH047012 | C47: WHT | D47: 20 | E47: 140 | F47: XT0111:8 | G47: JB70 RIGHT RAIL
A48: SH0470:13 | B48: SH047013 | C48: WHT | D48: 20 | E48: 140 | F48: XT0111:9 | G48: JB70 RIGHT RAIL
...

Sheet RAIL,LEFT,JB70_S
A1: RAIL,LEFT,JB70
A2: TURBINE CONTROL BOX, LEFT RAIL
A3: Project # | B3: 4P441
A4: Project Name | B4: Pallette Compressor Station
A5: Revision | B5: B
A7: Controls DE | B7: A. CHEN
A8: Phone:
A9: Controls ME | B9: A. PLVAN
A10: Phone:
A12: From | G12: To
A13: Device ID | B13: Wire No. | C13: Wire ID | D13: Gauge/Size | E13: Length | F13: Device ID | G13: Location | H13: Bundle Name
A14: AT0175:17 | B14: AT017517 | C14: WHT | D14: 20 | E14: 120 | F14: XT0173:2 | G14: RAIL,LEFT,JB70 | H14: AT
A15: AT0175:18 | B15: HL0171X1 | C15: WHT | D15: 20 | E15: 120 | F15: XT0173:3 | G15: RAIL,LEFT,JB70
A16: AT0175:2 | B16: SB017013 | C16: WHT | D16: 20 | E16: 120 | F16: XT0173:12 | G16: RAIL,LEFT,JB70
A17: AT0175:20 | B17: AT017520 | C17: WHT | D17: 20 | E17: 120 | F17: XT0173:5 | G17: RAIL,LEFT,JB70
A18: AT0175:21 | B18: HL0172X1 | C18: WHT | D18: 20 | E18: 120 | F18: XT0173:6 | G18: RAIL,LEFT,JB70
A19: AT0175:23 | B19: AT017523 | C19: WHT | D19: 20 | E19: 120 | F19: XT0173:8 | G19: RAIL,LEFT,JB70
A20: AT0175:24 | B20: HL0173X1 | C20: WHT | D20: 20 | E20: 120 | F20: XT0173:9 | G20: RAIL,LEFT,JB70
A21: AT0175:3 | B21: SB017014 | C21: WHT | D21: 20 | E21: 120 | F21: XT0173:13 | G21: RAIL,LEFT,JB70
A23: AT0178:23 | B23: AT017823 | C23: WHT | D23: 20 | E23: 120 | F23: XT0171:2 | G23: RAIL,LEFT,JB70
A24: AT0178:24 | B24: AT017824 | C24: WHT | D24: 20 | E24: 120 | F24: XT0171:3 | G24: RAIL,LEFT,JB70
A26: AT0176:4P1 | B26: AT01764P1 | C26: WHT | D26: 14 | E26: 60 | F26: AT0178:1P1 | G26: RAIL,LEFT,JB70
A27: AT0176:5P1 | B27: AT01765P1 | C27: WHT | D27: 14 | E27: 60 | F27: AT0178:2P1 | G27: RAIL,LEFT,JB70
A29: KA0178:A1 | B29: KA0178A1 | C29: WHT | D29: 20 | E29: 120 | F29: XT0171:1 | G29: RAIL,LEFT,JB70 | H29: KA
A30: KA0178:A2 | B30: AT017824 | C30: WHT | D30: 20 | E30: 120 | F30: XT0171:3 | G30: RAIL,LEFT,JB70
A31: KA6510:12 | B31: KA651012 | C31: WHT | D31: 20 | E31: 140 | F31: AT0175:11 | G31: RAIL,LEFT,JB70
A32: KA6510:A2 | B32: KA6510A2 | C32: WHT | D32: 20 | E32: 140 | F32: AT0175:5P1 | G32: RAIL,LEFT,JB70
A34: XT0171:4 | B34: FU0170 | C34: WHT | D34: 14 | E34: 60 | F34: XT0173:24 | G34: RAIL,LEFT,JB70 | H34: XT/FU
A35: XT0171:5 | B35: -0V | C35: WHT | D35: 14 | E35: 60 | F35: XT0173:25 | G35: RAIL,LEFT,JB70
A36: XT0171:6 | B36: LON1S2 | C36: WHT | D36: 14 | E36: 60 | F36: XT0173:23 | G36: RAIL,LEFT,JB70
A38: FU0294:LI | B38: FU0535 | C38: WHT | D38: 12 | E38: 120 | F38: XT0535:4 | G38: RAIL,LEFT,JB70
A39: FU0295:LI | B39: FU0535 | C39: WHT | D39: 12 | E39: 120 | F39: XT0535:5 | G39: RAIL,LEFT,JB70
A40: FU0535:LD | B40: FU0535 | C40: WHT | D40: 12 | E40: 60 | F40: XT0535:1 | G40: RAIL,LEFT,JB70
A42: XT0173:3 | B42: HL0171X1 | C42: WHT | D42: 20 | E42: 160 | F42: HL0171:X1 | G42: JB70 | H42: RAIL - JB70
A43: XT0173:1 | B43: HL0171X2 | C43: WHT | D43: 20 | E43: 160 | F43: HL0171:X2 | G43: JB70
A44: XT0173:6 | B44: HL0172X1 | C44: WHT | D44: 20 | E44: 160 | F44: HL0172:X1 | G44: JB70
A45: XT0173:4 | B45: HL0172X2 | C45: WHT | D45: 20 | E45: 160 | F45: HL0172:X2 | G45: JB70
A46: XT0173:9 | B46: HL0173X1 | C46: WHT | D46: 20 | E46: 160 | F46: HL0173:X1 | G46: JB70
A47: XT0173:7 | B47: HL0173X2 | C47: WHT | D47: 20 | E47: 160 | F47: HL0173:X2 | G47: JB70
A48: XT0173:10 | B48: SA0170B113 | C48: WHT | D48: 20 | E48: 160 | F48: SA0170:B1-13 | G48: JB70
...

Sheet FIRE PANEL_S
A1: FIRE PANEL
A2: CONTROL CONSOLE DOOR^(FIRE SYSTEM PANEL)
A3: Project # | B3: 4P441
A4: Project Name | B4: Pallette Compressor Station
A5: Revision | B5: B
A7: Controls DE | B7: A. CHEN
A8: Phone:
A9: Controls ME | B9: A. PLVAN
A10: Phone:
A12: From | G12: To
A13: Device ID | B13: Wire No. | C13: Wire ID | D13: Gauge/Size | E13: Length | F13: Device ID | G13: Location | H13: Bundle Name
A14: AT0170:24 | B14: FU0172 | C14: WHT | D14: 20 | E14: 60 | F14: XT0170:5 | G14: FIRE PANEL | H14: AT
A15: AT0170:30 | B15: FU0172 | C15: WHT | D15: 20 | E15: 60 | F15: XT0170:5 | G15: FIRE PANEL
A16: FU0172:LD | B16: FU0172 | C16: WHT | D16: 16 | E16: 60 | F16: XT0170:5 | G16: FIRE PANEL
A17: AT0170:1 | B17: UV01705 | C17: WHT | D17: 14 | E17: 60 | F17: UV0170:5(+) | G17: FIRE PANEL
A18: AT0170:2 | B18: UV01706 | C18: WHT | D18: 14 | E18: 60 | F18: UV0170:6(-) | G18: FIRE PANEL
A19: AT0170:3 | B19: UV01707 | C19: WHT | D19: 14 | E19: 60 | F19: UV0170:7(+) | G19: FIRE PANEL
A20: AT0170:4 | B20: UV01708 | C20: WHT | D20: 14 | E20: 60 | F20: UV0170:8(-) | G20: FIRE PANEL
A22: FU0170:LI | B22: FU0535 | C22: WHT | D22: 14 | E22: 60 | F22: XT0170:2 | G22: FIRE PANEL | H22: FU/UV
A23: FU0171:LD | B23: FU0171 | C23: WHT | D23: 14 | E23: 60 | F23: UV0170:1(+) | G23: FIRE PANEL
A24: FU0171:LD | B24: FU0171 | C24: WHT | D24: 14 | E24: 60 | F24: UV0170:3(+) | G24: FIRE PANEL
A25: FU0171:LI | B25: FU0535 | C25: WHT | D25: 14 | E25: 60 | F25: XT0170:2 | G25: FIRE PANEL
A26: FU0172:LI | B26: FU0535 | C26: WHT | D26: 14 | E26: 60 | F26: XT0170:1 | G26: FIRE PANEL
A27: UV0170:2(-) | B27: -0V | C27: WHT | D27: 14 | E27: 60 | F27: XT0170:3 | G27: FIRE PANEL
A28: UV0170:4(-) | B28: -0V | C28: WHT | D28: 14 | E28: 60 | F28: XT0170:3 | G28: FIRE PANEL

Sheet RAIL,RIGHT,JB70_S
A1: JB70 RIGHT RAIL
A2: TURBINE CONTROL BOX, RIGHT RAIL
A3: Project # | B3: 4P441
A4: Project Name | B4: Pallette Compressor Station
A5: Revision | B5: B
A7: Controls DE | B7: A. CHEN
A8: Phone:
A9: Controls ME | B9: A. PLVAN
A10: Phone:
A12: From | G12: To
A13: Device ID | B13: Wire No. | C13: Wire ID | D13: Gauge/Size | E13: Length | F13: Device ID | G13: Location | H13: Bundle Name
A14: BA0001:V1(-) | B14: -0V | C14: WHT | D14: 16 | E14: 60 | F14: XT0051:5 | G14: JB70 RIGHT RAIL | H14: BA
A15: BA0001:V1(+) | B15: FU0021 | C15: WHT | D15: 16 | E15: 60 | F15: FU0021:LD | G15: JB70 RIGHT RAIL
A16: BA0002:V1(-) | B16: -0V | C16: WHT | D16: 16 | E16: 60 | F16: XT0051:6 | G16: JB70 RIGHT RAIL
A17: BA0002:V1(+) | B17: FU0022 | C17: WHT | D17: 16 | E17: 60 | F17: FU0022:LD | G17: JB70 RIGHT RAIL
A18: BA0009:V1(-) | B18: -0V | C18: WHT | D18: 16 | E18: 60 | F18: XT0051:7 | G18: JB70 RIGHT RAIL
A19: BA0009:V1(+) | B19: FU0029 | C19: WHT | D19: 16 | E19: 60 | F19: FU0029:LD | G19: JB70 RIGHT RAIL
A20: BA1100:NEG | B20: BA1100N | C20: WHT | D20: 16 | E20: 80 | F20: UJ1100:OUT1(-) | G20: JB70 RIGHT RAIL
A21: BA1100:POS | B21: BA1100P | C21: WHT | D21: 16 | E21: 80 | F21: UJ1100:OUT1(+) | G21: JB70 RIGHT RAIL
A23: FU0021:LI | B23: FU0136 | C23: WHT | D23: 16 | E23: 60 | F23: XT0051:1 | G23: JB70 RIGHT RAIL | H23: FU/UJ
A24: FU0022:LI | B24: FU0136 | C24: WHT | D24: 16 | E24: 60 | F24: XT0051:2 | G24: JB70 RIGHT RAIL
A25: FU0029:LI | B25: FU0136 | C25: WHT | D25: 16 | E25: 60 | F25: XT0051:3 | G25: JB70 RIGHT RAIL
A26: UJ1100:24V(-) | B26: -0V | C26: WHT | D26: 16 | E26: 80 | F26: XT0111:22 | G26: JB70 RIGHT RAIL
A28: FU1100:LI | B28: FU0136 | C28: WHT | D28: 14 | E28: 60 | F28: XT0111:21 | G28: JB70 RIGHT RAIL
A30: XT0111:4 | B30: SH047114 | C30: WHT | D30: 20 | E30: 140 | F30: AF0087:00 | G30: PANEL A | H30: XT - AF A
A31: XT0111:8 | B31: SH047012 | C31: WHT | D31: 20 | E31: 140 | F31: AF0087:01 | G31: PANEL A
A32: XT0111:3 | B32: SH047113 | C32: WHT | D32: 20 | E32: 140 | F32: AF0087:32 | G32: PANEL A
A33: XT0111:7 | B33: SH047011 | C33: WHT | D33: 20 | E33: 140 | F33: AF0087:33 | G33: PANEL A
A35: XT0111:17 | B35: SH0472X2 | C35: WHT | D35: 20 | E35: 140 | F35: AF0092:13 | G35: PANEL A
A36: XT0111:24 | B36: HA047201 | C36: WHT | D36: 20 | E36: 140 | F36: AF0092:28 | G36: PANEL A
A37: XT0111:18 | B37: SH0472X1 | C37: WHT | D37: 20 | E37: 140 | F37: AF0092:29 | G37: PANEL A
A38: XT0111:11 | B38: SH0470X2 | C38: WHT | D38: 20 | E38: 140 | F38: AF0093:06 | G38: PANEL A
A39: XT0111:5 | B39: SH0471X2 | C39: WHT | D39: 20 | E39: 140 | F39: AF0093:15 | G39: PANEL A
A40: XT0111:12 | B40: SH0470X1 | C40: WHT | D40: 20 | E40: 140 | F40: AF0093:22 | G40: PANEL A
A41: XT0111:6 | B41: SH0471X1 | C41: WHT | D41: 20 | E41: 140 | F41: AF0093:31 | G41: PANEL A
A43: UJ1100:24V(+) | B43: FU1101LD | C43: WHT | D43: 16 | E43: 160 | F43: FU1101:LD | G43: PANEL A | H43: XT/UJ - A
A44: XT0111:21 | B44: FU0136 | C44: WHT | D44: 14 | E44: 140 | F44: FU1101:LI | G44: PANEL A
A45: XT0111:17 | B45: SH0472X2 | C45: WHT | D45: 20 | E45: 160 | F45: KA0240:21 | G45: PANEL A
A46: XT0111:23 | B46: HA047202 | C46: WHT | D46: 20 | E46: 160 | F46: KA0875:11 | G46: PANEL A
A47: XT0111:24 | B47: HA047201 | C47: WHT | D47: 20 | E47: 160 | F47: KA0875:A2 | G47: PANEL A
...

Sheet PLC_S
A1: PLC
A2: PLC PANEL,JB70
A3: Project # | B3: 4P441
A4: Project Name | B4: Pallette Compressor Station
A5: Revision | B5: B
A7: Controls DE | B7: A. CHEN
A8: Phone:
A9: Controls ME | B9: A. PLVAN
A10: Phone:
A12: From | G12: To
A13: Device ID | B13: Wire No. | C13: Wire ID | D13: Gauge/Size | E13: Length | F13: Device ID | G13: Location | H13: Bundle Name
A14: AT0680:NEG | B14: -0V | C14: WHT | D14: 14 | E14: 60 | F14: XT0680:2 | G14: PLC | H14: PLC
A15: AT0680:POS | B15: AT0680POS | C15: WHT | D15: 14 | E15: 60 | F15: XT0680:1 | G15: PLC
A17: FU0010:LD | B17: FU0010 | C17: WHT | D17: 14 | E17: 60 | F17: UV0600:(+) | G17: PLC
A18: FU0680:LD | B18: AT0680POS | C18: WHT | D18: 14 | E18: 60 | F18: XT0680:1 | G18: PLC
A20: FU0010:LI | B20: FU0136 | C20: WHT | D20: 14 | E20: 120 | F20: XT0002:4 | G20: PANEL A | H20: PLC - A
A21: UV0600:(-) | B21: -0V | C21: WHT | D21: 14 | E21: 120 | F21: XT0003:4 | G21: PANEL A

Sheet PANEL A_S
A1: PANEL A
A2: CONTROL PANEL A,JB70
A3: Project # | B3: 4P441
A4: Project Name | B4: Pallette Compressor Station
A5: Revision | B5: B
A7: Controls DE | B7: A. CHEN
A8: Phone:
A9: Controls ME | B9: A. PLVAN
A10: Phone:
A12: From | G12: To
A13: Device ID | B13: Wire No. | C13: Wire ID | D13: Gauge/Size | E13: Length | F13: Device ID | G13: Location | H13: Bundle Name
A14: UJ0131:OK2 | B14: UJ0131OK2 | C14: WHT | D14: 20 | E14: 60 | F14: AF0091:09 | G14: PANEL A | H14: UJ0131
A15: UJ0131:OK1 | B15: UJ0131OK1 | C15: WHT | D15: 20 | E15: 60 | F15: AF0091:41 | G15: PANEL A
A16: UJ0131:VIN | B16: UJ0131VIN | C16: WHT | D16: 20 | E16: 60 | F16: AF0094:04 | G16: PANEL A
A17: UJ0131:IOUT | B17: UJ0131IOUT | C17: WHT | D17: 20 | E17: 60 | F17: AF0094:06 | G17: PANEL A
A19: UJ0131:- | B19: -521NEG | C19: WHT | D19: 12 | E19: 60 | F19: XT0011:1 | G19: PANEL A
A20: UJ0131:+ | B20: UJ0131P | C20: WHT | D20: 12 | E20: 60 | F20: FU0011:LD | G20: PANEL A
A22: AF0093:12 | B22: -009312 | C22: WHT | D22: 20 | E22: 60 | F22: PC0470:INP_A | G22: PANEL A | H22: AF
A23: AF0093:28 | B23: -009328 | C23: WHT | D23: 20 | E23: 60 | F23: PC0470:-PWR | G23: PANEL A
A24: AF0093:44 | B24: -009344 | C24: WHT | D24: 20 | E24: 60 | F24: PC0470:+PWR | G24: PANEL A
A26: AF0091:COM | B26: AF0091N | C26: WHT | D26: 16 | E26: 60 | F26: AF0094:COM | G26: PANEL A
A27: AF0091:V+ | B27: AF0091P | C27: WHT | D27: 16 | E27: 60 | F27: AF0094:V+ | G27: PANEL A
A28: AU0080:V+ | B28: FU0081 | C28: WHT | D28: 16 | E28: 60 | F28: FU0081:LD | G28: PANEL A
A29: AU0090:V+ | B29: FU0090 | C29: WHT | D29: 16 | E29: 60 | F29: FU0090:LD | G29: PANEL A
A30: AF0092:V+ | B30: FU0091 | C30: WHT | D30: 16 | E30: 60 | F30: FU0091:LD | G30: PANEL A
A31: AF0093:V+ | B31: FU0092 | C31: WHT | D31: 16 | E31: 60 | F31: FU0092:LD | G31: PANEL A
A32: AF0095:V+ | B32: FU0093 | C32: WHT | D32: 16 | E32: 80 | F32: FU0093:LD | G32: PANEL A
A33: AU0080:COM | B33: -0V | C33: WHT | D33: 16 | E33: 60 | F33: XT0080:1 | G33: PANEL A
A34: AF0092:COM | B34: -0V | C34: WHT | D34: 16 | E34: 60 | F34: XT0080:2 | G34: PANEL A
A35: AU0090:COM | B35: -0V | C35: WHT | D35: 16 | E35: 60 | F35: XT0080:2 | G35: PANEL A
... A37: AF0095:COM | B37: -0V | C37: WHT | D37: 16 | E37: 80 | F37: XT0080:4 | G37: PANEL A
A39: KA2160:A1 | B39: KA2160A1 | C39: WHT | D39: 20 | E39: 80 | F39: AF0092:04 | G39: PANEL A | H39: KA A1/2
A40: KA2161:A1 | B40: KA2161A1 | C40: WHT | D40: 20 | E40: 80 | F40: AF0092:07 | G40: PANEL A
A41: KA3103:A1 | B41: KA3103A1 | C41: WHT | D41: 20 | E41: 80 | F41: AF0092:08 | G41: PANEL A
A42: KA0875:A1 | B42: -009212 | C42: WHT | D42: 20 | E42: 60 | F42: AF0092:12 | G42: PANEL A
A43: KA2160:A2 | B43: KA2160A2 | C43: WHT | D43: 20 | E43: 80 | F43: AF0092:20 | G43: PANEL A
A44: KA2161:A2 | B44: KA2161A2 | C44: WHT | D44: 20 | E44: 80 | F44: AF0092:23 | G44: PANEL A
A45: KA3103:A2 | B45: KA3103A2 | C45: WHT | D45: 20 | E45: 80 | F45: AF0092:24 | G45: PANEL A
A46: KA3220:A1 | B46: KA3220A1 | C46: WHT | D46: 20 | E46: 60 | F46: AF0093:01 | G46: PANEL A
A47: KA3220:A2 | B47: KA3220A2 | C47: WHT | D47: 20 | E47: 60 | F47: AF0093:17 | G47: PANEL A
...

Sheet PANEL B_S
A1: PANEL B
A2: JB70
A3: Project # | B3: 4P441
A4: Project Name | B4: Pallette Compressor Station
A5: Revision | B5: B
A7: Controls DE | B7: A. CHEN
A8: Phone:
A9: Controls ME | B9: A. PLVAN
A10: Phone:
A12: From | G12: To
A13: Device ID | B13: Wire No. | C13: Wire ID | D13: Gauge/Size | E13: Length | F13: Device ID | G13: Location | H13: Bundle Name
A14: AF0074:05 | B14: -007405 | C14: WHT | D14: 20 | E14: 60 | F14: XT0089:17 | G14: PANEL B | H14: AU/AF
A15: AF0074:21 | B15: -0V | C15: WHT | D15: 20 | E15: 60 | F15: XT0089:18 | G15: PANEL B
A16: AF0076:12 | B16: -007612 | C16: WHT | D16: 20 | E16: 60 | F16: XT0237:1 B2 | G16: PANEL B
A18: AF0066:COM | B18: AF0066N | C18: WHT | D18: 16 | E18: 60 | F18: AF0068:COM | G18: PANEL B
A19: AF0066:V+ | B19: AF0066P | C19: WHT | D19: 16 | E19: 60 | F19: AF0068:V+ | G19: PANEL B
A20: AF0063:COM | B20: AU0060N | C20: WHT | D20: 16 | E20: 60 | F20: AU0060:COM | G20: PANEL B
A21: AF0063:V+ | B21: AU0060P | C21: WHT | D21: 16 | E21: 60 | F21: AU0060:V+ | G21: PANEL B
A23: AU0060:V+ | B23: FU0061 | C23: WHT | D23: 16 | E23: 80 | F23: FU0061:LD | G23: PANEL B | H23: AU/AF - FU/XT
A24: AF0061:V+ | B24: FU0062 | C24: WHT | D24: 16 | E24: 80 | F24: FU0062:LD | G24: PANEL B
A25: AF0062:V+ | B25: FU0063 | C25: WHT | D25: 16 | E25: 60 | F25: FU0063:LD | G25: PANEL B
A26: AF0067:V+ | B26: FU0064 | C26: WHT | D26: 16 | E26: 60 | F26: FU0064:LD | G26: PANEL B
A27: AU0070:V+ | B27: FU0070 | C27: WHT | D27: 16 | E27: 60 | F27: FU0070:LD | G27: PANEL B
A28: AF0076:V+ | B28: FU0076 | C28: WHT | D28: 16 | E28: 60 | F28: FU0076:LD | G28: PANEL B
A30: AF0061:COM | B30: -0V | C30: WHT | D30: 16 | E30: 80 | F30: XT0060:2 | G30: PANEL B
A31: AU0060:COM | B31: -0V | C31: WHT | D31: 16 | E31: 80 | F31: XT0060:2 | G31: PANEL B
A32: AF0062:COM | B32: -0V | C32: WHT | D32: 16 | E32: 80 | F32: XT0060:3 | G32: PANEL B
A33: AF0067:COM | B33: -0V | C33: WHT | D33: 16 | E33: 60 | F33: XT0060:3 | G33: PANEL B
A34: AF0076:COM | B34: -0V | C34: WHT | D34: 16 | E34: 120 | F34: XT0060:4 | G34: PANEL B
A35: AU0070:COM | B35: -0V | C35: WHT | D35: 16 | E35: 100 | F35: XT0060:4 | G35: PANEL B
A37: AF0410:53 | B37: -0V | C37: WHT | D37: 16 | E37: 60 | F37: XT0401:2 | G37: PANEL B | H37: AF0400's
A38: AF0410:54 | B38: -0V | C38: WHT | D38: 16 | E38: 60 | F38: AF0420:53 | G38: PANEL B
A39: AF0420:54 | B39: -0V | C39: WHT | D39: 16 | E39: 60 | F39: AF0430:53 | G39: PANEL B
A40: AF0430:54 | B40: -0V | C40: WHT | D40: 16 | E40: 60 | F40: AF0450:53 | G40: PANEL B
A41: AF0410:55 | B41: FU0410 | C41: WHT | D41: 16 | E41: 60 | F41: FU0410:LD | G41: PANEL B
A42: AF0410:56 | B42: FU0410 | C42: WHT | D42: 16 | E42: 60 | F42: AF0420:55 | G42: PANEL B
A43: AF0420:56 | B43: FU0410 | C43: WHT | D43: 16 | E43: 60 | F43: AF0430:55 | G43: PANEL B
A44: AF0430:56 | B44: FU0410 | C44: WHT | D44: 16 | E44: 60 | F44: AF0450:55 | G44: PANEL B
A46: KA0130:A1 | B46: KA0130A1 | C46: WHT | D46: 20 | E46: 120 | F46: KA0130:11 | G46: PANEL B | H46: KA A1/2
A47: KA0131:A1 | B47: KA0131A1 | C47: WHT | D47: 20 | E47: 140 | F47: KA0242:14 | G47: PANEL B
...

Sheet HPC CTRL_S
A1: HPC CTRL
A2: HPC CTRL,COMPRESSOR BOX
A3: Project # | B3: 4P441
A4: Project Name | B4: Pallette Compressor Station
A5: Revision | B5: B
A7: Controls DE | B7: A. CHEN
A8: Phone:
A9: Controls ME | B9: A. PLVAN
A10: Phone:
A12: From | G12: To
A13: Device ID | B13: Wire No. | C13: Wire ID | D13: Gauge/Size | E13: Length | F13: Device ID | G13: Location | H13: Bundle Name
A14: AF0510:53 | B14: -0V | C14: WHT | D14: 16 | E14: 60 | F14: XT0510:2 | G14: HPC CTRL | H14: AF0510
A15: AF0510:54 | B15: -0V | C15: WHT | D15: 16 | E15: 60 | F15: AF0520:53 | G15: HPC CTRL
A16: AF0510:55 | B16: FU0510 | C16: WHT | D16: 16 | E16: 60 | F16: FU0510:LD | G16: HPC CTRL
A17: AF0510:56 | B17: FU0510 | C17: WHT | D17: 16 | E17: 60 | F17: AF0520:55 | G17: HPC CTRL
A19: AF1206:COM | B19: AF1207N | C19: WHT | D19: 16 | E19: 60 | F19: AF1207:COM | G19: HPC CTRL | H19: AF
A20: AF1206:V+ | B20: AF1207P | C20: WHT | D20: 16 | E20: 60 | F20: AF1207:V+ | G20: HPC CTRL
A21: AF1202:COM | B21: AF1202N | C21: WHT | D21: 16 | E21: 60 | F21: AU1200:COM | G21: HPC CTRL
A22: AF1202:V+ | B22: AF1202P | C22: WHT | D22: 16 | E22: 60 | F22: AU1200:V+ | G22: HPC CTRL
A23: AU1200:V+ | B23: FU0120 | C23: WHT | D23: 16 | E23: 100 | F23: FU0120:LD | G23: HPC CTRL
A24: AF1201:V+ | B24: FU0121 | C24: WHT | D24: 16 | E24: 100 | F24: FU0121:LD | G24: HPC CTRL
A25: AF1201:COM | B25: -0V | C25: WHT | D25: 16 | E25: 100 | F25: XT0120:2 | G25: HPC CTRL
A26: AU1200:COM | B26: -0V | C26: WHT | D26: 16 | E26: 100 | F26: XT0120:2 | G26: HPC CTRL
A28: KA0120:A1 | B28: KA0131A1 | C28: WHT | D28: 20 | E28: 60 | F28: XT0120:4 | G28: HPC CTRL | H28: KA A1/2
A29: KA4401:A2 | B29: -120718 | C29: WHT | D29: 20 | E29: 80 | F29: AF1207:18 | G29: HPC CTRL
A30: KA0120:A2 | B30: -0V | C30: WHT | D30: 20 | E30: 60 | F30: XT0120:3 | G30: HPC CTRL
A32: KA0120:14 | B32: -120100 | C32: WHT | D32: 20 | E32: 100 | F32: AF1201:00 | G32: HPC CTRL | H32: KA
A33: KA4401:22 | B33: -120132 | C33: WHT | D33: 20 | E33: 100 | F33: AF1201:32 | G33: HPC CTRL
A34: KA4401:14 | B34: -120702 | C34: WHT | D34: 20 | E34: 80 | F34: AF1207:02 | G34: HPC CTRL
A35: KA4401:11 | B35: PS44012 | C35: WHT | D35: 20 | E35: 80 | F35: AF1207:34 | G35: HPC CTRL
A36: KA4401:11 | B36: PS44012 | C36: WHT | D36: 20 | E36: 60 | F36: XT0120:5 | G36: HPC CTRL
A38: FU0120:LI | B38: FU0122 | C38: WHT | D38: 14 | E38: 60 | F38: FU0122:LD | G38: HPC CTRL | H38: FU/XT
A39: FU0121:LI | B39: FU0122 | C39: WHT | D39: 14 | E39: 60 | F39: FU0510:LI | G39: HPC CTRL
A40: FU0510:LI | B40: FU0122 | C40: WHT | D40: 14 | E40: 60 | F40: XT0121:1 | G40: HPC CTRL
A41: XT0120:3 | B41: -0V | C41: WHT | D41: 14 | E41: 60 | F41: XT0510:1 | G41: HPC CTRL
A42: XT0121:3 | B42: -0V | C42: WHT | D42: 14 | E42: 80 | F42: XT0510:2 | G42: HPC CTRL
A44: XT0336:2 | B44: -0V | C44: WHT | D44: 12 | E44: 60 | F44: XT0120:1 | G44: HPC CTRL
A45: FU0332:LD | B45: FU0332 | C45: WHT | D45: 12 | E45: 60 | F45: XT0335:1 | G45: HPC CTRL
A46: FU0122:LI | B46: FU0332 | C46: WHT | D46: 12 | E46: 60 | F46: XT0335:2 | G46: HPC CTRL

Sheet JB74,LEFT RAIL_S
A1: JB74,LEFT RAIL
A2: Balance of Plant, Left Rail
A3: Project # | B3: 4P441
A4: Project Name | B4: Pallette Compressor Station
A5: Revision | B5: B
A7: Controls DE | B7: A. CHEN
A8: Phone:
A9: Controls ME | B9: A. PLVAN
A10: Phone:
A12: From | G12: To
A13: Device ID | B13: Wire No. | C13: Wire ID | D13: Gauge/Size | E13: Length | F13: Device ID | G13: Location | H13: Bundle Name
A14: BA0007:V1(+) | B14: FU0027 | C14: WHT | D14: 16 | E14: 60 | F14: FU0027:LD | G14: JB74,LEFT RAIL | H14: BA
A15: BA0008:V1(+) | B15: FU0028 | C15: WHT | D15: 16 | E15: 60 | F15: FU0028:LD | G15: JB74,LEFT RAIL
A16: BA1212:POS | B16: FU1212 | C16: WHT | D16: 16 | E16: 60 | F16: FU1212:LD | G16: JB74,LEFT RAIL
A18: BA1212:NEG | B18: BA1212N | C18: WHT | D18: 16 | E18: 120 | F18: XT1212:2 | G18: BOP | H18: RAIL - BOP
C19: MRCA | D19: 1996192
A20: FU1212:LI | B20: BA1212P | C20: WHT | D20: 16 | E20: 120 | F20: XT1212:1 | G20: BOP

Sheet BOP_S
A1: BOP
A2: BALANCE OF PLANT,JB74
A3: Project # | B3: 4P441
A4: Project Name | B4: Pallette Compressor Station
A5: Revision | B5: B
A7: Controls DE | B7: A. CHEN
A8: Phone:
A9: Controls ME | B9: A. PLVAN
A10: Phone:
A12: From | G12: To
A13: Device ID | B13: Wire No. | C13: Wire ID | D13: Gauge/Size | E13: Length | F13: Device ID | G13: Location | H13: Bundle Name
A14: AF0142:07 | B14: ZSC76112 | C14: WHT | D14: 20 | E14: 60 | F14: XT0572:2 | G14: BOP | H14: AU/AF
A15: AF0141:16 | B15: SV76212 | C15: WHT | D15: 20 | E15: 60 | F15: XT0572:3 | G15: BOP
A16: AF0183:04 | B16: ZSC76212 | C16: WHT | D16: 20 | E16: 80 | F16: XT0572:4 | G16: BOP
A17: AF0141:20 | B17: SV76412 | C17: WHT | D17: 20 | E17: 60 | F17: XT0572:5 | G17: BOP
A18: AF0183:05 | B18: ZSC76412 | C18: WHT | D18: 20 | E18: 80 | F18: XT0572:6 | G18: BOP
A20: AF0183:COM | B20: AF0183N | C20: WHT | D20: 16 | E20: 60 | F20: AF0185:COM | G20: BOP
A21: AF0183:V+ | B21: AF0183P | C21: WHT | D21: 16 | E21: 60 | F21: AF0185:V+ | G21: BOP
A22: AF0142:COM | B22: AU0140N | C22: WHT | D22: 16 | E22: 60 | F22: AU0140:COM | G22: BOP
A23: AF0142:V+ | B23: AU0140P | C23: WHT | D23: 16 | E23: 60 | F23: AU0140:V+ | G23: BOP
A24: AF0182:COM | B24: AU0180N | C24: WHT | D24: 16 | E24: 60 | F24: AU0180:COM | G24: BOP
A25: AF0182:V+ | B25: AU0180P | C25: WHT | D25: 16 | E25: 60 | F25: AU0180:V+ | G25: BOP
A27: AU0140:V+ | B27: FU0140 | C27: WHT | D27: 16 | E27: 60 | F27: FU0140:LD | G27: BOP | H27: AU/AF - XT/FU
A28: AF0141:V+ | B28: FU0141 | C28: WHT | D28: 16 | E28: 60 | F28: FU0141:LD | G28: BOP
A29: AF0146:V+ | B29: FU0142 | C29: WHT | D29: 16 | E29: 80 | F29: FU0142:LD | G29: BOP
A30: AU0180:V+ | B30: FU0180 | C30: WHT | D30: 16 | E30: 60 | F30: FU0180:LD | G30: BOP
A31: AF0181:V+ | B31: FU0181 | C31: WHT | D31: 16 | E31: 60 | F31: FU0181:LD | G31: BOP
A32: AF0184:V+ | B32: FU0182 | C32: WHT | D32: 16 | E32: 60 | F32: FU0182:LD | G32: BOP
A34: AF0141:COM | B34: -0V | C34: WHT | D34: 16 | E34: 60 | F34: XT0140:2 | G34: BOP
A35: AU0140:COM | B35: -0V | C35: WHT | D35: 16 | E35: 60 | F35: XT0140:2 | G35: BOP
A36: AF0146:COM | B36: -0V | C36: WHT | D36: 16 | E36: 60 | F36: XT0140:3 | G36: BOP
A37: AF0181:COM | B37: -0V | C37: WHT | D37: 16 | E37: 60 | F37: XT0140:4 | G37: BOP
A38: AU0180:COM | B38: -0V | C38: WHT | D38: 16 | E38: 60 | F38: XT0140:4 | G38: BOP
A39: AF0184:COM | B39: -0V | C39: WHT | D39: 16 | E39: 80 | F39: XT0140:5 | G39: BOP
A41: KA0572:A2 | B41: KA0572A2 | C41: WHT | D41: 20 | E41: 80 | F41: AF0183:20 | G41: BOP | H41: KA A1/2
A42: KA0573:A2 | B42: KA0573A2 | C42: WHT | D42: 20 | E42: 80 | F42: AF0183:21 | G42: BOP
A43: KA0550:A1 | B43: KA0550A1 | C43: WHT | D43: 20 | E43: 80 | F43: AF0184:00 | G43: BOP
A44: KA0552:A1 | B44: KA0552A1 | C44: WHT | D44: 20 | E44: 80 | F44: AF0184:01 | G44: BOP
A45: KA0551:A1 | B45: KA0551A1 | C45: WHT | D45: 20 | E45: 80 | F45: AF0184:02 | G45: BOP
A46: KA0553:A1 | B46: KA0553A1 | C46: WHT | D46: 20 | E46: 80 | F46: AF0184:03 | G46: BOP
...

Sheet JB1123_S
A1: JB1123
A2: FIBER OPTIC MEDIA CONVERTER BOX, JB1123
A3: Project # | B3: 4P441
A4: Project Name | B4: Pallette Compressor Station
A5: Revision | B5: B
A7: Controls DE | B7: A. CHEN
A8: Phone:
A9: Controls ME | B9: A. PLVAN
A10: Phone:
A12: From | G12: To
A13: Device ID | B13: Wire No. | C13: Wire ID | D13: Gauge/Size | E13: Length | F13: Device ID | G13: Location | H13: Bundle Name
A14: BA0005:V1(-) | B14: -0V | C14: WHT | D14: 16 | E14: 60 | F14: XT1123:2 | G14: JB1123 | H14: BA
A15: BA0005:V1(+) | B15: FU1123 | C15: WHT | D15: 16 | E15: 60 | F15: FU1123:LD | G15: JB1123
A16: BA0006:V1(-) | B16: -0V | C16: WHT | D16: 16 | E16: 60 | F16: XT1123:2 | G16: JB1123
A17: BA0006:V1(+) | B17: FU1124 | C17: WHT | D17: 16 | E17: 60 | F17: FU1124:LD | G17: JB1123
A19: FU1123:LI | B19: FU0136 | C19: WHT | D19: 16 | E19: 60 | F19: XT1123:1 | G19: JB1123 | H19: FU
A20: FU1124:LI | B20: FU0136 | C20: WHT | D20: 16 | E20: 60 | F20: XT1123:1 | G20: JB1123

Sheet Bundle Tag Info
A1: TCM-70 #1
A2: 4P441
A3: B.1
A6: JB70 | B6: JB70 LEFT RAIL | C6: FIRE PANEL | D6: JB70 RIGHT RAIL | E6: PLC | F6: A | G6: B | H6: HPC | I6: JB74 L RAIL | J6: BOP | K6: JB1123 | L6: Panel Name | M6: Panel Name | N6: Panel Name | O6: Panel Name | P6: Panel Name | Q6: Panel Name | R6: Panel Name | S6: Panel Name | T6: Panel Name | U6: Panel Name | V6: Panel Name | W6: Panel Name | X6: Panel Name | Y6: Panel Name | Z6: Panel Name | AA6: Panel Name | AB6: Panel Name | AC6: Panel Name | AD6: Panel Name
A7: AT | B7: AT | C7: AT | D7: BA | E7: PLC | F7: UJ0131 | G7: AU/AF | H7: AF0510 | I7: BA | J7: AU/AF | K7: BA
A8: SA0474 | B8: KA | C8: FU/UV | D8: FU/UJ | E8: PLC-A | F8: AF | G8: AU/AF - FU/XT | H8: AF | I8: RAIL - BOP | J8: AU/AF - XT/FU | K8: FU
A9: SA0471 | B9: XT/FU | D9: XT - AF A | F9: KA A1/2 | G9: AF0400's | H9: KA A1/2 | J9: KA A1/2
A10: SA0473 | B10: RAIL - JB70 | D10: XT/UJ - A | F10: KA | G10: KA A1/2 | H10: KA | J10: KA
A11: SH0472 | B11: KA / AT - FS | D11: XT - B | F11: FU | G11: KA DOUBLES | H11: FU/XT | J11: FU
A12: SH0471 | B12: XT - FS | D12: XT - PLC | F12: AF0080's - B | G12: KA
A13: SH0470 | B13: THRU | F13: AF0090's - B | G13: KT
A14: SB0474 | F14: KA A1/2 - B | G14: UA1200
A15: SB0472 | F15: KA - B | G15: XT/FU
A16: SB0473 | F16: XT/FU - B
A17: SB0471

Sheet Bundle Tags2
A1: =IF('Bundle Tag Info'!A6<>"Panel Name",'Bundle Tag Info'!A6,"") -> JB70 | B1: =IF('Bundle Tag Info'!B6<>"Panel Name",'Bundle Tag Info'!B6,"") -> JB70 LEFT RAIL | C1: =IF('Bundle Tag Info'!C6<>"Panel Name",'Bundle Tag Info'!C6,"") -> FIRE PANEL | D1: =IF('Bundle Tag Info'!D6<>"Panel Name",'Bundle Tag Info'!D6,"") -> JB70 RIGHT RAIL | E1: =IF('Bundle Tag Info'!E6<>"Panel Name",'Bundle Tag Info'!E6,"") -> PLC | F1: =IF('Bundle Tag Info'!F6<>"Panel Name",'Bundle Tag Info'!F6,"") -> A | G1: =IF('Bundle Tag Info'!G6<>"Panel Name",'Bundle Tag Info'!G6,"") -> B | H1: =IF('Bundle Tag Info'!H6<>"Panel Name",'Bundle Tag Info'!H6,"") -> HPC | ... AD1: =IF('Bundle Tag Info'!AD6<>"Panel Name",'Bundle Tag Info'!AD6,"")
A2: =IF('Bundle Tag Info'!A$7<>"",CONCATENATE('Bundle Tag Info'!$A$1," ",CHAR(10),'Bundle Tag Info'!$A$2," ",'Bundle Tag Info'!$A$3,CHAR(10),'Bundle Tag Info'!A$6,CHAR(10),'Bundle Tag Info'!A$7),"") -> TCM-70 #1 4P441 B.1 JB70 AT | B2: =IF('Bundle Tag Info'!B$7<>"",CONCATENATE('Bundle Tag Info'!$A$1," ",CHAR(10),'Bundle Tag Info'!$A$2," ",'Bundle Tag Info'!$A$3,CHAR(10),'Bundle Tag Info'!B$6,CHAR(10),'Bundle Tag Info'!B$7),"") -> TCM-70 #1 4P441 B.1 JB70 LEFT RAIL AT | C2: =IF('Bundle Tag Info'!C$7<>"",CONCATENATE('Bundle Tag Info'!$A$1," ",CHAR(10),'Bundle Tag Info'!$A$2," ",'Bundle Tag Info'!$A$3,CHAR(10),'Bundle Tag Info'!C$6,CHAR(10),'Bundle Tag Info'!C$7),"") -> TCM-70 #1 4P441 B.1 FIRE PANEL AT | D2: =IF('Bundle Tag Info'!D$7<>"",CONCATENATE('Bundle Tag Info'!$A$1," ",CHAR(10),'Bundle Tag Info'!$A$2," ",'Bundle Tag Info'!$A$3,CHAR(10),'Bundle Tag Info'!D$6,CHAR(10),'Bundle Tag Info'!D$7),"") -> TCM-70 #1 4P441 B.1 JB70 RIGHT RAIL BA | E2: =IF('Bundle Tag Info'!E$7<>"",CONCATENATE('Bundle Tag Info'!$A$1," ",CHAR(10),'Bundle Tag Info'!$A$2," ",'Bundle Tag Info'!$A$3,CHAR(10),'Bundle Tag Info'!E$6,CHAR(10),'Bundle Tag Info'!E$7),"") -> TCM-70 #1 4P441 B.1 PLC PLC | F2: =IF('Bundle Tag Info'!F$7<>"",CONCATENATE('Bundle Tag Info'!$A$1," ",CHAR(10),'Bundle Tag Info'!$A$2," ",'Bundle Tag Info'!$A$3,CHAR(10),'Bundle Tag Info'!F$6,CHAR(10),'Bundle Tag Info'!F$7),"") -> TCM-70 #1 4P441 B.1 A UJ0131 | G2: =IF('Bundle Tag Info'!G$7<>"",CONCATENATE('Bundle Tag Info'!$A$1," ",CHAR(10),'Bundle Tag Info'!$A$2," ",'Bundle Tag Info'!$A$3,CHAR(10),'Bundle Tag Info'!G$6,CHAR(10),'Bundle Tag Info'!G$7),"") -> TCM-70 #1 4P441 B.1 B AU/AF | H2: =IF('Bundle Tag Info'!H$7<>"",CONCATENATE('Bundle Tag Info'!$A$1," ",CHAR(10),'Bundle Tag Info'!$A$2," ",'Bundle Tag Info'!$A$3,CHAR(10),'Bundle Tag Info'!H$6,CHAR(10),'Bundle Tag Info'!H$7),"") -> TCM-70 #1 4P441 B.1 HPC AF0510 | ... AD2: =IF('Bundle Tag Info'!AD$7<>"",CONCATENATE('Bundle Tag Info'!$A$1," ",CHAR(10),'Bundle Tag Info'!$A$2," ",'Bundle Tag Info'!$A$3,CHAR(10),'Bundle Tag Info'!AD$6,CHAR(10),'Bundle Tag Info'!AD$7),"")
A3: =IF('Bundle Tag Info'!A$8<>"",CONCATENATE('Bundle Tag Info'!$A$1," ",CHAR(10),'Bundle Tag Info'!$A$2," ",'Bundle Tag Info'!$A$3,CHAR(10),'Bundle Tag Info'!A$6,CHAR(10),'Bundle Tag Info'!A$8),"") -> TCM-70 #1 4P441 B.1 JB70 SA0474 | B3: =IF('Bundle Tag Info'!B$8<>"",CONCATENATE('Bundle Tag Info'!$A$1," ",CHAR(10),'Bundle Tag Info'!$A$2," ",'Bundle Tag Info'!$A$3,CHAR(10),'Bundle Tag Info'!B$6,CHAR(10),'Bundle Tag Info'!B$8),"") -> TCM-70 #1 4P441 B.1 JB70 LEFT RAIL KA | C3: =IF('Bundle Tag Info'!C$8<>"",CONCATENATE('Bundle Tag Info'!$A$1," ",CHAR(10),'Bundle Tag Info'!$A$2," ",'Bundle Tag Info'!$A$3,CHAR(10),'Bundle Tag Info'!C$6,CHAR(10),'Bundle Tag Info'!C$8),"") -> TCM-70 #1 4P441 B.1 FIRE PANEL FU/UV | D3: =IF('Bundle Tag Info'!D$8<>"",CONCATENATE('Bundle Tag Info'!$A$1," ",CHAR(10),'Bundle Tag Info'!$A$2," ",'Bundle Tag Info'!$A$3,CHAR(10),'Bundle Tag Info'!D$6,CHAR(10),'Bundle Tag Info'!D$8),"") -> TCM-70 #1 4P441 B.1 JB70 RIGHT RAIL FU/UJ | E3: =IF('Bundle Tag Info'!E$8<>"",CONCATENATE('Bundle Tag Info'!$A$1," ",CHAR(10),'Bundle Tag Info'!$A$2," ",'Bundle Tag Info'!$A$3,CHAR(10),'Bundle Tag Info'!E$6,CHAR(10),'Bundle Tag Info'!E$8),"") -> TCM-70 #1 4P441 B.1 PLC PLC-A | F3: =IF('Bundle Tag Info'!F$8<>"",CONCATENATE('Bundle Tag Info'!$A$1," ",CHAR(10),'Bundle Tag Info'!$A$2," ",'Bundle Tag Info'!$A$3,CHAR(10),'Bundle Tag Info'!F$6,CHAR(10),'Bundle Tag Info'!F$8),"") -> TCM-70 #1 4P441 B.1 A AF | G3: =IF('Bundle Tag Info'!G$8<>"",CONCATENATE('Bundle Tag Info'!$A$1," ",CHAR(10),'Bundle Tag Info'!$A$2," ",'Bundle Tag Info'!$A$3,CHAR(10),'Bundle Tag Info'!G$6,CHAR(10),'Bundle Tag Info'!G$8),"") -> TCM-70 #1 4P441 B.1 B AU/AF - FU/XT | H3: =IF('Bundle Tag Info'!H$9<>"",CONCATENATE('Bundle Tag Info'!$A$1," ",CHAR(10),'Bundle Tag Info'!$A$2," ",'Bundle Tag Info'!$A$3,CHAR(10),'Bundle Tag Info'!H$6,CHAR(10),'Bundle Tag Info'!H$9),"") -> TCM-70 #1 4P441 B.1 HPC KA A1/2 | I3: =IF('Bundle Tag Info'!I$8<>"",CONCATENATE('Bundle Tag Info'!$A$1," ",CHAR(10),'Bundle Tag Info'!$A$2," ",'Bundle Tag Info'!$A$3,CHAR(10),'Bundle Tag Info'!I$6,CHAR(10),'Bundle Tag Info'!I$8),"") -> TCM-70 #1 4P441 B.1 JB74 L RAIL RAIL - BOP | J3: =IF('Bundle Tag Info'!J$8<>"",CONCATENATE('Bundle Tag Info'!$A$1," ",CHAR(10),'Bundle Tag Info'!$A$2," ",'Bundle Tag Info'!$A$3,CHAR(10),'Bundle Tag Info'!J$6,CHAR(10),'Bundle Tag Info'!J$8),"") -> TCM-70 #1 4P441 B.1 BOP AU/AF - XT/FU | K3: =IF('Bundle Tag Info'!K$8<>"",CONCATENATE('Bundle Tag Info'!$A$1," ",CHAR(10),'Bundle Tag Info'!$A$2," ",'Bundle Tag Info'!$A$3,CHAR(10),'Bundle Tag Info'!K$6,CHAR(10),'Bundle Tag Info'!K$8),"") -> TCM-70 #1 4P441 B.1 JB1123 FU | L3: =IF('Bundle Tag Info'!L$8<>"",CONCATENATE('Bundle Tag Info'!$A$1," ",CHAR(10),'Bundle Tag Info'!$A$2," ",'Bundle Tag Info'!$A$3,CHAR(10),'Bundle Tag Info'!L$6,CHAR(10),'Bundle Tag Info'!L$8),"") | M3: =IF('Bundle Tag Info'!M$8<>"",CONCATENATE('Bundle Tag Info'!$A$1," ",CHAR(10),'Bundle Tag Info'!$A$2," ",'Bundle Tag Info'!$A$3,CHAR(10),'Bundle Tag Info'!M$6,CHAR(10),'Bundle Tag Info'!M$8),"") | N3: =IF('Bundle Tag Info'!N$8<>"",CONCATENATE('Bundle Tag Info'!$A$1," ",CHAR(10),'Bundle Tag Info'!$A$2," ",'Bundle Tag Info'!$A$3,CHAR(10),'Bundle Tag Info'!N$6,CHAR(10),'Bundle Tag Info'!N$8),"") | O3: =IF('Bundle Tag Info'!O$8<>"",CONCATENATE('Bundle Tag Info'!$A$1," ",CHAR(10),'Bundle Tag Info'!$A$2," ",'Bundle Tag Info'!$A$3,CHAR(10),'Bundle Tag Info'!O$6,CHAR(10),'Bundle Tag Info'!O$8),"") | P3: =IF('Bundle Tag Info'!P$8<>"",CONCATENATE('Bundle Tag Info'!$A$1," ",CHAR(10),'Bundle Tag Info'!$A$2," ",'Bundle Tag Info'!$A$3,CHAR(10),'Bundle Tag Info'!P$6,CHAR(10),'Bundle Tag Info'!P$8),"") | ... AD3: =IF('Bundle Tag Info'!AD$8<>"",CONCATENATE('Bundle Tag Info'!$A$1," ",CHAR(10),'Bundle Tag Info'!$A$2," ",'Bundle Tag Info'!$A$3,CHAR(10),'Bundle Tag Info'!AD$6,CHAR(10),'Bundle Tag Info'!AD$8),"")
A4: =IF('Bundle Tag Info'!A$9<>"",CONCATENATE('Bundle Tag Info'!$A$1," ",CHAR(10),'Bundle Tag Info'!$A$2," ",'Bundle Tag Info'!$A$3,CHAR(10),'Bundle Tag Info'!A$6,CHAR(10),'Bundle Tag Info'!A$9),"") -> TCM-70 #1 4P441 B.1 JB70 SA0471 | B4: =IF('Bundle Tag Info'!B$9<>"",CONCATENATE('Bundle Tag Info'!$A$1," ",CHAR(10),'Bundle Tag Info'!$A$2," ",'Bundle Tag Info'!$A$3,CHAR(10),'Bundle Tag Info'!B$6,CHAR(10),'Bundle Tag Info'!B$9),"") -> TCM-70 #1 4P441 B.1 JB70 LEFT RAIL XT/FU | C4: =IF('Bundle Tag Info'!C$9<>"",CONCATENATE('Bundle Tag Info'!$A$1," ",CHAR(10),'Bundle Tag Info'!$A$2," ",'Bundle Tag Info'!$A$3,CHAR(10),'Bundle Tag Info'!C$6,CHAR(10),'Bundle Tag Info'!C$9),"") | D4: =IF('Bundle Tag Info'!D$9<>"",CONCATENATE('Bundle Tag Info'!$A$1," ",CHAR(10),'Bundle Tag Info'!$A$2," ",'Bundle Tag Info'!$A$3,CHAR(10),'Bundle Tag Info'!D$6,CHAR(10),'Bundle Tag Info'!D$9),"") -> TCM-70 #1 4P441 B.1 JB70 RIGHT RAIL XT - AF A | E4: =IF('Bundle Tag Info'!E$9<>"",CONCATENATE('Bundle Tag Info'!$A$1," ",CHAR(10),'Bundle Tag Info'!$A$2," ",'Bundle Tag Info'!$A$3,CHAR(10),'Bundle Tag Info'!E$6,CHAR(10),'Bundle Tag Info'!E$9),"") | F4: =IF('Bundle Tag Info'!F$9<>"",CONCATENATE('Bundle Tag Info'!$A$1," ",CHAR(10),'Bundle Tag Info'!$A$2," ",'Bundle Tag Info'!$A$3,CHAR(10),'Bundle Tag Info'!F$6,CHAR(10),'Bundle Tag Info'!F$9),"") -> TCM-70 #1 4P441 B.1 A KA A1/2 | G4: =IF('Bundle Tag Info'!G$9<>"",CONCATENATE('Bundle Tag Info'!$A$1," ",CHAR(10),'Bundle Tag Info'!$A$2," ",'Bundle Tag Info'!$A$3,CHAR(10),'Bundle Tag Info'!G$6,CHAR(10),'Bundle Tag Info'!G$9),"") -> TCM-70 #1 4P441 B.1 B AF0400's | H4: =IF('Bundle Tag Info'!H$10<>"",CONCATENATE('Bundle Tag Info'!$A$1," ",CHAR(10),'Bundle Tag Info'!$A$2," ",'Bundle Tag Info'!$A$3,CHAR(10),'Bundle Tag Info'!H$6,CHAR(10),'Bundle Tag Info'!H$10),"") -> TCM-70 #1 4P441 B.1 HPC KA | I4: =IF('Bundle Tag Info'!I$9<>"",CONCATENATE('Bundle Tag Info'!$A$1," ",CHAR(10),'Bundle Tag Info'!$A$2," ",'Bundle Tag Info'!$A$3,CHAR(10),'Bundle Tag Info'!I$6,CHAR(10),'Bundle Tag Info'!I$9),"") | J4: =IF('Bundle Tag Info'!J$9<>"",CONCATENATE('Bundle Tag Info'!$A$1," ",CHAR(10),'Bundle Tag Info'!$A$2," ",'Bundle Tag Info'!$A$3,CHAR(10),'Bundle Tag Info'!J$6,CHAR(10),'Bundle Tag Info'!J$9),"") -> TCM-70 #1 4P441 B.1 BOP KA A1/2 | K4: =IF('Bundle Tag Info'!K$9<>"",CONCATENATE('Bundle Tag Info'!$A$1," ",CHAR(10),'Bundle Tag Info'!$A$2," ",'Bundle Tag Info'!$A$3,CHAR(10),'Bundle Tag Info'!K$6,CHAR(10),'Bundle Tag Info'!K$9),"") | L4: =IF('Bundle Tag Info'!L$9<>"",CONCATENATE('Bundle Tag Info'!$A$1," ",CHAR(10),'Bundle Tag Info'!$A$2," ",'Bundle Tag Info'!$A$3,CHAR(10),'Bundle Tag Info'!L$6,CHAR(10),'Bundle Tag Info'!L$9),"") | M4: =IF('Bundle Tag Info'!M$9<>"",CONCATENATE('Bundle Tag Info'!$A$1," ",CHAR(10),'Bundle Tag Info'!$A$2," ",'Bundle Tag Info'!$A$3,CHAR(10),'Bundle Tag Info'!M$6,CHAR(10),'Bundle Tag Info'!M$9),"") | N4: =IF('Bundle Tag Info'!N$9<>"",CONCATENATE('Bundle Tag Info'!$A$1," ",CHAR(10),'Bundle Tag Info'!$A$2," ",'Bundle Tag Info'!$A$3,CHAR(10),'Bundle Tag Info'!N$6,CHAR(10),'Bundle Tag Info'!N$9),"") | O4: =IF('Bundle Tag Info'!O$9<>"",CONCATENATE('Bundle Tag Info'!$A$1," ",CHAR(10),'Bundle Tag Info'!$A$2," ",'Bundle Tag Info'!$A$3,CHAR(10),'Bundle Tag Info'!O$6,CHAR(10),'Bundle Tag Info'!O$9),"") | P4: =IF('Bundle Tag Info'!P$9<>"",CONCATENATE('Bundle Tag Info'!$A$1," ",CHAR(10),'Bundle Tag Info'!$A$2," ",'Bundle Tag Info'!$A$3,CHAR(10),'Bundle Tag Info'!P$6,CHAR(10),'Bundle Tag Info'!P$9),"") | ... AD4: =IF('Bundle Tag Info'!AD$9<>"",CONCATENATE('Bundle Tag Info'!$A$1," ",CHAR(10),'Bundle Tag Info'!$A$2," ",'Bundle Tag Info'!$A$3,CHAR(10),'Bundle Tag Info'!AD$6,CHAR(10),'Bundle Tag Info'!AD$9),"")
A5: =IF('Bundle Tag Info'!A$10<>"",CONCATENATE('Bundle Tag Info'!$A$1," ",CHAR(10),'Bundle Tag Info'!$A$2," ",'Bundle Tag Info'!$A$3,CHAR(10),'Bundle Tag Info'!A$6,CHAR(10),'Bundle Tag Info'!A$10),"") -> TCM-70 #1 4P441 B.1 JB70 SA0473 | B5: =IF('Bundle Tag Info'!B$10<>"",CONCATENATE('Bundle Tag Info'!$A$1," ",CHAR(10),'Bundle Tag Info'!$A$2," ",'Bundle Tag Info'!$A$3,CHAR(10),'Bundle Tag Info'!B$6,CHAR(10),'Bundle Tag Info'!B$10),"") -> TCM-70 #1 4P441 B.1 JB70 LEFT RAIL RAIL - JB70 | C5: =IF('Bundle Tag Info'!C$10<>"",CONCATENATE('Bundle Tag Info'!$A$1," ",CHAR(10),'Bundle Tag Info'!$A$2," ",'Bundle Tag Info'!$A$3,CHAR(10),'Bundle Tag Info'!C$6,CHAR(10),'Bundle Tag Info'!C$10),"") | D5: =IF('Bundle Tag Info'!D$10<>"",CONCATENATE('Bundle Tag Info'!$A$1," ",CHAR(10),'Bundle Tag Info'!$A$2," ",'Bundle Tag Info'!$A$3,CHAR(10),'Bundle Tag Info'!D$6,CHAR(10),'Bundle Tag Info'!D$10),"") -> TCM-70 #1 4P441 B.1 JB70 RIGHT RAIL XT/UJ - A | E5: =IF('Bundle Tag Info'!E$10<>"",CONCATENATE('Bundle Tag Info'!$A$1," ",CHAR(10),'Bundle Tag Info'!$A$2," ",'Bundle Tag Info'!$A$3,CHAR(10),'Bundle Tag Info'!E$6,CHAR(10),'Bundle Tag Info'!E$10),"") | F5: =IF('Bundle Tag Info'!F$10<>"",CONCATENATE('Bundle Tag Info'!$A$1," ",CHAR(10),'Bundle Tag Info'!$A$2," ",'Bundle Tag Info'!$A$3,CHAR(10),'Bundle Tag Info'!F$6,CHAR(10),'Bundle Tag Info'!F$10),"") -> TCM-70 #1 4P441 B.1 A KA | G5: =IF('Bundle Tag Info'!G$10<>"",CONCATENATE('Bundle Tag Info'!$A$1," ",CHAR(10),'Bundle Tag Info'!$A$2," ",'Bundle Tag Info'!$A$3,CHAR(10),'Bundle Tag Info'!G$6,CHAR(10),'Bundle Tag Info'!G$10),"") -> TCM-70 #1 4P441 B.1 B KA A1/2 | H5: =IF('Bundle Tag Info'!H$11<>"",CONCATENATE('Bundle Tag Info'!$A$1," ",CHAR(10),'Bundle Tag Info'!$A$2," ",'Bundle Tag Info'!$A$3,CHAR(10),'Bundle Tag Info'!H$6,CHAR(10),'Bundle Tag Info'!H$11),"") -> TCM-70 #1 4P441 B.1 HPC FU/XT | I5: =IF('Bundle Tag Info'!I$10<>"",CONCATENATE('Bundle Tag Info'!$A$1," ",CHAR(10),'Bundle Tag Info'!$A$2," ",'Bundle Tag Info'!$A$3,CHAR(10),'Bundle Tag Info'!I$6,CHAR(10),'Bundle Tag Info'!I$10),"") | J5: =IF('Bundle Tag Info'!J$10<>"",CONCATENATE('Bundle Tag Info'!$A$1," ",CHAR(10),'Bundle Tag Info'!$A$2," ",'Bundle Tag Info'!$A$3,CHAR(10),'Bundle Tag Info'!J$6,CHAR(10),'Bundle Tag Info'!J$10),"") -> TCM-70 #1 4P441 B.1 BOP KA | K5: =IF('Bundle Tag Info'!K$10<>"",CONCATENATE('Bundle Tag Info'!$A$1," ",CHAR(10),'Bundle Tag Info'!$A$2," ",'Bundle Tag Info'!$A$3,CHAR(10),'Bundle Tag Info'!K$6,CHAR(10),'Bundle Tag Info'!K$10),"") | L5: =IF('Bundle Tag Info'!L$10<>"",CONCATENATE('Bundle Tag Info'!$A$1," ",CHAR(10),'Bundle Tag Info'!$A$2," ",'Bundle Tag Info'!$A$3,CHAR(10),'Bundle Tag Info'!L$6,CHAR(10),'Bundle Tag Info'!L$10),"") | M5: =IF('Bundle Tag Info'!M$10<>"",CONCATENATE('Bundle Tag Info'!$A$1," ",CHAR(10),'Bundle Tag Info'!$A$2," ",'Bundle Tag Info'!$A$3,CHAR(10),'Bundle Tag Info'!M$6,CHAR(10),'Bundle Tag Info'!M$10),"") | N5: =IF('Bundle Tag Info'!N$10<>"",CONCATENATE('Bundle Tag Info'!$A$1," ",CHAR(10),'Bundle Tag Info'!$A$2," ",'Bundle Tag Info'!$A$3,CHAR(10),'Bundle Tag Info'!N$6,CHAR(10),'Bundle Tag Info'!N$10),"") | O5: =IF('Bundle Tag Info'!O$10<>"",CONCATENATE('Bundle Tag Info'!$A$1," ",CHAR(10),'Bundle Tag Info'!$A$2," ",'Bundle Tag Info'!$A$3,CHAR(10),'Bundle Tag Info'!O$6,CHAR(10),'Bundle Tag Info'!O$10),"") | P5: =IF('Bundle Tag Info'!P$10<>"",CONCATENATE('Bundle Tag Info'!$A$1," ",CHAR(10),'Bundle Tag Info'!$A$2," ",'Bundle Tag Info'!$A$3,CHAR(10),'Bundle Tag Info'!P$6,CHAR(10),'Bundle Tag Info'!P$10),"") | ... AD5: =IF('Bundle Tag Info'!AD$10<>"",CONCATENATE('Bundle Tag Info'!$A$1," ",CHAR(10),'Bundle Tag Info'!$A$2," ",'Bundle Tag Info'!$A$3,CHAR(10),'Bundle Tag Info'!AD$6,CHAR(10),'Bundle Tag Info'!AD$10),"")
A6: =IF('Bundle Tag Info'!A$11<>"",CONCATENATE('Bundle Tag Info'!$A$1," ",CHAR(10),'Bundle Tag Info'!$A$2," ",'Bundle Tag Info'!$A$3,CHAR(10),'Bundle Tag Info'!A$6,CHAR(10),'Bundle Tag Info'!A$11),"") -> TCM-70 #1 4P441 B.1 JB70 SH0472 | B6: =IF('Bundle Tag Info'!B$11<>"",CONCATENATE('Bundle Tag Info'!$A$1," ",CHAR(10),'Bundle Tag Info'!$A$2," ",'Bundle Tag Info'!$A$3,CHAR(10),'Bundle Tag Info'!B$6,CHAR(10),'Bundle Tag Info'!B$11),"") -> TCM-70 #1 4P441 B.1 JB70 LEFT RAIL KA / AT - FS | C6: =IF('Bundle Tag Info'!C$11<>"",CONCATENATE('Bundle Tag Info'!$A$1," ",CHAR(10),'Bundle Tag Info'!$A$2," ",'Bundle Tag Info'!$A$3,CHAR(10),'Bundle Tag Info'!C$6,CHAR(10),'Bundle Tag Info'!C$11),"") | D6: =IF('Bundle Tag Info'!D$11<>"",CONCATENATE('Bundle Tag Info'!$A$1," ",CHAR(10),'Bundle Tag Info'!$A$2," ",'Bundle Tag Info'!$A$3,CHAR(10),'Bundle Tag Info'!D$6,CHAR(10),'Bundle Tag Info'!D$11),"") -> TCM-70 #1 4P441 B.1 JB70 RIGHT RAIL XT - B | E6: =IF('Bundle Tag Info'!E$11<>"",CONCATENATE('Bundle Tag Info'!$A$1," ",CHAR(10),'Bundle Tag Info'!$A$2," ",'Bundle Tag Info'!$A$3,CHAR(10),'Bundle Tag Info'!E$6,CHAR(10),'Bundle Tag Info'!E$11),"") | F6: =IF('Bundle Tag Info'!F$11<>"",CONCATENATE('Bundle Tag Info'!$A$1," ",CHAR(10),'Bundle Tag Info'!$A$2," ",'Bundle Tag Info'!$A$3,CHAR(10),'Bundle Tag Info'!F$6,CHAR(10),'Bundle Tag Info'!F$11),"") -> TCM-70 #1 4P441 B.1 A FU | G6: =IF('Bundle Tag Info'!G$11<>"",CONCATENATE('Bundle Tag Info'!$A$1," ",CHAR(10),'Bundle Tag Info'!$A$2," ",'Bundle Tag Info'!$A$3,CHAR(10),'Bundle Tag Info'!G$6,CHAR(10),'Bundle Tag Info'!G$11),"") -> TCM-70 #1 4P441 B.1 B KA DOUBLES | H6: =IF('Bundle Tag Info'!H$12<>"",CONCATENATE('Bundle Tag Info'!$A$1," ",CHAR(10),'Bundle Tag Info'!$A$2," ",'Bundle Tag Info'!$A$3,CHAR(10),'Bundle Tag Info'!H$6,CHAR(10),'Bundle Tag Info'!H$12),"") | I6: =IF('Bundle Tag Info'!I$11<>"",CONCATENATE('Bundle Tag Info'!$A$1," ",CHAR(10),'Bundle Tag Info'!$A$2," ",'Bundle Tag Info'!$A$3,CHAR(10),'Bundle Tag Info'!I$6,CHAR(10),'Bundle Tag Info'!I$11),"") | J6: =IF('Bundle Tag Info'!J$11<>"",CONCATENATE('Bundle Tag Info'!$A$1," ",CHAR(10),'Bundle Tag Info'!$A$2," ",'Bundle Tag Info'!$A$3,CHAR(10),'Bundle Tag Info'!J$6,CHAR(10),'Bundle Tag Info'!J$11),"") -> TCM-70 #1 4P441 B.1 BOP FU | K6: =IF('Bundle Tag Info'!K$11<>"",CONCATENATE('Bundle Tag Info'!$A$1," ",CHAR(10),'Bundle Tag Info'!$A$2," ",'Bundle Tag Info'!$A$3,CHAR(10),'Bundle Tag Info'!K$6,CHAR(10),'Bundle Tag Info'!K$11),"") | L6: =IF('Bundle Tag Info'!L$11<>"",CONCATENATE('Bundle Tag Info'!$A$1," ",CHAR(10),'Bundle Tag Info'!$A$2," ",'Bundle Tag Info'!$A$3,CHAR(10),'Bundle Tag Info'!L$6,CHAR(10),'Bundle Tag Info'!L$11),"") | M6: =IF('Bundle Tag Info'!M$11<>"",CONCATENATE('Bundle Tag Info'!$A$1," ",CHAR(10),'Bundle Tag Info'!$A$2," ",'Bundle Tag Info'!$A$3,CHAR(10),'Bundle Tag Info'!M$6,CHAR(10),'Bundle Tag Info'!M$11),"") | N6: =IF('Bundle Tag Info'!N$11<>"",CONCATENATE('Bundle Tag Info'!$A$1," ",CHAR(10),'Bundle Tag Info'!$A$2," ",'Bundle Tag Info'!$A$3,CHAR(10),'Bundle Tag Info'!N$6,CHAR(10),'Bundle Tag Info'!N$11),"") | O6: =IF('Bundle Tag Info'!O$11<>"",CONCATENATE('Bundle Tag Info'!$A$1," ",CHAR(10),'Bundle Tag Info'!$A$2," ",'Bundle Tag Info'!$A$3,CHAR(10),'Bundle Tag Info'!O$6,CHAR(10),'Bundle Tag Info'!O$11),"") | P6: =IF('Bundle Tag Info'!P$11<>"",CONCATENATE('Bundle Tag Info'!$A$1," ",CHAR(10),'Bundle Tag Info'!$A$2," ",'Bundle Tag Info'!$A$3,CHAR(10),'Bundle Tag Info'!P$6,CHAR(10),'Bundle Tag Info'!P$11),"") | ... AD6: =IF('Bundle Tag Info'!AD$11<>"",CONCATENATE('Bundle Tag Info'!$A$1," ",CHAR(10),'Bundle Tag Info'!$A$2," ",'Bundle Tag Info'!$A$3,CHAR(10),'Bundle Tag Info'!AD$6,CHAR(10),'Bundle Tag Info'!AD$11),"")
A7: =IF('Bundle Tag Info'!A$12<>"",CONCATENATE('Bundle Tag Info'!$A$1," ",CHAR(10),'Bundle Tag Info'!$A$2," ",'Bundle Tag Info'!$A$3,CHAR(10),'Bundle Tag Info'!A$6,CHAR(10),'Bundle Tag Info'!A$12),"") -> TCM-70 #1 4P441 B.1 JB70 SH0471 | B7: =IF('Bundle Tag Info'!B$12<>"",CONCATENATE('Bundle Tag Info'!$A$1," ",CHAR(10),'Bundle Tag Info'!$A$2," ",'Bundle Tag Info'!$A$3,CHAR(10),'Bundle Tag Info'!B$6,CHAR(10),'Bundle Tag Info'!B$12),"") -> TCM-70 #1 4P441 B.1 JB70 LEFT RAIL XT - FS | C7: =IF('Bundle Tag Info'!C$12<>"",CONCATENATE('Bundle Tag Info'!$A$1," ",CHAR(10),'Bundle Tag Info'!$A$2," ",'Bundle Tag Info'!$A$3,CHAR(10),'Bundle Tag Info'!C$6,CHAR(10),'Bundle Tag Info'!C$12),"") | D7: =IF('Bundle Tag Info'!D$12<>"",CONCATENATE('Bundle Tag Info'!$A$1," ",CHAR(10),'Bundle Tag Info'!$A$2," ",'Bundle Tag Info'!$A$3,CHAR(10),'Bundle Tag Info'!D$6,CHAR(10),'Bundle Tag Info'!D$12),"") -> TCM-70 #1 4P441 B.1 JB70 RIGHT RAIL XT - PLC | E7: =IF('Bundle Tag Info'!E$12<>"",CONCATENATE('Bundle Tag Info'!$A$1," ",CHAR(10),'Bundle Tag Info'!$A$2," ",'Bundle Tag Info'!$A$3,CHAR(10),'Bundle Tag Info'!E$6,CHAR(10),'Bundle Tag Info'!E$12),"") | F7: =IF('Bundle Tag Info'!F$12<>"",CONCATENATE('Bundle Tag Info'!$A$1," ",CHAR(10),'Bundle Tag Info'!$A$2," ",'Bundle Tag Info'!$A$3,CHAR(10),'Bundle Tag Info'!F$6,CHAR(10),'Bundle Tag Info'!F$12),"") -> TCM-70 #1 4P441 B.1 A AF0080's - B | G7: =IF('Bundle Tag Info'!G$12<>"",CONCATENATE('Bundle Tag Info'!$A$1," ",CHAR(10),'Bundle Tag Info'!$A$2," ",'Bundle Tag Info'!$A$3,CHAR(10),'Bundle Tag Info'!G$6,CHAR(10),'Bundle Tag Info'!G$12),"") -> TCM-70 #1 4P441 B.1 B KA | H7: =IF('Bundle Tag Info'!H$13<>"",CONCATENATE('Bundle Tag Info'!$A$1," ",CHAR(10),'Bundle Tag Info'!$A$2," ",'Bundle Tag Info'!$A$3,CHAR(10),'Bundle Tag Info'!H$6,CHAR(10),'Bundle Tag Info'!H$13),"") | I7: =IF('Bundle Tag Info'!I$12<>"",CONCATENATE('Bundle Tag Info'!$A$1," ",CHAR(10),'Bundle Tag Info'!$A$2," ",'Bundle Tag Info'!$A$3,CHAR(10),'Bundle Tag Info'!I$6,CHAR(10),'Bundle Tag Info'!I$12),"") | J7: =IF('Bundle Tag Info'!J$12<>"",CONCATENATE('Bundle Tag Info'!$A$1," ",CHAR(10),'Bundle Tag Info'!$A$2," ",'Bundle Tag Info'!$A$3,CHAR(10),'Bundle Tag Info'!J$6,CHAR(10),'Bundle Tag Info'!J$12),"") | K7: =IF('Bundle Tag Info'!K$12<>"",CONCATENATE('Bundle Tag Info'!$A$1," ",CHAR(10),'Bundle Tag Info'!$A$2," ",'Bundle Tag Info'!$A$3,CHAR(10),'Bundle Tag Info'!K$6,CHAR(10),'Bundle Tag Info'!K$12),"") | L7: =IF('Bundle Tag Info'!L$12<>"",CONCATENATE('Bundle Tag Info'!$A$1," ",CHAR(10),'Bundle Tag Info'!$A$2," ",'Bundle Tag Info'!$A$3,CHAR(10),'Bundle Tag Info'!L$6,CHAR(10),'Bundle Tag Info'!L$12),"") | M7: =IF('Bundle Tag Info'!M$12<>"",CONCATENATE('Bundle Tag Info'!$A$1," ",CHAR(10),'Bundle Tag Info'!$A$2," ",'Bundle Tag Info'!$A$3,CHAR(10),'Bundle Tag Info'!M$6,CHAR(10),'Bundle Tag Info'!M$12),"") | N7: =IF('Bundle Tag Info'!N$12<>"",CONCATENATE('Bundle Tag Info'!$A$1," ",CHAR(10),'Bundle Tag Info'!$A$2," ",'Bundle Tag Info'!$A$3,CHAR(10),'Bundle Tag Info'!N$6,CHAR(10),'Bundle Tag Info'!N$12),"") | O7: =IF('Bundle Tag Info'!O$12<>"",CONCATENATE('Bundle Tag Info'!$A$1," ",CHAR(10),'Bundle Tag Info'!$A$2," ",'Bundle Tag Info'!$A$3,CHAR(10),'Bundle Tag Info'!O$6,CHAR(10),'Bundle Tag Info'!O$12),"") | P7: =IF('Bundle Tag Info'!P$12<>"",CONCATENATE('Bundle Tag Info'!$A$1," ",CHAR(10),'Bundle Tag Info'!$A$2," ",'Bundle Tag Info'!$A$3,CHAR(10),'Bundle Tag Info'!P$6,CHAR(10),'Bundle Tag Info'!P$12),"") | ... AD7: =IF('Bundle Tag Info'!AD$12<>"",CONCATENATE('Bundle Tag Info'!$A$1," ",CHAR(10),'Bundle Tag Info'!$A$2," ",'Bundle Tag Info'!$A$3,CHAR(10),'Bundle Tag Info'!AD$6,CHAR(10),'Bundle Tag Info'!AD$12),"")
A8: =IF('Bundle Tag Info'!A$13<>"",CONCATENATE('Bundle Tag Info'!$A$1," ",CHAR(10),'Bundle Tag Info'!$A$2," ",'Bundle Tag Info'!$A$3,CHAR(10),'Bundle Tag Info'!A$6,CHAR(10),'Bundle Tag Info'!A$13),"") -> TCM-70 #1 4P441 B.1 JB70 SH0470 | B8: =IF('Bundle Tag Info'!B$13<>"",CONCATENATE('Bundle Tag Info'!$A$1," ",CHAR(10),'Bundle Tag Info'!$A$2," ",'Bundle Tag Info'!$A$3,CHAR(10),'Bundle Tag Info'!B$6,CHAR(10),'Bundle Tag Info'!B$13),"") -> TCM-70 #1 4P441 B.1 JB70 LEFT RAIL THRU | C8: =IF('Bundle Tag Info'!C$13<>"",CONCATENATE('Bundle Tag Info'!$A$1," ",CHAR(10),'Bundle Tag Info'!$A$2," ",'Bundle Tag Info'!$A$3,CHAR(10),'Bundle Tag Info'!C$6,CHAR(10),'Bundle Tag Info'!C$13),"") | D8: =IF('Bundle Tag Info'!D$13<>"",CONCATENATE('Bundle Tag Info'!$A$1," ",CHAR(10),'Bundle Tag Info'!$A$2," ",'Bundle Tag Info'!$A$3,CHAR(10),'Bundle Tag Info'!D$6,CHAR(10),'Bundle Tag Info'!D$13),"") | E8: =IF('Bundle Tag Info'!E$13<>"",CONCATENATE('Bundle Tag Info'!$A$1," ",CHAR(10),'Bundle Tag Info'!$A$2," ",'Bundle Tag Info'!$A$3,CHAR(10),'Bundle Tag Info'!E$6,CHAR(10),'Bundle Tag Info'!E$13),"") | F8: =IF('Bundle Tag Info'!F$13<>"",CONCATENATE('Bundle Tag Info'!$A$1," ",CHAR(10),'Bundle Tag Info'!$A$2," ",'Bundle Tag Info'!$A$3,CHAR(10),'Bundle Tag Info'!F$6,CHAR(10),'Bundle Tag Info'!F$13),"") -> TCM-70 #1 4P441 B.1 A AF0090's - B | G8: =IF('Bundle Tag Info'!G$13<>"",CONCATENATE('Bundle Tag Info'!$A$1," ",CHAR(10),'Bundle Tag Info'!$A$2," ",'Bundle Tag Info'!$A$3,CHAR(10),'Bundle Tag Info'!G$6,CHAR(10),'Bundle Tag Info'!G$13),"") -> TCM-70 #1 4P441 B.1 B KT | H8: =IF('Bundle Tag Info'!H$14<>"",CONCATENATE('Bundle Tag Info'!$A$1," ",CHAR(10),'Bundle Tag Info'!$A$2," ",'Bundle Tag Info'!$A$3,CHAR(10),'Bundle Tag Info'!H$6,CHAR(10),'Bundle Tag Info'!H$14),"") | I8: =IF('Bundle Tag Info'!I$13<>"",CONCATENATE('Bundle Tag Info'!$A$1," ",CHAR(10),'Bundle Tag Info'!$A$2," ",'Bundle Tag Info'!$A$3,CHAR(10),'Bundle Tag Info'!I$6,CHAR(10),'Bundle Tag Info'!I$13),"") | J8: =IF('Bundle Tag Info'!J$13<>"",CONCATENATE('Bundle Tag Info'!$A$1," ",CHAR(10),'Bundle Tag Info'!$A$2," ",'Bundle Tag Info'!$A$3,CHAR(10),'Bundle Tag Info'!J$6,CHAR(10),'Bundle Tag Info'!J$13),"") | K8: =IF('Bundle Tag Info'!K$13<>"",CONCATENATE('Bundle Tag Info'!$A$1," ",CHAR(10),'Bundle Tag Info'!$A$2," ",'Bundle Tag Info'!$A$3,CHAR(10),'Bundle Tag Info'!K$6,CHAR(10),'Bundle Tag Info'!K$13),"") | L8: =IF('Bundle Tag Info'!L$13<>"",CONCATENATE('Bundle Tag Info'!$A$1," ",CHAR(10),'Bundle Tag Info'!$A$2," ",'Bundle Tag Info'!$A$3,CHAR(10),'Bundle Tag Info'!L$6,CHAR(10),'Bundle Tag Info'!L$13),"") | M8: =IF('Bundle Tag Info'!M$13<>"",CONCATENATE('Bundle Tag Info'!$A$1," ",CHAR(10),'Bundle Tag Info'!$A$2," ",'Bundle Tag Info'!$A$3,CHAR(10),'Bundle Tag Info'!M$6,CHAR(10),'Bundle Tag Info'!M$13),"") | N8: =IF('Bundle Tag Info'!N$13<>"",CONCATENATE('Bundle Tag Info'!$A$1," ",CHAR(10),'Bundle Tag Info'!$A$2," ",'Bundle Tag Info'!$A$3,CHAR(10),'Bundle Tag Info'!N$6,CHAR(10),'Bundle Tag Info'!N$13),"") | O8: =IF('Bundle Tag Info'!O$13<>"",CONCATENATE('Bundle Tag Info'!$A$1," ",CHAR(10),'Bundle Tag Info'!$A$2," ",'Bundle Tag Info'!$A$3,CHAR(10),'Bundle Tag Info'!O$6,CHAR(10),'Bundle Tag Info'!O$13),"") | P8: =IF('Bundle Tag Info'!P$13<>"",CONCATENATE('Bundle Tag Info'!$A$1," ",CHAR(10),'Bundle Tag Info'!$A$2," ",'Bundle Tag Info'!$A$3,CHAR(10),'Bundle Tag Info'!P$6,CHAR(10),'Bundle Tag Info'!P$13),"") | ... AD8: =IF('Bundle Tag Info'!AD$13<>"",CONCATENATE('Bundle Tag Info'!$A$1," ",CHAR(10),'Bundle Tag Info'!$A$2," ",'Bundle Tag Info'!$A$3,CHAR(10),'Bundle Tag Info'!AD$6,CHAR(10),'Bundle Tag Info'!AD$13),"")
A9: =IF('Bundle Tag Info'!A$14<>"",CONCATENATE('Bundle Tag Info'!$A$1," ",CHAR(10),'Bundle Tag Info'!$A$2," ",'Bundle Tag Info'!$A$3,CHAR(10),'Bundle Tag Info'!A$6,CHAR(10),'Bundle Tag Info'!A$14),"") -> TCM-70 #1 4P441 B.1 JB70 SB0474 | B9: =IF('Bundle Tag Info'!B$14<>"",CONCATENATE('Bundle Tag Info'!$A$1," ",CHAR(10),'Bundle Tag Info'!$A$2," ",'Bundle Tag Info'!$A$3,CHAR(10),'Bundle Tag Info'!B$6,CHAR(10),'Bundle Tag Info'!B$14),"") | C9: =IF('Bundle Tag Info'!C$14<>"",CONCATENATE('Bundle Tag Info'!$A$1," ",CHAR(10),'Bundle Tag Info'!$A$2," ",'Bundle Tag Info'!$A$3,CHAR(10),'Bundle Tag Info'!C$6,CHAR(10),'Bundle Tag Info'!C$14),"") | D9: =IF('Bundle Tag Info'!D$14<>"",CONCATENATE('Bundle Tag Info'!$A$1," ",CHAR(10),'Bundle Tag Info'!$A$2," ",'Bundle Tag Info'!$A$3,CHAR(10),'Bundle Tag Info'!D$6,CHAR(10),'Bundle Tag Info'!D$14),"") | E9: =IF('Bundle Tag Info'!E$14<>"",CONCATENATE('Bundle Tag Info'!$A$1," ",CHAR(10),'Bundle Tag Info'!$A$2," ",'Bundle Tag Info'!$A$3,CHAR(10),'Bundle Tag Info'!E$6,CHAR(10),'Bundle Tag Info'!E$14),"") | F9: =IF('Bundle Tag Info'!F$14<>"",CONCATENATE('Bundle Tag Info'!$A$1," ",CHAR(10),'Bundle Tag Info'!$A$2," ",'Bundle Tag Info'!$A$3,CHAR(10),'Bundle Tag Info'!F$6,CHAR(10),'Bundle Tag Info'!F$14),"") -> TCM-70 #1 4P441 B.1 A KA A1/2 - B | G9: =IF('Bundle Tag Info'!G$14<>"",CONCATENATE('Bundle Tag Info'!$A$1," ",CHAR(10),'Bundle Tag Info'!$A$2," ",'Bundle Tag Info'!$A$3,CHAR(10),'Bundle Tag Info'!G$6,CHAR(10),'Bundle Tag Info'!G$14),"") -> TCM-70 #1 4P441 B.1 B UA1200 | H9: =IF('Bundle Tag Info'!H$15<>"",CONCATENATE('Bundle Tag Info'!$A$1," ",CHAR(10),'Bundle Tag Info'!$A$2," ",'Bundle Tag Info'!$A$3,CHAR(10),'Bundle Tag Info'!H$6,CHAR(10),'Bundle Tag Info'!H$15),"") | I9: =IF('Bundle Tag Info'!I$14<>"",CONCATENATE('Bundle Tag Info'!$A$1," ",CHAR(10),'Bundle Tag Info'!$A$2," ",'Bundle Tag Info'!$A$3,CHAR(10),'Bundle Tag Info'!I$6,CHAR(10),'Bundle Tag Info'!I$14),"") | J9: =IF('Bundle Tag Info'!J$14<>"",CONCATENATE('Bundle Tag Info'!$A$1," ",CHAR(10),'Bundle Tag Info'!$A$2," ",'Bundle Tag Info'!$A$3,CHAR(10),'Bundle Tag Info'!J$6,CHAR(10),'Bundle Tag Info'!J$14),"") | K9: =IF('Bundle Tag Info'!K$14<>"",CONCATENATE('Bundle Tag Info'!$A$1," ",CHAR(10),'Bundle Tag Info'!$A$2," ",'Bundle Tag Info'!$A$3,CHAR(10),'Bundle Tag Info'!K$6,CHAR(10),'Bundle Tag Info'!K$14),"") | L9: =IF('Bundle Tag Info'!L$14<>"",CONCATENATE('Bundle Tag Info'!$A$1," ",CHAR(10),'Bundle Tag Info'!$A$2," ",'Bundle Tag Info'!$A$3,CHAR(10),'Bundle Tag Info'!L$6,CHAR(10),'Bundle Tag Info'!L$14),"") | M9: =IF('Bundle Tag Info'!M$14<>"",CONCATENATE('Bundle Tag Info'!$A$1," ",CHAR(10),'Bundle Tag Info'!$A$2," ",'Bundle Tag Info'!$A$3,CHAR(10),'Bundle Tag Info'!M$6,CHAR(10),'Bundle Tag Info'!M$14),"") | N9: =IF('Bundle Tag Info'!N$14<>"",CONCATENATE('Bundle Tag Info'!$A$1," ",CHAR(10),'Bundle Tag Info'!$A$2," ",'Bundle Tag Info'!$A$3,CHAR(10),'Bundle Tag Info'!N$6,CHAR(10),'Bundle Tag Info'!N$14),"") | O9: =IF('Bundle Tag Info'!O$14<>"",CONCATENATE('Bundle Tag Info'!$A$1," ",CHAR(10),'Bundle Tag Info'!$A$2," ",'Bundle Tag Info'!$A$3,CHAR(10),'Bundle Tag Info'!O$6,CHAR(10),'Bundle Tag Info'!O$14),"") | P9: =IF('Bundle Tag Info'!P$14<>"",CONCATENATE('Bundle Tag Info'!$A$1," ",CHAR(10),'Bundle Tag Info'!$A$2," ",'Bundle Tag Info'!$A$3,CHAR(10),'Bundle Tag Info'!P$6,CHAR(10),'Bundle Tag Info'!P$14),"") | ... AD9: =IF('Bundle Tag Info'!AD$14<>"",CONCATENATE('Bundle Tag Info'!$A$1," ",CHAR(10),'Bundle Tag Info'!$A$2," ",'Bundle Tag Info'!$A$3,CHAR(10),'Bundle Tag Info'!AD$6,CHAR(10),'Bundle Tag Info'!AD$14),"")
