Workbook

Sheet LIGHTS_S
A1: ASSEMBLY^CONSOLE
A2: CONTROL CONSOLE
A3: Project # | B3: J1620
A4: Project Name | B4: SOUTHERNSTAR LONEJACK
A5: Revision | B5: A
A7: Controls DE | B7: M.ZUNIGA
A8: Phone:
A9: Controls ME | B9: S.MARTINEZ
A10: Phone:
A12: From | G12: To
A13: Device ID | B13: Wire No. | C13: Wire ID | D13: Gauge/Size | E13: Length | F13: Device ID | G13: Location | H13: Bundle Name
A14: EL0273:B1 | B14: ZS0273 | C14: WHT | D14: 14 | E14: 60 | F14: ZS0273:2 | G14: LIGHTS | H14: EL0/ZS
A16: EL0273:W1 | B16: -0V1 | C16: WHT | D16: 14 | E16: 120 | F16: XT0562:1 | G16: PWR DST RAIL
A17: ZS0273:1 | B17: FU0273 | C17: WHT | D17: 14 | E17: 120 | F17: FU0273:LD | G17: PWR DST RAIL

Sheet DOOR_S
A1: CONSOLE DOOR^PANELS
A2: CONTROL CONSOLE
A3: Project # | B3: J1620
A4: Project Name | B4: SOUTHERNSTAR LONEJACK
A5: Revision | B5: A
A7: Controls DE | B7: M.ZUNIGA
A8: Phone:
A9: Controls ME | B9: S.MARTINEZ
A10: Phone:
A12: From | G12: To
A13: Device ID | B13: Wire No. | C13: Wire ID | D13: Gauge/Size | E13: Length | F13: Device ID | G13: Location | H13: Bundle Name
A14: AT0190:NEG | B14: -0V1 | C14: WHT | D14: 14 | E14: 80 | F14: XT0562:2 | G14: PWR DST RAIL | H14: AT0190
A15: AT0190:POS | B15: FU0190 | C15: WHT | D15: 14 | E15: 80 | F15: FU0190:LD | G15: PWR DST RAIL

Sheet PWR DST RAIL_S
A1: PWR DISTRIBUTION RAIL
A2: CONTROL CONSOLE
A3: Project # | B3: J1620
A4: Project Name | B4: SOUTHERNSTAR LONEJACK
A5: Revision | B5: A
A7: Controls DE | B7: M.ZUNIGA
A8: Phone:
A9: Controls ME | B9: S.MARTINEZ
A10: Phone:
A12: From | G12: To
A13: Device ID | B13: Wire No. | C13: Wire ID | D13: Gauge/Size | E13: Length | F13: Device ID | G13: Location | H13: Bundle Name
A14: AT0680:POS | B14: AT0680POS | C14: WHT | D14: 14 | E14: 60 | F14: XT0680:1 | G14: PWR DST RAIL | H14: AT
A16: AT0680:NEG | B16: -0V | C16: WHT | D16: 12 | E16: 60 | F16: XT0680:2 | G16: PWR DST RAIL
A18: FU0680:LD | B18: AT0680POS | C18: WHT | D18: 14 | E18: 60 | F18: XT0680:1 | G18: PWR DST RAIL | H18: FU
A19: FU0200:LI | B19: FU0200LI | C19: WHT | D19: 14 | E19: 60 | F19: XT0561:1 | G19: PWR DST RAIL
A20: FU0201:LI | B20: FU0200LI | C20: WHT | D20: 14 | E20: 60 | F20: FU0273:LI | G20: PWR DST RAIL
A21: FU0560:LD | B21: FU0200LI | C21: WHT | D21: 14 | E21: 60 | F21: XT0561:1 | G21: PWR DST RAIL
A23: FU0560:LI | B23: FU0136 | C23: WHT | D23: 12 | E23: 60 | F23: XT0560:1 | G23: PWR DST RAIL
A25: XT0560:2 | B25: -0V | C25: WHT | D25: 12 | E25: 160 | F25: XT0134:2 | G25: A | H25: XT-A
A26: XT0560:1 | B26: FU0136 | C26: WHT | D26: 12 | E26: 140 | F26: XT0138:2 | G26: A
A28: XT0563:2 | B28: ESTOPA | C28: WHT | D28: 20 | E28: 180 | F28: XT0240:3 | G28: B | H28: XT/FU-B
A29: XT0563:1 | B29: ESTOPB | C29: WHT | D29: 20 | E29: 180 | F29: XT0240:2 | G29: B
A30: XT0563:6 | B30: FU0139 | C30: WHT | D30: 20 | E30: 180 | F30: XT0240:11 | G30: B
A31: XT0563:3 | B31: KA023612 | C31: WHT | D31: 20 | E31: 180 | F31: XT0240:13 | G31: B
A32: XT0563:5 | B32: KA0241A1 | C32: WHT | D32: 20 | E32: 180 | F32: XT0240:6 | G32: B
A34: XT0563:4 | B34: -0V | C34: WHT | D34: 12 | E34: 180 | F34: XT0240:9 | G34: B
A35: XT0680:2 | B35: -0V | C35: WHT | D35: 12 | E35: 160 | F35: XT0235:3 | G35: B
A36: FU0680:LI | B36: FU0210 | C36: WHT | D36: 12 | E36: 160 | F36: XT0233:3 | G36: B

Sheet BOP_S
A1: BOP^PANEL
A2: CONTROL CONSOLE
A3: Project # | B3: J1620
A4: Project Name | B4: SOUTHERNSTAR LONEJACK
A5: Revision | B5: A
A7: Controls DE | B7: M.ZUNIGA
A8: Phone:
A9: Controls ME | B9: S.MARTINEZ
A10: Phone:
A12: From | G12: To
A13: Device ID | B13: Wire No. | C13: Wire ID | D13: Gauge/Size | E13: Length | F13: Device ID | G13: Location | H13: Bundle Name
A14: AF0141:16 | B14: SV76212 | C14: WHT | D14: 20 | E14: 60 | F14: XT0572:4 | G14: BOP | H14: AF/AU
A15: AF0141:20 | B15: SV76412 | C15: WHT | D15: 20 | E15: 60 | F15: XT0572:5 | G15: BOP
A16: AF0141:10 | B16: XT0573B2 | C16: WHT | D16: 20 | E16: 60 | F16: XT0573:4 B2 | G16: BOP
A17: AF0142:07 | B17: ZSC76112 | C17: WHT | D17: 20 | E17: 60 | F17: XT0572:1 | G17: BOP
A18: AF0147:04 | B18: ZSC76212 | C18: WHT | D18: 20 | E18: 80 | F18: XT0572:2 | G18: BOP
A19: AF0147:05 | B19: ZSC76412 | C19: WHT | D19: 20 | E19: 80 | F19: XT0572:3 | G19: BOP
A21: AF0141:COM | B21: -0V | C21: WHT | D21: 16 | E21: 60 | F21: XT0140:3 | G21: BOP
A22: AF0146:COM | B22: -0V | C22: WHT | D22: 16 | E22: 60 | F22: XT0140:3 | G22: BOP
A23: AU0140:COM | B23: -0V | C23: WHT | D23: 16 | E23: 60 | F23: XT0140:2 | G23: BOP
A24: AF0145:COM | B24: AF0145N | C24: WHT | D24: 16 | E24: 60 | F24: AF0147:COM | G24: BOP
A25: AF0145:V+ | B25: AF0145P | C25: WHT | D25: 16 | E25: 60 | F25: AF0147:V+ | G25: BOP
A26: AF0142:COM | B26: AU0140N | C26: WHT | D26: 16 | E26: 60 | F26: AU0140:COM | G26: BOP
A27: AF0142:V+ | B27: AU0140P | C27: WHT | D27: 16 | E27: 60 | F27: AU0140:V+ | G27: BOP
... A30: AF0146:V+ | B30: FU0142 | C30: WHT | D30: 16 | E30: 60 | F30: FU0142:LD | G30: BOP
A32: KA0550:A1 | B32: -014602 | C32: WHT | D32: 20 | E32: 100 | F32: AF0146:02 | G32: BOP | H32: KA A1
A33: KA0552:A1 | B33: -014603 | C33: WHT | D33: 20 | E33: 100 | F33: AF0146:03 | G33: BOP
A34: KA0551:A1 | B34: -014605 | C34: WHT | D34: 20 | E34: 100 | F34: AF0146:05 | G34: BOP
A35: KA0553:A1 | B35: -014606 | C35: WHT | D35: 20 | E35: 100 | F35: AF0146:06 | G35: BOP
A36: KA0554:A1 | B36: -014608 | C36: WHT | D36: 20 | E36: 100 | F36: AF0146:08 | G36: BOP
A37: KA0555:A1 | B37: -014609 | C37: WHT | D37: 20 | E37: 100 | F37: AF0146:09 | G37: BOP
A38: KA0531:A1 | B38: ESTOP | C38: WHT | D38: 20 | E38: 60 | F38: XT0140:6 | G38: BOP
A39: KA0535:A1 | B39: KA0120A1 | C39: WHT | D39: 20 | E39: 60 | F39: XT0140:5 | G39: BOP
A40: KA0540:A1 | B40: KA053124 | C40: WHT | D40: 20 | E40: 60 | F40: KA0531:24 | G40: BOP
A41: KA0541:A1 | B41: KA053214 | C41: WHT | D41: 20 | E41: 60 | F41: KA0532:14 | G41: BOP
A43: KA0550:A2 | B43: -014618 | C43: WHT | D43: 20 | E43: 100 | F43: AF0146:18 | G43: BOP | H43: KA A2
A44: KA0552:A2 | B44: -014619 | C44: WHT | D44: 20 | E44: 100 | F44: AF0146:19 | G44: BOP
A45: KA0551:A2 | B45: -014621 | C45: WHT | D45: 20 | E45: 100 | F45: AF0146:21 | G45: BOP
A46: KA0553:A2 | B46: -014622 | C46: WHT | D46: 20 | E46: 100 | F46: AF0146:22 | G46: BOP
A47: KA0554:A2 | B47: -014624 | C47: WHT | D47: 20 | E47: 100 | F47: AF0146:24 | G47: BOP
...

Sheet PLC_S
A1: PLC PANEL
A2: CONTROL CONSOLE
A3: Project # | B3: J1620
A4: Project Name | B4: SOUTHERNSTAR LONEJACK
A5: Revision | B5: A
A7: Controls DE | B7: M.ZUNIGA
A8: Phone:
A9: Controls ME | B9: S.MARTINEZ
A10: Phone:
A12: From | G12: To
A13: Device ID | B13: Wire No. | C13: Wire ID | D13: Gauge/Size | E13: Length | F13: Device ID | G13: Location | H13: Bundle Name
A14: PC0470:INP_A | B14: -009312 | C14: WHT | D14: 20 | E14: 80 | F14: AF0093:12 | G14: A | H14: PC
A15: PC0470:-PWR | B15: -009328 | C15: WHT | D15: 20 | E15: 80 | F15: AF0093:28 | G15: A
A16: PC0470:+PWR | B16: -009344 | C16: WHT | D16: 20 | E16: 80 | F16: AF0093:44 | G16: A
A18: UV0600:(+) | B18: FU0010 | C18: WHT | D18: 14 | E18: 80 | F18: FU0010:LD | G18: A | H18: UV
A20: UV0600:(-) | B20: -0V | C20: WHT | D20: 12 | E20: 80 | F20: XT0135:1 | G20: A

Sheet A_S
A1: TURBINE PANEL A
A2: CONTROL CONSOLE
A3: Project # | B3: J1620
A4: Project Name | B4: SOUTHERNSTAR LONEJACK
A5: Revision | B5: A
A7: Controls DE | B7: M.ZUNIGA
A8: Phone:
A9: Controls ME | B9: S.MARTINEZ
A10: Phone:
A12: From | G12: To
A13: Device ID | B13: Wire No. | C13: Wire ID | D13: Gauge/Size | E13: Length | F13: Device ID | G13: Location | H13: Bundle Name
A14: AF0082:COM | B14: -0V | C14: WHT | D14: 14 | E14: 60 | F14: XT0080:2 | G14: A | H14: AF/AU080s
A15: AU0080:COM | B15: -0V | C15: WHT | D15: 14 | E15: 60 | F15: XT0080:1 | G15: A
A16: AU0080:V+ | B16: FU0080 | C16: WHT | D16: 14 | E16: 60 | F16: FU0080:LD | G16: A
A17: AF0082:V+ | B17: FU0081 | C17: WHT | D17: 14 | E17: 60 | F17: FU0081:LD | G17: A
A19: AF0093:04 | B19: -009304 | C19: WHT | D19: 20 | E19: 60 | F19: XT0171:2 | G19: A | H19: AF/AU090s
A20: AF0094:00 | B20: -009400 | C20: WHT | D20: 20 | E20: 80 | F20: XT0085:2 | G20: A
A21: AF0094:01 | B21: -0V | C21: WHT | D21: 20 | E21: 80 | F21: XT0085:3 | G21: A
A22: AF0091:COM | B22: AF0091N | C22: WHT | D22: 20 | E22: 60 | F22: AF0094:COM | G22: A
A23: AF0091:V+ | B23: AF0091P | C23: WHT | D23: 20 | E23: 60 | F23: AF0094:V+ | G23: A
A24: AF0094:COM | B24: AF0094N | C24: WHT | D24: 20 | E24: 60 | F24: AF0096:COM | G24: A
A25: AF0094:V+ | B25: AF0094P | C25: WHT | D25: 20 | E25: 60 | F25: AF0096:V+ | G25: A
A27: AF0092:COM | B27: -0V | C27: WHT | D27: 14 | E27: 60 | F27: XT0090:2 | G27: A
A28: AF0093:COM | B28: -0V | C28: WHT | D28: 14 | E28: 60 | F28: XT0090:2 | G28: A
A29: AF0095:COM | B29: -0V | C29: WHT | D29: 14 | E29: 60 | F29: XT0090:2 | G29: A
A30: AU0090:COM | B30: -0V | C30: WHT | D30: 14 | E30: 60 | F30: XT0090:1 | G30: A
A31: AU0090:V+ | B31: FU0090 | C31: WHT | D31: 14 | E31: 60 | F31: FU0090:LD | G31: A
A32: AF0092:V+ | B32: FU0091 | C32: WHT | D32: 14 | E32: 60 | F32: FU0091:LD | G32: A
... A34: AF0095:V+ | B34: FU0093 | C34: WHT | D34: 14 | E34: 80 | F34: FU0093:LD | G34: A
A36: FU0010:LI | B36: FU0137 | C36: WHT | D36: 14 | E36: 60 | F36: XT0139:1 | G36: A | H36: FU
A37: FU0080:LI | B37: FU0137 | C37: WHT | D37: 14 | E37: 60 | F37: XT0139:2 | G37: A
A38: FU0090:LI | B38: FU0137 | C38: WHT | D38: 14 | E38: 60 | F38: XT0139:2 | G38: A
A39: FU0139:LI | B39: FU0137 | C39: WHT | D39: 14 | E39: 60 | F39: XT0139:1 | G39: A
A40: FU0139:LD | B40: FU0139 | C40: WHT | D40: 14 | E40: 60 | F40: XT0136:1 | G40: A
A42: FU0012:LI | B42: -24V | C42: WHT | D42: 12 | E42: 60 | F42: XT0012:3 | G42: A
A43: FU0137:LI | B43: FU0136 | C43: WHT | D43: 12 | E43: 60 | F43: XT0138:1 | G43: A
A44: FU0137:LD | B44: FU0137 | C44: WHT | D44: 12 | E44: 60 | F44: XT0139:1 | G44: A
A46: KA0130:A1 | B46: -008135 | C46: WHT | D46: 20 | E46: 100 | F46: AF0081:35 | G46: A | H46: KA A1
A47: KA0130:A1 | B47: -008135 | C47: WHT | D47: 20 | E47: 100 | F47: KA0130:11 | G47: A
A48: KA2160:A1 | B48: -009204 | C48: WHT | D48: 20 | E48: 60 | F48: AF0092:04 | G48: A
...

Sheet B_S
A1: TURBINE PANEL B
A2: CONTROL CONSOLE
A3: Project # | B3: J1620
A4: Project Name | B4: SOUTHERNSTAR LONEJACK
A5: Revision | B5: A
A7: Controls DE | B7: M.ZUNIGA
A8: Phone:
A9: Controls ME | B9: S.MARTINEZ
A10: Phone:
A12: From | G12: To
A13: Device ID | B13: Wire No. | C13: Wire ID | D13: Gauge/Size | E13: Length | F13: Device ID | G13: Location | H13: Bundle Name
A14: AF0063:COM | B14: AU0060N | C14: WHT | D14: 20 | E14: 60 | F14: AU0060:COM | G14: B | H14: AF/AU060s
A15: AF0063:V+ | B15: AU0060P | C15: WHT | D15: 20 | E15: 60 | F15: AU0060:V+ | G15: B
A16: AF0062:16 | B16: SV21242 | C16: WHT | D16: 20 | E16: 60 | F16: XT0060:6 | G16: B
A18: AF0061:COM | B18: -0V | C18: WHT | D18: 16 | E18: 60 | F18: XT0060:2 | G18: B
A19: AF0062:COM | B19: -0V | C19: WHT | D19: 16 | E19: 60 | F19: XT0060:2 | G19: B
A20: AU0060:COM | B20: -0V | C20: WHT | D20: 16 | E20: 60 | F20: XT0060:1 | G20: B
A21: AU0060:V+ | B21: FU0060 | C21: WHT | D21: 16 | E21: 60 | F21: FU0060:LD | G21: B
A23: AF0061:V+ | B23: FU0061 | C23: WHT | D23: 14 | E23: 60 | F23: FU0061:LD | G23: B
A24: AF0062:V+ | B24: FU0062 | C24: WHT | D24: 14 | E24: 60 | F24: FU0062:LD | G24: B
A26: AF0076:12 | B26: -007612 | C26: WHT | D26: 20 | E26: 60 | F26: XT0237:1 B2 | G26: B | H26: AF/AU070s
A28: AF0076:COM | B28: -0V | C28: WHT | D28: 16 | E28: 60 | F28: XT0070:2 | G28: B
A29: AU0070:COM | B29: -0V | C29: WHT | D29: 16 | E29: 60 | F29: XT0070:1 | G29: B
A30: AU0070:V+ | B30: FU0070 | C30: WHT | D30: 16 | E30: 60 | F30: FU0070:LD | G30: B
A31: AF0076:V+ | B31: FU0071 | C31: WHT | D31: 16 | E31: 60 | F31: FU0071:LD | G31: B
A33: FU0060:LI | B33: FU0210 | C33: WHT | D33: 16 | E33: 60 | F33: XT0233:1 | G33: B | H33: FU
A34: FU0070:LI | B34: FU0210 | C34: WHT | D34: 16 | E34: 60 | F34: XT0233:2 | G34: B
A35: FU0212:LD | B35: FU0212 | C35: WHT | D35: 16 | E35: 60 | F35: XT0233:4 | G35: B
A37: FU0210:LD | B37: FU0210 | C37: WHT | D37: 12 | E37: 60 | F37: XT0233:1 | G37: B
A38: FU0212:LI | B38: FU0210 | C38: WHT | D38: 12 | E38: 60 | F38: XT0233:1 | G38: B
A40: KA0217:A1 | B40: -007600 | C40: WHT | D40: 20 | E40: 80 | F40: AF0076:00 | G40: B | H40: KA A1
A41: KA1020:A1 | B41: -007607 | C41: WHT | D41: 20 | E41: 100 | F41: AF0076:07 | G41: B
A42: KA0235:A1 | B42: ESTOP | C42: WHT | D42: 20 | E42: 60 | F42: XT0240:4 | G42: B
A43: KA0241:A1 | B43: KA0241A1 | C43: WHT | D43: 20 | E43: 60 | F43: XT0240:6 | G43: B
A44: KA0243:A1 | B44: KA0243A1 | C44: WHT | D44: 20 | E44: 60 | F44: XT0240:7 | G44: B
A45: KA0245:A1 | B45: KA0245A1 | C45: WHT | D45: 20 | E45: 60 | F45: XT0240:8 | G45: B
A47: KA0221:A1 | B47: -007602 | C47: WHT | D47: 16 | E47: 100 | F47: AF0076:02 | G47: B
A48: KA0222:A1 | B48: -007604 | C48: WHT | D48: 16 | E48: 100 | F48: AF0076:04 | G48: B
A50: KA0217:A2 | B50: -007616 | C50: WHT | D50: 20 | E50: 80 | F50: AF0076:16 | G50: B | H50: KA A2
A51: KA0221:A2 | B51: -007618 | C51: WHT | D51: 20 | E51: 100 | F51: AF0076:18 | G51: B
...

Sheet HPC_S
A1: HP COMPRESSOR^PANEL
A2: CONTROL CONSOLE
A3: Project # | B3: J1620
A4: Project Name | B4: SOUTHERNSTAR LONEJACK
A5: Revision | B5: A
A7: Controls DE | B7: M.ZUNIGA
A8: Phone:
A9: Controls ME | B9: S.MARTINEZ
A10: Phone:
A12: From | G12: To
A13: Device ID | B13: Wire No. | C13: Wire ID | D13: Gauge/Size | E13: Length | F13: Device ID | G13: Location | H13: Bundle Name
A14: AF0410:53 | B14: -0V | C14: WHT | D14: 16 | E14: 60 | F14: XT0110:2 | G14: HPC | H14: 1444s
A15: AF0510:53 | B15: -0V | C15: WHT | D15: 16 | E15: 60 | F15: XT0130:2 | G15: HPC
A16: AF0410:55 | B16: FU0113 | C16: WHT | D16: 16 | E16: 60 | F16: FU0113:LD | G16: HPC
A17: AF0510:55 | B17: FU0131 | C17: WHT | D17: 16 | E17: 60 | F17: FU0131:LD | G17: HPC
A19: AF1202:COM | B19: AU1200N | C19: WHT | D19: 20 | E19: 60 | F19: AU1200:COM | G19: HPC | H19: AF/AU1200s
A20: AF1202:V+ | B20: AU1200P | C20: WHT | D20: 20 | E20: 60 | F20: AU1200:V+ | G20: HPC
A22: AF1201:COM | B22: -0V | C22: WHT | D22: 16 | E22: 60 | F22: XT0130:3 | G22: HPC
A23: AU1200:COM | B23: -0V | C23: WHT | D23: 16 | E23: 60 | F23: XT0130:4 | G23: HPC
A25: AU1200:V+ | B25: FU0120 | C25: WHT | D25: 14 | E25: 100 | F25: FU0120:LD | G25: HPC
A26: AF1201:V+ | B26: FU0121 | C26: WHT | D26: 14 | E26: 100 | F26: FU0121:LD | G26: HPC
A28: FU0113:LI | B28: FU0136 | C28: WHT | D28: 14 | E28: 60 | F28: XT0110:1 | G28: HPC | H28: FU
A29: FU0121:LI | B29: FU0136 | C29: WHT | D29: 14 | E29: 60 | F29: XT0190:3 | G29: HPC
A30: FU0131:LI | B30: FU0136 | C30: WHT | D30: 14 | E30: 60 | F30: XT0130:1 | G30: HPC
A32: KA0120:A1 | B32: KA0120A1 | C32: WHT | D32: 20 | E32: 60 | F32: XT0130:6 | G32: HPC | H32: KA A1/A2
A33: KA0190:A1 | B33: KA0120A1 | C33: WHT | D33: 20 | E33: 60 | F33: XT0130:6 | G33: HPC
A34: KA4401:A1 | B34: PS44013 | C34: WHT | D34: 20 | E34: 60 | F34: XT0121:2 | G34: HPC
A36: KA0190:A2 | B36: -0V | C36: WHT | D36: 20 | E36: 60 | F36: XT0130:7 | G36: HPC
A37: KA4401:A2 | B37: -120718 | C37: WHT | D37: 20 | E37: 60 | F37: AF1207:18 | G37: HPC
A39: KA0120:A2 | B39: -0V | C39: WHT | D39: 14 | E39: 60 | F39: XT0130:7 | G39: HPC
A41: KA0193:14 | B41: -120106 | C41: WHT | D41: 20 | E41: 80 | F41: AF1201:06 | G41: HPC | H41: KA
A42: KA4401:14 | B42: -120702 | C42: WHT | D42: 20 | E42: 60 | F42: AF1207:02 | G42: HPC
A43: KA0193:12 | B43: KA019312 | C43: WHT | D43: 20 | E43: 60 | F43: XT0190:1 | G43: HPC
A44: KA4401:24 | B44: KA019312 | C44: WHT | D44: 20 | E44: 60 | F44: XT0190:1 | G44: HPC
A45: KA4401:11 | B45: PS44012 | C45: WHT | D45: 20 | E45: 60 | F45: AF1207:34 | G45: HPC
A46: KA4401:11 | B46: PS44012 | C46: WHT | D46: 20 | E46: 60 | F46: XT0121:1 | G46: HPC
A48: XT0110:3 | B48: KA0120A1 | C48: WHT | D48: 20 | E48: 60 | F48: XT0130:5 | G48: HPC | H48: XT
A50: XT0130:4 | B50: -0V | C50: WHT | D50: 14 | E50: 60 | F50: XT0520:2 | G50: HPC
A51: XT0110:1 | B51: FU0136 | C51: WHT | D51: 14 | E51: 60 | F51: XT0130:1 | G51: HPC
A52: XT0110:1 | B52: FU0136 | C52: WHT | D52: 14 | E52: 60 | F52: XT0520:1 | G52: HPC
...

Sheet ISOLATOR_S
A1: CONSOLE ISOLATOR^PANEL
A2: CONTROL CONSOLE
A3: Project # | B3: J1620
A4: Project Name | B4: SOUTHERNSTAR LONEJACK
A5: Revision | B5: A
A7: Controls DE | B7: M.ZUNIGA
A8: Phone:
A9: Controls ME | B9: S.MARTINEZ
A10: Phone:
A12: From | G12: To
A13: Device ID | B13: Wire No. | C13: Wire ID | D13: Gauge/Size | E13: Length | F13: Device ID | G13: Location | H13: Bundle Name
A14: UV0271:8+ | B14: UV0271P | C14: WHT | D14: 14 | E14: 60 | F14: FU0272:LD | G14: ISOLATOR | H14: UAI

Sheet Bundle Tag Info
A1: SOUTHERN STAR #1
A2: J1620
A3: 0.1
A6: LIGHTS | B6: DOOR | C6: PWR DST RAIL | D6: BOP | E6: PLC | F6: A | G6: B | H6: HPC | I6: ISOLATOR | J6: Panel Name | K6: Panel Name | L6: Panel Name | M6: Panel Name | N6: Panel Name | O6: Panel Name | P6: Panel Name | Q6: Panel Name | R6: Panel Name | S6: Panel Name | T6: Panel Name | U6: Panel Name | V6: Panel Name | W6: Panel Name | X6: Panel Name | Y6: Panel Name | Z6: Panel Name | AA6: Panel Name | AB6: Panel Name | AC6: Panel Name | AD6: Panel Name
A7: EL0/ZS | B7: AT0190 | C7: AT | D7: AF/AU | E7: PC | F7: AF/AU080s | G7: AF/AU060s | H7: 1444s | I7: UAI
C8: FU | D8: KA A1 | E8: UV | F8: AF/AU090s | G8: AF/AU070s | H8: AF/AU1200s
C9: XT-A | D9: KA A2 | F9: FU | G9: FU | H9: FU
C10: XT/FU-B | D10: KA | F10: KA A1 | G10: KA A1 | H10: KA A1/A2
D11: KT L/S | F11: KA A2 | G11: KA A2 | H11: KA
D12: KT R/S | F12: KA | G12: KA | H12: XT
D13: FU/XT | F13: XT | G13: KT L/S | H13: XT-ISO
D14: XT-HPC | F14: XT-HPC | G14: KT R/S
D15: XT-B | F15: AF-B | G15: XT
F16: FU-B
F17: KA A1/A2-B
F18: KA-B
F19: XT-B

Sheet Bundle Tags2
A1: =IF('Bundle Tag Info'!A6<>"Panel Name",'Bundle Tag Info'!A6,"") -> LIGHTS | B1: =IF('Bundle Tag Info'!B6<>"Panel Name",'Bundle Tag Info'!B6,"") -> DOOR | C1: =IF('Bundle Tag Info'!C6<>"Panel Name",'Bundle Tag Info'!C6,"") -> PWR DST RAIL | D1: =IF('Bundle Tag Info'!D6<>"Panel Name",'Bundle Tag Info'!D6,"") -> BOP | E1: =IF('Bundle Tag Info'!E6<>"Panel Name",'Bundle Tag Info'!E6,"") -> PLC | F1: =IF('Bundle Tag Info'!F6<>"Panel Name",'Bundle Tag Info'!F6,"") -> A | G1: =IF('Bundle Tag Info'!G6<>"Panel Name",'Bundle Tag Info'!G6,"") -> B | H1: =IF('Bundle Tag Info'!H6<>"Panel Name",'Bundle Tag Info'!H6,"") -> HPC | ... AD1: =IF('Bundle Tag Info'!AD6<>"Panel Name",'Bundle Tag Info'!AD6,"")
A2: =IF('Bundle Tag Info'!A$7<>"",CONCATENATE('Bundle Tag Info'!$A$1," ",CHAR(10),'Bundle Tag Info'!$A$2," ",'Bundle Tag Info'!$A$3,CHAR(10),'Bundle Tag Info'!A$6,CHAR(10),'Bundle Tag Info'!A$7),"") -> SOUTHERN STAR #1 J1620 0.1 LIGHTS EL0/ZS | B2: =IF('Bundle Tag Info'!B$7<>"",CONCATENATE('Bundle Tag Info'!$A$1," ",CHAR(10),'Bundle Tag Info'!$A$2," ",'Bundle Tag Info'!$A$3,CHAR(10),'Bundle Tag Info'!B$6,CHAR(10),'Bundle Tag Info'!B$7),"") -> SOUTHERN STAR #1 J1620 0.1 DOOR AT0190 | C2: =IF('Bundle Tag Info'!C$7<>"",CONCATENATE('Bundle Tag Info'!$A$1," ",CHAR(10),'Bundle Tag Info'!$A$2," ",'Bundle Tag Info'!$A$3,CHAR(10),'Bundle Tag Info'!C$6,CHAR(10),'Bundle Tag Info'!C$7),"") -> SOUTHERN STAR #1 J1620 0.1 PWR DST RAIL AT | D2: =IF('Bundle Tag Info'!D$7<>"",CONCATENATE('Bundle Tag Info'!$A$1," ",CHAR(10),'Bundle Tag Info'!$A$2," ",'Bundle Tag Info'!$A$3,CHAR(10),'Bundle Tag Info'!D$6,CHAR(10),'Bundle Tag Info'!D$7),"") -> SOUTHERN STAR #1 J1620 0.1 BOP AF/AU | E2: =IF('Bundle Tag Info'!E$7<>"",CONCATENATE('Bundle Tag Info'!$A$1," ",CHAR(10),'Bundle Tag Info'!$A$2," ",'Bundle Tag Info'!$A$3,CHAR(10),'Bundle Tag Info'!E$6,CHAR(10),'Bundle Tag Info'!E$7),"") -> SOUTHERN STAR #1 J1620 0.1 PLC PC | F2: =IF('Bundle Tag Info'!F$7<>"",CONCATENATE('Bundle Tag Info'!$A$1," ",CHAR(10),'Bundle Tag Info'!$A$2," ",'Bundle Tag Info'!$A$3,CHAR(10),'Bundle Tag Info'!F$6,CHAR(10),'Bundle Tag Info'!F$7),"") -> SOUTHERN STAR #1 J1620 0.1 A AF/AU080s | G2: =IF('Bundle Tag Info'!G$7<>"",CONCATENATE('Bundle Tag Info'!$A$1," ",CHAR(10),'Bundle Tag Info'!$A$2," ",'Bundle Tag Info'!$A$3,CHAR(10),'Bundle Tag Info'!G$6,CHAR(10),'Bundle Tag Info'!G$7),"") -> SOUTHERN STAR #1 J1620 0.1 B AF/AU060s | H2: =IF('Bundle Tag Info'!H$7<>"",CONCATENATE('Bundle Tag Info'!$A$1," ",CHAR(10),'Bundle Tag Info'!$A$2," ",'Bundle Tag Info'!$A$3,CHAR(10),'Bundle Tag Info'!H$6,CHAR(10),'Bundle Tag Info'!H$7),"") -> SOUTHERN STAR #1 J1620 0.1 HPC 1444s | ... AD2: =IF('Bundle Tag Info'!AD$7<>"",CONCATENATE('Bundle Tag Info'!$A$1," ",CHAR(10),'Bundle Tag Info'!$A$2," ",'Bundle Tag Info'!$A$3,CHAR(10),'Bundle Tag Info'!AD$6,CHAR(10),'Bundle Tag Info'!AD$7),"")
A3: =IF('Bundle Tag Info'!A$8<>"",CONCATENATE('Bundle Tag Info'!$A$1," ",CHAR(10),'Bundle Tag Info'!$A$2," ",'Bundle Tag Info'!$A$3,CHAR(10),'Bundle Tag Info'!A$6,CHAR(10),'Bundle Tag Info'!A$8),"") | B3: =IF('Bundle Tag Info'!B$8<>"",CONCATENATE('Bundle Tag Info'!$A$1," ",CHAR(10),'Bundle Tag Info'!$A$2," ",'Bundle Tag Info'!$A$3,CHAR(10),'Bundle Tag Info'!B$6,CHAR(10),'Bundle Tag Info'!B$8),"") | C3: =IF('Bundle Tag Info'!C$8<>"",CONCATENATE('Bundle Tag Info'!$A$1," ",CHAR(10),'Bundle Tag Info'!$A$2," ",'Bundle Tag Info'!$A$3,CHAR(10),'Bundle Tag Info'!C$6,CHAR(10),'Bundle Tag Info'!C$8),"") -> SOUTHERN STAR #1 J1620 0.1 PWR DST RAIL FU | D3: =IF('Bundle Tag Info'!D$8<>"",CONCATENATE('Bundle Tag Info'!$A$1," ",CHAR(10),'Bundle Tag Info'!$A$2," ",'Bundle Tag Info'!$A$3,CHAR(10),'Bundle Tag Info'!D$6,CHAR(10),'Bundle Tag Info'!D$8),"") -> SOUTHERN STAR #1 J1620 0.1 BOP KA A1 | E3: =IF('Bundle Tag Info'!E$8<>"",CONCATENATE('Bundle Tag Info'!$A$1," ",CHAR(10),'Bundle Tag Info'!$A$2," ",'Bundle Tag Info'!$A$3,CHAR(10),'Bundle Tag Info'!E$6,CHAR(10),'Bundle Tag Info'!E$8),"") -> SOUTHERN STAR #1 J1620 0.1 PLC UV | F3: =IF('Bundle Tag Info'!F$8<>"",CONCATENATE('Bundle Tag Info'!$A$1," ",CHAR(10),'Bundle Tag Info'!$A$2," ",'Bundle Tag Info'!$A$3,CHAR(10),'Bundle Tag Info'!F$6,CHAR(10),'Bundle Tag Info'!F$8),"") -> SOUTHERN STAR #1 J1620 0.1 A AF/AU090s | G3: =IF('Bundle Tag Info'!G$8<>"",CONCATENATE('Bundle Tag Info'!$A$1," ",CHAR(10),'Bundle Tag Info'!$A$2," ",'Bundle Tag Info'!$A$3,CHAR(10),'Bundle Tag Info'!G$6,CHAR(10),'Bundle Tag Info'!G$8),"") -> SOUTHERN STAR #1 J1620 0.1 B AF/AU070s | H3: =IF('Bundle Tag Info'!H$8<>"",CONCATENATE('Bundle Tag Info'!$A$1," ",CHAR(10),'Bundle Tag Info'!$A$2," ",'Bundle Tag Info'!$A$3,CHAR(10),'Bundle Tag Info'!H$6,CHAR(10),'Bundle Tag Info'!H$8),"") -> SOUTHERN STAR #1 J1620 0.1 HPC AF/AU1200s | ... AD3: =IF('Bundle Tag Info'!AD$8<>"",CONCATENATE('Bundle Tag Info'!$A$1," ",CHAR(10),'Bundle Tag Info'!$A$2," ",'Bundle Tag Info'!$A$3,CHAR(10),'Bundle Tag Info'!AD$6,CHAR(10),'Bundle Tag Info'!AD$8),"")
A4: =IF('Bundle Tag Info'!A$9<>"",CONCATENATE('Bundle Tag Info'!$A$1," ",CHAR(10),'Bundle Tag Info'!$A$2," ",'Bundle Tag Info'!$A$3,CHAR(10),'Bundle Tag Info'!A$6,CHAR(10),'Bundle Tag Info'!A$9),"") | B4: =IF('Bundle Tag Info'!B$9<>"",CONCATENATE('Bundle Tag Info'!$A$1," ",CHAR(10),'Bundle Tag Info'!$A$2," ",'Bundle Tag Info'!$A$3,CHAR(10),'Bundle Tag Info'!B$6,CHAR(10),'Bundle Tag Info'!B$9),"") | C4: =IF('Bundle Tag Info'!C$9<>"",CONCATENATE('Bundle Tag Info'!$A$1," ",CHAR(10),'Bundle Tag Info'!$A$2," ",'Bundle Tag Info'!$A$3,CHAR(10),'Bundle Tag Info'!C$6,CHAR(10),'Bundle Tag Info'!C$9),"") -> SOUTHERN STAR #1 J1620 0.1 PWR DST RAIL XT-A | D4: =IF('Bundle Tag Info'!D$9<>"",CONCATENATE('Bundle Tag Info'!$A$1," ",CHAR(10),'Bundle Tag Info'!$A$2," ",'Bundle Tag Info'!$A$3,CHAR(10),'Bundle Tag Info'!D$6,CHAR(10),'Bundle Tag Info'!D$9),"") -> SOUTHERN STAR #1 J1620 0.1 BOP KA A2 | E4: =IF('Bundle Tag Info'!E$9<>"",CONCATENATE('Bundle Tag Info'!$A$1," ",CHAR(10),'Bundle Tag Info'!$A$2," ",'Bundle Tag Info'!$A$3,CHAR(10),'Bundle Tag Info'!E$6,CHAR(10),'Bundle Tag Info'!E$9),"") | F4: =IF('Bundle Tag Info'!F$9<>"",CONCATENATE('Bundle Tag Info'!$A$1," ",CHAR(10),'Bundle Tag Info'!$A$2," ",'Bundle Tag Info'!$A$3,CHAR(10),'Bundle Tag Info'!F$6,CHAR(10),'Bundle Tag Info'!F$9),"") -> SOUTHERN STAR #1 J1620 0.1 A FU | G4: =IF('Bundle Tag Info'!G$9<>"",CONCATENATE('Bundle Tag Info'!$A$1," ",CHAR(10),'Bundle Tag Info'!$A$2," ",'Bundle Tag Info'!$A$3,CHAR(10),'Bundle Tag Info'!G$6,CHAR(10),'Bundle Tag Info'!G$9),"") -> SOUTHERN STAR #1 J1620 0.1 B FU | H4: =IF('Bundle Tag Info'!H$9<>"",CONCATENATE('Bundle Tag Info'!$A$1," ",CHAR(10),'Bundle Tag Info'!$A$2," ",'Bundle Tag Info'!$A$3,CHAR(10),'Bundle Tag Info'!H$6,CHAR(10),'Bundle Tag Info'!H$9),"") -> SOUTHERN STAR #1 J1620 0.1 HPC FU | ... AD4: =IF('Bundle Tag Info'!AD$9<>"",CONCATENATE('Bundle Tag Info'!$A$1," ",CHAR(10),'Bundle Tag Info'!$A$2," ",'Bundle Tag Info'!$A$3,CHAR(10),'Bundle Tag Info'!AD$6,CHAR(10),'Bundle Tag Info'!AD$9),"")
A5: =IF('Bundle Tag Info'!A$10<>"",CONCATENATE('Bundle Tag Info'!$A$1," ",CHAR(10),'Bundle Tag Info'!$A$2," ",'Bundle Tag Info'!$A$3,CHAR(10),'Bundle Tag Info'!A$6,CHAR(10),'Bundle Tag Info'!A$10),"") | B5: =IF('Bundle Tag Info'!B$10<>"",CONCATENATE('Bundle Tag Info'!$A$1," ",CHAR(10),'Bundle Tag Info'!$A$2," ",'Bundle Tag Info'!$A$3,CHAR(10),'Bundle Tag Info'!B$6,CHAR(10),'Bundle Tag Info'!B$10),"") | C5: =IF('Bundle Tag Info'!C$10<>"",CONCATENATE('Bundle Tag Info'!$A$1," ",CHAR(10),'Bundle Tag Info'!$A$2," ",'Bundle Tag Info'!$A$3,CHAR(10),'Bundle Tag Info'!C$6,CHAR(10),'Bundle Tag Info'!C$10),"") -> SOUTHERN STAR #1 J1620 0.1 PWR DST RAIL XT/FU-B | D5: =IF('Bundle Tag Info'!D$10<>"",CONCATENATE('Bundle Tag Info'!$A$1," ",CHAR(10),'Bundle Tag Info'!$A$2," ",'Bundle Tag Info'!$A$3,CHAR(10),'Bundle Tag Info'!D$6,CHAR(10),'Bundle Tag Info'!D$10),"") -> SOUTHERN STAR #1 J1620 0.1 BOP KA | E5: =IF('Bundle Tag Info'!E$10<>"",CONCATENATE('Bundle Tag Info'!$A$1," ",CHAR(10),'Bundle Tag Info'!$A$2," ",'Bundle Tag Info'!$A$3,CHAR(10),'Bundle Tag Info'!E$6,CHAR(10),'Bundle Tag Info'!E$10),"") | F5: =IF('Bundle Tag Info'!F$10<>"",CONCATENATE('Bundle Tag Info'!$A$1," ",CHAR(10),'Bundle Tag Info'!$A$2," ",'Bundle Tag Info'!$A$3,CHAR(10),'Bundle Tag Info'!F$6,CHAR(10),'Bundle Tag Info'!F$10),"") -> SOUTHERN STAR #1 J1620 0.1 A KA A1 | G5: =IF('Bundle Tag Info'!G$10<>"",CONCATENATE('Bundle Tag Info'!$A$1," ",CHAR(10),'Bundle Tag Info'!$A$2," ",'Bundle Tag Info'!$A$3,CHAR(10),'Bundle Tag Info'!G$6,CHAR(10),'Bundle Tag Info'!G$10),"") -> SOUTHERN STAR #1 J1620 0.1 B KA A1 | H5: =IF('Bundle Tag Info'!H$10<>"",CONCATENATE('Bundle Tag Info'!$A$1," ",CHAR(10),'Bundle Tag Info'!$A$2," ",'Bundle Tag Info'!$A$3,CHAR(10),'Bundle Tag Info'!H$6,CHAR(10),'Bundle Tag Info'!H$10),"") -> SOUTHERN STAR #1 J1620 0.1 HPC KA A1/A2 | ... AD5: =IF('Bundle Tag Info'!AD$10<>"",CONCATENATE('Bundle Tag Info'!$A$1," ",CHAR(10),'Bundle Tag Info'!$A$2," ",'Bundle Tag Info'!$A$3,CHAR(10),'Bundle Tag Info'!AD$6,CHAR(10),'Bundle Tag Info'!AD$10),"")
A6: =IF('Bundle Tag Info'!A$11<>"",CONCATENATE('Bundle Tag Info'!$A$1," ",CHAR(10),'Bundle Tag Info'!$A$2," ",'Bundle Tag Info'!$A$3,CHAR(10),'Bundle Tag Info'!A$6,CHAR(10),'Bundle Tag Info'!A$11),"") | B6: =IF('Bundle Tag Info'!B$11<>"",CONCATENATE('Bundle Tag Info'!$A$1," ",CHAR(10),'Bundle Tag Info'!$A$2," ",'Bundle Tag Info'!$A$3,CHAR(10),'Bundle Tag Info'!B$6,CHAR(10),'Bundle Tag Info'!B$11),"") | C6: =IF('Bundle Tag Info'!C$11<>"",CONCATENATE('Bundle Tag Info'!$A$1," ",CHAR(10),'Bundle Tag Info'!$A$2," ",'Bundle Tag Info'!$A$3,CHAR(10),'Bundle Tag Info'!C$6,CHAR(10),'Bundle Tag Info'!C$11),"") | D6: =IF('Bundle Tag Info'!D$11<>"",CONCATENATE('Bundle Tag Info'!$A$1," ",CHAR(10),'Bundle Tag Info'!$A$2," ",'Bundle Tag Info'!$A$3,CHAR(10),'Bundle Tag Info'!D$6,CHAR(10),'Bundle Tag Info'!D$11),"") -> SOUTHERN STAR #1 J1620 0.1 BOP KT L/S | E6: =IF('Bundle Tag Info'!E$11<>"",CONCATENATE('Bundle Tag Info'!$A$1," ",CHAR(10),'Bundle Tag Info'!$A$2," ",'Bundle Tag Info'!$A$3,CHAR(10),'Bundle Tag Info'!E$6,CHAR(10),'Bundle Tag Info'!E$11),"") | F6: =IF('Bundle Tag Info'!F$11<>"",CONCATENATE('Bundle Tag Info'!$A$1," ",CHAR(10),'Bundle Tag Info'!$A$2," ",'Bundle Tag Info'!$A$3,CHAR(10),'Bundle Tag Info'!F$6,CHAR(10),'Bundle Tag Info'!F$11),"") -> SOUTHERN STAR #1 J1620 0.1 A KA A2 | G6: =IF('Bundle Tag Info'!G$11<>"",CONCATENATE('Bundle Tag Info'!$A$1," ",CHAR(10),'Bundle Tag Info'!$A$2," ",'Bundle Tag Info'!$A$3,CHAR(10),'Bundle Tag Info'!G$6,CHAR(10),'Bundle Tag Info'!G$11),"") -> SOUTHERN STAR #1 J1620 0.1 B KA A2 | H6: =IF('Bundle Tag Info'!H$11<>"",CONCATENATE('Bundle Tag Info'!$A$1," ",CHAR(10),'Bundle Tag Info'!$A$2," ",'Bundle Tag Info'!$A$3,CHAR(10),'Bundle Tag Info'!H$6,CHAR(10),'Bundle Tag Info'!H$11),"") -> SOUTHERN STAR #1 J1620 0.1 HPC KA | ... AD6: =IF('Bundle Tag Info'!AD$11<>"",CONCATENATE('Bundle Tag Info'!$A$1," ",CHAR(10),'Bundle Tag Info'!$A$2," ",'Bundle Tag Info'!$A$3,CHAR(10),'Bundle Tag Info'!AD$6,CHAR(10),'Bundle Tag Info'!AD$11),"")
A7: =IF('Bundle Tag Info'!A$12<>"",CONCATENATE('Bundle Tag Info'!$A$1," ",CHAR(10),'Bundle Tag Info'!$A$2," ",'Bundle Tag Info'!$A$3,CHAR(10),'Bundle Tag Info'!A$6,CHAR(10),'Bundle Tag Info'!A$12),"") | B7: =IF('Bundle Tag Info'!B$12<>"",CONCATENATE('Bundle Tag Info'!$A$1," ",CHAR(10),'Bundle Tag Info'!$A$2," ",'Bundle Tag Info'!$A$3,CHAR(10),'Bundle Tag Info'!B$6,CHAR(10),'Bundle Tag Info'!B$12),"") | C7: =IF('Bundle Tag Info'!C$12<>"",CONCATENATE('Bundle Tag Info'!$A$1," ",CHAR(10),'Bundle Tag Info'!$A$2," ",'Bundle Tag Info'!$A$3,CHAR(10),'Bundle Tag Info'!C$6,CHAR(10),'Bundle Tag Info'!C$12),"") | D7: =IF('Bundle Tag Info'!D$12<>"",CONCATENATE('Bundle Tag Info'!$A$1," ",CHAR(10),'Bundle Tag Info'!$A$2," ",'Bundle Tag Info'!$A$3,CHAR(10),'Bundle Tag Info'!D$6,CHAR(10),'Bundle Tag Info'!D$12),"") -> SOUTHERN STAR #1 J1620 0.1 BOP KT R/S | E7: =IF('Bundle Tag Info'!E$12<>"",CONCATENATE('Bundle Tag Info'!$A$1," ",CHAR(10),'Bundle Tag Info'!$A$2," ",'Bundle Tag Info'!$A$3,CHAR(10),'Bundle Tag Info'!E$6,CHAR(10),'Bundle Tag Info'!E$12),"") | F7: =IF('Bundle Tag Info'!F$12<>"",CONCATENATE('Bundle Tag Info'!$A$1," ",CHAR(10),'Bundle Tag Info'!$A$2," ",'Bundle Tag Info'!$A$3,CHAR(10),'Bundle Tag Info'!F$6,CHAR(10),'Bundle Tag Info'!F$12),"") -> SOUTHERN STAR #1 J1620 0.1 A KA | G7: =IF('Bundle Tag Info'!G$12<>"",CONCATENATE('Bundle Tag Info'!$A$1," ",CHAR(10),'Bundle Tag Info'!$A$2," ",'Bundle Tag Info'!$A$3,CHAR(10),'Bundle Tag Info'!G$6,CHAR(10),'Bundle Tag Info'!G$12),"") -> SOUTHERN STAR #1 J1620 0.1 B KA | H7: =IF('Bundle Tag Info'!H$12<>"",CONCATENATE('Bundle Tag Info'!$A$1," ",CHAR(10),'Bundle Tag Info'!$A$2," ",'Bundle Tag Info'!$A$3,CHAR(10),'Bundle Tag Info'!H$6,CHAR(10),'Bundle Tag Info'!H$12),"") -> SOUTHERN STAR #1 J1620 0.1 HPC XT | ... AD7: =IF('Bundle Tag Info'!AD$12<>"",CONCATENATE('Bundle Tag Info'!$A$1," ",CHAR(10),'Bundle Tag Info'!$A$2," ",'Bundle Tag Info'!$A$3,CHAR(10),'Bundle Tag Info'!AD$6,CHAR(10),'Bundle Tag Info'!AD$12),"")
A8: =IF('Bundle Tag Info'!A$13<>"",CONCATENATE('Bundle Tag Info'!$A$1," ",CHAR(10),'Bundle Tag Info'!$A$2," ",'Bundle Tag Info'!$A$3,CHAR(10),'Bundle Tag Info'!A$6,CHAR(10),'Bundle Tag Info'!A$13),"") | B8: =IF('Bundle Tag Info'!B$13<>"",CONCATENATE('Bundle Tag Info'!$A$1," ",CHAR(10),'Bundle Tag Info'!$A$2," ",'Bundle Tag Info'!$A$3,CHAR(10),'Bundle Tag Info'!B$6,CHAR(10),'Bundle Tag Info'!B$13),"") | C8: =IF('Bundle Tag Info'!C$13<>"",CONCATENATE('Bundle Tag Info'!$A$1," ",CHAR(10),'Bundle Tag Info'!$A$2," ",'Bundle Tag Info'!$A$3,CHAR(10),'Bundle Tag Info'!C$6,CHAR(10),'Bundle Tag Info'!C$13),"") | D8: =IF('Bundle Tag Info'!D$13<>"",CONCATENATE('Bundle Tag Info'!$A$1," ",CHAR(10),'Bundle Tag Info'!$A$2," ",'Bundle Tag Info'!$A$3,CHAR(10),'Bundle Tag Info'!D$6,CHAR(10),'Bundle Tag Info'!D$13),"") -> SOUTHERN STAR #1 J1620 0.1 BOP FU/XT | E8: =IF('Bundle Tag Info'!E$13<>"",CONCATENATE('Bundle Tag Info'!$A$1," ",CHAR(10),'Bundle Tag Info'!$A$2," ",'Bundle Tag Info'!$A$3,CHAR(10),'Bundle Tag Info'!E$6,CHAR(10),'Bundle Tag Info'!E$13),"") | F8: =IF('Bundle Tag Info'!F$13<>"",CONCATENATE('Bundle Tag Info'!$A$1," ",CHAR(10),'Bundle Tag Info'!$A$2," ",'Bundle Tag Info'!$A$3,CHAR(10),'Bundle Tag Info'!F$6,CHAR(10),'Bundle Tag Info'!F$13),"") -> SOUTHERN STAR #1 J1620 0.1 A XT | G8: =IF('Bundle Tag Info'!G$13<>"",CONCATENATE('Bundle Tag Info'!$A$1," ",CHAR(10),'Bundle Tag Info'!$A$2," ",'Bundle Tag Info'!$A$3,CHAR(10),'Bundle Tag Info'!G$6,CHAR(10),'Bundle Tag Info'!G$13),"") -> SOUTHERN STAR #1 J1620 0.1 B KT L/S | H8: =IF('Bundle Tag Info'!H$13<>"",CONCATENATE('Bundle Tag Info'!$A$1," ",CHAR(10),'Bundle Tag Info'!$A$2," ",'Bundle Tag Info'!$A$3,CHAR(10),'Bundle Tag Info'!H$6,CHAR(10),'Bundle Tag Info'!H$13),"") -> SOUTHERN STAR #1 J1620 0.1 HPC XT-ISO | ... AD8: =IF('Bundle Tag Info'!AD$13<>"",CONCATENATE('Bundle Tag Info'!$A$1," ",CHAR(10),'Bundle Tag Info'!$A$2," ",'Bundle Tag Info'!$A$3,CHAR(10),'Bundle Tag Info'!AD$6,CHAR(10),'Bundle Tag Info'!AD$13),"")
A9: =IF('Bundle Tag Info'!A$14<>"",CONCATENATE('Bundle Tag Info'!$A$1," ",CHAR(10),'Bundle Tag Info'!$A$2," ",'Bundle Tag Info'!$A$3,CHAR(10),'Bundle Tag Info'!A$6,CHAR(10),'Bundle Tag Info'!A$14),"") | B9: =IF('Bundle Tag Info'!B$14<>"",CONCATENATE('Bundle Tag Info'!$A$1," ",CHAR(10),'Bundle Tag Info'!$A$2," ",'Bundle Tag Info'!$A$3,CHAR(10),'Bundle Tag Info'!B$6,CHAR(10),'Bundle Tag Info'!B$14),"") | C9: =IF('Bundle Tag Info'!C$14<>"",CONCATENATE('Bundle Tag Info'!$A$1," ",CHAR(10),'Bundle Tag Info'!$A$2," ",'Bundle Tag Info'!$A$3,CHAR(10),'Bundle Tag Info'!C$6,CHAR(10),'Bundle Tag Info'!C$14),"") | D9: =IF('Bundle Tag Info'!D$14<>"",CONCATENATE('Bundle Tag Info'!$A$1," ",CHAR(10),'Bundle Tag Info'!$A$2," ",'Bundle Tag Info'!$A$3,CHAR(10),'Bundle Tag Info'!D$6,CHAR(10),'Bundle Tag Info'!D$14),"") -> SOUTHERN STAR #1 J1620 0.1 BOP XT-HPC | E9: =IF('Bundle Tag Info'!E$14<>"",CONCATENATE('Bundle Tag Info'!$A$1," ",CHAR(10),'Bundle Tag Info'!$A$2," ",'Bundle Tag Info'!$A$3,CHAR(10),'Bundle Tag Info'!E$6,CHAR(10),'Bundle Tag Info'!E$14),"") | F9: =IF('Bundle Tag Info'!F$14<>"",CONCATENATE('Bundle Tag Info'!$A$1," ",CHAR(10),'Bundle Tag Info'!$A$2," ",'Bundle Tag Info'!$A$3,CHAR(10),'Bundle Tag Info'!F$6,CHAR(10),'Bundle Tag Info'!F$14),"") -> SOUTHERN STAR #1 J1620 0.1 A XT-HPC | G9: =IF('Bundle Tag Info'!G$14<>"",CONCATENATE('Bundle Tag Info'!$A$1," ",CHAR(10),'Bundle Tag Info'!$A$2," ",'Bundle Tag Info'!$A$3,CHAR(10),'Bundle Tag Info'!G$6,CHAR(10),'Bundle Tag Info'!G$14),"") -> SOUTHERN STAR #1 J1620 0.1 B KT R/S | H9: =IF('Bundle Tag Info'!H$14<>"",CONCATENATE('Bundle Tag Info'!$A$1," ",CHAR(10),'Bundle Tag Info'!$A$2," ",'Bundle Tag Info'!$A$3,CHAR(10),'Bundle Tag Info'!H$6,CHAR(10),'Bundle Tag Info'!H$14),"") | ... AD9: =IF('Bundle Tag Info'!AD$14<>"",CONCATENATE('Bundle Tag Info'!$A$1," ",CHAR(10),'Bundle Tag Info'!$A$2," ",'Bundle Tag Info'!$A$3,CHAR(10),'Bundle Tag Info'!AD$6,CHAR(10),'Bundle Tag Info'!AD$14),"")
A10: =IF('Bundle Tag Info'!A$15<>"",CONCATENATE('Bundle Tag Info'!$A$1," ",CHAR(10),'Bundle Tag Info'!$A$2," ",'Bundle Tag Info'!$A$3,CHAR(10),'Bundle Tag Info'!A$6,CHAR(10),'Bundle Tag Info'!A$15),"") | B10: =IF('Bundle Tag Info'!B$15<>"",CONCATENATE('Bundle Tag Info'!$A$1," ",CHAR(10),'Bundle Tag Info'!$A$2," ",'Bundle Tag Info'!$A$3,CHAR(10),'Bundle Tag Info'!B$6,CHAR(10),'Bundle Tag Info'!B$15),"") | C10: =IF('Bundle Tag Info'!C$15<>"",CONCATENATE('Bundle Tag Info'!$A$1," ",CHAR(10),'Bundle Tag Info'!$A$2," ",'Bundle Tag Info'!$A$3,CHAR(10),'Bundle Tag Info'!C$6,CHAR(10),'Bundle Tag Info'!C$15),"") | D10: =IF('Bundle Tag Info'!D$15<>"",CONCATENATE('Bundle Tag Info'!$A$1," ",CHAR(10),'Bundle Tag Info'!$A$2," ",'Bundle Tag Info'!$A$3,CHAR(10),'Bundle Tag Info'!D$6,CHAR(10),'Bundle Tag Info'!D$15),"") -> SOUTHERN STAR #1 J1620 0.1 BOP XT-B | E10: =IF('Bundle Tag Info'!E$15<>"",CONCATENATE('Bundle Tag Info'!$A$1," ",CHAR(10),'Bundle Tag Info'!$A$2," ",'Bundle Tag Info'!$A$3,CHAR(10),'Bundle Tag Info'!E$6,CHAR(10),'Bundle Tag Info'!E$15),"") | F10: =IF('Bundle Tag Info'!F$15<>"",CONCATENATE('Bundle Tag Info'!$A$1," ",CHAR(10),'Bundle Tag Info'!$A$2," ",'Bundle Tag Info'!$A$3,CHAR(10),'Bundle Tag Info'!F$6,CHAR(10),'Bundle Tag Info'!F$15),"") -> SOUTHERN STAR #1 J1620 0.1 A AF-B | G10: =IF('Bundle Tag Info'!G$15<>"",CONCATENATE('Bundle Tag Info'!$A$1," ",CHAR(10),'Bundle Tag Info'!$A$2," ",'Bundle Tag Info'!$A$3,CHAR(10),'Bundle Tag Info'!G$6,CHAR(10),'Bundle Tag Info'!G$15),"") -> SOUTHERN STAR #1 J1620 0.1 B XT | H10: =IF('Bundle Tag Info'!H$15<>"",CONCATENATE('Bundle Tag Info'!$A$1," ",CHAR(10),'Bundle Tag Info'!$A$2," ",'Bundle Tag Info'!$A$3,CHAR(10),'Bundle Tag Info'!H$6,CHAR(10),'Bundle Tag Info'!H$15),"") | ... AD10: =IF('Bundle Tag Info'!AD$15<>"",CONCATENATE('Bundle Tag Info'!$A$1," ",CHAR(10),'Bundle Tag Info'!$A$2," ",'Bundle Tag Info'!$A$3,CHAR(10),'Bundle Tag Info'!AD$6,CHAR(10),'Bundle Tag Info'!AD$15),"")
A11: =IF('Bundle Tag Info'!A$16<>"",CONCATENATE('Bundle Tag Info'!$A$1," ",CHAR(10),'Bundle Tag Info'!$A$2," ",'Bundle Tag Info'!$A$3,CHAR(10),'Bundle Tag Info'!A$6,CHAR(10),'Bundle Tag Info'!A$16),"") | B11: =IF('Bundle Tag Info'!B$16<>"",CONCATENATE('Bundle Tag Info'!$A$1," ",CHAR(10),'Bundle Tag Info'!$A$2," ",'Bundle Tag Info'!$A$3,CHAR(10),'Bundle Tag Info'!B$6,CHAR(10),'Bundle Tag Info'!B$16),"") | C11: =IF('Bundle Tag Info'!C$16<>"",CONCATENATE('Bundle Tag Info'!$A$1," ",CHAR(10),'Bundle Tag Info'!$A$2," ",'Bundle Tag Info'!$A$3,CHAR(10),'Bundle Tag Info'!C$6,CHAR(10),'Bundle Tag Info'!C$16),"") | D11: =IF('Bundle Tag Info'!D$16<>"",CONCATENATE('Bundle Tag Info'!$A$1," ",CHAR(10),'Bundle Tag Info'!$A$2," ",'Bundle Tag Info'!$A$3,CHAR(10),'Bundle Tag Info'!D$6,CHAR(10),'Bundle Tag Info'!D$16),"") | E11: =IF('Bundle Tag Info'!E$16<>"",CONCATENATE('Bundle Tag Info'!$A$1," ",CHAR(10),'Bundle Tag Info'!$A$2," ",'Bundle Tag Info'!$A$3,CHAR(10),'Bundle Tag Info'!E$6,CHAR(10),'Bundle Tag Info'!E$16),"") | F11: =IF('Bundle Tag Info'!F$16<>"",CONCATENATE('Bundle Tag Info'!$A$1," ",CHAR(10),'Bundle Tag Info'!$A$2," ",'Bundle Tag Info'!$A$3,CHAR(10),'Bundle Tag Info'!F$6,CHAR(10),'Bundle Tag Info'!F$16),"") -> SOUTHERN STAR #1 J1620 0.1 A FU-B | G11: =IF('Bundle Tag Info'!G$16<>"",CONCATENATE('Bundle Tag Info'!$A$1," ",CHAR(10),'Bundle Tag Info'!$A$2," ",'Bundle Tag Info'!$A$3,CHAR(10),'Bundle Tag Info'!G$6,CHAR(10),'Bundle Tag Info'!G$16),"") | H11: =IF('Bundle Tag Info'!H$16<>"",CONCATENATE('Bundle Tag Info'!$A$1," ",CHAR(10),'Bundle Tag Info'!$A$2," ",'Bundle Tag Info'!$A$3,CHAR(10),'Bundle Tag Info'!H$6,CHAR(10),'Bundle Tag Info'!H$16),"") | ... AD11: =IF('Bundle Tag Info'!AD$16<>"",CONCATENATE('Bundle Tag Info'!$A$1," ",CHAR(10),'Bundle Tag Info'!$A$2," ",'Bundle Tag Info'!$A$3,CHAR(10),'Bundle Tag Info'!AD$6,CHAR(10),'Bundle Tag Info'!AD$16),"")
A12: =IF('Bundle Tag Info'!A$17<>"",CONCATENATE('Bundle Tag Info'!$A$1," ",CHAR(10),'Bundle Tag Info'!$A$2," ",'Bundle Tag Info'!$A$3,CHAR(10),'Bundle Tag Info'!A$6,CHAR(10),'Bundle Tag Info'!A$17),"") | B12: =IF('Bundle Tag Info'!B$17<>"",CONCATENATE('Bundle Tag Info'!$A$1," ",CHAR(10),'Bundle Tag Info'!$A$2," ",'Bundle Tag Info'!$A$3,CHAR(10),'Bundle Tag Info'!B$6,CHAR(10),'Bundle Tag Info'!B$17),"") | C12: =IF('Bundle Tag Info'!C$17<>"",CONCATENATE('Bundle Tag Info'!$A$1," ",CHAR(10),'Bundle Tag Info'!$A$2," ",'Bundle Tag Info'!$A$3,CHAR(10),'Bundle Tag Info'!C$6,CHAR(10),'Bundle Tag Info'!C$17),"") | D12: =IF('Bundle Tag Info'!D$17<>"",CONCATENATE('Bundle Tag Info'!$A$1," ",CHAR(10),'Bundle Tag Info'!$A$2," ",'Bundle Tag Info'!$A$3,CHAR(10),'Bundle Tag Info'!D$6,CHAR(10),'Bundle Tag Info'!D$17),"") | E12: =IF('Bundle Tag Info'!E$17<>"",CONCATENATE('Bundle Tag Info'!$A$1," ",CHAR(10),'Bundle Tag Info'!$A$2," ",'Bundle Tag Info'!$A$3,CHAR(10),'Bundle Tag Info'!E$6,CHAR(10),'Bundle Tag Info'!E$17),"") | F12: =IF('Bundle Tag Info'!F$17<>"",CONCATENATE('Bundle Tag Info'!$A$1," ",CHAR(10),'Bundle Tag Info'!$A$2," ",'Bundle Tag Info'!$A$3,CHAR(10),'Bundle Tag Info'!F$6,CHAR(10),'Bundle Tag Info'!F$17),"") -> SOUTHERN STAR #1 J1620 0.1 A KA A1/A2-B | G12: =IF('Bundle Tag Info'!G$17<>"",CONCATENATE('Bundle Tag Info'!$A$1," ",CHAR(10),'Bundle Tag Info'!$A$2," ",'Bundle Tag Info'!$A$3,CHAR(10),'Bundle Tag Info'!G$6,CHAR(10),'Bundle Tag Info'!G$17),"") | H12: =IF('Bundle Tag Info'!H$17<>"",CONCATENATE('Bundle Tag Info'!$A$1," ",CHAR(10),'Bundle Tag Info'!$A$2," ",'Bundle Tag Info'!$A$3,CHAR(10),'Bundle Tag Info'!H$6,CHAR(10),'Bundle Tag Info'!H$17),"") | ... AD12: =IF('Bundle Tag Info'!AD$17<>"",CONCATENATE('Bundle Tag Info'!$A$1," ",CHAR(10),'Bundle Tag Info'!$A$2," ",'Bundle Tag Info'!$A$3,CHAR(10),'Bundle Tag Info'!AD$6,CHAR(10),'Bundle Tag Info'!AD$17),"")
A13: =IF('Bundle Tag Info'!A$18<>"",CONCATENATE('Bundle Tag Info'!$A$1," ",CHAR(10),'Bundle Tag Info'!$A$2," ",'Bundle Tag Info'!$A$3,CHAR(10),'Bundle Tag Info'!A$6,CHAR(10),'Bundle Tag Info'!A$18),"") | B13: =IF('Bundle Tag Info'!B$18<>"",CONCATENATE('Bundle Tag Info'!$A$1," ",CHAR(10),'Bundle Tag Info'!$A$2," ",'Bundle Tag Info'!$A$3,CHAR(10),'Bundle Tag Info'!B$6,CHAR(10),'Bundle Tag Info'!B$18),"") | C13: =IF('Bundle Tag Info'!C$18<>"",CONCATENATE('Bundle Tag Info'!$A$1," ",CHAR(10),'Bundle Tag Info'!$A$2," ",'Bundle Tag Info'!$A$3,CHAR(10),'Bundle Tag Info'!C$6,CHAR(10),'Bundle Tag Info'!C$18),"") | D13: =IF('Bundle Tag Info'!D$18<>"",CONCATENATE('Bundle Tag Info'!$A$1," ",CHAR(10),'Bundle Tag Info'!$A$2," ",'Bundle Tag Info'!$A$3,CHAR(10),'Bundle Tag Info'!D$6,CHAR(10),'Bundle Tag Info'!D$18),"") | E13: =IF('Bundle Tag Info'!E$18<>"",CONCATENATE('Bundle Tag Info'!$A$1," ",CHAR(10),'Bundle Tag Info'!$A$2," ",'Bundle Tag Info'!$A$3,CHAR(10),'Bundle Tag Info'!E$6,CHAR(10),'Bundle Tag Info'!E$18),"") | F13: =IF('Bundle Tag Info'!F$18<>"",CONCATENATE('Bundle Tag Info'!$A$1," ",CHAR(10),'Bundle Tag Info'!$A$2," ",'Bundle Tag Info'!$A$3,CHAR(10),'Bundle Tag Info'!F$6,CHAR(10),'Bundle Tag Info'!F$18),"") -> SOUTHERN STAR #1 J1620 0.1 A KA-B | G13: =IF('Bundle Tag Info'!G$18<>"",CONCATENATE('Bundle Tag Info'!$A$1," ",CHAR(10),'Bundle Tag Info'!$A$2," ",'Bundle Tag Info'!$A$3,CHAR(10),'Bundle Tag Info'!G$6,CHAR(10),'Bundle Tag Info'!G$18),"") | H13: =IF('Bundle Tag Info'!H$18<>"",CONCATENATE('Bundle Tag Info'!$A$1," ",CHAR(10),'Bundle Tag Info'!$A$2," ",'Bundle Tag Info'!$A$3,CHAR(10),'Bundle Tag Info'!H$6,CHAR(10),'Bundle Tag Info'!H$18),"") | ... AD13: =IF('Bundle Tag Info'!AD$18<>"",CONCATENATE('Bundle Tag Info'!$A$1," ",CHAR(10),'Bundle Tag Info'!$A$2," ",'Bundle Tag Info'!$A$3,CHAR(10),'Bundle Tag Info'!AD$6,CHAR(10),'Bundle Tag Info'!AD$18),"")
A14: =IF('Bundle Tag Info'!A$19<>"",CONCATENATE('Bundle Tag Info'!$A$1," ",CHAR(10),'Bundle Tag Info'!$A$2," ",'Bundle Tag Info'!$A$3,CHAR(10),'Bundle Tag Info'!A$6,CHAR(10),'Bundle Tag Info'!A$19),"") | B14: =IF('Bundle Tag Info'!B$19<>"",CONCATENATE('Bundle Tag Info'!$A$1," ",CHAR(10),'Bundle Tag Info'!$A$2," ",'Bundle Tag Info'!$A$3,CHAR(10),'Bundle Tag Info'!B$6,CHAR(10),'Bundle Tag Info'!B$19),"") | C14: =IF('Bundle Tag Info'!C$19<>"",CONCATENATE('Bundle Tag Info'!$A$1," ",CHAR(10),'Bundle Tag Info'!$A$2," ",'Bundle Tag Info'!$A$3,CHAR(10),'Bundle Tag Info'!C$6,CHAR(10),'Bundle Tag Info'!C$19),"") | D14: =IF('Bundle Tag Info'!D$19<>"",CONCATENATE('Bundle Tag Info'!$A$1," ",CHAR(10),'Bundle Tag Info'!$A$2," ",'Bundle Tag Info'!$A$3,CHAR(10),'Bundle Tag Info'!D$6,CHAR(10),'Bundle Tag Info'!D$19),"") | E14: =IF('Bundle Tag Info'!E$19<>"",CONCATENATE('Bundle Tag Info'!$A$1," ",CHAR(10),'Bundle Tag Info'!$A$2," ",'Bundle Tag Info'!$A$3,CHAR(10),'Bundle Tag Info'!E$6,CHAR(10),'Bundle Tag Info'!E$19),"") | F14: =IF('Bundle Tag Info'!F$19<>"",CONCATENATE('Bundle Tag Info'!$A$1," ",CHAR(10),'Bundle Tag Info'!$A$2," ",'Bundle Tag Info'!$A$3,CHAR(10),'Bundle Tag Info'!F$6,CHAR(10),'Bundle Tag Info'!F$19),"") -> SOUTHERN STAR #1 J1620 0.1 A XT-B | G14: =IF('Bundle Tag Info'!G$19<>"",CONCATENATE('Bundle Tag Info'!$A$1," ",CHAR(10),'Bundle Tag Info'!$A$2," ",'Bundle Tag Info'!$A$3,CHAR(10),'Bundle Tag Info'!G$6,CHAR(10),'Bundle Tag Info'!G$19),"") | H14: =IF('Bundle Tag Info'!H$19<>"",CONCATENATE('Bundle Tag Info'!$A$1," ",CHAR(10),'Bundle Tag Info'!$A$2," ",'Bundle Tag Info'!$A$3,CHAR(10),'Bundle Tag Info'!H$6,CHAR(10),'Bundle Tag Info'!H$19),"") | ... AD14: =IF('Bundle Tag Info'!AD$19<>"",CONCATENATE('Bundle Tag Info'!$A$1," ",CHAR(10),'Bundle Tag Info'!$A$2," ",'Bundle Tag Info'!$A$3,CHAR(10),'Bundle Tag Info'!AD$6,CHAR(10),'Bundle Tag Info'!AD$19),"")
A15: =IF('Bundle Tag Info'!A$20<>"",CONCATENATE('Bundle Tag Info'!$A$1," ",CHAR(10),'Bundle Tag Info'!$A$2," ",'Bundle Tag Info'!$A$3,CHAR(10),'Bundle Tag Info'!A$6,CHAR(10),'Bundle Tag Info'!A$20),"") | B15: =IF('Bundle Tag Info'!B$20<>"",CONCATENATE('Bundle Tag Info'!$A$1," ",CHAR(10),'Bundle Tag Info'!$A$2," ",'Bundle Tag Info'!$A$3,CHAR(10),'Bundle Tag Info'!B$6,CHAR(10),'Bundle Tag Info'!B$20),"") | C15: =IF('Bundle Tag Info'!C$20<>"",CONCATENATE('Bundle Tag Info'!$A$1," ",CHAR(10),'Bundle Tag Info'!$A$2," ",'Bundle Tag Info'!$A$3,CHAR(10),'Bundle Tag Info'!C$6,CHAR(10),'Bundle Tag Info'!C$20),"") | D15: =IF('Bundle Tag Info'!D$20<>"",CONCATENATE('Bundle Tag Info'!$A$1," ",CHAR(10),'Bundle Tag Info'!$A$2," ",'Bundle Tag Info'!$A$3,CHAR(10),'Bundle Tag Info'!D$6,CHAR(10),'Bundle Tag Info'!D$20),"") | E15: =IF('Bundle Tag Info'!E$20<>"",CONCATENATE('Bundle Tag Info'!$A$1," ",CHAR(10),'Bundle Tag Info'!$A$2," ",'Bundle Tag Info'!$A$3,CHAR(10),'Bundle Tag Info'!E$6,CHAR(10),'Bundle Tag Info'!E$20),"") | F15: =IF('Bundle Tag Info'!F$20<>"",CONCATENATE('Bundle Tag Info'!$A$1," ",CHAR(10),'Bundle Tag Info'!$A$2," ",'Bundle Tag Info'!$A$3,CHAR(10),'Bundle Tag Info'!F$6,CHAR(10),'Bundle Tag Info'!F$20),"") | G15: =IF('Bundle Tag Info'!G$20<>"",CONCATENATE('Bundle Tag Info'!$A$1," ",CHAR(10),'Bundle Tag Info'!$A$2," ",'Bundle Tag Info'!$A$3,CHAR(10),'Bundle Tag Info'!G$6,CHAR(10),'Bundle Tag Info'!G$20),"") | H15: =IF('Bundle Tag Info'!H$20<>"",CONCATENATE('Bundle Tag Info'!$A$1," ",CHAR(10),'Bundle Tag Info'!$A$2," ",'Bundle Tag Info'!$A$3,CHAR(10),'Bundle Tag Info'!H$6,CHAR(10),'Bundle Tag Info'!H$20),"") | ... AD15: =IF('Bundle Tag Info'!AD$20<>"",CONCATENATE('Bundle Tag Info'!$A$1," ",CHAR(10),'Bundle Tag Info'!$A$2," ",'Bundle Tag Info'!$A$3,CHAR(10),'Bundle Tag Info'!AD$6,CHAR(10),'Bundle Tag Info'!AD$20),"")
A16: =IF('Bundle Tag Info'!A$21<>"",CONCATENATE('Bundle Tag Info'!$A$1," ",CHAR(10),'Bundle Tag Info'!$A$2," ",'Bundle Tag Info'!$A$3,CHAR(10),'Bundle Tag Info'!A$6,CHAR(10),'Bundle Tag Info'!A$21),"") | B16: =IF('Bundle Tag Info'!B$21<>"",CONCATENATE('Bundle Tag Info'!$A$1," ",CHAR(10),'Bundle Tag Info'!$A$2," ",'Bundle Tag Info'!$A$3,CHAR(10),'Bundle Tag Info'!B$6,CHAR(10),'Bundle Tag Info'!B$21),"") | C16: =IF('Bundle Tag Info'!C$21<>"",CONCATENATE('Bundle Tag Info'!$A$1," ",CHAR(10),'Bundle Tag Info'!$A$2," ",'Bundle Tag Info'!$A$3,CHAR(10),'Bundle Tag Info'!C$6,CHAR(10),'Bundle Tag Info'!C$21),"") | D16: =IF('Bundle Tag Info'!D$21<>"",CONCATENATE('Bundle Tag Info'!$A$1," ",CHAR(10),'Bundle Tag Info'!$A$2," ",'Bundle Tag Info'!$A$3,CHAR(10),'Bundle Tag Info'!D$6,CHAR(10),'Bundle Tag Info'!D$21),"") | E16: =IF('Bundle Tag Info'!E$21<>"",CONCATENATE('Bundle Tag Info'!$A$1," ",CHAR(10),'Bundle Tag Info'!$A$2," ",'Bundle Tag Info'!$A$3,CHAR(10),'Bundle Tag Info'!E$6,CHAR(10),'Bundle Tag Info'!E$21),"") | F16: =IF('Bundle Tag Info'!F$21<>"",CONCATENATE('Bundle Tag Info'!$A$1," ",CHAR(10),'Bundle Tag Info'!$A$2," ",'Bundle Tag Info'!$A$3,CHAR(10),'Bundle Tag Info'!F$6,CHAR(10),'Bundle Tag Info'!F$21),"") | G16: =IF('Bundle Tag Info'!G$21<>"",CONCATENATE('Bundle Tag Info'!$A$1," ",CHAR(10),'Bundle Tag Info'!$A$2," ",'Bundle Tag Info'!$A$3,CHAR(10),'Bundle Tag Info'!G$6,CHAR(10),'Bundle Tag Info'!G$21),"") | H16: =IF('Bundle Tag Info'!H$21<>"",CONCATENATE('Bundle Tag Info'!$A$1," ",CHAR(10),'Bundle Tag Info'!$A$2," ",'Bundle Tag Info'!$A$3,CHAR(10),'Bundle Tag Info'!H$6,CHAR(10),'Bundle Tag Info'!H$21),"") | ... AD16: =IF('Bundle Tag Info'!AD$21<>"",CONCATENATE('Bundle Tag Info'!$A$1," ",CHAR(10),'Bundle Tag Info'!$A$2," ",'Bundle Tag Info'!$A$3,CHAR(10),'Bundle Tag Info'!AD$6,CHAR(10),'Bundle Tag Info'!AD$21),"")
A17: =IF('Bundle Tag Info'!A$22<>"",CONCATENATE('Bundle Tag Info'!$A$1," ",CHAR(10),'Bundle Tag Info'!$A$2," ",'Bundle Tag Info'!$A$3,CHAR(10),'Bundle Tag Info'!A$6,CHAR(10),'Bundle Tag Info'!A$22),"") | B17: =IF('Bundle Tag Info'!B$22<>"",CONCATENATE('Bundle Tag Info'!$A$1," ",CHAR(10),'Bundle Tag Info'!$A$2," ",'Bundle Tag Info'!$A$3,CHAR(10),'Bundle Tag Info'!B$6,CHAR(10),'Bundle Tag Info'!B$22),"") | C17: =IF('Bundle Tag Info'!C$22<>"",CONCATENATE('Bundle Tag Info'!$A$1," ",CHAR(10),'Bundle Tag Info'!$A$2," ",'Bundle Tag Info'!$A$3,CHAR(10),'Bundle Tag Info'!C$6,CHAR(10),'Bundle Tag Info'!C$22),"") | D17: =IF('Bundle Tag Info'!D$22<>"",CONCATENATE('Bundle Tag Info'!$A$1," ",CHAR(10),'Bundle Tag Info'!$A$2," ",'Bundle Tag Info'!$A$3,CHAR(10),'Bundle Tag Info'!D$6,CHAR(10),'Bundle Tag Info'!D$22),"") | E17: =IF('Bundle Tag Info'!E$22<>"",CONCATENATE('Bundle Tag Info'!$A$1," ",CHAR(10),'Bundle Tag Info'!$A$2," ",'Bundle Tag Info'!$A$3,CHAR(10),'Bundle Tag Info'!E$6,CHAR(10),'Bundle Tag Info'!E$22),"") | F17: =IF('Bundle Tag Info'!F$22<>"",CONCATENATE('Bundle Tag Info'!$A$1," ",CHAR(10),'Bundle Tag Info'!$A$2," ",'Bundle Tag Info'!$A$3,CHAR(10),'Bundle Tag Info'!F$6,CHAR(10),'Bundle Tag Info'!F$22),"") | G17: =IF('Bundle Tag Info'!G$22<>"",CONCATENATE('Bundle Tag Info'!$A$1," ",CHAR(10),'Bundle Tag Info'!$A$2," ",'Bundle Tag Info'!$A$3,CHAR(10),'Bundle Tag Info'!G$6,CHAR(10),'Bundle Tag Info'!G$22),"") | H17: =IF('Bundle Tag Info'!H$22<>"",CONCATENATE('Bundle Tag Info'!$A$1," ",CHAR(10),'Bundle Tag Info'!$A$2," ",'Bundle Tag Info'!$A$3,CHAR(10),'Bundle Tag Info'!H$6,CHAR(10),'Bundle Tag Info'!H$22),"") | ... AD17: =IF('Bundle Tag Info'!AD$22<>"",CONCATENATE('Bundle Tag Info'!$A$1," ",CHAR(10),'Bundle Tag Info'!$A$2," ",'Bundle Tag Info'!$A$3,CHAR(10),'Bundle Tag Info'!AD$6,CHAR(10),'Bundle Tag Info'!AD$22),"")
A18: =IF('Bundle Tag Info'!A$23<>"",CONCATENATE('Bundle Tag Info'!$A$1," ",CHAR(10),'Bundle Tag Info'!$A$2," ",'Bundle Tag Info'!$A$3,CHAR(10),'Bundle Tag Info'!A$6,CHAR(10),'Bundle Tag Info'!A$23),"") | B18: =IF('Bundle Tag Info'!B$23<>"",CONCATENATE('Bundle Tag Info'!$A$1," ",CHAR(10),'Bundle Tag Info'!$A$2," ",'Bundle Tag Info'!$A$3,CHAR(10),'Bundle Tag Info'!B$6,CHAR(10),'Bundle Tag Info'!B$23),"") | C18: =IF('Bundle Tag Info'!C$23<>"",CONCATENATE('Bundle Tag Info'!$A$1," ",CHAR(10),'Bundle Tag Info'!$A$2," ",'Bundle Tag Info'!$A$3,CHAR(10),'Bundle Tag Info'!C$6,CHAR(10),'Bundle Tag Info'!C$23),"") | D18: =IF('Bundle Tag Info'!D$23<>"",CONCATENATE('Bundle Tag Info'!$A$1," ",CHAR(10),'Bundle Tag Info'!$A$2," ",'Bundle Tag Info'!$A$3,CHAR(10),'Bundle Tag Info'!D$6,CHAR(10),'Bundle Tag Info'!D$23),"") | E18: =IF('Bundle Tag Info'!E$23<>"",CONCATENATE('Bundle Tag Info'!$A$1," ",CHAR(10),'Bundle Tag Info'!$A$2," ",'Bundle Tag Info'!$A$3,CHAR(10),'Bundle Tag Info'!E$6,CHAR(10),'Bundle Tag Info'!E$23),"") | F18: =IF('Bundle Tag Info'!F$23<>"",CONCATENATE('Bundle Tag Info'!$A$1," ",CHAR(10),'Bundle Tag Info'!$A$2," ",'Bundle Tag Info'!$A$3,CHAR(10),'Bundle Tag Info'!F$6,CHAR(10),'Bundle Tag Info'!F$23),"") | G18: =IF('Bundle Tag Info'!G$23<>"",CONCATENATE('Bundle Tag Info'!$A$1," ",CHAR(10),'Bundle Tag Info'!$A$2," ",'Bundle Tag Info'!$A$3,CHAR(10),'Bundle Tag Info'!G$6,CHAR(10),'Bundle Tag Info'!G$23),"") | H18: =IF('Bundle Tag Info'!H$23<>"",CONCATENATE('Bundle Tag Info'!$A$1," ",CHAR(10),'Bundle Tag Info'!$A$2," ",'Bundle Tag Info'!$A$3,CHAR(10),'Bundle Tag Info'!H$6,CHAR(10),'Bundle Tag Info'!H$23),"") | ... AD18: =IF('Bundle Tag Info'!AD$23<>"",CONCATENATE('Bundle Tag Info'!$A$1," ",CHAR(10),'Bundle Tag Info'!$A$2," ",'Bundle Tag Info'!$A$3,CHAR(10),'Bundle Tag Info'!AD$6,CHAR(10),'Bundle Tag Info'!AD$23),"")
A19: =IF('Bundle Tag Info'!A$24<>"",CONCATENATE('Bundle Tag Info'!$A$1," ",CHAR(10),'Bundle Tag Info'!$A$2," ",'Bundle Tag Info'!$A$3,CHAR(10),'Bundle Tag Info'!A$6,CHAR(10),'Bundle Tag Info'!A$24),"") | B19: =IF('Bundle Tag Info'!B$24<>"",CONCATENATE('Bundle Tag Info'!$A$1," ",CHAR(10),'Bundle Tag Info'!$A$2," ",'Bundle Tag Info'!$A$3,CHAR(10),'Bundle Tag Info'!B$6,CHAR(10),'Bundle Tag Info'!B$24),"") | C19: =IF('Bundle Tag Info'!C$24<>"",CONCATENATE('Bundle Tag Info'!$A$1," ",CHAR(10),'Bundle Tag Info'!$A$2," ",'Bundle Tag Info'!$A$3,CHAR(10),'Bundle Tag Info'!C$6,CHAR(10),'Bundle Tag Info'!C$24),"") | D19: =IF('Bundle Tag Info'!D$24<>"",CONCATENATE('Bundle Tag Info'!$A$1," ",CHAR(10),'Bundle Tag Info'!$A$2," ",'Bundle Tag Info'!$A$3,CHAR(10),'Bundle Tag Info'!D$6,CHAR(10),'Bundle Tag Info'!D$24),"") | E19: =IF('Bundle Tag Info'!E$24<>"",CONCATENATE('Bundle Tag Info'!$A$1," ",CHAR(10),'Bundle Tag Info'!$A$2," ",'Bundle Tag Info'!$A$3,CHAR(10),'Bundle Tag Info'!E$6,CHAR(10),'Bundle Tag Info'!E$24),"") | F19: =IF('Bundle Tag Info'!F$24<>"",CONCATENATE('Bundle Tag Info'!$A$1," ",CHAR(10),'Bundle Tag Info'!$A$2," ",'Bundle Tag Info'!$A$3,CHAR(10),'Bundle Tag Info'!F$6,CHAR(10),'Bundle Tag Info'!F$24),"") | G19: =IF('Bundle Tag Info'!G$24<>"",CONCATENATE('Bundle Tag Info'!$A$1," ",CHAR(10),'Bundle Tag Info'!$A$2," ",'Bundle Tag Info'!$A$3,CHAR(10),'Bundle Tag Info'!G$6,CHAR(10),'Bundle Tag Info'!G$24),"") | H19: =IF('Bundle Tag Info'!H$24<>"",CONCATENATE('Bundle Tag Info'!$A$1," ",CHAR(10),'Bundle Tag Info'!$A$2," ",'Bundle Tag Info'!$A$3,CHAR(10),'Bundle Tag Info'!H$6,CHAR(10),'Bundle Tag Info'!H$24),"") | ... AD19: =IF('Bundle Tag Info'!AD$24<>"",CONCATENATE('Bundle Tag Info'!$A$1," ",CHAR(10),'Bundle Tag Info'!$A$2," ",'Bundle Tag Info'!$A$3,CHAR(10),'Bundle Tag Info'!AD$6,CHAR(10),'Bundle Tag Info'!AD$24),"")
A20: =IF('Bundle Tag Info'!A$25<>"",CONCATENATE('Bundle Tag Info'!$A$1," ",CHAR(10),'Bundle Tag Info'!$A$2," ",'Bundle Tag Info'!$A$3,CHAR(10),'Bundle Tag Info'!A$6,CHAR(10),'Bundle Tag Info'!A$25),"") | B20: =IF('Bundle Tag Info'!B$25<>"",CONCATENATE('Bundle Tag Info'!$A$1," ",CHAR(10),'Bundle Tag Info'!$A$2," ",'Bundle Tag Info'!$A$3,CHAR(10),'Bundle Tag Info'!B$6,CHAR(10),'Bundle Tag Info'!B$25),"") | C20: =IF('Bundle Tag Info'!C$25<>"",CONCATENATE('Bundle Tag Info'!$A$1," ",CHAR(10),'Bundle Tag Info'!$A$2," ",'Bundle Tag Info'!$A$3,CHAR(10),'Bundle Tag Info'!C$6,CHAR(10),'Bundle Tag Info'!C$25),"") | D20: =IF('Bundle Tag Info'!D$25<>"",CONCATENATE('Bundle Tag Info'!$A$1," ",CHAR(10),'Bundle Tag Info'!$A$2," ",'Bundle Tag Info'!$A$3,CHAR(10),'Bundle Tag Info'!D$6,CHAR(10),'Bundle Tag Info'!D$25),"") | E20: =IF('Bundle Tag Info'!E$25<>"",CONCATENATE('Bundle Tag Info'!$A$1," ",CHAR(10),'Bundle Tag Info'!$A$2," ",'Bundle Tag Info'!$A$3,CHAR(10),'Bundle Tag Info'!E$6,CHAR(10),'Bundle Tag Info'!E$25),"") | F20: =IF('Bundle Tag Info'!F$25<>"",CONCATENATE('Bundle Tag Info'!$A$1," ",CHAR(10),'Bundle Tag Info'!$A$2," ",'Bundle Tag Info'!$A$3,CHAR(10),'Bundle Tag Info'!F$6,CHAR(10),'Bundle Tag Info'!F$25),"") | G20: =IF('Bundle Tag Info'!G$25<>"",CONCATENATE('Bundle Tag Info'!$A$1," ",CHAR(10),'Bundle Tag Info'!$A$2," ",'Bundle Tag Info'!$A$3,CHAR(10),'Bundle Tag Info'!G$6,CHAR(10),'Bundle Tag Info'!G$25),"") | H20: =IF('Bundle Tag Info'!H$25<>"",CONCATENATE('Bundle Tag Info'!$A$1," ",CHAR(10),'Bundle Tag Info'!$A$2," ",'Bundle Tag Info'!$A$3,CHAR(10),'Bundle Tag Info'!H$6,CHAR(10),'Bundle Tag Info'!H$25),"") | ... AD20: =IF('Bundle Tag Info'!AD$25<>"",CONCATENATE('Bundle Tag Info'!$A$1," ",CHAR(10),'Bundle Tag Info'!$A$2," ",'Bundle Tag Info'!$A$3,CHAR(10),'Bundle Tag Info'!AD$6,CHAR(10),'Bundle Tag Info'!AD$25),"")
A21: =IF('Bundle Tag Info'!A$26<>"",CONCATENATE('Bundle Tag Info'!$A$1," ",CHAR(10),'Bundle Tag Info'!$A$2," ",'Bundle Tag Info'!$A$3,CHAR(10),'Bundle Tag Info'!A$6,CHAR(10),'Bundle Tag Info'!A$26),"") | B21: =IF('Bundle Tag Info'!B$26<>"",CONCATENATE('Bundle Tag Info'!$A$1," ",CHAR(10),'Bundle Tag Info'!$A$2," ",'Bundle Tag Info'!$A$3,CHAR(10),'Bundle Tag Info'!B$6,CHAR(10),'Bundle Tag Info'!B$26),"") | C21: =IF('Bundle Tag Info'!C$26<>"",CONCATENATE('Bundle Tag Info'!$A$1," ",CHAR(10),'Bundle Tag Info'!$A$2," ",'Bundle Tag Info'!$A$3,CHAR(10),'Bundle Tag Info'!C$6,CHAR(10),'Bundle Tag Info'!C$26),"") | D21: =IF('Bundle Tag Info'!D$26<>"",CONCATENATE('Bundle Tag Info'!$A$1," ",CHAR(10),'Bundle Tag Info'!$A$2," ",'Bundle Tag Info'!$A$3,CHAR(10),'Bundle Tag Info'!D$6,CHAR(10),'Bundle Tag Info'!D$26),"") | E21: =IF('Bundle Tag Info'!E$26<>"",CONCATENATE('Bundle Tag Info'!$A$1," ",CHAR(10),'Bundle Tag Info'!$A$2," ",'Bundle Tag Info'!$A$3,CHAR(10),'Bundle Tag Info'!E$6,CHAR(10),'Bundle Tag Info'!E$26),"") | F21: =IF('Bundle Tag Info'!F$26<>"",CONCATENATE('Bundle Tag Info'!$A$1," ",CHAR(10),'Bundle Tag Info'!$A$2," ",'Bundle Tag Info'!$A$3,CHAR(10),'Bundle Tag Info'!F$6,CHAR(10),'Bundle Tag Info'!F$26),"") | G21: =IF('Bundle Tag Info'!G$26<>"",CONCATENATE('Bundle Tag Info'!$A$1," ",CHAR(10),'Bundle Tag Info'!$A$2," ",'Bundle Tag Info'!$A$3,CHAR(10),'Bundle Tag Info'!G$6,CHAR(10),'Bundle Tag Info'!G$26),"") | H21: =IF('Bundle Tag Info'!H$26<>"",CONCATENATE('Bundle Tag Info'!$A$1," ",CHAR(10),'Bundle Tag Info'!$A$2," ",'Bundle Tag Info'!$A$3,CHAR(10),'Bundle Tag Info'!H$6,CHAR(10),'Bundle Tag Info'!H$26),"") | ... AD21: =IF('Bundle Tag Info'!AD$26<>"",CONCATENATE('Bundle Tag Info'!$A$1," ",CHAR(10),'Bundle Tag Info'!$A$2," ",'Bundle Tag Info'!$A$3,CHAR(10),'Bundle Tag Info'!AD$6,CHAR(10),'Bundle Tag Info'!AD$26),"")
A22: =IF('Bundle Tag Info'!A$27<>"",CONCATENATE('Bundle Tag Info'!$A$1," ",CHAR(10),'Bundle Tag Info'!$A$2," ",'Bundle Tag Info'!$A$3,CHAR(10),'Bundle Tag Info'!A$6,CHAR(10),'Bundle Tag Info'!A$27),"") | B22: =IF('Bundle Tag Info'!B$27<>"",CONCATENATE('Bundle Tag Info'!$A$1," ",CHAR(10),'Bundle Tag Info'!$A$2," ",'Bundle Tag Info'!$A$3,CHAR(10),'Bundle Tag Info'!B$6,CHAR(10),'Bundle Tag Info'!B$27),"") | C22: =IF('Bundle Tag Info'!C$27<>"",CONCATENATE('Bundle Tag Info'!$A$1," ",CHAR(10),'Bundle Tag Info'!$A$2," ",'Bundle Tag Info'!$A$3,CHAR(10),'Bundle Tag Info'!C$6,CHAR(10),'Bundle Tag Info'!C$27),"") | D22: =IF('Bundle Tag Info'!D$27<>"",CONCATENATE('Bundle Tag Info'!$A$1," ",CHAR(10),'Bundle Tag Info'!$A$2," ",'Bundle Tag Info'!$A$3,CHAR(10),'Bundle Tag Info'!D$6,CHAR(10),'Bundle Tag Info'!D$27),"") | E22: =IF('Bundle Tag Info'!E$27<>"",CONCATENATE('Bundle Tag Info'!$A$1," ",CHAR(10),'Bundle Tag Info'!$A$2," ",'Bundle Tag Info'!$A$3,CHAR(10),'Bundle Tag Info'!E$6,CHAR(10),'Bundle Tag Info'!E$27),"") | F22: =IF('Bundle Tag Info'!F$27<>"",CONCATENATE('Bundle Tag Info'!$A$1," ",CHAR(10),'Bundle Tag Info'!$A$2," ",'Bundle Tag Info'!$A$3,CHAR(10),'Bundle Tag Info'!F$6,CHAR(10),'Bundle Tag Info'!F$27),"") | G22: =IF('Bundle Tag Info'!G$27<>"",CONCATENATE('Bundle Tag Info'!$A$1," ",CHAR(10),'Bundle Tag Info'!$A$2," ",'Bundle Tag Info'!$A$3,CHAR(10),'Bundle Tag Info'!G$6,CHAR(10),'Bundle Tag Info'!G$27),"") | H22: =IF('Bundle Tag Info'!H$27<>"",CONCATENATE('Bundle Tag Info'!$A$1," ",CHAR(10),'Bundle Tag Info'!$A$2," ",'Bundle Tag Info'!$A$3,CHAR(10),'Bundle Tag Info'!H$6,CHAR(10),'Bundle Tag Info'!H$27),"") | ... AD22: =IF('Bundle Tag Info'!AD$27<>"",CONCATENATE('Bundle Tag Info'!$A$1," ",CHAR(10),'Bundle Tag Info'!$A$2," ",'Bundle Tag Info'!$A$3,CHAR(10),'Bundle Tag Info'!AD$6,CHAR(10),'Bundle Tag Info'!AD$27),"")
