Workbook

Sheet Panel Errors
A1: Panel Errors
A3: Project # | B3: 4P101
A4: Project Name | B4: DEPLETION COMPRESSION SYSTEM & SRU
A5: Revision | B5: C
A7: Controls DE
A8: Phone:
A9: Controls ME
A10: Phone:
A12: From | H12: To
A13: Device ID | B13: Location | C13: Cable (W) Conductor (SC) Jumper Clip (JC) | D13: Wire ID | E13: Wire No. | F13: Gauge/Size | G13: Page/Zone | H13: Device ID | I13: Location | J13: Page/Zone
E15: SolarTools ver. 24.0.84.24712 (Jul 31, 2025)
A16: Report date: 2/19/2026 4:51 PM

Sheet JB70 DOOR_S
A1: JB70 DOOR
A3: Project # | B3: 4P101
A4: Project Name | B4: DEPLETION COMPRESSION SYSTEM & SRU
A5: Revision | B5: C
A7: Controls DE
A8: Phone:
A9: Controls ME
A10: Phone:
A12: From | G12: To
A13: Device ID | B13: Wire No. | C13: Wire ID | D13: Gauge/Size | E13: Length | F13: Device ID | G13: Location | H13: Bundle Name
A14: AT1100:NEG | B14: -0V | C14: WHT | D14: 14 | E14: 180 | F14: XT0111:22 | G14: JB70 R RAIL | H14: AT1100
A16: AT1100:POS | B16: FU1100 | C16: WHT | D16: 14 | E16: 140 | F16: FU1100:LD | G16: HMI-S PWR
A18: SA0471:B1-13 | B18: SA0471B113 | C18: WHT | D18: 20 | E18: 240 | F18: AF0087:40 | G18: A | H18: SA0471
A19: SA0471:B1-14 | B19: SA0471B114 | C19: WHT | D19: 20 | E19: 240 | F19: AF0087:08 | G19: A
A20: SA0471:B2-13 | B20: SA0471B213 | C20: WHT | D20: 20 | E20: 240 | F20: AF0087:39 | G20: A
A21: SA0471:B2-14 | B21: SA0471B214 | C21: WHT | D21: 20 | E21: 240 | F21: AF0087:07 | G21: A
A23: SA0472:B1-13 | B23: SA0472B113 | C23: WHT | D23: 20 | E23: 220 | F23: AF0091:47 | G23: B | H23: SA0472
A24: SA0472:B1-14 | B24: SA0472B114 | C24: WHT | D24: 20 | E24: 220 | F24: AF0091:15 | G24: B
A25: SA0472:B2-13 | B25: SA0472B213 | C25: WHT | D25: 20 | E25: 220 | F25: AF0091:46 | G25: B
A26: SA0472:B2-14 | B26: SA0472B214 | C26: WHT | D26: 20 | E26: 220 | F26: AF0091:14 | G26: B
A28: SA0473:11 | B28: SA047311 | C28: WHT | D28: 20 | E28: 240 | F28: AF0087:37 | G28: A | H28: SA0473
A29: SA0473:12 | B29: SA047312 | C29: WHT | D29: 20 | E29: 240 | F29: AF0087:05 | G29: A
A30: SA0473:13 | B30: SA047313 | C30: WHT | D30: 20 | E30: 240 | F30: AF0087:38 | G30: A
A31: SA0473:14 | B31: SA047314 | C31: WHT | D31: 20 | E31: 240 | F31: AF0087:06 | G31: A
A33: SB0471:11 | B33: SB047111 | C33: WHT | D33: 20 | E33: 240 | F33: AF0087:34 | G33: A | H33: SB0471
A34: SB0471:12 | B34: SB047112 | C34: WHT | D34: 20 | E34: 240 | F34: AF0087:02 | G34: A
A36: SB0472:B1-12 | B36: ESTOPA | C36: WHT | D36: 20 | E36: 180 | F36: XT0111:20 | G36: JB70 R RAIL | H36: SB0472
A37: SB0472:B1-11 | B37: ESTOPB | C37: WHT | D37: 20 | E37: 180 | F37: XT0111:19 | G37: JB70 R RAIL
A39: SB0472:B2-11 | B39: SB0472B211 | C39: WHT | D39: 20 | E39: 240 | F39: AF0081:36 | G39: A
A40: SB0472:B2-12 | B40: SB0472B212 | C40: WHT | D40: 20 | E40: 240 | F40: AF0081:04 | G40: A
A42: SB0473:13 | B42: SB047313 | C42: WHT | D42: 20 | E42: 240 | F42: AF0087:35 | G42: A | H42: SB0473
A43: SB0473:14 | B43: SB047314 | C43: WHT | D43: 20 | E43: 240 | F43: AF0087:03 | G43: A
A45: SB0474:13 | B45: SB047413 | C45: WHT | D45: 20 | E45: 240 | F45: AF0087:36 | G45: A | H45: SB0474
A46: SB0474:14 | B46: SB047414 | C46: WHT | D46: 20 | E46: 240 | F46: AF0087:04 | G46: A
A48: SH0470:11 | B48: SH047011 | C48: WHT | D48: 20 | E48: 180 | F48: XT0111:7 | G48: JB70 R RAIL | H48: SH0470
A49: SH0470:12 | B49: SH047012 | C49: WHT | D49: 20 | E49: 180 | F49: XT0111:8 | G49: JB70 R RAIL
A50: SH0470:13 | B50: SH047013 | C50: WHT | D50: 20 | E50: 180 | F50: XT0111:9 | G50: JB70 R RAIL
A51: SH0470:14 | B51: SH047014 | C51: WHT | D51: 20 | E51: 180 | F51: XT0111:10 | G51: JB70 R RAIL
A52: SH0470:X1 | B52: SH0470X1 | C52: WHT | D52: 20 | E52: 180 | F52: XT0111:12 | G52: JB70 R RAIL
A53: SH0470:X2 | B53: SH0470X2 | C53: WHT | D53: 20 | E53: 180 | F53: XT0111:11 | G53: JB70 R RAIL
...

Sheet HMI-S PWR_S
A1: HMI-S PWR
A3: Project # | B3: 4P101
A4: Project Name | B4: DEPLETION COMPRESSION SYSTEM & SRU
A5: Revision | B5: C
A7: Controls DE
A8: Phone:
A9: Controls ME
A10: Phone:
A12: From | G12: To
A13: Device ID | B13: Wire No. | C13: Wire ID | D13: Gauge/Size | E13: Length | F13: Device ID | G13: Location | H13: Bundle Name
A14: BA1100:NEG | B14: -0V | C14: WHT | D14: 16 | E14: 60 | F14: XT0111:22 | G14: HMI-S | H14: BA
A15: BA1100:POS | B15: FU1101LD | C15: WHT | D15: 16 | E15: 60 | F15: FU1101:LD | G15: HMI-S

Sheet JB70 R RAIL_S
A1: JB70 RIGHT RAIL
A3: Project # | B3: 4P101
A4: Project Name | B4: DEPLETION COMPRESSION SYSTEM & SRU
A5: Revision | B5: C
A7: Controls DE
A8: Phone:
A9: Controls ME
A10: Phone:
A12: From | G12: To
A13: Device ID | B13: Wire No. | C13: Wire ID | D13: Gauge/Size | E13: Length | F13: Device ID | G13: Location | H13: Bundle Name
A14: XT0111:22 | B14: -0V | C14: WHT | D14: 16 | E14: 180 | F14: BA1100:NEG | G14: HMI-S | H14: XT-HMI
A16: XT0111:21 | B16: FU0136 | C16: WHT | D16: 14 | E16: 180 | F16: FU1101:LI | G16: HMI-S
A17: XT0111:21 | B17: FU0136 | C17: WHT | D17: 14 | E17: 180 | F17: FU1100:LI | G17: HM-S
A19: XT0111:20 | B19: ESTOPA | C19: WHT | D19: 20 | E19: 220 | F19: XT0089:4 | G19: A | H19: XT-A
A20: XT0111:19 | B20: ESTOPB | C20: WHT | D20: 20 | E20: 220 | F20: XT0089:3 | G20: A
A21: XT0111:15 | B21: FU0139 | C21: WHT | D21: 20 | E21: 220 | F21: XT0081:6 | G21: A
A22: XT0111:25 | B22: FU0535 | C22: WHT | D22: 20 | E22: 220 | F22: KA0875:14 | G22: A
A23: XT0111:24 | B23: HA047201 | C23: WHT | D23: 20 | E23: 220 | F23: KA0875:A2 | G23: A
A24: XT0111:23 | B24: HA047202 | C24: WHT | D24: 20 | E24: 220 | F24: KA0875:11 | G24: A
A25: XT0111:23 | B25: HA047202 | C25: WHT | D25: 20 | E25: 220 | F25: KA0232:11 | G25: A
A26: XT0111:16 | B26: KA0241A1 | C26: WHT | D26: 20 | E26: 220 | F26: XT0081:7 | G26: A
A27: XT0111:7 | B27: SH047011 | C27: WHT | D27: 20 | E27: 220 | F27: AF0087:33 | G27: A
A28: XT0111:8 | B28: SH047012 | C28: WHT | D28: 20 | E28: 220 | F28: AF0087:01 | G28: A
A29: XT0111:3 | B29: SH047113 | C29: WHT | D29: 20 | E29: 220 | F29: AF0087:32 | G29: A
A30: XT0111:4 | B30: SH047114 | C30: WHT | D30: 20 | E30: 220 | F30: AF0087:00 | G30: A
A31: XT0111:17 | B31: SH0472X2 | C31: WHT | D31: 20 | E31: 220 | F31: KA0240:21 | G31: A
... A34: XT0111:21 | B34: FU0136 | C34: WHT | D34: 14 | E34: 220 | F34: XT0002:6 | G34: A
A36: XT0111:24 | B36: HA047201 | C36: WHT | D36: 20 | E36: 180 | F36: AF0092:28 | G36: B | H36: XT-B
A37: XT0111:12 | B37: SH0470X1 | C37: WHT | D37: 20 | E37: 180 | F37: AF0093:22 | G37: B
A38: XT0111:11 | B38: SH0470X2 | C38: WHT | D38: 20 | E38: 180 | F38: AF0093:06 | G38: B
A39: XT0111:6 | B39: SH0471X1 | C39: WHT | D39: 20 | E39: 180 | F39: AF0093:31 | G39: B
A40: XT0111:5 | B40: SH0471X2 | C40: WHT | D40: 20 | E40: 180 | F40: AF0093:15 | G40: B
A41: XT0111:18 | B41: SH0472X1 | C41: WHT | D41: 20 | E41: 180 | F41: AF0092:29 | G41: B
A42: XT0111:17 | B42: SH0472X2 | C42: WHT | D42: 20 | E42: 180 | F42: AF0092:13 | G42: B

Sheet PLC_S
A1: PLC
A3: Project # | B3: 4P101
A4: Project Name | B4: DEPLETION COMPRESSION SYSTEM & SRU
A5: Revision | B5: C
A7: Controls DE
A8: Phone:
A9: Controls ME
A10: Phone:
A12: From | G12: To
A13: Device ID | B13: Wire No. | C13: Wire ID | D13: Gauge/Size | E13: Length | F13: Device ID | G13: Location | H13: Bundle Name
A14: AT0680:NEG | B14: -0V | C14: WHT | D14: 14 | E14: 60 | F14: XT0680:2 | G14: PLC | H14: FU/AT
A15: AT0680:POS | B15: AT0680POS | C15: WHT | D15: 14 | E15: 60 | F15: XT0680:1 | G15: PLC
A17: FU0680:LD | B17: AT0680POS | C17: WHT | D17: 14 | E17: 60 | F17: XT0680:1 | G17: PLC
A18: FU0010:LD | B18: FU0010 | C18: WHT | D18: 14 | E18: 60 | F18: UV0600:(+) | G18: PLC
A20: UV0600:(-) | B20: -0V | C20: WHT | D20: 14 | E20: 80 | F20: XT0003:4 | G20: A | H20: FU/UV-A
A21: FU0010:LI | B21: FU0136 | C21: WHT | D21: 14 | E21: 80 | F21: XT0002:4 | G21: A
A23: BA0001:V1(-) | B23: -0V | C23: WHT | D23: 16 | E23: 80 | F23: XT0051:5 | G23: B | H23: BA-B
A24: BA0002:V1(-) | B24: -0V | C24: WHT | D24: 16 | E24: 80 | F24: XT0051:6 | G24: B
A25: BA0009:V1(-) | B25: -0V | C25: WHT | D25: 16 | E25: 80 | F25: XT0051:7 | G25: B
A26: BA0001:V1(+) | B26: FU0021 | C26: WHT | D26: 16 | E26: 80 | F26: FU0021:LD | G26: B
A27: BA0002:V1(+) | B27: FU0022 | C27: WHT | D27: 16 | E27: 80 | F27: FU0022:LD | G27: B
A28: BA0009:V1(+) | B28: FU0029 | C28: WHT | D28: 16 | E28: 80 | F28: FU0029:LD | G28: B
A30: XT1124:2 | B30: -0V | C30: WHT | D30: 16 | E30: 80 | F30: XT0051:6 | G30: B | H30: FU/XT-B
A31: XT1124:1 | B31: FU5122 | C31: WHT | D31: 16 | E31: 80 | F31: FU5122:LD | G31: B
A33: XT0680:2 | B33: -0V | C33: WHT | D33: 14 | E33: 80 | F33: XT0051:8 | G33: B
A34: FU0680:LI | B34: FU0136 | C34: WHT | D34: 14 | E34: 80 | F34: XT0051:4 | G34: B

Sheet A_S
A1: CONTROL A
A3: Project # | B3: 4P101
A4: Project Name | B4: DEPLETION COMPRESSION SYSTEM & SRU
A5: Revision | B5: C
A7: Controls DE
A8: Phone:
A9: Controls ME
A10: Phone:
A12: From | G12: To
A13: Device ID | B13: Wire No. | C13: Wire ID | D13: Gauge/Size | E13: Length | F13: Device ID | G13: Location | H13: Bundle Name
A14: AF0081:00 | B14: UA1200J21 | C14: WHT | D14: 20 | E14: 80 | F14: XT0089:20 | G14: A | H14: AF
A16: AU0080:COM | B16: -0V | C16: WHT | D16: 16 | E16: 60 | F16: XT0080:1 | G16: A
A17: AU0080:V+ | B17: FU0081 | C17: WHT | D17: 16 | E17: 60 | F17: FU0081:LD | G17: A
A19: FU0139:LD | B19: FU0139 | C19: WHT | D19: 16 | E19: 60 | F19: XT0081:1 | G19: A | H19: FU
A20: FU0389:LD | B20: FU0389 | C20: WHT | D20: 16 | E20: 60 | F20: XT0089:21 | G20: A
A22: FU0081:LI | B22: FU0080 | C22: WHT | D22: 14 | E22: 60 | F22: FU0080:LD | G22: A
A23: FU0081:LI | B23: FU0080 | C23: WHT | D23: 14 | E23: 60 | F23: FU0090:LI | G23: A
A24: FU0137:LI | B24: FU0136 | C24: WHT | D24: 14 | E24: 60 | F24: XT0002:2 | G24: A
A26: FU0080:LI | B26: FU0137 | C26: WHT | D26: 12 | E26: 60 | F26: FU0137:LD | G26: A
A27: FU0139:LI | B27: FU0137 | C27: WHT | D27: 12 | E27: 60 | F27: FU0387:LI | G27: A
A29: KA0239:A1 | B29: ESTOP | C29: WHT | D29: 20 | E29: 60 | F29: KA0240:A1 | G29: A | H29: KA A1
A30: KA0130:A1 | B30: KA0130A1 | C30: WHT | D30: 20 | E30: 60 | F30: AF0081:35 | G30: A
A31: KA0130:A1 | B31: KA0130A1 | C31: WHT | D31: 20 | E31: 60 | F31: KA0130:11 | G31: A
A32: KA0131:A1 | B32: KA0131A1 | C32: WHT | D32: 20 | E32: 60 | F32: KA0242:14 | G32: A
A33: KA0132:A1 | B33: KA0131A1 | C33: WHT | D33: 20 | E33: 60 | F33: KA0141:A1 | G33: A
A34: KA0141:A1 | B34: KA0131A1 | C34: WHT | D34: 20 | E34: 60 | F34: KA0230:A1 | G34: A
A35: KA0230:A1 | B35: KA0131A1 | C35: WHT | D35: 20 | E35: 60 | F35: KA0231:A1 | G35: A
A36: KA0231:A1 | B36: KA0131A1 | C36: WHT | D36: 20 | E36: 60 | F36: KA0232:A1 | G36: A
A37: KA0135:A1 | B37: KA0135A1 | C37: WHT | D37: 20 | E37: 80 | F37: XT0089:23 | G37: A
A38: KA0135:A1 | B38: KA0135A1 | C38: WHT | D38: 20 | E38: 100 | F38: KA0131:11 | G38: A
A39: KA0138:A1 | B39: KA0138A1 | C39: WHT | D39: 20 | E39: 60 | F39: KA0132:21 | G39: A
A40: KA0241:A1 | B40: KA0241A1 | C40: WHT | D40: 20 | E40: 60 | F40: XT0081:7 | G40: A
A41: KA0243:A1 | B41: KA0243A1 | C41: WHT | D41: 20 | E41: 60 | F41: XT0089:10 | G41: A
... A43: KA0136:A1 | B43: PS32002 | C43: WHT | D43: 20 | E43: 60 | F43: XT0089:14 | G43: A
A45: KA0133:A2 | B45: -0V | C45: WHT | D45: 20 | E45: 60 | F45: KA0136:A2 | G45: A | H45: KA A2
A46: KA0135:A2 | B46: -0V | C46: WHT | D46: 20 | E46: 80 | F46: KA0137:A2 | G46: A
A47: KA0136:A2 | B47: -0V | C47: WHT | D47: 20 | E47: 60 | F47: KA0138:A2 | G47: A
A48: KA0239:A2 | B48: -0V | C48: WHT | D48: 20 | E48: 60 | F48: KA0240:A2 | G48: A
A49: KA0241:A2 | B49: -0V | C49: WHT | D49: 20 | E49: 60 | F49: XT0080:8 | G49: A
A50: KA0243:A2 | B50: -0V | C50: WHT | D50: 20 | E50: 60 | F50: XT0080:7 | G50: A
...

Sheet B_S
A1: CONTROL B
A3: Project # | B3: 4P101
A4: Project Name | B4: DEPLETION COMPRESSION SYSTEM & SRU
A5: Revision | B5: C
A7: Controls DE
A8: Phone:
A9: Controls ME
A10: Phone:
A12: From | G12: To
A13: Device ID | B13: Wire No. | C13: Wire ID | D13: Gauge/Size | E13: Length | F13: Device ID | G13: Location | H13: Bundle Name
A14: PC0470:INP_A | B14: -009312 | C14: WHT | D14: 20 | E14: 80 | F14: AF0093:12 | G14: B | H14: PC
A15: PC0470:-PWR | B15: -009328 | C15: WHT | D15: 20 | E15: 80 | F15: AF0093:28 | G15: B
A16: PC0470:+PWR | B16: -009344 | C16: WHT | D16: 20 | E16: 80 | F16: AF0093:44 | G16: B
A18: AF0061:COM | B18: -0V | C18: WHT | D18: 16 | E18: 60 | F18: XT0060:2 | G18: B | H18: AF/AU060s
A19: AF0062:COM | B19: -0V | C19: WHT | D19: 16 | E19: 80 | F19: XT0060:3 | G19: B
A20: AF0067:COM | B20: -0V | C20: WHT | D20: 16 | E20: 80 | F20: XT0060:3 | G20: B
A21: AU0060:COM | B21: -0V | C21: WHT | D21: 16 | E21: 60 | F21: XT0060:2 | G21: B
A22: AF0066:COM | B22: AF0066N | C22: WHT | D22: 16 | E22: 60 | F22: AF0068:COM | G22: B
A23: AF0066:V+ | B23: AF0066P | C23: WHT | D23: 16 | E23: 60 | F23: AF0068:V+ | G23: B
A24: AF0063:COM | B24: AU0060N | C24: WHT | D24: 16 | E24: 60 | F24: AU0060:COM | G24: B
A25: AF0063:V+ | B25: AU0060P | C25: WHT | D25: 16 | E25: 60 | F25: AU0060:V+ | G25: B
A26: AU0060:V+ | B26: FU0061 | C26: WHT | D26: 16 | E26: 60 | F26: FU0061:LD | G26: B
A27: AF0061:V+ | B27: FU0062 | C27: WHT | D27: 16 | E27: 60 | F27: FU0062:LD | G27: B
A28: AF0062:V+ | B28: FU0063 | C28: WHT | D28: 16 | E28: 60 | F28: FU0063:LD | G28: B
A29: AF0067:V+ | B29: FU0064 | C29: WHT | D29: 16 | E29: 60 | F29: FU0064:LD | G29: B
A31: AF0076:COM | B31: -0V | C31: WHT | D31: 16 | E31: 80 | F31: XT0060:4 | G31: B | H31: AF/AU070s
A32: AU0070:COM | B32: -0V | C32: WHT | D32: 16 | E32: 60 | F32: XT0060:4 | G32: B
A33: AF0075:COM | B33: AF0075N | C33: WHT | D33: 16 | E33: 60 | F33: AF0077:COM | G33: B
A34: AF0075:V+ | B34: AF0075P | C34: WHT | D34: 16 | E34: 60 | F34: AF0077:V+ | G34: B
A35: AU0070:V+ | B35: FU0070 | C35: WHT | D35: 16 | E35: 60 | F35: FU0070:LD | G35: B
A36: AF0076:V+ | B36: FU0076 | C36: WHT | D36: 16 | E36: 60 | F36: FU0076:LD | G36: B
A38: AF0091:COM | B38: AF0091N | C38: WHT | D38: 16 | E38: 60 | F38: AF0094:COM | G38: B | H38: AF090s
A39: AF0091:V+ | B39: AF0091P | C39: WHT | D39: 16 | E39: 60 | F39: AF0094:V+ | G39: B
A41: AF0410:53 | B41: -0V | C41: WHT | D41: 16 | E41: 60 | F41: XT0401:2 | G41: B | H41: 1444s
A42: AF0410:54 | B42: -0V | C42: WHT | D42: 16 | E42: 60 | F42: AF0420:53 | G42: B
A43: AF0420:54 | B43: -0V | C43: WHT | D43: 16 | E43: 60 | F43: AF0440:53 | G43: B
A44: AF0440:54 | B44: -0V | C44: WHT | D44: 16 | E44: 60 | F44: AF0450:53 | G44: B
A45: AF0410:55 | B45: FU0410 | C45: WHT | D45: 16 | E45: 120 | F45: FU0410:LD | G45: B
A46: AF0410:56 | B46: FU0410 | C46: WHT | D46: 16 | E46: 60 | F46: AF0420:55 | G46: B
A47: AF0420:56 | B47: FU0410 | C47: WHT | D47: 16 | E47: 60 | F47: AF0440:55 | G47: B
...

Sheet JB72 DOOR_S
A1: CONTROL,JB72
A3: Project # | B3: 4P101
A4: Project Name | B4: DEPLETION COMPRESSION SYSTEM & SRU
A5: Revision | B5: C
A7: Controls DE
A8: Phone:
A9: Controls ME
A10: Phone:
A12: From | G12: To
A13: Device ID | B13: Wire No. | C13: Wire ID | D13: Gauge/Size | E13: Length | F13: Device ID | G13: Location | H13: Bundle Name
A14: HL0171:X1 | B14: HL0171X1 | C14: WHT | D14: 20 | E14: 220 | F14: XT0173:3 | G14: FG&E CTRL | H14: HL0171
A15: HL0171:X2 | B15: HL0171X2 | C15: WHT | D15: 20 | E15: 220 | F15: XT0173:1 | G15: FG&E CTRL
A17: HL0172:X1 | B17: HL0172X1 | C17: WHT | D17: 20 | E17: 220 | F17: XT0173:6 | G17: FG&E CTRL | H17: HL0172
A18: HL0172:X2 | B18: HL0172X2 | C18: WHT | D18: 20 | E18: 220 | F18: XT0173:4 | G18: FG&E CTRL
A20: HL0173:X1 | B20: HL0173X1 | C20: WHT | D20: 20 | E20: 220 | F20: XT0173:9 | G20: FG&E CTRL | H20: HL0173
A21: HL0173:X2 | B21: HL0173X2 | C21: WHT | D21: 20 | E21: 220 | F21: XT0173:7 | G21: FG&E CTRL
A23: SA0170:B1-13 | B23: AT01754P1 | C23: WHT | D23: 20 | E23: 240 | F23: AT0175:4P1 | G23: FG&E CTRL | H23: SA0170
A24: SA0170:B1-14 | B24: SA0170B114 | C24: WHT | D24: 20 | E24: 240 | F24: KA6510:A1 | G24: FG&E CTRL
A25: SA0170:B2-13 | B25: SA0170B213 | C25: WHT | D25: 20 | E25: 220 | F25: XT0173:10 | G25: FG&E CTRL
A26: SA0170:B2-14 | B26: SA0170B214 | C26: WHT | D26: 20 | E26: 220 | F26: XT0173:11 | G26: FG&E CTRL
A28: SB0170:13 | B28: SB017013 | C28: WHT | D28: 20 | E28: 220 | F28: XT0173:12 | G28: FG&E CTRL | H28: SB0170
A29: SB0170:14 | B29: SB017014 | C29: WHT | D29: 20 | E29: 220 | F29: XT0173:13 | G29: FG&E CTRL

Sheet FG&E CTRL_S
A1: FG&E CTRL
A3: Project # | B3: 4P101
A4: Project Name | B4: DEPLETION COMPRESSION SYSTEM & SRU
A5: Revision | B5: C
A7: Controls DE
A8: Phone:
A9: Controls ME
A10: Phone:
A12: From | G12: To
A13: Device ID | B13: Wire No. | C13: Wire ID | D13: Gauge/Size | E13: Length | F13: Device ID | G13: Location | H13: Bundle Name
A14: AF0181:26 | B14: -018126 | C14: WHT | D14: 20 | E14: 60 | F14: XT0181:2 | G14: FG&E CTRL | H14: AF/AU180s
A16: AF0181:COM | B16: -0V | C16: WHT | D16: 16 | E16: 60 | F16: XT0180:1 | G16: FG&E CTRL
A17: AU0180:COM | B17: -0V | C17: WHT | D17: 16 | E17: 60 | F17: XT0180:1 | G17: FG&E CTRL
A18: AF0182:COM | B18: AU0180N | C18: WHT | D18: 16 | E18: 60 | F18: AU0180:COM | G18: FG&E CTRL
A19: AF0182:V+ | B19: AU0180P | C19: WHT | D19: 16 | E19: 60 | F19: AU0180:V+ | G19: FG&E CTRL
A20: AU0180:V+ | B20: FU0180 | C20: WHT | D20: 16 | E20: 60 | F20: FU0180:LD | G20: FG&E CTRL
A21: AF0181:V+ | B21: FU0181 | C21: WHT | D21: 16 | E21: 60 | F21: FU0181:LD | G21: FG&E CTRL
A23: AT0175:14 | B23: AT017514 | C23: WHT | D23: 20 | E23: 60 | F23: RR1755: -10K OHM | G23: FG&E CTRL | H23: AT
A24: AT0175:15 | B24: AT017515 | C24: WHT | D24: 20 | E24: 60 | F24: RR1755: -10K OHM | G24: FG&E CTRL
A25: AT0175:17 | B25: AT017517 | C25: WHT | D25: 20 | E25: 60 | F25: XT0173:2 | G25: FG&E CTRL
A26: AT0175:20 | B26: AT017520 | C26: WHT | D26: 20 | E26: 60 | F26: XT0173:5 | G26: FG&E CTRL
A27: AT0175:23 | B27: AT017523 | C27: WHT | D27: 20 | E27: 60 | F27: XT0173:8 | G27: FG&E CTRL
A28: AT0178:23 | B28: AT017823 | C28: WHT | D28: 20 | E28: 60 | F28: XT0171:2 | G28: FG&E CTRL
A29: AT0178:24 | B29: AT017824 | C29: WHT | D29: 20 | E29: 60 | F29: XT0171:3 | G29: FG&E CTRL
A30: AT0170:24 | B30: FU0172 | C30: WHT | D30: 20 | E30: 60 | F30: XT0170:5 | G30: FG&E CTRL
A31: AT0170:30 | B31: FU0172 | C31: WHT | D31: 20 | E31: 60 | F31: XT0170:5 | G31: FG&E CTRL
A32: AT0175:18 | B32: HL0171X1 | C32: WHT | D32: 20 | E32: 60 | F32: XT0173:3 | G32: FG&E CTRL
A33: AT0175:21 | B33: HL0172X1 | C33: WHT | D33: 20 | E33: 60 | F33: XT0173:6 | G33: FG&E CTRL
A34: AT0175:24 | B34: HL0173X1 | C34: WHT | D34: 20 | E34: 60 | F34: XT0173:9 | G34: FG&E CTRL
A35: AT0170:26 | B35: KA0243A1 | C35: WHT | D35: 20 | E35: 80 | F35: XT0291:3 | G35: FG&E CTRL
... A62: AT0175:1P1 | B62: UV01709 | C62: WHT | D62: 14 | E62: 60 | F62: UV0170:9(+) | G62: FG&E CTRL
A64: FU0172:LD | B64: FU0172 | C64: WHT | D64: 16 | E64: 60 | F64: XT0170:5 | G64: FG&E CTRL | H64: FU
A66: FU0170:LD | B66: FU0170 | C66: WHT | D66: 14 | E66: 60 | F66: XT0171:4 | G66: FG&E CTRL
A67: FU0180:LI | B67: FU0182 | C67: WHT | D67: 14 | E67: 60 | F67: FU0182:LD | G67: FG&E CTRL
A68: FU0170:LI | B68: FU0535 | C68: WHT | D68: 14 | E68: 60 | F68: XT0170:2 | G68: FG&E CTRL
A69: FU0171:LI | B69: FU0535 | C69: WHT | D69: 14 | E69: 60 | F69: XT0170:2 | G69: FG&E CTRL
A70: FU0172:LI | B70: FU0535 | C70: WHT | D70: 14 | E70: 60 | F70: XT0170:1 | G70: FG&E CTRL
A72: FU0294:LI | B72: FU0535 | C72: WHT | D72: 12 | E72: 60 | F72: XT0535:4 | G72: FG&E CTRL
A73: FU0295:LI | B73: FU0535 | C73: WHT | D73: 12 | E73: 60 | F73: XT0535:5 | G73: FG&E CTRL
A74: FU0535:LD | B74: FU0535 | C74: WHT | D74: 12 | E74: 60 | F74: XT0535:1 | G74: FG&E CTRL
...

Sheet GEN_S
A1: GEN CTRL
A3: Project # | B3: 4P101
A4: Project Name | B4: DEPLETION COMPRESSION SYSTEM & SRU
A5: Revision | B5: C
A7: Controls DE
A8: Phone:
A9: Controls ME
A10: Phone:
A12: From | G12: To
A13: Device ID | B13: Wire No. | C13: Wire ID | D13: Gauge/Size | E13: Length | F13: Device ID | G13: Location | H13: Bundle Name
A14: AF0121:COM | B14: -0V | C14: WHT | D14: 16 | E14: 60 | F14: XT0120:2 | G14: GEN | H14: AF/AU120s
A15: AU0120:COM | B15: -0V | C15: WHT | D15: 16 | E15: 60 | F15: XT0120:2 | G15: GEN
A16: AF0122:COM | B16: AU0120N | C16: WHT | D16: 16 | E16: 60 | F16: AU0120:COM | G16: GEN
A17: AF0122:V+ | B17: AU0120P | C17: WHT | D17: 16 | E17: 60 | F17: AU0120:V+ | G17: GEN
A18: AU0120:V+ | B18: FU0120 | C18: WHT | D18: 16 | E18: 60 | F18: FU0120:LD | G18: GEN
A19: AF0121:V+ | B19: FU0121 | C19: WHT | D19: 16 | E19: 60 | F19: FU0121:LD | G19: GEN
A21: AT0140:FLT 29 | B21: KA0310A2 | C21: WHT | D21: 20 | E21: 100 | F21: KA0310:A2 | G21: GEN | H21: AT
A23: AT0140:3 EX-D(-) | B23: -0V | C23: WHT | D23: 16 | E23: 60 | F23: XT0336:6 | G23: GEN
A24: AT0140:BAT(-) 48 | B24: -0V | C24: WHT | D24: 16 | E24: 60 | F24: XT0336:6 | G24: GEN
A25: AT0140:FLT 30 | B25: -0V | C25: WHT | D25: 16 | E25: 60 | F25: XT0336:6 | G25: GEN
A26: AT0140:BAT(+) 47 | B26: FU0334 | C26: WHT | D26: 16 | E26: 60 | F26: XT0339:1 | G26: GEN
A27: AT0140:4 EX-D(+) | B27: KA012314 | C27: WHT | D27: 16 | E27: 100 | F27: KA0123:14 | G27: GEN
A29: AT0140:17 VBUS-A | B29: VBUSA | C29: RED | D29: 16R | E29: 120 | F29: XT0351:2 | G29: GEN | H29: AT RED
A30: AT0140:18 VBUS-B | B30: VBUSB | C30: RED | D30: 16R | E30: 120 | F30: XT0351:3 | G30: GEN
A31: AT0140:19 VBUS-C | B31: VBUSC | C31: RED | D31: 16R | E31: 120 | F31: XT0351:5 | G31: GEN
A32: AT0140:13 VGEN-A | B32: VGENA | C32: RED | D32: 16R | E32: 120 | F32: XT0351:9 | G32: GEN
A33: AT0140:14 VGEN-B | B33: VGENB | C33: RED | D33: 16R | E33: 120 | F33: XT0351:11 | G33: GEN
A34: AT0140:15 VGEN-C | B34: VGENC | C34: RED | D34: 16R | E34: 120 | F34: XT0351:13 | G34: GEN
A36: AT0140:36 I1(+) | B36: MCTA | C36: BLU | D36: 12B | E36: 120 | F36: XT0352:1 | G36: GEN | H36: AT BLU
A37: AT0140:37 I1(-) | B37: MCTAN | C37: BLU | D37: 12B | E37: 120 | F37: XT0352:6 | G37: GEN
A38: AT0140:38 I2(+) | B38: MCTB | C38: BLU | D38: 12B | E38: 120 | F38: XT0352:2 | G38: GEN
A39: AT0140:39 I2(-) | B39: MCTBN | C39: BLU | D39: 12B | E39: 120 | F39: XT0352:5 | G39: GEN
A40: AT0140:40 I3(+) | B40: MCTC | C40: BLU | D40: 12B | E40: 120 | F40: XT0352:3 | G40: GEN
A41: AT0140:41 I3(-) | B41: MCTN | C41: BLU | D41: 12B | E41: 120 | F41: XT0352:4 | G41: GEN
A43: FU0333:LD | B43: FU0333 | C43: WHT | D43: 16 | E43: 60 | F43: XT0338:1 | G43: GEN | H43: FU/XT
A44: FU0334:LD | B44: FU0334 | C44: WHT | D44: 16 | E44: 60 | F44: XT0339:1 | G44: GEN
A46: XT0336:2 | B46: -0V | C46: WHT | D46: 14 | E46: 80 | F46: XT0120:1 | G46: GEN
A47: FU0120:LI | B47: FU0122 | C47: WHT | D47: 14 | E47: 60 | F47: FU0122:LD | G47: GEN
A49: FU0122:LI | B49: FU0332 | C49: WHT | D49: 12 | E49: 80 | F49: XT0335:2 | G49: GEN
A50: FU0332:LD | B50: FU0332 | C50: WHT | D50: 12 | E50: 60 | F50: XT0335:1 | G50: GEN
...

Sheet VFD_S
A1: FO CONV,VFD
A3: Project # | B3: 4P101
A4: Project Name | B4: DEPLETION COMPRESSION SYSTEM & SRU
A5: Revision | B5: C
A7: Controls DE
A8: Phone:
A9: Controls ME
A10: Phone:
A12: From | G12: To
A13: Device ID | B13: Wire No. | C13: Wire ID | D13: Gauge/Size | E13: Length | F13: Device ID | G13: Location | H13: Bundle Name
A14: BA0005:V1(-) | B14: -0V | C14: WHT | D14: 16 | E14: 60 | F14: XT1123:2 | G14: VFD | H14: FU/BA
A15: BA0006:V1(-) | B15: -0V | C15: WHT | D15: 16 | E15: 60 | F15: XT1123:2 | G15: VFD
A16: BA0005:V1(+) | B16: FU1123 | C16: WHT | D16: 16 | E16: 60 | F16: FU1123:LD | G16: VFD
A17: BA0006:V1(+) | B17: FU1124 | C17: WHT | D17: 16 | E17: 60 | F17: FU1124:LD | G17: VFD
A19: FU1123:LI | B19: FU5122 | C19: WHT | D19: 16 | E19: 60 | F19: XT1123:1 | G19: VFD
A20: FU1124:LI | B20: FU5122 | C20: WHT | D20: 16 | E20: 60 | F20: XT1123:1 | G20: VFD

Sheet Bundle Tag Info
A1: KOC-JPF #1
A2: 4P101
A3: C.1
A6: JB70 DOOR | B6: HMI-S PWR | C6: JB70 R RAIL | D6: PLC | E6: A | F6: B | G6: JB72 DOOR | H6: FG&E | I6: GEN | J6: VFD | K6: Panel Name | L6: Panel Name | M6: Panel Name | N6: Panel Name | O6: Panel Name | P6: Panel Name | Q6: Panel Name | R6: Panel Name | S6: Panel Name | T6: Panel Name | U6: Panel Name | V6: Panel Name | W6: Panel Name | X6: Panel Name | Y6: Panel Name | Z6: Panel Name | AA6: Panel Name | AB6: Panel Name | AC6: Panel Name | AD6: Panel Name
A7: AT1100 | B7: BA | C7: XT-HMI | D7: FU/AT | E7: AF | F7: PC | G7: HL0171 | H7: AF/AU180s | I7: AF/AU120s | J7: FU/BA
A8: SA0471 | C8: XT-A | D8: FU/UV-A | E8: FU | F8: AF/AU060s | G8: HL0172 | H8: AT | I8: AT
A9: SA0472 | C9: XT-B | D9: BA-B | E9: KA A1 | F9: AF/AU070s | G9: HL0173 | H9: FU | I9: AT RED
A10: SA0473 | D10: FU/XT-B | E10: KA A2 | F10: AF090s | G10: SA0170 | H10: KA A1 | I10: AT BLU
A11: SB0471 | E11: KA | F11: 1444s | G11: SB0170 | H11: KA A2 | I11: FU/XT
A12: SB0472 | E12: RR | F12: FU | H12: KA | I12: KA A1
A13: SB0473 | E13: UA | F13: KA A1 | H13: RR | I13: KA A2
A14: SB0474 | E14: UJ | F14: KA A2 | H14: UV | I14: KA
A15: SH0470 | E15: XT | F15: KA | H15: VD
A16: SH0471 | E16: FU/AF-B | F16: KT L/S | H16: XT
A17: SH0472 | E17: KA A1-B | F17: KT R/S | H17: KA-GEN
E18: KA A2-B | H18: FU/XT-GEN
E19: KA-B
E20: UA/UJ-B
E21: VD-B
E22: XT-B

Sheet Bundle Tags2
A1: =IF('Bundle Tag Info'!A6<>"Panel Name",'Bundle Tag Info'!A6,"") -> JB70 DOOR | B1: =IF('Bundle Tag Info'!B6<>"Panel Name",'Bundle Tag Info'!B6,"") -> HMI-S PWR | C1: =IF('Bundle Tag Info'!C6<>"Panel Name",'Bundle Tag Info'!C6,"") -> JB70 R RAIL | D1: =IF('Bundle Tag Info'!D6<>"Panel Name",'Bundle Tag Info'!D6,"") -> PLC | E1: =IF('Bundle Tag Info'!E6<>"Panel Name",'Bundle Tag Info'!E6,"") -> A | F1: =IF('Bundle Tag Info'!F6<>"Panel Name",'Bundle Tag Info'!F6,"") -> B | G1: =IF('Bundle Tag Info'!G6<>"Panel Name",'Bundle Tag Info'!G6,"") -> JB72 DOOR | H1: =IF('Bundle Tag Info'!H6<>"Panel Name",'Bundle Tag Info'!H6,"") -> FG&E | ... AD1: =IF('Bundle Tag Info'!AD6<>"Panel Name",'Bundle Tag Info'!AD6,"")
A2: =IF('Bundle Tag Info'!A$7<>"",CONCATENATE('Bundle Tag Info'!$A$1," ",CHAR(10),'Bundle Tag Info'!$A$2," ",'Bundle Tag Info'!$A$3,CHAR(10),'Bundle Tag Info'!A$6,CHAR(10),'Bundle Tag Info'!A$7),"") -> KOC-JPF #1 4P101 C.1 JB70 DOOR AT1100 | B2: =IF('Bundle Tag Info'!B$7<>"",CONCATENATE('Bundle Tag Info'!$A$1," ",CHAR(10),'Bundle Tag Info'!$A$2," ",'Bundle Tag Info'!$A$3,CHAR(10),'Bundle Tag Info'!B$6,CHAR(10),'Bundle Tag Info'!B$7),"") -> KOC-JPF #1 4P101 C.1 HMI-S PWR BA | C2: =IF('Bundle Tag Info'!C$7<>"",CONCATENATE('Bundle Tag Info'!$A$1," ",CHAR(10),'Bundle Tag Info'!$A$2," ",'Bundle Tag Info'!$A$3,CHAR(10),'Bundle Tag Info'!C$6,CHAR(10),'Bundle Tag Info'!C$7),"") -> KOC-JPF #1 4P101 C.1 JB70 R RAIL XT-HMI | D2: =IF('Bundle Tag Info'!D$7<>"",CONCATENATE('Bundle Tag Info'!$A$1," ",CHAR(10),'Bundle Tag Info'!$A$2," ",'Bundle Tag Info'!$A$3,CHAR(10),'Bundle Tag Info'!D$6,CHAR(10),'Bundle Tag Info'!D$7),"") -> KOC-JPF #1 4P101 C.1 PLC FU/AT | E2: =IF('Bundle Tag Info'!E$7<>"",CONCATENATE('Bundle Tag Info'!$A$1," ",CHAR(10),'Bundle Tag Info'!$A$2," ",'Bundle Tag Info'!$A$3,CHAR(10),'Bundle Tag Info'!E$6,CHAR(10),'Bundle Tag Info'!E$7),"") -> KOC-JPF #1 4P101 C.1 A AF | F2: =IF('Bundle Tag Info'!F$7<>"",CONCATENATE('Bundle Tag Info'!$A$1," ",CHAR(10),'Bundle Tag Info'!$A$2," ",'Bundle Tag Info'!$A$3,CHAR(10),'Bundle Tag Info'!F$6,CHAR(10),'Bundle Tag Info'!F$7),"") -> KOC-JPF #1 4P101 C.1 B PC | G2: =IF('Bundle Tag Info'!G$7<>"",CONCATENATE('Bundle Tag Info'!$A$1," ",CHAR(10),'Bundle Tag Info'!$A$2," ",'Bundle Tag Info'!$A$3,CHAR(10),'Bundle Tag Info'!G$6,CHAR(10),'Bundle Tag Info'!G$7),"") -> KOC-JPF #1 4P101 C.1 JB72 DOOR HL0171 | H2: =IF('Bundle Tag Info'!H$7<>"",CONCATENATE('Bundle Tag Info'!$A$1," ",CHAR(10),'Bundle Tag Info'!$A$2," ",'Bundle Tag Info'!$A$3,CHAR(10),'Bundle Tag Info'!H$6,CHAR(10),'Bundle Tag Info'!H$7),"") -> KOC-JPF #1 4P101 C.1 FG&E AF/AU180s | ... AD2: =IF('Bundle Tag Info'!AD$7<>"",CONCATENATE('Bundle Tag Info'!$A$1," ",CHAR(10),'Bundle Tag Info'!$A$2," ",'Bundle Tag Info'!$A$3,CHAR(10),'Bundle Tag Info'!AD$6,CHAR(10),'Bundle Tag Info'!AD$7),"")
A3: =IF('Bundle Tag Info'!A$8<>"",CONCATENATE('Bundle Tag Info'!$A$1," ",CHAR(10),'Bundle Tag Info'!$A$2," ",'Bundle Tag Info'!$A$3,CHAR(10),'Bundle Tag Info'!A$6,CHAR(10),'Bundle Tag Info'!A$8),"") -> KOC-JPF #1 4P101 C.1 JB70 DOOR SA0471 | B3: =IF('Bundle Tag Info'!B$8<>"",CONCATENATE('Bundle Tag Info'!$A$1," ",CHAR(10),'Bundle Tag Info'!$A$2," ",'Bundle Tag Info'!$A$3,CHAR(10),'Bundle Tag Info'!B$6,CHAR(10),'Bundle Tag Info'!B$8),"") | C3: =IF('Bundle Tag Info'!C$8<>"",CONCATENATE('Bundle Tag Info'!$A$1," ",CHAR(10),'Bundle Tag Info'!$A$2," ",'Bundle Tag Info'!$A$3,CHAR(10),'Bundle Tag Info'!C$6,CHAR(10),'Bundle Tag Info'!C$8),"") -> KOC-JPF #1 4P101 C.1 JB70 R RAIL XT-A | D3: =IF('Bundle Tag Info'!D$8<>"",CONCATENATE('Bundle Tag Info'!$A$1," ",CHAR(10),'Bundle Tag Info'!$A$2," ",'Bundle Tag Info'!$A$3,CHAR(10),'Bundle Tag Info'!D$6,CHAR(10),'Bundle Tag Info'!D$8),"") -> KOC-JPF #1 4P101 C.1 PLC FU/UV-A | E3: =IF('Bundle Tag Info'!E$8<>"",CONCATENATE('Bundle Tag Info'!$A$1," ",CHAR(10),'Bundle Tag Info'!$A$2," ",'Bundle Tag Info'!$A$3,CHAR(10),'Bundle Tag Info'!E$6,CHAR(10),'Bundle Tag Info'!E$8),"") -> KOC-JPF #1 4P101 C.1 A FU | F3: =IF('Bundle Tag Info'!F$8<>"",CONCATENATE('Bundle Tag Info'!$A$1," ",CHAR(10),'Bundle Tag Info'!$A$2," ",'Bundle Tag Info'!$A$3,CHAR(10),'Bundle Tag Info'!F$6,CHAR(10),'Bundle Tag Info'!F$8),"") -> KOC-JPF #1 4P101 C.1 B AF/AU060s | G3: =IF('Bundle Tag Info'!G$8<>"",CONCATENATE('Bundle Tag Info'!$A$1," ",CHAR(10),'Bundle Tag Info'!$A$2," ",'Bundle Tag Info'!$A$3,CHAR(10),'Bundle Tag Info'!G$6,CHAR(10),'Bundle Tag Info'!G$8),"") -> KOC-JPF #1 4P101 C.1 JB72 DOOR HL0172 | H3: =IF('Bundle Tag Info'!H$8<>"",CONCATENATE('Bundle Tag Info'!$A$1," ",CHAR(10),'Bundle Tag Info'!$A$2," ",'Bundle Tag Info'!$A$3,CHAR(10),'Bundle Tag Info'!H$6,CHAR(10),'Bundle Tag Info'!H$8),"") -> KOC-JPF #1 4P101 C.1 FG&E AT | ... AD3: =IF('Bundle Tag Info'!AD$8<>"",CONCATENATE('Bundle Tag Info'!$A$1," ",CHAR(10),'Bundle Tag Info'!$A$2," ",'Bundle Tag Info'!$A$3,CHAR(10),'Bundle Tag Info'!AD$6,CHAR(10),'Bundle Tag Info'!AD$8),"")
A4: =IF('Bundle Tag Info'!A$9<>"",CONCATENATE('Bundle Tag Info'!$A$1," ",CHAR(10),'Bundle Tag Info'!$A$2," ",'Bundle Tag Info'!$A$3,CHAR(10),'Bundle Tag Info'!A$6,CHAR(10),'Bundle Tag Info'!A$9),"") -> KOC-JPF #1 4P101 C.1 JB70 DOOR SA0472 | B4: =IF('Bundle Tag Info'!B$9<>"",CONCATENATE('Bundle Tag Info'!$A$1," ",CHAR(10),'Bundle Tag Info'!$A$2," ",'Bundle Tag Info'!$A$3,CHAR(10),'Bundle Tag Info'!B$6,CHAR(10),'Bundle Tag Info'!B$9),"") | C4: =IF('Bundle Tag Info'!C$9<>"",CONCATENATE('Bundle Tag Info'!$A$1," ",CHAR(10),'Bundle Tag Info'!$A$2," ",'Bundle Tag Info'!$A$3,CHAR(10),'Bundle Tag Info'!C$6,CHAR(10),'Bundle Tag Info'!C$9),"") -> KOC-JPF #1 4P101 C.1 JB70 R RAIL XT-B | D4: =IF('Bundle Tag Info'!D$9<>"",CONCATENATE('Bundle Tag Info'!$A$1," ",CHAR(10),'Bundle Tag Info'!$A$2," ",'Bundle Tag Info'!$A$3,CHAR(10),'Bundle Tag Info'!D$6,CHAR(10),'Bundle Tag Info'!D$9),"") -> KOC-JPF #1 4P101 C.1 PLC BA-B | E4: =IF('Bundle Tag Info'!E$9<>"",CONCATENATE('Bundle Tag Info'!$A$1," ",CHAR(10),'Bundle Tag Info'!$A$2," ",'Bundle Tag Info'!$A$3,CHAR(10),'Bundle Tag Info'!E$6,CHAR(10),'Bundle Tag Info'!E$9),"") -> KOC-JPF #1 4P101 C.1 A KA A1 | F4: =IF('Bundle Tag Info'!F$9<>"",CONCATENATE('Bundle Tag Info'!$A$1," ",CHAR(10),'Bundle Tag Info'!$A$2," ",'Bundle Tag Info'!$A$3,CHAR(10),'Bundle Tag Info'!F$6,CHAR(10),'Bundle Tag Info'!F$9),"") -> KOC-JPF #1 4P101 C.1 B AF/AU070s | G4: =IF('Bundle Tag Info'!G$9<>"",CONCATENATE('Bundle Tag Info'!$A$1," ",CHAR(10),'Bundle Tag Info'!$A$2," ",'Bundle Tag Info'!$A$3,CHAR(10),'Bundle Tag Info'!G$6,CHAR(10),'Bundle Tag Info'!G$9),"") -> KOC-JPF #1 4P101 C.1 JB72 DOOR HL0173 | H4: =IF('Bundle Tag Info'!H$9<>"",CONCATENATE('Bundle Tag Info'!$A$1," ",CHAR(10),'Bundle Tag Info'!$A$2," ",'Bundle Tag Info'!$A$3,CHAR(10),'Bundle Tag Info'!H$6,CHAR(10),'Bundle Tag Info'!H$9),"") -> KOC-JPF #1 4P101 C.1 FG&E FU | ... AD4: =IF('Bundle Tag Info'!AD$9<>"",CONCATENATE('Bundle Tag Info'!$A$1," ",CHAR(10),'Bundle Tag Info'!$A$2," ",'Bundle Tag Info'!$A$3,CHAR(10),'Bundle Tag Info'!AD$6,CHAR(10),'Bundle Tag Info'!AD$9),"")
A5: =IF('Bundle Tag Info'!A$10<>"",CONCATENATE('Bundle Tag Info'!$A$1," ",CHAR(10),'Bundle Tag Info'!$A$2," ",'Bundle Tag Info'!$A$3,CHAR(10),'Bundle Tag Info'!A$6,CHAR(10),'Bundle Tag Info'!A$10),"") -> KOC-JPF #1 4P101 C.1 JB70 DOOR SA0473 | B5: =IF('Bundle Tag Info'!B$10<>"",CONCATENATE('Bundle Tag Info'!$A$1," ",CHAR(10),'Bundle Tag Info'!$A$2," ",'Bundle Tag Info'!$A$3,CHAR(10),'Bundle Tag Info'!B$6,CHAR(10),'Bundle Tag Info'!B$10),"") | C5: =IF('Bundle Tag Info'!C$10<>"",CONCATENATE('Bundle Tag Info'!$A$1," ",CHAR(10),'Bundle Tag Info'!$A$2," ",'Bundle Tag Info'!$A$3,CHAR(10),'Bundle Tag Info'!C$6,CHAR(10),'Bundle Tag Info'!C$10),"") | D5: =IF('Bundle Tag Info'!D$10<>"",CONCATENATE('Bundle Tag Info'!$A$1," ",CHAR(10),'Bundle Tag Info'!$A$2," ",'Bundle Tag Info'!$A$3,CHAR(10),'Bundle Tag Info'!D$6,CHAR(10),'Bundle Tag Info'!D$10),"") -> KOC-JPF #1 4P101 C.1 PLC FU/XT-B | E5: =IF('Bundle Tag Info'!E$10<>"",CONCATENATE('Bundle Tag Info'!$A$1," ",CHAR(10),'Bundle Tag Info'!$A$2," ",'Bundle Tag Info'!$A$3,CHAR(10),'Bundle Tag Info'!E$6,CHAR(10),'Bundle Tag Info'!E$10),"") -> KOC-JPF #1 4P101 C.1 A KA A2 | F5: =IF('Bundle Tag Info'!F$10<>"",CONCATENATE('Bundle Tag Info'!$A$1," ",CHAR(10),'Bundle Tag Info'!$A$2," ",'Bundle Tag Info'!$A$3,CHAR(10),'Bundle Tag Info'!F$6,CHAR(10),'Bundle Tag Info'!F$10),"") -> KOC-JPF #1 4P101 C.1 B AF090s | G5: =IF('Bundle Tag Info'!G$10<>"",CONCATENATE('Bundle Tag Info'!$A$1," ",CHAR(10),'Bundle Tag Info'!$A$2," ",'Bundle Tag Info'!$A$3,CHAR(10),'Bundle Tag Info'!G$6,CHAR(10),'Bundle Tag Info'!G$10),"") -> KOC-JPF #1 4P101 C.1 JB72 DOOR SA0170 | H5: =IF('Bundle Tag Info'!H$10<>"",CONCATENATE('Bundle Tag Info'!$A$1," ",CHAR(10),'Bundle Tag Info'!$A$2," ",'Bundle Tag Info'!$A$3,CHAR(10),'Bundle Tag Info'!H$6,CHAR(10),'Bundle Tag Info'!H$10),"") -> KOC-JPF #1 4P101 C.1 FG&E KA A1 | ... AD5: =IF('Bundle Tag Info'!AD$10<>"",CONCATENATE('Bundle Tag Info'!$A$1," ",CHAR(10),'Bundle Tag Info'!$A$2," ",'Bundle Tag Info'!$A$3,CHAR(10),'Bundle Tag Info'!AD$6,CHAR(10),'Bundle Tag Info'!AD$10),"")
A6: =IF('Bundle Tag Info'!A$11<>"",CONCATENATE('Bundle Tag Info'!$A$1," ",CHAR(10),'Bundle Tag Info'!$A$2," ",'Bundle Tag Info'!$A$3,CHAR(10),'Bundle Tag Info'!A$6,CHAR(10),'Bundle Tag Info'!A$11),"") -> KOC-JPF #1 4P101 C.1 JB70 DOOR SB0471 | B6: =IF('Bundle Tag Info'!B$11<>"",CONCATENATE('Bundle Tag Info'!$A$1," ",CHAR(10),'Bundle Tag Info'!$A$2," ",'Bundle Tag Info'!$A$3,CHAR(10),'Bundle Tag Info'!B$6,CHAR(10),'Bundle Tag Info'!B$11),"") | C6: =IF('Bundle Tag Info'!C$11<>"",CONCATENATE('Bundle Tag Info'!$A$1," ",CHAR(10),'Bundle Tag Info'!$A$2," ",'Bundle Tag Info'!$A$3,CHAR(10),'Bundle Tag Info'!C$6,CHAR(10),'Bundle Tag Info'!C$11),"") | D6: =IF('Bundle Tag Info'!D$11<>"",CONCATENATE('Bundle Tag Info'!$A$1," ",CHAR(10),'Bundle Tag Info'!$A$2," ",'Bundle Tag Info'!$A$3,CHAR(10),'Bundle Tag Info'!D$6,CHAR(10),'Bundle Tag Info'!D$11),"") | E6: =IF('Bundle Tag Info'!E$11<>"",CONCATENATE('Bundle Tag Info'!$A$1," ",CHAR(10),'Bundle Tag Info'!$A$2," ",'Bundle Tag Info'!$A$3,CHAR(10),'Bundle Tag Info'!E$6,CHAR(10),'Bundle Tag Info'!E$11),"") -> KOC-JPF #1 4P101 C.1 A KA | F6: =IF('Bundle Tag Info'!F$11<>"",CONCATENATE('Bundle Tag Info'!$A$1," ",CHAR(10),'Bundle Tag Info'!$A$2," ",'Bundle Tag Info'!$A$3,CHAR(10),'Bundle Tag Info'!F$6,CHAR(10),'Bundle Tag Info'!F$11),"") -> KOC-JPF #1 4P101 C.1 B 1444s | G6: =IF('Bundle Tag Info'!G$11<>"",CONCATENATE('Bundle Tag Info'!$A$1," ",CHAR(10),'Bundle Tag Info'!$A$2," ",'Bundle Tag Info'!$A$3,CHAR(10),'Bundle Tag Info'!G$6,CHAR(10),'Bundle Tag Info'!G$11),"") -> KOC-JPF #1 4P101 C.1 JB72 DOOR SB0170 | H6: =IF('Bundle Tag Info'!H$11<>"",CONCATENATE('Bundle Tag Info'!$A$1," ",CHAR(10),'Bundle Tag Info'!$A$2," ",'Bundle Tag Info'!$A$3,CHAR(10),'Bundle Tag Info'!H$6,CHAR(10),'Bundle Tag Info'!H$11),"") -> KOC-JPF #1 4P101 C.1 FG&E KA A2 | ... AD6: =IF('Bundle Tag Info'!AD$11<>"",CONCATENATE('Bundle Tag Info'!$A$1," ",CHAR(10),'Bundle Tag Info'!$A$2," ",'Bundle Tag Info'!$A$3,CHAR(10),'Bundle Tag Info'!AD$6,CHAR(10),'Bundle Tag Info'!AD$11),"")
A7: =IF('Bundle Tag Info'!A$12<>"",CONCATENATE('Bundle Tag Info'!$A$1," ",CHAR(10),'Bundle Tag Info'!$A$2," ",'Bundle Tag Info'!$A$3,CHAR(10),'Bundle Tag Info'!A$6,CHAR(10),'Bundle Tag Info'!A$12),"") -> KOC-JPF #1 4P101 C.1 JB70 DOOR SB0472 | B7: =IF('Bundle Tag Info'!B$12<>"",CONCATENATE('Bundle Tag Info'!$A$1," ",CHAR(10),'Bundle Tag Info'!$A$2," ",'Bundle Tag Info'!$A$3,CHAR(10),'Bundle Tag Info'!B$6,CHAR(10),'Bundle Tag Info'!B$12),"") | C7: =IF('Bundle Tag Info'!C$12<>"",CONCATENATE('Bundle Tag Info'!$A$1," ",CHAR(10),'Bundle Tag Info'!$A$2," ",'Bundle Tag Info'!$A$3,CHAR(10),'Bundle Tag Info'!C$6,CHAR(10),'Bundle Tag Info'!C$12),"") | D7: =IF('Bundle Tag Info'!D$12<>"",CONCATENATE('Bundle Tag Info'!$A$1," ",CHAR(10),'Bundle Tag Info'!$A$2," ",'Bundle Tag Info'!$A$3,CHAR(10),'Bundle Tag Info'!D$6,CHAR(10),'Bundle Tag Info'!D$12),"") | E7: =IF('Bundle Tag Info'!E$12<>"",CONCATENATE('Bundle Tag Info'!$A$1," ",CHAR(10),'Bundle Tag Info'!$A$2," ",'Bundle Tag Info'!$A$3,CHAR(10),'Bundle Tag Info'!E$6,CHAR(10),'Bundle Tag Info'!E$12),"") -> KOC-JPF #1 4P101 C.1 A RR | F7: =IF('Bundle Tag Info'!F$12<>"",CONCATENATE('Bundle Tag Info'!$A$1," ",CHAR(10),'Bundle Tag Info'!$A$2," ",'Bundle Tag Info'!$A$3,CHAR(10),'Bundle Tag Info'!F$6,CHAR(10),'Bundle Tag Info'!F$12),"") -> KOC-JPF #1 4P101 C.1 B FU | G7: =IF('Bundle Tag Info'!G$12<>"",CONCATENATE('Bundle Tag Info'!$A$1," ",CHAR(10),'Bundle Tag Info'!$A$2," ",'Bundle Tag Info'!$A$3,CHAR(10),'Bundle Tag Info'!G$6,CHAR(10),'Bundle Tag Info'!G$12),"") | H7: =IF('Bundle Tag Info'!H$12<>"",CONCATENATE('Bundle Tag Info'!$A$1," ",CHAR(10),'Bundle Tag Info'!$A$2," ",'Bundle Tag Info'!$A$3,CHAR(10),'Bundle Tag Info'!H$6,CHAR(10),'Bundle Tag Info'!H$12),"") -> KOC-JPF #1 4P101 C.1 FG&E KA | ... AD7: =IF('Bundle Tag Info'!AD$12<>"",CONCATENATE('Bundle Tag Info'!$A$1," ",CHAR(10),'Bundle Tag Info'!$A$2," ",'Bundle Tag Info'!$A$3,CHAR(10),'Bundle Tag Info'!AD$6,CHAR(10),'Bundle Tag Info'!AD$12),"")
A8: =IF('Bundle Tag Info'!A$13<>"",CONCATENATE('Bundle Tag Info'!$A$1," ",CHAR(10),'Bundle Tag Info'!$A$2," ",'Bundle Tag Info'!$A$3,CHAR(10),'Bundle Tag Info'!A$6,CHAR(10),'Bundle Tag Info'!A$13),"") -> KOC-JPF #1 4P101 C.1 JB70 DOOR SB0473 | B8: =IF('Bundle Tag Info'!B$13<>"",CONCATENATE('Bundle Tag Info'!$A$1," ",CHAR(10),'Bundle Tag Info'!$A$2," ",'Bundle Tag Info'!$A$3,CHAR(10),'Bundle Tag Info'!B$6,CHAR(10),'Bundle Tag Info'!B$13),"") | C8: =IF('Bundle Tag Info'!C$13<>"",CONCATENATE('Bundle Tag Info'!$A$1," ",CHAR(10),'Bundle Tag Info'!$A$2," ",'Bundle Tag Info'!$A$3,CHAR(10),'Bundle Tag Info'!C$6,CHAR(10),'Bundle Tag Info'!C$13),"") | D8: =IF('Bundle Tag Info'!D$13<>"",CONCATENATE('Bundle Tag Info'!$A$1," ",CHAR(10),'Bundle Tag Info'!$A$2," ",'Bundle Tag Info'!$A$3,CHAR(10),'Bundle Tag Info'!D$6,CHAR(10),'Bundle Tag Info'!D$13),"") | E8: =IF('Bundle Tag Info'!E$13<>"",CONCATENATE('Bundle Tag Info'!$A$1," ",CHAR(10),'Bundle Tag Info'!$A$2," ",'Bundle Tag Info'!$A$3,CHAR(10),'Bundle Tag Info'!E$6,CHAR(10),'Bundle Tag Info'!E$13),"") -> KOC-JPF #1 4P101 C.1 A UA | F8: =IF('Bundle Tag Info'!F$13<>"",CONCATENATE('Bundle Tag Info'!$A$1," ",CHAR(10),'Bundle Tag Info'!$A$2," ",'Bundle Tag Info'!$A$3,CHAR(10),'Bundle Tag Info'!F$6,CHAR(10),'Bundle Tag Info'!F$13),"") -> KOC-JPF #1 4P101 C.1 B KA A1 | G8: =IF('Bundle Tag Info'!G$13<>"",CONCATENATE('Bundle Tag Info'!$A$1," ",CHAR(10),'Bundle Tag Info'!$A$2," ",'Bundle Tag Info'!$A$3,CHAR(10),'Bundle Tag Info'!G$6,CHAR(10),'Bundle Tag Info'!G$13),"") | H8: =IF('Bundle Tag Info'!H$13<>"",CONCATENATE('Bundle Tag Info'!$A$1," ",CHAR(10),'Bundle Tag Info'!$A$2," ",'Bundle Tag Info'!$A$3,CHAR(10),'Bundle Tag Info'!H$6,CHAR(10),'Bundle Tag Info'!H$13),"") -> KOC-JPF #1 4P101 C.1 FG&E RR | ... AD8: =IF('Bundle Tag Info'!AD$13<>"",CONCATENATE('Bundle Tag Info'!$A$1," ",CHAR(10),'Bundle Tag Info'!$A$2," ",'Bundle Tag Info'!$A$3,CHAR(10),'Bundle Tag Info'!AD$6,CHAR(10),'Bundle Tag Info'!AD$13),"")
A9: =IF('Bundle Tag Info'!A$14<>"",CONCATENATE('Bundle Tag Info'!$A$1," ",CHAR(10),'Bundle Tag Info'!$A$2," ",'Bundle Tag Info'!$A$3,CHAR(10),'Bundle Tag Info'!A$6,CHAR(10),'Bundle Tag Info'!A$14),"") -> KOC-JPF #1 4P101 C.1 JB70 DOOR SB0474 | B9: =IF('Bundle Tag Info'!B$14<>"",CONCATENATE('Bundle Tag Info'!$A$1," ",CHAR(10),'Bundle Tag Info'!$A$2," ",'Bundle Tag Info'!$A$3,CHAR(10),'Bundle Tag Info'!B$6,CHAR(10),'Bundle Tag Info'!B$14),"") | C9: =IF('Bundle Tag Info'!C$14<>"",CONCATENATE('Bundle Tag Info'!$A$1," ",CHAR(10),'Bundle Tag Info'!$A$2," ",'Bundle Tag Info'!$A$3,CHAR(10),'Bundle Tag Info'!C$6,CHAR(10),'Bundle Tag Info'!C$14),"") | D9: =IF('Bundle Tag Info'!D$14<>"",CONCATENATE('Bundle Tag Info'!$A$1," ",CHAR(10),'Bundle Tag Info'!$A$2," ",'Bundle Tag Info'!$A$3,CHAR(10),'Bundle Tag Info'!D$6,CHAR(10),'Bundle Tag Info'!D$14),"") | E9: =IF('Bundle Tag Info'!E$14<>"",CONCATENATE('Bundle Tag Info'!$A$1," ",CHAR(10),'Bundle Tag Info'!$A$2," ",'Bundle Tag Info'!$A$3,CHAR(10),'Bundle Tag Info'!E$6,CHAR(10),'Bundle Tag Info'!E$14),"") -> KOC-JPF #1 4P101 C.1 A UJ | F9: =IF('Bundle Tag Info'!F$14<>"",CONCATENATE('Bundle Tag Info'!$A$1," ",CHAR(10),'Bundle Tag Info'!$A$2," ",'Bundle Tag Info'!$A$3,CHAR(10),'Bundle Tag Info'!F$6,CHAR(10),'Bundle Tag Info'!F$14),"") -> KOC-JPF #1 4P101 C.1 B KA A2 | G9: =IF('Bundle Tag Info'!G$14<>"",CONCATENATE('Bundle Tag Info'!$A$1," ",CHAR(10),'Bundle Tag Info'!$A$2," ",'Bundle Tag Info'!$A$3,CHAR(10),'Bundle Tag Info'!G$6,CHAR(10),'Bundle Tag Info'!G$14),"") | H9: =IF('Bundle Tag Info'!H$14<>"",CONCATENATE('Bundle Tag Info'!$A$1," ",CHAR(10),'Bundle Tag Info'!$A$2," ",'Bundle Tag Info'!$A$3,CHAR(10),'Bundle Tag Info'!H$6,CHAR(10),'Bundle Tag Info'!H$14),"") -> KOC-JPF #1 4P101 C.1 FG&E UV | ... AD9: =IF('Bundle Tag Info'!AD$14<>"",CONCATENATE('Bundle Tag Info'!$A$1," ",CHAR(10),'Bundle Tag Info'!$A$2," ",'Bundle Tag Info'!$A$3,CHAR(10),'Bundle Tag Info'!AD$6,CHAR(10),'Bundle Tag Info'!AD$14),"")
A10: =IF('Bundle Tag Info'!A$15<>"",CONCATENATE('Bundle Tag Info'!$A$1," ",CHAR(10),'Bundle Tag Info'!$A$2," ",'Bundle Tag Info'!$A$3,CHAR(10),'Bundle Tag Info'!A$6,CHAR(10),'Bundle Tag Info'!A$15),"") -> KOC-JPF #1 4P101 C.1 JB70 DOOR SH0470 | B10: =IF('Bundle Tag Info'!B$15<>"",CONCATENATE('Bundle Tag Info'!$A$1," ",CHAR(10),'Bundle Tag Info'!$A$2," ",'Bundle Tag Info'!$A$3,CHAR(10),'Bundle Tag Info'!B$6,CHAR(10),'Bundle Tag Info'!B$15),"") | C10: =IF('Bundle Tag Info'!C$15<>"",CONCATENATE('Bundle Tag Info'!$A$1," ",CHAR(10),'Bundle Tag Info'!$A$2," ",'Bundle Tag Info'!$A$3,CHAR(10),'Bundle Tag Info'!C$6,CHAR(10),'Bundle Tag Info'!C$15),"") | D10: =IF('Bundle Tag Info'!D$15<>"",CONCATENATE('Bundle Tag Info'!$A$1," ",CHAR(10),'Bundle Tag Info'!$A$2," ",'Bundle Tag Info'!$A$3,CHAR(10),'Bundle Tag Info'!D$6,CHAR(10),'Bundle Tag Info'!D$15),"") | E10: =IF('Bundle Tag Info'!E$15<>"",CONCATENATE('Bundle Tag Info'!$A$1," ",CHAR(10),'Bundle Tag Info'!$A$2," ",'Bundle Tag Info'!$A$3,CHAR(10),'Bundle Tag Info'!E$6,CHAR(10),'Bundle Tag Info'!E$15),"") -> KOC-JPF #1 4P101 C.1 A XT | F10: =IF('Bundle Tag Info'!F$15<>"",CONCATENATE('Bundle Tag Info'!$A$1," ",CHAR(10),'Bundle Tag Info'!$A$2," ",'Bundle Tag Info'!$A$3,CHAR(10),'Bundle Tag Info'!F$6,CHAR(10),'Bundle Tag Info'!F$15),"") -> KOC-JPF #1 4P101 C.1 B KA | G10: =IF('Bundle Tag Info'!G$15<>"",CONCATENATE('Bundle Tag Info'!$A$1," ",CHAR(10),'Bundle Tag Info'!$A$2," ",'Bundle Tag Info'!$A$3,CHAR(10),'Bundle Tag Info'!G$6,CHAR(10),'Bundle Tag Info'!G$15),"") | H10: =IF('Bundle Tag Info'!H$15<>"",CONCATENATE('Bundle Tag Info'!$A$1," ",CHAR(10),'Bundle Tag Info'!$A$2," ",'Bundle Tag Info'!$A$3,CHAR(10),'Bundle Tag Info'!H$6,CHAR(10),'Bundle Tag Info'!H$15),"") -> KOC-JPF #1 4P101 C.1 FG&E VD | ... AD10: =IF('Bundle Tag Info'!AD$15<>"",CONCATENATE('Bundle Tag Info'!$A$1," ",CHAR(10),'Bundle Tag Info'!$A$2," ",'Bundle Tag Info'!$A$3,CHAR(10),'Bundle Tag Info'!AD$6,CHAR(10),'Bundle Tag Info'!AD$15),"")
A11: =IF('Bundle Tag Info'!A$16<>"",CONCATENATE('Bundle Tag Info'!$A$1," ",CHAR(10),'Bundle Tag Info'!$A$2," ",'Bundle Tag Info'!$A$3,CHAR(10),'Bundle Tag Info'!A$6,CHAR(10),'Bundle Tag Info'!A$16),"") -> KOC-JPF #1 4P101 C.1 JB70 DOOR SH0471 | B11: =IF('Bundle Tag Info'!B$16<>"",CONCATENATE('Bundle Tag Info'!$A$1," ",CHAR(10),'Bundle Tag Info'!$A$2," ",'Bundle Tag Info'!$A$3,CHAR(10),'Bundle Tag Info'!B$6,CHAR(10),'Bundle Tag Info'!B$16),"") | C11: =IF('Bundle Tag Info'!C$16<>"",CONCATENATE('Bundle Tag Info'!$A$1," ",CHAR(10),'Bundle Tag Info'!$A$2," ",'Bundle Tag Info'!$A$3,CHAR(10),'Bundle Tag Info'!C$6,CHAR(10),'Bundle Tag Info'!C$16),"") | D11: =IF('Bundle Tag Info'!D$16<>"",CONCATENATE('Bundle Tag Info'!$A$1," ",CHAR(10),'Bundle Tag Info'!$A$2," ",'Bundle Tag Info'!$A$3,CHAR(10),'Bundle Tag Info'!D$6,CHAR(10),'Bundle Tag Info'!D$16),"") | E11: =IF('Bundle Tag Info'!E$16<>"",CONCATENATE('Bundle Tag Info'!$A$1," ",CHAR(10),'Bundle Tag Info'!$A$2," ",'Bundle Tag Info'!$A$3,CHAR(10),'Bundle Tag Info'!E$6,CHAR(10),'Bundle Tag Info'!E$16),"") -> KOC-JPF #1 4P101 C.1 A FU/AF-B | F11: =IF('Bundle Tag Info'!F$16<>"",CONCATENATE('Bundle Tag Info'!$A$1," ",CHAR(10),'Bundle Tag Info'!$A$2," ",'Bundle Tag Info'!$A$3,CHAR(10),'Bundle Tag Info'!F$6,CHAR(10),'Bundle Tag Info'!F$16),"") -> KOC-JPF #1 4P101 C.1 B KT L/S | G11: =IF('Bundle Tag Info'!G$16<>"",CONCATENATE('Bundle Tag Info'!$A$1," ",CHAR(10),'Bundle Tag Info'!$A$2," ",'Bundle Tag Info'!$A$3,CHAR(10),'Bundle Tag Info'!G$6,CHAR(10),'Bundle Tag Info'!G$16),"") | H11: =IF('Bundle Tag Info'!H$16<>"",CONCATENATE('Bundle Tag Info'!$A$1," ",CHAR(10),'Bundle Tag Info'!$A$2," ",'Bundle Tag Info'!$A$3,CHAR(10),'Bundle Tag Info'!H$6,CHAR(10),'Bundle Tag Info'!H$16),"") -> KOC-JPF #1 4P101 C.1 FG&E XT | ... AD11: =IF('Bundle Tag Info'!AD$16<>"",CONCATENATE('Bundle Tag Info'!$A$1," ",CHAR(10),'Bundle Tag Info'!$A$2," ",'Bundle Tag Info'!$A$3,CHAR(10),'Bundle Tag Info'!AD$6,CHAR(10),'Bundle Tag Info'!AD$16),"")
A12: =IF('Bundle Tag Info'!A$17<>"",CONCATENATE('Bundle Tag Info'!$A$1," ",CHAR(10),'Bundle Tag Info'!$A$2," ",'Bundle Tag Info'!$A$3,CHAR(10),'Bundle Tag Info'!A$6,CHAR(10),'Bundle Tag Info'!A$17),"") -> KOC-JPF #1 4P101 C.1 JB70 DOOR SH0472 | B12: =IF('Bundle Tag Info'!B$17<>"",CONCATENATE('Bundle Tag Info'!$A$1," ",CHAR(10),'Bundle Tag Info'!$A$2," ",'Bundle Tag Info'!$A$3,CHAR(10),'Bundle Tag Info'!B$6,CHAR(10),'Bundle Tag Info'!B$17),"") | C12: =IF('Bundle Tag Info'!C$17<>"",CONCATENATE('Bundle Tag Info'!$A$1," ",CHAR(10),'Bundle Tag Info'!$A$2," ",'Bundle Tag Info'!$A$3,CHAR(10),'Bundle Tag Info'!C$6,CHAR(10),'Bundle Tag Info'!C$17),"") | D12: =IF('Bundle Tag Info'!D$17<>"",CONCATENATE('Bundle Tag Info'!$A$1," ",CHAR(10),'Bundle Tag Info'!$A$2," ",'Bundle Tag Info'!$A$3,CHAR(10),'Bundle Tag Info'!D$6,CHAR(10),'Bundle Tag Info'!D$17),"") | E12: =IF('Bundle Tag Info'!E$17<>"",CONCATENATE('Bundle Tag Info'!$A$1," ",CHAR(10),'Bundle Tag Info'!$A$2," ",'Bundle Tag Info'!$A$3,CHAR(10),'Bundle Tag Info'!E$6,CHAR(10),'Bundle Tag Info'!E$17),"") -> KOC-JPF #1 4P101 C.1 A KA A1-B | F12: =IF('Bundle Tag Info'!F$17<>"",CONCATENATE('Bundle Tag Info'!$A$1," ",CHAR(10),'Bundle Tag Info'!$A$2," ",'Bundle Tag Info'!$A$3,CHAR(10),'Bundle Tag Info'!F$6,CHAR(10),'Bundle Tag Info'!F$17),"") -> KOC-JPF #1 4P101 C.1 B KT R/S | G12: =IF('Bundle Tag Info'!G$17<>"",CONCATENATE('Bundle Tag Info'!$A$1," ",CHAR(10),'Bundle Tag Info'!$A$2," ",'Bundle Tag Info'!$A$3,CHAR(10),'Bundle Tag Info'!G$6,CHAR(10),'Bundle Tag Info'!G$17),"") | H12: =IF('Bundle Tag Info'!H$17<>"",CONCATENATE('Bundle Tag Info'!$A$1," ",CHAR(10),'Bundle Tag Info'!$A$2," ",'Bundle Tag Info'!$A$3,CHAR(10),'Bundle Tag Info'!H$6,CHAR(10),'Bundle Tag Info'!H$17),"") -> KOC-JPF #1 4P101 C.1 FG&E KA-GEN | ... AD12: =IF('Bundle Tag Info'!AD$17<>"",CONCATENATE('Bundle Tag Info'!$A$1," ",CHAR(10),'Bundle Tag Info'!$A$2," ",'Bundle Tag Info'!$A$3,CHAR(10),'Bundle Tag Info'!AD$6,CHAR(10),'Bundle Tag Info'!AD$17),"")
A13: =IF('Bundle Tag Info'!A$18<>"",CONCATENATE('Bundle Tag Info'!$A$1," ",CHAR(10),'Bundle Tag Info'!$A$2," ",'Bundle Tag Info'!$A$3,CHAR(10),'Bundle Tag Info'!A$6,CHAR(10),'Bundle Tag Info'!A$18),"") | B13: =IF('Bundle Tag Info'!B$18<>"",CONCATENATE('Bundle Tag Info'!$A$1," ",CHAR(10),'Bundle Tag Info'!$A$2," ",'Bundle Tag Info'!$A$3,CHAR(10),'Bundle Tag Info'!B$6,CHAR(10),'Bundle Tag Info'!B$18),"") | C13: =IF('Bundle Tag Info'!C$18<>"",CONCATENATE('Bundle Tag Info'!$A$1," ",CHAR(10),'Bundle Tag Info'!$A$2," ",'Bundle Tag Info'!$A$3,CHAR(10),'Bundle Tag Info'!C$6,CHAR(10),'Bundle Tag Info'!C$18),"") | D13: =IF('Bundle Tag Info'!D$18<>"",CONCATENATE('Bundle Tag Info'!$A$1," ",CHAR(10),'Bundle Tag Info'!$A$2," ",'Bundle Tag Info'!$A$3,CHAR(10),'Bundle Tag Info'!D$6,CHAR(10),'Bundle Tag Info'!D$18),"") | E13: =IF('Bundle Tag Info'!E$18<>"",CONCATENATE('Bundle Tag Info'!$A$1," ",CHAR(10),'Bundle Tag Info'!$A$2," ",'Bundle Tag Info'!$A$3,CHAR(10),'Bundle Tag Info'!E$6,CHAR(10),'Bundle Tag Info'!E$18),"") -> KOC-JPF #1 4P101 C.1 A KA A2-B | F13: =IF('Bundle Tag Info'!F$18<>"",CONCATENATE('Bundle Tag Info'!$A$1," ",CHAR(10),'Bundle Tag Info'!$A$2," ",'Bundle Tag Info'!$A$3,CHAR(10),'Bundle Tag Info'!F$6,CHAR(10),'Bundle Tag Info'!F$18),"") | G13: =IF('Bundle Tag Info'!G$18<>"",CONCATENATE('Bundle Tag Info'!$A$1," ",CHAR(10),'Bundle Tag Info'!$A$2," ",'Bundle Tag Info'!$A$3,CHAR(10),'Bundle Tag Info'!G$6,CHAR(10),'Bundle Tag Info'!G$18),"") | H13: =IF('Bundle Tag Info'!H$18<>"",CONCATENATE('Bundle Tag Info'!$A$1," ",CHAR(10),'Bundle Tag Info'!$A$2," ",'Bundle Tag Info'!$A$3,CHAR(10),'Bundle Tag Info'!H$6,CHAR(10),'Bundle Tag Info'!H$18),"") -> KOC-JPF #1 4P101 C.1 FG&E FU/XT-GEN | ... AD13: =IF('Bundle Tag Info'!AD$18<>"",CONCATENATE('Bundle Tag Info'!$A$1," ",CHAR(10),'Bundle Tag Info'!$A$2," ",'Bundle Tag Info'!$A$3,CHAR(10),'Bundle Tag Info'!AD$6,CHAR(10),'Bundle Tag Info'!AD$18),"")
A14: =IF('Bundle Tag Info'!A$19<>"",CONCATENATE('Bundle Tag Info'!$A$1," ",CHAR(10),'Bundle Tag Info'!$A$2," ",'Bundle Tag Info'!$A$3,CHAR(10),'Bundle Tag Info'!A$6,CHAR(10),'Bundle Tag Info'!A$19),"") | B14: =IF('Bundle Tag Info'!B$19<>"",CONCATENATE('Bundle Tag Info'!$A$1," ",CHAR(10),'Bundle Tag Info'!$A$2," ",'Bundle Tag Info'!$A$3,CHAR(10),'Bundle Tag Info'!B$6,CHAR(10),'Bundle Tag Info'!B$19),"") | C14: =IF('Bundle Tag Info'!C$19<>"",CONCATENATE('Bundle Tag Info'!$A$1," ",CHAR(10),'Bundle Tag Info'!$A$2," ",'Bundle Tag Info'!$A$3,CHAR(10),'Bundle Tag Info'!C$6,CHAR(10),'Bundle Tag Info'!C$19),"") | D14: =IF('Bundle Tag Info'!D$19<>"",CONCATENATE('Bundle Tag Info'!$A$1," ",CHAR(10),'Bundle Tag Info'!$A$2," ",'Bundle Tag Info'!$A$3,CHAR(10),'Bundle Tag Info'!D$6,CHAR(10),'Bundle Tag Info'!D$19),"") | E14: =IF('Bundle Tag Info'!E$19<>"",CONCATENATE('Bundle Tag Info'!$A$1," ",CHAR(10),'Bundle Tag Info'!$A$2," ",'Bundle Tag Info'!$A$3,CHAR(10),'Bundle Tag Info'!E$6,CHAR(10),'Bundle Tag Info'!E$19),"") -> KOC-JPF #1 4P101 C.1 A KA-B | F14: =IF('Bundle Tag Info'!F$19<>"",CONCATENATE('Bundle Tag Info'!$A$1," ",CHAR(10),'Bundle Tag Info'!$A$2," ",'Bundle Tag Info'!$A$3,CHAR(10),'Bundle Tag Info'!F$6,CHAR(10),'Bundle Tag Info'!F$19),"") | G14: =IF('Bundle Tag Info'!G$19<>"",CONCATENATE('Bundle Tag Info'!$A$1," ",CHAR(10),'Bundle Tag Info'!$A$2," ",'Bundle Tag Info'!$A$3,CHAR(10),'Bundle Tag Info'!G$6,CHAR(10),'Bundle Tag Info'!G$19),"") | H14: =IF('Bundle Tag Info'!H$19<>"",CONCATENATE('Bundle Tag Info'!$A$1," ",CHAR(10),'Bundle Tag Info'!$A$2," ",'Bundle Tag Info'!$A$3,CHAR(10),'Bundle Tag Info'!H$6,CHAR(10),'Bundle Tag Info'!H$19),"") | ... AD14: =IF('Bundle Tag Info'!AD$19<>"",CONCATENATE('Bundle Tag Info'!$A$1," ",CHAR(10),'Bundle Tag Info'!$A$2," ",'Bundle Tag Info'!$A$3,CHAR(10),'Bundle Tag Info'!AD$6,CHAR(10),'Bundle Tag Info'!AD$19),"")
A15: =IF('Bundle Tag Info'!A$20<>"",CONCATENATE('Bundle Tag Info'!$A$1," ",CHAR(10),'Bundle Tag Info'!$A$2," ",'Bundle Tag Info'!$A$3,CHAR(10),'Bundle Tag Info'!A$6,CHAR(10),'Bundle Tag Info'!A$20),"") | B15: =IF('Bundle Tag Info'!B$20<>"",CONCATENATE('Bundle Tag Info'!$A$1," ",CHAR(10),'Bundle Tag Info'!$A$2," ",'Bundle Tag Info'!$A$3,CHAR(10),'Bundle Tag Info'!B$6,CHAR(10),'Bundle Tag Info'!B$20),"") | C15: =IF('Bundle Tag Info'!C$20<>"",CONCATENATE('Bundle Tag Info'!$A$1," ",CHAR(10),'Bundle Tag Info'!$A$2," ",'Bundle Tag Info'!$A$3,CHAR(10),'Bundle Tag Info'!C$6,CHAR(10),'Bundle Tag Info'!C$20),"") | D15: =IF('Bundle Tag Info'!D$20<>"",CONCATENATE('Bundle Tag Info'!$A$1," ",CHAR(10),'Bundle Tag Info'!$A$2," ",'Bundle Tag Info'!$A$3,CHAR(10),'Bundle Tag Info'!D$6,CHAR(10),'Bundle Tag Info'!D$20),"") | E15: =IF('Bundle Tag Info'!E$20<>"",CONCATENATE('Bundle Tag Info'!$A$1," ",CHAR(10),'Bundle Tag Info'!$A$2," ",'Bundle Tag Info'!$A$3,CHAR(10),'Bundle Tag Info'!E$6,CHAR(10),'Bundle Tag Info'!E$20),"") -> KOC-JPF #1 4P101 C.1 A UA/UJ-B | F15: =IF('Bundle Tag Info'!F$20<>"",CONCATENATE('Bundle Tag Info'!$A$1," ",CHAR(10),'Bundle Tag Info'!$A$2," ",'Bundle Tag Info'!$A$3,CHAR(10),'Bundle Tag Info'!F$6,CHAR(10),'Bundle Tag Info'!F$20),"") | G15: =IF('Bundle Tag Info'!G$20<>"",CONCATENATE('Bundle Tag Info'!$A$1," ",CHAR(10),'Bundle Tag Info'!$A$2," ",'Bundle Tag Info'!$A$3,CHAR(10),'Bundle Tag Info'!G$6,CHAR(10),'Bundle Tag Info'!G$20),"") | H15: =IF('Bundle Tag Info'!H$20<>"",CONCATENATE('Bundle Tag Info'!$A$1," ",CHAR(10),'Bundle Tag Info'!$A$2," ",'Bundle Tag Info'!$A$3,CHAR(10),'Bundle Tag Info'!H$6,CHAR(10),'Bundle Tag Info'!H$20),"") | ... AD15: =IF('Bundle Tag Info'!AD$20<>"",CONCATENATE('Bundle Tag Info'!$A$1," ",CHAR(10),'Bundle Tag Info'!$A$2," ",'Bundle Tag Info'!$A$3,CHAR(10),'Bundle Tag Info'!AD$6,CHAR(10),'Bundle Tag Info'!AD$20),"")
A16: =IF('Bundle Tag Info'!A$21<>"",CONCATENATE('Bundle Tag Info'!$A$1," ",CHAR(10),'Bundle Tag Info'!$A$2," ",'Bundle Tag Info'!$A$3,CHAR(10),'Bundle Tag Info'!A$6,CHAR(10),'Bundle Tag Info'!A$21),"") | B16: =IF('Bundle Tag Info'!B$21<>"",CONCATENATE('Bundle Tag Info'!$A$1," ",CHAR(10),'Bundle Tag Info'!$A$2," ",'Bundle Tag Info'!$A$3,CHAR(10),'Bundle Tag Info'!B$6,CHAR(10),'Bundle Tag Info'!B$21),"") | C16: =IF('Bundle Tag Info'!C$21<>"",CONCATENATE('Bundle Tag Info'!$A$1," ",CHAR(10),'Bundle Tag Info'!$A$2," ",'Bundle Tag Info'!$A$3,CHAR(10),'Bundle Tag Info'!C$6,CHAR(10),'Bundle Tag Info'!C$21),"") | D16: =IF('Bundle Tag Info'!D$21<>"",CONCATENATE('Bundle Tag Info'!$A$1," ",CHAR(10),'Bundle Tag Info'!$A$2," ",'Bundle Tag Info'!$A$3,CHAR(10),'Bundle Tag Info'!D$6,CHAR(10),'Bundle Tag Info'!D$21),"") | E16: =IF('Bundle Tag Info'!E$21<>"",CONCATENATE('Bundle Tag Info'!$A$1," ",CHAR(10),'Bundle Tag Info'!$A$2," ",'Bundle Tag Info'!$A$3,CHAR(10),'Bundle Tag Info'!E$6,CHAR(10),'Bundle Tag Info'!E$21),"") -> KOC-JPF #1 4P101 C.1 A VD-B | F16: =IF('Bundle Tag Info'!F$21<>"",CONCATENATE('Bundle Tag Info'!$A$1," ",CHAR(10),'Bundle Tag Info'!$A$2," ",'Bundle Tag Info'!$A$3,CHAR(10),'Bundle Tag Info'!F$6,CHAR(10),'Bundle Tag Info'!F$21),"") | G16: =IF('Bundle Tag Info'!G$21<>"",CONCATENATE('Bundle Tag Info'!$A$1," ",CHAR(10),'Bundle Tag Info'!$A$2," ",'Bundle Tag Info'!$A$3,CHAR(10),'Bundle Tag Info'!G$6,CHAR(10),'Bundle Tag Info'!G$21),"") | H16: =IF('Bundle Tag Info'!H$21<>"",CONCATENATE('Bundle Tag Info'!$A$1," ",CHAR(10),'Bundle Tag Info'!$A$2," ",'Bundle Tag Info'!$A$3,CHAR(10),'Bundle Tag Info'!H$6,CHAR(10),'Bundle Tag Info'!H$21),"") | ... AD16: =IF('Bundle Tag Info'!AD$21<>"",CONCATENATE('Bundle Tag Info'!$A$1," ",CHAR(10),'Bundle Tag Info'!$A$2," ",'Bundle Tag Info'!$A$3,CHAR(10),'Bundle Tag Info'!AD$6,CHAR(10),'Bundle Tag Info'!AD$21),"")
A17: =IF('Bundle Tag Info'!A$22<>"",CONCATENATE('Bundle Tag Info'!$A$1," ",CHAR(10),'Bundle Tag Info'!$A$2," ",'Bundle Tag Info'!$A$3,CHAR(10),'Bundle Tag Info'!A$6,CHAR(10),'Bundle Tag Info'!A$22),"") | B17: =IF('Bundle Tag Info'!B$22<>"",CONCATENATE('Bundle Tag Info'!$A$1," ",CHAR(10),'Bundle Tag Info'!$A$2," ",'Bundle Tag Info'!$A$3,CHAR(10),'Bundle Tag Info'!B$6,CHAR(10),'Bundle Tag Info'!B$22),"") | C17: =IF('Bundle Tag Info'!C$22<>"",CONCATENATE('Bundle Tag Info'!$A$1," ",CHAR(10),'Bundle Tag Info'!$A$2," ",'Bundle Tag Info'!$A$3,CHAR(10),'Bundle Tag Info'!C$6,CHAR(10),'Bundle Tag Info'!C$22),"") | D17: =IF('Bundle Tag Info'!D$22<>"",CONCATENATE('Bundle Tag Info'!$A$1," ",CHAR(10),'Bundle Tag Info'!$A$2," ",'Bundle Tag Info'!$A$3,CHAR(10),'Bundle Tag Info'!D$6,CHAR(10),'Bundle Tag Info'!D$22),"") | E17: =IF('Bundle Tag Info'!E$22<>"",CONCATENATE('Bundle Tag Info'!$A$1," ",CHAR(10),'Bundle Tag Info'!$A$2," ",'Bundle Tag Info'!$A$3,CHAR(10),'Bundle Tag Info'!E$6,CHAR(10),'Bundle Tag Info'!E$22),"") -> KOC-JPF #1 4P101 C.1 A XT-B | F17: =IF('Bundle Tag Info'!F$22<>"",CONCATENATE('Bundle Tag Info'!$A$1," ",CHAR(10),'Bundle Tag Info'!$A$2," ",'Bundle Tag Info'!$A$3,CHAR(10),'Bundle Tag Info'!F$6,CHAR(10),'Bundle Tag Info'!F$22),"") | G17: =IF('Bundle Tag Info'!G$22<>"",CONCATENATE('Bundle Tag Info'!$A$1," ",CHAR(10),'Bundle Tag Info'!$A$2," ",'Bundle Tag Info'!$A$3,CHAR(10),'Bundle Tag Info'!G$6,CHAR(10),'Bundle Tag Info'!G$22),"") | H17: =IF('Bundle Tag Info'!H$22<>"",CONCATENATE('Bundle Tag Info'!$A$1," ",CHAR(10),'Bundle Tag Info'!$A$2," ",'Bundle Tag Info'!$A$3,CHAR(10),'Bundle Tag Info'!H$6,CHAR(10),'Bundle Tag Info'!H$22),"") | ... AD17: =IF('Bundle Tag Info'!AD$22<>"",CONCATENATE('Bundle Tag Info'!$A$1," ",CHAR(10),'Bundle Tag Info'!$A$2," ",'Bundle Tag Info'!$A$3,CHAR(10),'Bundle Tag Info'!AD$6,CHAR(10),'Bundle Tag Info'!AD$22),"")
A18: =IF('Bundle Tag Info'!A$23<>"",CONCATENATE('Bundle Tag Info'!$A$1," ",CHAR(10),'Bundle Tag Info'!$A$2," ",'Bundle Tag Info'!$A$3,CHAR(10),'Bundle Tag Info'!A$6,CHAR(10),'Bundle Tag Info'!A$23),"") | B18: =IF('Bundle Tag Info'!B$23<>"",CONCATENATE('Bundle Tag Info'!$A$1," ",CHAR(10),'Bundle Tag Info'!$A$2," ",'Bundle Tag Info'!$A$3,CHAR(10),'Bundle Tag Info'!B$6,CHAR(10),'Bundle Tag Info'!B$23),"") | C18: =IF('Bundle Tag Info'!C$23<>"",CONCATENATE('Bundle Tag Info'!$A$1," ",CHAR(10),'Bundle Tag Info'!$A$2," ",'Bundle Tag Info'!$A$3,CHAR(10),'Bundle Tag Info'!C$6,CHAR(10),'Bundle Tag Info'!C$23),"") | D18: =IF('Bundle Tag Info'!D$23<>"",CONCATENATE('Bundle Tag Info'!$A$1," ",CHAR(10),'Bundle Tag Info'!$A$2," ",'Bundle Tag Info'!$A$3,CHAR(10),'Bundle Tag Info'!D$6,CHAR(10),'Bundle Tag Info'!D$23),"") | E18: =IF('Bundle Tag Info'!E$23<>"",CONCATENATE('Bundle Tag Info'!$A$1," ",CHAR(10),'Bundle Tag Info'!$A$2," ",'Bundle Tag Info'!$A$3,CHAR(10),'Bundle Tag Info'!E$6,CHAR(10),'Bundle Tag Info'!E$23),"") | F18: =IF('Bundle Tag Info'!F$23<>"",CONCATENATE('Bundle Tag Info'!$A$1," ",CHAR(10),'Bundle Tag Info'!$A$2," ",'Bundle Tag Info'!$A$3,CHAR(10),'Bundle Tag Info'!F$6,CHAR(10),'Bundle Tag Info'!F$23),"") | G18: =IF('Bundle Tag Info'!G$23<>"",CONCATENATE('Bundle Tag Info'!$A$1," ",CHAR(10),'Bundle Tag Info'!$A$2," ",'Bundle Tag Info'!$A$3,CHAR(10),'Bundle Tag Info'!G$6,CHAR(10),'Bundle Tag Info'!G$23),"") | H18: =IF('Bundle Tag Info'!H$23<>"",CONCATENATE('Bundle Tag Info'!$A$1," ",CHAR(10),'Bundle Tag Info'!$A$2," ",'Bundle Tag Info'!$A$3,CHAR(10),'Bundle Tag Info'!H$6,CHAR(10),'Bundle Tag Info'!H$23),"") | ... AD18: =IF('Bundle Tag Info'!AD$23<>"",CONCATENATE('Bundle Tag Info'!$A$1," ",CHAR(10),'Bundle Tag Info'!$A$2," ",'Bundle Tag Info'!$A$3,CHAR(10),'Bundle Tag Info'!AD$6,CHAR(10),'Bundle Tag Info'!AD$23),"")
