Workbook

Sheet Blue Labels
A1: (SHT 1) CONSOLE | B1: (SHT 10) REDUNDANT POWER PANEL | C1: (SHT 11) PLC PANEL | D1: (SHT 12) PANEL A | E1: (SHT 13) PANEL B | F1: (SHT 14) SURGE NON-I.S. PANEL | G1: (SHT 15) GENERATOR PANEL | H1: (SHT 16) ISOLATOR #1 PANEL | I1: (SHT 17) ISOLATOR #2 PANEL | J1: (SHT 18) BLANK PANEL | K1: (SHT 19) METER PANEL | L1: (SHT 2) TCP | M1: (SHT 20) SWITCH PANEL | N1: (SHT 21) CONSOLE HEATER LIGHT | O1: (SHT 22) BN3500^DOOR PANEL | P1: (SHT 23) BECKWITH #1 | Q1: (SHT 24) BECKWITH #2 | R1: (SHT 25) JB70 | S1: (SHT 26) JB70 LEFT RAIL | T1: (SHT 27) JB70 RIGHT RAIL | U1: (SHT 28) JB70 | V1: (SHT 29) JB70 DOOR HEATER PANEL | W1: (SHT 3) CONSOLE | X1: (SHT 31) JB72 | Y1: (SHT 32) JB72 DOOR HEATER PANEL | Z1: (SHT 33) JB5 | AA1: (SHT 35) LIQUID FUEL BOX | AB1: (SHT 36) FIRE SYS POWER | AC1: (SHT 37) 3-BAY FAN DOOR PANEL | AD1: (SHT 38) 1-BAY FAN DOOR PANEL | AE1: (SHT 5) PWR DISTRIBUTION RAIL | AF1: (SHT 6) FIRE SYSTEM CONTROLLER PANEL | AG1: (SHT 7) HEATER PANEL | AH1: (SHT 8) FIRE SYSTEM | AI1: (SHT 9) VIBRATION PANEL
A2: EL0273 | B2: UJ0031 | C2: UV0600 | D2: FU0080 | E2: XT0240 | F2: FU0460 | G2: AT0140 | H2: EA0741 | I2: EA0760 | J2: GR0140 | K2: PA0771 | L2: HL0411 | M2: HL0704 | N2: HL0750 | O2: AP0625 | P2: RM0460 | Q2: RM0462 | R2: HL0171 | S2: KA7000 | T2: XTFGB | U2: IEG1100 | V2: TS7000 | W2: AT0190K | X2: XTA0831 | Y2: H7200 | Z2: XT0824 | AA2: IEG0051 | AB2: UV0171 | AC2: EF0256 | AD2: EF0258 | AE2: FU0680 | AF2: UV0170 | AG2: QS0750 | AH2: FU0170 | AI2: AF0450
A3: EL0271 | B3: EA0031 | C3: AT0600 | D3: FU0081 | E3: FU0070 | F3: FU0462 | G3: AT0220 | H3: EA0742 | I3: EA0761 | J3: GR0031 | K3: PV0701 | L3: HL0410 | M3: HL0703 | O3: AP0624 | R3: HL0172 | S3: FU7000 | T3: GR1100 | U3: AP1100 | V3: H7000 | W3: AT0190 | X3: XTA0832 | Y3: TS7200 | Z3: UA1520 | AA3: PC0471 | AB3: KA0150 | AC3: EF0257 | AD3: EF0259 | AE3: XT0680 | AF3: AT0170 | AG3: H07500 | AH3: FU0171 | AI3: XT0400
A4: EL0270 | B4: QS0031 | C4: AP0601 | D4: XT0080 | E4: AU0070 | F4: FU0120 | G4: TM0102 | H4: EA0743 | I4: EA0762 | K4: PA0701 | L4: HL0409 | M4: HL0702 | O4: AP0622 | R4: HL0173 | S4: XT7000 | U4: XT0001 | V4: XT7001 | W4: AC0201 | X4: XT1008 | Y4: XT7201 | Z4: XT1521 | AA4: FU0018 | AB4: KA0151 | AC4: FU0256 | AD4: FU0275 | AE4: XT0563 | AF4: KA0172 | AG4: GR0750 | AH4: FU0172 | AI4: IEG0130
A5: HA0273 | B5: XT0031 | C5: AP0602 | D5: XT0085 | E5: AF0070 | F5: FU0121 | G5: VD0121 | H5: EA0744 | I5: EA0763 | K5: PF0701 | L5: HL0408 | M5: HL0701 | O5: AP0623 | R5: SA0170 | S5: XTFGA | U5: XT1005 | V5: GR0700 | X5: KA7200 | Y5: GR0701 | Z5: XTFGH | AA5: FU0020 | AB5: KA0152 | AC5: FU0257 | AD5: FU0276 | AE5: FU0560 | AF5: KA0174 | AG5: XT0750 | AH5: KA6510 | AI5: XT0130
A6: ZS0273 | B6: GR0030 | C6: AP0603 | D6: AU0080 | E6: AF0071 | F6: FU0332 | G6: VD0122 | H6: EA0745 | I6: EA0764 | K6: PA0703 | L6: HL0407 | M6: SA0770 | O6: AP0621 | R6: SB0170 | S6: GR1101 | U6: GR1232 | X6: FU7200 | Z6: GR1150 | AA6: FU0019 | AB6: KA0153 | AC6: XT0238 | AD6: XT7202 | AE6: XT0560 | AF6: KA0176 | AG6: XT0751 | AH6: KA6511 | AI6: XT0180
A7: ZS0271 | B7: FU0110 | C7: AP0604 | D7: AF0080 | E7: AF0072 | F7: FU0333 | G7: VD0123 | H7: EA0746 | I7: EA0765 | K7: PV0700 | L7: SB0400 | M7: SA0710 | O7: AP0620 | R7: HA0472 | U7: GR1235 | X7: XT7200 | Z7: UA1210 | AA7: FU0021 | AB7: GR0173 | AE7: XT0561 | AF7: KA0177 | AG7: H07501 | AH7: XT0170 | AI7: FU0180
A8: ZS0270 | B8: FU0111 | C8: AP0605 | D8: AF0081 | E8: AF0073 | F8: FU0334 | G8: VD0124 | H8: EA0747 | I8: EA0766 | K8: PA0700 | L8: HL0406 | M8: SA0740 | O8: AP0619 | R8: SB0472 | U8: XTA0820 | X8: GR4142 | Z8: UA1211 | AA8: FU0022 | AE8: FU0200 | AF8: XT0171 | AG8: GR0751 | AH8: XT0172 | AI8: FU0181
A9: FG0001 | B9: FU0113 | C9: AP0606 | D9: AF0082 | E9: AF0074 | F9: FU0335 | G9: RS0106 | H9: EA0750 | I9: EA0767 | L9: HL0405 | M9: PF0700 | O9: AP0618 | U9: XTA0823 | X9: FU0317 | Z9: UA1220 | AA9: FU0023 | AE9: FU0190 | AF9: GR0171 | AG9: TS0750 | AH9: GR0170 | AI9: FU0182
A10: FG0002 | B10: FU0114 | C10: AP0607 | D10: AF0083 | E10: AF0075 | F10: FU0336 | G10: KA0185 | H10: EA0751 | I10: EA0837 | L10: HL0404 | M10: SA0700 | O10: AP0617 | U10: XT0821 | X10: FU0318 | Z10: UA1221 | AA10: FU0024 | AE10: FU0273 | AH10: AT0175 | AI10: KA0200
B11: FU0150 | C11: AP0608 | D11: AF0084 | E11: AF0076 | F11: XT0362 | G11: KA0310 | H11: EA0752 | I11: EA1230 | L11: HL0403 | M11: KA0460 | O11: AP0616 | U11: XT1004 | X11: FU0319 | Z11: UA1230 | AA11: FU0025 | AE11: XT0562 | AH11: AT0177 | AI11: KA0201
B12: XT0110 | C12: AP0609 | D12: AF0085 | E12: FU0103 | F12: XT0120 | G12: KA0320 | H12: EA0753 | I12: EA0845 | L12: HL0402 | M12: KA0462 | O12: AP0615 | U12: XTA0824 | X12: XT0833 | Z12: UA1231 | AA12: KA0505 | AE12: FU0271 | AH12: AT0179 | AI12: KA0202
B13: XT0033 | C13: UV0700 | D13: AF0086 | E13: FU0104 | F13: XT0332 | G13: KA0329 | H13: EA0754 | I13: EA3510 | L13: HL0401 | M13: SA0701 | O13: AP0614 | U13: GR1233 | X13: XT0835 | Z13: UA1262 | AA13: XT0050 | AH13: GR0172 | AI13: KA0203
B14: FU0031 | C14: AT0700 | D14: AF0087 | E14: FU0105 | F14: XT0460 | G14: KA0330 | H14: EA00755 | I14: EA3520 | L14: HL0400 | O14: AP0613 | U14: IEG1200 | X14: XT1009 | Z14: UA1263 | AA14: XT0700 | AI14: KA0204
B15: XT1000 | C15: AP0701 | D15: BA0680 | E15: BA0015 | F15: XT0461 | G15: KA0331 | H15: EA00756 | I15: EA3540 | L15: SH0412 | O15: AP0612 | U15: XTA0815 | X15: XT0836 | Z15: UA1273 | AA15: XTA0700 | AI15: KA0205
B16: XT1001 | C16: AP0702 | D16: FU0681 | E16: BA0016 | F16: XT0462 | G16: KA0332 | H16: EA00757 | I16: EA0830 | L16: SH0411 | O16: AP0611 | U16: XTA0803 | X16: XTFGC | Z16: UA1241 | AA16: GR0050 | AI16: KA0206
B17: GR0110 | C17: AP0703 | D17: GR0134 | E17: BA0017 | F17: XT1002 | G17: KA0333 | H17: EA6121 | I17: EA0831 | L17: SH0405 | O17: UV0610 | U17: XTA0805 | X17: GR4141 | Z17: UA1240 | AA17: IEG0050 | AI17: KA0207
B18: IEG0110 | C18: AP0704 | D18: AU0090 | E18: GR0233 | F18: GR0291 | G18: KA0335 | H18: EA6122 | I18: EA0835 | L18: SH0404 | O18: UV0611 | U18: XTA0807 | X18: GR4181 | Z18: UA1251 | AA18: AU0050 | AI18: KA0208
C19: AP0705 | D19: AF0090 | E19: KA0235 | F19: EA0600 | G19: KA0336 | H19: EA6123 | I19: EA0836 | L19: SA0400 | O19: AR0610 | U19: XTA0813 | Z19: UA1250 | AA19: AF0050 | AI19: GR0181
C20: AP0706 | D20: AF0091 | E20: KA0236 | F20: EA0601 | G20: KA0358 | H20: EA6141 | I20: EA0840 | L20: SH0410 | U20: XT1007 | Z20: UA1272 | AA20: AF0051 | AI20: IEG0180
C21: AP0707 | D21: AF0092 | E21: KA0237 | F21: EA0602 | G21: KA0359 | H21: EA6142 | I21: EA0870 | L21: SH0409 | U21: GR1134 | Z21: GR1110 | AA21: AF0052 | AI21: AU0180
C22: AP0708 | D22: AF0093 | E22: KA0238 | F22: EA0603 | G22: KA0121 | H22: EA6143 | I22: EA0841 | L22: SH0401 | U22: XT0811 | AA22: AF0053 | AI22: AF0180
C23: AP0709 | D23: AF0094 | E23: KA0239 | F23: EA0604 | G23: KA0123 | H23: EA6144 | I23: EA0842 | L23: SH0400 | U23: XT0814 | AA23: AF0054 | AI23: AF0181
C24: AP0290 | D24: AF0095 | E24: KA0240 | F24: EA0605 | G24: KA0126 | H24: EA6151 | I24: EA0843 | L24: XT0564 | U24: XT0815 | AA24: AF0055 | AI24: AF0182
C25: UV0800 | D25: KA4360 | E25: KA0248 | F25: EA0606 | G25: KA0128 | H25: EA6152 | I25: EA0844 | L25: AU0200 | U25: RR0175A | AA25: AF0056 | AI25: AF0183
C26: AP0800 | D26: KA4361 | E26: KA0250 | F26: EA0607 | G26: KA4203 | H26: EA6153 | I26: EA0846 | L26: AF0200 | U26: RR0175I | AA26: GR0051 | AI26: AF0184
C27: AP0801 | D27: KA4362 | E27: KA0241 | F27: EA0620 | G27: KA4204 | H27: EA6154 | I27: EA4210 | L27: AF0201 | U27: RR0175D | AI27: AF0185
C28: AP0802 | D28: KA9599 | E28: KA0242 | F28: EA0622 | G28: AF0123 | H28: EA6161 | I28: EA4213 | L28: AF0202 | U28: RR0175M | AI28: GR0180
C29: AP0803 | D29: KA0610 | E29: KA0243 | F29: EA0623 | G29: AF0122 | H29: EA6162 | I29: EA4216 | L29: SB0408 | U29: VD0175A
C30: AP0804 | D30: XT7003 | E30: KA0244 | F30: EA0624 | G30: AF0121 | H30: EA6171 | I30: EA4230 | L30: SB0407 | U30: VD0175I
C31: AP0805 | D31: KA0135 | E31: KA0246 | F31: EA0625 | G31: AF0120 | H31: EA6172 | I31: EA4240 | L31: SH0408 | U31: VD0175D
C32: AP0806 | D32: KA3103 | E32: KA0247 | F32: EA0626 | G32: AU0120 | H32: EA6221 | I32: EA4250 | L32: SB0405 | U32: GR1133
C33: AP0808 | D33: KA3220 | E33: KA0245 | F33: EA0627 | G33: XT1003 | H33: EA6181 | I33: EA4251 | L33: SB0406 | U33: XT0800
C34: AP0809 | D34: KA3221 | E34: KA0249 | F34: EA0630 | G34: GR0120 | H34: EA6182 | I34: EA1220 | L34: SA0401 | U34: XT0801
C35: AR0600 | D35: KA6211 | E35: KA0231 | F35: EA0631 | G35: XT0334 | H35: EA6183 | I35: GR0275 | L35: SB0404 | U35: XT0802
C36: AR0700 | D36: KA6212 | E36: KA0232 | F36: EA0632 | G36: XT0335 | H36: EA6184 | I36: UV0272 | L36: SB0403 | U36: XT1006
C37: AR0800 | D37: GR0133 | E37: KA0233 | F37: EA0633 | G37: XT0336 | H37: EA6211 | I37: UAI0760 | L37: SB0402 | U37: XT0804
C38: AP0807 | D38: PC0470 | E38: KA0234 | F38: EA0634 | G38: XT0337 | H38: EA4501 | I38: UAI0761 | L38: SB0401 | U38: GR1132
C39: TE9900 | D39: FU0090 | E39: KA0130 | F39: EA0635 | G39: XT0343 | H39: GR0273 | I39: UAI0762 | L39: GR0200
C40: FU0007 | D40: FU0091 | E40: KA0131 | F40: EA0636 | G40: XT0313 | H40: FU0272 | I40: UAI0763
...

Sheet White Labels
A1: (SHT 23) BECKWITH #1 | B1: (SHT 18) BLANK PANEL | C1: (SHT 22) BN3500^DOOR PANEL - (SHT 13) PANEL B | D1: (SHT 3) CONSOLE - (SHT 7) HEATER PANEL | E1: (SHT 36) FIRE SYS POWER | F1: (SHT 15) GENERATOR PANEL | G1: (SHT 15) GENERATOR PANEL - (SHT 12) PANEL A | H1: (SHT 7) HEATER PANEL | I1: (SHT 16) ISOLATOR #1 PANEL | J1: (SHT 16) ISOLATOR #1 PANEL - (SHT 17) ISOLATOR #2 PANEL | K1: (SHT 16) ISOLATOR #1 PANEL - (SHT 13) PANEL B | L1: (SHT 17) ISOLATOR #2 PANEL - (SHT 9) VIBRATION PANEL | M1: (SHT 28) JB70 | N1: (SHT 29) JB70 DOOR HEATER PANEL | O1: (SHT 31) JB72 | P1: (SHT 31) JB72 - (SHT 32) JB72 DOOR HEATER PANEL | Q1: (SHT 32) JB72 DOOR HEATER PANEL | R1: (SHT 35) LIQUID FUEL BOX | S1: (SHT 35) LIQUID FUEL BOX - (SHT 13) PANEL B | T1: (SHT 12) PANEL A | U1: (SHT 12) PANEL A - (SHT 13) PANEL B | V1: (SHT 13) PANEL B | W1: (SHT 13) PANEL B - (SHT 11) PLC PANEL | X1: (SHT 13) PANEL B - (SHT 10) REDUNDANT POWER PANEL | Y1: (SHT 13) PANEL B - (SHT 2) TCP | Z1: (SHT 13) PANEL B - (SHT 9) VIBRATION PANEL | AA1: (SHT 11) PLC PANEL | AB1: (SHT 11) PLC PANEL - (SHT 10) REDUNDANT POWER PANEL | AC1: (SHT 5) PWR DISTRIBUTION RAIL - (SHT 2) TCP | AD1: (SHT 10) REDUNDANT POWER PANEL | AE1: (SHT 10) REDUNDANT POWER PANEL - (SHT 9) VIBRATION PANEL | AF1: (SHT 9) VIBRATION PANEL
A2: AT0140VGENN | B2: GR0140 | C2: IEG023010 | D2: AC0201G | E2: GR0173 | F2: AT0140G1 | G2: PEG0140G | H2: H07500G | I2: EAG02102 | J2: EAG02104 | K2: IEG0120G | L2: IEG01301 | M2: GR1232 | N2: CCH7000G | O2: GR4141 | P2: CCH7200G | Q2: GR0701 | R2: FT2220S | S2: FCE2228S1 | T2: 0V | U2: IEG023011 | V2: IEG02304 | W2: GR0234 | X2: IEG0110G | Y2: IEG02309 | Z2: IEG0130G | AA2: UV0600G | AB2: IEG01102 | AC2: 0V1 | AD2: EA0031UPG | AE2: IEG01101 | AF2: AF045032
A3: DCTX2N | C3: IEG023013 | F3: EXCS | K3: IEG02300 | L3: IEG01307 | M3: GR1235 | N3: GR0700 | O3: GR4142 | R3: FT2240S | T3: EA0131UPG | U3: IEG02302 | V3: IEG02305 | W3: IEG02301 | AA3: UV0700G | AC3: ESTOPA | AF3: IEG01303
F4: PEG01404 | K4: IEG023014 | M4: IEG12002 | O4: GR4181 | R4: GR0050 | V4: IEG02306 | W4: IEG02307 | AA4: UV0800G | AC4: ESTOPB | AF4: IEG01304
F5: PEG01405 | O5: WC8401 | R5: IEG005113 | V5: IEG0230G | W5: IEG02308 | AC5: FU0139
F6: WC8003 | R6: PDT2201S | AC6: FU0200
F7: WC8004 | R7: PDT2211S | AC7: KA023612
F8: WC8101 | R8: PT2230S | AC8: KA0241A1
F9: WC8102 | R9: PT2240S
F10: WC8103 | R10: PT2645S
F11: WC8104 | R11: PT6402S
F12: WC8201 | R12: TE2645S
F13: WC8202 | R13: UA2611S
F14: WC8203
F15: WC8301

Sheet Heat Shrink Labels
A1: (SHT 22) BN3500^DOOR PANEL - (SHT 16) ISOLATOR #1 PANEL | B1: (SHT 8) FIRE SYSTEM | C1: (SHT 8) FIRE SYSTEM - (SHT 6) FIRE SYSTEM CONTROLLER PANEL | D1: (SHT 15) GENERATOR PANEL | E1: (SHT 15) GENERATOR PANEL - (SHT 17) ISOLATOR #2 PANEL | F1: (SHT 15) GENERATOR PANEL - (SHT 19) METER PANEL | G1: (SHT 16) ISOLATOR #1 PANEL | H1: (SHT 16) ISOLATOR #1 PANEL - (SHT 13) PANEL B | I1: (SHT 16) ISOLATOR #1 PANEL - (SHT 9) VIBRATION PANEL | J1: (SHT 17) ISOLATOR #2 PANEL | K1: (SHT 17) ISOLATOR #2 PANEL - (SHT 12) PANEL A | L1: (SHT 17) ISOLATOR #2 PANEL - (SHT 13) PANEL B | M1: (SHT 12) PANEL A - (SHT 11) PLC PANEL | N1: (SHT 13) PANEL B - (SHT 11) PLC PANEL | O1: (SHT 13) PANEL B - (SHT 14) SURGE NON-I.S. PANEL | P1: (SHT 11) PLC PANEL | Q1: (SHT 11) PLC PANEL - (SHT 14) SURGE NON-I.S. PANEL | R1: (SHT 14) SURGE NON-I.S. PANEL - (SHT 9) VIBRATION PANEL
A2: WC1304 | B2: WC5500 | C2: WC5118 | D2: WC8009 | E2: WC01230 | F2: WC8065 | G2: WC0450 | H2: WC07401 | I2: WC4749 | J2: WC1260 | K2: WC0830 | L2: WC07600 | M2: WC029004 | N2: WC029002 | O2: WC0641 | P2: WTXRX1 | Q2: WC00646 | R2: WC1840
A3: WC1328 | B3: WC8066 | C3: WC8069 | D3: WC8010 | E3: WC2170 | G3: WCI2101 | H3: WC07402 | J3: WC1270 | K3: WC0831 | L3: WC07601 | M3: WC029005 | N3: WC029006 | O3: WC0642 | Q3: WC00651 | R3: WC1841
A4: WC1329 | B4: WC8068 | D4: WC8164 | E4: WC2270 | G4: WCI2102 | H4: WC07403 | J4: WC2180 | K4: WC0835 | L4: WC07602 | M4: WC02901 | N4: WC029007 | O4: WC0711 | Q4: WC00652 | R4: WC1842
A5: WC1330 | D5: WC8165 | E5: WC2370 | G5: WCI2103 | H5: WC07404 | J5: WCI0765 | K5: WC0836 | L5: WC07603 | M5: WC029013 | N5: WC029008 | O5: WC0712 | Q5: WC00653
A6: WC1331 | D6: WC8264 | E6: WC2470 | G6: WCI2201 | H6: WC07405 | J6: WCI0766 | K6: WC0837 | L6: WC07604 | M6: WC029014 | N6: WC029010 | Q6: WC00730
A7: WC1332 | E7: WC2570 | G7: WCI2202 | H7: WC07406 | J7: WCI0767 | K7: WC0839 | L7: WC0765 | M7: WC029015 | N7: WC029011 | Q7: WC00731
A8: WC1333 | E8: WC2670 | G8: WCI2203 | H8: WC0747 | J8: WCI0836 | K8: WC0842 | L8: WC0766 | M8: WC029016 | N8: WC029012 | Q8: WC00732
A9: WC1334 | E9: WC2770 | G9: WCI2301 | H9: WC0750 | J9: WCI0840 | K9: WC0843 | L9: WC0767 | M9: WC029017 | N9: WC029029 | Q9: WC00733
A10: WC1335 | E10: WC2870 | G10: WCI2302 | H10: WC0751 | J10: WCI0841 | K10: WC2126 | M10: WC029018 | N10: WCO29003 | Q10: WC00852
A11: WC1336 | G11: WCI2303 | H11: WC0752 | J11: WCI0842 | K11: WC2127 | M11: WC029019 | Q11: WC00855
A12: WC1337 | G12: WCI2401 | H12: WC0753 | J12: WCI0843 | K12: WC2128 | M12: WC029020 | Q12: WC0650
A13: WC1338 | G13: WCI2402 | H13: WC0754 | J13: WCI0844 | K13: WC2129 | M13: WC029021 | Q13: WC0850
A14: WC1339 | G14: WCI2403 | H14: WC0755 | J14: WCI0846 | K14: WC2156 | M14: WC029022 | Q14: WC0851
A15: WC1340 | G15: WCI6121 | H15: WC0756 | J15: WCI1220 | K15: WC2157 | M15: WC029023 | Q15: WC0853
A16: WC1341 | G16: WCI6122 | H16: WC0757 | J16: WCI2007 | K16: WC2162 | M16: WTE9900 | Q16: WC0854
A17: WC1342 | G17: WCI6123 | J17: WCI2100 | K17: WC2258 | Q17: WC0856
A18: WC1343 | G18: WCI6141 | J18: WCI2110 | Q18: WC0863
A19: WC1344 | G19: WCI6142 | J19: WCI2129 | Q19: WC0867
A20: WC1345 | G20: WCI6143 | J20: WCI2503
A21: WC1346 | G21: WCI6144 | J21: WCI2603
G22: WCI6151 | J22: WCI2703
G23: WCI6152 | J23: WCI2803
G24: WCI6153 | J24: WCI2903
G25: WCI6154 | J25: WCI3510
G26: WCI6161 | J26: WCI3520
G27: WCI6162 | J27: WCI3540
G28: WCI6171 | J28: WCI4210
G29: WCI6172 | J29: WCI4213
G30: WCI6181 | J30: WCI4230
G31: WCI6182 | J31: WCI4240
G32: WCI6183 | J32: WCI4250
G33: WCI6184 | J33: WCI4251
G34: WCI6211 | J34: WCII4216
G35: WCI6221
G36: WCI7555
G37: WCI7556
G38: WCI7557

Sheet 1-BAY FAN DOOR PANEL
A1: 1-BAY FAN DOOR PANEL
A3: Project # | B3: 4H161
A4: Project Name | B4: QATARGAS - NFPS
A5: Revision | B5: D.2
A7: Controls DE | B7: K. NYBERG
A8: Phone: | B8: 0
A9: Controls ME | B9: D. FIGUEROA
A10: Phone:
A12: From | G12: To
A13: Device ID | B13: Cable (W) Conductor (SC) Jumper Clip (JC) | C13: Wire No. | D13: Wire ID | E13: Gauge/Size | F13: Page/Zone | G13: Device ID | H13: Location | I13: Page/Zone
A14: EF0258: | B14: SC | C14: FU0275 | D14: WHT | E14: 14 | F14: 57.C6 | G14: XT7202:1 | H14: 1-BAY FAN DOOR PANEL | I14: 57.C6 | M14: USED
A15: EF0258: | B15: SC | C15: 0V | D15: WHT | E15: 14 | F15: 57.C6 | G15: XT7202:2 | H15: 1-BAY FAN DOOR PANEL | I15: 57.C6 | M15: USED
A16: EF0259: | B16: SC | C16: FU0276 | D16: WHT | E16: 14 | F16: 57.C6 | G16: XT7202:3 | H16: 1-BAY FAN DOOR PANEL | I16: 57.C6 | M16: USED
A17: EF0259: | B17: SC | C17: 0V | D17: WHT | E17: 14 | F17: 57.C6 | G17: XT7202:4 | H17: 1-BAY FAN DOOR PANEL | I17: 57.C6 | M17: USED
A18: FU0275:LD | B18: SC | C18: FU0275 | D18: WHT | E18: 14 | F18: 57.C5 | G18: XT7202:1 | H18: 1-BAY FAN DOOR PANEL | I18: 57.C6 | M18: USED
A19: FU0275:LI | B19: SC | C19: FU0137 | D19: WHT | E19: 14 | F19: 57.C5 | G19: FU0276:LI | H19: 1-BAY FAN DOOR PANEL | I19: 57.C5 | M19: USED
A20: FU0276:LD | B20: SC | C20: FU0276 | D20: WHT | E20: 14 | F20: 57.C5 | G20: XT7202:3 | H20: 1-BAY FAN DOOR PANEL | I20: 57.C6 | M20: USED
A21: XT7202:4 | B21: SC | C21: 0V | D21: WHT | E21: 14 | F21: 57.C6 | G21: XT7202:2 | H21: 1-BAY FAN DOOR PANEL | I21: 57.C6 | M21: USED
A22: FU0275:LI | B22: SC | C22: FU0137 | D22: WHT | E22: 14 | F22: 57.C5 | G22: FU0270:LI | H22: ISOLATOR #1 PANEL | I22: 54.A6 | M22: USED
A23: XT7202:2 | B23: SC | C23: 0V | D23: WHT | E23: 14 | F23: 57.C6 | G23: XT0235:4 | H23: PANEL B | I23: 20.D4 | M23: USED
F25: SolarTools ver. 7.0.17.15318 (Jul 24, 2024)
A26: Report date: 9/13/2024 1:02 PM

Sheet 3-BAY FAN DOOR PANEL
A1: 3-BAY FAN DOOR PANEL
A3: Project # | B3: 4H161
A4: Project Name | B4: QATARGAS - NFPS
A5: Revision | B5: D.2
A7: Controls DE | B7: K. NYBERG
A8: Phone: | B8: 0
A9: Controls ME | B9: D. FIGUEROA
A10: Phone:
A12: From | G12: To
A13: Device ID | B13: Cable (W) Conductor (SC) Jumper Clip (JC) | C13: Wire No. | D13: Wire ID | E13: Gauge/Size | F13: Page/Zone | G13: Device ID | H13: Location | I13: Page/Zone
A14: EF0256: | B14: SC | C14: FU0256 | D14: WHT | E14: 14 | F14: 20.B6 | G14: XT0238:1 | H14: 3-BAY FAN DOOR PANEL | I14: 20.B6 | M14: USED
A15: EF0256: | B15: SC | C15: 0V | D15: WHT | E15: 14 | F15: 20.B6 | G15: XT0238:3 | H15: 3-BAY FAN DOOR PANEL | I15: 20.B6 | M15: USED
A16: EF0257: | B16: SC | C16: FU0257 | D16: WHT | E16: 14 | F16: 20.C6 | G16: XT0238:2 | H16: 3-BAY FAN DOOR PANEL | I16: 20.C6 | M16: USED
A17: EF0257: | B17: SC | C17: 0V | D17: WHT | E17: 14 | F17: 20.C6 | G17: XT0238:4 | H17: 3-BAY FAN DOOR PANEL | I17: 20.C6 | M17: USED
A18: FU0256:LD | B18: SC | C18: FU0256 | D18: WHT | E18: 14 | F18: 20.B5 | G18: XT0238:1 | H18: 3-BAY FAN DOOR PANEL | I18: 20.B6 | M18: USED
A19: FU0257:LD | B19: SC | C19: FU0257 | D19: WHT | E19: 14 | F19: 20.C5 | G19: XT0238:2 | H19: 3-BAY FAN DOOR PANEL | I19: 20.C6 | M19: USED
A20: FU0256:LI | B20: SC | C20: FU0137 | D20: WHT | E20: 12 | F20: 20.B5 | G20: XT0139:2 | H20: PANEL A | I20: 20.A4 | M20: USED
A21: XT0238:3 | B21: SC | C21: 0V | D21: WHT | E21: 14 | F21: 20.B6 | G21: XT0135:2 | H21: PANEL A | I21: 20.B4 | M21: USED
A22: FU0257:LI | B22: SC | C22: FU0210 | D22: WHT | E22: 14 | F22: 20.C5 | G22: FU0212:LI | H22: PANEL B | I22: 20.C5 | M22: USED
A23: XT0238:4 | B23: SC | C23: 0V | D23: WHT | E23: 14 | F23: 20.C6 | G23: XT0235:4 | H23: PANEL B | I23: 20.D4 | M23: USED
F25: SolarTools ver. 7.0.17.15318 (Jul 24, 2024)
A26: Report date: 9/13/2024 1:02 PM

Sheet BECKWITH #1
A1: BECKWITH #1
A3: Project # | B3: 4H161
A4: Project Name | B4: QATARGAS - NFPS
A5: Revision | B5: D.2
A7: Controls DE | B7: K. NYBERG
A8: Phone: | B8: 0
A9: Controls ME | B9: D. FIGUEROA
A10: Phone:
A12: From | G12: To
A13: Device ID | B13: Cable (W) Conductor (SC) Jumper Clip (JC) | C13: Wire No. | D13: Wire ID | E13: Gauge/Size | F13: Page/Zone | G13: Device ID | H13: Location | I13: Page/Zone
A14: RM0460:31 | B14: SC | C14: FU0460 | D14: WHT | E14: 14 | F14: 102.A4 | G14: RM0460:33 | H14: BECKWITH #1 | I14: 102.A4 | M14: USED
A15: RM0460:31 | B15: SC | C15: FU0460 | D15: WHT | E15: 14 | F15: 102.A4 | G15: RM0460:62 | H15: BECKWITH #1 | I15: 102.A4 | M15: USED
A16: RM0460:38 | B16: SC | C16: AT0140VGENN | D16: GRN/YEL | E16: 12 | F16: 105.C7 | G16: RM0460:40 | H16: BECKWITH #1 | I16: 105.C7 | M16: USED
A17: RM0460:40 | B17: SC | C17: AT0140VGENN | D17: GRN/YEL | E17: 12 | F17: 105.C7 | G17: RM0460:42 | H17: BECKWITH #1 | I17: 105.C7 | M17: USED
A18: RM0460:47 | B18: SC | C18: DCTX2N | D18: GRN/YEL | E18: 12 | F18: 104.C7 | G18: RM0460:49 | H18: BECKWITH #1 | I18: 104.C7 | M18: USED
A19: RM0460:49 | B19: SC | C19: DCTX2N | D19: GRN/YEL | E19: 12 | F19: 104.C7 | G19: RM0460:51 | H19: BECKWITH #1 | I19: 104.C7 | M19: USED
A20: RM0460:38 | B20: SC | C20: AT0140VGENN | D20: GRN/YEL | E20: 12 | F20: 105.C7 | G20: XT0463:8 | H20: GENERATOR PANEL | I20: 105.C5 | M20: USED
A21: RM0460:39 | B21: SC | C21: AT0140VGENA | D21: RED | E21: 16 | F21: 105.C7 | G21: XT0463:7 | H21: GENERATOR PANEL | I21: 105.C5 | M21: USED
A22: RM0460:41 | B22: SC | C22: AT0140VGENB | D22: RED | E22: 16 | F22: 105.C7 | G22: XT0463:6 | H22: GENERATOR PANEL | I22: 105.C5 | M22: USED
A23: RM0460:43 | B23: SC | C23: AT0140VGENC | D23: RED | E23: 16 | F23: 105.C7 | G23: XT0463:5 | H23: GENERATOR PANEL | I23: 105.C5 | M23: USED
A24: RM0460:46 | B24: SC | C24: DCTAX1 | D24: BLU | E24: 16 | F24: 104.C7 | G24: XT0463:1 | H24: GENERATOR PANEL | I24: 104.C5 | M24: USED
A25: RM0460:47 | B25: SC | C25: DCTX2N | D25: GRN/YEL | E25: 12 | F25: 104.C7 | G25: XT0463:4 | H25: GENERATOR PANEL | I25: 104.C5 | M25: USED
... A48: RM0460:34 | B48: SC | C48: KA0358A1 | D48: WHT | E48: 20 | F48: 102.A4 | G48: KA0460:12 | H48: SWITCH PANEL | I48: 102.C3 | M48: USED
F50: SolarTools ver. 7.0.17.15318 (Jul 24, 2024)
A51: Report date: 9/13/2024 1:02 PM

Sheet BECKWITH #2
A1: BECKWITH #2
A3: Project # | B3: 4H161
A4: Project Name | B4: QATARGAS - NFPS
A5: Revision | B5: D.2
A7: Controls DE | B7: K. NYBERG
A8: Phone: | B8: 0
A9: Controls ME | B9: D. FIGUEROA
A10: Phone:
A12: From | G12: To
A13: Device ID | B13: Cable (W) Conductor (SC) Jumper Clip (JC) | C13: Wire No. | D13: Wire ID | E13: Gauge/Size | F13: Page/Zone | G13: Device ID | H13: Location | I13: Page/Zone
A14: RM0462:31 | B14: SC | C14: FU0462 | D14: WHT | E14: 14 | F14: 103.A4 | G14: RM0462:33 | H14: BECKWITH #2 | I14: 103.A4 | M14: USED
A15: RM0462:31 | B15: SC | C15: FU0462 | D15: WHT | E15: 14 | F15: 103.A4 | G15: RM0462:62 | H15: BECKWITH #2 | I15: 103.A4 | M15: USED
A16: RM0462:38 | B16: SC | C16: AT0140VGENN | D16: GRN/YEL | E16: 12 | F16: 105.D7 | G16: RM0462:40 | H16: BECKWITH #2 | I16: 105.D7 | M16: USED
A17: RM0462:40 | B17: SC | C17: AT0140VGENN | D17: GRN/YEL | E17: 12 | F17: 105.D7 | G17: RM0462:42 | H17: BECKWITH #2 | I17: 105.D7 | M17: USED
A18: RM0462:47 | B18: SC | C18: DCTX2N | D18: GRN/YEL | E18: 12 | F18: 104.D7 | G18: RM0462:49 | H18: BECKWITH #2 | I18: 104.D7 | M18: USED
A19: RM0462:49 | B19: SC | C19: DCTX2N | D19: GRN/YEL | E19: 12 | F19: 104.D7 | G19: RM0462:51 | H19: BECKWITH #2 | I19: 104.D7 | M19: USED
A20: RM0462:38 | B20: SC | C20: AT0140VGENN | D20: GRN/YEL | E20: 12 | F20: 105.D7 | G20: XT0463:8 | H20: GENERATOR PANEL | I20: 105.C5 | M20: USED
A21: RM0462:39 | B21: SC | C21: AT0140VGENA | D21: RED | E21: 16 | F21: 105.D7 | G21: XT0463:7 | H21: GENERATOR PANEL | I21: 105.C5 | M21: USED
A22: RM0462:41 | B22: SC | C22: AT0140VGENB | D22: RED | E22: 16 | F22: 105.D7 | G22: XT0463:6 | H22: GENERATOR PANEL | I22: 105.C5 | M22: USED
A23: RM0462:43 | B23: SC | C23: AT0140VGENC | D23: RED | E23: 16 | F23: 105.D7 | G23: XT0463:5 | H23: GENERATOR PANEL | I23: 105.C5 | M23: USED
A24: RM0462:46 | B24: SC | C24: DCTAX1 | D24: BLU | E24: 16 | F24: 104.D7 | G24: XT0463:1 | H24: GENERATOR PANEL | I24: 104.C5 | M24: USED
A25: RM0462:47 | B25: SC | C25: DCTX2N | D25: GRN/YEL | E25: 12 | F25: 104.D7 | G25: XT0463:4 | H25: GENERATOR PANEL | I25: 104.C5 | M25: USED
... A48: RM0462:34 | B48: SC | C48: KA0359A1 | D48: WHT | E48: 20 | F48: 103.A4 | G48: KA0462:12 | H48: SWITCH PANEL | I48: 103.C3 | M48: USED
F50: SolarTools ver. 7.0.17.15318 (Jul 24, 2024)
A51: Report date: 9/13/2024 1:02 PM

Sheet BLANK PANEL
A1: BLANK PANEL
A3: Project # | B3: 4H161
A4: Project Name | B4: QATARGAS - NFPS
A5: Revision | B5: D.2
A7: Controls DE | B7: K. NYBERG
A8: Phone: | B8: 0
A9: Controls ME | B9: D. FIGUEROA
A10: Phone:
A12: From | G12: To
A13: Device ID | B13: Cable (W) Conductor (SC) Jumper Clip (JC) | C13: Wire No. | D13: Wire ID | E13: Gauge/Size | F13: Page/Zone | G13: Device ID | H13: Location | I13: Page/Zone
A14: GR0031: | B14: SC | C14: GR0031 | D14: GRN/YEL | E14: 14 | F14: 19.C4 | G14: FRAME | H14: BLANK PANEL | I14: 19.C4 | M14: USED
A15: GR0140: | B15: SC | C15: GR0140 | D15: GRN/YEL | E15: 14 | F15: 4.B4 | G15: FG1126:1 | H15: BLANK PANEL | I15: 4.B4 | M15: USED
F17: SolarTools ver. 7.0.17.15318 (Jul 24, 2024)
A18: Report date: 9/13/2024 1:02 PM

Sheet BN3500^DOOR PANEL
A1: BN3500^DOOR PANEL
A2: CONTROL CONSOLE (BN3500 DOOR PANEL)
A3: Project # | B3: 4H161
A4: Project Name | B4: QATARGAS - NFPS
A5: Revision | B5: D.2
A7: Controls DE | B7: K. NYBERG
A8: Phone: | B8: 0
A9: Controls ME | B9: D. FIGUEROA
A10: Phone:
A12: From | G12: To
A13: Device ID | B13: Cable (W) Conductor (SC) Jumper Clip (JC) | C13: Wire No. | D13: Wire ID | E13: Gauge/Size | F13: Page/Zone | G13: Device ID | H13: Location | I13: Page/Zone
A14: AP0621:SIG1 | B14: WC1304 | C14: UAI62117 | D14: RED | E14: 20 | F14: 81.D7 | G14: UAI6211:7 | H14: ISOLATOR #1 PANEL | I14: 81.D6 | M14: USED
A15: AP0621:COM1 | B15: WC1304 | C15: UAI62118 | D15: BLK | E15: 20 | F15: 81.D7 | G15: UAI6211:8 | H15: ISOLATOR #1 PANEL | I15: 81.D6 | M15: USED
A16: AP0621:SH1 | B16: WC1304 | C16: UAI6211S | D16: SH | E16: 20 | F16: 81.D7 | G16: FLOATING | H16: ISOLATOR #1 PANEL | I16: 81.D6 | M16: USED
A17: AP0622:PWR1 | B17: WC1327 | C17: UAI62217 | D17: RED | E17: 20 | F17: 80.D7 | G17: UAI6221:7- | H17: ISOLATOR #1 PANEL | I17: 80.D6 | M17: USED
A18: AP0622:SIG1 | B18: WC1327 | C18: UAI62218 | D18: BLK | E18: 20 | F18: 80.D7 | G18: UAI6221:8+ | H18: ISOLATOR #1 PANEL | I18: 80.D6 | M18: USED
A19: AP0612:KPHT1 | B19: WC1328 | C19: UAI61217 | D19: RED | E19: 20 | F19: 79.A6 | G19: UAI6121:7 | H19: ISOLATOR #1 PANEL | I19: 79.A6 | M19: USED
A20: AP0612:COMT1 | B20: WC1328 | C20: UAI61218 | D20: BLK | E20: 20 | F20: 79.A6 | G20: UAI6121:8 | H20: ISOLATOR #1 PANEL | I20: 79.A6 | M20: USED
A21: AP0612:SHT1 | B21: WC1328 | C21: UAI6121S | D21: SH | E21: 20 | F21: 79.A6 | G21: FLOATING | H21: ISOLATOR #1 PANEL | I21: 79.A6 | M21: USED
A22: AP0614:SIG1 | B22: WC1329 | C22: UAI61417 | D22: RED | E22: 20 | F22: 79.A6 | G22: UAI6141:7 | H22: ISOLATOR #1 PANEL | I22: 79.A6 | M22: USED
A23: AP0614:COM1 | B23: WC1329 | C23: UAI61418 | D23: BLK | E23: 20 | F23: 79.A6 | G23: UAI6141:8 | H23: ISOLATOR #1 PANEL | I23: 79.A6 | M23: USED
A24: AP0614:SH1 | B24: WC1329 | C24: UAI6141S | D24: SH | E24: 20 | F24: 79.A6 | G24: FLOATING | H24: ISOLATOR #1 PANEL | I24: 79.A6 | M24: USED
A25: AP0614:SIG2 | B25: WC1330 | C25: UAI61427 | D25: RED | E25: 20 | F25: 79.B6 | G25: UAI6142:7 | H25: ISOLATOR #1 PANEL | I25: 79.B6 | M25: USED
... A91: UV0611:(+) | B91: SC | C91: FU0150 | D91: WHT | E91: 14 | F91: 28.C1 | G91: FU0150:LD | H91: REDUNDANT POWER PANEL | I91: 28.A4 | M91: USED
A93: Report date: 9/13/2024 1:02 PM | F93: SolarTools ver. 7.0.17.15318 (Jul 24, 2024)

Sheet CONSOLE
A1: CONSOLE
A2: CONTROL CONSOLE & CONTROL CONSOLE (DOOR PANELS)
A3: Project # | B3: 4H161
A4: Project Name | B4: QATARGAS - NFPS
A5: Revision | B5: D.2
A7: Controls DE | B7: K. NYBERG
A8: Phone: | B8: 0
A9: Controls ME | B9: D. FIGUEROA
A10: Phone:
A12: From | G12: To
A13: Device ID | B13: Cable (W) Conductor (SC) Jumper Clip (JC) | C13: Wire No. | D13: Wire ID | E13: Gauge/Size | F13: Page/Zone | G13: Device ID | H13: Location | I13: Page/Zone
A14: AT0190:GND | B14: SC | C14: AT0190G | D14: GRN/YEL | E14: 14 | F14: 15.B4 | G14: FRAME | H14: CONSOLE | I14: 15.C3 | M14: USED
A15: AT0190:USB1 | B15: SC | C15: AT0190K | D15: CABLE | E15: USB | F15: 15.B4 | G15: AT0190K:KI | H15: CONSOLE | I15: 15.C5 | M15: USED
A16: EL0270:B1 | B16: SC | C16: EL0270B1 | D16: WHT | E16: 14 | F16: 54.B5 | G16: ZS0270:2 | H16: CONSOLE | I16: 54.B6 | M16: USED
A17: EL0271:B1 | B17: SC | C17: ZS0271 | D17: WHT | E17: 14 | F17: 15.B4 | G17: ZS0271:2 | H17: CONSOLE | I17: 15.B3 | M17: USED
A18: EL0273:B1 | B18: SC | C18: ZS0273 | D18: WHT | E18: 14 | F18: 15.B4 | G18: ZS0273:2 | H18: CONSOLE | I18: 15.B3 | M18: USED
A19: AC0201:L1 | B19: WCAC0201 | C19: AC0201L1 | D19: BRN | E19: - - - | F19: 10.C4 | G19: XT0750:4 | H19: HEATER PANEL | I19: 10.C2 | M19: USED
A20: AC0201:L2 | B20: WCAC0201 | C20: AC0201L2 | D20: BLU | E20: - - - | F20: 10.C4 | G20: XT0750:5 | H20: HEATER PANEL | I20: 10.C2 | M20: USED
A21: AC0201:GND | B21: WCAC0201 | C21: AC0201G | D21: GRN/YEL | E21: - - - | F21: 10.C4 | G21: XT0750:6 | H21: HEATER PANEL | I21: 10.C2 | M21: USED
A22: ZS0270:1 | B22: SC | C22: FU0270LD | D22: WHT | E22: 14 | F22: 54.B6 | G22: FU0270:LD | H22: ISOLATOR #1 PANEL | I22: 54.A6 | M22: USED
A23: EL0270:W1 | B23: SC | C23: 0V | D23: WHT | E23: 14 | F23: 54.B5 | G23: XT0135:3 | H23: PANEL A | I23: 20.B4 | M23: USED
A24: AT0190:E1 | B24: WC0019 | C24: AT0190E | D24: ENET | E24: CABLE | F24: 15.B4 | G24: AT0680:LAN2 | H24: PLC PANEL | I24: 8.A4 | M24: USED
A25: AT0190:NEG | B25: SC | C25: 0V1 | D25: WHT | E25: 14 | F25: 15.B4 | G25: XT0562:2 | H25: PWR DISTRIBUTION RAIL | I25: 15.C2 | M25: USED
... A32: HA0273:(-) | B32: WC5540 | C32: HA0273N | D32: WHT | E32: 16 | F32: 18.A1 | G32: AF0201:27 | H32: TCP | I32: 18.A3 | M32: USED
F34: SolarTools ver. 7.0.17.15318 (Jul 24, 2024)
A35: Report date: 9/13/2024 1:02 PM

Sheet CONSOLE HEATER LIGHT
A1: CONSOLE HEATER LIGHT
A2: CONTROL CONSOLE^SPACE HEATER LIGHT PANEL
A3: Project # | B3: 4H161
A4: Project Name | B4: QATARGAS - NFPS
A5: Revision | B5: D.2
A7: Controls DE | B7: K. NYBERG
A8: Phone: | B8: 0
A9: Controls ME | B9: D. FIGUEROA
A10: Phone:
A12: From | G12: To
A13: Device ID | B13: Cable (W) Conductor (SC) Jumper Clip (JC) | C13: Wire No. | D13: Wire ID | E13: Gauge/Size | F13: Page/Zone | G13: Device ID | H13: Location | I13: Page/Zone
A14: HL0750:X1 | B14: SC | C14: QS0750LD3 | D14: RED | E14: 16 | F14: 10.A6 | G14: XT0751:3 | H14: HEATER PANEL | I14: 10.A6 | M14: USED
A15: HL0750:X2 | B15: SC | C15: TS0750NC | D15: RED | E15: 16 | F15: 10.A6 | G15: XT0751:5 | H15: HEATER PANEL | I15: 10.A6 | M15: USED
F17: SolarTools ver. 7.0.17.15318 (Jul 24, 2024)
A18: Report date: 9/13/2024 1:02 PM

Sheet FIRE SYS POWER
A1: FIRE SYS POWER
A3: Project # | B3: 4H161
A4: Project Name | B4: QATARGAS - NFPS
A5: Revision | B5: D.2
A7: Controls DE | B7: K. NYBERG
A8: Phone: | B8: 0
A9: Controls ME | B9: D. FIGUEROA
A10: Phone:
A12: From | G12: To
A13: Device ID | B13: Cable (W) Conductor (SC) Jumper Clip (JC) | C13: Wire No. | D13: Wire ID | E13: Gauge/Size | F13: Page/Zone | G13: Device ID | H13: Location | I13: Page/Zone
A14: GR0173: | B14: SC | C14: GR0173 | D14: GRN/YEL | E14: 14 | F14: 14.C2 | G14: FG1129:1 | H14: FIRE SYS POWER | I14: 14.C3 | M14: USED
A15: KA0150:2 | B15: SC | C15: KA01502 | D15: WHT | E15: 16 | F15: 14.B3 | G15: UV0171:5(+) | H15: FIRE SYS POWER | I15: 14.B2 | M15: USED
A16: KA0150:3 | B16: SC | C16: KA01503 | D16: WHT | E16: 14 | F16: 14.A4 | G16: KA0151:1 | H16: FIRE SYS POWER | I16: 14.A4 | M16: USED
A17: KA0150:7 | B17: SC | C17: KA01507 | D17: WHT | E17: 16 | F17: 14.B3 | G17: UV0171:6(-) | H17: FIRE SYS POWER | I17: 14.B2 | M17: USED
A18: KA0151:2 | B18: SC | C18: KA01512 | D18: WHT | E18: 16 | F18: 14.B3 | G18: UV0171:7(+) | H18: FIRE SYS POWER | I18: 14.B2 | M18: USED
A19: KA0151:3 | B19: SC | C19: KA01513 | D19: WHT | E19: 14 | F19: 14.A4 | G19: KA0152:3 | H19: FIRE SYS POWER | I19: 14.A4 | M19: USED
A20: KA0151:7 | B20: SC | C20: KA01517 | D20: WHT | E20: 16 | F20: 14.B3 | G20: UV0171:8(-) | H20: FIRE SYS POWER | I20: 14.B2 | M20: USED
A21: UV0171:2(-) | B21: SC | C21: 0V | D21: WHT | E21: 14 | F21: 14.B2 | G21: UV0171:4(-) | H21: FIRE SYS POWER | I21: 14.B2 | M21: USED
A22: UV0171:GND | B22: SC | C22: UV0171G | D22: GRN/YEL | E22: 14 | F22: 14.B2 | G22: FRAME | H22: FIRE SYS POWER | I22: 14.C3 | M22: USED
A23: KA0152:2 | B23: SC | C23: FU0172LD | D23: WHT | E23: 14 | F23: 125.A6 | G23: XT0172:16 | H23: FIRE SYSTEM | I23: 125.A6 | M23: USED
A24: KA0152:7 | B24: SC | C24: 0V | D24: WHT | E24: 14 | F24: 125.A6 | G24: XT0172:17 | H24: FIRE SYSTEM | I24: 125.A6 | M24: USED
A25: UV0171:1(+) | B25: SC | C25: FU0171LD | D25: WHT | E25: 14 | F25: 14.B2 | G25: FU0171:LD | H25: FIRE SYSTEM | I25: 14.B1 | M25: USED
... A39: KA0152:8 | B39: SC | C39: 009510 | D39: WHT | E39: 20 | F39: 114.C6 | G39: AF0095:10 | H39: PANEL A | I39: 114.C6 | M39: USED
A41: Report date: 9/13/2024 1:02 PM | F41: SolarTools ver. 7.0.17.15318 (Jul 24, 2024)

Sheet FIRE SYSTEM
A1: FIRE SYSTEM
A2: CONTROL CONSOLE (FIRE SYSTEM PANEL)
A3: Project # | B3: 4H161
A4: Project Name | B4: QATARGAS - NFPS
A5: Revision | B5: D.2
A7: Controls DE | B7: K. NYBERG
A8: Phone: | B8: 0
A9: Controls ME | B9: D. FIGUEROA
A10: Phone:
A12: From | G12: To
A13: Device ID | B13: Cable (W) Conductor (SC) Jumper Clip (JC) | C13: Wire No. | D13: Wire ID | E13: Gauge/Size | F13: Page/Zone | G13: Device ID | H13: Location | I13: Page/Zone
A14: XT0170:1 | B14: JC | C14: FU0170 | D14: CLIP | E14: --- | F14: 14.A2 | G14: XT0170:2 | H14: FIRE SYSTEM | I14: 14.A2 | M14: USED
A15: XT0170:3 | B15: JC | C15: 0V | D15: CLIP | E15: --- | F15: 14.A2 | G15: XT0170:4 | H15: FIRE SYSTEM | I15: 14.A2 | M15: USED
A16: KA6510:12 | B16: SC | C16: KA651012 | D16: WHT | E16: 20 | F16: 115.A6 | G16: AT0175:11 | H16: FIRE SYSTEM | I16: 115.A6 | M16: USED
A17: AT0175:4P1 | B17: SC | C17: AT01754P1 | D17: WHT | E17: 20 | F17: 14.B5 | G17: XT0170:5 | H17: FIRE SYSTEM | I17: 40.A5 | M17: USED
A18: KA6510:A2 | B18: SC | C18: KA6510A2 | D18: WHT | E18: 20 | F18: 14.B5 | G18: AT0175:5P1 | H18: FIRE SYSTEM | I18: 40.A6 | M18: USED
A19: AT0175:GND | B19: SC | C19: AT0175G | D19: GRN/YEL | E19: 14 | F19: 14.B5 | G19: FRAME | H19: FIRE SYSTEM | I19: 14.C6 | M19: USED
A20: AT0177:4P1 | B20: SC | C20: AT01774P1 | D20: WHT | E20: 14 | F20: 14.C5 | G20: AT0179:1P1 | H20: FIRE SYSTEM | I20: 14.D5 | M20: USED
A21: AT0177:5P1 | B21: SC | C21: AT01775P1 | D21: WHT | E21: 14 | F21: 14.C5 | G21: AT0179:2P1 | H21: FIRE SYSTEM | I21: 14.D5 | M21: USED
A22: AT0177:8 | B22: SC | C22: AT01778 | D22: LEAD | E22: --- | F22: 114.B6 | G22: RR0177S3: -10K OHM | H22: FIRE SYSTEM | I22: 114.B6 | M22: USED
A23: AT0177:9 | B23: SC | C23: AT01779 | D23: LEAD | E23: --- | F23: 114.B6 | G23: RR0177S3: -10K OHM | H23: FIRE SYSTEM | I23: 114.B6 | M23: USED
A24: AT0177:GND | B24: SC | C24: AT0177G | D24: GRN/YEL | E24: 14 | F24: 14.C5 | G24: FRAME | H24: FIRE SYSTEM | I24: 14.C6 | M24: USED
A25: AT0179:14 | B25: SC | C25: AT017914 | D25: LEAD | E25: --- | F25: 117.C6 | G25: RR0179S5:-10K OHM | H25: FIRE SYSTEM | I25: 117.C6 | M25: USED
... A107: AT0175:6 | B107: SC | C107: TS65402 | D107: WHT | E107: 20 | F107: 114.A6 | G107: EA01752:2 | H107: SURGE NON-I.S. PANEL | I107: 114.A5 | M107: USED
F109: SolarTools ver. 7.0.17.15318 (Jul 24, 2024)
A110: Report date: 9/13/2024 1:02 PM

Sheet FIRE SYSTEM CONTROLLER PANEL
A1: FIRE SYSTEM CONTROLLER PANEL
A2: CONTROL CONSOLE DOOR^(FIRE SYSTEM PANEL)
A3: Project # | B3: 4H161
A4: Project Name | B4: QATARGAS - NFPS
A5: Revision | B5: D.2
A7: Controls DE | B7: K. NYBERG
A8: Phone: | B8: 0
A9: Controls ME | B9: D. FIGUEROA
A10: Phone:
A12: From | G12: To
A13: Device ID | B13: Cable (W) Conductor (SC) Jumper Clip (JC) | C13: Wire No. | D13: Wire ID | E13: Gauge/Size | F13: Page/Zone | G13: Device ID | H13: Location | I13: Page/Zone
A14: AT0170:1 | B14: SC | C14: UV01705 | D14: WHT | E14: 14 | F14: 14.A5 | G14: UV0170:5(+) | H14: FIRE SYSTEM CONTROLLER PANEL | I14: 14.A2 | M14: USED
A15: AT0170:2 | B15: SC | C15: UV01706 | D15: WHT | E15: 14 | F15: 14.A5 | G15: UV0170:6(-) | H15: FIRE SYSTEM CONTROLLER PANEL | I15: 14.A2 | M15: USED
A16: KA0172:A1 | B16: SC | C16: AT017025 | D16: WHT | E16: 20 | F16: 14.D3 | G16: AT0170:25 | H16: FIRE SYSTEM CONTROLLER PANEL | I16: 14.D1 | M16: USED
A17: KA0174:A1 | B17: SC | C17: AT017031 | D17: WHT | E17: 20 | F17: 14.D3 | G17: AT0170:31 | H17: FIRE SYSTEM CONTROLLER PANEL | I17: 14.D1 | M17: USED
A18: AT0170:4 | B18: SC | C18: UV01708 | D18: WHT | E18: 14 | F18: 14.A5 | G18: UV0170:8(-) | H18: FIRE SYSTEM CONTROLLER PANEL | I18: 14.A2 | M18: USED
A19: AT0170:GND | B19: SC | C19: AT0170G | D19: GRN/YEL | E19: 14 | F19: 14.A5 | G19: FRAME | H19: FIRE SYSTEM CONTROLLER PANEL | I19: 14.B6 | M19: USED
A20: GR0171: | B20: SC | C20: GR0171 | D20: GRN/YEL | E20: 14 | F20: 14.A5 | G20: FRAME | H20: FIRE SYSTEM CONTROLLER PANEL | I20: 14.A6 | M20: USED
A21: KA0172:A2 | B21: SC | C21: 0V | D21: WHT | E21: 12 | F21: 14.D1 | G21: KA0174:A2 | H21: FIRE SYSTEM CONTROLLER PANEL | I21: 14.D1 | M21: USED
A22: KA0176:11 | B22: SC | C22: KA017611 | D22: WHT | E22: 20 | F22: 129.A6 | G22: XT0171:3 | H22: FIRE SYSTEM CONTROLLER PANEL | I22: 129.A5 | M22: USED
A23: KA0176:A1 | B23: SC | C23: KA014422 | D23: WHT | E23: 20 | F23: 129.B5 | G23: KA0177:A1 | H23: FIRE SYSTEM CONTROLLER PANEL | I23: 129.B5 | M23: USED
A24: KA0176:A2 | B24: SC | C24: 0V | D24: WHT | E24: 20 | F24: 129.B5 | G24: KA0177:A2 | H24: FIRE SYSTEM CONTROLLER PANEL | I24: 129.B5 | M24: USED
A25: KA0177:11 | B25: SC | C25: KA017711 | D25: WHT | E25: 20 | F25: 130.A6 | G25: XT0171:1 | H25: FIRE SYSTEM CONTROLLER PANEL | I25: 130.A5 | M25: USED
... A73: AT0170:L1 | B73: WC9018 | C73: AT0170L1 | D73: ENET | E73: CABLE | F73: 14.A5 | G73: AU0200:L2 | H73: TCP | I73: 15.A3 | M73: USED
F75: SolarTools ver. 7.0.17.15318 (Jul 24, 2024)
A76: Report date: 9/13/2024 1:02 PM

Sheet GENERATOR PANEL
A1: GENERATOR PANEL
A2: CONTROL CONSOLE (GENERATOR PANEL)
A3: Project # | B3: 4H161
A4: Project Name | B4: QATARGAS - NFPS
A5: Revision | B5: D.2
A7: Controls DE | B7: K. NYBERG
A8: Phone: | B8: 0
A9: Controls ME | B9: D. FIGUEROA
A10: Phone:
A12: From | G12: To
A13: Device ID | B13: Cable (W) Conductor (SC) Jumper Clip (JC) | C13: Wire No. | D13: Wire ID | E13: Gauge/Size | F13: Page/Zone | G13: Device ID | H13: Location | I13: Page/Zone
A14: XT0336:2 | B14: JC | C14: 0V | D14: CLIP | E14: --- | F14: 30.C4 | G14: XT0336:3 | H14: GENERATOR PANEL | I14: 30.C4 | M14: USED
A15: XT0336:3 | B15: JC | C15: 0V | D15: CLIP | E15: --- | F15: 30.C4 | G15: XT0336:4 | H15: GENERATOR PANEL | I15: 30.D4 | M15: USED
A16: XT0336:4 | B16: JC | C16: 0V | D16: CLIP | E16: --- | F16: 30.D4 | G16: XT0336:5 | H16: GENERATOR PANEL | I16: 30.D4 | M16: USED
A17: XT0341:4 | B17: JC | C17: AT0140VGENB | D17: CLIP | E17: --- | F17: 25.D2 | G17: XT0341:5 | H17: GENERATOR PANEL | I17: 25.D2 | M17: USED
A18: XT0351:1 | B18: JC | C18: AT0140VGENN | D18: CLIP | E18: --- | F18: 104.A5 | G18: XT0351:2 | H18: GENERATOR PANEL | I18: 104.A5 | M18: USED
A19: XT0351:10 | B19: JC | C19: AT0140VGENA | D19: CLIP | E19: --- | F19: 105.B5 | G19: XT0351:11 | H19: GENERATOR PANEL | I19: 105.B5 | M19: USED
A20: XT0351:12 | B20: JC | C20: AT0140VGENB | D20: CLIP | E20: --- | F20: 105.B5 | G20: XT0351:13 | H20: GENERATOR PANEL | I20: 105.C5 | M20: USED
A21: XT0351:14 | B21: JC | C21: AT0140VGENC | D21: CLIP | E21: --- | F21: 105.C5 | G21: XT0351:15 | H21: GENERATOR PANEL | I21: 105.C5 | M21: USED
A22: XT0351:16 | B22: JC | C22: AT0140VGENN | D22: CLIP | E22: --- | F22: 105.C5 | G22: XT0351:17 | H22: GENERATOR PANEL | I22: 105.C5 | M22: USED
A23: XT0351:2 | B23: JC | C23: AT0140VGENN | D23: CLIP | E23: --- | F23: 104.A5 | G23: XT0351:3 | H23: GENERATOR PANEL | I23: 104.A5 | M23: USED
A24: XT0351:4 | B24: JC | C24: PTBUSA | D24: CLIP | E24: --- | F24: 104.A5 | G24: XT0351:5 | H24: GENERATOR PANEL | I24: 104.A5 | M24: USED
A25: XT0351:6 | B25: JC | C25: PTBUSB | D25: CLIP | E25: --- | F25: 104.A5 | G25: XT0351:7 | H25: GENERATOR PANEL | I25: 104.A5 | M25: USED
... A180: PEG0140:3 | B180: SC | C180: AT0140G1 | D180: GRN/YEL | E180: 12 | F180: 107.B7 | G180: XT0313:2 | H180: GENERATOR PANEL | I180: 107.B6 | M180: USED
A181: PEG0140:4 | B181: SC | C181: EXCS | E181: 12 | F181: 107.D7 | G181: XT0124:2 | H181: GENERATOR PANEL | I181: 107.D6 | M181: USED
A182: PEG0140:5 | B182: SC | C182: PEG01405 | D182: GRN/YEL | E182: 12 | F182: 109.B5 | G182: XT0352:2 | H182: GENERATOR PANEL | I182: 109.B4 | M182: USED
A183: PEG0140:6 | B183: SC | C183: PEG01404 | D183: GRN/YEL | E183: 12 | F183: 110.C5 | G183: XT0464:1 | H183: GENERATOR PANEL | I183: 110.C4 | M183: USED
A184: TM0102:GND | B184: SC | C184: TM0102G | D184: GRN/YEL | E184: 14 | F184: 25.B5 | G184: FRAME | H184: GENERATOR PANEL | I184: 25.C5 | M184: USED
A185: VD0121:- | B185: SC | C185: VD0122 | D185: WHT | E185: 12 | F185: 107.D4 | G185: VD0122:+ | H185: GENERATOR PANEL | I185: 107.D4 | M185: USED
A186: VD0121:+ | B186: SC | C186: EXC2 | D186: WHT | E186: 12 | F186: 107.D4 | G186: XT0370:2 | H186: GENERATOR PANEL | I186: 107.C4 | M186: USED
A187: VD0122:- | B187: SC | C187: VD0123 | D187: WHT | E187: 12 | F187: 107.D4 | G187: VD0123:+ | H187: GENERATOR PANEL | I187: 107.C4 | M187: USED
A188: VD0123:- | B188: SC | C188: VD0124 | D188: WHT | E188: 12 | F188: 107.C4 | G188: VD0124:+ | H188: GENERATOR PANEL | I188: 107.C4 | M188: USED
A189: VD0124:- | B189: SC | C189: EXC0 | D189: WHT | E189: 12 | F189: 107.C4 | G189: XT0370:1 | H189: GENERATOR PANEL | I189: 107.C4 | M189: USED
A190: XT0334:1 | B190: SC | C190: 0V | D190: WHT | E190: 12 | F190: 30.C2 | G190: XT0336:2 | H190: GENERATOR PANEL | I190: 30.C4 | M190: USED
A191: XT0335:4 | B191: SC | C191: FU0333 | D191: WHT | E191: 16 | F191: 30.B4 | G191: XT0337:10 | H191: GENERATOR PANEL | I191: 33.C3 | M191: USED
A192: XT0336:3 | B192: SC | C192: 0V | D192: WHT | E192: 20 | F192: 30.C4 | G192: XT0337:19 | H192: GENERATOR PANEL | I192: 33.D3 | M192: USED
A193: XT0337:10 | B193: SC | C193: FU0333 | D193: WHT | E193: 20 | F193: 33.C3 | G193: XT0337:7 | H193: GENERATOR PANEL | I193: 33.B3 | M193: USED
... A403: AU0120:L1 | B403: WC0018 | C403: AU0180L2 | D403: ENET | E403: CABLE | F403: 31.C1 | G403: AU0180:L2 | H403: VIBRATION PANEL | I403: 15.C3 | M403: USED
F405: SolarTools ver. 7.0.17.15318 (Jul 24, 2024)
A406: Report date: 9/13/2024 1:02 PM

Sheet HEATER PANEL
A1: HEATER PANEL
A2: CONTROL CONSOLE HEATER PANEL
A3: Project # | B3: 4H161
A4: Project Name | B4: QATARGAS - NFPS
A5: Revision | B5: D.2
A7: Controls DE | B7: K. NYBERG
A8: Phone: | B8: 0
A9: Controls ME | B9: D. FIGUEROA
A10: Phone:
A12: From | G12: To
A13: Device ID | B13: Cable (W) Conductor (SC) Jumper Clip (JC) | C13: Wire No. | D13: Wire ID | E13: Gauge/Size | F13: Page/Zone | G13: Device ID | H13: Location | I13: Page/Zone
A14: XT0751:1 | B14: JC | C14: H07500G | D14: CLIP | E14: --- | F14: 10.A5 | G14: XT0751:2 | H14: HEATER PANEL | I14: 10.B5 | M14: USED
A15: XT0751:3 | B15: JC | C15: QS0750LD3 | D15: CLIP | E15: --- | F15: 10.A6 | G15: XT0751:4 | H15: HEATER PANEL | I15: 10.B6 | M15: USED
A16: XT0751:5 | B16: JC | C16: TS0750NC | D16: CLIP | E16: --- | F16: 10.A6 | G16: XT0751:6 | H16: HEATER PANEL | I16: 10.B6 | M16: USED
A17: GR0750: | B17: SC | C17: GR0750G | D17: GRN/YEL | E17: 14 | F17: 10.B6 | G17: FRAME | H17: HEATER PANEL | I17: 10.B6 | M17: USED
A18: GR0751: | B18: SC | C18: GR0751G | D18: GRN/YEL | E18: 14 | F18: 10.B6 | G18: FRAME | H18: HEATER PANEL | I18: 10.B6 | M18: USED
A19: H07500:GND | B19: SC | C19: H07500G | D19: GRN/YEL | E19: 14 | F19: 10.A7 | G19: XT0751:1 | H19: HEATER PANEL | I19: 10.A5 | M19: USED
A20: H07500:L1 | B20: SC | C20: TS0750NC | D20: RED | E20: 16 | F20: 10.A7 | G20: XT0751:5 | H20: HEATER PANEL | I20: 10.A6 | M20: USED
A21: H07500:L2 | B21: SC | C21: QS0750LD3 | D21: RED | E21: 16 | F21: 10.A7 | G21: XT0751:3 | H21: HEATER PANEL | I21: 10.A6 | M21: USED
A22: H07501:GND | B22: SC | C22: H07500G | D22: GRN/YEL | E22: 14 | F22: 10.B7 | G22: XT0751:2 | H22: HEATER PANEL | I22: 10.B5 | M22: USED
A23: H07501:L1 | B23: SC | C23: TS0750NC | D23: RED | E23: 16 | F23: 10.B7 | G23: XT0751:6 | H23: HEATER PANEL | I23: 10.B6 | M23: USED
A24: H07501:L2 | B24: SC | C24: QS0750LD3 | D24: RED | E24: 16 | F24: 10.B7 | G24: XT0751:4 | H24: HEATER PANEL | I24: 10.B6 | M24: USED
A25: QS0750:LD-1 | B25: SC | C25: TS0750C | D25: RED | E25: 12 | F25: 10.A3 | G25: TS0750:C | H25: HEATER PANEL | I25: 10.A4 | M25: USED
... A35: XT0751:5 | B35: SC | C35: TS0750NC | D35: RED | E35: 16 | F35: 10.A6 | G35: HL0750:X2 | H35: CONSOLE HEATER LIGHT | I35: 10.A6 | M35: USED
F37: SolarTools ver. 7.0.17.15318 (Jul 24, 2024)
A38: Report date: 9/13/2024 1:02 PM

Sheet ISOLATOR #1 PANEL
A1: ISOLATOR #1 PANEL
A3: Project # | B3: 4H161
A4: Project Name | B4: QATARGAS - NFPS
A5: Revision | B5: D.2
A7: Controls DE | B7: K. NYBERG
A8: Phone: | B8: 0
A9: Controls ME | B9: D. FIGUEROA
A10: Phone:
A12: From | G12: To
A13: Device ID | B13: Cable (W) Conductor (SC) Jumper Clip (JC) | C13: Wire No. | D13: Wire ID | E13: Gauge/Size | F13: Page/Zone | G13: Device ID | H13: Location | I13: Page/Zone
A14: EAG02102: | B14: SC | C14: EAG02102 | D14: GRN | E14: 14 | F14: 4.C4 | G14: IEG0210:4 | H14: ISOLATOR #1 PANEL | I14: 4.C4 | M14: USED
A15: FU0270:LI | B15: SC | C15: FU0137 | D15: WHT | E15: 14 | F15: 54.A6 | G15: FU0274:LI | H15: ISOLATOR #1 PANEL | I15: 54.A6 | M15: USED
A16: FU0272:LD | B16: SC | C16: UV0271P | D16: WHT | E16: 14 | F16: 55.A6 | G16: UV0271:8+ | H16: ISOLATOR #1 PANEL | I16: 55.A5 | M16: USED
A17: FU0274:LD | B17: SC | C17: UV0270P | D17: WHT | E17: 14 | F17: 54.A6 | G17: UV0270:8+ | H17: ISOLATOR #1 PANEL | I17: 54.A5 | M17: USED
A18: GR0272: | B18: SC | C18: GR0272 | D18: GRN/YEL | E18: 14 | F18: 55.A6 | G18: FRAME | H18: ISOLATOR #1 PANEL | I18: 55.A7 | M18: USED
A19: GR0273: | B19: SC | C19: GR0273 | D19: GRN/YEL | E19: 14 | F19: 55.A6 | G19: FRAME | H19: ISOLATOR #1 PANEL | I19: 55.A7 | M19: USED
A20: EA4501:1 | B20: WC0450 | C20: UA1520P | D20: RED | E20: 20 | F20: 61.A5 | G20: UAI1520:+ | H20: ISOLATOR #1 PANEL | I20: 61.A5 | M20: USED
A21: EA4501:2 | B21: WC0450 | C21: UA1520N | D21: WHT | E21: 20 | F21: 61.A5 | G21: UAI1520:- | H21: ISOLATOR #1 PANEL | I21: 61.A5 | M21: USED
A22: UAI1520:IE | B22: WC0450 | C22: UA1520S1 | D22: SH | E22: 20 | F22: 61.A5 | G22: FLOATING | H22: ISOLATOR #1 PANEL | I22: 61.A5 | M22: USED
A23: EA0741:1 | B23: WCI2101 | C23: AP1100P1 | D23: RED | E23: 20 | F23: 55.B5 | G23: UAI0741:4+ | H23: ISOLATOR #1 PANEL | I23: 55.B6 | M23: USED
A24: EA0741:2 | B24: WCI2101 | C24: AP1100N1 | D24: BLK | E24: 20 | F24: 55.B5 | G24: UAI0741:5- | H24: ISOLATOR #1 PANEL | I24: 55.B6 | M24: USED
A25: UAI0741:IE | B25: WCI2101 | C25: AP1100S01 | D25: SH | E25: 20 | F25: 55.B6 | G25: FLOATING | H25: ISOLATOR #1 PANEL | I25: 55.B5 | M25: USED
... A276: UAI1520:0V | B276: WC4749 | C276: UAI15200V | D276: BLK | E276: 20 | F276: 61.A5 | G276: AF0450:08 | H276: VIBRATION PANEL | I276: 61.A7 | M276: USED
F278: SolarTools ver. 7.0.17.15318 (Jul 24, 2024)
A279: Report date: 9/13/2024 1:02 PM

Sheet ISOLATOR #2 PANEL
A1: ISOLATOR #2 PANEL
A3: Project # | B3: 4H161
A4: Project Name | B4: QATARGAS - NFPS
A5: Revision | B5: D.2
A7: Controls DE | B7: K. NYBERG
A8: Phone: | B8: 0
A9: Controls ME | B9: D. FIGUEROA
A10: Phone:
A12: From | G12: To
A13: Device ID | B13: Cable (W) Conductor (SC) Jumper Clip (JC) | C13: Wire No. | D13: Wire ID | E13: Gauge/Size | F13: Page/Zone | G13: Device ID | H13: Location | I13: Page/Zone
A14: EA4240:3 | B14: SC | C14: TE42401 | F14: 84.B5 | G14: UAI4240:4 | H14: ISOLATOR #2 PANEL | I14: 84.B6 | M14: USED
A15: GR0274: | B15: SC | C15: GR0274 | D15: GRN/YEL | E15: 14 | F15: 54.A6 | G15: FRAME | H15: ISOLATOR #2 PANEL | I15: 54.A7 | M15: USED
A16: GR0275: | B16: SC | C16: GR0275 | D16: GRN/YEL | E16: 14 | F16: 54.A6 | G16: FRAME | H16: ISOLATOR #2 PANEL | I16: 54.A7 | M16: USED
A17: UAI0830:1 | B17: SC | C17: TE12703 | D17: WHT | E17: 20 | F17: 78.C6 | G17: UAI0830:2 | H17: ISOLATOR #2 PANEL | I17: 78.C6 | M17: USED
A18: UAI0831:1 | B18: SC | C18: TE12603 | D18: WHT | E18: 20 | F18: 78.B6 | G18: UAI0831:2 | H18: ISOLATOR #2 PANEL | I18: 78.B6 | M18: USED
A19: UAI0835:1 | B19: SC | C19: TE11103 | D19: WHT | E19: 20 | F19: 53.A6 | G19: UAI0835:2 | H19: ISOLATOR #2 PANEL | I19: 53.A6 | M19: USED
A20: UAI0836:1 | B20: SC | C20: AP12003 | D20: WHT | E20: 20 | F20: 58.A6 | G20: UAI0836:2 | H20: ISOLATOR #2 PANEL | I20: 58.A6 | M20: USED
A21: UAI0840:1 | B21: SC | C21: TE32003 | D21: WHT | E21: 20 | F21: 91.A6 | G21: UAI0840:2 | H21: ISOLATOR #2 PANEL | I21: 91.A6 | M21: USED
A22: UAI0841:1 | B22: SC | C22: TE31003 | D22: WHT | E22: 20 | F22: 100.A6 | G22: UAI0841:2 | H22: ISOLATOR #2 PANEL | I22: 100.A6 | M22: USED
A23: UAI0842:1 | B23: SC | C23: TE32203 | D23: WHT | E23: 20 | F23: 97.A6 | G23: UAI0842:2 | H23: ISOLATOR #2 PANEL | I23: 97.A6 | M23: USED
A24: UAI0843:1 | B24: SC | C24: TE32213 | D24: WHT | E24: 20 | F24: 97.B6 | G24: UAI0843:2 | H24: ISOLATOR #2 PANEL | I24: 97.B6 | M24: USED
A25: UAI0844:1 | B25: SC | C25: TE61103 | D25: WHT | E25: 20 | F25: 122.A6 | G25: UAI0844:2 | H25: ISOLATOR #2 PANEL | I25: 122.A6 | M25: USED
A26: UAI0846:1 | B26: SC | C26: TE31073 | D26: WHT | E26: 20 | F26: 100.B6 | G26: UAI0846:2 | H26: ISOLATOR #2 PANEL | I26: 100.B6 | M26: USED
... A37: UAI4230:1 | B37: SC | C37: TE42303 | D37: WHT | E37: 20 | F37: 84.A6 | G37: UAI4230:2 | H37: ISOLATOR #2 PANEL | I37: 84.A6 | M37: USED
A38: UAI4230:2 | B38: SC | C38: TE42303 | F38: 84.A6 | G38: EA4230:1 | H38: ISOLATOR #2 PANEL | I38: 84.A5 | M38: USED
A39: UAI4240:1 | B39: SC | C39: TE42403 | D39: WHT | E39: 20 | F39: 84.B6 | G39: UAI4240:2 | H39: ISOLATOR #2 PANEL | I39: 84.B6 | M39: USED
A40: UAI4240:2 | B40: SC | C40: TE42403 | F40: 84.B6 | G40: EA4240:1 | H40: ISOLATOR #2 PANEL | I40: 84.B5 | M40: USED
A41: UAI4250:1 | B41: SC | C41: TE42601 | D41: WHT | E41: 20 | F41: 85.C6 | G41: UAI4250:2 | H41: ISOLATOR #2 PANEL | I41: 85.C6 | M41: USED
A42: UAI4251:1 | B42: SC | C42: TE42511 | D42: WHT | E42: 20 | F42: 85.B6 | G42: UAI4251:2 | H42: ISOLATOR #2 PANEL | I42: 85.B6 | M42: USED
A43: UAI4260:1 | B43: SC | C43: TE42501 | D43: WHT | E43: 20 | F43: 85.A6 | G43: UAI4260:2 | H43: ISOLATOR #2 PANEL | I43: 85.A6 | M43: USED
A44: EA0831:3 | B44: WC1260 | C44: TE12601 | D44: RED | E44: 20 | F44: 78.B5 | G44: UAI0831:4 | H44: ISOLATOR #2 PANEL | I44: 78.B6 | M44: USED
A45: EA0831:2 | B45: WC1260 | C45: TE12602 | D45: WHT | E45: 20 | F45: 78.B5 | G45: UAI0831:3 | H45: ISOLATOR #2 PANEL | I45: 78.B6 | M45: USED
A46: UAI0831:2 | B46: WC1260 | C46: TE12603 | D46: BLK | E46: 20 | F46: 78.B6 | G46: EA0831:1 | H46: ISOLATOR #2 PANEL | I46: 78.B5 | M46: USED
A47: UAI0831:IE | B47: WC1260 | C47: TE1260S1 | D47: SH | E47: 20 | F47: 78.B6 | G47: FLOATING | H47: ISOLATOR #2 PANEL | I47: 78.B5 | M47: USED
A48: EA0830:3 | B48: WC1270 | C48: TE12701 | D48: RED | E48: 20 | F48: 78.C5 | G48: UAI0830:4 | H48: ISOLATOR #2 PANEL | I48: 78.C6 | M48: USED
A49: EA0830:2 | B49: WC1270 | C49: TE12702 | D49: WHT | E49: 20 | F49: 78.C5 | G49: UAI0830:3 | H49: ISOLATOR #2 PANEL | I49: 78.C6 | M49: USED
A50: UAI0830:2 | B50: WC1270 | C50: TE12703 | D50: BLK | E50: 20 | F50: 78.C6 | G50: EA0830:1 | H50: ISOLATOR #2 PANEL | I50: 78.C5 | M50: USED
A51: UAI0830:IE | B51: WC1270 | C51: TE1270S1 | D51: SH | E51: 20 | F51: 78.C6 | G51: FLOATING | H51: ISOLATOR #2 PANEL | I51: 78.C5 | M51: USED
A52: EA0835:3 | B52: WC2180 | C52: TE11101 | D52: RED | E52: 20 | F52: 53.A5 | G52: UAI0835:4 | H52: ISOLATOR #2 PANEL | I52: 53.A6 | M52: USED
... A295: UV0273:IE | B295: SC | C295: IEG01301 | D295: GRN | E295: 14 | F295: 54.A5 | G295: IEG0130:1 | H295: VIBRATION PANEL | I295: 54.A5 | M295: USED
...

Sheet JB5
A1: JB5
A3: Project # | B3: 4H161
A4: Project Name | B4: QATARGAS - NFPS
A5: Revision | B5: D.2
A7: Controls DE | B7: K. NYBERG
A8: Phone: | B8: 0
A9: Controls ME | B9: D. FIGUEROA
A10: Phone:
A12: From | G12: To
A13: Device ID | B13: Cable (W) Conductor (SC) Jumper Clip (JC) | C13: Wire No. | D13: Wire ID | E13: Gauge/Size | F13: Page/Zone | G13: Device ID | H13: Location | I13: Page/Zone
A14: GR1110: | B14: SC | C14: GR1110 | D14: GRN/YEL | E14: 14 | F14: 4.C6 | G14: FRAME | H14: JB5 | I14: 4.C7 | M14: USED
A15: GR1150: | B15: SC | C15: GR1150 | D15: GRN/YEL | E15: 14 | F15: 4.C6 | G15: FRAME | H15: JB5 | I15: 4.C6 | M15: USED
F17: SolarTools ver. 7.0.17.15318 (Jul 24, 2024)
A18: Report date: 9/13/2024 1:02 PM

Sheet JB70
A1: JB70
A3: Project # | B3: 4H161
A4: Project Name | B4: QATARGAS - NFPS
A5: Revision | B5: D.2
A7: Controls DE | B7: K. NYBERG
A8: Phone: | B8: 0
A9: Controls ME | B9: D. FIGUEROA
A10: Phone:
A12: From | G12: To
A13: Device ID | B13: Cable (W) Conductor (SC) Jumper Clip (JC) | C13: Wire No. | D13: Wire ID | E13: Gauge/Size | F13: Page/Zone | G13: Device ID | H13: Location | I13: Page/Zone
A14: GR1132: | B14: SC | C14: GR1132 | D14: GRN/YEL | E14: 14 | F14: 4.A6 | G14: FRAME | H14: JB70 | I14: 4.A6 | M14: USED
A15: GR1133: | B15: SC | C15: GR1133 | D15: GRN/YEL | E15: 14 | F15: 4.A6 | G15: FRAME | H15: JB70 | I15: 4.A6 | M15: USED
A16: GR1134: | B16: SC | C16: GR1134 | D16: GRN/YEL | E16: 14 | F16: 4.A6 | G16: FRAME | H16: JB70 | I16: 4.A6 | M16: USED
A17: GR1232: | B17: SC | C17: GR1232 | D17: GRN/YEL | E17: 14 | F17: 4.A6 | G17: FG1127:1 | H17: JB70 | I17: 4.A7 | M17: USED
A18: GR1233: | B18: SC | C18: GR1233 | D18: GRN/YEL | E18: 14 | F18: 4.A6 | G18: FRAME | H18: JB70 | I18: 4.A7 | M18: USED
A19: GR1235: | B19: SC | C19: GR1235 | D19: GRN/YEL | E19: 14 | F19: 4.B6 | G19: FG1128:1 | H19: JB70 | I19: 4.B6 | M19: USED
A20: HL0171:X2 | B20: SC | C20: HL0171X2 | D20: WHT | E20: 20 | F20: 40.B1 | G20: VD0175A:--1N4005/1 | H20: JB70 | I20: 40.B3 | M20: USED
A21: HL0172:X2 | B21: SC | C21: HL0172X2 | D21: WHT | E21: 20 | F21: 40.C1 | G21: VD0175I:--1N4005/1 | H21: JB70 | I21: 40.C3 | M21: USED
A22: HL0173:X2 | B22: SC | C22: HL0173X2 | D22: WHT | E22: 20 | F22: 40.C1 | G22: VD0175D:--1N4005/1 | H22: JB70 | I22: 40.C3 | M22: USED
A23: IEG1100: | B23: SC | C23: IEG12002 | D23: GRN | E23: 14 | F23: 55.A4 | G23: IEG1200:2 | H23: JB70 | I23: 55.A4 | M23: USED
A24: RR0175A: -10K OHM | B24: SC | C24: HL0171X1 | D24: WHT | E24: 20 | F24: 40.B3 | G24: HL0171:X1 | H24: JB70 | I24: 40.B1 | M24: USED
A25: RR0175A: -10K OHM | B25: SC | C25: VD0175A | D25: WHT | E25: 20 | F25: 40.B3 | G25: VD0175A:+-1N4005/1 | H25: JB70 | I25: 40.B3 | M25: USED
... A35: SA0170:B2-14 | B35: SC | C35: SA0170B214 | D35: WHT | E35: 20 | F35: 40.A1 | G35: XT0811:16 | H35: JB70 | I35: 40.A3 | M35: USED
F37: SolarTools ver. 7.0.17.15318 (Jul 24, 2024)
A38: Report date: 9/13/2024 1:02 PM

Sheet JB70 DOOR HEATER PANEL
A1: JB70 DOOR HEATER PANEL
A3: Project # | B3: 4H161
A4: Project Name | B4: QATARGAS - NFPS
A5: Revision | B5: D.2
A7: Controls DE | B7: K. NYBERG
A8: Phone: | B8: 0
A9: Controls ME | B9: D. FIGUEROA
A10: Phone:
A12: From | G12: To
A13: Device ID | B13: Cable (W) Conductor (SC) Jumper Clip (JC) | C13: Wire No. | D13: Wire ID | E13: Gauge/Size | F13: Page/Zone | G13: Device ID | H13: Location | I13: Page/Zone
A14: GR0700: | B14: SC | C14: GR0700 | D14: GRN/YEL | E14: 16 | F14: 11.B6 | G14: FG1:1 | H14: JB70 DOOR HEATER PANEL | I14: 11.B7 | M14: USED
A15: TS7000:GND | B15: SC | C15: CCH7000G | D15: GRN/YEL | E15: 16 | F15: 11.A7 | G15: XT7001:3 | H15: JB70 DOOR HEATER PANEL | I15: 11.B4 | M15: USED
A16: H7000:L2 | B16: WH7000 | C16: KA700022 | D16: BLU | E16: 14 | F16: 11.A7 | G16: XT7001:2 | H16: JB70 DOOR HEATER PANEL | I16: 11.B4 | M16: USED
A17: H7000:L1 | B17: WH7000 | C17: TS7000 | D17: BRN | E17: 14 | F17: 11.A7 | G17: XT7001:4 | H17: JB70 DOOR HEATER PANEL | I17: 11.B4 | M17: USED
A18: H7000:GND | B18: WH7000 | C18: CCH7000G | D18: GRN/YEL | E18: 14 | F18: 11.A7 | G18: XT7001:3 | H18: JB70 DOOR HEATER PANEL | I18: 11.B4 | M18: USED
A19: TS7000:NC | B19: WTS7000 | C19: TS7000 | D19: BLU | E19: 14 | F19: 11.A7 | G19: XT7001:4 | H19: JB70 DOOR HEATER PANEL | I19: 11.B4 | M19: USED
A20: TS7000:C | B20: WTS7000 | C20: KA700012 | D20: BRN | E20: 14 | F20: 11.A7 | G20: XT7001:1 | H20: JB70 DOOR HEATER PANEL | I20: 11.A4 | M20: USED
A21: XT7001:1 | B21: SC | C21: KA700012 | D21: BLU | E21: 16 | F21: 11.A4 | G21: KA7000:12 | H21: JB70 LEFT RAIL | I21: 11.A4 | M21: USED
A22: XT7001:2 | B22: SC | C22: KA700022 | D22: BLU | E22: 16 | F22: 11.B4 | G22: KA7000:22 | H22: JB70 LEFT RAIL | I22: 11.B4 | M22: USED
A23: XT7001:3 | B23: SC | C23: CCH7000G | D23: GRN/YEL | E23: 16 | F23: 11.B4 | G23: XT7000:3 | H23: JB70 LEFT RAIL | I23: 11.B2 | M23: USED
F25: SolarTools ver. 7.0.17.15318 (Jul 24, 2024)
A26: Report date: 9/13/2024 1:02 PM

Sheet JB70 LEFT RAIL
A1: JB70 LEFT RAIL
A2: JB70 (LEFT RAIL)
A3: Project # | B3: 4H161
A4: Project Name | B4: QATARGAS - NFPS
A5: Revision | B5: D.2
A7: Controls DE | B7: K. NYBERG
A8: Phone: | B8: 0
A9: Controls ME | B9: D. FIGUEROA
A10: Phone:
A12: From | G12: To
A13: Device ID | B13: Cable (W) Conductor (SC) Jumper Clip (JC) | C13: Wire No. | D13: Wire ID | E13: Gauge/Size | F13: Page/Zone | G13: Device ID | H13: Location | I13: Page/Zone
A14: KA7000:11 | B14: SC | C14: FU7000 | D14: BLU | E14: 16 | F14: 11.A3 | G14: FU7000:LD | H14: JB70 LEFT RAIL | I14: 11.A4 | M14: USED
A15: FU7000:LI | B15: SC | C15: CCH7000L1 | D15: BLU | E15: 16 | F15: 11.A3 | G15: XT7000:1 | H15: JB70 LEFT RAIL | I15: 11.A2 | M15: USED
A16: GR1101: | B16: SC | C16: GR1101 | D16: GRN/YEL | E16: 14 | F16: 4.A6 | G16: FRAME | H16: JB70 LEFT RAIL | I16: 4.A6 | M16: USED
A17: KA7000:21 | B17: SC | C17: CCH7000L2 | D17: BLU | E17: 16 | F17: 11.B4 | G17: XT7000:2 | H17: JB70 LEFT RAIL | I17: 11.B2 | M17: USED
A18: KA7000:12 | B18: SC | C18: KA700012 | D18: BLU | E18: 16 | F18: 11.A4 | G18: XT7001:1 | H18: JB70 DOOR HEATER PANEL | I18: 11.A4 | M18: USED
A19: KA7000:22 | B19: SC | C19: KA700022 | D19: BLU | E19: 16 | F19: 11.B4 | G19: XT7001:2 | H19: JB70 DOOR HEATER PANEL | I19: 11.B4 | M19: USED
A20: XT7000:3 | B20: SC | C20: CCH7000G | D20: GRN/YEL | E20: 16 | F20: 11.B2 | G20: XT7001:3 | H20: JB70 DOOR HEATER PANEL | I20: 11.B4 | M20: USED
F22: SolarTools ver. 7.0.17.15318 (Jul 24, 2024)
A23: Report date: 9/13/2024 1:02 PM

Sheet JB70 RIGHT RAIL
A1: JB70 RIGHT RAIL
A2: JB70 (RIGHT RAIL)
A3: Project # | B3: 4H161
A4: Project Name | B4: QATARGAS - NFPS
A5: Revision | B5: D.2
A7: Controls DE | B7: K. NYBERG
A8: Phone: | B8: 0
A9: Controls ME | B9: D. FIGUEROA
A10: Phone:
A12: From | G12: To
A13: Device ID | B13: Cable (W) Conductor (SC) Jumper Clip (JC) | C13: Wire No. | D13: Wire ID | E13: Gauge/Size | F13: Page/Zone | G13: Device ID | H13: Location | I13: Page/Zone
A14: GR1100: | B14: SC | C14: GR1100 | D14: GRN/YEL | E14: 14 | F14: 4.A6 | G14: FRAME | H14: JB70 RIGHT RAIL | I14: 4.A7 | M14: USED
F16: SolarTools ver. 7.0.17.15318 (Jul 24, 2024)
A17: Report date: 9/13/2024 1:02 PM

Sheet JB72
A1: JB72
A3: Project # | B3: 4H161
A4: Project Name | B4: QATARGAS - NFPS
A5: Revision | B5: D.2
A7: Controls DE | B7: K. NYBERG
A8: Phone: | B8: 0
A9: Controls ME | B9: D. FIGUEROA
A10: Phone:
A12: From | G12: To
A13: Device ID | B13: Cable (W) Conductor (SC) Jumper Clip (JC) | C13: Wire No. | D13: Wire ID | E13: Gauge/Size | F13: Page/Zone | G13: Device ID | H13: Location | I13: Page/Zone
A14: XT0833:8 | B14: JC | C14: AT0140G1 | D14: CLIP | E14: --- | F14: 107.A3 | G14: XT0833:9 | H14: JB72 | I14: 107.B3 | M14: USED
A15: XT0834:13 | B15: JC | C15: EXC0 | D15: CLIP | E15: --- | F15: 107.C3 | G15: XT0834:14 | H15: JB72 | I15: 107.C3 | M15: USED
A16: XT0834:15 | B16: JC | C16: EXC2 | D16: CLIP | E16: --- | F16: 107.C3 | G16: XT0834:16 | H16: JB72 | I16: 107.C3 | M16: USED
A17: XT0834:17 | B17: JC | C17: EXCS | D17: CLIP | E17: --- | F17: 107.C3 | G17: XT0834:18 | H17: JB72 | I17: 107.C3 | M17: USED
A18: KA7200:11 | B18: SC | C18: FU7200 | D18: BLU | E18: 16 | F18: 11.D3 | G18: FU7200:LD | H18: JB72 | I18: 11.D3 | M18: USED
A19: FU7200:LI | B19: SC | C19: CCH7200L1 | D19: BLU | E19: 16 | F19: 11.D3 | G19: XT7200:1 | H19: JB72 | I19: 11.D2 | M19: USED
A20: GR4141: | B20: SC | C20: GR4141 | D20: GRN/YEL | E20: 14 | F20: 4.D6 | G20: FG61:1 | H20: JB72 | I20: 4.D7 | M20: USED
A21: GR4142: | B21: SC | C21: GR4142 | D21: GRN/YEL | E21: 14 | F21: 4.D6 | G21: FG61:2 | H21: JB72 | I21: 4.D7 | M21: USED
A22: GR4181: | B22: SC | C22: GR4181 | D22: GRN/YEL | E22: 14 | F22: 4.D6 | G22: FG61:3 | H22: JB72 | I22: 4.D6 | M22: USED
A23: KA7200:21 | B23: SC | C23: CCH7200L2 | D23: BLU | E23: 16 | F23: 11.D3 | G23: XT7200:2 | H23: JB72 | I23: 11.D2 | M23: USED
