Workbook

Sheet Blue Labels
A1: (SHT 1) ASSEMBLY CONSOLE | B1: (SHT 10) ASSEMBLY^CONTROL PANEL | C1: (SHT 11) 2 BAY LEFT WALL | D1: (SHT 12) 2 BAY BACK LEFT WALL | E1: (SHT 13) 2 BAY BACK RIGHT PANEL | F1: (SHT 14) 2 BAY RIGHT WALL | G1: (SHT 15) ORBIT 60^DOOR PANEL | H1: (SHT 2) CONSOLE DOOR^PANEL | I1: (SHT 4) METER PANEL | J1: (SHT 5) SWITCH PANEL | K1: (SHT 6) 1 BAY LEFT WALL | L1: (SHT 7) 1 BAY BACK WALL | M1: (SHT 8) 1 BAY RIGHT WALL | N1: (SHT 9) PWR,DISTRIBUTION RAIL^LEFT DOOR
A2: EL0274 | B2: SH0412 | C2: IEG8210 | D2: IEG8220 | E2: IEG8230 | F2: IEG8240 | G2: AR0610 | H2: GF4000 | I2: PA0703 | J2: HL0704 | K2: AT0140 | L2: XT-9103 | M2: IEG8130 | N2: AT0680
A3: EL0273 | B3: SH0411 | C3: XT-9201 | D3: XT-9220 | E3: XT0080 | F3: XT-9350 | G3: AP0629 | H3: GF4000 | I3: PV0700 | J3: HL0703 | K3: AT0220 | L3: XT-9104 | M3: FU0031 | N3: XT0680
A4: HA0273 | B4: SH0405 | C4: XT-9202 | D4: XT-9221 | E4: FU0080 | F4: XT-9355 | G4: AP0628 | H4: GF4000 | I4: PA0700 | J4: HL0702 | K4: XT0341 | L4: XT9008 | M4: XT0031 | N4: XT0560
A5: ZS0273 | B5: SH0404 | C5: XT-9203 | D5: XT-9221A | E5: FU0081 | F5: XT-9360 | G5: AP0627 | H5: GF4000 | I5: PA0771 | J5: HL0701 | K5: XT0342 | L5: XT9015 | M5: FU0032 | N5: FU0680
A6: ZS0274 | B6: SA0400 | C6: XT-9204 | D6: XT-9222 | E6: FU0082 | F6: XT-9370 | G6: AP0626 | H6: GF4000 | I6: PV0701 | J6: SA0770 | K6: GR9111 | L6: XT-9107 | M6: XT0032 | N6: FU0560
A7: FG0000 | B7: SH0410 | C7: XT-9205 | D7: XT-9222A | E7: XT0090 | F7: XT-9380 | G7: AP0625 | H7: GF4000 | I7: PA0701 | J7: SA0710 | K7: XT0930 | L7: GR9123 | M7: XT0085 | N7: FU0200
A8: 24Y | B8: SH0401 | C8: XT-9206 | D8: XT-9223 | E8: FU0090 | F8: XT-9381 | G8: AP0624 | H8: TM0102 | I8: PF0701 | J8: SA0740 | K8: XT0340 | L8: XT-9110 | M8: FU0332 | N8: FU0201
B9: SH0400 | C9: XT-9207 | D9: XT-9223A | E9: FU0091 | F9: GR9242 | G9: AP0623 | H9: AT0190K | J9: PF0700 | K9: XT0343 | L9: XT-9113 | M9: FU0333 | N9: FU0190
B10: XT0564 | C10: XT-9208 | D10: XT-9242 | E10: FU0092 | F10: XT-9331 | G10: AP0622 | H10: AT0190 | J10: SA0700 | K10: XT-9390 | L10: XT-9105 | M10: FU0334 | N10: FU0273
B11: AU0200 | C11: XT-9209 | D11: XT-9270 | E11: FU0093 | F11: XT-9334 | G11: AP0621 | J11: SA0701 | K11: GR9112 | L11: XT-9106 | M11: FU0335 | N11: XT0561
B12: HL0411 | C12: GR9211 | D12: XT-9271 | E12: XT0171 | F12: XT-9335 | G12: AP0620 | K12: KA0364 | L12: XT-9114 | M12: XT0332 | N12: XT0562
B13: HL0410 | C13: HIEG8210 | D13: XT-9290 | E13: KA0130 | F13: XT-9336 | G13: AP0619 | L13: XT-9115 | M13: XT0334 | N13: XT0563
B14: HL0409 | C14: PC0470 | D14: XT-9291 | E14: KA0176 | F14: XT-9337 | G14: AP0618 | L14: XT-9116 | M14: XT0335
B15: HL0408 | C15: PC0471 | D15: GR9222 | E15: KA0177 | F15: XT-9338 | G15: AP0617 | L15: XT-9117 | M15: XT0336
B16: HL0407 | C16: FU0136 | D16: HIEG8220 | E16: KA0221 | F16: XT-9338A | G16: AP0616 | L16: XT-9118 | M16: XT0337
B17: SB0400 | C17: XT0138 | D17: XT-9210 | E17: KA0222 | F17: GR9241 | G17: AP0615 | L17: XT-9120 | M17: KA0310
B18: HL0406 | C18: FU0137 | D18: XT-9211 | E18: KA0224 | F18: XT0110 | G18: AP0614 | L18: XT-9150 | M18: KA0320
B19: HL0405 | C19: XT0139 | D19: XT-9212 | E19: KA0225 | F19: FU0110 | G19: AP0613 | L19: XT-9127 | M19: KA0330
B20: HL0404 | C20: FU0210 | D20: XT-9214 | E20: KA0701 | F20: FU0111 | G20: AP0612 | L20: GR9121 | M20: KA0331
B21: HL0403 | C21: FU0170 | D21: XT-9215 | E21: KA076E | F21: FU0112 | G21: UV0610 | L21: RS0106 | M21: KA0332
B22: HL0402 | C22: XT0233 | D22: XT-9216 | E22: KA0817 | F22: XT0050 | G22: UV0611 | L22: XT0106 | M22: KA0333
B23: HL0401 | C23: FU0010 | D23: XT-9217 | E23: KA0870 | F23: FU0050 | L23: KA121C | M23: KA0335
B24: HL0400 | C24: FU0139 | D24: XT-9218 | E24: KA0871 | F24: FU0051 | L24: KA0135 | M24: KA0336
B25: SB0408 | C25: FU0211 | D25: XT-9219 | E25: KA0923 | F25: FU0052 | L25: KA3103 | M25: KA0337
B26: SB0407 | C26: FU0212 | D26: XT-9219A | E26: KA0924 | F26: FU0053 | L26: KA3420 | M26: XT0130
B27: SH0408 | C27: FU0271 | D27: GR9221 | E27: KA0925 | F27: FU0054 | L27: KA4100 | M27: XT0120
B28: SB0405 | C28: SPARE | D28: UV0291 | E28: KA0927 | F28: FU0055 | L28: KA6211 | M28: FU0120
B29: SB0406 | C29: FU0274 | D29: UAI9220-1 | E29: KA0929 | F29: XT0060 | L29: KA6212 | M29: FU0121
B30: SA0401 | C30: FU0281 | D30: UAI9221-1 | E30: KA093A | F30: FU0060 | L30: KA121A | M30: AF0123
B31: SB0404 | C31: FU0291 | D31: UAI9221-2 | E31: KA0936 | F31: FU0061 | L31: GR9122 | M31: AF0122
B32: SB0403 | C32: XT0134 | D32: UAI9221-3 | E32: KA0937 | F32: FU0062 | L32: VD0121 | M32: AF0121
B33: SB0402 | C33: XT0135 | D33: UAI9221-4 | E33: KA0938 | F33: FU0063 | L33: VD0122 | M33: AU0120
B34: SB0401 | C34: XT0235 | D34: UAI9221-5 | E34: KA0939 | F34: FU0064 | L34: VD0123 | M34: GR8131
B35: SH0409 | C35: XT0237 | D35: UAI9221A-1 | E35: KA0942 | F35: XT0070 | L35: VD0124 | M35: PEG0130
B36: AF0201 | C36: XT0136 | D36: UAI9222-1 | E36: KA0943 | F36: FU0070 | M36: UJ0131
B37: AF0202 | C37: KA0131 | D37: UAI9222A-1 | E37: KA0944 | F37: FU0071 | M37: UJ0031
B38: GR0200 | C38: KA0132 | D38: UAI9223-1 | E38: KA1020 | F38: XT0450 | M38: QS0131
C39: KA0133 | D39: UAI9223-2 | E39: KA9982 | F39: FU0450 | M39: XT-QS0131
C40: KA0134 | D40: UAI9223-3 | E40: KA9984 | F40: AF0076 | M40: GR9132
...

Sheet White Labels
A1: (SHT 7) 1 BAY BACK WALL | B1: (SHT 7) 1 BAY BACK WALL - (SHT 6) 1 BAY LEFT WALL | C1: (SHT 7) 1 BAY BACK WALL - (SHT 8) 1 BAY RIGHT WALL | D1: (SHT 6) 1 BAY LEFT WALL | E1: (SHT 6) 1 BAY LEFT WALL - (SHT 8) 1 BAY RIGHT WALL | F1: (SHT 8) 1 BAY RIGHT WALL | G1: (SHT 8) 1 BAY RIGHT WALL - (SHT 11) 2 BAY LEFT WALL | H1: (SHT 8) 1 BAY RIGHT WALL - (SHT 15) ORBIT 60^DOOR PANEL | I1: (SHT 12) 2 BAY BACK LEFT WALL | J1: (SHT 12) 2 BAY BACK LEFT WALL - (SHT 13) 2 BAY BACK RIGHT PANEL | K1: (SHT 12) 2 BAY BACK LEFT WALL - (SHT 11) 2 BAY LEFT WALL | L1: (SHT 12) 2 BAY BACK LEFT WALL - JB70 | M1: (SHT 13) 2 BAY BACK RIGHT PANEL | N1: (SHT 13) 2 BAY BACK RIGHT PANEL - (SHT 14) 2 BAY RIGHT WALL | O1: (SHT 11) 2 BAY LEFT WALL | P1: (SHT 11) 2 BAY LEFT WALL - (SHT 10) ASSEMBLY^CONTROL PANEL | Q1: (SHT 14) 2 BAY RIGHT WALL | R1: (SHT 2) CONSOLE DOOR^PANEL
A2: GR9123 | B2: VBUSN | C2: PEG013010 | D2: GR9111 | E2: W8104 | F2: EXCS | G2: IEG8210-G | H2: PEG01301 | I2: GR9221 | J2: IEG8230-G | K2: HIEG8220-HG | L2: IEG01101 | M2: AF0083G | N2: IEG8240-G | O2: HIEG8210-1 | P2: IEG8210-1 | Q2: AF0055G | R2: GF4000-A13
C3: W8003 | E3: W8202 | F3: GR9131 | H3: PEG01302 | I3: GR9222 | K3: IEG8220-G | M3: AF0084G | O3: HIEG8210-2 | Q3: AF0056G
C4: W8004 | E4: W8203 | F4: IEG8130-1 | I4: GR9224 | M4: AF0085G | Q4: AF0064G
C5: W8101 | E5: W8301 | F5: IEG8130-2 | I5: HIEG8220-1 | M5: GR9231 | Q5: AF0065G
C6: W8102 | F6: PMGS | I6: HIEG8220-2 | M6: GR9232 | Q6: AF0066G
F7: W8103 | I7: HIEG8220-3 | M7: GR9233 | Q7: AF0071G
F8: W8201 | I8: HIEG8220-4 | M8: IEG8230-1 | Q8: AF0072G
M9: IEG8230-2 | Q9: AF0073G
M10: IEG8230-3 | Q10: AF0074G
M11: IEG8230-4 | Q11: GR9241
M12: UV0600G | Q12: GR9242
Q13: IEG02304
Q14: IEG02305
Q15: IEG8240-1
Q16: IEG8240-2
Q17: IEG8240-3
Q18: IEG8240-6

Sheet Heat Shrink Labels
A1: (SHT 7) 1 BAY BACK WALL | B1: (SHT 7) 1 BAY BACK WALL - (SHT 6) 1 BAY LEFT WALL | C1: (SHT 7) 1 BAY BACK WALL - (SHT 4) METER PANEL | D1: (SHT 6) 1 BAY LEFT WALL | E1: (SHT 6) 1 BAY LEFT WALL - (SHT 4) METER PANEL | F1: (SHT 12) 2 BAY BACK LEFT WALL | G1: (SHT 12) 2 BAY BACK LEFT WALL - (SHT 13) 2 BAY BACK RIGHT PANEL | H1: (SHT 12) 2 BAY BACK LEFT WALL - (SHT 14) 2 BAY RIGHT WALL | I1: (SHT 12) 2 BAY BACK LEFT WALL - (SHT 15) ORBIT 60^DOOR PANEL | J1: (SHT 13) 2 BAY BACK RIGHT PANEL - (SHT 11) 2 BAY LEFT WALL | K1: (SHT 13) 2 BAY BACK RIGHT PANEL - (SHT 14) 2 BAY RIGHT WALL | L1: (SHT 11) 2 BAY LEFT WALL | M1: (SHT 11) 2 BAY LEFT WALL - (SHT 14) 2 BAY RIGHT WALL | N1: (SHT 11) 2 BAY LEFT WALL - (SHT 15) ORBIT 60^DOOR PANEL | O1: (SHT 14) 2 BAY RIGHT WALL
A2: W4000 | B2: W8164 | C2: W8064 | D2: WC8008 | E2: W8065 | F2: WI0554 | G2: W0832 | H2: W0554 | I2: W6163 | J2: W0831 | K2: W0570 | L2: WI0680 | M2: W0680 | N2: W6161 | O2: W0552
B3: W8165 | D3: WC8009 | F3: WI0556 | G3: W0834 | H3: W0556 | I3: W6224 | J3: W0833 | K3: W0571 | L3: WI0681 | M3: W0681 | N3: W6171 | O3: W0553
B4: W8264 | F4: WI0557 | G4: W0837 | H4: W0557 | I4: W6241 | J4: W0835 | K4: W0572 | L4: WI0682 | M4: W0682 | N4: W6172 | O4: W0643
F5: WI0560 | G5: W0843 | H5: W0560 | I5: W6242 | J5: W0836 | K5: W0573 | L5: WI0683 | M5: W0683 | N5: W6173 | O5: W0646
F6: WI0561 | G6: W0844 | H6: W0561 | I6: W6243 | J6: W0840 | K6: W0710 | L6: WI0684 | M6: W0684 | N6: W6174 | O6: W0663
F7: WI0562 | G7: W0845 | H7: W0562 | I7: W6244 | J7: W0841 | K7: W0857 | L7: WI0685 | M7: W0685 | N7: W6181 | O7: W0665
F8: WI0563 | G8: W0846 | H8: W0563 | J8: W0842 | K8: W0860 | L8: WI0686 | M8: W0686 | N8: W6182 | O8: W0720
F9: WI0565 | G9: W0852 | H9: W0565 | K9: W0866 | L9: WI0730 | M9: W0730 | N9: W6211 | O9: W0741
F10: WI0640 | G10: W0853 | H10: W0640 | K10: WC4191 | L10: WI0731 | M10: W0731 | N10: W6213 | O10: W0742
F11: WI0641 | G11: W0854 | H11: W0641 | K11: WC4681 | L11: WI0732 | M11: W0732 | O11: W0743
F12: WI0642 | G12: W0855 | H12: W0642 | K12: WC4682 | L12: WI0733 | M12: W0733 | O12: WC4190
F13: WI0650 | G13: W0856 | H13: W0650 | L13: WI0734 | M13: W0734
F14: WI0722 | G14: W0861 | H14: W0722 | L14: WI0735 | M14: W0735
F15: WI0723 | G15: W0863 | H15: W0723 | L15: WI0736 | M15: W0736
F16: WI0750 | G16: W0864 | H16: W0750 | L16: WI0746 | M16: W0746
F17: WI0751 | H17: W0751 | L17: WI0747 | M17: W0747
F18: WI0752 | H18: W0752 | L18: WI0831
F19: WI0753 | H19: W0753 | L19: WI0833
F20: WI0813A | H20: W4501 | L20: WI0835
F21: WI0814A | L21: WI0836
F22: WI0814B | L22: WI0840
F23: WI0816A | L23: WI0841
F24: WI0820 | L24: WI0842
F25: WI0821 | L25: WI6161
F26: WI0826A | L26: WI6171
F27: WI0826B | L27: WI6172
F28: WI0832 | L28: WI6173
F29: WI0834 | L29: WI6174
F30: WI0837 | L30: WI6181
F31: WI0843 | L31: WI6182
F32: WI0844 | L32: WI6211
F33: WI0845 | L33: WI6213
F34: WI0846
F35: WI0851
F36: WI0852
F37: WI0853
F38: WI0854
F39: WI0855
F40: WI0856
...

Sheet 1 BAY BACK WALL
A1: 1 BAY BACK WALL
A3: Project # | B3: G9440
A4: Project Name | B4: NOC AL SHAHEEN T130
A5: Revision | B5: A.5
A7: Controls DE | B7: G. Colby
A8: Phone:
A9: Controls ME | B9: R. Duran
A10: Phone:
A12: From | G12: To
A13: Device ID | B13: Cable (W) Conductor (SC) Jumper Clip (JC) | C13: Wire No. | D13: Wire ID | E13: Gauge/Size | F13: Page/Zone | G13: Device ID | H13: Location | I13: Page/Zone
A14: XT-9103:1 | B14: JC | C14: EXC0 | D14: CLIP | E14: --- | F14: 102.C4 | G14: XT-9103:2 | H14: 1 BAY BACK WALL | I14: 102.C4 | M14: USED
A15: XT-9103:5 | B15: JC | C15: EXC2 | D15: CLIP | E15: --- | F15: 102.C4 | G15: XT-9103:4 | H15: 1 BAY BACK WALL | I15: 102.C5 | M15: USED
A16: XT-9103:6 | B16: JC | C16: EXCS | D16: CLIP | E16: --- | F16: 102.C4 | G16: XT-9103:7 | H16: 1 BAY BACK WALL | I16: 102.C5 | M16: USED
A17: XT-9106:2 | B17: JC | C17: CCT1(+) | D17: CLIP | E17: --- | F17: 103.B4 | G17: XT-9106:1 | H17: 1 BAY BACK WALL | I17: 103.B4 | M17: USED
A18: XT-9106:4 | B18: JC | C18: CCT1(-) | D18: CLIP | E18: --- | F18: 103.B4 | G18: XT-9106:3 | H18: 1 BAY BACK WALL | I18: 103.B4 | M18: USED
A19: XT-9110:1 | B19: JC | C19: VGENA | D19: CLIP | E19: --- | F19: 100.D4 | G19: XT-9110:2 | H19: 1 BAY BACK WALL | I19: 100.D4 | M19: USED
A20: XT-9110:3 | B20: JC | C20: VGENB | D20: CLIP | E20: --- | F20: 100.D4 | G20: XT-9110:4 | H20: 1 BAY BACK WALL | I20: 100.D4 | M20: USED
A21: XT-9110:5 | B21: JC | C21: VGENC | D21: CLIP | E21: --- | F21: 100.D4 | G21: XT-9110:6 | H21: 1 BAY BACK WALL | I21: 100.D4 | M21: USED
A22: XT-9113:1 | B22: JC | C22: VBUSA | D22: CLIP | E22: --- | F22: 100.B4 | G22: XT-9113:2 | H22: 1 BAY BACK WALL | I22: 100.B4 | M22: USED
A23: XT-9113:3 | B23: JC | C23: VBUSB | D23: CLIP | E23: --- | F23: 100.B4 | G23: XT-9113:4 | H23: 1 BAY BACK WALL | I23: 100.B4 | M23: USED
A24: XT-9113:5 | B24: JC | C24: VBUSC | D24: CLIP | E24: --- | F24: 100.B4 | G24: XT-9113:6 | H24: 1 BAY BACK WALL | I24: 100.B4 | M24: USED
A25: XT-9113:7 | B25: JC | C25: VBUSN | D25: CLIP | E25: --- | F25: 100.B4 | G25: XT-9113:8 | H25: 1 BAY BACK WALL | I25: 100.B4 | M25: USED
... A47: VD0123:- | B47: SC | C47: VD0124 | D47: WHT | E47: 12 | F47: 102.D4 | G47: VD0124:+ | H47: 1 BAY BACK WALL | I47: 102.D4 | M47: USED
A48: VD0124:- | B48: SC | C48: EXC0 | F48: 102.D4 | G48: XT-9103:1 | H48: 1 BAY BACK WALL | I48: 102.C4 | M48: USED
A49: XT-9103:2 | B49: SC | C49: EXC0 | F49: 102.C4 | G49: XT-9103:1 | H49: 1 BAY BACK WALL | I49: 102.C4 | M49: USED
A50: XT-9105:3 | B50: W4000 | C50: RE4000-S | D50: SH | E50: 16 | F50: 105.A4 | G50: FG-GF4000:2 | H50: 1 BAY BACK WALL | I50: 105.B5 | M50: USED
A51: XT-9106:1 | B51: SC | C51: CCT1(+) | D51: BLU | E51: 12 | F51: 103.B4 | G51: AT0220:33 ID RES(+) | H51: 1 BAY LEFT WALL | I51: 103.D7 | M51: USED
A52: XT-9106:2 | B52: SC | C52: CCT1(+) | D52: BLU | E52: 12 | F52: 103.B4 | G52: AT0220:27 ID RLY | H52: 1 BAY LEFT WALL | I52: 103.D7 | M52: USED
A53: XT-9106:3 | B53: SC | C53: CCT1(-) | D53: BLU | E53: 12 | F53: 103.B4 | G53: AT0140:43 ID(-) | H53: 1 BAY LEFT WALL | I53: 103.C7 | M53: USED
A54: XT-9106:4 | B54: SC | C54: CCT1(-) | D54: BLU | E54: 12 | F54: 103.B4 | G54: AT0140:28 ID RLY | H54: 1 BAY LEFT WALL | I54: 103.C7 | M54: USED
A55: XT-9110:1 | B55: SC | C55: VGENA | D55: RED | E55: 16 | F55: 100.D4 | G55: AT0140:13 VGEN-A | H55: 1 BAY LEFT WALL | I55: 100.D7 | M55: USED
A56: XT-9110:1 | B56: SC | C56: VGENA | D56: RED | E56: 16 | F56: 100.D4 | G56: AT0220:13 VGEN-A | H56: 1 BAY LEFT WALL | I56: 100.C7 | M56: USED
A57: XT-9110:2 | B57: SC | C57: VGENA | D57: RED | E57: 16 | F57: 100.D4 | G57: XT0341:7 | H57: 1 BAY LEFT WALL | I57: 21.D2 | M57: USED
A58: XT-9110:3 | B58: SC | C58: VGENB | D58: RED | E58: 16 | F58: 100.D4 | G58: AT0140:14 VGEN-B | H58: 1 BAY LEFT WALL | I58: 100.D7 | M58: USED
A59: XT-9110:3 | B59: SC | C59: VGENB | D59: RED | E59: 16 | F59: 100.D4 | G59: AT0220:14 VGEN-B | H59: 1 BAY LEFT WALL | I59: 100.C7 | M59: USED
A60: XT-9110:4 | B60: SC | C60: VGENB | D60: RED | E60: 16 | F60: 100.D4 | G60: XT0341:4 | H60: 1 BAY LEFT WALL | I60: 21.D2 | M60: USED
A61: XT-9110:4 | B61: SC | C61: VGENB | D61: RED | E61: 16 | F61: 100.D4 | G61: KA0364:2 | H61: 1 BAY LEFT WALL | I61: 21.C1 | M61: USED
... A140: KA121A:11 | B140: SC | C140: VGENC | D140: RED | E140: 16 | F140: 21.B6 | G140: SA0770:24 | H140: SWITCH PANEL | I140: 21.B6 | M140: USED
F142: SolarTools ver. 24.0.84.26264 (Jun 3, 2025)
A143: Report date: 7/10/2025 2:58 PM

Sheet 1 BAY LEFT WALL
A1: 1 BAY LEFT WALL
A3: Project # | B3: G9440
A4: Project Name | B4: NOC AL SHAHEEN T130
A5: Revision | B5: A.5
A7: Controls DE | B7: G. Colby
A8: Phone:
A9: Controls ME | B9: R. Duran
A10: Phone:
A12: From | G12: To
A13: Device ID | B13: Cable (W) Conductor (SC) Jumper Clip (JC) | C13: Wire No. | D13: Wire ID | E13: Gauge/Size | F13: Page/Zone | G13: Device ID | H13: Location | I13: Page/Zone
A14: XT0341:4 | B14: JC | C14: VGENB | D14: CLIP | E14: --- | F14: 21.D2 | G14: XT0341:5 | H14: 1 BAY LEFT WALL | I14: 21.D2 | M14: USED
A15: AT0140:27 ID RLY | B15: SC | C15: AT022028 | D15: BLU | E15: 12 | F15: 103.C7 | G15: AT0220:28 ID RLY | H15: 1 BAY LEFT WALL | I15: 103.D7 | M15: USED
A16: AT0140:33 ID RES(+) | B16: SC | C16: AT022043 | D16: BLU | E16: 12 | F16: 103.C7 | G16: AT0220:43 ID(-) | H16: 1 BAY LEFT WALL | I16: 103.D7 | M16: USED
A17: AT0140:34 ID RES(-) | B17: SC | C17: AT014034 | D17: WHT | E17: 16 | F17: 103.C7 | G17: AT0140:42 ID(+) | H17: 1 BAY LEFT WALL | I17: 103.C7 | M17: USED
A18: AT0140:37 I1(-) | B18: SC | C18: AT0140I1(-) | D18: BLU | E18: 12 | F18: 101.B7 | G18: AT0220:36 I1(+) | H18: 1 BAY LEFT WALL | I18: 101.C7 | M18: USED
A19: AT0140:39 I2(-) | B19: SC | C19: AT0140I2(-) | D19: BLU | E19: 12 | F19: 101.B7 | G19: AT0220:38 I2(+) | H19: 1 BAY LEFT WALL | I19: 101.C7 | M19: USED
A20: AT0140:41 I3(-) | B20: SC | C20: AT0140I3(-) | D20: BLU | E20: 12 | F20: 101.B7 | G20: AT0220:40 I3(+) | H20: 1 BAY LEFT WALL | I20: 101.C7 | M20: USED
A21: AT0140:56 FG | B21: SC | C21: AT0140G | D21: GRN/YEL | E21: 12 | F21: 25.C6 | G21: FRAME | H21: 1 BAY LEFT WALL | I21: 25.C6 | M21: USED
A22: AT0220:34 ID RES(-) | B22: SC | C22: AT022034 | D22: WHT | E22: 16 | F22: 103.D7 | G22: AT0220:42 ID(+) | H22: 1 BAY LEFT WALL | I22: 103.D7 | M22: USED
A23: AT0220:37 I1(-) | B23: SC | C23: PA07716 | D23: BLU | E23: 16 | F23: 101.C7 | G23: XT0342:4 | H23: 1 BAY LEFT WALL | I23: 21.C2 | M23: USED
A24: AT0220:39 I2(-) | B24: SC | C24: SA074013 | D24: BLU | E24: 16 | F24: 101.C7 | G24: XT0342:3 | H24: 1 BAY LEFT WALL | I24: 21.B3 | M24: USED
A25: AT0220:41 I3(-) | B25: SC | C25: PA07035 | D25: BLU | E25: 16 | F25: 101.C7 | G25: XT0342:1 | H25: 1 BAY LEFT WALL | I25: 21.A2 | M25: USED
... A139: XT0343:4 | B139: SC | C139: KA0330A1 | D139: WHT | E139: 16 | F139: 20.C5 | G139: HL0702:A+ | H139: SWITCH PANEL | I139: 20.C2 | M139: USED
A141: Report date: 7/10/2025 2:58 PM | F141: SolarTools ver. 24.0.84.26264 (Jun 3, 2025)

Sheet 1 BAY RIGHT WALL
A1: 1 BAY RIGHT WALL
A3: Project # | B3: G9440
A4: Project Name | B4: NOC AL SHAHEEN T130
A5: Revision | B5: A.5
A7: Controls DE | B7: G. Colby
A8: Phone:
A9: Controls ME | B9: R. Duran
A10: Phone:
A12: From | G12: To
A13: Device ID | B13: Cable (W) Conductor (SC) Jumper Clip (JC) | C13: Wire No. | D13: Wire ID | E13: Gauge/Size | F13: Page/Zone | G13: Device ID | H13: Location | I13: Page/Zone
A14: XT0031:2 | B14: JC | C14: 24V | D14: CLIP | E14: --- | F14: 15.D5 | G14: XT0031:1 | H14: 1 BAY RIGHT WALL | I14: 15.D5 | M14: USED
A15: XT0031:4 | B15: JC | C15: 0V | D15: CLIP | E15: --- | F15: 15.D5 | G15: XT0031:3 | H15: 1 BAY RIGHT WALL | I15: 15.D5 | M15: USED
A16: XT0032:1 | B16: JC | C16: 24V | D16: CLIP | E16: --- | F16: 15.C5 | G16: XT0032:2 | H16: 1 BAY RIGHT WALL | I16: 15.C5 | M16: USED
A17: XT0032:3 | B17: JC | C17: 0V | D17: CLIP | E17: --- | F17: 15.C5 | G17: XT0032:4 | H17: 1 BAY RIGHT WALL | I17: 15.C5 | M17: USED
A18: XT0085:3 | B18: JC | C18: 0V | D18: CLIP | E18: --- | F18: 15.C6 | G18: XT0085:4 | H18: 1 BAY RIGHT WALL | I18: 15.C6 | M18: USED
A19: XT0085:4 | B19: JC | C19: 0V | D19: CLIP | E19: --- | F19: 15.C6 | G19: XT0085:5 | H19: 1 BAY RIGHT WALL | I19: 15.C6 | M19: USED
A20: XT0120:1 | B20: JC | C20: 0V | D20: CLIP | E20: --- | F20: 25.D1 | G20: XT0120:2 | H20: 1 BAY RIGHT WALL | I20: 25.D1 | M20: USED
A21: XT0130:3 | B21: JC | C21: 0V | D21: CLIP | E21: --- | F21: 25.A5 | G21: XT0130:2 | H21: 1 BAY RIGHT WALL | I21: 25.A5 | M21: USED
A22: XT0336:2 | B22: JC | C22: 0V | D22: CLIP | E22: --- | F22: 24.C4 | G22: XT0336:3 | H22: 1 BAY RIGHT WALL | I22: 24.C4 | M22: USED
A23: XT0336:3 | B23: JC | C23: 0V | D23: CLIP | E23: --- | F23: 24.C4 | G23: XT0336:4 | H23: 1 BAY RIGHT WALL | I23: 24.D4 | M23: USED
A24: XT0336:4 | B24: JC | C24: 0V | D24: CLIP | E24: --- | F24: 24.D4 | G24: XT0336:5 | H24: 1 BAY RIGHT WALL | I24: 24.D4 | M24: USED
A25: KA0121:A1 | B25: SC | C25: 012101 | D25: WHT | E25: 20 | F25: 27.A7 | G25: AF0121:01 | H25: 1 BAY RIGHT WALL | I25: 27.A5 | M25: USED
... A37: AF0121:COM | B37: SC | C37: 0V | D37: WHT | E37: 14 | F37: 25.D2 | G37: XT0120:2 | H37: 1 BAY RIGHT WALL | I37: 25.D1 | M37: USED
A38: AF0121:J | B38: SC | C38: * | F38: 25.D2 | G38: AF0122:P | H38: 1 BAY RIGHT WALL | I38: 25.D3 | M38: USED
A39: AF0121:P | B39: SC | C39: * | F39: 25.D2 | G39: AU0120:J | H39: 1 BAY RIGHT WALL | I39: 25.C1 | M39: USED
A40: AF0121:V+ | B40: SC | C40: FU0121 | D40: WHT | E40: 14 | F40: 25.D2 | G40: FU0121:LD | H40: 1 BAY RIGHT WALL | I40: 25.D1 | M40: USED
A41: KA0330:11 | B41: SC | C41: 012200 | D41: WHT | E41: 20 | F41: 29.A7 | G41: AF0122:00 | H41: 1 BAY RIGHT WALL | I41: 29.A6 | M41: USED
A42: KA0331:11 | B42: SC | C42: 012201 | D42: WHT | E42: 20 | F42: 29.A7 | G42: AF0122:01 | H42: 1 BAY RIGHT WALL | I42: 29.A6 | M42: USED
A43: KA0310:11 | B43: SC | C43: 012202 | D43: WHT | E43: 20 | F43: 29.B7 | G43: AF0122:02 | H43: 1 BAY RIGHT WALL | I43: 29.B6 | M43: USED
A44: KA0320:11 | B44: SC | C44: 012208 | D44: WHT | E44: 20 | F44: 29.B7 | G44: AF0122:08 | H44: 1 BAY RIGHT WALL | I44: 29.B6 | M44: USED
A45: AF0122:12 | B45: SC | C45: UJ0131OK2 | D45: WHT | E45: 20 | F45: 15.B7 | G45: UJ0131:OK2 | H45: 1 BAY RIGHT WALL | I45: 15.B4 | M45: USED
A46: AF0122:13 | B46: SC | C46: UJ0031OK2 | D46: WHT | E46: 20 | F46: 15.D7 | G46: UJ0031:OK2 | H46: 1 BAY RIGHT WALL | I46: 15.D4 | M46: USED
A47: KA0330:14 | B47: SC | C47: 012232 | D47: WHT | E47: 20 | F47: 29.A7 | G47: AF0122:32 | H47: 1 BAY RIGHT WALL | I47: 29.A6 | M47: USED
A48: KA0331:14 | B48: SC | C48: 012233 | D48: WHT | E48: 20 | F48: 29.A7 | G48: AF0122:33 | H48: 1 BAY RIGHT WALL | I48: 29.A6 | M48: USED
A49: KA0310:14 | B49: SC | C49: 012234 | D49: WHT | E49: 20 | F49: 29.B7 | G49: AF0122:34 | H49: 1 BAY RIGHT WALL | I49: 29.B6 | M49: USED
A50: KA0320:14 | B50: SC | C50: 012240 | D50: WHT | E50: 20 | F50: 29.B7 | G50: AF0122:40 | H50: 1 BAY RIGHT WALL | I50: 29.B6 | M50: USED
A51: AF0122:44 | B51: SC | C51: UJ0131OK1 | D51: WHT | E51: 20 | F51: 15.B7 | G51: UJ0131:OK1 | H51: 1 BAY RIGHT WALL | I51: 15.B4 | M51: USED
... A54: AF0122:COM | B54: SC | C54: AU0120N | D54: WHT | E54: 16 | F54: 25.D3 | G54: AU0120:COM | H54: 1 BAY RIGHT WALL | I54: 25.C1 | M54: USED
A55: AF0122:J | B55: SC | C55: * | F55: 25.D3 | G55: AF0123:P | H55: 1 BAY RIGHT WALL | I55: 25.D3 | M55: USED
A56: AF0122:V+ | B56: SC | C56: AF0122P | D56: WHT | E56: 16 | F56: 25.D3 | G56: AF0123:V+ | H56: 1 BAY RIGHT WALL | I56: 25.D3 | M56: USED
...

Sheet 2 BAY BACK LEFT WALL
A1: 2 BAY BACK LEFT WALL
A3: Project # | B3: G9440
A4: Project Name | B4: NOC AL SHAHEEN T130
A5: Revision | B5: A.5
A7: Controls DE | B7: G. Colby
A8: Phone:
A9: Controls ME | B9: R. Duran
A10: Phone:
A12: From | G12: To
A13: Device ID | B13: Cable (W) Conductor (SC) Jumper Clip (JC) | C13: Wire No. | D13: Wire ID | E13: Gauge/Size | F13: Page/Zone | G13: Device ID | H13: Location | I13: Page/Zone
A14: XT-9216:5 | B14: SC | C14: JP100 | D14: VIO | E14: 20 | F14: 34.C4 | G14: XT-9216:4 | H14: 2 BAY BACK LEFT WALL | I14: 34.C4 | M14: USED
A15: GR9221: | B15: SC | C15: GR9221 | D15: GRN/YEL | E15: 14 | F15: 4.C4 | G15: FG0003:1 | H15: 2 BAY BACK LEFT WALL | I15: 4.C3 | M15: USED
A16: GR9222: | B16: SC | C16: GR9222 | D16: GRN/YEL | E16: 14 | F16: 4.C4 | G16: FG0004:1 | H16: 2 BAY BACK LEFT WALL | I16: 4.C4 | M16: USED
A17: GR9223: | B17: SC | C17: GR9223 | D17: GRN/YEL | E17: 14 | F17: 4.C5 | G17: FRAME | H17: 2 BAY BACK LEFT WALL | I17: 4.C5 | M17: USED
A18: GR9224: | B18: SC | C18: GR9224 | D18: GRN/YEL | E18: 14 | F18: 4.C4 | G18: FG0003:2 | H18: 2 BAY BACK LEFT WALL | I18: 4.C3 | M18: USED
A19: HIEG8220:1 | B19: SC | C19: HIEG8220-1 | D19: GRN | E19: 14 | F19: 16.C1 | G19: UV0281:IE | H19: 2 BAY BACK LEFT WALL | I19: 16.C1 | M19: USED
A20: HIEG8220:2 | B20: SC | C20: HIEG8220-2 | D20: GRN | E20: 14 | F20: 16.C1 | G20: UV0282:IE | H20: 2 BAY BACK LEFT WALL | I20: 16.C1 | M20: USED
A21: HIEG8220:3 | B21: SC | C21: HIEG8220-3 | D21: GRN | E21: 14 | F21: 16.D1 | G21: UV0291:IE | H21: 2 BAY BACK LEFT WALL | I21: 16.D1 | M21: USED
A22: HIEG8220:4 | B22: SC | C22: HIEG8220-4 | D22: GRN | E22: 14 | F22: 16.D1 | G22: UV0292:IE | H22: 2 BAY BACK LEFT WALL | I22: 16.D1 | M22: USED
A23: UAI9221-1:1 | B23: SC | C23: TE42103 | D23: WHT | E23: 20 | F23: 85.A5 | G23: UAI9221-1:2 | H23: 2 BAY BACK LEFT WALL | I23: 85.A5 | M23: USED
A24: UAI9221-2:1 | B24: SC | C24: TE42133 | D24: WHT | E24: 20 | F24: 85.B5 | G24: UAI9221-2:2 | H24: 2 BAY BACK LEFT WALL | I24: 85.B5 | M24: USED
A25: UAI9221-3:1 | B25: SC | C25: TE42163 | D25: WHT | E25: 20 | F25: 85.C5 | G25: UAI9221-3:2 | H25: 2 BAY BACK LEFT WALL | I25: 85.C5 | M25: USED
... A382: FLOATING | B382: W6244 | C382: 0624SHLD4 | D382: SH | E382: 20 | F382: 89.C6 | G382: AP0624:SHLD4 | H382: ORBIT 60^DOOR PANEL | I382: 89.C6 | M382: USED
F384: SolarTools ver. 24.0.84.26264 (Jun 3, 2025)
A385: Report date: 7/10/2025 2:58 PM

Sheet 2 BAY BACK RIGHT PANEL
A1: 2 BAY BACK RIGHT PANEL
A3: Project # | B3: G9440
A4: Project Name | B4: NOC AL SHAHEEN T130
A5: Revision | B5: A.5
A7: Controls DE | B7: G. Colby
A8: Phone:
A9: Controls ME | B9: R. Duran
A10: Phone:
A12: From | G12: To
A13: Device ID | B13: Cable (W) Conductor (SC) Jumper Clip (JC) | C13: Wire No. | D13: Wire ID | E13: Gauge/Size | F13: Page/Zone | G13: Device ID | H13: Location | I13: Page/Zone
A14: XT0080:1 | B14: JC | C14: 0V | D14: CLIP | E14: --- | F14: 8.D1 | G14: XT0080:2 | H14: 2 BAY BACK RIGHT PANEL | I14: 8.D1 | M14: USED
A15: XT0080:2 | B15: JC | C15: 0V | D15: CLIP | E15: --- | F15: 8.D1 | G15: XT0080:3 | H15: 2 BAY BACK RIGHT PANEL | I15: 8.D1 | M15: USED
A16: XT0090:1 | B16: JC | C16: 0V | D16: CLIP | E16: --- | F16: 8.B1 | G16: XT0090:2 | H16: 2 BAY BACK RIGHT PANEL | I16: 8.B1 | M16: USED
A17: KA0130:14 | B17: SC | C17: 008103 | D17: WHT | E17: 20 | F17: 19.C7 | G17: AF0081:03 | H17: 2 BAY BACK RIGHT PANEL | I17: 19.C6 | M17: USED
A18: KA0817:14 | B18: SC | C18: 008107 | D18: WHT | E18: 20 | F18: 37.A7 | G18: AF0081:07 | H18: 2 BAY BACK RIGHT PANEL | I18: 37.A5 | M18: USED
A19: AF0081:19 | B19: SC | C19: UA1200J27 | D19: WHT | E19: 20 | F19: 19.C7 | G19: XT-9326:4 | H19: 2 BAY BACK RIGHT PANEL | I19: 19.D4 | M19: USED
A20: KA0130:A2 | B20: SC | C20: 008135 | D20: WHT | E20: 20 | F20: 19.C7 | G20: AF0081:35 | H20: 2 BAY BACK RIGHT PANEL | I20: 19.C5 | M20: USED
A21: KA0817:11 | B21: SC | C21: 008139 | D21: WHT | E21: 20 | F21: 37.A7 | G21: AF0081:39 | H21: 2 BAY BACK RIGHT PANEL | I21: 37.A5 | M21: USED
A22: AF0081:07 | B22: SC | C22: JP2 | D22: VIO | E22: 20 | F22: 37.A7 | G22: AF0081:39 | H22: 2 BAY BACK RIGHT PANEL | I22: 37.A7 | M22: USED
A23: AF0082:02 | B23: SC | C23: JP4 | D23: VIO | E23: 20 | F23: 120.A7 | G23: AF0082:34 | H23: 2 BAY BACK RIGHT PANEL | I23: 120.A7 | M23: USED
A24: AF0082:03 | B24: SC | C24: JP6 | D24: VIO | E24: 20 | F24: 120.B7 | G24: AF0082:35 | H24: 2 BAY BACK RIGHT PANEL | I24: 120.B7 | M24: USED
A25: AF0087:12 | B25: SC | C25: JP3 | D25: VIO | E25: 20 | F25: 36.B7 | G25: AF0087:44 | H25: 2 BAY BACK RIGHT PANEL | I25: 36.B7 | M25: USED
... A27: AF0081:COM | B27: SC | C27: AU0080N | D27: WHT | E27: 20 | F27: 8.C2 | G27: AU0080:COM | H27: 2 BAY BACK RIGHT PANEL | I27: 8.C2 | M27: USED
A28: AF0081:J | B28: SC | C28: * | F28: 8.C2 | G28: AF0082:P | H28: 2 BAY BACK RIGHT PANEL | I28: 8.D3 | M28: USED
A29: AF0081:P | B29: SC | C29: * | F29: 8.C2 | G29: AU0080:J | H29: 2 BAY BACK RIGHT PANEL | I29: 8.C2 | M29: USED
A30: AF0081:V+ | B30: SC | C30: AU0080P | D30: WHT | E30: 20 | F30: 8.C2 | G30: AU0080:V+ | H30: 2 BAY BACK RIGHT PANEL | I30: 8.C2 | M30: USED
A31: AF0082:COM | B31: SC | C31: 0V | D31: WHT | E31: 16 | F31: 8.D3 | G31: XT0080:2 | H31: 2 BAY BACK RIGHT PANEL | I31: 8.D1 | M31: USED
A32: AF0082:COM | B32: SC | C32: AF0082N | D32: WHT | E32: 20 | F32: 8.D3 | G32: AF0083:COM | H32: 2 BAY BACK RIGHT PANEL | I32: 8.D3 | M32: USED
A33: AF0082:J | B33: SC | C33: * | F33: 8.D3 | G33: AF0083:P | H33: 2 BAY BACK RIGHT PANEL | I33: 8.D3 | M33: USED
A34: AF0082:V+ | B34: SC | C34: FU0081 | D34: WHT | E34: 14 | F34: 8.D3 | G34: FU0081:LD | H34: 2 BAY BACK RIGHT PANEL | I34: 8.D1 | M34: USED
A35: AF0082:V+ | B35: SC | C35: AF0082P | D35: WHT | E35: 20 | F35: 8.D3 | G35: AF0083:V+ | H35: 2 BAY BACK RIGHT PANEL | I35: 8.D3 | M35: USED
A36: AF0083:COM | B36: SC | C36: AF0083N | D36: WHT | E36: 20 | F36: 8.D3 | G36: AF0084:COM | H36: 2 BAY BACK RIGHT PANEL | I36: 8.D4 | M36: USED
A37: AF0083:J | B37: SC | C37: * | F37: 8.D3 | G37: AF0084:P | H37: 2 BAY BACK RIGHT PANEL | I37: 8.D4 | M37: USED
A38: AF0083:V+ | B38: SC | C38: AF0083P | D38: WHT | E38: 20 | F38: 8.D3 | G38: AF0084:V+ | H38: 2 BAY BACK RIGHT PANEL | I38: 8.D4 | M38: USED
A39: AF0084:COM | B39: SC | C39: AF0084N | D39: WHT | E39: 20 | F39: 8.D4 | G39: AF0085:COM | H39: 2 BAY BACK RIGHT PANEL | I39: 8.D5 | M39: USED
A40: AF0084:J | B40: SC | C40: * | F40: 8.D4 | G40: AF0085:P | H40: 2 BAY BACK RIGHT PANEL | I40: 8.D5 | M40: USED
A41: AF0084:SH | B41: SC | C41: AF0083G | D41: GRN | E41: 14 | F41: 8.D4 | G41: AF0083:SH | H41: 2 BAY BACK RIGHT PANEL | I41: 8.D3 | M41: USED
A42: AF0084:SH | B42: SC | C42: AF0084G | D42: GRN | E42: 14 | F42: 8.D4 | G42: AF0085:SH | H42: 2 BAY BACK RIGHT PANEL | I42: 8.D5 | M42: USED
A43: AF0084:V+ | B43: SC | C43: AF0084P | D43: WHT | E43: 20 | F43: 8.D4 | G43: AF0085:V+ | H43: 2 BAY BACK RIGHT PANEL | I43: 8.D5 | M43: USED
A44: AF0085:COM | B44: SC | C44: AF0085N | D44: WHT | E44: 20 | F44: 8.D5 | G44: AF0086:COM | H44: 2 BAY BACK RIGHT PANEL | I44: 8.D5 | M44: USED
...

Sheet 2 BAY LEFT WALL
A1: 2 BAY LEFT WALL
A3: Project # | B3: G9440
A4: Project Name | B4: NOC AL SHAHEEN T130
A5: Revision | B5: A.5
A7: Controls DE | B7: G. Colby
A8: Phone:
A9: Controls ME | B9: R. Duran
A10: Phone:
A12: From | G12: To
A13: Device ID | B13: Cable (W) Conductor (SC) Jumper Clip (JC) | C13: Wire No. | D13: Wire ID | E13: Gauge/Size | F13: Page/Zone | G13: Device ID | H13: Location | I13: Page/Zone
A14: XT0134:1 | B14: JC | C14: 0V | D14: CLIP | E14: --- | F14: 16.B4 | G14: XT0134:2 | H14: 2 BAY LEFT WALL | I14: 16.B4 | M14: USED
A15: XT0134:2 | B15: JC | C15: 0V | D15: CLIP | E15: --- | F15: 16.B4 | G15: XT0134:3 | H15: 2 BAY LEFT WALL | I15: 16.B4 | M15: USED
A16: XT0134:3 | B16: JC | C16: 0V | D16: CLIP | E16: --- | F16: 16.B4 | G16: XT0134:4 | H16: 2 BAY LEFT WALL | I16: 16.B4 | M16: USED
A17: XT0135:1 | B17: JC | C17: 0V | D17: CLIP | E17: --- | F17: 16.B5 | G17: XT0135:2 | H17: 2 BAY LEFT WALL | I17: 16.B5 | M17: USED
A18: XT0135:2 | B18: JC | C18: 0V | D18: CLIP | E18: --- | F18: 16.B5 | G18: XT0135:3 | H18: 2 BAY LEFT WALL | I18: 16.B5 | M18: USED
A19: XT0135:3 | B19: JC | C19: 0V | D19: CLIP | E19: --- | F19: 16.B5 | G19: XT0135:4 | H19: 2 BAY LEFT WALL | I19: 16.B5 | M19: USED
A20: XT0135:4 | B20: JC | C20: 0V | D20: CLIP | E20: --- | F20: 16.B5 | G20: XT0135:5 | H20: 2 BAY LEFT WALL | I20: 16.C5 | M20: USED
A21: XT0136:1 | B21: JC | C21: FU0139 | D21: CLIP | E21: --- | F21: 17.A2 | G21: XT0136:2 | H21: 2 BAY LEFT WALL | I21: 17.A2 | M21: USED
A22: XT0138:1 | B22: JC | C22: FU0136 | D22: CLIP | E22: --- | F22: 16.A4 | G22: XT0138:2 | H22: 2 BAY LEFT WALL | I22: 16.A4 | M22: USED
A23: XT0138:2 | B23: JC | C23: FU0136 | D23: CLIP | E23: --- | F23: 16.A4 | G23: XT0138:3 | H23: 2 BAY LEFT WALL | I23: 16.A4 | M23: USED
A24: XT0138:3 | B24: JC | C24: FU0136 | D24: CLIP | E24: --- | F24: 16.A4 | G24: XT0138:4 | H24: 2 BAY LEFT WALL | I24: 16.A4 | M24: USED
A25: XT0139:1 | B25: JC | C25: FU0137 | D25: CLIP | E25: --- | F25: 16.A5 | G25: XT0139:2 | H25: 2 BAY LEFT WALL | I25: 16.A5 | M25: USED
... A571: XT0240:9 | B571: SC | C571: 0V | D571: WHT | E571: 20 | F571: 18.D3 | G571: XT0563:4 | H571: PWR,DISTRIBUTION RAIL^LEFT DOOR | I571: 14.B6 | M571: USED
F573: SolarTools ver. 24.0.84.26264 (Jun 3, 2025)
A574: Report date: 7/10/2025 2:57 PM

Sheet 2 BAY RIGHT WALL
A1: 2 BAY RIGHT WALL
A3: Project # | B3: G9440
A4: Project Name | B4: NOC AL SHAHEEN T130
A5: Revision | B5: A.5
A7: Controls DE | B7: G. Colby
A8: Phone:
A9: Controls ME | B9: R. Duran
A10: Phone:
A12: From | G12: To
A13: Device ID | B13: Cable (W) Conductor (SC) Jumper Clip (JC) | C13: Wire No. | D13: Wire ID | E13: Gauge/Size | F13: Page/Zone | G13: Device ID | H13: Location | I13: Page/Zone
A14: XT0050:1 | B14: JC | C14: 0V | D14: CLIP | E14: --- | F14: 10.B1 | G14: XT0050:2 | H14: 2 BAY RIGHT WALL | I14: 10.B1 | M14: USED
A15: XT0050:2 | B15: JC | C15: 0V | D15: CLIP | E15: --- | F15: 10.B1 | G15: XT0050:3 | H15: 2 BAY RIGHT WALL | I15: 10.B1 | M15: USED
A16: XT0060:1 | B16: JC | C16: 0V | D16: CLIP | E16: --- | F16: 9.D1 | G16: XT0060:2 | H16: 2 BAY RIGHT WALL | I16: 9.D1 | M16: USED
A17: XT0110:3 | B17: JC | C17: 0V | D17: CLIP | E17: --- | F17: 23.A6 | G17: XT0110:2 | H17: 2 BAY RIGHT WALL | I17: 23.A6 | M17: USED
A18: AF0051:COM | B18: SC | C18: 0V | D18: WHT | E18: 14 | F18: 10.B2 | G18: XT0050:2 | H18: 2 BAY RIGHT WALL | I18: 10.B1 | M18: USED
A19: AF0051:J | B19: SC | C19: * | F19: 10.B2 | G19: AF0052:P | H19: 2 BAY RIGHT WALL | I19: 10.B3 | M19: USED
A20: AF0051:P | B20: SC | C20: * | F20: 10.B2 | G20: AU0050:J | H20: 2 BAY RIGHT WALL | I20: 10.A2 | M20: USED
A21: AF0051:V+ | B21: SC | C21: FU0051 | D21: WHT | E21: 14 | F21: 10.B2 | G21: FU0051:LD | H21: 2 BAY RIGHT WALL | I21: 10.B1 | M21: USED
A22: AF0052:COM | B22: SC | C22: 0V | D22: WHT | E22: 14 | F22: 10.B3 | G22: XT0050:2 | H22: 2 BAY RIGHT WALL | I22: 10.B1 | M22: USED
A23: AF0052:J | B23: SC | C23: * | F23: 10.B3 | G23: AF0053:P | H23: 2 BAY RIGHT WALL | I23: 10.B3 | M23: USED
A24: AF0052:V+ | B24: SC | C24: FU0052 | D24: WHT | E24: 14 | F24: 10.B3 | G24: FU0052:LD | H24: 2 BAY RIGHT WALL | I24: 10.B1 | M24: USED
A25: AF0053:COM | B25: SC | C25: 0V | D25: WHT | E25: 14 | F25: 10.B3 | G25: XT0050:3 | H25: 2 BAY RIGHT WALL | I25: 10.B1 | M25: USED
A26: AF0053:J | B26: SC | C26: * | F26: 10.B3 | G26: AF0054:P | H26: 2 BAY RIGHT WALL | I26: 10.B4 | M26: USED
A27: AF0053:V+ | B27: SC | C27: FU0053 | D27: WHT | E27: 16 | F27: 10.B3 | G27: FU0053:LD | H27: 2 BAY RIGHT WALL | I27: 10.B1 | M27: USED
A28: AF0054:COM | B28: SC | C28: AU0050N | D28: WHT | E28: 16 | F28: 10.B4 | G28: AU0050:COM | H28: 2 BAY RIGHT WALL | I28: 10.A2 | M28: USED
A29: AF0054:COM | B29: SC | C29: AF0054N | D29: WHT | E29: 20 | F29: 10.B4 | G29: AF0055:COM | H29: 2 BAY RIGHT WALL | I29: 10.B5 | M29: USED
A30: AF0054:J | B30: SC | C30: * | F30: 10.B4 | G30: AF0055:P | H30: 2 BAY RIGHT WALL | I30: 10.B5 | M30: USED
A31: AF0054:V+ | B31: SC | C31: AU0050P | D31: WHT | E31: 14 | F31: 10.B4 | G31: AU0050:V+ | H31: 2 BAY RIGHT WALL | I31: 10.A2 | M31: USED
A32: AF0054:V+ | B32: SC | C32: AF0054P | D32: WHT | E32: 20 | F32: 10.B4 | G32: AF0055:V+ | H32: 2 BAY RIGHT WALL | I32: 10.B5 | M32: USED
A33: AF0055:COM | B33: SC | C33: AF0055N | D33: WHT | E33: 20 | F33: 10.B5 | G33: AF0056:COM | H33: 2 BAY RIGHT WALL | I33: 10.B5 | M33: USED
A34: AF0055:J | B34: SC | C34: * | F34: 10.B5 | G34: AF0056:P | H34: 2 BAY RIGHT WALL | I34: 10.B5 | M34: USED
A35: AF0055:SH | B35: SC | C35: IEG8240-6 | D35: GRN | E35: 14 | F35: 10.B5 | G35: IEG8240:6 | H35: 2 BAY RIGHT WALL | I35: 10.B4 | M35: USED
A36: AF0055:SH | B36: SC | C36: AF0055G | D36: GRN | E36: 16 | F36: 10.B5 | G36: AF0056:SH | H36: 2 BAY RIGHT WALL | I36: 10.B5 | M36: USED
A37: AF0055:V+ | B37: SC | C37: AF0055P | D37: WHT | E37: 20 | F37: 10.B5 | G37: AF0056:V+ | H37: 2 BAY RIGHT WALL | I37: 10.B5 | M37: USED
A38: AF0056:COM | B38: SC | C38: AF0056N | D38: WHT | E38: 20 | F38: 10.B5 | G38: AF0057:COM | H38: 2 BAY RIGHT WALL | I38: 10.B6 | M38: USED
A39: AF0056:J | B39: SC | C39: * | F39: 10.B5 | G39: AF0057:P | H39: 2 BAY RIGHT WALL | I39: 10.B6 | M39: USED
A40: AF0056:SH | B40: SC | C40: AF0056G | D40: GRN | E40: 14 | F40: 10.B5 | G40: AF0057:SH | H40: 2 BAY RIGHT WALL | I40: 10.B6 | M40: USED
A41: AF0056:V+ | B41: SC | C41: AF0056P | D41: WHT | E41: 20 | F41: 10.B5 | G41: AF0057:V+ | H41: 2 BAY RIGHT WALL | I41: 10.B6 | M41: USED
A42: AF0061:00 | B42: SC | C42: FCE1420-9 | D42: WHT | E42: 20 | F42: 45.C7 | G42: XT-9335:10 | H42: 2 BAY RIGHT WALL | I42: 45.C5 | M42: USED
A43: AF0061:08 | B43: SC | C43: FCE2140-9 | D43: WHT | E43: 20 | F43: 57.C7 | G43: XT-9334:10 | H43: 2 BAY RIGHT WALL | I43: 57.B5 | M43: USED
...

Sheet ASSEMBLY CONSOLE
A1: ASSEMBLY CONSOLE
A3: Project # | B3: G9440
A4: Project Name | B4: NOC AL SHAHEEN T130
A5: Revision | B5: A.5
A7: Controls DE | B7: G. Colby
A8: Phone:
A9: Controls ME | B9: R. Duran
A10: Phone:
A12: From | G12: To
A13: Device ID | B13: Cable (W) Conductor (SC) Jumper Clip (JC) | C13: Wire No. | D13: Wire ID | E13: Gauge/Size | F13: Page/Zone | G13: Device ID | H13: Location | I13: Page/Zone
A14: EL0273:B1 | B14: SC | C14: ZS0273 | D14: WHT | E14: 14 | F14: 11.B4 | G14: ZS0273:2 | H14: ASSEMBLY CONSOLE | I14: 11.B4 | M14: USED
A15: EL0274:B1 | B15: SC | C15: ZS0274 | D15: WHT | E15: 14 | F15: 11.C4 | G15: ZS0274:2 | H15: ASSEMBLY CONSOLE | I15: 11.C4 | M15: USED
A16: ZS0274:1 | B16: SC | C16: FU0274 | D16: WHT | E16: 14 | F16: 11.C4 | G16: FU0274:LD | H16: 2 BAY LEFT WALL | I16: 11.C3 | M16: USED
A17: HA0273:(+) | B17: WC5540 | C17: HA0273P | D17: BLK | E17: 16 | F17: 13.A1 | G17: AF0202:23 | H17: ASSEMBLY^CONTROL PANEL | I17: 13.A3 | M17: USED
A18: HA0273:(-) | B18: WC5540 | C18: HA0273N | D18: WHT | E18: 16 | F18: 13.A1 | G18: AF0202:55 | H18: ASSEMBLY^CONTROL PANEL | I18: 13.A3 | M18: USED
A19: EL0273:W1 | B19: SC | C19: 0V1 | D19: WHT | E19: 14 | F19: 11.B4 | G19: XT0562:1 | H19: PWR,DISTRIBUTION RAIL^LEFT DOOR | I19: 11.B2 | M19: USED
A20: EL0274:W1 | B20: SC | C20: 0V1 | D20: WHT | E20: 14 | F20: 11.C4 | G20: XT0562:3 | H20: PWR,DISTRIBUTION RAIL^LEFT DOOR | I20: 11.B2 | M20: USED
A21: ZS0273:1 | B21: SC | C21: FU0273 | D21: WHT | E21: 14 | F21: 11.B4 | G21: FU0273:LD | H21: PWR,DISTRIBUTION RAIL^LEFT DOOR | I21: 11.B3 | M21: USED
F23: SolarTools ver. 24.0.84.26264 (Jun 3, 2025)
A24: Report date: 7/10/2025 2:56 PM

Sheet ASSEMBLY^CONTROL PANEL
A1: ASSEMBLY^CONTROL PANEL
A3: Project # | B3: G9440
A4: Project Name | B4: NOC AL SHAHEEN T130
A5: Revision | B5: A.5
A7: Controls DE | B7: G. Colby
A8: Phone:
A9: Controls ME | B9: R. Duran
A10: Phone:
A12: From | G12: To
A13: Device ID | B13: Cable (W) Conductor (SC) Jumper Clip (JC) | C13: Wire No. | D13: Wire ID | E13: Gauge/Size | F13: Page/Zone | G13: Device ID | H13: Location | I13: Page/Zone
A14: AF0201:00 | B14: SC | C14: TCP13NO | D14: WHT | E14: 20 | F14: 14.A3 | G14: SH0400:NO | H14: ASSEMBLY^CONTROL PANEL | I14: 14.A1 | M14: USED
A15: AF0201:01 | B15: SC | C15: TCP14NO | D15: WHT | E15: 20 | F15: 14.A3 | G15: SH0401:NO | H15: ASSEMBLY^CONTROL PANEL | I15: 14.A1 | M15: USED
A16: AF0201:02 | B16: SC | C16: TCP15NO | D16: WHT | E16: 20 | F16: 14.B3 | G16: SH0409:NO | H16: ASSEMBLY^CONTROL PANEL | I16: 14.B1 | M16: USED
A17: AF0201:03 | B17: SC | C17: TCP16NO | D17: WHT | E17: 20 | F17: 14.B3 | G17: SH0410:NO | H17: ASSEMBLY^CONTROL PANEL | I17: 14.B1 | M17: USED
A18: AF0201:04 | B18: SC | C18: TCP17A2 | D18: WHT | E18: 20 | F18: 14.C3 | G18: SA0400:14 | H18: ASSEMBLY^CONTROL PANEL | I18: 14.C1 | M18: USED
A19: AF0201:05 | B19: SC | C19: TCP17B2 | D19: WHT | E19: 20 | F19: 14.C3 | G19: SA0400:22 | H19: ASSEMBLY^CONTROL PANEL | I19: 14.C1 | M19: USED
A20: AF0201:08 | B20: SC | C20: TCP23NC | D20: WHT | E20: 20 | F20: 14.D3 | G20: SB0401:NC | H20: ASSEMBLY^CONTROL PANEL | I20: 14.D1 | M20: USED
A21: AF0201:09 | B21: SC | C21: TCP24NO | D21: WHT | E21: 20 | F21: 14.D3 | G21: SB0402:NO | H21: ASSEMBLY^CONTROL PANEL | I21: 14.D1 | M21: USED
A22: AF0201:10 | B22: SC | C22: TCP25NO | D22: WHT | E22: 20 | F22: 14.A7 | G22: SB0403:NO | H22: ASSEMBLY^CONTROL PANEL | I22: 14.A5 | M22: USED
A23: AF0201:11 | B23: SC | C23: TCP26NO | D23: WHT | E23: 20 | F23: 14.A7 | G23: SB0404:NO | H23: ASSEMBLY^CONTROL PANEL | I23: 14.A5 | M23: USED
A24: AF0201:12 | B24: SC | C24: TCP29NO | D24: WHT | E24: 20 | F24: 13.D3 | G24: SB0405:NO | H24: ASSEMBLY^CONTROL PANEL | I24: 13.D1 | M24: USED
A25: AF0201:13 | B25: SC | C25: TCP28NC | D25: WHT | E25: 20 | F25: 13.C3 | G25: SB0406:NC | H25: ASSEMBLY^CONTROL PANEL | I25: 13.C1 | M25: USED
... A52: AF0201:COM | B52: SC | C52: AU0200N | D52: WHT | E52: 16 | F52: 11.A4 | G52: AU0200:COM | H52: ASSEMBLY^CONTROL PANEL | I52: 11.A3 | M52: USED
A53: AF0201:J | B53: SC | C53: * | F53: 11.A4 | G53: AF0202:P | H53: ASSEMBLY^CONTROL PANEL | I53: 11.A5 | M53: USED
A54: AF0201:P | B54: SC | C54: * | F54: 11.A4 | G54: AU0200:J | H54: ASSEMBLY^CONTROL PANEL | I54: 11.A3 | M54: USED
A55: AF0201:SHLD | B55: SC | C55: AF0201V+ | D55: WHT | E55: 20 | F55: 11.B7 | G55: AF0201:V+ | H55: ASSEMBLY^CONTROL PANEL | I55: 11.B7 | M55: USED
A56: AF0201:V+ | B56: SC | C56: AU0200P | D56: WHT | E56: 16 | F56: 11.A4 | G56: AU0200:V+ | H56: ASSEMBLY^CONTROL PANEL | I56: 11.A3 | M56: USED
A57: AF0202:00 | B57: SC | C57: TCP01AP | D57: WHT | E57: 20 | F57: 12.A3 | G57: HL0400:A+ | H57: ASSEMBLY^CONTROL PANEL | I57: 12.A1 | M57: USED
A58: AF0202:01 | B58: SC | C58: TCP02AP | D58: WHT | E58: 20 | F58: 12.A3 | G58: HL0401:A+ | H58: ASSEMBLY^CONTROL PANEL | I58: 12.A1 | M58: USED
A59: AF0202:02 | B59: SC | C59: TCP03AP | D59: WHT | E59: 20 | F59: 12.B3 | G59: HL0402:A+ | H59: ASSEMBLY^CONTROL PANEL | I59: 12.B1 | M59: USED
A60: AF0202:03 | B60: SC | C60: TCP04AP | D60: WHT | E60: 20 | F60: 12.B3 | G60: HL0403:A+ | H60: ASSEMBLY^CONTROL PANEL | I60: 12.B1 | M60: USED
A61: AF0202:04 | B61: SC | C61: TCP05AP | D61: WHT | E61: 20 | F61: 12.C3 | G61: HL0404:A+ | H61: ASSEMBLY^CONTROL PANEL | I61: 12.C1 | M61: USED
A62: AF0202:05 | B62: SC | C62: TCP06AP | D62: WHT | E62: 20 | F62: 12.C3 | G62: HL0405:A+ | H62: ASSEMBLY^CONTROL PANEL | I62: 12.C1 | M62: USED
A63: AF0202:06 | B63: SC | C63: TCP06BP | D63: WHT | E63: 20 | F63: 12.D3 | G63: HL0405:B+ | H63: ASSEMBLY^CONTROL PANEL | I63: 12.D1 | M63: USED
A64: AF0202:08 | B64: SC | C64: TCP07AP | D64: WHT | E64: 20 | F64: 12.D3 | G64: HL0406:A+ | H64: ASSEMBLY^CONTROL PANEL | I64: 12.D1 | M64: USED
A65: AF0202:09 | B65: SC | C65: TCP08AP | D65: WHT | E65: 20 | F65: 12.A7 | G65: HL0407:A+ | H65: ASSEMBLY^CONTROL PANEL | I65: 12.A5 | M65: USED
A66: AF0202:10 | B66: SC | C66: TCP09AP | D66: WHT | E66: 20 | F66: 12.A7 | G66: HL0408:A+ | H66: ASSEMBLY^CONTROL PANEL | I66: 12.A5 | M66: USED
... A161: XT0564:1 B2 | B161: SC | C161: KA023612 | D161: WHT | E161: 20 | F161: 14.B5 | G161: XT0563:3 | H161: PWR,DISTRIBUTION RAIL^LEFT DOOR | I161: 14.B6 | M161: USED
F163: SolarTools ver. 24.0.84.26264 (Jun 3, 2025)
A164: Report date: 7/10/2025 2:56 PM

Sheet CONSOLE DOOR^PANEL
A1: CONSOLE DOOR^PANEL
A3: Project # | B3: G9440
A4: Project Name | B4: NOC AL SHAHEEN T130
A5: Revision | B5: A.5
A7: Controls DE | B7: G. Colby
A8: Phone:
A9: Controls ME | B9: R. Duran
A10: Phone:
A12: From | G12: To
A13: Device ID | B13: Cable (W) Conductor (SC) Jumper Clip (JC) | C13: Wire No. | D13: Wire ID | E13: Gauge/Size | F13: Page/Zone | G13: Device ID | H13: Location | I13: Page/Zone
A14: AT0190:GND | B14: SC | C14: AT0190G | D14: GRN/YEL | E14: 14 | F14: 11.C4 | G14: FRAME | H14: CONSOLE DOOR^PANEL | I14: 11.D3 | M14: USED
A15: AT0190:USB1 | B15: SC | C15: AT0190K | D15: CABLE | E15: USB | F15: 11.C4 | G15: AT0190K:KI | H15: CONSOLE DOOR^PANEL | I15: 11.D5 | M15: USED
A16: GF4000:A13 | B16: SC | C16: GF4000-A13 | D16: GRN/YEL | E16: 14 | F16: 105.B5 | G16: FG-GF4000:1 | H16: CONSOLE DOOR^PANEL | I16: 105.B5 | M16: USED
A17: TM0102:GND | B17: SC | C17: TM0102G | D17: GRN/YEL | E17: 14 | F17: 21.B5 | G17: FRAME | H17: CONSOLE DOOR^PANEL | I17: 21.C5 | M17: USED
A18: GF4000:A1 | B18: W4000 | C18: RE4000-1 | D18: WHT | E18: 16 | F18: 105.A5 | G18: XT-9105:1 | H18: 1 BAY BACK WALL | I18: 105.A4 | M18: USED
A19: GF4000:A3 | B19: W4000 | C19: RE4000-2 | D19: BLK | E19: 16 | F19: 105.A5 | G19: XT-9105:2 | H19: 1 BAY BACK WALL | I19: 105.A4 | M19: USED
A20: GF4000:A4 | B20: SC | C20: 012246 | D20: WHT | E20: 20 | F20: 105.A6 | G20: AF0122:46 | H20: 1 BAY RIGHT WALL | I20: 105.A7 | M20: USED
A21: GF4000:A5 | B21: SC | C21: 012214 | D21: WHT | E21: 20 | F21: 105.A6 | G21: AF0122:14 | H21: 1 BAY RIGHT WALL | I21: 105.A7 | M21: USED
A22: GF4000:A6 | B22: SC | C22: 012247 | D22: WHT | E22: 20 | F22: 105.B6 | G22: AF0122:47 | H22: 1 BAY RIGHT WALL | I22: 105.B7 | M22: USED
A23: GF4000:A7 | B23: SC | C23: 012215 | D23: WHT | E23: 20 | F23: 105.B6 | G23: AF0122:15 | H23: 1 BAY RIGHT WALL | I23: 105.B7 | M23: USED
A24: AT0190:NEG | B24: SC | C24: 0V1 | D24: WHT | E24: 14 | F24: 11.C4 | G24: XT0562:2 | H24: PWR,DISTRIBUTION RAIL^LEFT DOOR | I24: 11.B2 | M24: USED
A25: AT0190:POS | B25: SC | C25: FU0190 | D25: WHT | E25: 14 | F25: 11.C4 | G25: FU0190:LD | H25: PWR,DISTRIBUTION RAIL^LEFT DOOR | I25: 11.D3 | M25: USED
... A33: TM0102:7 | B33: SC | C33: TM01027 | D33: RED | E33: 16 | F33: 21.B5 | G33: SA0770:23 | H33: SWITCH PANEL | I33: 21.B5 | M33: USED
F35: SolarTools ver. 24.0.84.26264 (Jun 3, 2025)
A36: Report date: 7/10/2025 2:56 PM

Sheet METER PANEL
A1: METER PANEL
A3: Project # | B3: G9440
A4: Project Name | B4: NOC AL SHAHEEN T130
A5: Revision | B5: A.5
A7: Controls DE | B7: G. Colby
A8: Phone:
A9: Controls ME | B9: R. Duran
A10: Phone:
A12: From | G12: To
A13: Device ID | B13: Cable (W) Conductor (SC) Jumper Clip (JC) | C13: Wire No. | D13: Wire ID | E13: Gauge/Size | F13: Page/Zone | G13: Device ID | H13: Location | I13: Page/Zone
A14: PA0703:1 | B14: SC | C14: PA07714 | D14: BLU | E14: 16 | F14: 21.A4 | G14: PA0771:4 | H14: METER PANEL | I14: 21.C3 | M14: USED
A15: PA0771:8 | B15: SC | C15: VGENC | D15: RED | E15: 16 | F15: 21.C3 | G15: XT-9110:6 | H15: 1 BAY BACK WALL | I15: 100.D4 | M15: USED
A16: PF0701:7 | B16: SC | C16: PF07017 | D16: RED | E16: 16 | F16: 21.B6 | G16: KA121A:14 | H16: 1 BAY BACK WALL | I16: 21.B6 | M16: USED
A17: PA0701:7 | B17: W8064 | C17: PA07017 | D17: RED | E17: 20 | F17: 20.A1 | G17: RS0106:1 | H17: 1 BAY BACK WALL | I17: 20.A4 | M17: USED
A18: PA0701:8 | B18: W8064 | C18: PA07018 | D18: BLK | E18: 20 | F18: 20.A1 | G18: RS0106:3 | H18: 1 BAY BACK WALL | I18: 20.A4 | M18: USED
A19: FLOATING | B19: W8064 | C19: EXCS | D19: SH | E19: 20 | F19: 20.A1 | G19: XT0106:1 | H19: 1 BAY BACK WALL | I19: 20.A4 | M19: USED
A20: PA0703:5 | B20: SC | C20: PA07035 | D20: BLU | E20: 16 | F20: 21.A4 | G20: XT0342:1 | H20: 1 BAY LEFT WALL | I20: 21.A2 | M20: USED
A21: PA0771:6 | B21: SC | C21: PA07716 | D21: BLU | E21: 16 | F21: 21.C3 | G21: XT0342:4 | H21: 1 BAY LEFT WALL | I21: 21.C2 | M21: USED
A22: PA0771:7 | B22: SC | C22: VGENB | D22: RED | E22: 16 | F22: 21.C3 | G22: XT0341:4 | H22: 1 BAY LEFT WALL | I22: 21.D2 | M22: USED
A23: PV0701:7 | B23: W8065 | C23: EXC0 | D23: RED | E23: 20 | F23: 20.A1 | G23: XT0340:5 | H23: 1 BAY LEFT WALL | I23: 20.A5 | M23: USED
A24: PV0701:8 | B24: W8065 | C24: EXC2 | D24: BLK | E24: 20 | F24: 20.A1 | G24: XT0340:6 | H24: 1 BAY LEFT WALL | I24: 20.B5 | M24: USED
A25: FLOATING | B25: W8065 | C25: EXCS | D25: SH | E25: 20 | F25: 20.B1 | G25: XT0340:7 | H25: 1 BAY LEFT WALL | I25: 20.B5 | M25: USED
... A36: PV0700:8 | B36: SC | C36: PV07008 | D36: RED | E36: 16 | F36: 21.C5 | G36: SA0710:21 | H36: SWITCH PANEL | I36: 21.C5 | M36: USED
F38: SolarTools ver. 24.0.84.26264 (Jun 3, 2025)
A39: Report date: 7/10/2025 2:56 PM

Sheet ORBIT 60^DOOR PANEL
A1: ORBIT 60^DOOR PANEL
A2: CONTROL CONSOLE^(ORBIT 60 RACK DOOR PANEL)
A3: Project # | B3: G9440
A4: Project Name | B4: NOC AL SHAHEEN T130
A5: Revision | B5: A.5
A7: Controls DE | B7: G. Colby
A8: Phone:
A9: Controls ME | B9: R. Duran
A10: Phone:
A12: From | G12: To
A13: Device ID | B13: Cable (W) Conductor (SC) Jumper Clip (JC) | C13: Wire No. | D13: Wire ID | E13: Gauge/Size | F13: Page/Zone | G13: Device ID | H13: Location | I13: Page/Zone
A14: UV0610:P.E. | B14: SC | C14: PEG01301 | D14: GRN/YEL | E14: 14 | F14: 23.B1 | G14: PEG0130:1 | H14: 1 BAY RIGHT WALL | I14: 23.C1 | M14: USED
A15: UV0611:P.E. | B15: SC | C15: PEG01302 | D15: GRN/YEL | E15: 14 | F15: 23.C1 | G15: PEG0130:2 | H15: 1 BAY RIGHT WALL | I15: 23.C2 | M15: USED
A16: AP0616:SIG3 | B16: W6163 | C16: 0616SIG3 | D16: RED | E16: 20 | F16: 89.A6 | G16: UAI9223-1:7 | H16: 2 BAY BACK LEFT WALL | I16: 89.A5 | M16: USED
A17: AP0616:COM3 | B17: W6163 | C17: 0616COM3 | D17: BLK | E17: 20 | F17: 89.A6 | G17: UAI9223-1:8 | H17: 2 BAY BACK LEFT WALL | I17: 89.A5 | M17: USED
A18: AP0616:SHLD3 | B18: W6163 | C18: 0616SHLD3 | D18: SH | E18: 20 | F18: 89.A6 | G18: FLOATING | H18: 2 BAY BACK LEFT WALL | I18: 89.A6 | M18: USED
A19: AP0622:A4(+) | B19: W6224 | C19: 0622A4 | D19: RED | E19: 20 | F19: 89.D6 | G19: UAI9223A-1:8+ | H19: 2 BAY BACK LEFT WALL | I19: 89.D5 | M19: USED
A20: AP0622:B4(-) | B20: W6224 | C20: 0622B4 | D20: BLK | E20: 20 | F20: 89.D6 | G20: UAI9223A-1:7- | H20: 2 BAY BACK LEFT WALL | I20: 89.D5 | M20: USED
A21: AP0622:SHLD4 | B21: W6224 | C21: 06224SHLD4 | D21: SH | E21: 20 | F21: 89.D6 | G21: FW2?:1 | H21: 2 BAY BACK LEFT WALL | I21: 89.D6 | M21: USED
A22: AP0624:SIG1 | B22: W6241 | C22: 0624SIG1 | D22: RED | E22: 20 | F22: 89.B6 | G22: UAI9223-2:7 | H22: 2 BAY BACK LEFT WALL | I22: 89.B5 | M22: USED
A23: AP0624:COM1 | B23: W6241 | C23: 0624COM1 | D23: BLK | E23: 20 | F23: 89.B6 | G23: UAI9223-2:8 | H23: 2 BAY BACK LEFT WALL | I23: 89.B5 | M23: USED
A24: AP0624:SHLD1 | B24: W6241 | C24: 0624SHLD1 | D24: SH | E24: 20 | F24: 89.B6 | G24: FLOATING | H24: 2 BAY BACK LEFT WALL | I24: 89.B6 | M24: USED
A25: AP0624:SIG2 | B25: W6242 | C25: 0624SIG2 | D25: RED | E25: 20 | F25: 89.B6 | G25: UAI9223-3:7 | H25: 2 BAY BACK LEFT WALL | I25: 89.B5 | M25: USED
... A75: UV0611:COM | B75: SC | C75: 0V | D75: WHT | E75: 14 | F75: 23.C1 | G75: XT0110:3 | H75: 2 BAY RIGHT WALL | I75: 23.A6 | M75: USED
F77: SolarTools ver. 24.0.84.26264 (Jun 3, 2025)
A78: Report date: 7/10/2025 2:56 PM

Sheet PWR,DIST RAIL^LEFT DOOR
A1: PWR,DISTRIBUTION RAIL^LEFT DOOR
A3: Project # | B3: G9440
A4: Project Name | B4: NOC AL SHAHEEN T130
A5: Revision | B5: A.5
A7: Controls DE | B7: G. Colby
A8: Phone:
A9: Controls ME | B9: R. Duran
A10: Phone:
A12: From | G12: To
A13: Device ID | B13: Cable (W) Conductor (SC) Jumper Clip (JC) | C13: Wire No. | D13: Wire ID | E13: Gauge/Size | F13: Page/Zone | G13: Device ID | H13: Location | I13: Page/Zone
A14: XT0561:2 | B14: JC | C14: FU0200LI | D14: CLIP | E14: --- | F14: 11.A2 | G14: XT0561:1 | H14: PWR,DISTRIBUTION RAIL^LEFT DOOR | I14: 11.A2 | M14: USED
A15: XT0562:1 | B15: JC | C15: 0V1 | D15: CLIP | E15: --- | F15: 11.B2 | G15: XT0562:2 | H15: PWR,DISTRIBUTION RAIL^LEFT DOOR | I15: 11.B2 | M15: USED
A16: XT0562:2 | B16: JC | C16: 0V1 | D16: CLIP | E16: --- | F16: 11.B2 | G16: XT0562:3 | H16: PWR,DISTRIBUTION RAIL^LEFT DOOR | I16: 11.B2 | M16: USED
A17: XT0560:2 | B17: SC | C17: JW0 | D17: CLIP | E17: -- | F17: 11.B2 | G17: XT0562:1 | H17: PWR,DISTRIBUTION RAIL^LEFT DOOR | I17: 11.B2 | M17: USED
A18: AT0680:NEG | B18: SC | C18: 0V | D18: WHT | E18: 14 | F18: 5.A4 | G18: XT0680:2 | H18: PWR,DISTRIBUTION RAIL^LEFT DOOR | I18: 5.B3 | M18: USED
A19: AT0680:POS | B19: SC | C19: AT0680POS | D19: WHT | E19: 14 | F19: 5.A4 | G19: XT0680:1 | H19: PWR,DISTRIBUTION RAIL^LEFT DOOR | I19: 5.B3 | M19: USED
A20: FU0200:LI | B20: SC | C20: FU0200LI | D20: WHT | E20: 14 | F20: 11.A3 | G20: FU0201:LI | H20: PWR,DISTRIBUTION RAIL^LEFT DOOR | I20: 11.B3 | M20: USED
A21: FU0200:LI | B21: SC | C21: FU0200LI | D21: WHT | E21: 14 | F21: 11.A3 | G21: XT0561:1 | H21: PWR,DISTRIBUTION RAIL^LEFT DOOR | I21: 11.A2 | M21: USED
A22: FU0201:LI | B22: SC | C22: FU0200LI | D22: WHT | E22: 14 | F22: 11.B3 | G22: FU0273:LI | H22: PWR,DISTRIBUTION RAIL^LEFT DOOR | I22: 11.B3 | M22: USED
A23: FU0560:LD | B23: SC | C23: FU0200LI | D23: WHT | E23: 14 | F23: 11.A2 | G23: XT0561:1 | H23: PWR,DISTRIBUTION RAIL^LEFT DOOR | I23: 11.A2 | M23: USED
A24: FU0560:LI | B24: SC | C24: FU0136 | D24: WHT | E24: 12 | F24: 11.A2 | G24: XT0560:1 | H24: PWR,DISTRIBUTION RAIL^LEFT DOOR | I24: 11.A2 | M24: USED
A25: FU0680:LD | B25: SC | C25: AT0680POS | D25: WHT | E25: 14 | F25: 5.B2 | G25: XT0680:1 | H25: PWR,DISTRIBUTION RAIL^LEFT DOOR | I25: 5.B3 | M25: USED
... A55: AT0680:LAN2 | B55: WC0019 | C55: AT0190E | D55: ENET | E55: CABLE | F55: 5.A4 | G55: AT0190:ETAP:L1 | H55: CONSOLE DOOR^PANEL | I55: 11.C4 | M55: USED
F57: SolarTools ver. 24.0.84.26264 (Jun 3, 2025)
A58: Report date: 7/10/2025 2:56 PM

Sheet SWITCH PANEL
A1: SWITCH PANEL
A3: Project # | B3: G9440
A4: Project Name | B4: NOC AL SHAHEEN T130
A5: Revision | B5: A.5
A7: Controls DE | B7: G. Colby
A8: Phone:
A9: Controls ME | B9: R. Duran
A10: Phone:
A12: From | G12: To
A13: Device ID | B13: Cable (W) Conductor (SC) Jumper Clip (JC) | C13: Wire No. | D13: Wire ID | E13: Gauge/Size | F13: Page/Zone | G13: Device ID | H13: Location | I13: Page/Zone
A14: HL0701:A | B14: SC | C14: 0V | D14: WHT | E14: 16 | F14: 20.C2 | G14: HL0702:A | H14: SWITCH PANEL | I14: 20.C2 | M14: USED
A15: HL0703: | B15: SC | C15: VBUSA | D15: RED | E15: 16 | F15: 21.A5 | G15: PF0700:2 | H15: SWITCH PANEL | I15: 21.A4 | M15: USED
A16: HL0703: | B16: SC | C16: PF07008 | D16: RED | E16: 16 | F16: 21.A5 | G16: SA0700:12 | H16: SWITCH PANEL | I16: 21.A5 | M16: USED
A17: HL0704: | B17: SC | C17: VBUSC | D17: RED | E17: 16 | F17: 21.A5 | G17: PF0700:1 | H17: SWITCH PANEL | I17: 21.A4 | M17: USED
A18: HL0704: | B18: SC | C18: PF07007 | D18: RED | E18: 16 | F18: 21.A5 | G18: SA0700:16 | H18: SWITCH PANEL | I18: 21.A5 | M18: USED
A19: SA0700:12 | B19: SC | C19: PF07008 | D19: RED | E19: 16 | F19: 21.A5 | G19: PF0700:8 | H19: SWITCH PANEL | I19: 21.A4 | M19: USED
A20: SA0700:13 | B20: SC | C20: VGENA | D20: RED | E20: 16 | F20: 21.A5 | G20: SA0770:18 | H20: SWITCH PANEL | I20: 21.B6 | M20: USED
A21: SA0700:16 | B21: SC | C21: PF07007 | D21: RED | E21: 16 | F21: 21.A5 | G21: PF0700:7 | H21: SWITCH PANEL | I21: 21.A4 | M21: USED
A22: SA0700:17 | B22: SC | C22: VGENC | D22: RED | E22: 16 | F22: 21.A5 | G22: SA0770:24 | H22: SWITCH PANEL | I22: 21.B6 | M22: USED
A23: SA0700:22 | B23: SC | C23: SA070022 | D23: WHT | E23: 16 | F23: 20.C3 | G23: SA0701:13 | H23: SWITCH PANEL | I23: 20.C2 | M23: USED
A24: SA0701:12 | B24: SC | C24: FU0333 | D24: WHT | E24: 16 | F24: 20.C2 | G24: SA0701:14 | H24: SWITCH PANEL | I24: 20.C2 | M24: USED
A25: SA0710:12 | B25: SC | C25: VBUSA | D25: RED | E25: 16 | F25: 21.D5 | G25: SA0710:24 | H25: SWITCH PANEL | I25: 21.D5 | M25: USED
... A76: SA0770:28 | B76: SC | C76: VGENB | D76: RED | E76: 16 | F76: 21.B6 | G76: PF0701:8 | H76: METER PANEL | I76: 21.B6 | M76: USED
F78: SolarTools ver. 24.0.84.26264 (Jun 3, 2025)
A79: Report date: 7/10/2025 2:56 PM

Sheet Panel Errors
A1: Panel Errors
A3: Project # | B3: G9440
A4: Project Name | B4: NOC AL SHAHEEN T130
A5: Revision | B5: A.5
A7: Controls DE | B7: G. Colby
A8: Phone:
A9: Controls ME | B9: R. Duran
A10: Phone:
A12: From | H12: To
A13: Device ID | B13: Location | C13: Cable (W) Conductor (SC) Jumper Clip (JC) | D13: Wire ID | E13: Wire No. | F13: Gauge/Size | G13: Page/Zone | H13: Device ID | I13: Location | J13: Page/Zone
A14: XT0930:3 | B14: 1 BAY LEFT WALL | C14: WC8010 | D14: SH | E14: AT0140LS(S) | F14: 16 | G14: 104.C5 | H14: FW0220:3 | I14: PANEL | J14: 104.D6
A16: Report date: 7/10/2025 2:56 PM | E16: SolarTools ver. 24.0.84.26264 (Jun 3, 2025)

Sheet Cable Part Numbers
A1: Cable Part Numbers | D1: SolarTools ver. 24.0.84.26264 (Jun 3, 2025)
A2: Project # | B2: G9440
D3: Report date: 7/10/2025 2:58 PM
A4: Project Name | B4: NOC AL SHAHEEN T130
A6: Revision | B6: A.5
A8: Controls DE | B8: G. Colby
A9: Phone:
A10: Controls ME | B10: R. Duran
A11: Phone:
A13: Device ID | C13: Part Number | E13: Description
A14: W0851 | C14: 1022941-12 | E14: TPE, 1 PAIR TWISTED SHIELDED
A15: WI0851 | C15: 1022941-12 | E15: TPE, 1 PAIR TWISTED SHIELDED
A17: W0552 | C17: 1022941-12 | E17: TPE, 1 PAIR TWISTED SHIELDED
A18: W0553 | C18: 1022941-12 | E18: TPE, 1 PAIR TWISTED SHIELDED
A19: W0554 | C19: 1022941-12 | E19: TPE, 1 PAIR TWISTED SHIELDED
A20: W0556 | C20: 1022941-12 | E20: TPE, 1 PAIR TWISTED SHIELDED
A21: W0557 | C21: 1022941-12 | E21: TPE, 1 PAIR TWISTED SHIELDED
A22: W0560 | C22: 1022941-12 | E22: TPE, 1 PAIR TWISTED SHIELDED
A23: W0561 | C23: 1022941-12 | E23: TPE, 1 PAIR TWISTED SHIELDED
A24: W0562 | C24: 1022941-12 | E24: TPE, 1 PAIR TWISTED SHIELDED
A25: W0563 | C25: 1022941-12 | E25: TPE, 1 PAIR TWISTED SHIELDED
... A232: WI6244 | C232: 1022941-13 | E232: TPE, 1 TRIAD TWISTED SHIELDED

Sheet Part Number List
A1: Part Number List | C1: SolarTools ver. 24.0.84.26264 (Jun 3, 2025)
A2: Project # | B2: G9440
C3: Report date: 7/10/2025 2:58 PM
A4: Project Name | B4: NOC AL SHAHEEN T130
A6: Revision | B6: A.5
A8: Controls DE | B8: G. Colby
A9: Phone:
A10: Controls ME | B10: R. Duran
A11: Phone:
A13: Device ID | B13: Part Number | C13: Description | D13: Location
A14: GR9121 | B14: 903849C1 | C14: RAIL GROUND, DIN RAIL GROUNDING | D14: 1 BAY BACK WALL
A15: GR9122 | B15: 903849C1 | C15: RAIL GROUND, DIN RAIL GROUNDING | D15: 1 BAY BACK WALL
A16: GR9123 | B16: 903849C1 | C16: RAIL GROUND, DIN RAIL GROUNDING | D16: 1 BAY BACK WALL
A17: KA0135 | B17: 1061979-1 | C17: RELAY, AC PRE/POST PUMP DRIVE | D17: 1 BAY BACK WALL
A18: KA121A | B18: 1061979-1 | C18: RELAY, 90% SPEED | D18: 1 BAY BACK WALL
A19: KA121C | B19: 1061979-1 | C19: RELAY, DRIVER MAIN LIQUID^FUEL PUMP | D19: 1 BAY BACK WALL
A20: KA3103 | B20: 1061979-1 | C20: RELAY, LUBE OIL TANK HEATER | D20: 1 BAY BACK WALL
A21: KA3420 | B21: 1061979-1 | C21: RELAY, GENERATOR JACKING OIL | D21: 1 BAY BACK WALL
A22: KA4100 | B22: 1061979-1 | C22: RELAY, GENERATOR HEATER^DISABLED | D22: 1 BAY BACK WALL
A23: KA6211 | B23: 1061979-1 | C23: RELAY, DRIVER ENCLOSURE^VENT FAN #1 | D23: 1 BAY BACK WALL
A24: KA6212 | B24: 1061979-1 | C24: RELAY, DRIVER ENCLOSURE^VENT FAN #2 | D24: 1 BAY BACK WALL
... A561: BA0543 | B561: 1271449-1 | C561: MEDIA CONVERTER, ETHERNET-FIBER OPTIC | D561: PANEL
A562: BUOSM | B562: CUSTOMER DEFINED | D562: PANEL
A563: CCGB0523 | B563: CUSTOMER DEFINED | C563: CUSTOMER CONNECTION, VOLTAGE INPUT: 100-240VAC/90-340VDC^FREQ INPUT: 50/60HZ^UPS POWER-1 | D563: PANEL
A564: CC-KA7500 | B564: CUSTOMER SUPPLIED | C564: CUSTOMER CONNECTION, AUTOMATIC SYNCHRONIZE^INITIATE (REMOTE)^(PULSE SIGNAL) | D564: PANEL
A565: CC-KA7505 | B565: CUSTOMER SUPPLIED | C565: CUSTOMER CONNECTION, START AND AUTO-SYNC^(REMOTE)^(PULSE SIGNAL) | D565: PANEL
A566: CCPS6670 | B566: CUSTOMER DEFINED | C566: CUSTOMER CONNECTION, H20#1 RELEASE CONFIRM | D566: PANEL
A567: CCPS6675 | B567: CUSTOMER DEFINED | C567: CUSTOMER CONNECTION, N2#1 PRESSURE | D567: PANEL
A568: CCPS6680 | B568: CUSTOMER DEFINED | C568: CUSTOMER CONNECTION, H20 #2 RELEASE CONFIRM | D568: PANEL
A569: CCPS6685 | B569: CUSTOMER DEFINED | C569: CUSTOMER CONNECTION, N2 #2 PRESSURE | D569: PANEL
A570: CC-SM7632 | B570: < no partnumber assigned > | C570: CUSTOMER CONNECTION, GAS FUEL FLOW (MASS)^4/20MA = 0 - 12000 LB/H^4/20MA = 0 - 5443 KG/H | D570: PANEL
A571: CC-SM7633 | B571: CUSTOMER SUPPLIED | C571: CUSTOMER CONNECTION, GAS FUEL TEMPERATURE^4/20MA = 32 - 392 DEG F^4/20MA = 0 - 200 DEG C | D571: PANEL
A572: CC-SM7634 | B572: CUSTOMER SUPPLIED | C572: CUSTOMER CONNECTION, T1 TEMPERATURE^4/20MA = 32 - 212 DEG F^4/20MA = 0 - 100 DEG C | D572: PANEL
A573: CC-SM7635 | B573: CUSTOMER SUPPLIED | C573: CUSTOMER CONNECTION, GENERATOR CAPACITY^4/20MA = 8000 - 15000 KW | D573: PANEL
A574: CCSV6671 | B574: CUSTOMER DEFINED | C574: CUSTOMER CONNECTION, PRIMARY RELEASE#1 | D574: PANEL
... A604: SA0770 | B604: 1035040-1048,1051149-1 | C604: SELECTOR SWITCH, KW/KVAR SELECT | D604: SWITCH PANEL

Sheet CONSOLE DOOR^PANEL_S
A1: CONSOLE DOOR^PANEL
A3: Project # | B3: G9440
A4: Project Name | B4: NOC AL SHAHEEN T130
A5: Revision | B5: A.5
A7: Controls DE | B7: G. Colby
A8: Phone:
A9: Controls ME | B9: R. Duran
A10: Phone:
A12: From | G12: To
A13: Device ID | B13: Wire No. | C13: Wire ID | D13: Gauge/Size | E13: Length | F13: Device ID | G13: Location | H13: Bundle Name
A14: AT0190:NEG | B14: -0V1 | C14: WHT | D14: 14 | E14: 100 | F14: XT0562:2 | G14: PWR,DIST RAIL | H14: HMI
A15: AT0190:POS | B15: FU0190 | C15: WHT | D15: 14 | E15: 100 | F15: FU0190:LD | G15: PWR,DIST RAIL

Sheet METER PANEL_S
A1: METER PANEL
A3: Project # | B3: G9440
A4: Project Name | B4: NOC AL SHAHEEN T130
A5: Revision | B5: A.5
A7: Controls DE | B7: G. Colby
A8: Phone:
A9: Controls ME | B9: R. Duran
A10: Phone:
A12: From | G12: To
A13: Device ID | B13: Wire No. | C13: Wire ID | D13: Gauge/Size | E13: Length | F13: Device ID | G13: Location | H13: Bundle Name
A14: PF0701:7 | B14: PF07017 | C14: RED | D14: 16R | E14: 200 | F14: KA121A:14 | G14: 1 BAY BACK WALL | H14: PF0701
A15: PF0701:8 | B15: VGENB | C15: RED | D15: 16R | E15: 80 | F15: SA0770:28 | G15: SWITCH PANEL
A17: PA0771:8 | B17: VGENC | C17: RED | D17: 16R | E17: 200 | F17: XT-9110:6 | G17: 1 BAY BACK WALL | H17: PA0771
A18: PA0771:7 | B18: VGENB | C18: RED | D18: 16R | E18: 200 | F18: XT0341:4 | G18: 1 BAY LEFT WALL
A20: PA0771:6 | B20: PA07716 | C20: BLU | D20: 16B | E20: 200 | F20: XT0342:4 | G20: 1 BAY LEFT WALL
A22: PA0700:8 | B22: MCTN | C22: BLU | D22: 16B | E22: 80 | F22: SA0740:21 | G22: SWITCH PANEL | H22: PA0700
A23: PA0700:7 | B23: PA07007 | C23: BLU | D23: 16B | E23: 80 | F23: SA0740:11 | G23: SWITCH PANEL
