Workbook

Sheet JB70_S
A1: JB70
A3: Project # | B3: 4L541
A4: Project Name | B4: Kaskida
A5: Revision | B5: B
A7: Controls DE | B7: A. CHEN
A8: Phone: | B8: 0
A9: Controls ME | B9: A. PLVAN
A10: Phone:
A12: From | G12: To
A13: Device ID | B13: Wire No. | C13: Wire ID | D13: Gauge/Size | E13: Length | F13: Device ID | G13: Location | H13: Bundle Name
A14: AT1100:NEG | B14: -0V | C14: WHT | D14: 14 | E14: 220 | F14: XT0134:3 | G14: PANEL A | H14: AT1100
A16: SA0471:B1-13 | B16: SA0471B113 | C16: WHT | D16: 20 | E16: 220 | F16: AF0085:40 | G16: PANEL A | H16: SA0471
A17: SA0471:B1-14 | B17: SA0471B114 | C17: WHT | D17: 20 | E17: 220 | F17: AF0085:08 | G17: PANEL A
A18: SA0471:B2-13 | B18: SA0471B213 | C18: WHT | D18: 20 | E18: 220 | F18: AF0085:39 | G18: PANEL A
A19: SA0471:B2-14 | B19: SA0471B214 | C19: WHT | D19: 20 | E19: 220 | F19: AF0085:07 | G19: PANEL A
A21: SA0473:B-A3 | B21: SA0473B-A3 | C21: WHT | D21: 20 | E21: 220 | F21: AF0085:09 | G21: PANEL A | H21: SA0473
A22: SA0473:B-A4 | B22: SA0473B-A4 | C22: WHT | D22: 20 | E22: 220 | F22: AF0085:41 | G22: PANEL A
A23: SA0473:B-B1 | B23: SA0473B-B1 | C23: WHT | D23: 20 | E23: 220 | F23: AF0085:06 | G23: PANEL A
A24: SA0473:B-B2 | B24: SA0473B-B2 | C24: WHT | D24: 20 | E24: 220 | F24: AF0085:38 | G24: PANEL A
A25: SA0473:W-B1 | B25: SA0473W-B1 | C25: WHT | D25: 20 | E25: 220 | F25: AF0085:05 | G25: PANEL A
A26: SA0473:W-B2 | B26: SA0473W-B2 | C26: WHT | D26: 20 | E26: 220 | F26: AF0085:37 | G26: PANEL A
A28: SA0474:B2-13 | B28: SA0474B113 | C28: WHT | D28: 20 | E28: 220 | F28: AF0082:32 | G28: PANEL A | H28: SA0474
A29: SA0474:B2-14 | B29: SA0474B114 | C29: WHT | D29: 20 | E29: 220 | F29: AF0082:00 | G29: PANEL A
A30: SA0474:B1-13 | B30: SA0474B213 | C30: WHT | D30: 20 | E30: 220 | F30: AF0082:33 | G30: PANEL A
A31: SA0474:B1-14 | B31: SA0474B214 | C31: WHT | D31: 20 | E31: 220 | F31: AF0082:01 | G31: PANEL A
A33: SB0471:11 | B33: SB047111 | C33: WHT | D33: 20 | E33: 220 | F33: AF0085:34 | G33: PANEL A | H33: SB0471
A34: SB0471:12 | B34: SB047112 | C34: WHT | D34: 20 | E34: 220 | F34: AF0085:02 | G34: PANEL A
A36: SB0472:B1-12 | B36: ESTOP | C36: WHT | D36: 20 | E36: 220 | F36: XT0137:2 | G36: PANEL A | H36: SB0472
A37: SB0472:B1-11 | B37: ESTOPA | C37: WHT | D37: 20 | E37: 220 | F37: XT0137:3 | G37: PANEL A
A38: SB0472:B2-11 | B38: SB0472B211 | C38: WHT | D38: 20 | E38: 220 | F38: AF0094:36 | G38: PANEL A
A39: SB0472:B2-12 | B39: SB0472B212 | C39: WHT | D39: 20 | E39: 220 | F39: AF0094:04 | G39: PANEL A
A41: SB0473:13 | B41: SB047313 | C41: WHT | D41: 20 | E41: 220 | F41: AF0085:35 | G41: PANEL A | H41: SB0473
A42: SB0473:14 | B42: SB047314 | C42: WHT | D42: 20 | E42: 220 | F42: AF0085:03 | G42: PANEL A
A44: SB0474:13 | B44: SB047413 | C44: WHT | D44: 20 | E44: 220 | F44: AF0085:36 | G44: PANEL A | H44: SB0474
A45: SB0474:14 | B45: SB047414 | C45: WHT | D45: 20 | E45: 220 | F45: AF0085:04 | G45: PANEL A
A47: SH0470:11 | B47: SH047011 | C47: WHT | D47: 20 | E47: 220 | F47: AF0085:33 | G47: PANEL A | H47: SH0470
A48: SH0470:12 | B48: SH047012 | C48: WHT | D48: 20 | E48: 220 | F48: AF0085:01 | G48: PANEL A
A49: SH0470:13 | B49: SH047013 | C49: WHT | D49: 20 | E49: 220 | F49: XT0137:5 | G49: PANEL A
A50: SH0470:14 | B50: SH047014 | C50: WHT | D50: 20 | E50: 220 | F50: XT0137:6 | G50: PANEL A
A51: SH0470:X1 | B51: SH0470X1 | C51: WHT | D51: 20 | E51: 220 | F51: AF0086:2 | G51: PANEL A
...

Sheet JB70 R RAIL_S
A1: JB70 RIGHT RAIL
A3: Project # | B3: 4L541
A4: Project Name | B4: Kaskida
A5: Revision | B5: B
A7: Controls DE | B7: A. CHEN
A8: Phone: | B8: 0
A9: Controls ME | B9: A. PLVAN
A10: Phone:
A12: From | G12: To
A13: Device ID | B13: Wire No. | C13: Wire ID | D13: Gauge/Size | E13: Length | F13: Device ID | G13: Location | H13: Bundle Name
A14: BA1100:NEG | B14: BA1100N | C14: WHT | D14: 16 | E14: 60 | F14: UJ1100:OUT1(-) | G14: JB70 R RAIL | H14: BA/FU
A15: BA1100:POS | B15: BA1100P | C15: WHT | D15: 16 | E15: 60 | F15: UJ1100:OUT1(+) | G15: JB70 R RAIL
A16: FU1100:LD | B16: FU1100LD | C16: WHT | D16: 16 | E16: 60 | F16: UJ1100:24V(+) | G16: JB70 R RAIL
A18: FU1100:LI | B18: FU0136 | C18: WHT | D18: 14 | E18: 160 | F18: XT0138:3 | G18: PANEL A | H18: FU/UJ-A
A19: UJ1100:24V(-) | B19: -0V | C19: WHT | D19: 14 | E19: 160 | F19: XT0134:3 | G19: PANEL A

Sheet JB70 L RAIL_S
A1: JB70 LEFT RAIL
A3: Project # | B3: 4L541
A4: Project Name | B4: Kaskida
A5: Revision | B5: B
A7: Controls DE | B7: A. CHEN
A8: Phone: | B8: 0
A9: Controls ME | B9: A. PLVAN
A10: Phone:
A12: From | G12: To
A13: Device ID | B13: Wire No. | C13: Wire ID | D13: Gauge/Size | E13: Length | F13: Device ID | G13: Location | H13: Bundle Name
A14: XT9070M:19 | B14: -008208 | C14: WHT | D14: 20 | E14: 120 | F14: AF0082:08 | G14: PANEL A | H14: XT-A
A15: XT9070M:18 | B15: -008243 | C15: WHT | D15: 20 | E15: 120 | F15: AF0082:40 | G15: PANEL A
A16: XT9070M:43 | B16: -009500 | C16: WHT | D16: 20 | E16: 120 | F16: AF0095:00 | G16: PANEL A
A17: XT9070M:45 | B17: -009503 | C17: WHT | D17: 20 | E17: 120 | F17: AF0095:03 | G17: PANEL A
A18: XT9070M:55 | B18: -009504 | C18: WHT | D18: 20 | E18: 120 | F18: AF0095:04 | G18: PANEL A
A19: XT9070M:27 | B19: -009505 | C19: WHT | D19: 20 | E19: 120 | F19: AF0095:05 | G19: PANEL A
A20: XT9070M:25 | B20: -009507 | C20: WHT | D20: 20 | E20: 120 | F20: AF0095:07 | G20: PANEL A
A21: XT9070M:23 | B21: -009508 | C21: WHT | D21: 20 | E21: 120 | F21: AF0095:08 | G21: PANEL A
A22: XT9070M:29 | B22: -009512 | C22: WHT | D22: 20 | E22: 120 | F22: AF0095:12 | G22: PANEL A
A23: XT9070M:42 | B23: -009532 | C23: WHT | D23: 20 | E23: 120 | F23: AF0095:32 | G23: PANEL A
A24: XT9070M:44 | B24: -009535 | C24: WHT | D24: 20 | E24: 120 | F24: AF0095:35 | G24: PANEL A
A25: XT9070M:54 | B25: -009536 | C25: WHT | D25: 20 | E25: 120 | F25: AF0095:36 | G25: PANEL A
A26: XT9070M:26 | B26: -009537 | C26: WHT | D26: 20 | E26: 120 | F26: AF0095:37 | G26: PANEL A
... A43: XT9070M:11 | B43: FU0136 | C43: WHT | D43: 14 | E43: 120 | F43: XT0138:2 | G43: PANEL A
A45: XT0001:2 | B45: -0V | C45: WHT | D45: 20 | E45: 140 | F45: XT0235:3 | G45: PANEL B | H45: XT01s-B
A46: XT0001:5 | B46: -0V | C46: WHT | D46: 20 | E46: 140 | F46: XT0235:3 | G46: PANEL B
A48: XT0001:1 | B48: FU0210 | C48: WHT | D48: 14 | E48: 140 | F48: XT0233:3 | G48: PANEL B
A49: XT0001:4 | B49: FU0210 | C49: WHT | D49: 14 | E49: 140 | F49: XT0233:3 | G49: PANEL B
A51: XT9070M:34 | B51: -24V1 | C51: WHT | D51: 20 | E51: 140 | F51: KA8311:14 | G51: PANEL B | H51: XT9070s-B
A52: XT9070M:9 | B52: AP0612COM | C52: WHT | D52: 20 | E52: 140 | F52: KA0701:11 | G52: PANEL B
A53: XT9070M:10 | B53: AP0612TM | C53: WHT | D53: 20 | E53: 140 | F53: KA0701:14 | G53: PANEL B
A54: XT9070M:35 | B54: KA8311 | C54: WHT | D54: 20 | E54: 140 | F54: KA8311:11 | G54: PANEL B
A55: XT9070M:50 | B55: KA831211 | C55: WHT | D55: 20 | E55: 140 | F55: KA8312:11 | G55: PANEL B
A56: XT9070M:51 | B56: KA831214 | C56: WHT | D56: 20 | E56: 140 | F56: KA8312:14 | G56: PANEL B
A57: XT9070M:52 | B57: KA831411 | C57: WHT | D57: 20 | E57: 140 | F57: KA8314:11 | G57: PANEL B
A58: XT9070M:53 | B58: KA831414 | C58: WHT | D58: 20 | E58: 140 | F58: KA8314:14 | G58: PANEL B
A59: XT9070M:46 | B59: KA831511 | C59: WHT | D59: 20 | E59: 140 | F59: KA8315:11 | G59: PANEL B
A60: XT9070M:47 | B60: KA831514 | C60: WHT | D60: 20 | E60: 140 | F60: KA8315:14 | G60: PANEL B
A61: XT9070M:48 | B61: KA831611 | C61: WHT | D61: 20 | E61: 140 | F61: KA8316:11 | G61: PANEL B
A62: XT9070M:49 | B62: KA831614 | C62: WHT | D62: 20 | E62: 140 | F62: KA8316:14 | G62: PANEL B
...

Sheet PLC_S
A1: PLC PANEL
A2: JB70
A3: Project # | B3: 4L541
A4: Project Name | B4: Kaskida
A5: Revision | B5: B
A7: Controls DE | B7: A. CHEN
A8: Phone: | B8: 0
A9: Controls ME | B9: A. PLVAN
A10: Phone:
A12: From | G12: To
A13: Device ID | B13: Wire No. | C13: Wire ID | D13: Gauge/Size | E13: Length | F13: Device ID | G13: Location | H13: Bundle Name
A14: BA0001:V1(+) | B14: FU0001 | C14: WHT | D14: 16 | E14: 60 | F14: FU0001:LD | G14: PLC PANEL | H14: BA
A15: BA0002:V1(+) | B15: FU0002 | C15: WHT | D15: 16 | E15: 60 | F15: FU0002:LD | G15: PLC PANEL
A16: BA0011:V1(+) | B16: FU1011 | C16: WHT | D16: 16 | E16: 60 | F16: FU1011:LD | G16: PLC PANEL
A18: AT0680:NEG | B18: -0V | C18: WHT | D18: 14 | E18: 60 | F18: XT0680:2 | G18: PLC PANEL | H18: AT/FU
A19: AT0680:POS | B19: AT0680POS | C19: WHT | D19: 14 | E19: 60 | F19: XT0680:1 | G19: PLC PANEL
A20: FU0680:LD | B20: AT0680POS | C20: WHT | D20: 14 | E20: 60 | F20: XT0680:1 | G20: PLC PANEL
A22: UV0600:(-) | B22: -0V | C22: WHT | D22: 14 | E22: 80 | F22: XT0135:1 | G22: PANEL A | H22: UV-A
A23: UV0600:(+) | B23: FU0010 | C23: WHT | D23: 14 | E23: 80 | F23: FU0010:LD | G23: PANEL A
A25: BA0011:V1(-) | B25: -0V | C25: WHT | D25: 16 | E25: 80 | F25: XT0235:2 | G25: PANEL B | H25: BA-B
A27: FU0680:LI | B27: FU0210 | C27: WHT | D27: 14 | E27: 80 | F27: XT0233:4 | G27: PANEL B | H27: FU/XT-B
A28: FU1011:LI | B28: FU0210 | C28: WHT | D28: 16 | E28: 80 | F28: XT0233:2 | G28: PANEL B
A29: XT0680:2 | B29: -0V | C29: WHT | D29: 14 | E29: 80 | F29: XT0235:5 | G29: PANEL B

Sheet A_S
A1: PANEL A
A2: JB70
A3: Project # | B3: 4L541
A4: Project Name | B4: Kaskida
A5: Revision | B5: B
A7: Controls DE | B7: A. CHEN
A8: Phone: | B8: 0
A9: Controls ME | B9: A. PLVAN
A10: Phone:
A12: From | G12: To
A13: Device ID | B13: Wire No. | C13: Wire ID | D13: Gauge/Size | E13: Length | F13: Device ID | G13: Location | H13: Bundle Name
A14: AF0083:00 | B14: -008300 | C14: WHT | D14: 20 | E14: 80 | F14: XT0089:2 | G14: PANEL A | H14: AF080s
A15: AF0083:01 | B15: -0V | C15: WHT | D15: 20 | E15: 80 | F15: XT0089:3 | G15: PANEL A
A16: AF0083:05 | B16: -0V | C16: WHT | D16: 20 | E16: 80 | F16: XT0135:4 | G16: PANEL A
A17: AF0083:07 | B17: -0V | C17: WHT | D17: 20 | E17: 80 | F17: XT0135:4 | G17: PANEL A
A19: AF0082:COM | B19: AU0080N | C19: WHT | D19: 16 | E19: 60 | F19: AU0080:COM | G19: PANEL A
A20: AF0082:V+ | B20: AU0080P | C20: WHT | D20: 16 | E20: 60 | F20: AU0080:V+ | G20: PANEL A
A22: AF0086:COM | B22: 0V | C22: WHT | D22: 14 | E22: 60 | F22: XT0080:3 | G22: PANEL A
A23: AU0080:COM | B23: 0V | C23: WHT | D23: 14 | E23: 60 | F23: XT0080:1 | G23: PANEL A
A25: AF0091:COM | B25: AF0091N | C25: WHT | D25: 16 | E25: 60 | F25: AF0094:COM | G25: PANEL A | H25: AF/AU090s
A27: AF0092:COM | B27: -0V | C27: WHT | D27: 14 | E27: 60 | F27: XT0081:2 | G27: PANEL A
A28: AF0093:COM | B28: -0V | C28: WHT | D28: 14 | E28: 60 | F28: XT0081:2 | G28: PANEL A
A29: AF0096:COM | B29: -0V | C29: WHT | D29: 14 | E29: 80 | F29: XT0081:2 | G29: PANEL A
A30: AU0090:COM | B30: -0V | C30: WHT | D30: 14 | E30: 80 | F30: XT0081:1 | G30: PANEL A
A31: AF0091:V+ | B31: AF0091P | C31: WHT | D31: 14 | E31: 60 | F31: AF0094:V+ | G31: PANEL A
A32: AF0096:V+ | B32: FU0093 | C32: WHT | D32: 14 | E32: 60 | F32: FU0093:LD | G32: PANEL A
A34: FU0137:LI | B34: FU0136 | C34: WHT | D34: 14 | E34: 60 | F34: XT0138:1 | G34: PANEL A | H34: FU
A35: FU0210:LI | B35: FU0136 | C35: WHT | D35: 14 | E35: 60 | F35: XT0138:4 | G35: PANEL A
A36: FU1300:LI | B36: FU0136 | C36: WHT | D36: 14 | E36: 60 | F36: XT0138:3 | G36: PANEL A
A37: FU0010:LI | B37: FU0137 | C37: WHT | D37: 14 | E37: 60 | F37: FU0139:LI | G37: PANEL A
A38: FU0010:LI | B38: FU0137 | C38: WHT | D38: 14 | E38: 60 | F38: XT0139:1 | G38: PANEL A
A39: FU0139:LD | B39: FU0139 | C39: WHT | D39: 14 | E39: 60 | F39: XT0136:1 | G39: PANEL A
A41: FU0137:LD | B41: FU0137 | C41: WHT | D41: 12 | E41: 60 | F41: XT0139:1 | G41: PANEL A
A43: KA3103:A1 | B43: -009208 | C43: WHT | D43: 20 | E43: 60 | F43: AF0092:08 | G43: PANEL A | H43: KA
A44: KA3103:A2 | B44: -009224 | C44: WHT | D44: 20 | E44: 60 | F44: AF0092:24 | G44: PANEL A
A45: KA3220:A1 | B45: -009301 | C45: WHT | D45: 20 | E45: 60 | F45: AF0093:01 | G45: PANEL A
A46: KA3220:A2 | B46: -009317 | C46: WHT | D46: 20 | E46: 60 | F46: AF0093:17 | G46: PANEL A
A48: PC0470:INP_A | B48: -008601 | C48: WHT | D48: 20 | E48: 80 | F48: AF0086:01 | G48: PANEL A | H48: PC
A49: PC0470:-PWR | B49: -008617 | C49: WHT | D49: 20 | E49: 80 | F49: AF0086:17 | G49: PANEL A
A50: PC0470:+PWR | B50: -008633 | C50: WHT | D50: 20 | E50: 80 | F50: AF0086:33 | G50: PANEL A
...

Sheet B_S
A1: PANEL B
A2: JB70
A3: Project # | B3: 4L541
A4: Project Name | B4: Kaskida
A5: Revision | B5: B
A7: Controls DE | B7: A. CHEN
A8: Phone: | B8: 0
A9: Controls ME | B9: A. PLVAN
A10: Phone:
A12: From | G12: To
A13: Device ID | B13: Wire No. | C13: Wire ID | D13: Gauge/Size | E13: Length | F13: Device ID | G13: Location | H13: Bundle Name
A14: AF1201:COM | B14: -0V | C14: WHT | D14: 16 | E14: 120 | F14: XT0130:3 | G14: PANEL B | H14: AF/AU
A15: AU1200:COM | B15: -0V | C15: WHT | D15: 16 | E15: 120 | F15: XT0130:4 | G15: PANEL B
A16: AU1200:COM | B16: -0V | C16: WHT | D16: 16 | E16: 120 | F16: XT0130:4 | G16: PANEL B
A17: AF1207:COM | B17: AF1207N | C17: WHT | D17: 16 | E17: 60 | F17: AF1208:COM | G17: PANEL B
A18: AF1207:V+ | B18: AF1207P | C18: WHT | D18: 16 | E18: 60 | F18: AF1208:V+ | G18: PANEL B
A19: AF1202:COM | B19: AU1200N | C19: WHT | D19: 16 | E19: 60 | F19: AU1200:COM | G19: PANEL B
A20: AF1202:V+ | B20: AU1200P | C20: WHT | D20: 16 | E20: 60 | F20: AU1200:V+ | G20: PANEL B
A21: AU1200:V+ | B21: FU0120 | C21: WHT | D21: 16 | E21: 120 | F21: FU0120:LD | G21: PANEL B
A22: AU1200:V+ | B22: FU0120 | C22: WHT | D22: 16 | E22: 120 | F22: FU0120:LD | G22: PANEL B
A23: AF1201:V+ | B23: FU0121 | C23: WHT | D23: 16 | E23: 120 | F23: FU0121:LD | G23: PANEL B
A25: AP0294:- | B25: -0V | C25: WHT | D25: 20 | E25: 100 | F25: XT0235:5 | G25: PANEL B | H25: AP
A27: AP0294:+ | B27: FU2904 | C27: WHT | D27: 14 | E27: 60 | F27: FU2904:LD | G27: PANEL B
A29: FU0120:LI | B29: FU0130 | C29: WHT | D29: 14 | E29: 120 | F29: FU0130:LD | G29: PANEL B | H29: FU
A30: FU0130:LD | B30: FU0130 | C30: WHT | D30: 14 | E30: 80 | F30: XT0121:3 | G30: PANEL B
A31: FU0130:LI | B31: FU0136 | C31: WHT | D31: 14 | E31: 120 | F31: XT0130:1 | G31: PANEL B
A32: FU2900:LI | B32: FU0210 | C32: WHT | D32: 14 | E32: 60 | F32: XT0233:4 | G32: PANEL B
A33: FU2904:LI | B33: FU0210 | C33: WHT | D33: 14 | E33: 60 | F33: XT0233:4 | G33: PANEL B
A35: KA9130:A1 | B35: FU0210 | C35: WHT | D35: 14 | E35: 120 | F35: XT0233:2 | G35: PANEL B | H35: KA A1
A36: KA0137:A1 | B36: KA0137A1 | C36: WHT | D36: 20 | E36: 100 | F36: KT0142:18 | G36: PANEL B
A37: KA0132:21 | B37: KA0138A1 | C37: WHT | D37: 20 | E37: 100 | F37: KA0138:A1 | G37: PANEL B
A38: KA0120:A1 | B38: KA0231A1 | C38: WHT | D38: 20 | E38: 100 | F38: XT0130:5 | G38: PANEL B
A39: KA0132:A1 | B39: KA0231A1 | C39: WHT | D39: 20 | E39: 60 | F39: KA0141:A1 | G39: PANEL B
A40: KA0234:A1 | B40: KA0231A1 | C40: WHT | D40: 20 | E40: 100 | F40: XT0130:6 | G40: PANEL B
A41: KA0136:A1 | B41: PS32002 | C41: WHT | D41: 20 | E41: 60 | F41: XT0351:2 | G41: PANEL B
A42: KA4401:A1 | B42: PS44013 | C42: WHT | D42: 20 | E42: 100 | F42: XT0121:2 | G42: PANEL B
A44: KA0120:A2 | B44: -0V | C44: WHT | D44: 20 | E44: 120 | F44: XT0130:3 | G44: PANEL B | H44: KA A2
A45: KA0134:A2 | B45: -0V | C45: WHT | D45: 20 | E45: 60 | F45: KA0144:A2 | G45: PANEL B
A46: KA0241:A2 | B46: -0V | C46: WHT | D46: 20 | E46: 60 | F46: KA0253:A2 | G46: PANEL B
A47: KA0131:A2 | B47: -0V | C47: WHT | D47: 20 | E47: 60 | F47: KT0145:A2 | G47: PANEL B
...

Sheet GEAR BOX PANEL_S
A1: GEAR BOX PANEL
A2: JB78
A3: Project # | B3: 4L541
A4: Project Name | B4: Kaskida
A5: Revision | B5: B
A7: Controls DE | B7: A. CHEN
A8: Phone: | B8: 0
A9: Controls ME | B9: A. PLVAN
A10: Phone:
A12: From | G12: To
A13: Device ID | B13: Wire No. | C13: Wire ID | D13: Gauge/Size | E13: Length | F13: Device ID | G13: Location | H13: Bundle Name
A14: AF0322:33 | B14: PDS82001 | C14: WHT | D14: 20 | E14: 60 | F14: XT9078M:1 | G14: GEAR BOX PANEL | H14: AF
A15: AF0322:01 | B15: PDS82002 | C15: WHT | D15: 20 | E15: 60 | F15: XT9078M:2 | G15: GEAR BOX PANEL
A17: AU0320:COM | B17: -0V | C17: WHT | D17: 16 | E17: 60 | F17: XT0310:3 | G17: GEAR BOX PANEL
A18: AU0320:V+ | B18: FU0320 | C18: WHT | D18: 16 | E18: 60 | F18: FU0320:LD | G18: GEAR BOX PANEL
A20: FU0310:LI | B20: FU0136 | C20: WHT | D20: 14 | E20: 60 | F20: XT0310:1 | G20: GEAR BOX PANEL | H20: FU

Sheet JB73
A1: JB73
A3: Project # | B3: 4L541
A4: Project Name | B4: Kaskida
A5: Revision | B5: B
A7: Controls DE | B7: A. CHEN
A8: Phone: | B8: 0
A9: Controls ME | B9: A. PLVAN
A10: Phone:
A12: From | G12: To
A13: Device ID | B13: Wire No. | C13: Wire ID | D13: Gauge/Size | E13: Length | F13: Device ID | G13: Location | H13: Bundle Name
A14: AF0241:COM | B14: -0V | C14: WHT | D14: 20 | E14: 80 | F14: XT0250:4 | G14: JB73 | H14: AF
A15: AU0240:COM | B15: -0V | C15: WHT | D15: 20 | E15: 80 | F15: XT0250:5 | G15: JB73
A17: AU0270:COM | B17: -0V | C17: WHT | D17: 16 | E17: 80 | F17: XT0280:4 | G17: JB73
A18: AF0242:COM | B18: AU0240N | C18: WHT | D18: 16 | E18: 60 | F18: AU0240:COM | G18: JB73
A19: AF0242:V+ | B19: AU0240P | C19: WHT | D19: 16 | E19: 60 | F19: AU0240:V+ | G19: JB73
A20: AF0272:COM | B20: AU0270N | C20: WHT | D20: 16 | E20: 60 | F20: AU0270:COM | G20: JB73
A21: AF0272:V+ | B21: AU0270P | C21: WHT | D21: 16 | E21: 60 | F21: AU0270:V+ | G21: JB73
A22: AU0240:V+ | B22: FU0240 | C22: WHT | D22: 16 | E22: 60 | F22: FU0240:LD | G22: JB73
A23: AF0241:V+ | B23: FU0241 | C23: WHT | D23: 16 | E23: 60 | F23: FU0241:LD | G23: JB73
A24: AU0270:V+ | B24: FU0270 | C24: WHT | D24: 16 | E24: 80 | F24: FU0270:LD | G24: JB73
A25: AF0271:V+ | B25: FU0271 | C25: WHT | D25: 16 | E25: 80 | F25: FU0271:LD | G25: JB73
A27: AF0271:COM | B27: -0V | C27: WHT | D27: 14 | E27: 60 | F27: XT0280:4 | G27: JB73
A29: AP0292:- | B29: -0V | C29: WHT | D29: 20 | E29: 80 | F29: XT0250:5 | G29: JB73 | H29: AP
A31: AP0291:- | B31: -0V | C31: WHT | D31: 14 | E31: 80 | F31: XT0250:5 | G31: JB73
A32: AP0291:+ | B32: FU0292 | C32: WHT | D32: 14 | E32: 80 | F32: FU0292:LD | G32: JB73
A33: AP0292:+ | B33: FU0293LD | C33: WHT | D33: 14 | E33: 80 | F33: FU0293:LD | G33: JB73
A35: FU0250:LI | B35: FU0136 | C35: WHT | D35: 14 | E35: 60 | F35: XT0250:1 | G35: JB73 | H35: FU
A36: FU0280:LI | B36: FU0136 | C36: WHT | D36: 14 | E36: 60 | F36: XT0280:1 | G36: JB73
A37: FU0240:LI | B37: FU0250 | C37: WHT | D37: 14 | E37: 60 | F37: FU0253:LI | G37: JB73
A38: FU0250:LD | B38: FU0250 | C38: WHT | D38: 14 | E38: 80 | F38: XT0250:6 | G38: JB73
A39: FU0292:LI | B39: FU0250 | C39: WHT | D39: 14 | E39: 80 | F39: XT0250:6 | G39: JB73
A40: FU0293:LI | B40: FU0250 | C40: WHT | D40: 14 | E40: 80 | F40: XT0250:6 | G40: JB73
A41: FU0270:LI | B41: FU0280 | C41: WHT | D41: 14 | E41: 60 | F41: FU0283:LI | G41: JB73
A42: FU0280:LD | B42: FU0280 | C42: WHT | D42: 14 | E42: 80 | F42: XT0280:2 | G42: JB73
A44: XT0251:3 | B44: -0V | C44: WHT | D44: 20 | E44: 60 | F44: XT0250:5 | G44: JB73 | H44: XT
A45: XT0281:3 | B45: -0V | C45: WHT | D45: 20 | E45: 60 | F45: XT0280:4 | G45: JB73
A47: XT0250:4 | B47: -0V | C47: WHT | D47: 14 | E47: 60 | F47: XT0280:3 | G47: JB73
A48: XT0250:2 | B48: FU0136 | C48: WHT | D48: 14 | E48: 60 | F48: XT0280:1 | G48: JB73
A49: XT0251:1 | B49: FU0250 | C49: WHT | D49: 14 | E49: 60 | F49: XT0250:6 | G49: JB73
A50: XT0281:1 | B50: FU0280 | C50: WHT | D50: 14 | E50: 60 | F50: XT0280:2 | G50: JB73

Sheet BOP PANEL_S
A1: BOP PANEL
A2: JB74
A3: Project # | B3: 4L541
A4: Project Name | B4: Kaskida
A5: Revision | B5: B
A7: Controls DE | B7: A. CHEN
A8: Phone: | B8: 0
A9: Controls ME | B9: A. PLVAN
A10: Phone:
A12: From | G12: To
A13: Device ID | B13: Wire No. | C13: Wire ID | D13: Gauge/Size | E13: Length | F13: Device ID | G13: Location | H13: Bundle Name
A14: AF0146:COM | B14: -0V | C14: WHT | D14: 16 | E14: 60 | F14: XT0140:3 | G14: BOP PANEL | H14: AF140s
A15: AF0142:COM | B15: AU0140N | C15: WHT | D15: 16 | E15: 60 | F15: AU0140:COM | G15: BOP PANEL
A16: AF0142:V+ | B16: AU0140P | C16: WHT | D16: 16 | E16: 60 | F16: AU0140:V+ | G16: BOP PANEL
A17: AU0140:V+ | B17: FU0140 | C17: WHT | D17: 16 | E17: 60 | F17: FU0140:LD | G17: BOP PANEL
A18: AF0141:V+ | B18: FU0141 | C18: WHT | D18: 16 | E18: 60 | F18: FU0141:LD | G18: BOP PANEL
A20: AF0141:COM | B20: -0V | C20: WHT | D20: 14 | E20: 60 | F20: XT0140:3 | G20: BOP PANEL
A21: AU0140:COM | B21: -0V | C21: WHT | D21: 14 | E21: 60 | F21: XT0140:2 | G21: BOP PANEL
A23: AF0181:COM | B23: -0V | C23: WHT | D23: 16 | E23: 80 | F23: XT0180:2 | G23: BOP PANEL | H23: AF180s
A24: AF0184:COM | B24: -0V | C24: WHT | D24: 16 | E24: 80 | F24: XT0180:1 | G24: BOP PANEL
A25: AF0183:COM | B25: AF0183N | C25: WHT | D25: 16 | E25: 60 | F25: AF0185:COM | G25: BOP PANEL
A26: AF0183:V+ | B26: AF0183P | C26: WHT | D26: 16 | E26: 60 | F26: AF0185:V+ | G26: BOP PANEL
A27: AF0186:COM | B27: AF0186N | C27: WHT | D27: 16 | E27: 60 | F27: AF0188:COM | G27: BOP PANEL
A28: AF0186:V+ | B28: AF0186P | C28: WHT | D28: 16 | E28: 60 | F28: AF0188:V+ | G28: BOP PANEL
A29: AF0182:COM | B29: AU0180N | C29: WHT | D29: 16 | E29: 60 | F29: AU0180:COM | G29: BOP PANEL
A30: AF0182:V+ | B30: AU0180P | C30: WHT | D30: 16 | E30: 60 | F30: AU0180:V+ | G30: BOP PANEL
A31: AU0180:V+ | B31: FU0180 | C31: WHT | D31: 16 | E31: 80 | F31: FU0180:LD | G31: BOP PANEL
A32: AF0181:V+ | B32: FU0181 | C32: WHT | D32: 16 | E32: 80 | F32: FU0181:LD | G32: BOP PANEL
A33: AF0184:V+ | B33: FU0184 | C33: WHT | D33: 16 | E33: 100 | F33: FU0184:LD | G33: BOP PANEL
A34: AF0187:V+ | B34: FU0187 | C34: WHT | D34: 16 | E34: 100 | F34: FU0187:LD | G34: BOP PANEL
A36: AF0187:COM | B36: -0V | C36: WHT | D36: 14 | E36: 80 | F36: XT0180:2 | G36: BOP PANEL
A37: AU0180:COM | B37: -0V | C37: WHT | D37: 14 | E37: 80 | F37: XT0180:1 | G37: BOP PANEL
A39: AP0293:- | B39: -0V | C39: WHT | D39: 14 | E39: 60 | F39: XT0140:3 | G39: BOP PANEL | H39: AP
A40: AP0293:+ | B40: FU2901 | C40: WHT | D40: 14 | E40: 100 | F40: FU2901:LD | G40: BOP PANEL
A42: FU0142:LD | B42: FU0142 | C42: WHT | D42: 16 | E42: 60 | F42: AF0146:V+ | G42: BOP PANEL | H42: FU
A43: FU0142:LD | B43: FU0142 | C43: WHT | D43: 16 | E43: 60 | F43: XT0140:7 | G43: BOP PANEL
A45: FU0570:LI | B45: FU0210 | C45: WHT | D45: 14 | E45: 60 | F45: XT0140:1 | G45: BOP PANEL
A46: FU1212:LI | B46: FU0210 | C46: WHT | D46: 14 | E46: 60 | F46: FU2901:LI | G46: BOP PANEL
A47: FU1212:LI | B47: FU0210 | C47: WHT | D47: 14 | E47: 60 | F47: XT0140:1 | G47: BOP PANEL
A48: FU0140:LI | B48: FU0570 | C48: WHT | D48: 14 | E48: 80 | F48: FU0570:LD | G48: BOP PANEL
...

Sheet JB74 L RAIL
A1: JB74 LEFT RAIL
A2: JB74
A3: Project # | B3: 4L541
A4: Project Name | B4: Kaskida
A5: Revision | B5: B
A7: Controls DE | B7: A. CHEN
A8: Phone: | B8: 0
A9: Controls ME | B9: A. PLVAN
A10: Phone:
A12: From | G12: To
A13: Device ID | B13: Wire No. | C13: Wire ID | D13: Gauge/Size | E13: Length | F13: Device ID | G13: Location | H13: Bundle Name
A14: KA0537:A1 | B14: ESTOP | C14: WHT | D14: 20 | E14: 60 | F14: KA0538:A1 | G14: JB74 L RAIL | H14: KA A1
A15: KA0539:A1 | B15: ESTOP | C15: WHT | D15: 20 | E15: 60 | F15: KA0631:A1 | G15: JB74 L RAIL
A16: KA0631:A1 | B16: ESTOP | C16: WHT | D16: 20 | E16: 60 | F16: KA0632:A1 | G16: JB74 L RAIL
A17: KA0536:A1 | B17: KA0231A1 | C17: WHT | D17: 20 | E17: 60 | F17: KA1530:A1 | G17: JB74 L RAIL
A18: KA0540:A1 | B18: KA053214 | C18: WHT | D18: 20 | E18: 60 | F18: KA0532:14 | G18: JB74 L RAIL
A19: KA0541:A1 | B19: KA053224 | C19: WHT | D19: 20 | E19: 80 | F19: KA0532:24 | G19: JB74 L RAIL
A20: KA0580:A1 | B20: KA053424 | C20: WHT | D20: 20 | E20: 60 | F20: KA0534:24 | G20: JB74 L RAIL
A21: KA0560:A1 | B21: KA053724 | C21: WHT | D21: 20 | E21: 60 | F21: KA0537:24 | G21: JB74 L RAIL
A22: KA0561:A1 | B22: KA053814 | C22: WHT | D22: 20 | E22: 60 | F22: KA0538:14 | G22: JB74 L RAIL
A23: KA0581:A1 | B23: KA053824 | C23: WHT | D23: 20 | E23: 60 | F23: KA0538:24 | G23: JB74 L RAIL
A24: KA9599:A1 | B24: KA9599A1 | C24: WHT | D24: 20 | E24: 60 | F24: XT9074M:8 | G24: JB74 L RAIL
A26: KA0531:A2 | B26: -0V | C26: WHT | D26: 20 | E26: 60 | F26: KA1530:A2 | G26: JB74 L RAIL | H26: KA A2
A27: KA0536:A2 | B27: -0V | C27: WHT | D27: 20 | E27: 60 | F27: KA1530:A2 | G27: JB74 L RAIL
A28: KA0537:A2 | B28: -0V | C28: WHT | D28: 20 | E28: 60 | F28: KA0538:A2 | G28: JB74 L RAIL
A29: KA0539:A2 | B29: -0V | C29: WHT | D29: 20 | E29: 60 | F29: KA0631:A2 | G29: JB74 L RAIL
A30: KA0631:A2 | B30: -0V | C30: WHT | D30: 20 | E30: 60 | F30: KA0632:A2 | G30: JB74 L RAIL
A31: KA9599:A2 | B31: KA9599A2 | C31: WHT | D31: 20 | E31: 60 | F31: XT9074M:1 | G31: JB74 L RAIL
A32: KA0540:A2 | B32: SV76212 | C32: WHT | D32: 20 | E32: 80 | F32: XT9074M:54 | G32: JB74 L RAIL
A33: KA0541:A2 | B33: SV76412 | C33: WHT | D33: 20 | E33: 80 | F33: XT9074M:60 | G33: JB74 L RAIL
A35: KA0535:11 | B35: KA053511 | C35: WHT | D35: 20 | E35: 60 | F35: KA0554:14 | G35: JB74 L RAIL | H35: KA
A36: KA0540:11 | B36: KA054011 | C36: WHT | D36: 20 | E36: 60 | F36: KA0550:14 | G36: JB74 L RAIL
A37: KA0541:11 | B37: KA054111 | C37: WHT | D37: 20 | E37: 60 | F37: KA0551:14 | G37: JB74 L RAIL
A38: KA0560:11 | B38: KA056011 | C38: WHT | D38: 20 | E38: 60 | F38: KA0570:14 | G38: JB74 L RAIL
A39: KA0561:11 | B39: KA056111 | C39: WHT | D39: 20 | E39: 60 | F39: KA0571:14 | G39: JB74 L RAIL
A40: KA0535:21 | B40: KA057414 | C40: WHT | D40: 20 | E40: 60 | F40: KA0574:14 | G40: JB74 L RAIL
A41: KA0580:11 | B41: KA058011 | C41: WHT | D41: 20 | E41: 60 | F41: KA0590:14 | G41: JB74 L RAIL
A42: KA0581:11 | B42: KA058111 | C42: WHT | D42: 20 | E42: 60 | F42: KA0591:14 | G42: JB74 L RAIL
A43: KA0594:14 | B43: KA153011 | C43: WHT | D43: 20 | E43: 60 | F43: KA1530:11 | G43: JB74 L RAIL
A44: KA0537:11 | B44: SV75651 | C44: WHT | D44: 20 | E44: 60 | F44: XT9074M:71 | G44: JB74 L RAIL
...

Sheet JB74 R RAIL
A1: JB70 RIGHT RAIL
A2: JB74
A3: Project # | B3: 4L541
A4: Project Name | B4: Kaskida
A5: Revision | B5: B
A7: Controls DE | B7: A. CHEN
A8: Phone: | B8: 0
A9: Controls ME | B9: A. PLVAN
A10: Phone:
A12: From | G12: To
A13: Device ID | B13: Wire No. | C13: Wire ID | D13: Gauge/Size | E13: Length | F13: Device ID | G13: Location | H13: Bundle Name
A14: BA0007:V1(-) | B14: -0V | C14: WHT | D14: 16 | E14: 60 | F14: XT0004:2 | G14: JB74 R RAIL | H14: BA0007
A15: BA0008:V1(-) | B15: -0V | C15: WHT | D15: 16 | F15: XT0004:4 | G15: JB74 R RAIL
A17: BA1212:NEG | B17: -0V | C17: WHT | D17: 16 | E17: 160 | F17: XT0140:2 | G17: BOP | H17: BA-BOP
A18: BA0007:V1(+) | B18: FU0007 | C18: WHT | D18: 16 | E18: 160 | F18: FU0007:LD | G18: BOP
A19: BA0008:V1(+) | B19: FU0008 | C19: WHT | D19: 16 | E19: 160 | F19: FU0008:LD | G19: BOP
A20: BA1212:POS | B20: FU1212LD | C20: WHT | D20: 16 | E20: 160 | F20: FU1212:LD | G20: BOP
A22: XT9075M:98 | B22: SV74822 | C22: WHT | D22: 20 | E22: 160 | F22: AF0187:20 | G22: BOP | H22: XT-BOP
A23: XT9075M:45 | B23: SV75062 | C23: WHT | D23: 20 | E23: 160 | F23: AF0146:30 | G23: BOP
A24: XT9075M:5 | B24: SV75142 | C24: WHT | D24: 20 | E24: 160 | F24: AF0141:18 | G24: BOP
A25: XT9075M:17 | B25: SV75162 | C25: WHT | D25: 20 | E25: 160 | F25: AF0141:24 | G25: BOP
A26: XT9075M:29 | B26: SV75362 | C26: WHT | D26: 20 | E26: 160 | F26: AF0146:20 | G26: BOP
A27: XT9075M:80 | B27: SV75411 | C27: WHT | D27: 20 | E27: 160 | F27: AF0181:10 | G27: BOP
A28: XT9075M:81 | B28: SV75412 | C28: WHT | D28: 20 | E28: 160 | F28: AF0181:26 | G28: BOP
A29: XT9075M:62 | B29: SV75421 | C29: WHT | D29: 20 | E29: 160 | F29: AF0181:06 | G29: BOP
A30: XT9075M:63 | B30: SV75422 | C30: WHT | D30: 20 | E30: 160 | F30: AF0181:22 | G30: BOP
A31: XT9075M:71 | B31: SV75431 | C31: WHT | D31: 20 | E31: 160 | F31: AF0181:08 | G31: BOP
A32: XT9075M:72 | B32: SV75432 | C32: WHT | D32: 20 | E32: 160 | F32: AF0181:24 | G32: BOP
A33: XT9075M:86 | B33: SV75822 | C33: WHT | D33: 20 | E33: 160 | F33: AF0187:16 | G33: BOP
A34: XT9075M:51 | B34: SV76062 | C34: WHT | D34: 20 | E34: 160 | F34: AF0181:16 | G34: BOP
... A113: XT0004:3 | B113: FU0210 | C113: WHT | D113: 16 | E113: 160 | F113: FU0008:LI | G113: BOP

Sheet Bundle Tag Info
A1: BP-KEMD
A2: 4L541
A3: B.1
A6: JB70 | B6: JB70 R RAIL | C6: JB70 L RAIL | D6: PLC | E6: A | F6: B | G6: GEAR BOX | H6: JB73 | I6: BOP | J6: JB74 L RAIL | K6: JB74 R RAIL | L6: Panel Name | M6: Panel Name | N6: Panel Name | O6: Panel Name | P6: Panel Name | Q6: Panel Name | R6: Panel Name | S6: Panel Name | T6: Panel Name | U6: Panel Name | V6: Panel Name | W6: Panel Name | X6: Panel Name | Y6: Panel Name | Z6: Panel Name | AA6: Panel Name | AB6: Panel Name | AC6: Panel Name | AD6: Panel Name | AE6: Panel Name
A7: AT1100 | B7: BA/FU | C7: XT-A | D7: BA | E7: AF080s | F7: AF/AU | G7: AF | H7: AF | I7: AF140s | J7: KA A1 | K7: BA0007
A8: SA0471 | B8: FU/UJ-A | C8: XT01s-B | D8: AT/FU | E8: AF/AU090s | F8: AP | G8: FU | H8: AP | I8: AF180s | J8: KA A2 | K8: BA-BOP
A9: SA0473 | C9: XT9070s-B | D9: UV-A | E9: FU | F9: FU | H9: FU | I9: AP | J9: KA | K9: XT-BOP
A10: SA0474 | C10: XT-PLC | D10: BA-B | E10: KA | F10: KA A1 | H10: XT | I10: FU | J10: KA A2-R RAIL
A11: SB0471 | D11: FU/XT-B | E11: PC | F11: KA A2 | I11: KT L/S | J11: KA-R RAIL
A12: SB0472 | E12: UJ | F12: KA | I12: KT R/S | J12: KA A1-BOP
A13: SB0473 | E13: XT | F13: KT L/S | I13: XT | J13: KA A2-BOP
A14: SB0474 | E14: AF080s-B | F14: KT R/S | J14: KA-BOP
A15: SH0470 | E15: AF090s-B | F15: XT | J15: XT-BOP
A16: SH0471 | E16: AP-B
A17: SH0472 | E17: FU-B
E18: KA-B
E19: XT-B

Sheet Bundle Tags2
A1: =IF('Bundle Tag Info'!A6<>"Panel Name",'Bundle Tag Info'!A6,"") -> JB70 | B1: =IF('Bundle Tag Info'!B6<>"Panel Name",'Bundle Tag Info'!B6,"") -> JB70 R RAIL | C1: =IF('Bundle Tag Info'!C6<>"Panel Name",'Bundle Tag Info'!C6,"") -> JB70 L RAIL | D1: =IF('Bundle Tag Info'!D6<>"Panel Name",'Bundle Tag Info'!D6,"") -> PLC | E1: =IF('Bundle Tag Info'!E6<>"Panel Name",'Bundle Tag Info'!E6,"") -> A | F1: =IF('Bundle Tag Info'!F6<>"Panel Name",'Bundle Tag Info'!F6,"") -> B | G1: =IF('Bundle Tag Info'!H6<>"Panel Name",'Bundle Tag Info'!H6,"") -> JB73 | H1: =IF('Bundle Tag Info'!I6<>"Panel Name",'Bundle Tag Info'!I6,"") -> BOP | I1: =IF('Bundle Tag Info'!J6<>"Panel Name",'Bundle Tag Info'!J6,"") -> JB74 L RAIL | J1: =IF('Bundle Tag Info'!K6<>"Panel Name",'Bundle Tag Info'!K6,"") -> JB74 R RAIL | K1: =IF('Bundle Tag Info'!L6<>"Panel Name",'Bundle Tag Info'!L6,"") | L1: =IF('Bundle Tag Info'!M6<>"Panel Name",'Bundle Tag Info'!M6,"") | M1: =IF('Bundle Tag Info'!N6<>"Panel Name",'Bundle Tag Info'!N6,"") | N1: =IF('Bundle Tag Info'!O6<>"Panel Name",'Bundle Tag Info'!O6,"") | ... AD1: =IF('Bundle Tag Info'!AE6<>"Panel Name",'Bundle Tag Info'!AE6,"")
A2: =IF('Bundle Tag Info'!A$7<>"",CONCATENATE('Bundle Tag Info'!$A$1," ",CHAR(10),'Bundle Tag Info'!$A$2," ",'Bundle Tag Info'!$A$3,CHAR(10),'Bundle Tag Info'!A$6,CHAR(10),'Bundle Tag Info'!A$7),"") -> BP-KEMD 4L541 B.1 JB70 AT1100 | B2: =IF('Bundle Tag Info'!B$7<>"",CONCATENATE('Bundle Tag Info'!$A$1," ",CHAR(10),'Bundle Tag Info'!$A$2," ",'Bundle Tag Info'!$A$3,CHAR(10),'Bundle Tag Info'!B$6,CHAR(10),'Bundle Tag Info'!B$7),"") -> BP-KEMD 4L541 B.1 JB70 R RAIL BA/FU | C2: =IF('Bundle Tag Info'!C$7<>"",CONCATENATE('Bundle Tag Info'!$A$1," ",CHAR(10),'Bundle Tag Info'!$A$2," ",'Bundle Tag Info'!$A$3,CHAR(10),'Bundle Tag Info'!C$6,CHAR(10),'Bundle Tag Info'!C$7),"") -> BP-KEMD 4L541 B.1 JB70 L RAIL XT-A | D2: =IF('Bundle Tag Info'!D$7<>"",CONCATENATE('Bundle Tag Info'!$A$1," ",CHAR(10),'Bundle Tag Info'!$A$2," ",'Bundle Tag Info'!$A$3,CHAR(10),'Bundle Tag Info'!D$6,CHAR(10),'Bundle Tag Info'!D$7),"") -> BP-KEMD 4L541 B.1 PLC BA | E2: =IF('Bundle Tag Info'!E$7<>"",CONCATENATE('Bundle Tag Info'!$A$1," ",CHAR(10),'Bundle Tag Info'!$A$2," ",'Bundle Tag Info'!$A$3,CHAR(10),'Bundle Tag Info'!E$6,CHAR(10),'Bundle Tag Info'!E$7),"") -> BP-KEMD 4L541 B.1 A AF080s | F2: =IF('Bundle Tag Info'!F$7<>"",CONCATENATE('Bundle Tag Info'!$A$1," ",CHAR(10),'Bundle Tag Info'!$A$2," ",'Bundle Tag Info'!$A$3,CHAR(10),'Bundle Tag Info'!F$6,CHAR(10),'Bundle Tag Info'!F$7),"") -> BP-KEMD 4L541 B.1 B AF/AU | G2: =IF('Bundle Tag Info'!H$7<>"",CONCATENATE('Bundle Tag Info'!$A$1," ",CHAR(10),'Bundle Tag Info'!$A$2," ",'Bundle Tag Info'!$A$3,CHAR(10),'Bundle Tag Info'!H$6,CHAR(10),'Bundle Tag Info'!H$7),"") -> BP-KEMD 4L541 B.1 JB73 AF | H2: =IF('Bundle Tag Info'!I$7<>"",CONCATENATE('Bundle Tag Info'!$A$1," ",CHAR(10),'Bundle Tag Info'!$A$2," ",'Bundle Tag Info'!$A$3,CHAR(10),'Bundle Tag Info'!I$6,CHAR(10),'Bundle Tag Info'!I$7),"") -> BP-KEMD 4L541 B.1 BOP AF140s | I2: =IF('Bundle Tag Info'!J$7<>"",CONCATENATE('Bundle Tag Info'!$A$1," ",CHAR(10),'Bundle Tag Info'!$A$2," ",'Bundle Tag Info'!$A$3,CHAR(10),'Bundle Tag Info'!J$6,CHAR(10),'Bundle Tag Info'!J$7),"") -> BP-KEMD 4L541 B.1 JB74 L RAIL KA A1 | J2: =IF('Bundle Tag Info'!K$7<>"",CONCATENATE('Bundle Tag Info'!$A$1," ",CHAR(10),'Bundle Tag Info'!$A$2," ",'Bundle Tag Info'!$A$3,CHAR(10),'Bundle Tag Info'!K$6,CHAR(10),'Bundle Tag Info'!K$7),"") -> BP-KEMD 4L541 B.1 JB74 R RAIL BA0007 | K2: =IF('Bundle Tag Info'!L$7<>"",CONCATENATE('Bundle Tag Info'!$A$1," ",CHAR(10),'Bundle Tag Info'!$A$2," ",'Bundle Tag Info'!$A$3,CHAR(10),'Bundle Tag Info'!L$6,CHAR(10),'Bundle Tag Info'!L$7),"") | L2: =IF('Bundle Tag Info'!M$7<>"",CONCATENATE('Bundle Tag Info'!$A$1," ",CHAR(10),'Bundle Tag Info'!$A$2," ",'Bundle Tag Info'!$A$3,CHAR(10),'Bundle Tag Info'!M$6,CHAR(10),'Bundle Tag Info'!M$7),"") | M2: =IF('Bundle Tag Info'!N$7<>"",CONCATENATE('Bundle Tag Info'!$A$1," ",CHAR(10),'Bundle Tag Info'!$A$2," ",'Bundle Tag Info'!$A$3,CHAR(10),'Bundle Tag Info'!N$6,CHAR(10),'Bundle Tag Info'!N$7),"") | N2: =IF('Bundle Tag Info'!O$7<>"",CONCATENATE('Bundle Tag Info'!$A$1," ",CHAR(10),'Bundle Tag Info'!$A$2," ",'Bundle Tag Info'!$A$3,CHAR(10),'Bundle Tag Info'!O$6,CHAR(10),'Bundle Tag Info'!O$7),"") | ... AD2: =IF('Bundle Tag Info'!AE$7<>"",CONCATENATE('Bundle Tag Info'!$A$1," ",CHAR(10),'Bundle Tag Info'!$A$2," ",'Bundle Tag Info'!$A$3,CHAR(10),'Bundle Tag Info'!AE$6,CHAR(10),'Bundle Tag Info'!AE$7),"")
A3: =IF('Bundle Tag Info'!A$8<>"",CONCATENATE('Bundle Tag Info'!$A$1," ",CHAR(10),'Bundle Tag Info'!$A$2," ",'Bundle Tag Info'!$A$3,CHAR(10),'Bundle Tag Info'!A$6,CHAR(10),'Bundle Tag Info'!A$8),"") -> BP-KEMD 4L541 B.1 JB70 SA0471 | B3: =IF('Bundle Tag Info'!B$8<>"",CONCATENATE('Bundle Tag Info'!$A$1," ",CHAR(10),'Bundle Tag Info'!$A$2," ",'Bundle Tag Info'!$A$3,CHAR(10),'Bundle Tag Info'!B$6,CHAR(10),'Bundle Tag Info'!B$8),"") -> BP-KEMD 4L541 B.1 JB70 R RAIL FU/UJ-A | C3: =IF('Bundle Tag Info'!C$8<>"",CONCATENATE('Bundle Tag Info'!$A$1," ",CHAR(10),'Bundle Tag Info'!$A$2," ",'Bundle Tag Info'!$A$3,CHAR(10),'Bundle Tag Info'!C$6,CHAR(10),'Bundle Tag Info'!C$8),"") -> BP-KEMD 4L541 B.1 JB70 L RAIL XT01s-B | D3: =IF('Bundle Tag Info'!D$8<>"",CONCATENATE('Bundle Tag Info'!$A$1," ",CHAR(10),'Bundle Tag Info'!$A$2," ",'Bundle Tag Info'!$A$3,CHAR(10),'Bundle Tag Info'!D$6,CHAR(10),'Bundle Tag Info'!D$8),"") -> BP-KEMD 4L541 B.1 PLC AT/FU | E3: =IF('Bundle Tag Info'!E$8<>"",CONCATENATE('Bundle Tag Info'!$A$1," ",CHAR(10),'Bundle Tag Info'!$A$2," ",'Bundle Tag Info'!$A$3,CHAR(10),'Bundle Tag Info'!E$6,CHAR(10),'Bundle Tag Info'!E$8),"") -> BP-KEMD 4L541 B.1 A AF/AU090s | F3: =IF('Bundle Tag Info'!F$8<>"",CONCATENATE('Bundle Tag Info'!$A$1," ",CHAR(10),'Bundle Tag Info'!$A$2," ",'Bundle Tag Info'!$A$3,CHAR(10),'Bundle Tag Info'!F$6,CHAR(10),'Bundle Tag Info'!F$8),"") -> BP-KEMD 4L541 B.1 B AP | G3: =IF('Bundle Tag Info'!H$8<>"",CONCATENATE('Bundle Tag Info'!$A$1," ",CHAR(10),'Bundle Tag Info'!$A$2," ",'Bundle Tag Info'!$A$3,CHAR(10),'Bundle Tag Info'!H$6,CHAR(10),'Bundle Tag Info'!H$8),"") -> BP-KEMD 4L541 B.1 JB73 AP | H3: =IF('Bundle Tag Info'!I$8<>"",CONCATENATE('Bundle Tag Info'!$A$1," ",CHAR(10),'Bundle Tag Info'!$A$2," ",'Bundle Tag Info'!$A$3,CHAR(10),'Bundle Tag Info'!I$6,CHAR(10),'Bundle Tag Info'!I$8),"") -> BP-KEMD 4L541 B.1 BOP AF180s | I3: =IF('Bundle Tag Info'!J$8<>"",CONCATENATE('Bundle Tag Info'!$A$1," ",CHAR(10),'Bundle Tag Info'!$A$2," ",'Bundle Tag Info'!$A$3,CHAR(10),'Bundle Tag Info'!J$6,CHAR(10),'Bundle Tag Info'!J$8),"") -> BP-KEMD 4L541 B.1 JB74 L RAIL KA A2 | J3: =IF('Bundle Tag Info'!K$8<>"",CONCATENATE('Bundle Tag Info'!$A$1," ",CHAR(10),'Bundle Tag Info'!$A$2," ",'Bundle Tag Info'!$A$3,CHAR(10),'Bundle Tag Info'!K$6,CHAR(10),'Bundle Tag Info'!K$8),"") -> BP-KEMD 4L541 B.1 JB74 R RAIL BA-BOP | K3: =IF('Bundle Tag Info'!L$8<>"",CONCATENATE('Bundle Tag Info'!$A$1," ",CHAR(10),'Bundle Tag Info'!$A$2," ",'Bundle Tag Info'!$A$3,CHAR(10),'Bundle Tag Info'!L$6,CHAR(10),'Bundle Tag Info'!L$8),"") | L3: =IF('Bundle Tag Info'!M$8<>"",CONCATENATE('Bundle Tag Info'!$A$1," ",CHAR(10),'Bundle Tag Info'!$A$2," ",'Bundle Tag Info'!$A$3,CHAR(10),'Bundle Tag Info'!M$6,CHAR(10),'Bundle Tag Info'!M$8),"") | M3: =IF('Bundle Tag Info'!N$8<>"",CONCATENATE('Bundle Tag Info'!$A$1," ",CHAR(10),'Bundle Tag Info'!$A$2," ",'Bundle Tag Info'!$A$3,CHAR(10),'Bundle Tag Info'!N$6,CHAR(10),'Bundle Tag Info'!N$8),"") | N3: =IF('Bundle Tag Info'!O$8<>"",CONCATENATE('Bundle Tag Info'!$A$1," ",CHAR(10),'Bundle Tag Info'!$A$2," ",'Bundle Tag Info'!$A$3,CHAR(10),'Bundle Tag Info'!O$6,CHAR(10),'Bundle Tag Info'!O$8),"") | ... AD3: =IF('Bundle Tag Info'!AE$8<>"",CONCATENATE('Bundle Tag Info'!$A$1," ",CHAR(10),'Bundle Tag Info'!$A$2," ",'Bundle Tag Info'!$A$3,CHAR(10),'Bundle Tag Info'!AE$6,CHAR(10),'Bundle Tag Info'!AE$8),"")
A4: =IF('Bundle Tag Info'!A$9<>"",CONCATENATE('Bundle Tag Info'!$A$1," ",CHAR(10),'Bundle Tag Info'!$A$2," ",'Bundle Tag Info'!$A$3,CHAR(10),'Bundle Tag Info'!A$6,CHAR(10),'Bundle Tag Info'!A$9),"") -> BP-KEMD 4L541 B.1 JB70 SA0473 | B4: =IF('Bundle Tag Info'!B$9<>"",CONCATENATE('Bundle Tag Info'!$A$1," ",CHAR(10),'Bundle Tag Info'!$A$2," ",'Bundle Tag Info'!$A$3,CHAR(10),'Bundle Tag Info'!B$6,CHAR(10),'Bundle Tag Info'!B$9),"") | C4: =IF('Bundle Tag Info'!C$9<>"",CONCATENATE('Bundle Tag Info'!$A$1," ",CHAR(10),'Bundle Tag Info'!$A$2," ",'Bundle Tag Info'!$A$3,CHAR(10),'Bundle Tag Info'!C$6,CHAR(10),'Bundle Tag Info'!C$9),"") -> BP-KEMD 4L541 B.1 JB70 L RAIL XT9070s-B | D4: =IF('Bundle Tag Info'!D$9<>"",CONCATENATE('Bundle Tag Info'!$A$1," ",CHAR(10),'Bundle Tag Info'!$A$2," ",'Bundle Tag Info'!$A$3,CHAR(10),'Bundle Tag Info'!D$6,CHAR(10),'Bundle Tag Info'!D$9),"") -> BP-KEMD 4L541 B.1 PLC UV-A | E4: =IF('Bundle Tag Info'!E$9<>"",CONCATENATE('Bundle Tag Info'!$A$1," ",CHAR(10),'Bundle Tag Info'!$A$2," ",'Bundle Tag Info'!$A$3,CHAR(10),'Bundle Tag Info'!E$6,CHAR(10),'Bundle Tag Info'!E$9),"") -> BP-KEMD 4L541 B.1 A FU | F4: =IF('Bundle Tag Info'!F$9<>"",CONCATENATE('Bundle Tag Info'!$A$1," ",CHAR(10),'Bundle Tag Info'!$A$2," ",'Bundle Tag Info'!$A$3,CHAR(10),'Bundle Tag Info'!F$6,CHAR(10),'Bundle Tag Info'!F$9),"") -> BP-KEMD 4L541 B.1 B FU | G4: =IF('Bundle Tag Info'!H$9<>"",CONCATENATE('Bundle Tag Info'!$A$1," ",CHAR(10),'Bundle Tag Info'!$A$2," ",'Bundle Tag Info'!$A$3,CHAR(10),'Bundle Tag Info'!H$6,CHAR(10),'Bundle Tag Info'!H$9),"") -> BP-KEMD 4L541 B.1 JB73 FU | H4: =IF('Bundle Tag Info'!I$9<>"",CONCATENATE('Bundle Tag Info'!$A$1," ",CHAR(10),'Bundle Tag Info'!$A$2," ",'Bundle Tag Info'!$A$3,CHAR(10),'Bundle Tag Info'!I$6,CHAR(10),'Bundle Tag Info'!I$9),"") -> BP-KEMD 4L541 B.1 BOP AP | I4: =IF('Bundle Tag Info'!J$9<>"",CONCATENATE('Bundle Tag Info'!$A$1," ",CHAR(10),'Bundle Tag Info'!$A$2," ",'Bundle Tag Info'!$A$3,CHAR(10),'Bundle Tag Info'!J$6,CHAR(10),'Bundle Tag Info'!J$9),"") -> BP-KEMD 4L541 B.1 JB74 L RAIL KA | J4: =IF('Bundle Tag Info'!K$9<>"",CONCATENATE('Bundle Tag Info'!$A$1," ",CHAR(10),'Bundle Tag Info'!$A$2," ",'Bundle Tag Info'!$A$3,CHAR(10),'Bundle Tag Info'!K$6,CHAR(10),'Bundle Tag Info'!K$9),"") -> BP-KEMD 4L541 B.1 JB74 R RAIL XT-BOP | K4: =IF('Bundle Tag Info'!L$9<>"",CONCATENATE('Bundle Tag Info'!$A$1," ",CHAR(10),'Bundle Tag Info'!$A$2," ",'Bundle Tag Info'!$A$3,CHAR(10),'Bundle Tag Info'!L$6,CHAR(10),'Bundle Tag Info'!L$9),"") | L4: =IF('Bundle Tag Info'!M$9<>"",CONCATENATE('Bundle Tag Info'!$A$1," ",CHAR(10),'Bundle Tag Info'!$A$2," ",'Bundle Tag Info'!$A$3,CHAR(10),'Bundle Tag Info'!M$6,CHAR(10),'Bundle Tag Info'!M$9),"") | M4: =IF('Bundle Tag Info'!N$9<>"",CONCATENATE('Bundle Tag Info'!$A$1," ",CHAR(10),'Bundle Tag Info'!$A$2," ",'Bundle Tag Info'!$A$3,CHAR(10),'Bundle Tag Info'!N$6,CHAR(10),'Bundle Tag Info'!N$9),"") | N4: =IF('Bundle Tag Info'!O$9<>"",CONCATENATE('Bundle Tag Info'!$A$1," ",CHAR(10),'Bundle Tag Info'!$A$2," ",'Bundle Tag Info'!$A$3,CHAR(10),'Bundle Tag Info'!O$6,CHAR(10),'Bundle Tag Info'!O$9),"") | ... AD4: =IF('Bundle Tag Info'!AE$9<>"",CONCATENATE('Bundle Tag Info'!$A$1," ",CHAR(10),'Bundle Tag Info'!$A$2," ",'Bundle Tag Info'!$A$3,CHAR(10),'Bundle Tag Info'!AE$6,CHAR(10),'Bundle Tag Info'!AE$9),"")
A5: =IF('Bundle Tag Info'!A$10<>"",CONCATENATE('Bundle Tag Info'!$A$1," ",CHAR(10),'Bundle Tag Info'!$A$2," ",'Bundle Tag Info'!$A$3,CHAR(10),'Bundle Tag Info'!A$6,CHAR(10),'Bundle Tag Info'!A$10),"") -> BP-KEMD 4L541 B.1 JB70 SA0474 | B5: =IF('Bundle Tag Info'!B$10<>"",CONCATENATE('Bundle Tag Info'!$A$1," ",CHAR(10),'Bundle Tag Info'!$A$2," ",'Bundle Tag Info'!$A$3,CHAR(10),'Bundle Tag Info'!B$6,CHAR(10),'Bundle Tag Info'!B$10),"") | C5: =IF('Bundle Tag Info'!C$10<>"",CONCATENATE('Bundle Tag Info'!$A$1," ",CHAR(10),'Bundle Tag Info'!$A$2," ",'Bundle Tag Info'!$A$3,CHAR(10),'Bundle Tag Info'!C$6,CHAR(10),'Bundle Tag Info'!C$10),"") -> BP-KEMD 4L541 B.1 JB70 L RAIL XT-PLC | D5: =IF('Bundle Tag Info'!D$10<>"",CONCATENATE('Bundle Tag Info'!$A$1," ",CHAR(10),'Bundle Tag Info'!$A$2," ",'Bundle Tag Info'!$A$3,CHAR(10),'Bundle Tag Info'!D$6,CHAR(10),'Bundle Tag Info'!D$10),"") -> BP-KEMD 4L541 B.1 PLC BA-B | E5: =IF('Bundle Tag Info'!E$10<>"",CONCATENATE('Bundle Tag Info'!$A$1," ",CHAR(10),'Bundle Tag Info'!$A$2," ",'Bundle Tag Info'!$A$3,CHAR(10),'Bundle Tag Info'!E$6,CHAR(10),'Bundle Tag Info'!E$10),"") -> BP-KEMD 4L541 B.1 A KA | F5: =IF('Bundle Tag Info'!F$10<>"",CONCATENATE('Bundle Tag Info'!$A$1," ",CHAR(10),'Bundle Tag Info'!$A$2," ",'Bundle Tag Info'!$A$3,CHAR(10),'Bundle Tag Info'!F$6,CHAR(10),'Bundle Tag Info'!F$10),"") -> BP-KEMD 4L541 B.1 B KA A1 | G5: =IF('Bundle Tag Info'!H$10<>"",CONCATENATE('Bundle Tag Info'!$A$1," ",CHAR(10),'Bundle Tag Info'!$A$2," ",'Bundle Tag Info'!$A$3,CHAR(10),'Bundle Tag Info'!H$6,CHAR(10),'Bundle Tag Info'!H$10),"") -> BP-KEMD 4L541 B.1 JB73 XT | H5: =IF('Bundle Tag Info'!I$10<>"",CONCATENATE('Bundle Tag Info'!$A$1," ",CHAR(10),'Bundle Tag Info'!$A$2," ",'Bundle Tag Info'!$A$3,CHAR(10),'Bundle Tag Info'!I$6,CHAR(10),'Bundle Tag Info'!I$10),"") -> BP-KEMD 4L541 B.1 BOP FU | I5: =IF('Bundle Tag Info'!J$10<>"",CONCATENATE('Bundle Tag Info'!$A$1," ",CHAR(10),'Bundle Tag Info'!$A$2," ",'Bundle Tag Info'!$A$3,CHAR(10),'Bundle Tag Info'!J$6,CHAR(10),'Bundle Tag Info'!J$10),"") -> BP-KEMD 4L541 B.1 JB74 L RAIL KA A2-R RAIL | J5: =IF('Bundle Tag Info'!K$10<>"",CONCATENATE('Bundle Tag Info'!$A$1," ",CHAR(10),'Bundle Tag Info'!$A$2," ",'Bundle Tag Info'!$A$3,CHAR(10),'Bundle Tag Info'!K$6,CHAR(10),'Bundle Tag Info'!K$10),"") | K5: =IF('Bundle Tag Info'!L$10<>"",CONCATENATE('Bundle Tag Info'!$A$1," ",CHAR(10),'Bundle Tag Info'!$A$2," ",'Bundle Tag Info'!$A$3,CHAR(10),'Bundle Tag Info'!L$6,CHAR(10),'Bundle Tag Info'!L$10),"") | L5: =IF('Bundle Tag Info'!M$10<>"",CONCATENATE('Bundle Tag Info'!$A$1," ",CHAR(10),'Bundle Tag Info'!$A$2," ",'Bundle Tag Info'!$A$3,CHAR(10),'Bundle Tag Info'!M$6,CHAR(10),'Bundle Tag Info'!M$10),"") | M5: =IF('Bundle Tag Info'!N$10<>"",CONCATENATE('Bundle Tag Info'!$A$1," ",CHAR(10),'Bundle Tag Info'!$A$2," ",'Bundle Tag Info'!$A$3,CHAR(10),'Bundle Tag Info'!N$6,CHAR(10),'Bundle Tag Info'!N$10),"") | N5: =IF('Bundle Tag Info'!O$10<>"",CONCATENATE('Bundle Tag Info'!$A$1," ",CHAR(10),'Bundle Tag Info'!$A$2," ",'Bundle Tag Info'!$A$3,CHAR(10),'Bundle Tag Info'!O$6,CHAR(10),'Bundle Tag Info'!O$10),"") | ... AD5: =IF('Bundle Tag Info'!AE$10<>"",CONCATENATE('Bundle Tag Info'!$A$1," ",CHAR(10),'Bundle Tag Info'!$A$2," ",'Bundle Tag Info'!$A$3,CHAR(10),'Bundle Tag Info'!AE$6,CHAR(10),'Bundle Tag Info'!AE$10),"")
A6: =IF('Bundle Tag Info'!A$11<>"",CONCATENATE('Bundle Tag Info'!$A$1," ",CHAR(10),'Bundle Tag Info'!$A$2," ",'Bundle Tag Info'!$A$3,CHAR(10),'Bundle Tag Info'!A$6,CHAR(10),'Bundle Tag Info'!A$11),"") -> BP-KEMD 4L541 B.1 JB70 SB0471 | B6: =IF('Bundle Tag Info'!B$11<>"",CONCATENATE('Bundle Tag Info'!$A$1," ",CHAR(10),'Bundle Tag Info'!$A$2," ",'Bundle Tag Info'!$A$3,CHAR(10),'Bundle Tag Info'!B$6,CHAR(10),'Bundle Tag Info'!B$11),"") | C6: =IF('Bundle Tag Info'!C$11<>"",CONCATENATE('Bundle Tag Info'!$A$1," ",CHAR(10),'Bundle Tag Info'!$A$2," ",'Bundle Tag Info'!$A$3,CHAR(10),'Bundle Tag Info'!C$6,CHAR(10),'Bundle Tag Info'!C$11),"") | D6: =IF('Bundle Tag Info'!D$11<>"",CONCATENATE('Bundle Tag Info'!$A$1," ",CHAR(10),'Bundle Tag Info'!$A$2," ",'Bundle Tag Info'!$A$3,CHAR(10),'Bundle Tag Info'!D$6,CHAR(10),'Bundle Tag Info'!D$11),"") -> BP-KEMD 4L541 B.1 PLC FU/XT-B | E6: =IF('Bundle Tag Info'!E$11<>"",CONCATENATE('Bundle Tag Info'!$A$1," ",CHAR(10),'Bundle Tag Info'!$A$2," ",'Bundle Tag Info'!$A$3,CHAR(10),'Bundle Tag Info'!E$6,CHAR(10),'Bundle Tag Info'!E$11),"") -> BP-KEMD 4L541 B.1 A PC | F6: =IF('Bundle Tag Info'!F$11<>"",CONCATENATE('Bundle Tag Info'!$A$1," ",CHAR(10),'Bundle Tag Info'!$A$2," ",'Bundle Tag Info'!$A$3,CHAR(10),'Bundle Tag Info'!F$6,CHAR(10),'Bundle Tag Info'!F$11),"") -> BP-KEMD 4L541 B.1 B KA A2 | G6: =IF('Bundle Tag Info'!H$11<>"",CONCATENATE('Bundle Tag Info'!$A$1," ",CHAR(10),'Bundle Tag Info'!$A$2," ",'Bundle Tag Info'!$A$3,CHAR(10),'Bundle Tag Info'!H$6,CHAR(10),'Bundle Tag Info'!H$11),"") | H6: =IF('Bundle Tag Info'!I$11<>"",CONCATENATE('Bundle Tag Info'!$A$1," ",CHAR(10),'Bundle Tag Info'!$A$2," ",'Bundle Tag Info'!$A$3,CHAR(10),'Bundle Tag Info'!I$6,CHAR(10),'Bundle Tag Info'!I$11),"") -> BP-KEMD 4L541 B.1 BOP KT L/S | I6: =IF('Bundle Tag Info'!J$11<>"",CONCATENATE('Bundle Tag Info'!$A$1," ",CHAR(10),'Bundle Tag Info'!$A$2," ",'Bundle Tag Info'!$A$3,CHAR(10),'Bundle Tag Info'!J$6,CHAR(10),'Bundle Tag Info'!J$11),"") -> BP-KEMD 4L541 B.1 JB74 L RAIL KA-R RAIL | J6: =IF('Bundle Tag Info'!K$11<>"",CONCATENATE('Bundle Tag Info'!$A$1," ",CHAR(10),'Bundle Tag Info'!$A$2," ",'Bundle Tag Info'!$A$3,CHAR(10),'Bundle Tag Info'!K$6,CHAR(10),'Bundle Tag Info'!K$11),"") | K6: =IF('Bundle Tag Info'!L$11<>"",CONCATENATE('Bundle Tag Info'!$A$1," ",CHAR(10),'Bundle Tag Info'!$A$2," ",'Bundle Tag Info'!$A$3,CHAR(10),'Bundle Tag Info'!L$6,CHAR(10),'Bundle Tag Info'!L$11),"") | L6: =IF('Bundle Tag Info'!M$11<>"",CONCATENATE('Bundle Tag Info'!$A$1," ",CHAR(10),'Bundle Tag Info'!$A$2," ",'Bundle Tag Info'!$A$3,CHAR(10),'Bundle Tag Info'!M$6,CHAR(10),'Bundle Tag Info'!M$11),"") | M6: =IF('Bundle Tag Info'!N$11<>"",CONCATENATE('Bundle Tag Info'!$A$1," ",CHAR(10),'Bundle Tag Info'!$A$2," ",'Bundle Tag Info'!$A$3,CHAR(10),'Bundle Tag Info'!N$6,CHAR(10),'Bundle Tag Info'!N$11),"") | N6: =IF('Bundle Tag Info'!O$11<>"",CONCATENATE('Bundle Tag Info'!$A$1," ",CHAR(10),'Bundle Tag Info'!$A$2," ",'Bundle Tag Info'!$A$3,CHAR(10),'Bundle Tag Info'!O$6,CHAR(10),'Bundle Tag Info'!O$11),"") | ... AD6: =IF('Bundle Tag Info'!AE$11<>"",CONCATENATE('Bundle Tag Info'!$A$1," ",CHAR(10),'Bundle Tag Info'!$A$2," ",'Bundle Tag Info'!$A$3,CHAR(10),'Bundle Tag Info'!AE$6,CHAR(10),'Bundle Tag Info'!AE$11),"")
A7: =IF('Bundle Tag Info'!A$12<>"",CONCATENATE('Bundle Tag Info'!$A$1," ",CHAR(10),'Bundle Tag Info'!$A$2," ",'Bundle Tag Info'!$A$3,CHAR(10),'Bundle Tag Info'!A$6,CHAR(10),'Bundle Tag Info'!A$12),"") -> BP-KEMD 4L541 B.1 JB70 SB0472 | B7: =IF('Bundle Tag Info'!B$12<>"",CONCATENATE('Bundle Tag Info'!$A$1," ",CHAR(10),'Bundle Tag Info'!$A$2," ",'Bundle Tag Info'!$A$3,CHAR(10),'Bundle Tag Info'!B$6,CHAR(10),'Bundle Tag Info'!B$12),"") | C7: =IF('Bundle Tag Info'!C$12<>"",CONCATENATE('Bundle Tag Info'!$A$1," ",CHAR(10),'Bundle Tag Info'!$A$2," ",'Bundle Tag Info'!$A$3,CHAR(10),'Bundle Tag Info'!C$6,CHAR(10),'Bundle Tag Info'!C$12),"") | D7: =IF('Bundle Tag Info'!D$12<>"",CONCATENATE('Bundle Tag Info'!$A$1," ",CHAR(10),'Bundle Tag Info'!$A$2," ",'Bundle Tag Info'!$A$3,CHAR(10),'Bundle Tag Info'!D$6,CHAR(10),'Bundle Tag Info'!D$12),"") | E7: =IF('Bundle Tag Info'!E$12<>"",CONCATENATE('Bundle Tag Info'!$A$1," ",CHAR(10),'Bundle Tag Info'!$A$2," ",'Bundle Tag Info'!$A$3,CHAR(10),'Bundle Tag Info'!E$6,CHAR(10),'Bundle Tag Info'!E$12),"") -> BP-KEMD 4L541 B.1 A UJ | F7: =IF('Bundle Tag Info'!F$12<>"",CONCATENATE('Bundle Tag Info'!$A$1," ",CHAR(10),'Bundle Tag Info'!$A$2," ",'Bundle Tag Info'!$A$3,CHAR(10),'Bundle Tag Info'!F$6,CHAR(10),'Bundle Tag Info'!F$12),"") -> BP-KEMD 4L541 B.1 B KA | G7: =IF('Bundle Tag Info'!H$12<>"",CONCATENATE('Bundle Tag Info'!$A$1," ",CHAR(10),'Bundle Tag Info'!$A$2," ",'Bundle Tag Info'!$A$3,CHAR(10),'Bundle Tag Info'!H$6,CHAR(10),'Bundle Tag Info'!H$12),"") | H7: =IF('Bundle Tag Info'!I$12<>"",CONCATENATE('Bundle Tag Info'!$A$1," ",CHAR(10),'Bundle Tag Info'!$A$2," ",'Bundle Tag Info'!$A$3,CHAR(10),'Bundle Tag Info'!I$6,CHAR(10),'Bundle Tag Info'!I$12),"") -> BP-KEMD 4L541 B.1 BOP KT R/S | I7: =IF('Bundle Tag Info'!J$12<>"",CONCATENATE('Bundle Tag Info'!$A$1," ",CHAR(10),'Bundle Tag Info'!$A$2," ",'Bundle Tag Info'!$A$3,CHAR(10),'Bundle Tag Info'!J$6,CHAR(10),'Bundle Tag Info'!J$12),"") -> BP-KEMD 4L541 B.1 JB74 L RAIL KA A1-BOP | J7: =IF('Bundle Tag Info'!K$12<>"",CONCATENATE('Bundle Tag Info'!$A$1," ",CHAR(10),'Bundle Tag Info'!$A$2," ",'Bundle Tag Info'!$A$3,CHAR(10),'Bundle Tag Info'!K$6,CHAR(10),'Bundle Tag Info'!K$12),"") | K7: =IF('Bundle Tag Info'!L$12<>"",CONCATENATE('Bundle Tag Info'!$A$1," ",CHAR(10),'Bundle Tag Info'!$A$2," ",'Bundle Tag Info'!$A$3,CHAR(10),'Bundle Tag Info'!L$6,CHAR(10),'Bundle Tag Info'!L$12),"") | L7: =IF('Bundle Tag Info'!M$12<>"",CONCATENATE('Bundle Tag Info'!$A$1," ",CHAR(10),'Bundle Tag Info'!$A$2," ",'Bundle Tag Info'!$A$3,CHAR(10),'Bundle Tag Info'!M$6,CHAR(10),'Bundle Tag Info'!M$12),"") | M7: =IF('Bundle Tag Info'!N$12<>"",CONCATENATE('Bundle Tag Info'!$A$1," ",CHAR(10),'Bundle Tag Info'!$A$2," ",'Bundle Tag Info'!$A$3,CHAR(10),'Bundle Tag Info'!N$6,CHAR(10),'Bundle Tag Info'!N$12),"") | N7: =IF('Bundle Tag Info'!O$12<>"",CONCATENATE('Bundle Tag Info'!$A$1," ",CHAR(10),'Bundle Tag Info'!$A$2," ",'Bundle Tag Info'!$A$3,CHAR(10),'Bundle Tag Info'!O$6,CHAR(10),'Bundle Tag Info'!O$12),"") | ... AD7: =IF('Bundle Tag Info'!AE$12<>"",CONCATENATE('Bundle Tag Info'!$A$1," ",CHAR(10),'Bundle Tag Info'!$A$2," ",'Bundle Tag Info'!$A$3,CHAR(10),'Bundle Tag Info'!AE$6,CHAR(10),'Bundle Tag Info'!AE$12),"")
A8: =IF('Bundle Tag Info'!A$13<>"",CONCATENATE('Bundle Tag Info'!$A$1," ",CHAR(10),'Bundle Tag Info'!$A$2," ",'Bundle Tag Info'!$A$3,CHAR(10),'Bundle Tag Info'!A$6,CHAR(10),'Bundle Tag Info'!A$13),"") -> BP-KEMD 4L541 B.1 JB70 SB0473 | B8: =IF('Bundle Tag Info'!B$13<>"",CONCATENATE('Bundle Tag Info'!$A$1," ",CHAR(10),'Bundle Tag Info'!$A$2," ",'Bundle Tag Info'!$A$3,CHAR(10),'Bundle Tag Info'!B$6,CHAR(10),'Bundle Tag Info'!B$13),"") | C8: =IF('Bundle Tag Info'!C$13<>"",CONCATENATE('Bundle Tag Info'!$A$1," ",CHAR(10),'Bundle Tag Info'!$A$2," ",'Bundle Tag Info'!$A$3,CHAR(10),'Bundle Tag Info'!C$6,CHAR(10),'Bundle Tag Info'!C$13),"") | D8: =IF('Bundle Tag Info'!D$13<>"",CONCATENATE('Bundle Tag Info'!$A$1," ",CHAR(10),'Bundle Tag Info'!$A$2," ",'Bundle Tag Info'!$A$3,CHAR(10),'Bundle Tag Info'!D$6,CHAR(10),'Bundle Tag Info'!D$13),"") | E8: =IF('Bundle Tag Info'!E$13<>"",CONCATENATE('Bundle Tag Info'!$A$1," ",CHAR(10),'Bundle Tag Info'!$A$2," ",'Bundle Tag Info'!$A$3,CHAR(10),'Bundle Tag Info'!E$6,CHAR(10),'Bundle Tag Info'!E$13),"") -> BP-KEMD 4L541 B.1 A XT | F8: =IF('Bundle Tag Info'!F$13<>"",CONCATENATE('Bundle Tag Info'!$A$1," ",CHAR(10),'Bundle Tag Info'!$A$2," ",'Bundle Tag Info'!$A$3,CHAR(10),'Bundle Tag Info'!F$6,CHAR(10),'Bundle Tag Info'!F$13),"") -> BP-KEMD 4L541 B.1 B KT L/S | G8: =IF('Bundle Tag Info'!H$13<>"",CONCATENATE('Bundle Tag Info'!$A$1," ",CHAR(10),'Bundle Tag Info'!$A$2," ",'Bundle Tag Info'!$A$3,CHAR(10),'Bundle Tag Info'!H$6,CHAR(10),'Bundle Tag Info'!H$13),"") | H8: =IF('Bundle Tag Info'!I$13<>"",CONCATENATE('Bundle Tag Info'!$A$1," ",CHAR(10),'Bundle Tag Info'!$A$2," ",'Bundle Tag Info'!$A$3,CHAR(10),'Bundle Tag Info'!I$6,CHAR(10),'Bundle Tag Info'!I$13),"") -> BP-KEMD 4L541 B.1 BOP XT | I8: =IF('Bundle Tag Info'!J$13<>"",CONCATENATE('Bundle Tag Info'!$A$1," ",CHAR(10),'Bundle Tag Info'!$A$2," ",'Bundle Tag Info'!$A$3,CHAR(10),'Bundle Tag Info'!J$6,CHAR(10),'Bundle Tag Info'!J$13),"") -> BP-KEMD 4L541 B.1 JB74 L RAIL KA A2-BOP | J8: =IF('Bundle Tag Info'!K$13<>"",CONCATENATE('Bundle Tag Info'!$A$1," ",CHAR(10),'Bundle Tag Info'!$A$2," ",'Bundle Tag Info'!$A$3,CHAR(10),'Bundle Tag Info'!K$6,CHAR(10),'Bundle Tag Info'!K$13),"") | K8: =IF('Bundle Tag Info'!L$13<>"",CONCATENATE('Bundle Tag Info'!$A$1," ",CHAR(10),'Bundle Tag Info'!$A$2," ",'Bundle Tag Info'!$A$3,CHAR(10),'Bundle Tag Info'!L$6,CHAR(10),'Bundle Tag Info'!L$13),"") | L8: =IF('Bundle Tag Info'!M$13<>"",CONCATENATE('Bundle Tag Info'!$A$1," ",CHAR(10),'Bundle Tag Info'!$A$2," ",'Bundle Tag Info'!$A$3,CHAR(10),'Bundle Tag Info'!M$6,CHAR(10),'Bundle Tag Info'!M$13),"") | M8: =IF('Bundle Tag Info'!N$13<>"",CONCATENATE('Bundle Tag Info'!$A$1," ",CHAR(10),'Bundle Tag Info'!$A$2," ",'Bundle Tag Info'!$A$3,CHAR(10),'Bundle Tag Info'!N$6,CHAR(10),'Bundle Tag Info'!N$13),"") | N8: =IF('Bundle Tag Info'!O$13<>"",CONCATENATE('Bundle Tag Info'!$A$1," ",CHAR(10),'Bundle Tag Info'!$A$2," ",'Bundle Tag Info'!$A$3,CHAR(10),'Bundle Tag Info'!O$6,CHAR(10),'Bundle Tag Info'!O$13),"") | ... AD8: =IF('Bundle Tag Info'!AE$13<>"",CONCATENATE('Bundle Tag Info'!$A$1," ",CHAR(10),'Bundle Tag Info'!$A$2," ",'Bundle Tag Info'!$A$3,CHAR(10),'Bundle Tag Info'!AE$6,CHAR(10),'Bundle Tag Info'!AE$13),"")
A9: =IF('Bundle Tag Info'!A$14<>"",CONCATENATE('Bundle Tag Info'!$A$1," ",CHAR(10),'Bundle Tag Info'!$A$2," ",'Bundle Tag Info'!$A$3,CHAR(10),'Bundle Tag Info'!A$6,CHAR(10),'Bundle Tag Info'!A$14),"") -> BP-KEMD 4L541 B.1 JB70 SB0474 | B9: =IF('Bundle Tag Info'!B$14<>"",CONCATENATE('Bundle Tag Info'!$A$1," ",CHAR(10),'Bundle Tag Info'!$A$2," ",'Bundle Tag Info'!$A$3,CHAR(10),'Bundle Tag Info'!B$6,CHAR(10),'Bundle Tag Info'!B$14),"") | C9: =IF('Bundle Tag Info'!C$14<>"",CONCATENATE('Bundle Tag Info'!$A$1," ",CHAR(10),'Bundle Tag Info'!$A$2," ",'Bundle Tag Info'!$A$3,CHAR(10),'Bundle Tag Info'!C$6,CHAR(10),'Bundle Tag Info'!C$14),"") | D9: =IF('Bundle Tag Info'!D$14<>"",CONCATENATE('Bundle Tag Info'!$A$1," ",CHAR(10),'Bundle Tag Info'!$A$2," ",'Bundle Tag Info'!$A$3,CHAR(10),'Bundle Tag Info'!D$6,CHAR(10),'Bundle Tag Info'!D$14),"") | E9: =IF('Bundle Tag Info'!E$14<>"",CONCATENATE('Bundle Tag Info'!$A$1," ",CHAR(10),'Bundle Tag Info'!$A$2," ",'Bundle Tag Info'!$A$3,CHAR(10),'Bundle Tag Info'!E$6,CHAR(10),'Bundle Tag Info'!E$14),"") -> BP-KEMD 4L541 B.1 A AF080s-B | F9: =IF('Bundle Tag Info'!F$14<>"",CONCATENATE('Bundle Tag Info'!$A$1," ",CHAR(10),'Bundle Tag Info'!$A$2," ",'Bundle Tag Info'!$A$3,CHAR(10),'Bundle Tag Info'!F$6,CHAR(10),'Bundle Tag Info'!F$14),"") -> BP-KEMD 4L541 B.1 B KT R/S | G9: =IF('Bundle Tag Info'!H$14<>"",CONCATENATE('Bundle Tag Info'!$A$1," ",CHAR(10),'Bundle Tag Info'!$A$2," ",'Bundle Tag Info'!$A$3,CHAR(10),'Bundle Tag Info'!H$6,CHAR(10),'Bundle Tag Info'!H$14),"") | H9: =IF('Bundle Tag Info'!I$14<>"",CONCATENATE('Bundle Tag Info'!$A$1," ",CHAR(10),'Bundle Tag Info'!$A$2," ",'Bundle Tag Info'!$A$3,CHAR(10),'Bundle Tag Info'!I$6,CHAR(10),'Bundle Tag Info'!I$14),"") | I9: =IF('Bundle Tag Info'!J$14<>"",CONCATENATE('Bundle Tag Info'!$A$1," ",CHAR(10),'Bundle Tag Info'!$A$2," ",'Bundle Tag Info'!$A$3,CHAR(10),'Bundle Tag Info'!J$6,CHAR(10),'Bundle Tag Info'!J$14),"") -> BP-KEMD 4L541 B.1 JB74 L RAIL KA-BOP | J9: =IF('Bundle Tag Info'!K$14<>"",CONCATENATE('Bundle Tag Info'!$A$1," ",CHAR(10),'Bundle Tag Info'!$A$2," ",'Bundle Tag Info'!$A$3,CHAR(10),'Bundle Tag Info'!K$6,CHAR(10),'Bundle Tag Info'!K$14),"") | K9: =IF('Bundle Tag Info'!L$14<>"",CONCATENATE('Bundle Tag Info'!$A$1," ",CHAR(10),'Bundle Tag Info'!$A$2," ",'Bundle Tag Info'!$A$3,CHAR(10),'Bundle Tag Info'!L$6,CHAR(10),'Bundle Tag Info'!L$14),"") | L9: =IF('Bundle Tag Info'!M$14<>"",CONCATENATE('Bundle Tag Info'!$A$1," ",CHAR(10),'Bundle Tag Info'!$A$2," ",'Bundle Tag Info'!$A$3,CHAR(10),'Bundle Tag Info'!M$6,CHAR(10),'Bundle Tag Info'!M$14),"") | M9: =IF('Bundle Tag Info'!N$14<>"",CONCATENATE('Bundle Tag Info'!$A$1," ",CHAR(10),'Bundle Tag Info'!$A$2," ",'Bundle Tag Info'!$A$3,CHAR(10),'Bundle Tag Info'!N$6,CHAR(10),'Bundle Tag Info'!N$14),"") | N9: =IF('Bundle Tag Info'!O$14<>"",CONCATENATE('Bundle Tag Info'!$A$1," ",CHAR(10),'Bundle Tag Info'!$A$2," ",'Bundle Tag Info'!$A$3,CHAR(10),'Bundle Tag Info'!O$6,CHAR(10),'Bundle Tag Info'!O$14),"") | ... AD9: =IF('Bundle Tag Info'!AE$14<>"",CONCATENATE('Bundle Tag Info'!$A$1," ",CHAR(10),'Bundle Tag Info'!$A$2," ",'Bundle Tag Info'!$A$3,CHAR(10),'Bundle Tag Info'!AE$6,CHAR(10),'Bundle Tag Info'!AE$14),"")
A10: =IF('Bundle Tag Info'!A$15<>"",CONCATENATE('Bundle Tag Info'!$A$1," ",CHAR(10),'Bundle Tag Info'!$A$2," ",'Bundle Tag Info'!$A$3,CHAR(10),'Bundle Tag Info'!A$6,CHAR(10),'Bundle Tag Info'!A$15),"") -> BP-KEMD 4L541 B.1 JB70 SH0470 | B10: =IF('Bundle Tag Info'!B$15<>"",CONCATENATE('Bundle Tag Info'!$A$1," ",CHAR(10),'Bundle Tag Info'!$A$2," ",'Bundle Tag Info'!$A$3,CHAR(10),'Bundle Tag Info'!B$6,CHAR(10),'Bundle Tag Info'!B$15),"") | C10: =IF('Bundle Tag Info'!C$15<>"",CONCATENATE('Bundle Tag Info'!$A$1," ",CHAR(10),'Bundle Tag Info'!$A$2," ",'Bundle Tag Info'!$A$3,CHAR(10),'Bundle Tag Info'!C$6,CHAR(10),'Bundle Tag Info'!C$15),"") | D10: =IF('Bundle Tag Info'!D$15<>"",CONCATENATE('Bundle Tag Info'!$A$1," ",CHAR(10),'Bundle Tag Info'!$A$2," ",'Bundle Tag Info'!$A$3,CHAR(10),'Bundle Tag Info'!D$6,CHAR(10),'Bundle Tag Info'!D$15),"") | E10: =IF('Bundle Tag Info'!E$15<>"",CONCATENATE('Bundle Tag Info'!$A$1," ",CHAR(10),'Bundle Tag Info'!$A$2," ",'Bundle Tag Info'!$A$3,CHAR(10),'Bundle Tag Info'!E$6,CHAR(10),'Bundle Tag Info'!E$15),"") -> BP-KEMD 4L541 B.1 A AF090s-B | F10: =IF('Bundle Tag Info'!F$15<>"",CONCATENATE('Bundle Tag Info'!$A$1," ",CHAR(10),'Bundle Tag Info'!$A$2," ",'Bundle Tag Info'!$A$3,CHAR(10),'Bundle Tag Info'!F$6,CHAR(10),'Bundle Tag Info'!F$15),"") -> BP-KEMD 4L541 B.1 B XT | G10: =IF('Bundle Tag Info'!H$15<>"",CONCATENATE('Bundle Tag Info'!$A$1," ",CHAR(10),'Bundle Tag Info'!$A$2," ",'Bundle Tag Info'!$A$3,CHAR(10),'Bundle Tag Info'!H$6,CHAR(10),'Bundle Tag Info'!H$15),"") | H10: =IF('Bundle Tag Info'!I$15<>"",CONCATENATE('Bundle Tag Info'!$A$1," ",CHAR(10),'Bundle Tag Info'!$A$2," ",'Bundle Tag Info'!$A$3,CHAR(10),'Bundle Tag Info'!I$6,CHAR(10),'Bundle Tag Info'!I$15),"") | I10: =IF('Bundle Tag Info'!J$15<>"",CONCATENATE('Bundle Tag Info'!$A$1," ",CHAR(10),'Bundle Tag Info'!$A$2," ",'Bundle Tag Info'!$A$3,CHAR(10),'Bundle Tag Info'!J$6,CHAR(10),'Bundle Tag Info'!J$15),"") -> BP-KEMD 4L541 B.1 JB74 L RAIL XT-BOP | J10: =IF('Bundle Tag Info'!K$15<>"",CONCATENATE('Bundle Tag Info'!$A$1," ",CHAR(10),'Bundle Tag Info'!$A$2," ",'Bundle Tag Info'!$A$3,CHAR(10),'Bundle Tag Info'!K$6,CHAR(10),'Bundle Tag Info'!K$15),"") | K10: =IF('Bundle Tag Info'!L$15<>"",CONCATENATE('Bundle Tag Info'!$A$1," ",CHAR(10),'Bundle Tag Info'!$A$2," ",'Bundle Tag Info'!$A$3,CHAR(10),'Bundle Tag Info'!L$6,CHAR(10),'Bundle Tag Info'!L$15),"") | L10: =IF('Bundle Tag Info'!M$15<>"",CONCATENATE('Bundle Tag Info'!$A$1," ",CHAR(10),'Bundle Tag Info'!$A$2," ",'Bundle Tag Info'!$A$3,CHAR(10),'Bundle Tag Info'!M$6,CHAR(10),'Bundle Tag Info'!M$15),"") | M10: =IF('Bundle Tag Info'!N$15<>"",CONCATENATE('Bundle Tag Info'!$A$1," ",CHAR(10),'Bundle Tag Info'!$A$2," ",'Bundle Tag Info'!$A$3,CHAR(10),'Bundle Tag Info'!N$6,CHAR(10),'Bundle Tag Info'!N$15),"") | N10: =IF('Bundle Tag Info'!O$15<>"",CONCATENATE('Bundle Tag Info'!$A$1," ",CHAR(10),'Bundle Tag Info'!$A$2," ",'Bundle Tag Info'!$A$3,CHAR(10),'Bundle Tag Info'!O$6,CHAR(10),'Bundle Tag Info'!O$15),"") | ... AD10: =IF('Bundle Tag Info'!AE$15<>"",CONCATENATE('Bundle Tag Info'!$A$1," ",CHAR(10),'Bundle Tag Info'!$A$2," ",'Bundle Tag Info'!$A$3,CHAR(10),'Bundle Tag Info'!AE$6,CHAR(10),'Bundle Tag Info'!AE$15),"")
