Workbook

Sheet Panel Errors
A1: Panel Errors
A3: Project # | B3: J0400
A4: Project Name | B4: NOC ASBAB-A-4401
A5: Revision | B5: A.2
A7: Controls DE | B7: N.GONZALEZ
A8: Phone: | B8: 0
A9: Controls ME | B9: R.DURAN
A10: Phone:
A12: From | H12: To
A13: Device ID | B13: Location | C13: Cable (W) Conductor (SC) Jumper Clip (JC) | D13: Wire ID | E13: Wire No. | F13: Gauge/Size | G13: Page/Zone | H13: Device ID | I13: Location | J13: Page/Zone
A14: AT0190:USB2 | B14: CONSOLE | C14: SC | E14: * | G14: 9.B4 | H14: CC1000:1 | I14: PANEL | J14: 9.C5
A15: TS8000:1 | B15: PANEL | C15: SC | D15: WHT | E15: 006336 | F15: 20 | G15: 25.C5 | H15: AF0063:36 | I15: RIGHT WALL | J15: 25.C7
A16: TS8000:2 | B16: PANEL | C16: SC | D16: WHT | E16: 006304 | F16: 20 | G16: 25.C5 | H16: AF0063:04 | I16: RIGHT WALL | J16: 25.C7
E18: SolarTools ver. 24.0.84.24712 (Jul 31, 2025)
A19: Report date: 1/29/2026 12:50 AM

Sheet CONSOLE_S
A1: CONSOLE
A2: CONTROL CONSOLE & CONTROL CONSOLE (DOOR PANELS)
A3: Project # | B3: J0400
A4: Project Name | B4: NOC ASBAB-A-4401
A5: Revision | B5: A.2
A7: Controls DE | B7: N.GONZALEZ
A8: Phone: | B8: 0
A9: Controls ME | B9: R.DURAN
A10: Phone:
A12: From | G12: To
A13: Device ID | B13: Wire No. | C13: Wire ID | D13: Gauge/Size | E13: Length | F13: Device ID | G13: Location | H13: Bundle Name
A14: EL0271:B2 | B14: EL0271B | C14: WHT | D14: 14 | E14: 100 | F14: EL0272:B1 | G14: CONSOLE | H14: EL
A15: EL0271:W2 | B15: EL0271W | C15: WHT | D15: 14 | E15: 100 | F15: EL0272:W1 | G15: CONSOLE
A16: EL0272:B2 | B16: EL0272B | C16: WHT | D16: 14 | E16: 100 | F16: ZS0271:2 | G16: CONSOLE
A17: EL0271:B1 | B17: ZS0273 | C17: WHT | D17: 14 | E17: 100 | F17: ZS0273:2 | G17: CONSOLE
A19: AT0190:NEG | B19: -0V1 | C19: WHT | D19: 14 | E19: 140 | F19: XT0562:2 | G19: PWR DST RAIL | H19: AT-PDR
A20: AT0190:POS | B20: FU0190 | C20: WHT | D20: 14 | E20: 140 | F20: FU0190:LD | G20: PWR DST RAIL
A22: EL0271:W1 | B22: -0V1 | C22: WHT | D22: 14 | E22: 120 | F22: XT0562:1 | G22: PWR DST RAIL | H22: EL-PDR
A24: ZS0271:1 | B24: FU0273 | C24: WHT | D24: 14 | E24: 120 | F24: FU0273:LD | G24: PWR DST RAIL | H24: AZ-PDR
A25: ZS0273:1 | B25: FU0273 | C25: WHT | D25: 14 | E25: 120 | F25: FU0273:LD | G25: PWR DST RAIL

Sheet POWER SUPPLY_S
A1: POWER SUPPLY
A3: Project # | B3: J0400
A4: Project Name | B4: NOC ASBAB-A-4401
A5: Revision | B5: A.2
A7: Controls DE | B7: N.GONZALEZ
A8: Phone: | B8: 0
A9: Controls ME | B9: R.DURAN
A10: Phone:
A12: From | G12: To
A13: Device ID | B13: Wire No. | C13: Wire ID | D13: Gauge/Size | E13: Length | F13: Device ID | G13: Location | H13: Bundle Name
A14: UJ0031:IS | B14: UJ0131IS | C14: WHT | D14: 20 | E14: 60 | F14: UJ0131:IS | G14: POWER SUPPLY | H14: UJ/QS
A16: QS0031:LD-3 | B16: UJ0031N | C16: WHT | D16: 12 | E16: 60 | F16: UJ0031:- | G16: POWER SUPPLY
A17: QS0031:LD-1 | B17: UJ0031P | C17: WHT | D17: 12 | E17: 60 | F17: UJ0031:+ | G17: POWER SUPPLY
A18: QS0011:LD-3 | B18: UJ0131N | C18: WHT | D18: 12 | E18: 60 | F18: UJ0131:- | G18: POWER SUPPLY
A19: QS0011:LD-1 | B19: UJ0131P | C19: WHT | D19: 12 | E19: 60 | F19: UJ0131:+ | G19: POWER SUPPLY
A21: UJ0031:IOUT | B21: UJ0031IOUT | C21: WHT | D21: 20 | E21: 240 | F21: AF0094:10 | G21: LEFT BACK PNL | H21: UJ-LBACK
A22: UJ0031:OK1 | B22: UJ0031OK1 | C22: WHT | D22: 20 | E22: 240 | F22: AF0091:42 | G22: LEFT BACK PNL
A23: UJ0031:OK2 | B23: UJ0031OK2 | C23: WHT | D23: 20 | E23: 240 | F23: AF0091:10 | G23: LEFT BACK PNL
A24: UJ0031:VIN | B24: UJ0031VIN | C24: WHT | D24: 20 | E24: 240 | F24: AF0094:08 | G24: LEFT BACK PNL
A25: UJ0131:IOUT | B25: UJ0131IOUT | C25: WHT | D25: 20 | E25: 240 | F25: AF0094:06 | G25: LEFT BACK PNL
A26: UJ0131:OK1 | B26: UJ0131OK1 | C26: WHT | D26: 20 | E26: 240 | F26: AF0091:41 | G26: LEFT BACK PNL
A27: UJ0131:OK2 | B27: UJ0131OK2 | C27: WHT | D27: 20 | E27: 240 | F27: AF0091:09 | G27: LEFT BACK PNL
A28: UJ0131:VIN | B28: UJ0131VIN | C28: WHT | D28: 20 | E28: 240 | F28: AF0094:04 | G28: LEFT BACK PNL
A30: XT0032:3 | B30: -0V | C30: WHT | D30: 12 | E30: 240 | F30: XT0085:3 | G30: LEFT BACK PNL | H30: XT-LBACK
A31: XT0032:1 | B31: -24V | C31: WHT | D31: 12 | E31: 240 | F31: XT0085:1 | G31: LEFT BACK PNL
A33: XT0033:3 | B33: -0V | C33: WHT | D33: 10 | E33: 200 | F33: XT0134:1 | G33: LEFT WALL | H33: XT-LWALL
A34: XT0033:2 | B34: -24V | C34: WHT | D34: 10 | E34: 200 | F34: FU0136:LI | G34: LEFT WALL

Sheet PWR DISTRIBUTION RAIL_S
A1: POWER DISTRIBUTION RAIL LEFT DOOR
A2: CONTROL CONSOLE DOOR (PWR DIST RAIL)
A3: Project # | B3: J0400
A4: Project Name | B4: NOC ASBAB-A-4401
A5: Revision | B5: A.2
A7: Controls DE | B7: N.GONZALEZ
A8: Phone: | B8: 0
A9: Controls ME | B9: R.DURAN
A10: Phone:
A12: From | G12: To
A13: Device ID | B13: Wire No. | C13: Wire ID | D13: Gauge/Size | E13: Length | F13: Device ID | G13: Location | H13: Bundle Name
A14: AT0680:NEG | B14: -0V | C14: WHT | D14: 14 | E14: 60 | F14: XT0680:2 | G14: PWR DST RAIL | H14: AT
A15: AT0680:POS | B15: AT0680POS | C15: WHT | D15: 14 | E15: 60 | F15: XT0680:1 | G15: PWR DST RAIL
A17: FU0190:LI | B17: FU0200LI | C17: WHT | D17: 14 | E17: 60 | F17: FU0273:LI | G17: PWR DST RAIL | H17: FU/XT
A18: FU0200:LI | B18: FU0200LI | C18: WHT | D18: 14 | E18: 60 | F18: XT0561:1 | G18: PWR DST RAIL
A19: FU0201:LI | B19: FU0200LI | C19: WHT | D19: 14 | E19: 60 | F19: FU0273:LI | G19: PWR DST RAIL
A20: FU0560:LD | B20: FU0200LI | C20: WHT | D20: 14 | E20: 60 | F20: XT0561:1 | G20: PWR DST RAIL
A21: FU0680:LD | B21: AT0680POS | C21: WHT | D21: 14 | E21: 60 | F21: XT0680:1 | G21: PWR DST RAIL
A23: FU0560:LI | B23: FU0139 | C23: WHT | D23: 12 | E23: 60 | F23: XT0560:1 | G23: PWR DST RAIL
A25: XT0563:8 | B25: TCP18B1 | C25: WHT | D25: 20 | E25: 280 | F25: AF0081:37 | G25: LEFT BACK PNL | H25: XT-LBACK
A26: XT0563:9 | B26: TCP18B2 | C26: WHT | D26: 20 | E26: 280 | F26: AF0081:05 | G26: LEFT BACK PNL
F27: `
A28: XT0561:2 | B28: FU9999L1 | C28: WHT | D28: 14 | E28: 240 | F28: FU9999:LI | G28: LEFT WALL | H28: XT-LWALL
A30: XT0560:2 | B30: -0V | C30: WHT | D30: 12 | E30: 240 | F30: XT0134:2 | G30: LEFT WALL
A31: XT0560:1 | B31: FU0139 | C31: WHT | D31: 12 | E31: 240 | F31: XT0138:2 | G31: LEFT WALL
A33: XT0563:4 | B33: -0V | C33: WHT | D33: 20 | E33: 360 | F33: XT0240:9 | G33: RIGHT WALL | H33: FU/XT-RWALL
A34: XT0563:2 | B34: ESTOPA | C34: WHT | D34: 20 | E34: 360 | F34: XT0240:3 | G34: RIGHT WALL
A35: XT0563:1 | B35: ESTOPB | C35: WHT | D35: 20 | E35: 360 | F35: XT0240:2 | G35: RIGHT WALL
A36: XT0563:6 | B36: FU0139 | C36: WHT | D36: 20 | E36: 360 | F36: XT0240:11 | G36: RIGHT WALL
A37: XT0563:3 | B37: KA023612 | C37: WHT | D37: 20 | E37: 360 | F37: XT0240:13 | G37: RIGHT WALL
A38: XT0563:5 | B38: KA0241A1 | C38: WHT | D38: 20 | E38: 360 | F38: XT0240:6 | G38: RIGHT WALL
A40: XT0680:2 | B40: -0V | C40: WHT | D40: 14 | E40: 360 | F40: XT0235:3 | G40: RIGHT WALL
A42: FU0680:LI | B42: FU0210 | C42: WHT | D42: 14 | E42: 360 | F42: XT0233:3 | G42: RIGHT WALL

Sheet OBRIT_S
A1: ORBIT 60^DOOR PANEL
A2: CONTROL CONSOLE^(ORBIT 60 RACK DOOR PANEL)
A3: Project # | B3: J0400
A4: Project Name | B4: NOC ASBAB-A-4401
A5: Revision | B5: A.2
A7: Controls DE | B7: N.GONZALEZ
A8: Phone: | B8: 0
A9: Controls ME | B9: R.DURAN
A10: Phone:
A12: From | G12: To
A13: Device ID | B13: Wire No. | C13: Wire ID | D13: Gauge/Size | E13: Length | F13: Device ID | G13: Location | H13: Bundle Name
A14: AP0612:ARM | B14: -0612ARM | C14: WHT | D14: 20 | E14: 260 | F14: AF0082:38 | G14: LEFT BACK PNL | H14: AP-LBACK
A15: AP0612:NO | B15: -0612NO | C15: WHT | D15: 20 | E15: 260 | F15: AF0082:06 | G15: LEFT BACK PNL
A16: AP0628:ARM1 | B16: -0628ARM1 | C16: WHT | D16: 20 | E16: 260 | F16: AF0082:39 | G16: LEFT BACK PNL
A17: AP0628:ARM2 | B17: -0628ARM2 | C17: WHT | D17: 20 | E17: 260 | F17: AF0082:40 | G17: LEFT BACK PNL
A18: AP0628:ARM3 | B18: -0628ARM3 | C18: WHT | D18: 20 | E18: 260 | F18: AF0082:41 | G18: LEFT BACK PNL
A19: AP0628:NO1 | B19: -0628NO1 | C19: WHT | D19: 20 | E19: 260 | F19: AF0082:07 | G19: LEFT BACK PNL
A20: AP0628:NO2 | B20: -0628NO2 | C20: WHT | D20: 20 | E20: 260 | F20: AF0082:08 | G20: LEFT BACK PNL
A21: AP0628:NO3 | B21: -0628NO3 | C21: WHT | D21: 20 | E21: 260 | F21: AF0082:09 | G21: LEFT BACK PNL
A23: AP0612:COM | B23: -0612COM | C23: WHT | D23: 20 | E23: 300 | F23: KA0701:14 | G23: LEFT WALL | H23: AP/UV-LWALL
A24: AP0612:TM | B24: -0612TM | C24: WHT | D24: 20 | E24: 300 | F24: KA0701:11 | G24: LEFT WALL
A26: UV0610:+DC | B26: FU0111 | C26: WHT | D26: 14 | E26: 300 | F26: FU0111:LD | G26: LEFT WALL
A27: UV0611:+DC | B27: FU0112 | C27: WHT | D27: 14 | E27: 300 | F27: FU0112:LD | G27: LEFT WALL
A29: UV0610:COM | B29: -0V | C29: WHT | D29: 14 | E29: 400 | F29: XT0110:2 | G29: RIGHT WALL | H29: UV-RWALL
A30: UV0611:COM | B30: -0V | C30: WHT | D30: 14 | E30: 400 | F30: XT0110:3 | G30: RIGHT WALL

Sheet LS WALL_S
A1: LEFT SIDE WALL^PANEL
A3: Project # | B3: J0400
A4: Project Name | B4: NOC ASBAB-A-4401
A5: Revision | B5: A.2
A7: Controls DE | B7: N.GONZALEZ
A8: Phone: | B8: 0
A9: Controls ME | B9: R.DURAN
A10: Phone:
A12: From | G12: To
A13: Device ID | B13: Wire No. | C13: Wire ID | D13: Gauge/Size | E13: Length | F13: Device ID | G13: Location | H13: Bundle Name
A14: FU0082:LD | B14: FU0082 | C14: WHT | D14: 16 | E14: 120 | F14: XT9002:4 | G14: LEFT WALL | H14: FU
A16: FU0111:LI | B16: FU0110 | C16: WHT | D16: 14 | E16: 100 | F16: FU0110:LD | G16: LEFT WALL
A17: FU0120:LI | B17: FU0130 | C17: WHT | D17: 14 | E17: 100 | F17: FU0130:LD | G17: LEFT WALL
A18: FU0010:LI | B18: FU0137 | C18: WHT | D18: 14 | E18: 60 | F18: FU0139:LI | G18: LEFT WALL
A19: FU0010:LI | B19: FU0137 | C19: WHT | D19: 14 | E19: 60 | F19: XT0139:1 | G19: LEFT WALL
A20: FU0080:LI | B20: FU0137 | C20: WHT | D20: 14 | E20: 60 | F20: XT0139:1 | G20: LEFT WALL
A21: FU0090:LI | B21: FU0137 | C21: WHT | D21: 14 | E21: 60 | F21: XT0139:2 | G21: LEFT WALL
A22: FU0170:LI | B22: FU0137 | C22: WHT | D22: 14 | E22: 60 | F22: XT0139:3 | G22: LEFT WALL
A23: FU0211:LI | B23: FU0137 | C23: WHT | D23: 14 | E23: 60 | F23: XT0139:3 | G23: LEFT WALL
A24: FU0271:LI | B24: FU0137 | C24: WHT | D24: 14 | E24: 100 | F24: XT0139:2 | G24: LEFT WALL
A25: FU0272:LI | B25: FU0137 | C25: WHT | D25: 14 | E25: 100 | F25: XT0139:3 | G25: LEFT WALL
A26: FU0140:LI | B26: FU0570 | C26: WHT | D26: 14 | E26: 100 | F26: FU0570:LD | G26: LEFT WALL
A27: FU0142:LI | B27: FU0570 | C27: WHT | D27: 14 | E27: 100 | F27: FU0180:LI | G27: LEFT WALL
... A31: FU0210:LI | B31: FU0139 | C31: WHT | D31: 12 | E31: 60 | F31: XT0138:4 | G31: LEFT WALL
A33: KA0130:A1 | B33: -008135 | C33: WHT | D33: 20 | E33: 80 | F33: KA0130:11 | G33: LEFT WALL | H33: KA A1
A34: KA0240:A1 | B34: ESTOP | C34: WHT | D34: 20 | E34: 60 | F34: KA0248:A1 | G34: LEFT WALL
A35: KA0248:A1 | B35: ESTOP | C35: WHT | D35: 20 | E35: 60 | F35: KA0250:A1 | G35: LEFT WALL
A36: KA0534:A1 | B36: ESTOP | C36: WHT | D36: 20 | E36: 60 | F36: KA0537:A1 | G36: LEFT WALL
A37: KA0131:A1 | B37: KA0231A1 | C37: WHT | D37: 20 | E37: 80 | F37: KA0242:11 | G37: LEFT WALL
A38: KA0132:A1 | B38: KA0231A1 | C38: WHT | D38: 20 | E38: 60 | F38: KA0141:A1 | G38: LEFT WALL
A39: KA0230:A1 | B39: KA0231A1 | C39: WHT | D39: 20 | E39: 60 | F39: KA0234:A1 | G39: LEFT WALL
A40: KA0230:A1 | B40: KA0231A1 | C40: WHT | D40: 20 | E40: 60 | F40: XT0139:4 | G40: LEFT WALL
A41: KA0244:A1 | B41: KA0243A1 | C41: WHT | D41: 20 | E41: 60 | F41: KA0246:A1 | G41: LEFT WALL
A42: KA0245:A1 | B42: KA0245A1 | C42: WHT | D42: 20 | E42: 60 | F42: KA0249:A1 | G42: LEFT WALL
A43: KA0540:A1 | B43: KA053214 | C43: WHT | D43: 20 | E43: 100 | F43: KA0532:14 | G43: LEFT WALL
A44: KA0541:A1 | B44: KA053224 | C44: WHT | D44: 20 | E44: 100 | F44: KA0532:24 | G44: LEFT WALL
A45: KA0542:A1 | B45: KA053424 | C45: WHT | D45: 20 | E45: 100 | F45: KA0534:24 | G45: LEFT WALL
... A48: KA1823:A1 | B48: SB7513-1 | C48: WHT | D48: 20 | E48: 100 | F48: XT9002K:20 | G48: LEFT WALL
A50: KA0132:A2 | B50: -0V | C50: WHT | D50: 20 | E50: 60 | F50: KA0141:A2 | G50: LEFT WALL | H50: KA A2
A51: KA0133:A2 | B51: -0V | C51: WHT | D51: 20 | E51: 60 | F51: KA0141:A2 | G51: LEFT WALL
...

Sheet L BACK_S
A1: LEFT BACK^PANEL
A3: Project # | B3: J0400
A4: Project Name | B4: NOC ASBAB-A-4401
A5: Revision | B5: A.2
A7: Controls DE | B7: N.GONZALEZ
A8: Phone: | B8: 0
A9: Controls ME | B9: R.DURAN
A10: Phone:
A12: From | G12: To
A13: Device ID | B13: Wire No. | C13: Wire ID | D13: Gauge/Size | E13: Length | F13: Device ID | G13: Location | H13: Bundle Name
A14: PC0470:INP_A | B14: -009312 | C14: WHT | D14: 20 | E14: 60 | F14: AF0093:12 | G14: LEFT BACK PNL | H14: PC
A15: PC0470:-PWR | B15: -009328 | C15: WHT | D15: 20 | E15: 60 | F15: AF0093:28 | G15: LEFT BACK PNL
A16: PC0470:+PWR | B16: -009344 | C16: WHT | D16: 20 | E16: 60 | F16: AF0093:44 | G16: LEFT BACK PNL
A18: AF0093:04 | B18: -009304 | C18: WHT | D18: 20 | E18: 60 | F18: XT0171:2 | G18: LEFT BACK PNL | H18: AF/AU
A19: AF0093:05 | B19: -009305 | C19: WHT | D19: 20 | E19: 60 | F19: XT0171:6 | G19: LEFT BACK PNL
A20: AF0094:00 | B20: -009400 | C20: WHT | D20: 20 | E20: 60 | F20: XT0085:2 | G20: LEFT BACK PNL
A22: AF0091:COM | B22: AF0091N | C22: WHT | D22: 16 | E22: 60 | F22: AF0094:COM | G22: LEFT BACK PNL
A24: AF0092:COM | B24: -0V | C24: WHT | D24: 14 | E24: 60 | F24: XT0081:1 | G24: LEFT BACK PNL
A25: AF0093:COM | B25: -0V | C25: WHT | D25: 14 | E25: 60 | F25: XT0081:2 | G25: LEFT BACK PNL
A26: AF0095:COM | B26: -0V | C26: WHT | D26: 14 | E26: 60 | F26: XT0081:2 | G26: LEFT BACK PNL
A27: AU0090:COM | B27: -0V | C27: WHT | D27: 14 | E27: 60 | F27: XT0081:1 | G27: LEFT BACK PNL
A28: AU0080:COM | B28: -0V | C28: WHT | D28: 14 | E28: 60 | F28: XT0080:1 | G28: LEFT BACK PNL
A29: AF0091:V+ | B29: AF0091P | C29: WHT | D29: 14 | E29: 60 | F29: AF0094:V+ | G29: LEFT BACK PNL
A30: AF0094:COM | B30: AF0094N | C30: WHT | D30: 14 | E30: 60 | F30: AF0096:COM | G30: LEFT BACK PNL
A31: AF0094:V+ | B31: AF0094P | C31: WHT | D31: 14 | E31: 60 | F31: AF0096:V+ | G31: LEFT BACK PNL
A33: AF0094:01 | B33: -0V | C33: WHT | D33: 12 | E33: 60 | F33: XT0085:3 | G33: LEFT BACK PNL
A35: KA3103:A1 | B35: -009208 | C35: WHT | D35: 20 | E35: 100 | F35: AF0092:08 | G35: LEFT BACK PNL | H35: KA A1/A2
A37: KA3103:A2 | B37: -009224 | C37: WHT | D37: 20 | E37: 100 | F37: AF0092:24 | G37: LEFT BACK PNL
A38: KA6211:A2 | B38: -009320 | C38: WHT | D38: 20 | E38: 100 | F38: AF0093:20 | G38: LEFT BACK PNL
A39: KA6212:A2 | B39: -009321 | C39: WHT | D39: 20 | E39: 100 | F39: AF0093:21 | G39: LEFT BACK PNL
A41: KA0138:11 | B41: FU0113 | C41: RED | D41: 16R | E41: 60 | F41: XT9004K:7 | G41: LEFT BACK PNL | H41: KA RED
A42: KA3103:14 | B42: H3103-T2 | C42: RED | D42: 16R | E42: 60 | F42: XT9004K:5 | G42: LEFT BACK PNL
A43: KA3103:11 | B43: KM3103-EN | C43: RED | D43: 16R | E43: 60 | F43: XT9004K:8 | G43: LEFT BACK PNL
A44: KA0135:11 | B44: KM3150-EN | C44: RED | D44: 16R | E44: 60 | F44: XT9004K:2 | G44: LEFT BACK PNL
A45: KA0135:12 | B45: KM3150-EP | C45: RED | D45: 16R | E45: 60 | F45: XT9004K:1 | G45: LEFT BACK PNL
A46: KA6211:11 | B46: KM6211-EN | C46: RED | D46: 16R | E46: 60 | F46: XT9004K:10 | G46: LEFT BACK PNL
A47: KA6211:14 | B47: KM6211-EP | C47: RED | D47: 16R | E47: 60 | F47: XT9004K:9 | G47: LEFT BACK PNL
A48: KA6212:11 | B48: KM6212-EN | C48: RED | D48: 16R | E48: 60 | F48: XT9004K:12 | G48: LEFT BACK PNL
A49: KA6212:14 | B49: KM6212-EP | C49: RED | D49: 16R | E49: 60 | F49: XT9004K:11 | G49: LEFT BACK PNL
A50: KA0138:12 | B50: SB3170-212 | C50: RED | D50: 16R | E50: 60 | F50: XT9004K:6 | G50: LEFT BACK PNL
...

Sheet ISO_S
A1: CENTER BACK^ISOLATOR PANEL
A3: Project # | B3: J0400
A4: Project Name | B4: NOC ASBAB-A-4401
A5: Revision | B5: A.2
A7: Controls DE | B7: N.GONZALEZ
A8: Phone: | B8: 0
A9: Controls ME | B9: R.DURAN
A10: Phone:
A12: From | G12: To
A13: Device ID | B13: Wire No. | C13: Wire ID | D13: Gauge/Size | E13: Length | F13: Device ID | G13: Location | H13: Bundle Name
A14: UAI0814:1+ | B14: ZS6151P | C14: WHT | D14: 20 | E14: 140 | F14: XT8001KI:76 | G14: ISOLATOR | H14: UAI
A15: UAI0814:3- | B15: ZS61551 | C15: WHT | D15: 20 | E15: 140 | F15: XT8001KI:77 | G15: ISOLATOR
A16: UAI1426:4+ | B16: ZSC7601-1 | C16: WHT | D16: 20 | E16: 140 | F16: XT8001KI:109 | G16: ISOLATOR
A17: UAI1426:6- | B17: ZSC7601-2 | C17: WHT | D17: 20 | E17: 140 | F17: XT8001KI:110 | G17: ISOLATOR
A18: UAI1428:4+ | B18: ZSC7611-1 | C18: WHT | D18: 20 | E18: 140 | F18: XT8001KI:90 | G18: ISOLATOR
A19: UAI1428:6- | B19: ZSC7611-2 | C19: WHT | D19: 20 | E19: 140 | F19: XT8001KI:91 | G19: ISOLATOR
A20: UAI1429:4+ | B20: ZSC7621-1 | C20: WHT | D20: 20 | E20: 140 | F20: XT8001KI:94 | G20: ISOLATOR
A21: UAI1429:6- | B21: ZSC7621-2 | C21: WHT | D21: 20 | E21: 140 | F21: XT8001KI:95 | G21: ISOLATOR
A22: UAI1831:4+ | B22: ZSC7641-1 | C22: WHT | D22: 20 | E22: 140 | F22: XT8001KI:101 | G22: ISOLATOR
A23: UAI1831:6- | B23: ZSC7641-2 | C23: WHT | D23: 20 | E23: 140 | F23: XT8001KI:102 | G23: ISOLATOR
A24: UAI1832:4+ | B24: ZSC7643-1 | C24: WHT | D24: 20 | E24: 140 | F24: XT8001KI:105 | G24: ISOLATOR
A25: UAI1832:6- | B25: ZSC7643-2 | C25: WHT | D25: 20 | E25: 140 | F25: XT8001KI:106 | G25: ISOLATOR
A26: UAI1426:1+ | B26: ZSO7601-1 | C26: WHT | D26: 20 | E26: 140 | F26: XT8001KI:107 | G26: ISOLATOR
... A35: UAI1832:3- | B35: ZSO7643-2 | C35: WHT | D35: 20 | E35: 140 | F35: XT8001KI:104 | G35: ISOLATOR
A37: UV0271:11+ | B37: UV0272-8 | C37: WHT | D37: 16 | E37: 60 | F37: UV0272:8+ | G37: ISOLATOR | H37: UV
A38: UV0271:12- | B38: UV0272-9 | C38: WHT | D38: 16 | E38: 60 | F38: UV0272:9- | G38: ISOLATOR
A39: UV0272:11+ | B39: UV0273-8 | C39: WHT | D39: 16 | E39: 160 | F39: UV0273:8+ | G39: ISOLATOR
A40: UV0272:12- | B40: UV0273-9 | C40: WHT | D40: 16 | E40: 160 | F40: UV0273:9- | G40: ISOLATOR
A42: UAI1426:11 | B42: -014205 | C42: WHT | D42: 20 | E42: 260 | F42: AF0142:05 | G42: RIGHT WALL | H42: UAI-RWALL
A43: UAI1426:8 | B43: -014206 | C43: WHT | D43: 20 | E43: 260 | F43: AF0142:06 | G43: RIGHT WALL
A44: UAI1428:11 | B44: -014207 | C44: WHT | D44: 20 | E44: 260 | F44: XT0572:1 | G44: RIGHT WALL
A45: UAI1428:8 | B45: -014208 | C45: WHT | D45: 20 | E45: 260 | F45: AF0142:08 | G45: RIGHT WALL
A46: UAI1429:8 | B46: -014209 | C46: WHT | D46: 20 | E46: 260 | F46: AF0142:09 | G46: RIGHT WALL
A47: UAI1831:8 | B47: -014212 | C47: WHT | D47: 20 | E47: 260 | F47: AF0142:12 | G47: RIGHT WALL
A48: UAI1832:8 | B48: -014213 | C48: WHT | D48: 20 | E48: 260 | F48: AF0142:13 | G48: RIGHT WALL
A49: UAI1426:10 | B49: -014237 | C49: WHT | D49: 20 | E49: 260 | F49: AF0142:37 | G49: RIGHT WALL
A50: UAI1426:7 | B50: -014238 | C50: WHT | D50: 20 | E50: 260 | F50: AF0142:38 | G50: RIGHT WALL
A51: UAI1428:10 | B51: -014239 | C51: WHT | D51: 20 | E51: 260 | F51: AF0142:39 | G51: RIGHT WALL
A52: UAI1428:7 | B52: -014240 | C52: WHT | D52: 20 | E52: 260 | F52: AF0142:40 | G52: RIGHT WALL
A53: UAI1429:7 | B53: -014241 | C53: WHT | D53: 20 | E53: 260 | F53: AF0142:41 | G53: RIGHT WALL
...

Sheet RS WALL_S
A1: RIGHT SIDE WALL^PANEL
A3: Project # | B3: J0400
A4: Project Name | B4: NOC ASBAB-A-4401
A5: Revision | B5: A.2
A7: Controls DE | B7: N.GONZALEZ
A8: Phone: | B8: 0
A9: Controls ME | B9: R.DURAN
A10: Phone:
A12: From | G12: To
A13: Device ID | B13: Wire No. | C13: Wire ID | D13: Gauge/Size | E13: Length | F13: Device ID | G13: Location | H13: Bundle Name
A14: AF0062:16 | B14: SV2124-2 | C14: WHT | D14: 20 | E14: 160 | F14: XT0060:6 | G14: RIGHT WALL | H14: AF/AU060s
A16: AF0065:COM | B16: AF0065N | C16: WHT | D16: 16 | E16: 60 | F16: AF0068:COM | G16: RIGHT WALL
A17: AF0065:V+ | B17: AF0065P | C17: WHT | D17: 16 | E17: 60 | F17: AF0068:V+ | G17: RIGHT WALL
A18: AF0063:COM | B18: AU0060N | C18: WHT | D18: 16 | E18: 60 | F18: AU0060:COM | G18: RIGHT WALL
A19: AF0063:V+ | B19: AU0060P | C19: WHT | D19: 16 | E19: 60 | F19: AU0060:V+ | G19: RIGHT WALL
A21: AF0061:COM | B21: -0V | C21: WHT | D21: 14 | E21: 160 | F21: XT0060:2 | G21: RIGHT WALL
A22: AF0062:COM | B22: -0V | C22: WHT | D22: 14 | E22: 160 | F22: XT0060:2 | G22: RIGHT WALL
A23: AF0066:COM | B23: -0V | C23: WHT | D23: 14 | E23: 160 | F23: XT0060:2 | G23: RIGHT WALL
A24: AF0067:COM | B24: -0V | C24: WHT | D24: 14 | E24: 160 | F24: XT0060:2 | G24: RIGHT WALL
A25: AU0060:COM | B25: -0V | C25: WHT | D25: 14 | E25: 160 | F25: XT0060:1 | G25: RIGHT WALL
A27: AF0076:12 | B27: -007612 | C27: WHT | D27: 20 | E27: 60 | F27: XT0237:1 B2 | G27: RIGHT WALL | H27: AF/AU070s
A29: AF0076:COM | B29: -0V | C29: WHT | D29: 14 | E29: 140 | F29: XT0070:1 | G29: RIGHT WALL
A30: AU0070:COM | B30: -0V | C30: WHT | D30: 14 | E30: 140 | F30: XT0070:1 | G30: RIGHT WALL
A32: AF0142:07 | B32: -014207 | C32: WHT | D32: 20 | E32: 100 | F32: XT0572:1 | G32: RIGHT WALL | H32: AF/AU140s
A33: AF0142:COM | B33: AU0140N | C33: WHT | D33: 20 | E33: 60 | F33: AU0140:COM | G33: RIGHT WALL
A34: AF0142:V+ | B34: AU0140P | C34: WHT | D34: 20 | E34: 60 | F34: AU0140:V+ | G34: RIGHT WALL
A35: AF0141:16 | B35: SV7621-2 | C35: WHT | D35: 20 | E35: 100 | F35: XT0572:4 | G35: RIGHT WALL
A36: AF0141:20 | B36: SV7641-2 | C36: WHT | D36: 20 | E36: 100 | F36: XT0572:5 | G36: RIGHT WALL
A37: AF0141:22 | B37: SV7643-2 | C37: WHT | D37: 20 | E37: 100 | F37: XT0572:10 | G37: RIGHT WALL
A39: AF0141:COM | B39: -0V | C39: WHT | D39: 14 | E39: 140 | F39: XT0140:3 | G39: RIGHT WALL
A40: AF0146:COM | B40: -0V | C40: WHT | D40: 14 | E40: 160 | F40: XT0140:3 | G40: RIGHT WALL
A41: AU0140:COM | B41: -0V | C41: WHT | D41: 14 | E41: 140 | F41: XT0140:2 | G41: RIGHT WALL
A43: AF0183:00 | B43: -018300 | C43: WHT | D43: 20 | E43: 80 | F43: XT0572:2 | G43: RIGHT WALL | H43: AF/AU0180s
A44: AF0183:01 | B44: -018301 | C44: WHT | D44: 20 | E44: 80 | F44: XT0572:3 | G44: RIGHT WALL
A45: AF0183:02 | B45: -018302 | C45: WHT | D45: 20 | E45: 80 | F45: XT0572:9 | G45: RIGHT WALL
A46: AF0183:COM | B46: AF0183N | C46: WHT | D46: 20 | E46: 60 | F46: AF0185:COM | G46: RIGHT WALL
A47: AF0183:V+ | B47: AF0183P | C47: WHT | D47: 20 | E47: 60 | F47: AF0185:V+ | G47: RIGHT WALL
A48: AF0182:COM | B48: AU0180N | C48: WHT | D48: 20 | E48: 60 | F48: AU0180:COM | G48: RIGHT WALL
A49: AF0182:V+ | B49: AU0180P | C49: WHT | D49: 20 | E49: 60 | F49: AU0180:V+ | G49: RIGHT WALL
A51: AF0181:COM | B51: -0V | C51: WHT | D51: 14 | E51: 160 | F51: XT0180:2 | G51: RIGHT WALL
...

Sheet JB44_S
A1: JB44
A2: BUOS BOX
A3: Project # | B3: J0400
A4: Project Name | B4: NOC ASBAB-A-4401
A5: Revision | B5: A.2
A7: Controls DE | B7: N.GONZALEZ
A8: Phone: | B8: 0
A9: Controls ME | B9: R.DURAN
A10: Phone:
A12: From | G12: To
A13: Device ID | B13: Wire No. | C13: Wire ID | D13: Gauge/Size | E13: Length | F13: Device ID | G13: Location | H13: Bundle Name
A14: UA1200:J1-9 | B14: -0V | C14: WHT | D14: 20 | E14: 60 | F14: XT1200:11 | G14: JB44 | H14: UA1200
A15: UA1200:J1-10 | B15: FU0212 | C15: WHT | D15: 20 | E15: 60 | F15: XT1200:10 | G15: JB44
A16: UA1200:J2-2 | B16: FU0212 | C16: WHT | D16: 20 | E16: 60 | F16: XT1200:9 | G16: JB44
A17: UA1200:J1-8 | B17: UA1200J | C17: WHT | D17: 20 | E17: 60 | F17: UA1200:J3-5 | G17: JB44
A18: UA1200:J1-4 | B18: UA1200J14 | C18: WHT | D18: 20 | E18: 60 | F18: XT1200:4 | G18: JB44
A19: UA1200:J1-5 | B19: UA1200J15 | C19: WHT | D19: 20 | E19: 60 | F19: XT1200:5 | G19: JB44
A20: UA1200:J2-1 | B20: UA1200J21 | C20: WHT | D20: 20 | E20: 60 | F20: XT1200:8 | G20: JB44
A21: UA1200:J2-6 | B21: UA1200J26 | C21: WHT | D21: 20 | E21: 60 | F21: XT1200:6 | G21: JB44
A22: UA1200:J2-7 | B22: UA1200J27 | C22: WHT | D22: 20 | E22: 60 | F22: XT1200:7 | G22: JB44

Sheet Bundle Tag Info
A1: NOC-A #1
A2: J0400
A3: A.2
A6: CONSOLE | B6: PWR SUPPLY | C6: PWR DST RAIL | D6: ORBIT | E6: LS WALL | F6: L BACK | G6: ISOLATOR | H6: RS WALL | I6: JB44 | J6: Panel Name | K6: Panel Name | L6: Panel Name | M6: Panel Name | N6: Panel Name | O6: Panel Name | P6: Panel Name | Q6: Panel Name | R6: Panel Name | S6: Panel Name | T6: Panel Name | U6: Panel Name | V6: Panel Name | W6: Panel Name | X6: Panel Name | Y6: Panel Name | Z6: Panel Name | AA6: Panel Name | AB6: Panel Name | AC6: Panel Name | AD6: Panel Name
A7: EL | B7: UJ/QS | C7: AT | D7: AP-LBACK | E7: FU | F7: PC | G7: UAI | H7: AF/AU060s | I7: UA1200
A8: AT-PDR | B8: UJ-LBACK | C8: FU/XT | D8: AP/UV-LWALL | E8: KA A1 | F8: AF/AU | G8: UV | H8: AF/AU070s
A9: EL-PDR | B9: XT-LBACK | C9: XT-LBACK | D9: UV-RWALL | E9: KA A2 | F9: KA A1/A2 | G9: UAI-RWALL | H9: AF/AU140s
A10: AZ-PDR | B10: XT-LWALL | C10: XT-LWALL | E10: KA | F10: KA RED | H10: AF/AU0180s
C11: FU/XT-RWALL | E11: XT | F11: KT L/S | H11: AF/AU1200s
E12: FU/XT-ISO | F12: KT R/S | H12: XT
E13: FU-LBACK | F13: AF-ISO
E14: KA A1/A2-LBACK | F14: KT L/S-RWALL
E15: KA-LBACK | F15: KT R/S-RWALL
E16: XT-LBACK | F16: AF/XT-RWALL
E17: XT9K-LBACK
E18: FU-RWALL
E19: KA A1-RWALL
E20: KA A2-RWALL
E21: KA-RWALL
E22: XT-RWALL
E23: XT9K-RWALL

Sheet Bundle Tags2
A1: =IF('Bundle Tag Info'!A6<>"Panel Name",'Bundle Tag Info'!A6,"") -> CONSOLE | B1: =IF('Bundle Tag Info'!B6<>"Panel Name",'Bundle Tag Info'!B6,"") -> PWR SUPPLY | C1: =IF('Bundle Tag Info'!C6<>"Panel Name",'Bundle Tag Info'!C6,"") -> PWR DST RAIL | D1: =IF('Bundle Tag Info'!D6<>"Panel Name",'Bundle Tag Info'!D6,"") -> ORBIT | E1: =IF('Bundle Tag Info'!E6<>"Panel Name",'Bundle Tag Info'!E6,"") -> LS WALL | F1: =IF('Bundle Tag Info'!F6<>"Panel Name",'Bundle Tag Info'!F6,"") -> L BACK | G1: =IF('Bundle Tag Info'!G6<>"Panel Name",'Bundle Tag Info'!G6,"") -> ISOLATOR | H1: =IF('Bundle Tag Info'!H6<>"Panel Name",'Bundle Tag Info'!H6,"") -> RS WALL | ... AD1: =IF('Bundle Tag Info'!AD6<>"Panel Name",'Bundle Tag Info'!AD6,"")
A2: =IF('Bundle Tag Info'!A$7<>"",CONCATENATE('Bundle Tag Info'!$A$1," ",CHAR(10),'Bundle Tag Info'!$A$2," ",'Bundle Tag Info'!$A$3,CHAR(10),'Bundle Tag Info'!A$6,CHAR(10),'Bundle Tag Info'!A$7),"") -> NOC-A #1 J0400 A.2 CONSOLE EL | B2: =IF('Bundle Tag Info'!B$7<>"",CONCATENATE('Bundle Tag Info'!$A$1," ",CHAR(10),'Bundle Tag Info'!$A$2," ",'Bundle Tag Info'!$A$3,CHAR(10),'Bundle Tag Info'!B$6,CHAR(10),'Bundle Tag Info'!B$7),"") -> NOC-A #1 J0400 A.2 PWR SUPPLY UJ/QS | C2: =IF('Bundle Tag Info'!C$7<>"",CONCATENATE('Bundle Tag Info'!$A$1," ",CHAR(10),'Bundle Tag Info'!$A$2," ",'Bundle Tag Info'!$A$3,CHAR(10),'Bundle Tag Info'!C$6,CHAR(10),'Bundle Tag Info'!C$7),"") -> NOC-A #1 J0400 A.2 PWR DST RAIL AT | D2: =IF('Bundle Tag Info'!D$7<>"",CONCATENATE('Bundle Tag Info'!$A$1," ",CHAR(10),'Bundle Tag Info'!$A$2," ",'Bundle Tag Info'!$A$3,CHAR(10),'Bundle Tag Info'!D$6,CHAR(10),'Bundle Tag Info'!D$7),"") -> NOC-A #1 J0400 A.2 ORBIT AP-LBACK | E2: =IF('Bundle Tag Info'!E$7<>"",CONCATENATE('Bundle Tag Info'!$A$1," ",CHAR(10),'Bundle Tag Info'!$A$2," ",'Bundle Tag Info'!$A$3,CHAR(10),'Bundle Tag Info'!E$6,CHAR(10),'Bundle Tag Info'!E$7),"") -> NOC-A #1 J0400 A.2 LS WALL FU | F2: =IF('Bundle Tag Info'!F$7<>"",CONCATENATE('Bundle Tag Info'!$A$1," ",CHAR(10),'Bundle Tag Info'!$A$2," ",'Bundle Tag Info'!$A$3,CHAR(10),'Bundle Tag Info'!F$6,CHAR(10),'Bundle Tag Info'!F$7),"") -> NOC-A #1 J0400 A.2 L BACK PC | G2: =IF('Bundle Tag Info'!G$7<>"",CONCATENATE('Bundle Tag Info'!$A$1," ",CHAR(10),'Bundle Tag Info'!$A$2," ",'Bundle Tag Info'!$A$3,CHAR(10),'Bundle Tag Info'!G$6,CHAR(10),'Bundle Tag Info'!G$7),"") -> NOC-A #1 J0400 A.2 ISOLATOR UAI | H2: =IF('Bundle Tag Info'!H$7<>"",CONCATENATE('Bundle Tag Info'!$A$1," ",CHAR(10),'Bundle Tag Info'!$A$2," ",'Bundle Tag Info'!$A$3,CHAR(10),'Bundle Tag Info'!H$6,CHAR(10),'Bundle Tag Info'!H$7),"") -> NOC-A #1 J0400 A.2 RS WALL AF/AU060s | ... AD2: =IF('Bundle Tag Info'!AD$7<>"",CONCATENATE('Bundle Tag Info'!$A$1," ",CHAR(10),'Bundle Tag Info'!$A$2," ",'Bundle Tag Info'!$A$3,CHAR(10),'Bundle Tag Info'!AD$6,CHAR(10),'Bundle Tag Info'!AD$7),"")
A3: =IF('Bundle Tag Info'!A$8<>"",CONCATENATE('Bundle Tag Info'!$A$1," ",CHAR(10),'Bundle Tag Info'!$A$2," ",'Bundle Tag Info'!$A$3,CHAR(10),'Bundle Tag Info'!A$6,CHAR(10),'Bundle Tag Info'!A$8),"") -> NOC-A #1 J0400 A.2 CONSOLE AT-PDR | B3: =IF('Bundle Tag Info'!B$8<>"",CONCATENATE('Bundle Tag Info'!$A$1," ",CHAR(10),'Bundle Tag Info'!$A$2," ",'Bundle Tag Info'!$A$3,CHAR(10),'Bundle Tag Info'!B$6,CHAR(10),'Bundle Tag Info'!B$8),"") -> NOC-A #1 J0400 A.2 PWR SUPPLY UJ-LBACK | C3: =IF('Bundle Tag Info'!C$8<>"",CONCATENATE('Bundle Tag Info'!$A$1," ",CHAR(10),'Bundle Tag Info'!$A$2," ",'Bundle Tag Info'!$A$3,CHAR(10),'Bundle Tag Info'!C$6,CHAR(10),'Bundle Tag Info'!C$8),"") -> NOC-A #1 J0400 A.2 PWR DST RAIL FU/XT | D3: =IF('Bundle Tag Info'!D$8<>"",CONCATENATE('Bundle Tag Info'!$A$1," ",CHAR(10),'Bundle Tag Info'!$A$2," ",'Bundle Tag Info'!$A$3,CHAR(10),'Bundle Tag Info'!D$6,CHAR(10),'Bundle Tag Info'!D$8),"") -> NOC-A #1 J0400 A.2 ORBIT AP/UV-LWALL | E3: =IF('Bundle Tag Info'!E$8<>"",CONCATENATE('Bundle Tag Info'!$A$1," ",CHAR(10),'Bundle Tag Info'!$A$2," ",'Bundle Tag Info'!$A$3,CHAR(10),'Bundle Tag Info'!E$6,CHAR(10),'Bundle Tag Info'!E$8),"") -> NOC-A #1 J0400 A.2 LS WALL KA A1 | F3: =IF('Bundle Tag Info'!F$8<>"",CONCATENATE('Bundle Tag Info'!$A$1," ",CHAR(10),'Bundle Tag Info'!$A$2," ",'Bundle Tag Info'!$A$3,CHAR(10),'Bundle Tag Info'!F$6,CHAR(10),'Bundle Tag Info'!F$8),"") -> NOC-A #1 J0400 A.2 L BACK AF/AU | G3: =IF('Bundle Tag Info'!G$8<>"",CONCATENATE('Bundle Tag Info'!$A$1," ",CHAR(10),'Bundle Tag Info'!$A$2," ",'Bundle Tag Info'!$A$3,CHAR(10),'Bundle Tag Info'!G$6,CHAR(10),'Bundle Tag Info'!G$8),"") -> NOC-A #1 J0400 A.2 ISOLATOR UV | H3: =IF('Bundle Tag Info'!H$8<>"",CONCATENATE('Bundle Tag Info'!$A$1," ",CHAR(10),'Bundle Tag Info'!$A$2," ",'Bundle Tag Info'!$A$3,CHAR(10),'Bundle Tag Info'!H$6,CHAR(10),'Bundle Tag Info'!H$8),"") -> NOC-A #1 J0400 A.2 RS WALL AF/AU070s | ... AD3: =IF('Bundle Tag Info'!AD$8<>"",CONCATENATE('Bundle Tag Info'!$A$1," ",CHAR(10),'Bundle Tag Info'!$A$2," ",'Bundle Tag Info'!$A$3,CHAR(10),'Bundle Tag Info'!AD$6,CHAR(10),'Bundle Tag Info'!AD$8),"")
A4: =IF('Bundle Tag Info'!A$9<>"",CONCATENATE('Bundle Tag Info'!$A$1," ",CHAR(10),'Bundle Tag Info'!$A$2," ",'Bundle Tag Info'!$A$3,CHAR(10),'Bundle Tag Info'!A$6,CHAR(10),'Bundle Tag Info'!A$9),"") -> NOC-A #1 J0400 A.2 CONSOLE EL-PDR | B4: =IF('Bundle Tag Info'!B$9<>"",CONCATENATE('Bundle Tag Info'!$A$1," ",CHAR(10),'Bundle Tag Info'!$A$2," ",'Bundle Tag Info'!$A$3,CHAR(10),'Bundle Tag Info'!B$6,CHAR(10),'Bundle Tag Info'!B$9),"") -> NOC-A #1 J0400 A.2 PWR SUPPLY XT-LBACK | C4: =IF('Bundle Tag Info'!C$9<>"",CONCATENATE('Bundle Tag Info'!$A$1," ",CHAR(10),'Bundle Tag Info'!$A$2," ",'Bundle Tag Info'!$A$3,CHAR(10),'Bundle Tag Info'!C$6,CHAR(10),'Bundle Tag Info'!C$9),"") -> NOC-A #1 J0400 A.2 PWR DST RAIL XT-LBACK | D4: =IF('Bundle Tag Info'!D$9<>"",CONCATENATE('Bundle Tag Info'!$A$1," ",CHAR(10),'Bundle Tag Info'!$A$2," ",'Bundle Tag Info'!$A$3,CHAR(10),'Bundle Tag Info'!D$6,CHAR(10),'Bundle Tag Info'!D$9),"") -> NOC-A #1 J0400 A.2 ORBIT UV-RWALL | E4: =IF('Bundle Tag Info'!E$9<>"",CONCATENATE('Bundle Tag Info'!$A$1," ",CHAR(10),'Bundle Tag Info'!$A$2," ",'Bundle Tag Info'!$A$3,CHAR(10),'Bundle Tag Info'!E$6,CHAR(10),'Bundle Tag Info'!E$9),"") -> NOC-A #1 J0400 A.2 LS WALL KA A2 | F4: =IF('Bundle Tag Info'!F$9<>"",CONCATENATE('Bundle Tag Info'!$A$1," ",CHAR(10),'Bundle Tag Info'!$A$2," ",'Bundle Tag Info'!$A$3,CHAR(10),'Bundle Tag Info'!F$6,CHAR(10),'Bundle Tag Info'!F$9),"") -> NOC-A #1 J0400 A.2 L BACK KA A1/A2 | G4: =IF('Bundle Tag Info'!G$9<>"",CONCATENATE('Bundle Tag Info'!$A$1," ",CHAR(10),'Bundle Tag Info'!$A$2," ",'Bundle Tag Info'!$A$3,CHAR(10),'Bundle Tag Info'!G$6,CHAR(10),'Bundle Tag Info'!G$9),"") -> NOC-A #1 J0400 A.2 ISOLATOR UAI-RWALL | H4: =IF('Bundle Tag Info'!H$9<>"",CONCATENATE('Bundle Tag Info'!$A$1," ",CHAR(10),'Bundle Tag Info'!$A$2," ",'Bundle Tag Info'!$A$3,CHAR(10),'Bundle Tag Info'!H$6,CHAR(10),'Bundle Tag Info'!H$9),"") -> NOC-A #1 J0400 A.2 RS WALL AF/AU140s | ... AD4: =IF('Bundle Tag Info'!AD$9<>"",CONCATENATE('Bundle Tag Info'!$A$1," ",CHAR(10),'Bundle Tag Info'!$A$2," ",'Bundle Tag Info'!$A$3,CHAR(10),'Bundle Tag Info'!AD$6,CHAR(10),'Bundle Tag Info'!AD$9),"")
A5: =IF('Bundle Tag Info'!A$10<>"",CONCATENATE('Bundle Tag Info'!$A$1," ",CHAR(10),'Bundle Tag Info'!$A$2," ",'Bundle Tag Info'!$A$3,CHAR(10),'Bundle Tag Info'!A$6,CHAR(10),'Bundle Tag Info'!A$10),"") -> NOC-A #1 J0400 A.2 CONSOLE AZ-PDR | B5: =IF('Bundle Tag Info'!B$10<>"",CONCATENATE('Bundle Tag Info'!$A$1," ",CHAR(10),'Bundle Tag Info'!$A$2," ",'Bundle Tag Info'!$A$3,CHAR(10),'Bundle Tag Info'!B$6,CHAR(10),'Bundle Tag Info'!B$10),"") -> NOC-A #1 J0400 A.2 PWR SUPPLY XT-LWALL | C5: =IF('Bundle Tag Info'!C$10<>"",CONCATENATE('Bundle Tag Info'!$A$1," ",CHAR(10),'Bundle Tag Info'!$A$2," ",'Bundle Tag Info'!$A$3,CHAR(10),'Bundle Tag Info'!C$6,CHAR(10),'Bundle Tag Info'!C$10),"") -> NOC-A #1 J0400 A.2 PWR DST RAIL XT-LWALL | D5: =IF('Bundle Tag Info'!D$10<>"",CONCATENATE('Bundle Tag Info'!$A$1," ",CHAR(10),'Bundle Tag Info'!$A$2," ",'Bundle Tag Info'!$A$3,CHAR(10),'Bundle Tag Info'!D$6,CHAR(10),'Bundle Tag Info'!D$10),"") | E5: =IF('Bundle Tag Info'!E$10<>"",CONCATENATE('Bundle Tag Info'!$A$1," ",CHAR(10),'Bundle Tag Info'!$A$2," ",'Bundle Tag Info'!$A$3,CHAR(10),'Bundle Tag Info'!E$6,CHAR(10),'Bundle Tag Info'!E$10),"") -> NOC-A #1 J0400 A.2 LS WALL KA | F5: =IF('Bundle Tag Info'!F$10<>"",CONCATENATE('Bundle Tag Info'!$A$1," ",CHAR(10),'Bundle Tag Info'!$A$2," ",'Bundle Tag Info'!$A$3,CHAR(10),'Bundle Tag Info'!F$6,CHAR(10),'Bundle Tag Info'!F$10),"") -> NOC-A #1 J0400 A.2 L BACK KA RED | G5: =IF('Bundle Tag Info'!G$10<>"",CONCATENATE('Bundle Tag Info'!$A$1," ",CHAR(10),'Bundle Tag Info'!$A$2," ",'Bundle Tag Info'!$A$3,CHAR(10),'Bundle Tag Info'!G$6,CHAR(10),'Bundle Tag Info'!G$10),"") | H5: =IF('Bundle Tag Info'!H$10<>"",CONCATENATE('Bundle Tag Info'!$A$1," ",CHAR(10),'Bundle Tag Info'!$A$2," ",'Bundle Tag Info'!$A$3,CHAR(10),'Bundle Tag Info'!H$6,CHAR(10),'Bundle Tag Info'!H$10),"") -> NOC-A #1 J0400 A.2 RS WALL AF/AU0180s | ... AD5: =IF('Bundle Tag Info'!AD$10<>"",CONCATENATE('Bundle Tag Info'!$A$1," ",CHAR(10),'Bundle Tag Info'!$A$2," ",'Bundle Tag Info'!$A$3,CHAR(10),'Bundle Tag Info'!AD$6,CHAR(10),'Bundle Tag Info'!AD$10),"")
A6: =IF('Bundle Tag Info'!A$11<>"",CONCATENATE('Bundle Tag Info'!$A$1," ",CHAR(10),'Bundle Tag Info'!$A$2," ",'Bundle Tag Info'!$A$3,CHAR(10),'Bundle Tag Info'!A$6,CHAR(10),'Bundle Tag Info'!A$11),"") | B6: =IF('Bundle Tag Info'!B$11<>"",CONCATENATE('Bundle Tag Info'!$A$1," ",CHAR(10),'Bundle Tag Info'!$A$2," ",'Bundle Tag Info'!$A$3,CHAR(10),'Bundle Tag Info'!B$6,CHAR(10),'Bundle Tag Info'!B$11),"") | C6: =IF('Bundle Tag Info'!C$11<>"",CONCATENATE('Bundle Tag Info'!$A$1," ",CHAR(10),'Bundle Tag Info'!$A$2," ",'Bundle Tag Info'!$A$3,CHAR(10),'Bundle Tag Info'!C$6,CHAR(10),'Bundle Tag Info'!C$11),"") -> NOC-A #1 J0400 A.2 PWR DST RAIL FU/XT-RWALL | D6: =IF('Bundle Tag Info'!D$11<>"",CONCATENATE('Bundle Tag Info'!$A$1," ",CHAR(10),'Bundle Tag Info'!$A$2," ",'Bundle Tag Info'!$A$3,CHAR(10),'Bundle Tag Info'!D$6,CHAR(10),'Bundle Tag Info'!D$11),"") | E6: =IF('Bundle Tag Info'!E$11<>"",CONCATENATE('Bundle Tag Info'!$A$1," ",CHAR(10),'Bundle Tag Info'!$A$2," ",'Bundle Tag Info'!$A$3,CHAR(10),'Bundle Tag Info'!E$6,CHAR(10),'Bundle Tag Info'!E$11),"") -> NOC-A #1 J0400 A.2 LS WALL XT | F6: =IF('Bundle Tag Info'!F$11<>"",CONCATENATE('Bundle Tag Info'!$A$1," ",CHAR(10),'Bundle Tag Info'!$A$2," ",'Bundle Tag Info'!$A$3,CHAR(10),'Bundle Tag Info'!F$6,CHAR(10),'Bundle Tag Info'!F$11),"") -> NOC-A #1 J0400 A.2 L BACK KT L/S | G6: =IF('Bundle Tag Info'!G$11<>"",CONCATENATE('Bundle Tag Info'!$A$1," ",CHAR(10),'Bundle Tag Info'!$A$2," ",'Bundle Tag Info'!$A$3,CHAR(10),'Bundle Tag Info'!G$6,CHAR(10),'Bundle Tag Info'!G$11),"") | H6: =IF('Bundle Tag Info'!H$11<>"",CONCATENATE('Bundle Tag Info'!$A$1," ",CHAR(10),'Bundle Tag Info'!$A$2," ",'Bundle Tag Info'!$A$3,CHAR(10),'Bundle Tag Info'!H$6,CHAR(10),'Bundle Tag Info'!H$11),"") -> NOC-A #1 J0400 A.2 RS WALL AF/AU1200s | ... AD6: =IF('Bundle Tag Info'!AD$11<>"",CONCATENATE('Bundle Tag Info'!$A$1," ",CHAR(10),'Bundle Tag Info'!$A$2," ",'Bundle Tag Info'!$A$3,CHAR(10),'Bundle Tag Info'!AD$6,CHAR(10),'Bundle Tag Info'!AD$11),"")
A7: =IF('Bundle Tag Info'!A$12<>"",CONCATENATE('Bundle Tag Info'!$A$1," ",CHAR(10),'Bundle Tag Info'!$A$2," ",'Bundle Tag Info'!$A$3,CHAR(10),'Bundle Tag Info'!A$6,CHAR(10),'Bundle Tag Info'!A$12),"") | B7: =IF('Bundle Tag Info'!B$12<>"",CONCATENATE('Bundle Tag Info'!$A$1," ",CHAR(10),'Bundle Tag Info'!$A$2," ",'Bundle Tag Info'!$A$3,CHAR(10),'Bundle Tag Info'!B$6,CHAR(10),'Bundle Tag Info'!B$12),"") | C7: =IF('Bundle Tag Info'!C$12<>"",CONCATENATE('Bundle Tag Info'!$A$1," ",CHAR(10),'Bundle Tag Info'!$A$2," ",'Bundle Tag Info'!$A$3,CHAR(10),'Bundle Tag Info'!C$6,CHAR(10),'Bundle Tag Info'!C$12),"") | D7: =IF('Bundle Tag Info'!D$12<>"",CONCATENATE('Bundle Tag Info'!$A$1," ",CHAR(10),'Bundle Tag Info'!$A$2," ",'Bundle Tag Info'!$A$3,CHAR(10),'Bundle Tag Info'!D$6,CHAR(10),'Bundle Tag Info'!D$12),"") | E7: =IF('Bundle Tag Info'!E$12<>"",CONCATENATE('Bundle Tag Info'!$A$1," ",CHAR(10),'Bundle Tag Info'!$A$2," ",'Bundle Tag Info'!$A$3,CHAR(10),'Bundle Tag Info'!E$6,CHAR(10),'Bundle Tag Info'!E$12),"") -> NOC-A #1 J0400 A.2 LS WALL FU/XT-ISO | F7: =IF('Bundle Tag Info'!F$12<>"",CONCATENATE('Bundle Tag Info'!$A$1," ",CHAR(10),'Bundle Tag Info'!$A$2," ",'Bundle Tag Info'!$A$3,CHAR(10),'Bundle Tag Info'!F$6,CHAR(10),'Bundle Tag Info'!F$12),"") -> NOC-A #1 J0400 A.2 L BACK KT R/S | G7: =IF('Bundle Tag Info'!G$12<>"",CONCATENATE('Bundle Tag Info'!$A$1," ",CHAR(10),'Bundle Tag Info'!$A$2," ",'Bundle Tag Info'!$A$3,CHAR(10),'Bundle Tag Info'!G$6,CHAR(10),'Bundle Tag Info'!G$12),"") | H7: =IF('Bundle Tag Info'!H$12<>"",CONCATENATE('Bundle Tag Info'!$A$1," ",CHAR(10),'Bundle Tag Info'!$A$2," ",'Bundle Tag Info'!$A$3,CHAR(10),'Bundle Tag Info'!H$6,CHAR(10),'Bundle Tag Info'!H$12),"") -> NOC-A #1 J0400 A.2 RS WALL XT | ... AD7: =IF('Bundle Tag Info'!AD$12<>"",CONCATENATE('Bundle Tag Info'!$A$1," ",CHAR(10),'Bundle Tag Info'!$A$2," ",'Bundle Tag Info'!$A$3,CHAR(10),'Bundle Tag Info'!AD$6,CHAR(10),'Bundle Tag Info'!AD$12),"")
A8: =IF('Bundle Tag Info'!A$13<>"",CONCATENATE('Bundle Tag Info'!$A$1," ",CHAR(10),'Bundle Tag Info'!$A$2," ",'Bundle Tag Info'!$A$3,CHAR(10),'Bundle Tag Info'!A$6,CHAR(10),'Bundle Tag Info'!A$13),"") | B8: =IF('Bundle Tag Info'!B$13<>"",CONCATENATE('Bundle Tag Info'!$A$1," ",CHAR(10),'Bundle Tag Info'!$A$2," ",'Bundle Tag Info'!$A$3,CHAR(10),'Bundle Tag Info'!B$6,CHAR(10),'Bundle Tag Info'!B$13),"") | C8: =IF('Bundle Tag Info'!C$13<>"",CONCATENATE('Bundle Tag Info'!$A$1," ",CHAR(10),'Bundle Tag Info'!$A$2," ",'Bundle Tag Info'!$A$3,CHAR(10),'Bundle Tag Info'!C$6,CHAR(10),'Bundle Tag Info'!C$13),"") | D8: =IF('Bundle Tag Info'!D$13<>"",CONCATENATE('Bundle Tag Info'!$A$1," ",CHAR(10),'Bundle Tag Info'!$A$2," ",'Bundle Tag Info'!$A$3,CHAR(10),'Bundle Tag Info'!D$6,CHAR(10),'Bundle Tag Info'!D$13),"") | E8: =IF('Bundle Tag Info'!E$13<>"",CONCATENATE('Bundle Tag Info'!$A$1," ",CHAR(10),'Bundle Tag Info'!$A$2," ",'Bundle Tag Info'!$A$3,CHAR(10),'Bundle Tag Info'!E$6,CHAR(10),'Bundle Tag Info'!E$13),"") -> NOC-A #1 J0400 A.2 LS WALL FU-LBACK | F8: =IF('Bundle Tag Info'!F$13<>"",CONCATENATE('Bundle Tag Info'!$A$1," ",CHAR(10),'Bundle Tag Info'!$A$2," ",'Bundle Tag Info'!$A$3,CHAR(10),'Bundle Tag Info'!F$6,CHAR(10),'Bundle Tag Info'!F$13),"") -> NOC-A #1 J0400 A.2 L BACK AF-ISO | G8: =IF('Bundle Tag Info'!G$13<>"",CONCATENATE('Bundle Tag Info'!$A$1," ",CHAR(10),'Bundle Tag Info'!$A$2," ",'Bundle Tag Info'!$A$3,CHAR(10),'Bundle Tag Info'!G$6,CHAR(10),'Bundle Tag Info'!G$13),"") | H8: =IF('Bundle Tag Info'!H$13<>"",CONCATENATE('Bundle Tag Info'!$A$1," ",CHAR(10),'Bundle Tag Info'!$A$2," ",'Bundle Tag Info'!$A$3,CHAR(10),'Bundle Tag Info'!H$6,CHAR(10),'Bundle Tag Info'!H$13),"") | ... AD8: =IF('Bundle Tag Info'!AD$13<>"",CONCATENATE('Bundle Tag Info'!$A$1," ",CHAR(10),'Bundle Tag Info'!$A$2," ",'Bundle Tag Info'!$A$3,CHAR(10),'Bundle Tag Info'!AD$6,CHAR(10),'Bundle Tag Info'!AD$13),"")
A9: =IF('Bundle Tag Info'!A$14<>"",CONCATENATE('Bundle Tag Info'!$A$1," ",CHAR(10),'Bundle Tag Info'!$A$2," ",'Bundle Tag Info'!$A$3,CHAR(10),'Bundle Tag Info'!A$6,CHAR(10),'Bundle Tag Info'!A$14),"") | B9: =IF('Bundle Tag Info'!B$14<>"",CONCATENATE('Bundle Tag Info'!$A$1," ",CHAR(10),'Bundle Tag Info'!$A$2," ",'Bundle Tag Info'!$A$3,CHAR(10),'Bundle Tag Info'!B$6,CHAR(10),'Bundle Tag Info'!B$14),"") | C9: =IF('Bundle Tag Info'!C$14<>"",CONCATENATE('Bundle Tag Info'!$A$1," ",CHAR(10),'Bundle Tag Info'!$A$2," ",'Bundle Tag Info'!$A$3,CHAR(10),'Bundle Tag Info'!C$6,CHAR(10),'Bundle Tag Info'!C$14),"") | D9: =IF('Bundle Tag Info'!D$14<>"",CONCATENATE('Bundle Tag Info'!$A$1," ",CHAR(10),'Bundle Tag Info'!$A$2," ",'Bundle Tag Info'!$A$3,CHAR(10),'Bundle Tag Info'!D$6,CHAR(10),'Bundle Tag Info'!D$14),"") | E9: =IF('Bundle Tag Info'!E$14<>"",CONCATENATE('Bundle Tag Info'!$A$1," ",CHAR(10),'Bundle Tag Info'!$A$2," ",'Bundle Tag Info'!$A$3,CHAR(10),'Bundle Tag Info'!E$6,CHAR(10),'Bundle Tag Info'!E$14),"") -> NOC-A #1 J0400 A.2 LS WALL KA A1/A2-LBACK | F9: =IF('Bundle Tag Info'!F$14<>"",CONCATENATE('Bundle Tag Info'!$A$1," ",CHAR(10),'Bundle Tag Info'!$A$2," ",'Bundle Tag Info'!$A$3,CHAR(10),'Bundle Tag Info'!F$6,CHAR(10),'Bundle Tag Info'!F$14),"") -> NOC-A #1 J0400 A.2 L BACK KT L/S-RWALL | G9: =IF('Bundle Tag Info'!G$14<>"",CONCATENATE('Bundle Tag Info'!$A$1," ",CHAR(10),'Bundle Tag Info'!$A$2," ",'Bundle Tag Info'!$A$3,CHAR(10),'Bundle Tag Info'!G$6,CHAR(10),'Bundle Tag Info'!G$14),"") | H9: =IF('Bundle Tag Info'!H$14<>"",CONCATENATE('Bundle Tag Info'!$A$1," ",CHAR(10),'Bundle Tag Info'!$A$2," ",'Bundle Tag Info'!$A$3,CHAR(10),'Bundle Tag Info'!H$6,CHAR(10),'Bundle Tag Info'!H$14),"") | ... AD9: =IF('Bundle Tag Info'!AD$14<>"",CONCATENATE('Bundle Tag Info'!$A$1," ",CHAR(10),'Bundle Tag Info'!$A$2," ",'Bundle Tag Info'!$A$3,CHAR(10),'Bundle Tag Info'!AD$6,CHAR(10),'Bundle Tag Info'!AD$14),"")
A10: =IF('Bundle Tag Info'!A$15<>"",CONCATENATE('Bundle Tag Info'!$A$1," ",CHAR(10),'Bundle Tag Info'!$A$2," ",'Bundle Tag Info'!$A$3,CHAR(10),'Bundle Tag Info'!A$6,CHAR(10),'Bundle Tag Info'!A$15),"") | B10: =IF('Bundle Tag Info'!B$15<>"",CONCATENATE('Bundle Tag Info'!$A$1," ",CHAR(10),'Bundle Tag Info'!$A$2," ",'Bundle Tag Info'!$A$3,CHAR(10),'Bundle Tag Info'!B$6,CHAR(10),'Bundle Tag Info'!B$15),"") | C10: =IF('Bundle Tag Info'!C$15<>"",CONCATENATE('Bundle Tag Info'!$A$1," ",CHAR(10),'Bundle Tag Info'!$A$2," ",'Bundle Tag Info'!$A$3,CHAR(10),'Bundle Tag Info'!C$6,CHAR(10),'Bundle Tag Info'!C$15),"") | D10: =IF('Bundle Tag Info'!D$15<>"",CONCATENATE('Bundle Tag Info'!$A$1," ",CHAR(10),'Bundle Tag Info'!$A$2," ",'Bundle Tag Info'!$A$3,CHAR(10),'Bundle Tag Info'!D$6,CHAR(10),'Bundle Tag Info'!D$15),"") | E10: =IF('Bundle Tag Info'!E$15<>"",CONCATENATE('Bundle Tag Info'!$A$1," ",CHAR(10),'Bundle Tag Info'!$A$2," ",'Bundle Tag Info'!$A$3,CHAR(10),'Bundle Tag Info'!E$6,CHAR(10),'Bundle Tag Info'!E$15),"") -> NOC-A #1 J0400 A.2 LS WALL KA-LBACK | F10: =IF('Bundle Tag Info'!F$15<>"",CONCATENATE('Bundle Tag Info'!$A$1," ",CHAR(10),'Bundle Tag Info'!$A$2," ",'Bundle Tag Info'!$A$3,CHAR(10),'Bundle Tag Info'!F$6,CHAR(10),'Bundle Tag Info'!F$15),"") -> NOC-A #1 J0400 A.2 L BACK KT R/S-RWALL | G10: =IF('Bundle Tag Info'!G$15<>"",CONCATENATE('Bundle Tag Info'!$A$1," ",CHAR(10),'Bundle Tag Info'!$A$2," ",'Bundle Tag Info'!$A$3,CHAR(10),'Bundle Tag Info'!G$6,CHAR(10),'Bundle Tag Info'!G$15),"") | H10: =IF('Bundle Tag Info'!H$15<>"",CONCATENATE('Bundle Tag Info'!$A$1," ",CHAR(10),'Bundle Tag Info'!$A$2," ",'Bundle Tag Info'!$A$3,CHAR(10),'Bundle Tag Info'!H$6,CHAR(10),'Bundle Tag Info'!H$15),"") | ... AD10: =IF('Bundle Tag Info'!AD$15<>"",CONCATENATE('Bundle Tag Info'!$A$1," ",CHAR(10),'Bundle Tag Info'!$A$2," ",'Bundle Tag Info'!$A$3,CHAR(10),'Bundle Tag Info'!AD$6,CHAR(10),'Bundle Tag Info'!AD$15),"")
A11: =IF('Bundle Tag Info'!A$16<>"",CONCATENATE('Bundle Tag Info'!$A$1," ",CHAR(10),'Bundle Tag Info'!$A$2," ",'Bundle Tag Info'!$A$3,CHAR(10),'Bundle Tag Info'!A$6,CHAR(10),'Bundle Tag Info'!A$16),"") | B11: =IF('Bundle Tag Info'!B$16<>"",CONCATENATE('Bundle Tag Info'!$A$1," ",CHAR(10),'Bundle Tag Info'!$A$2," ",'Bundle Tag Info'!$A$3,CHAR(10),'Bundle Tag Info'!B$6,CHAR(10),'Bundle Tag Info'!B$16),"") | C11: =IF('Bundle Tag Info'!C$16<>"",CONCATENATE('Bundle Tag Info'!$A$1," ",CHAR(10),'Bundle Tag Info'!$A$2," ",'Bundle Tag Info'!$A$3,CHAR(10),'Bundle Tag Info'!C$6,CHAR(10),'Bundle Tag Info'!C$16),"") | D11: =IF('Bundle Tag Info'!D$16<>"",CONCATENATE('Bundle Tag Info'!$A$1," ",CHAR(10),'Bundle Tag Info'!$A$2," ",'Bundle Tag Info'!$A$3,CHAR(10),'Bundle Tag Info'!D$6,CHAR(10),'Bundle Tag Info'!D$16),"") | E11: =IF('Bundle Tag Info'!E$16<>"",CONCATENATE('Bundle Tag Info'!$A$1," ",CHAR(10),'Bundle Tag Info'!$A$2," ",'Bundle Tag Info'!$A$3,CHAR(10),'Bundle Tag Info'!E$6,CHAR(10),'Bundle Tag Info'!E$16),"") -> NOC-A #1 J0400 A.2 LS WALL XT-LBACK | F11: =IF('Bundle Tag Info'!F$16<>"",CONCATENATE('Bundle Tag Info'!$A$1," ",CHAR(10),'Bundle Tag Info'!$A$2," ",'Bundle Tag Info'!$A$3,CHAR(10),'Bundle Tag Info'!F$6,CHAR(10),'Bundle Tag Info'!F$16),"") -> NOC-A #1 J0400 A.2 L BACK AF/XT-RWALL | G11: =IF('Bundle Tag Info'!G$16<>"",CONCATENATE('Bundle Tag Info'!$A$1," ",CHAR(10),'Bundle Tag Info'!$A$2," ",'Bundle Tag Info'!$A$3,CHAR(10),'Bundle Tag Info'!G$6,CHAR(10),'Bundle Tag Info'!G$16),"") | H11: =IF('Bundle Tag Info'!H$16<>"",CONCATENATE('Bundle Tag Info'!$A$1," ",CHAR(10),'Bundle Tag Info'!$A$2," ",'Bundle Tag Info'!$A$3,CHAR(10),'Bundle Tag Info'!H$6,CHAR(10),'Bundle Tag Info'!H$16),"") | ... AD11: =IF('Bundle Tag Info'!AD$16<>"",CONCATENATE('Bundle Tag Info'!$A$1," ",CHAR(10),'Bundle Tag Info'!$A$2," ",'Bundle Tag Info'!$A$3,CHAR(10),'Bundle Tag Info'!AD$6,CHAR(10),'Bundle Tag Info'!AD$16),"")
A12: =IF('Bundle Tag Info'!A$17<>"",CONCATENATE('Bundle Tag Info'!$A$1," ",CHAR(10),'Bundle Tag Info'!$A$2," ",'Bundle Tag Info'!$A$3,CHAR(10),'Bundle Tag Info'!A$6,CHAR(10),'Bundle Tag Info'!A$17),"") | B12: =IF('Bundle Tag Info'!B$17<>"",CONCATENATE('Bundle Tag Info'!$A$1," ",CHAR(10),'Bundle Tag Info'!$A$2," ",'Bundle Tag Info'!$A$3,CHAR(10),'Bundle Tag Info'!B$6,CHAR(10),'Bundle Tag Info'!B$17),"") | C12: =IF('Bundle Tag Info'!C$17<>"",CONCATENATE('Bundle Tag Info'!$A$1," ",CHAR(10),'Bundle Tag Info'!$A$2," ",'Bundle Tag Info'!$A$3,CHAR(10),'Bundle Tag Info'!C$6,CHAR(10),'Bundle Tag Info'!C$17),"") | D12: =IF('Bundle Tag Info'!D$17<>"",CONCATENATE('Bundle Tag Info'!$A$1," ",CHAR(10),'Bundle Tag Info'!$A$2," ",'Bundle Tag Info'!$A$3,CHAR(10),'Bundle Tag Info'!D$6,CHAR(10),'Bundle Tag Info'!D$17),"") | E12: =IF('Bundle Tag Info'!E$17<>"",CONCATENATE('Bundle Tag Info'!$A$1," ",CHAR(10),'Bundle Tag Info'!$A$2," ",'Bundle Tag Info'!$A$3,CHAR(10),'Bundle Tag Info'!E$6,CHAR(10),'Bundle Tag Info'!E$17),"") -> NOC-A #1 J0400 A.2 LS WALL XT9K-LBACK | F12: =IF('Bundle Tag Info'!F$17<>"",CONCATENATE('Bundle Tag Info'!$A$1," ",CHAR(10),'Bundle Tag Info'!$A$2," ",'Bundle Tag Info'!$A$3,CHAR(10),'Bundle Tag Info'!F$6,CHAR(10),'Bundle Tag Info'!F$17),"") | G12: =IF('Bundle Tag Info'!G$17<>"",CONCATENATE('Bundle Tag Info'!$A$1," ",CHAR(10),'Bundle Tag Info'!$A$2," ",'Bundle Tag Info'!$A$3,CHAR(10),'Bundle Tag Info'!G$6,CHAR(10),'Bundle Tag Info'!G$17),"") | H12: =IF('Bundle Tag Info'!H$17<>"",CONCATENATE('Bundle Tag Info'!$A$1," ",CHAR(10),'Bundle Tag Info'!$A$2," ",'Bundle Tag Info'!$A$3,CHAR(10),'Bundle Tag Info'!H$6,CHAR(10),'Bundle Tag Info'!H$17),"") | ... AD12: =IF('Bundle Tag Info'!AD$17<>"",CONCATENATE('Bundle Tag Info'!$A$1," ",CHAR(10),'Bundle Tag Info'!$A$2," ",'Bundle Tag Info'!$A$3,CHAR(10),'Bundle Tag Info'!AD$6,CHAR(10),'Bundle Tag Info'!AD$17),"")
A13: =IF('Bundle Tag Info'!A$18<>"",CONCATENATE('Bundle Tag Info'!$A$1," ",CHAR(10),'Bundle Tag Info'!$A$2," ",'Bundle Tag Info'!$A$3,CHAR(10),'Bundle Tag Info'!A$6,CHAR(10),'Bundle Tag Info'!A$18),"") | B13: =IF('Bundle Tag Info'!B$18<>"",CONCATENATE('Bundle Tag Info'!$A$1," ",CHAR(10),'Bundle Tag Info'!$A$2," ",'Bundle Tag Info'!$A$3,CHAR(10),'Bundle Tag Info'!B$6,CHAR(10),'Bundle Tag Info'!B$18),"") | C13: =IF('Bundle Tag Info'!C$18<>"",CONCATENATE('Bundle Tag Info'!$A$1," ",CHAR(10),'Bundle Tag Info'!$A$2," ",'Bundle Tag Info'!$A$3,CHAR(10),'Bundle Tag Info'!C$6,CHAR(10),'Bundle Tag Info'!C$18),"") | D13: =IF('Bundle Tag Info'!D$18<>"",CONCATENATE('Bundle Tag Info'!$A$1," ",CHAR(10),'Bundle Tag Info'!$A$2," ",'Bundle Tag Info'!$A$3,CHAR(10),'Bundle Tag Info'!D$6,CHAR(10),'Bundle Tag Info'!D$18),"") | E13: =IF('Bundle Tag Info'!E$18<>"",CONCATENATE('Bundle Tag Info'!$A$1," ",CHAR(10),'Bundle Tag Info'!$A$2," ",'Bundle Tag Info'!$A$3,CHAR(10),'Bundle Tag Info'!E$6,CHAR(10),'Bundle Tag Info'!E$18),"") -> NOC-A #1 J0400 A.2 LS WALL FU-RWALL | F13: =IF('Bundle Tag Info'!F$18<>"",CONCATENATE('Bundle Tag Info'!$A$1," ",CHAR(10),'Bundle Tag Info'!$A$2," ",'Bundle Tag Info'!$A$3,CHAR(10),'Bundle Tag Info'!F$6,CHAR(10),'Bundle Tag Info'!F$18),"") | G13: =IF('Bundle Tag Info'!G$18<>"",CONCATENATE('Bundle Tag Info'!$A$1," ",CHAR(10),'Bundle Tag Info'!$A$2," ",'Bundle Tag Info'!$A$3,CHAR(10),'Bundle Tag Info'!G$6,CHAR(10),'Bundle Tag Info'!G$18),"") | H13: =IF('Bundle Tag Info'!H$18<>"",CONCATENATE('Bundle Tag Info'!$A$1," ",CHAR(10),'Bundle Tag Info'!$A$2," ",'Bundle Tag Info'!$A$3,CHAR(10),'Bundle Tag Info'!H$6,CHAR(10),'Bundle Tag Info'!H$18),"") | ... AD13: =IF('Bundle Tag Info'!AD$18<>"",CONCATENATE('Bundle Tag Info'!$A$1," ",CHAR(10),'Bundle Tag Info'!$A$2," ",'Bundle Tag Info'!$A$3,CHAR(10),'Bundle Tag Info'!AD$6,CHAR(10),'Bundle Tag Info'!AD$18),"")
A14: =IF('Bundle Tag Info'!A$19<>"",CONCATENATE('Bundle Tag Info'!$A$1," ",CHAR(10),'Bundle Tag Info'!$A$2," ",'Bundle Tag Info'!$A$3,CHAR(10),'Bundle Tag Info'!A$6,CHAR(10),'Bundle Tag Info'!A$19),"") | B14: =IF('Bundle Tag Info'!B$19<>"",CONCATENATE('Bundle Tag Info'!$A$1," ",CHAR(10),'Bundle Tag Info'!$A$2," ",'Bundle Tag Info'!$A$3,CHAR(10),'Bundle Tag Info'!B$6,CHAR(10),'Bundle Tag Info'!B$19),"") | C14: =IF('Bundle Tag Info'!C$19<>"",CONCATENATE('Bundle Tag Info'!$A$1," ",CHAR(10),'Bundle Tag Info'!$A$2," ",'Bundle Tag Info'!$A$3,CHAR(10),'Bundle Tag Info'!C$6,CHAR(10),'Bundle Tag Info'!C$19),"") | D14: =IF('Bundle Tag Info'!D$19<>"",CONCATENATE('Bundle Tag Info'!$A$1," ",CHAR(10),'Bundle Tag Info'!$A$2," ",'Bundle Tag Info'!$A$3,CHAR(10),'Bundle Tag Info'!D$6,CHAR(10),'Bundle Tag Info'!D$19),"") | E14: =IF('Bundle Tag Info'!E$19<>"",CONCATENATE('Bundle Tag Info'!$A$1," ",CHAR(10),'Bundle Tag Info'!$A$2," ",'Bundle Tag Info'!$A$3,CHAR(10),'Bundle Tag Info'!E$6,CHAR(10),'Bundle Tag Info'!E$19),"") -> NOC-A #1 J0400 A.2 LS WALL KA A1-RWALL | F14: =IF('Bundle Tag Info'!F$19<>"",CONCATENATE('Bundle Tag Info'!$A$1," ",CHAR(10),'Bundle Tag Info'!$A$2," ",'Bundle Tag Info'!$A$3,CHAR(10),'Bundle Tag Info'!F$6,CHAR(10),'Bundle Tag Info'!F$19),"") | G14: =IF('Bundle Tag Info'!G$19<>"",CONCATENATE('Bundle Tag Info'!$A$1," ",CHAR(10),'Bundle Tag Info'!$A$2," ",'Bundle Tag Info'!$A$3,CHAR(10),'Bundle Tag Info'!G$6,CHAR(10),'Bundle Tag Info'!G$19),"") | H14: =IF('Bundle Tag Info'!H$19<>"",CONCATENATE('Bundle Tag Info'!$A$1," ",CHAR(10),'Bundle Tag Info'!$A$2," ",'Bundle Tag Info'!$A$3,CHAR(10),'Bundle Tag Info'!H$6,CHAR(10),'Bundle Tag Info'!H$19),"") | ... AD14: =IF('Bundle Tag Info'!AD$19<>"",CONCATENATE('Bundle Tag Info'!$A$1," ",CHAR(10),'Bundle Tag Info'!$A$2," ",'Bundle Tag Info'!$A$3,CHAR(10),'Bundle Tag Info'!AD$6,CHAR(10),'Bundle Tag Info'!AD$19),"")
A15: =IF('Bundle Tag Info'!A$20<>"",CONCATENATE('Bundle Tag Info'!$A$1," ",CHAR(10),'Bundle Tag Info'!$A$2," ",'Bundle Tag Info'!$A$3,CHAR(10),'Bundle Tag Info'!A$6,CHAR(10),'Bundle Tag Info'!A$20),"") | B15: =IF('Bundle Tag Info'!B$20<>"",CONCATENATE('Bundle Tag Info'!$A$1," ",CHAR(10),'Bundle Tag Info'!$A$2," ",'Bundle Tag Info'!$A$3,CHAR(10),'Bundle Tag Info'!B$6,CHAR(10),'Bundle Tag Info'!B$20),"") | C15: =IF('Bundle Tag Info'!C$20<>"",CONCATENATE('Bundle Tag Info'!$A$1," ",CHAR(10),'Bundle Tag Info'!$A$2," ",'Bundle Tag Info'!$A$3,CHAR(10),'Bundle Tag Info'!C$6,CHAR(10),'Bundle Tag Info'!C$20),"") | D15: =IF('Bundle Tag Info'!D$20<>"",CONCATENATE('Bundle Tag Info'!$A$1," ",CHAR(10),'Bundle Tag Info'!$A$2," ",'Bundle Tag Info'!$A$3,CHAR(10),'Bundle Tag Info'!D$6,CHAR(10),'Bundle Tag Info'!D$20),"") | E15: =IF('Bundle Tag Info'!E$20<>"",CONCATENATE('Bundle Tag Info'!$A$1," ",CHAR(10),'Bundle Tag Info'!$A$2," ",'Bundle Tag Info'!$A$3,CHAR(10),'Bundle Tag Info'!E$6,CHAR(10),'Bundle Tag Info'!E$20),"") -> NOC-A #1 J0400 A.2 LS WALL KA A2-RWALL | F15: =IF('Bundle Tag Info'!F$20<>"",CONCATENATE('Bundle Tag Info'!$A$1," ",CHAR(10),'Bundle Tag Info'!$A$2," ",'Bundle Tag Info'!$A$3,CHAR(10),'Bundle Tag Info'!F$6,CHAR(10),'Bundle Tag Info'!F$20),"") | G15: =IF('Bundle Tag Info'!G$20<>"",CONCATENATE('Bundle Tag Info'!$A$1," ",CHAR(10),'Bundle Tag Info'!$A$2," ",'Bundle Tag Info'!$A$3,CHAR(10),'Bundle Tag Info'!G$6,CHAR(10),'Bundle Tag Info'!G$20),"") | H15: =IF('Bundle Tag Info'!H$20<>"",CONCATENATE('Bundle Tag Info'!$A$1," ",CHAR(10),'Bundle Tag Info'!$A$2," ",'Bundle Tag Info'!$A$3,CHAR(10),'Bundle Tag Info'!H$6,CHAR(10),'Bundle Tag Info'!H$20),"") | ... AD15: =IF('Bundle Tag Info'!AD$20<>"",CONCATENATE('Bundle Tag Info'!$A$1," ",CHAR(10),'Bundle Tag Info'!$A$2," ",'Bundle Tag Info'!$A$3,CHAR(10),'Bundle Tag Info'!AD$6,CHAR(10),'Bundle Tag Info'!AD$20),"")
A16: =IF('Bundle Tag Info'!A$21<>"",CONCATENATE('Bundle Tag Info'!$A$1," ",CHAR(10),'Bundle Tag Info'!$A$2," ",'Bundle Tag Info'!$A$3,CHAR(10),'Bundle Tag Info'!A$6,CHAR(10),'Bundle Tag Info'!A$21),"") | B16: =IF('Bundle Tag Info'!B$21<>"",CONCATENATE('Bundle Tag Info'!$A$1," ",CHAR(10),'Bundle Tag Info'!$A$2," ",'Bundle Tag Info'!$A$3,CHAR(10),'Bundle Tag Info'!B$6,CHAR(10),'Bundle Tag Info'!B$21),"") | C16: =IF('Bundle Tag Info'!C$21<>"",CONCATENATE('Bundle Tag Info'!$A$1," ",CHAR(10),'Bundle Tag Info'!$A$2," ",'Bundle Tag Info'!$A$3,CHAR(10),'Bundle Tag Info'!C$6,CHAR(10),'Bundle Tag Info'!C$21),"") | D16: =IF('Bundle Tag Info'!D$21<>"",CONCATENATE('Bundle Tag Info'!$A$1," ",CHAR(10),'Bundle Tag Info'!$A$2," ",'Bundle Tag Info'!$A$3,CHAR(10),'Bundle Tag Info'!D$6,CHAR(10),'Bundle Tag Info'!D$21),"") | E16: =IF('Bundle Tag Info'!E$21<>"",CONCATENATE('Bundle Tag Info'!$A$1," ",CHAR(10),'Bundle Tag Info'!$A$2," ",'Bundle Tag Info'!$A$3,CHAR(10),'Bundle Tag Info'!E$6,CHAR(10),'Bundle Tag Info'!E$21),"") -> NOC-A #1 J0400 A.2 LS WALL KA-RWALL | F16: =IF('Bundle Tag Info'!F$21<>"",CONCATENATE('Bundle Tag Info'!$A$1," ",CHAR(10),'Bundle Tag Info'!$A$2," ",'Bundle Tag Info'!$A$3,CHAR(10),'Bundle Tag Info'!F$6,CHAR(10),'Bundle Tag Info'!F$21),"") | G16: =IF('Bundle Tag Info'!G$21<>"",CONCATENATE('Bundle Tag Info'!$A$1," ",CHAR(10),'Bundle Tag Info'!$A$2," ",'Bundle Tag Info'!$A$3,CHAR(10),'Bundle Tag Info'!G$6,CHAR(10),'Bundle Tag Info'!G$21),"") | H16: =IF('Bundle Tag Info'!H$21<>"",CONCATENATE('Bundle Tag Info'!$A$1," ",CHAR(10),'Bundle Tag Info'!$A$2," ",'Bundle Tag Info'!$A$3,CHAR(10),'Bundle Tag Info'!H$6,CHAR(10),'Bundle Tag Info'!H$21),"") | ... AD16: =IF('Bundle Tag Info'!AD$21<>"",CONCATENATE('Bundle Tag Info'!$A$1," ",CHAR(10),'Bundle Tag Info'!$A$2," ",'Bundle Tag Info'!$A$3,CHAR(10),'Bundle Tag Info'!AD$6,CHAR(10),'Bundle Tag Info'!AD$21),"")
A17: =IF('Bundle Tag Info'!A$22<>"",CONCATENATE('Bundle Tag Info'!$A$1," ",CHAR(10),'Bundle Tag Info'!$A$2," ",'Bundle Tag Info'!$A$3,CHAR(10),'Bundle Tag Info'!A$6,CHAR(10),'Bundle Tag Info'!A$22),"") | B17: =IF('Bundle Tag Info'!B$22<>"",CONCATENATE('Bundle Tag Info'!$A$1," ",CHAR(10),'Bundle Tag Info'!$A$2," ",'Bundle Tag Info'!$A$3,CHAR(10),'Bundle Tag Info'!B$6,CHAR(10),'Bundle Tag Info'!B$22),"") | C17: =IF('Bundle Tag Info'!C$22<>"",CONCATENATE('Bundle Tag Info'!$A$1," ",CHAR(10),'Bundle Tag Info'!$A$2," ",'Bundle Tag Info'!$A$3,CHAR(10),'Bundle Tag Info'!C$6,CHAR(10),'Bundle Tag Info'!C$22),"") | D17: =IF('Bundle Tag Info'!D$22<>"",CONCATENATE('Bundle Tag Info'!$A$1," ",CHAR(10),'Bundle Tag Info'!$A$2," ",'Bundle Tag Info'!$A$3,CHAR(10),'Bundle Tag Info'!D$6,CHAR(10),'Bundle Tag Info'!D$22),"") | E17: =IF('Bundle Tag Info'!E$22<>"",CONCATENATE('Bundle Tag Info'!$A$1," ",CHAR(10),'Bundle Tag Info'!$A$2," ",'Bundle Tag Info'!$A$3,CHAR(10),'Bundle Tag Info'!E$6,CHAR(10),'Bundle Tag Info'!E$22),"") -> NOC-A #1 J0400 A.2 LS WALL XT-RWALL | F17: =IF('Bundle Tag Info'!F$22<>"",CONCATENATE('Bundle Tag Info'!$A$1," ",CHAR(10),'Bundle Tag Info'!$A$2," ",'Bundle Tag Info'!$A$3,CHAR(10),'Bundle Tag Info'!F$6,CHAR(10),'Bundle Tag Info'!F$22),"") | G17: =IF('Bundle Tag Info'!G$22<>"",CONCATENATE('Bundle Tag Info'!$A$1," ",CHAR(10),'Bundle Tag Info'!$A$2," ",'Bundle Tag Info'!$A$3,CHAR(10),'Bundle Tag Info'!G$6,CHAR(10),'Bundle Tag Info'!G$22),"") | H17: =IF('Bundle Tag Info'!H$22<>"",CONCATENATE('Bundle Tag Info'!$A$1," ",CHAR(10),'Bundle Tag Info'!$A$2," ",'Bundle Tag Info'!$A$3,CHAR(10),'Bundle Tag Info'!H$6,CHAR(10),'Bundle Tag Info'!H$22),"") | ... AD17: =IF('Bundle Tag Info'!AD$22<>"",CONCATENATE('Bundle Tag Info'!$A$1," ",CHAR(10),'Bundle Tag Info'!$A$2," ",'Bundle Tag Info'!$A$3,CHAR(10),'Bundle Tag Info'!AD$6,CHAR(10),'Bundle Tag Info'!AD$22),"")
A18: =IF('Bundle Tag Info'!A$23<>"",CONCATENATE('Bundle Tag Info'!$A$1," ",CHAR(10),'Bundle Tag Info'!$A$2," ",'Bundle Tag Info'!$A$3,CHAR(10),'Bundle Tag Info'!A$6,CHAR(10),'Bundle Tag Info'!A$23),"") | B18: =IF('Bundle Tag Info'!B$23<>"",CONCATENATE('Bundle Tag Info'!$A$1," ",CHAR(10),'Bundle Tag Info'!$A$2," ",'Bundle Tag Info'!$A$3,CHAR(10),'Bundle Tag Info'!B$6,CHAR(10),'Bundle Tag Info'!B$23),"") | C18: =IF('Bundle Tag Info'!C$23<>"",CONCATENATE('Bundle Tag Info'!$A$1," ",CHAR(10),'Bundle Tag Info'!$A$2," ",'Bundle Tag Info'!$A$3,CHAR(10),'Bundle Tag Info'!C$6,CHAR(10),'Bundle Tag Info'!C$23),"") | D18: =IF('Bundle Tag Info'!D$23<>"",CONCATENATE('Bundle Tag Info'!$A$1," ",CHAR(10),'Bundle Tag Info'!$A$2," ",'Bundle Tag Info'!$A$3,CHAR(10),'Bundle Tag Info'!D$6,CHAR(10),'Bundle Tag Info'!D$23),"") | E18: =IF('Bundle Tag Info'!E$23<>"",CONCATENATE('Bundle Tag Info'!$A$1," ",CHAR(10),'Bundle Tag Info'!$A$2," ",'Bundle Tag Info'!$A$3,CHAR(10),'Bundle Tag Info'!E$6,CHAR(10),'Bundle Tag Info'!E$23),"") -> NOC-A #1 J0400 A.2 LS WALL XT9K-RWALL | F18: =IF('Bundle Tag Info'!F$23<>"",CONCATENATE('Bundle Tag Info'!$A$1," ",CHAR(10),'Bundle Tag Info'!$A$2," ",'Bundle Tag Info'!$A$3,CHAR(10),'Bundle Tag Info'!F$6,CHAR(10),'Bundle Tag Info'!F$23),"") | G18: =IF('Bundle Tag Info'!G$23<>"",CONCATENATE('Bundle Tag Info'!$A$1," ",CHAR(10),'Bundle Tag Info'!$A$2," ",'Bundle Tag Info'!$A$3,CHAR(10),'Bundle Tag Info'!G$6,CHAR(10),'Bundle Tag Info'!G$23),"") | H18: =IF('Bundle Tag Info'!H$23<>"",CONCATENATE('Bundle Tag Info'!$A$1," ",CHAR(10),'Bundle Tag Info'!$A$2," ",'Bundle Tag Info'!$A$3,CHAR(10),'Bundle Tag Info'!H$6,CHAR(10),'Bundle Tag Info'!H$23),"") | ... AD18: =IF('Bundle Tag Info'!AD$23<>"",CONCATENATE('Bundle Tag Info'!$A$1," ",CHAR(10),'Bundle Tag Info'!$A$2," ",'Bundle Tag Info'!$A$3,CHAR(10),'Bundle Tag Info'!AD$6,CHAR(10),'Bundle Tag Info'!AD$23),"")
