Workbook

Sheet Blue Labels
A1: (SHT 1) ASSEMBLY CONSOLE | B1: (SHT 10) FIRE SYSTEM^PANEL | C1: (SHT 11) SPARE MARSHALLING PANELS | D1: (SHT 12) PLC PANEL | E1: (SHT 13) TURBINE PANEL A | F1: (SHT 14) TURBINE PANEL B | G1: (SHT 15) GENERATOR DECS250^PANEL | H1: (SHT 2) CONSOLE DOOR^PANEL | I1: (SHT 3) ASSEMBLY^CONTROL PANEL | J1: (SHT 4) PWR,DIST RAIL LEFT DOOR | K1: (SHT 5) FIRE SYSTEM^CONTROLLER PANEL | L1: (SHT 6) METER AND SWITCH^PANELS | M1: (SHT 8) TURB VIB^PANEL | N1: (SHT 9) GENERATOR VIB^PANEL
A2: EL0273 | B2: FU0170 | C2: SPARE5 | D2: UV0600 | E2: AU0090 | F2: XT0240 | G2: SPARE2 | H2: AT0190K | I2: SH0412 | J2: AT0680 | K2: UV0170 | L2: HL0704 | M2: SPARE3 | N2: IEG0130
A3: HA0273 | B3: KA0875 | C3: SPARE6 | D3: AT0600 | E3: AF0091 | F3: FU0070 | G3: SPARE | H3: AT0190 | I3: SH0411 | J3: FU0680 | K3: AT0170 | L3: HL0703 | M3: SPARE4 | N3: XT0130
A4: ZS0273 | B4: KA0178 | C4: SPARE7 | D4: AP0601 | E4: AF0092 | F4: FU0071 | G4: GR0143 | H4: TM0102 | I4: SH0410 | J4: XT0680 | K4: KA0172 | L4: HL0702 | M4: GR0112 | N4: XT0180
A5: FG0000 | B5: KA6510 | C5: SPARE8 | D5: AP0602 | E5: AF0093 | F5: XT0070 | G5: XT0332 | I5: SH0409 | J5: XT0560 | K5: KA0174 | L5: HL0701 | M5: AF0410 | N5: FU0180
B6: XT0170 | C6: SPARE9 | D6: AP0603 | E6: AF0094 | F6: AU0070 | G6: XT0333 | I6: XT0564 | J6: FU0190 | K6: KA0176 | L6: SA0710 | M6: AF0450 | N6: FU0181
B7: XT0172 | C7: SPARE10 | D7: AP0604 | E7: AF0095 | F7: AF0071 | G7: FU0332 | I7: AU0200 | J7: FU0200 | K7: XT0171 | L7: SA0740 | M7: XT0400 | N7: KA0182
B8: GR0170 | C8: GR0135 | D8: AP0605 | E8: XT0136 | F8: AF0072 | G8: FU0120 | I8: AF0201 | J8: FU0201 | K8: GR0171 | L8: PF0700 | M8: IEG0110 | N8: GR0181
B9: AT0175 | C9: GR0136 | D9: AP0606 | E9: KA0130 | F9: AF0073 | G9: FU0121 | I9: AF0202 | J9: FU0273 | L9: SA0770 | M9: FU0113 | N9: AU0180
B10: AT0176 | C10: GR0137 | D10: AP0607 | E10: KA0131 | F10: AF0074 | G10: KA0121 | I10: GR0200 | J10: FU0560 | L10: PA0703 | M10: XT0110 | N10: AF0181
B11: AT0178 | C11: GR0138 | D11: AP0608 | E11: KA0132 | F11: AF0075 | G11: KA0123 | I11: HL0411 | J11: XT0561 | L11: SA0700 | M11: GR0110 | N11: AF0182
B12: GR0172 | C12: GR0139 | D12: AP0609 | E12: KA0141 | F12: AF0076 | G12: KA0128 | I12: HL0410 | J12: XT0562 | L12: PV0701 | N12: AF0183
C13: GR0140 | D13: AR0600 | E13: KA0133 | F13: AF0077 | G13: XT0120 | I13: HL0409 | J13: XT0563 | L13: PA0701 | N13: AF0184
D14: GR0111 | E14: KA0134 | F14: GR0233 | G14: GR0120 | I14: HL0408 | J14: XT0200 | L14: PF0701 | N14: AF0185
E15: KA0144 | F15: KA0235 | G15: GR0144 | I15: HL0407 | L15: PA0771 | N15: GR0180
E16: KA0136 | F16: KA0236 | G16: AT0140 | I16: SB0400 | L16: PV0700
E17: KA0137 | F17: KA0237 | G17: RS0106 | I17: HL0406 | L17: PA0700
E18: KA0138 | F18: KA0238 | G18: FU0333 | I18: HL0405 | L18: SA0701
E19: KA2160 | F19: KA0239 | G19: FU0334 | I19: HL0404
E20: KA2161 | F20: KA0240 | G20: FU0335 | I20: HL0403
E21: KT0140 | F21: KA0248 | G21: KA0185 | I21: HL0402
E22: KT0141 | F22: KA0250 | G22: KA0310 | I22: HL0401
E23: KT0142 | F23: KA0241 | G23: KA0330 | I23: HL0400
E24: KT0143 | F24: KA0242 | G24: KA0331 | I24: SB0408
E25: KT0144 | F25: KA0243 | G25: KA0332 | I25: SB0407
E26: KT0145 | F26: KA0244 | G26: KA0333 | I26: SH0408
E27: KT0146 | F27: KA0246 | G27: KA0335 | I27: SB0405
E28: KA0135 | F28: KA0247 | G28: KA0336 | I28: SB0406
E29: KA3103 | F29: KA0245 | G29: XT0334 | I29: SA0401
E30: KA3220 | F30: KA0249 | G30: XT0335 | I30: SB0404
... E38: FU0093 | F38: XT0235 | G38: GR0141 | I38: SH0400
E39: XT0090 | F39: XT0233 | G39: XT0340
E40: FU0010 | F40: XT0237 | G40: XT0341
E41: FU0139 | F41: GR0232 | G41: XT0342
E42: XT0138 | F42: FU0210 | G42: XT0343
E43: XT0139 | F43: FU0211 | G43: KA0180
E44: XT0134 | F44: FU0212 | G44: XT0351
E45: XT0135 | F45: FU0060 | G45: XT0352
E46: FU0137 | F46: FU0061 | G46: XT0350
E47: FU0136 | F47: FU0062 | G47: XT0338
...

Sheet White Labels
A1: (SHT 3) ASSEMBLY^CONTROL PANEL - (SHT 4) PWR,DIST RAIL LEFT DOOR | B1: (SHT 3) ASSEMBLY^CONTROL PANEL - (SHT 14) TURBINE PANEL B | C1: (SHT 15) GENERATOR DECS250^PANEL | D1: (SHT 15) GENERATOR DECS250^PANEL - (SHT 9) GENERATOR VIB^PANEL | E1: (SHT 15) GENERATOR DECS250^PANEL - (SHT 13) TURBINE PANEL A | F1: (SHT 15) GENERATOR DECS250^PANEL - (SHT 14) TURBINE PANEL B | G1: (SHT 9) GENERATOR VIB^PANEL | H1: (SHT 9) GENERATOR VIB^PANEL - (SHT 14) TURBINE PANEL B | I1: (SHT 12) PLC PANEL | J1: (SHT 12) PLC PANEL - (SHT 14) TURBINE PANEL B | K1: (SHT 4) PWR,DIST RAIL LEFT DOOR - (SHT 14) TURBINE PANEL B | L1: (SHT 8) TURB VIB^PANEL | M1: (SHT 8) TURB VIB^PANEL - (SHT 14) TURBINE PANEL B | N1: (SHT 13) TURBINE PANEL A | O1: (SHT 13) TURBINE PANEL A - (SHT 14) TURBINE PANEL B | P1: (SHT 14) TURBINE PANEL B
A2: AU0200G | B2: IEG02308 | C2: AU0120G | D2: AT0140LS(S) | E2: PEG0140G | F2: IEG023012 | G2: AU0180G | H2: IEG0130G | I2: UV0600G | J2: IEG02301 | K2: IEG02307 | L2: IEG01101 | M2: IEG0110G | N2: 0V | O2: IEG023011 | P2: AF0064G
C3: EXCS | D3: IEG01304 | G3: IEG01305 | L3: XT04001 | N3: AF0083G | O3: IEG02302 | P3: AF0065G
C4: PEG01405 | G4: IEG01308 | N4: AF0084G | O4: IEG02303 | P4: AF0066G
C5: PMGS | N5: AF0085G | P5: AF0071G
C6: VBUSN | N6: AU0080G | P6: AF0072G
C7: WC8101 | N7: AU0090G | P7: AF0073G
C8: WC8102 | N8: PEG01301 | P8: AF0074G
C9: WC8201 | P9: AF0075G
C10: WC8301 | P10: AU0060G
P11: AU0070G
P12: IEG02304
P13: IEG02305
P14: IEG02306
P15: IEG02309
P16: IEG0230G

Sheet Heat Shrink Labels
A1: (SHT 5) FIRE SYSTEM^CONTROLLER PANEL - (SHT 10) FIRE SYSTEM^PANEL | B1: (SHT 10) FIRE SYSTEM^PANEL | C1: (SHT 15) GENERATOR DECS250^PANEL | D1: (SHT 15) GENERATOR DECS250^PANEL - (SHT 6) METER AND SWITCH^PANELS
A2: WC5018 | B2: WC5500 | C2: WC8009 | D2: WC8064
A3: WC8069 | B3: WC8066 | C3: WC8164 | D3: WC8065
B4: WC8067

Sheet Panel Errors
A1: Panel Errors
A3: Project # | B3: J1645
A4: Project Name | B4: TALOS EW1003 PRINCE
A5: Revision | B5: 0.1
A7: Controls DE | B7: D.JOHN
A8: Phone:
A9: Controls ME | B9: A.ABENGOZA
A10: Phone:
A12: From | H12: To
A13: Device ID | B13: Location | C13: Cable (W) Conductor (SC) Jumper Clip (JC) | D13: Wire ID | E13: Wire No. | F13: Gauge/Size | G13: Page/Zone | H13: Device ID | I13: Location | J13: Page/Zone
A14: HL0171:X2 | B14: JB70 | C14: SC | D14: LEAD | E14: HL01711 | F14: --- | G14: 32.B1 | H14: VD0175A:- | I14: JB70 | J14: 32.B2
A15: HL0172:X2 | B15: JB70 | C15: SC | D15: LEAD | E15: HL01721 | F15: --- | G15: 32.C1 | H15: VD0175I:- | I15: JB70 | J15: 32.C2
A16: HL0173:X2 | B16: JB70 | C16: SC | D16: LEAD | E16: HL01731 | F16: --- | G16: 32.C1 | H16: VD0175D:- | I16: JB70 | J16: 32.C2
A17: RR0175A: -10K OHM | B17: JB70 | C17: SC | D17: LEAD | E17: HL01712 | F17: --- | G17: 32.B2 | H17: HL0171:X1 | I17: JB70 | J17: 32.B1
A18: RR0175A: -10K OHM | B18: JB70 | C18: SC | D18: LEAD | E18: VD0175A | F18: --- | G18: 32.B2 | H18: XT6170:7 | I18: JB70 | J18: 32.B3
A19: RR0175A: -10K OHM | B19: JB70 | C19: SC | D19: LEAD | E19: HL01712 | F19: --- | G19: 32.B2 | H19: XT6170:8 | I19: JB70 | J19: 32.B3
A20: RR0175A: -10K OHM | B20: JB70 | C20: SC | D20: LEAD | E20: VD0175A | F20: --- | G20: 32.B2 | H20: VD0175A:+ | I20: JB70 | J20: 32.B2
A21: RR0175D: -10K OHM | B21: JB70 | C21: SC | D21: LEAD | E21: HL01732 | F21: --- | G21: 32.C2 | H21: HL0173:X1 | I21: JB70 | J21: 32.C1
A22: RR0175D: -10K OHM | B22: JB70 | C22: SC | D22: LEAD | E22: VD0175D | F22: --- | G22: 32.C2 | H22: XT6170:11 | I22: JB70 | J22: 32.C3
A23: RR0175D: -10K OHM | B23: JB70 | C23: SC | D23: LEAD | E23: HL01732 | F23: --- | G23: 32.C2 | H23: XT6170:12 | I23: JB70 | J23: 32.C3
A24: RR0175D: -10K OHM | B24: JB70 | C24: SC | D24: LEAD | E24: VD0175D | F24: --- | G24: 32.C2 | H24: VD0175D:+ | I24: JB70 | J24: 32.C2
... A41: FWDTG20:1 | B41: PANEL | C41: WC5526 | D41: SH | E41: DTG71S2 | F41: 16 | G41: 74.C3 | H41: FWDTG20:2 | I41: PANEL | J41: 74.C3
E43: SolarTools ver. 24.0.84.24712 (Jul 31, 2025)
A44: Report date: 3/22/2026 11:24 PM

Sheet Cable Part Numbers
A1: Cable Part Numbers | D1: SolarTools ver. 24.0.84.24712 (Jul 31, 2025)
A2: Project # | B2: J1645
D3: Report date: 3/22/2026 11:24 PM
A4: Project Name | B4: TALOS EW1003 PRINCE
A6: Revision | B6: 0.1
A8: Controls DE | B8: D.JOHN
A9: Phone:
A10: Controls ME | B10: A.ABENGOZA
A11: Phone:
A13: Device ID | C13: Part Number | E13: Description
A14: WC0001 | C14: 1302073-36 | E14: CABLE, ETHERNET - 36 INCHES
A15: WC0003 | C15: 1302073-36 | E15: CABLE, ETHERNET - 36 INCHES
A16: WC0006 | C16: 1302073-36 | E16: CABLE, ETHERNET - 36 INCHES
A17: WC0007 | C17: 1302073-36 | E17: CABLE, ETHERNET - 36 INCHES
A18: WC0008 | C18: 1302073-36 | E18: CABLE, ETHERNET - 36 INCHES
A19: WC0009 | C19: 1302073-36 | E19: CABLE, ETHERNET - 36 INCHES
A20: WC0012 | C20: 1302073-36 | E20: CABLE, ETHERNET - 36 INCHES
A21: WC0017 | C21: 1302073-36 | E21: CABLE, ETHERNET - 36 INCHES
A22: WC0018 | C22: 1302073-36 | E22: CABLE, ETHERNET - 36 INCHES
A23: WC0041 | C23: 1302073-36 | E23: CABLE, ETHERNET - 36 INCHES
A24: WC0045 | C24: 1302073-36 | E24: CABLE, ETHERNET - 36 INCHES
... A43: WC8301 | C43: 1022941-32 | E43: TPE, 1 PAIR TWISTED SHIELDED

Sheet Part Number List
A1: Part Number List | C1: SolarTools ver. 24.0.84.24712 (Jul 31, 2025)
A2: Project # | B2: J1645
C3: Report date: 3/22/2026 11:24 PM
A4: Project Name | B4: TALOS EW1003 PRINCE
A6: Revision | B6: 0.1
A8: Controls DE | B8: D.JOHN
A9: Phone:
A10: Controls ME | B10: A.ABENGOZA
A11: Phone:
A13: Device ID | B13: Part Number | C13: Description | D13: Location
A14: EL0273 | B14: 1022899,22650R1 | C14: LIGHT, LED, WHITE | D14: ASSEMBLY CONSOLE
A15: HA0273 | B15: 1015162-10,1113568-100 | C15: HORN, AUDIBLE ALARM | D15: ASSEMBLY CONSOLE
A16: ZS0273 | B16: 1113474-1 | C16: LIMIT SWITCH, CONSOLE DOOR OPEN | D16: ASSEMBLY CONSOLE
A18: AF0201 | B18: 2684693-48,2684693-51 | C18: 5094-IB32XT, 32 DISCRETE INPUT | D18: ASSEMBLY^CONTROL PANEL
A19: AF0202 | B19: 2684693-49,2684693-52 | C19: 5094-OB32XT, 32 DISCRETE OUTPUT | D19: ASSEMBLY^CONTROL PANEL
A20: AU0200 | B20: 2684693-22 | C20: 5094-AENTRXT, FLEX 5000 I/O | D20: ASSEMBLY^CONTROL PANEL
A21: GR0200 | B21: PARTOFTCPASSY | C21: RAIL LUG, DIN RAIL GROUNDING | D21: ASSEMBLY^CONTROL PANEL
A22: HL0400 | B22: PARTOFTCPASSY | C22: LIGHT, READY, GREEN | D22: ASSEMBLY^CONTROL PANEL
A23: HL0401 | B23: PARTOFTCPASSY | C23: LIGHT, STARTING, WHITE | D23: ASSEMBLY^CONTROL PANEL
A24: HL0402 | B24: PARTOFTCPASSY | C24: LIGHT, READY TO LOAD, WHITE | D24: ASSEMBLY^CONTROL PANEL
A25: HL0403 | B25: PARTOFTCPASSY | C25: LIGHT, ON LOAD, WHITE | D25: ASSEMBLY^CONTROL PANEL
... A364: XT0240 | B364: 1066730-7,1066730-8 | C364: TERMINAL BLOCK, SPRING, 4 CONDUCTOR,30-12 AWG (0.05-3.31 MM2),NON-IS | D364: TURBINE PANEL B

Sheet PWR DIST RAIL _S
A1: PWR DIST RAIL
A3: Project # | B3: J1640
A4: Project Name | B4: TALOS EW1003 PRINCE
A5: Revision | B5: 0.1
A7: Controls DE | B7: D.JOHN
A8: Phone:
A9: Controls ME | B9: A.ABENGOZA
A10: Phone:
A12: From | G12: To
A13: Device ID | B13: Wire No. | C13: Wire ID | D13: Gauge/Size | E13: Length | F13: Device ID | G13: Location | H13: Bundle Name
A14: AT0680:NEG | B14: -0V | C14: WHT | D14: 14 | E14: 60 | F14: XT0680:2 | G14: PWR DIST RAIL | H14: AT0680
A15: AT0680:POS | B15: AT0680POS | C15: WHT | D15: 14 | E15: 60 | F15: XT0680:1 | G15: PWR DIST RAIL
A17: FU0680:LD | B17: AT0680POS | C17: WHT | D17: 14 | E17: 60 | F17: XT0680:1 | G17: PWR DIST RAIL | H17: FU/XT
A18: FU0200:LI | B18: FU0200LI | C18: WHT | D18: 14 | E18: 60 | F18: XT0561:1 | G18: PWR DIST RAIL
A19: FU0560:LD | B19: FU0200LI | C19: WHT | D19: 14 | E19: 60 | F19: XT0561:1 | G19: PWR DIST RAIL
A20: FU0190:LI | B20: FU0200LI | C20: WHT | D20: 14 | E20: 60 | F20: FU0273:LI | G20: PWR DIST RAIL
A22: XT0560:2 | B22: JW0 | C22: wht | D22: 12 | E22: 60 | F22: XT0562:1 | G22: PWR DIST RAIL
A23: FU0560:LI | B23: FU0136 | C23: WHT | D23: 12 | E23: 60 | F23: XT0560:1 | G23: PWR DIST RAIL
A25: XT0562:2 | B25: -0V1 | C25: WHT | D25: 14 | E25: 100 | F25: AT0190:NEG | G25: DOOR | H25: FU/XT-DOOR
A26: FU0190:LD | B26: FU0190 | C26: WHT | D26: 14 | E26: 100 | F26: AT0190:POS | G26: DOOR
A28: XT0560:2 | B28: -0V | C28: WHT | D28: 12 | E28: 220 | F28: XT0134:2 | G28: A PNL | H28: XT-A
A29: XT0560:1 | B29: FU0136 | C29: WHT | D29: 12 | E29: 220 | F29: XT0138:2 | G29: A PNL
A31: XT0563:2 | B31: ESTOPA | C31: WHT | D31: 20 | E31: 240 | F31: XT0240:3 | G31: B PNL | H31: XT-B
A32: XT0563:1 | B32: ESTOPB | C32: WHT | D32: 20 | E32: 240 | F32: XT0240:2 | G32: B PNL
A33: XT0563:6 | B33: FU0139 | C33: WHT | D33: 20 | E33: 240 | F33: XT0240:11 | G33: B PNL
A34: XT0563:3 | B34: KA023612 | C34: WHT | D34: 20 | E34: 240 | F34: XT0240:13 | G34: B PNL
A35: XT0563:5 | B35: KA0241A1 | C35: WHT | D35: 20 | E35: 240 | F35: XT0240:6 | G35: B PNL
A37: XT0563:4 | B37: -0V | C37: WHT | D37: 14 | E37: 240 | F37: XT0240:9 | G37: B PNL
A38: XT0680:2 | B38: -0V | C38: WHT | D38: 14 | E38: 240 | F38: XT0235:3 | G38: B PNL
A39: FU0680:LI | B39: FU0210 | C39: WHT | D39: 14 | E39: 240 | F39: XT0233:3 | G39: B PNL

Sheet FS CONT. PNL_S
A1: FIRE SYSTEM^CONTROLLER PANEL
A3: Project # | B3: J1640
A4: Project Name | B4: TALOS EW1003 PRINCE
A5: Revision | B5: 0.1
A7: Controls DE | B7: D.JOHN
A8: Phone:
A9: Controls ME | B9: A.ABENGOZA
A10: Phone:
A12: From | G12: To
A13: Device ID | B13: Wire No. | C13: Wire ID | D13: Gauge/Size | E13: Length | F13: Device ID | G13: Location | H13: Bundle Name
A14: AT0170:1 | B14: UV01705 | C14: WHT | D14: 14 | E14: 60 | F14: UV0170:5(+) | G14: FS CONTROLLER | H14: AT0170
A15: AT0170:2 | B15: UV01706 | C15: WHT | D15: 14 | E15: 60 | F15: UV0170:6(-) | G15: FS CONTROLLER
A16: AT0170:3 | B16: UV01707 | C16: WHT | D16: 14 | E16: 60 | F16: UV0170:7(+) | G16: FS CONTROLLER
A17: AT0170:4 | B17: UV01708 | C17: WHT | D17: 14 | E17: 60 | F17: UV0170:8(-) | G17: FS CONTROLLER
A19: KA0176:11 | B19: -009304 | C19: WHT | D19: 20 | E19: 60 | F19: XT0171:1 | G19: FS CONTROLLER | H19: KA
A20: KA0172:A1 | B20: AT017025 | C20: WHT | D20: 20 | E20: 60 | F20: AT0170:25 | G20: FS CONTROLLER
A21: KA0174:A1 | B21: AT017031 | C21: WHT | D21: 20 | E21: 60 | F21: AT0170:31 | G21: FS CONTROLLER
A23: AT0170:45 | B23: AT017045 | C23: WHT | D23: 20 | E23: 280 | F23: XT0170:5 | G23: FS PNL | H23: AT-FS PNL
A24: AT0170:46 | B24: AT017046 | C24: WHT | D24: 20 | E24: 280 | F24: XT0170:6 | G24: FS PNL
A25: AT0170:11 | B25: SA0170B113 | C25: WHT | D25: 20 | E25: 280 | F25: XT0170:11 | G25: FS PNL
A26: AT0170:12 | B26: SA0170B114 | C26: WHT | D26: 20 | E26: 280 | F26: XT0170:12 | G26: FS PNL
A28: UV0170:2(-) | B28: -0V | C28: WHT | D28: 14 | E28: 280 | F28: XT0170:3 | G28: FS PNL | H28: UV-FS PNL
A29: UV0170:4(-) | B29: -0V | C29: WHT | D29: 14 | E29: 280 | F29: XT0170:3 | G29: FS PNL
A30: UV0170:1(+) | B30: FU0170 | C30: WHT | D30: 14 | E30: 280 | F30: XT0170:2 | G30: FS PNL
A31: UV0170:3(+) | B31: FU0170 | C31: WHT | D31: 14 | E31: 280 | F31: XT0170:2 | G31: FS PNL
A32: UV0170:14(-) | B32: LON0N | C32: WHT | D32: 14 | E32: 280 | F32: XT0172:14 | G32: FS PNL
A33: UV0170:13(+) | B33: LON0P | C33: WHT | D33: 14 | E33: 280 | F33: XT0172:13 | G33: FS PNL
A34: UV0170:16(-) | B34: LON2N | C34: WHT | D34: 14 | E34: 280 | F34: XT0172:18 | G34: FS PNL
A35: UV0170:15(+) | B35: LON2P | C35: WHT | D35: 14 | E35: 280 | F35: XT0172:17 | G35: FS PNL
A36: UV0170:10(-) | B36: UV017010 | C36: WHT | D36: 14 | E36: 280 | F36: AT0175:2P1 | G36: FS PNL
A37: UV0170:11(+) | B37: UV017011 | C37: WHT | D37: 14 | E37: 280 | F37: AT0176:1P1 | G37: FS PNL
A38: UV0170:12(-) | B38: UV017012 | C38: WHT | D38: 14 | E38: 280 | F38: AT0176:2P1 | G38: FS PNL
A39: UV0170:9(+) | B39: UV01709 | C39: WHT | D39: 14 | E39: 280 | F39: AT0175:1P1 | G39: FS PNL
A41: KA0172:A2 | B41: -0V | C41: WHT | D41: 20 | E41: 280 | F41: XT0170:4 | G41: FS PNL | H41: KA-FS PNL
A42: KA0176:A2 | B42: -0V | C42: WHT | D42: 20 | E42: 280 | F42: XT0170:3 | G42: FS PNL
A43: KA0172:11 | B43: KA017211 | C43: WHT | D43: 20 | E43: 280 | F43: XT0170:7 | G43: FS PNL
A44: KA0172:12 | B44: KA017212 | C44: WHT | D44: 20 | E44: 280 | F44: XT0170:8 | G44: FS PNL
A45: KA0174:11 | B45: KA017411 | C45: WHT | D45: 20 | E45: 280 | F45: XT0170:9 | G45: FS PNL
A46: KA0174:12 | B46: KA017412 | C46: WHT | D46: 20 | E46: 280 | F46: XT0170:10 | G46: FS PNL
A48: KA0176:14 | B48: -009336 | C48: WHT | D48: 20 | E48: 280 | F48: AF0093:36 | G48: A PNL | H48: KA-A
...

Sheet TURB VIB PNL_S
A1: TURB VIB^PANEL
A3: Project # | B3: J1640
A4: Project Name | B4: TALOS EW1003 PRINCE
A5: Revision | B5: 0.1
A7: Controls DE | B7: D.JOHN
A8: Phone:
A9: Controls ME | B9: A.ABENGOZA
A10: Phone:
A12: From | G12: To
A13: Device ID | B13: Wire No. | C13: Wire ID | D13: Gauge/Size | E13: Length | F13: Device ID | G13: Location | H13: Bundle Name
A14: AF0410:53 | B14: -0V | C14: WHT | D14: 16 | E14: 60 | F14: XT0110:2 | G14: TURB VIB PNL | H14: 1444S
A15: AF0410:54 | B15: AF0450N | C15: WHT | D15: 16 | E15: 60 | F15: AF0450:53 | G15: TURB VIB PNL
A16: AF0410:55 | B16: FU0113 | C16: WHT | D16: 16 | E16: 60 | F16: FU0113:LD | G16: TURB VIB PNL
A17: AF0410:56 | B17: AF0450P | C17: WHT | D17: 16 | E17: 60 | F17: AF0450:55 | G17: TURB VIB PNL
A19: FU0113:LI | B19: FU0136 | C19: WHT | D19: 14 | E19: 60 | F19: XT0110:1 | G19: TURB VIB PNL | H19: FU
A21: XT0110:2 | B21: -0V | C21: WHT | D21: 14 | E21: 180 | F21: XT0134:4 | G21: A PNL | H21: XT-A PNL
A23: XT0110:1 | B23: FU0136 | C23: WHT | D23: 12 | E23: 180 | F23: XT0138:4 | G23: A PNL

Sheet GEN VIB^PNL_S
A1: GENERATOR VIB^PANEL
A3: Project # | B3: J1640
A4: Project Name | B4: TALOS EW1003 PRINCE
A5: Revision | B5: 0.1
A7: Controls DE | B7: D.JOHN
A8: Phone:
A9: Controls ME | B9: A.ABENGOZA
A10: Phone:
A12: From | G12: To
A13: Device ID | B13: Wire No. | C13: Wire ID | D13: Gauge/Size | E13: Length | F13: Device ID | G13: Location | H13: Bundle Name
A14: AF0182:COM | B14: AU0180N | C14: WHT | D14: 20 | E14: 60 | F14: AU0180:COM | G14: GEN VIB PNL | H14: AU/AF
A15: AF0182:V+ | B15: AU0180P | C15: WHT | D15: 20 | E15: 60 | F15: AU0180:V+ | G15: GEN VIB PNL
A17: AF0181:COM | B17: -0V | C17: WHT | D17: 14 | E17: 60 | F17: XT0180:2 | G17: GEN VIB PNL
A18: AU0180:COM | B18: -0V | C18: WHT | D18: 14 | E18: 60 | F18: XT0180:1 | G18: GEN VIB PNL
A19: AU0180:V+ | B19: FU0180 | C19: WHT | D19: 14 | E19: 60 | F19: FU0180:LD | G19: GEN VIB PNL
A20: AF0181:V+ | B20: FU0181 | C20: WHT | D20: 14 | E20: 60 | F20: FU0181:LD | G20: GEN VIB PNL
A22: KA0182:A1 | B22: -018102 | C22: WHT | D22: 20 | E22: 60 | F22: AF0181:02 | G22: GEN VIB PNL | H22: KA A1/A2
A23: KA0182:A2 | B23: -018118 | C23: WHT | D23: 20 | E23: 60 | F23: AF0181:18 | G23: GEN VIB PNL
A25: XT0130:3 | B25: -0V | C25: WHT | D25: 14 | E25: 60 | F25: XT0180:1 | G25: GEN VIB PNL | H25: FU/XT
A26: FU0180:LI | B26: FU0332 | C26: WHT | D26: 14 | E26: 60 | F26: FU0181:LI | G26: GEN VIB PNL
A27: FU0180:LI | B27: FU0332 | C27: WHT | D27: 14 | E27: 60 | F27: XT0130:1 | G27: GEN VIB PNL
A29: AF0181:00 | B29: -018100 | C29: WHT | D29: 20 | E29: 220 | F29: KA0180:A1 | G29: GEN PNL | H29: AF-GEN
A30: AF0181:10 | B30: -018110 | C30: WHT | D30: 20 | E30: 220 | F30: KA0185:A1 | G30: GEN PNL
A31: AF0181:16 | B31: -018116 | C31: WHT | D31: 20 | E31: 220 | F31: KA0180:A2 | G31: GEN PNL
A32: AF0181:26 | B32: -018126 | C32: WHT | D32: 20 | E32: 220 | F32: KA0364:14 | G32: GEN PNL
A34: XT0130:2 | B34: -0V | C34: WHT | D34: 14 | E34: 220 | F34: XT0336:3 | G34: GEN PNL | H34: XT-GEN
A35: XT0130:2 | B35: -0V | C35: WHT | D35: 14 | E35: 220 | F35: XT0120:1 | G35: GEN PNL
A36: XT0130:1 | B36: FU0332 | C36: WHT | D36: 14 | E36: 220 | F36: FU0120:LI | G36: GEN PNL
A37: XT0130:1 | B37: FU0332 | C37: WHT | D37: 14 | E37: 220 | F37: XT0333:1 | G37: GEN PNL

Sheet FS PNL_S
A1: FIRE SYSTEM^PANEL
A3: Project # | B3: J1640
A4: Project Name | B4: TALOS EW1003 PRINCE
A5: Revision | B5: 0.1
A7: Controls DE | B7: D.JOHN
A8: Phone:
A9: Controls ME | B9: A.ABENGOZA
A10: Phone:
A12: From | G12: To
A13: Device ID | B13: Wire No. | C13: Wire ID | D13: Gauge/Size | E13: Length | F13: Device ID | G13: Location | H13: Bundle Name
A14: AT0175:4P1 | B14: AT01754P1 | C14: WHT | D14: 20 | E14: 60 | F14: XT0170:31 | G14: FS PNL | H14: AT
A15: AT0178:24 | B15: KA0178A2 | C15: WHT | D15: 20 | E15: 60 | F15: XT0170:18 | G15: FS PNL
A16: AT0178:23 | B16: VD0178 | C16: WHT | D16: 20 | E16: 60 | F16: XT0170:17 | G16: FS PNL
A18: AT0176:4P1 | B18: AT01764P1 | C18: WHT | D18: 14 | E18: 60 | F18: AT0178:1P1 | G18: FS PNL
A19: AT0176:5P1 | B19: AT01765P1 | C19: WHT | D19: 14 | E19: 60 | F19: AT0178:2P1 | G19: FS PNL
A21: KA0178:A1 | B21: KA0178A1 | C21: WHT | D21: 20 | E21: 60 | F21: XT0170:16 | G21: FS PNL | H21: KA A1/A2
A22: KA6510:A1 | B22: SA017013 | C22: WHT | D22: 20 | E22: 60 | F22: XT0170:32 | G22: FS PNL
A24: KA0178:A2 | B24: KA0178A2 | C24: WHT | D24: 20 | E24: 60 | F24: XT0170:18 | G24: FS PNL
A25: KA6510:A2 | B25: KA6510A2 | C25: WHT | D25: 20 | E25: 60 | F25: AT0175:5P1 | G25: FS PNL
A27: KA6510:12 | B27: KA651012 | C27: WHT | D27: 20 | E27: 60 | F27: AT0175:11 | G27: FS PNL | H27: KA
A28: KA0178:11 | B28: HA04722 | C28: WHT | D28: 20 | E28: 60 | F28: XT0170:13 | G28: FS PNL
A29: KA0875:11 | B29: HA04722 | C29: WHT | D29: 20 | E29: 60 | F29: XT0170:13 | G29: FS PNL
A31: KA0875:14 | B31: FU0170 | C31: WHT | D31: 14 | E31: 60 | F31: XT0170:1 | G31: FS PNL
A33: XT0170:14 | B33: -0V | C33: WHT | D33: 20 | E33: 60 | F33: XT0170:4 | G33: FS PNL | H33: FU/XT
A34: FU0170:LD | B34: FU0170 | C34: WHT | D34: 20 | E34: 60 | F34: XT0170:2 | G34: FS PNL
A36: XT0170:4 | B36: -0V | C36: WHT | D36: 14 | E36: 60 | F36: XT0172:5 | G36: FS PNL
A37: XT0172:4 | B37: FU0170 | C37: WHT | D37: 14 | E37: 60 | F37: XT0170:1 | G37: FS PNL
A39: KA0875:A1 | B39: -009212 | C39: WHT | D39: 20 | E39: 200 | F39: AF0092:12 | G39: A PNL | H39: KA-A
A40: KA0875:A2 | B40: -009228 | C40: WHT | D40: 20 | E40: 200 | F40: AF0092:28 | G40: A PNL
A42: XT0170:3 | B42: -0V | C42: WHT | D42: 12 | E42: 200 | F42: XT0134:2 | G42: A PNL
A43: FU0170:LI | B43: FU0136 | C43: WHT | D43: 12 | E43: 200 | F43: XT0138:2 | G43: A PNL
A45: KA0875:14 | B45: FU0170 | C45: WHT | D45: 20 | E45: 220 | F45: KA0232:12 | G45: B PNL | H45: KA-B
A46: KA0178:14 | B46: KA017814 | C46: WHT | D46: 20 | E46: 220 | F46: KA0232:11 | G46: B PNL
A48: XT0170:2 | B48: FU0170 | C48: WHT | D48: 20 | E48: 220 | F48: KA0232:21 | G48: B PNL | H48: XT-B

Sheet PLC PNL_S
A1: PLC PANEL
A3: Project # | B3: J1640
A4: Project Name | B4: TALOS EW1003 PRINCE
A5: Revision | B5: 0.1
A7: Controls DE | B7: D.JOHN
A8: Phone:
A9: Controls ME | B9: A.ABENGOZA
A10: Phone:
A12: From | G12: To
A13: Device ID | B13: Wire No. | C13: Wire ID | D13: Gauge/Size | E13: Length | F13: Device ID | G13: Location | H13: Bundle Name
A14: UV0600:(-) | B14: -0V | C14: WHT | D14: 14 | E14: 80 | F14: XT0135:1 | G14: A PNL | H14: UV-A
A15: UV0600:(+) | B15: FU0010 | C15: WHT | D15: 14 | E15: 80 | F15: FU0010:LD | G15: A PNL

Sheet A PNL_S
A1: TURBINE PANEL A
A3: Project # | B3: J1640
A4: Project Name | B4: TALOS EW1003 PRINCE
A5: Revision | B5: 0.1
A7: Controls DE | B7: D.JOHN
A8: Phone:
A9: Controls ME | B9: A.ABENGOZA
A10: Phone:
A12: From | G12: To
A13: Device ID | B13: Wire No. | C13: Wire ID | D13: Gauge/Size | E13: Length | F13: Device ID | G13: Location | H13: Bundle Name
A14: PC0470:INP_A | B14: -009312 | C14: WHT | D14: 20 | E14: 60 | F14: AF0093:12 | G14: A PNL | H14: PC0470
A15: PC0470:-PWR | B15: -009328 | C15: WHT | D15: 20 | E15: 60 | F15: AF0093:28 | G15: A PNL
A16: PC0470:+PWR | B16: -009344 | C16: WHT | D16: 20 | E16: 60 | F16: AF0093:44 | G16: A PNL
A18: AF0094:00 | B18: -009400 | C18: WHT | D18: 20 | E18: 80 | F18: XT0085:2 | G18: A PNL | H18: AU/AF
A19: AF0094:01 | B19: -0V | C19: WHT | D19: 20 | E19: 80 | F19: XT0085:3 | G19: A PNL
A20: AF0091:COM | B20: AF0091N | C20: WHT | D20: 20 | E20: 60 | F20: AF0094:COM | G20: A PNL
A21: AF0091:V+ | B21: AF0091P | C21: WHT | D21: 20 | E21: 60 | F21: AF0094:V+ | G21: A PNL
A23: AU0080:COM | B23: -0V | C23: WHT | D23: 14 | E23: 60 | F23: XT0080:1 | G23: A PNL
A24: AF0082:COM | B24: -0V | C24: WHT | D24: 14 | E24: 60 | F24: XT0080:2 | G24: A PNL
A25: AU0090:COM | B25: -0V | C25: WHT | D25: 14 | E25: 60 | F25: XT0090:1 | G25: A PNL
A26: AF0092:COM | B26: -0V | C26: WHT | D26: 14 | E26: 60 | F26: XT0090:2 | G26: A PNL
A27: AF0093:COM | B27: -0V | C27: WHT | D27: 14 | E27: 60 | F27: XT0090:2 | G27: A PNL
A28: AF0095:COM | B28: -0V | C28: WHT | D28: 14 | E28: 60 | F28: XT0090:2 | G28: A PNL
A29: AU0080:V+ | B29: FU0080 | C29: WHT | D29: 14 | E29: 60 | F29: FU0080:LD | G29: A PNL
A30: AF0082:V+ | B30: FU0081 | C30: WHT | D30: 14 | E30: 60 | F30: FU0081:LD | G30: A PNL
A31: AU0090:V+ | B31: FU0090 | C31: WHT | D31: 14 | E31: 60 | F31: FU0090:LD | G31: A PNL
... A34: AF0095:V+ | B34: FU0093 | C34: WHT | D34: 14 | E34: 60 | F34: FU0093:LD | G34: A PNL
A36: KA0130:A1 | B36: -008135 | C36: WHT | D36: 20 | E36: 80 | F36: AF0081:35 | G36: A PNL | H36: KA A1
A37: KA0130:A1 | B37: -008135 | C37: WHT | D37: 20 | E37: 120 | F37: KA0130:11 | G37: A PNL
A38: KA3103:A1 | B38: -009208 | C38: WHT | D38: 20 | E38: 80 | F38: AF0092:08 | G38: A PNL
A39: KA0133:A1 | B39: KA0133A1 | C39: WHT | D39: 20 | E39: 60 | F39: AF0092:02 | G39: A PNL
A40: KA0134:A1 | B40: KA0134A1 | C40: WHT | D40: 20 | E40: 60 | F40: AF0091:12 | G40: A PNL
A41: KA0134:A1 | B41: KA0134A1 | C41: WHT | D41: 20 | E41: 60 | F41: AF0095:10 | G41: A PNL
A42: KA0135:A1 | B42: KA0135A1 | C42: WHT | D42: 20 | E42: 60 | F42: KA0144:A1 | G42: A PNL
A43: KA0131:A1 | B43: KA0231A1 | C43: WHT | D43: 20 | E43: 60 | F43: XT0136:10 | G43: A PNL
A44: KA3220:A1 | B44: KA32201 | C44: WHT | D44: 20 | E44: 80 | F44: AF0093:01 | G44: A PNL
A45: KA3221:A1 | B45: KA32211 | C45: WHT | D45: 20 | E45: 80 | F45: AF0093:02 | G45: A PNL
A46: KA0136:A1 | B46: PS32002 | C46: WHT | D46: 20 | E46: 60 | F46: XT0136:5 | G46: A PNL
A47: KA0135:A1 | B47: KA0135A1 | C47: WHT | D47: 20 | E47: 120 | F47: KA0131:11 | G47: A PNL
A48: KA0138:A1 | B48: KA0138A1 | C48: WHT | D48: 20 | E48: 120 | F48: KA0132:21 | G48: A PNL
...

Sheet B PNL_S
A1: TURBINE PANEL B
A3: Project # | B3: J1640
A4: Project Name | B4: TALOS EW1003 PRINCE
A5: Revision | B5: 0.1
A7: Controls DE | B7: D.JOHN
A8: Phone:
A9: Controls ME | B9: A.ABENGOZA
A10: Phone:
A12: From | G12: To
A13: Device ID | B13: Wire No. | C13: Wire ID | D13: Gauge/Size | E13: Length | F13: Device ID | G13: Location | H13: Bundle Name
A14: AF0076:12 | B14: -007612 | C14: WHT | D14: 20 | E14: 60 | F14: XT0237:1 B2 | G14: B PNL | H14: AU/AF
A15: AF0066:COM | B15: AF0066N | C15: WHT | D15: 20 | E15: 60 | F15: AF0068:COM | G15: B PNL
A16: AF0066:V+ | B16: AF0066P | C16: WHT | D16: 20 | E16: 60 | F16: AF0068:V+ | G16: B PNL
A17: AF0075:COM | B17: AF0075N | C17: WHT | D17: 20 | E17: 60 | F17: AF0077:COM | G17: B PNL
A18: AF0075:V+ | B18: AF0075P | C18: WHT | D18: 20 | E18: 60 | F18: AF0077:V+ | G18: B PNL
A19: AF0063:COM | B19: AU0060N | C19: WHT | D19: 20 | E19: 60 | F19: AU0060:COM | G19: B PNL
A20: AF0063:V+ | B20: AU0060P | C20: WHT | D20: 20 | E20: 60 | F20: AU0060:V+ | G20: B PNL
A21: AF0062:16 | B21: SV21242 | C21: WHT | D21: 20 | E21: 60 | F21: XT0060:6 | G21: B PNL
A23: AF0061:COM | B23: -0V | C23: WHT | D23: 14 | E23: 60 | F23: XT0060:2 | G23: B PNL
A24: AF0062:COM | B24: -0V | C24: WHT | D24: 14 | E24: 60 | F24: XT0060:2 | G24: B PNL
A25: AF0067:COM | B25: -0V | C25: WHT | D25: 14 | E25: 60 | F25: XT0060:2 | G25: B PNL
A26: AF0076:COM | B26: -0V | C26: WHT | D26: 14 | E26: 60 | F26: XT0070:2 | G26: B PNL
A27: AU0060:COM | B27: -0V | C27: WHT | D27: 14 | E27: 60 | F27: XT0060:1 | G27: B PNL
... A34: AF0076:V+ | B34: FU0071 | C34: WHT | D34: 14 | E34: 60 | F34: FU0071:LD | G34: B PNL
A36: KA1020:A1 | B36: -007607 | C36: WHT | D36: 20 | E36: 80 | F36: AF0076:07 | G36: B PNL | H36: KA A1
A37: KA0235:A1 | B37: ESTOP | C37: WHT | D37: 20 | E37: 60 | F37: XT0240:4 | G37: B PNL
A38: KA0241:A1 | B38: KA0241A1 | C38: WHT | D38: 20 | E38: 60 | F38: XT0240:6 | G38: B PNL
A39: KA0243:A1 | B39: KA0243A1 | C39: WHT | D39: 20 | E39: 60 | F39: XT0240:7 | G39: B PNL
A40: KA0245:A1 | B40: KA0245A1 | C40: WHT | D40: 20 | E40: 60 | F40: XT0240:8 | G40: B PNL
A42: KA0222:A1 | B42: -007604 | C42: WHT | D42: 16 | E42: 80 | F42: AF0076:04 | G42: B PNL
A44: KA1020:14 | B44: FU0211 | C44: WHT | D44: 14 | E44: 60 | F44: FU0211:LD | G44: B PNL
A46: KA0222:A2 | B46: -007620 | C46: WHT | D46: 20 | E46: 80 | F46: AF0076:20 | G46: B PNL | H46: KA A2
A47: KA1020:A2 | B47: -007623 | C47: WHT | D47: 20 | E47: 80 | F47: AF0076:23 | G47: B PNL
A48: KA0249:A2 | B48: -0V | C48: WHT | D48: 20 | E48: 60 | F48: XT0240:10 | G48: B PNL
A49: KA0231:A2 | B49: KA0231A2 | C49: WHT | D49: 20 | E49: 80 | F49: AF0076:26 | G49: B PNL
A51: KA0222:14 | B51: -006200 | C51: WHT | D51: 20 | E51: 100 | F51: AF0062:00 | G51: B PNL | H51: KA
A52: KA0234:14 | B52: -006210 | C52: WHT | D52: 20 | E52: 100 | F52: AF0062:10 | G52: B PNL
A53: KA0222:11 | B53: -022211 | C53: WHT | D53: 20 | E53: 60 | F53: KA0236:24 | G53: B PNL
A54: KA0242:21 | B54: -024221 | C54: WHT | D54: 20 | E54: 60 | F54: XT0237:1 T2 | G54: B PNL
A55: KA0243:21 | B55: ESTOPC | C55: WHT | D55: 20 | E55: 60 | F55: XT0240:1 | G55: B PNL
...

Sheet GEN PNL_S
A1: GENERATOR DECS250^PANEL
A3: Project # | B3: J1640
A4: Project Name | B4: TALOS EW1003 PRINCE
A5: Revision | B5: 0.1
A7: Controls DE | B7: D.JOHN
A8: Phone:
A9: Controls ME | B9: A.ABENGOZA
A10: Phone:
A12: From | G12: To
A13: Device ID | B13: Wire No. | C13: Wire ID | D13: Gauge/Size | E13: Length | F13: Device ID | G13: Location | H13: Bundle Name
A14: AT0140:17 VBUS-A | B14: VBUSA | C14: RED | D14: 16R | E14: 120 | F14: XT0351:2 | G14: GEN PNL | H14: AT RED
A15: AT0140:18 VBUS-B | B15: VBUSB | C15: RED | D15: 16R | E15: 120 | F15: XT0351:3 | G15: GEN PNL
A16: AT0140:19 VBUS-C | B16: VBUSC | C16: RED | D16: 16R | E16: 120 | F16: XT0351:5 | G16: GEN PNL
A17: AT0140:13 VGEN-A | B17: VGENA | C17: RED | D17: 16R | E17: 120 | F17: XT0351:9 | G17: GEN PNL
A18: AT0140:14 VGEN-B | B18: VGENB | C18: RED | D18: 16R | E18: 120 | F18: XT0351:11 | G18: GEN PNL
A19: AT0140:15 VGEN-C | B19: VGENC | C19: RED | D19: 16R | E19: 120 | F19: XT0351:13 | G19: GEN PNL
A21: AT0140:41 I3(-) | B21: PA07035 | C21: BLU | D21: 16B | E21: 120 | F21: XT0342:1 | G21: GEN PNL | H21: AT BLU
A22: AT0140:37 I1(-) | B22: PA07716 | C22: BLU | D22: 16B | E22: 120 | F22: XT0342:4 | G22: GEN PNL
A23: AT0140:39 I2(-) | B23: SA074013 | C23: BLU | D23: 16B | E23: 120 | F23: XT0342:3 | G23: GEN PNL
A25: AT0140:28 ID RLY | B25: CCT1(-) | C25: BLU | D25: 12B | E25: 140 | F25: XT0350:4 | G25: GEN PNL
A26: AT0140:43 ID(-) | B26: CCT1(-) | C26: BLU | D26: 12B | E26: 140 | F26: XT0350:3 | G26: GEN PNL
A27: AT0140:27 ID RLY | B27: CCT1(+) | C27: BLU | D27: 12B | E27: 140 | F27: XT0350:2 | G27: GEN PNL
A28: AT0140:33 ID RES(+) | B28: CCT1(+) | C28: BLU | D28: 12B | E28: 140 | F28: XT0350:1 | G28: GEN PNL
A29: AT0140:36 I1(+) | B29: MCTA | C29: BLU | D29: 12B | E29: 140 | F29: XT0352:1 | G29: GEN PNL
A30: AT0140:38 I2(+) | B30: MCTB | C30: BLU | D30: 12B | E30: 140 | F30: XT0352:2 | G30: GEN PNL
A31: AT0140:40 I3(+) | B31: MCTC | C31: BLU | D31: 12B | E31: 140 | F31: XT0352:3 | G31: GEN PNL
A33: AT0140:34 ID RES(-) | B33: AT014034 | C33: WHT | D33: 16 | E33: 60 | F33: AT0140:42 ID(+) | G33: GEN PNL | H33: AT0140
A34: AT0140:BAT(+) 47 | B34: FU0334 | C34: WHT | D34: 16 | E34: 140 | F34: XT0335:2 | G34: GEN PNL
A35: AT0140:4 EX-D(+) | B35: KA012314 | C35: WHT | D35: 16 | E35: 120 | F35: KA0123:14 | G35: GEN PNL
A37: AT0140:3 EX-D(-) | B37: -0V | C37: WHT | D37: 14 | E37: 140 | F37: XT0336:4 | G37: GEN PNL
A38: AT0140:BAT(-) 48 | B38: -0V | C38: WHT | D38: 14 | E38: 140 | F38: XT0336:4 | G38: GEN PNL
A39: AT0140:FLT 30 | B39: -0V | C39: WHT | D39: 14 | E39: 140 | F39: XT0336:4 | G39: GEN PNL
A41: AF0122:COM | B41: AU0120N | C41: WHT | D41: 20 | E41: 60 | F41: AU0120:COM | G41: GEN PNL | H41: AU/AF
A42: AF0122:V+ | B42: AU0120P | C42: WHT | D42: 20 | E42: 60 | F42: AU0120:V+ | G42: GEN PNL
A44: AF0121:COM | B44: -0V | C44: WHT | D44: 14 | E44: 60 | F44: XT0120:2 | G44: GEN PNL
A45: AU0120:COM | B45: -0V | C45: WHT | D45: 14 | E45: 60 | F45: XT0120:1 | G45: GEN PNL
A46: AU0120:V+ | B46: FU0120 | C46: WHT | D46: 14 | E46: 60 | F46: FU0120:LD | G46: GEN PNL
A47: AF0121:V+ | B47: FU0121 | C47: WHT | D47: 14 | E47: 60 | F47: FU0121:LD | G47: GEN PNL
A49: KA0121:A1 | B49: -012101 | C49: WHT | D49: 20 | E49: 60 | F49: AF0121:01 | G49: GEN PNL | H49: KA A1
A50: KA0123:A1 | B50: -012103 | C50: WHT | D50: 20 | E50: 60 | F50: AF0121:03 | G50: GEN PNL
...

Sheet METER PNL_S 
A1: METER AND SWITCH^PANELS
A3: Project # | B3: J1640
A4: Project Name | B4: TALOS EW1003 PRINCE
A5: Revision | B5: 0.1
A7: Controls DE | B7: D.JOHN
A8: Phone:
A9: Controls ME | B9: A.ABENGOZA
A10: Phone:
A12: From | G12: To
A13: Device ID | B13: Wire No. | C13: Wire ID | D13: Gauge/Size | E13: Length | F13: Device ID | G13: Location | H13: Bundle Name
A14: PA0703:1 | B14: PA07714 | C14: BLU | D14: 16B | E14: 60 | F14: PA0771:4 | G14: METER PNL | H14: PA0703
A16: PV0700:7 | B16: PV07007 | C16: RED | D16: 16R | E16: 140 | F16: SA0710:11 | G16: SWITCH PNL | H16: PV0700-SWITCH
A17: PV0700:8 | B17: PV07008 | C17: RED | D17: 16R | E17: 140 | F17: SA0710:21 | G17: SWITCH PNL
A19: PA0703:2 | B19: PA07032 | C19: RED | D19: 16R | E19: 140 | F19: SA0770:26 | G19: SWITCH PNL | H19: PA0703 R-SWITCH
A20: PA0703:4 | B20: PA07034 | C20: RED | D20: 16R | E20: 140 | F20: SA0770:22 | G20: SWITCH PNL
A21: PA0703:6 | B21: PA07036 | C21: RED | D21: 16R | E21: 140 | F21: SA0770:12 | G21: SWITCH PNL
A22: PA0703:8 | B22: PA07038 | C22: RED | D22: 16R | E22: 140 | F22: SA0770:16 | G22: SWITCH PNL
A24: PF0701:8 | B24: VGENB | C24: RED | D24: 16R | E24: 140 | F24: SA0770:28 | G24: SWITCH PNL | H24: PF0701-SWITCH
A26: PA0700:8 | B26: MCTN | C26: BLU | D26: 16B | E26: 140 | F26: SA0740:21 | G26: SWITCH PNL | H26: PA0700-SWITCH
A27: PA0700:7 | B27: PA07007 | C27: BLU | D27: 16B | E27: 140 | F27: SA0740:11 | G27: SWITCH PNL
A29: PA0703:3 | B29: PA07033 | C29: BLU | D29: 16B | E29: 140 | F29: SA0740:12 | G29: SWITCH PNL | H29: PA0703 B-SWITCH
A30: PA0703:7 | B30: PA07037 | C30: BLU | D30: 16B | E30: 140 | F30: SA0740:24 | G30: SWITCH PNL
A32: PA0703:5 | B32: PA07035 | C32: BLU | D32: 16B | E32: 200 | F32: XT0342:1 | G32: GEN PNL | H32: PA0703-GEN
A34: PA0771:6 | B34: PA07716 | C34: BLU | D34: 16B | E34: 200 | F34: XT0342:4 | G34: GEN PNL | H34: PA0771-GEN
A36: PA0771:7 | B36: VGENB | C36: RED | D36: 16R | E36: 200 | F36: XT0341:4 | G36: GEN PNL
A37: PA0771:8 | B37: VGENC | C37: RED | D37: 16R | E37: 200 | F37: XT0341:6 | G37: GEN PNL
A39: PF0701:7 | B39: PF07017 | C39: RED | D39: 16R | E39: 200 | F39: KA0180:14 | G39: GEN PNL | H39: PF0701-GEN

Sheet SWITCH PNL_S
A1: SWITCH PANEL
A3: Project # | B3: J1640
A4: Project Name | B4: TALOS EW1003 PRINCE
A5: Revision | B5: 0.1
A7: Controls DE | B7: D.JOHN
A8: Phone:
A9: Controls ME | B9: A.ABENGOZA
A10: Phone:
A12: From | G12: To
A13: Device ID | B13: Wire No. | C13: Wire ID | D13: Gauge/Size | E13: Length | F13: Device ID | G13: Location | H13: Bundle Name
A14: SA0700:22 | B14: SA070022 | C14: WHT | D14: 16 | E14: 60 | F14: SA0701:13 | G14: SWITCH PNL | H14: SA0700
A16: HL0701: | B16: -0V | C16: WHT | D16: 16 | E16: 60 | F16: HL0702: | G16: SWITCH PNL | H16: HL0701
A18: HL0703: | B18: VBUSA | C18: RED | D18: 16R | E18: 80 | F18: PF0700:2 | G18: SWITCH PNL | H18: HL0703 RED
A19: HL0703: | B19: PF07008 | C19: RED | D19: 16R | E19: 80 | F19: SA0700:12 | G19: SWITCH PNL
A21: HL0704: | B21: VBUSC | C21: RED | D21: 16R | E21: 80 | F21: PF0700:1 | G21: SWITCH PNL | H21: HL0704 RED
A22: HL0704: | B22: PF07007 | C22: RED | D22: 16R | E22: 60 | F22: SA0700:16 | G22: SWITCH PNL
A24: SA0700:12 | B24: PF07008 | C24: RED | D24: 16R | E24: 80 | F24: PF0700:8 | G24: SWITCH PNL | H24: SA0700 RED
A25: SA0700:13 | B25: VGENA | C25: RED | D25: 16R | E25: 60 | F25: SA0770:18 | G25: SWITCH PNL
A26: SA0700:16 | B26: PF07007 | C26: RED | D26: 16R | E26: 80 | F26: PF0700:7 | G26: SWITCH PNL
A27: SA0700:17 | B27: VGENC | C27: RED | D27: 16R | E27: 60 | F27: SA0770:24 | G27: SWITCH PNL
A29: SA0710:12 | B29: VBUSA | C29: RED | D29: 16R | E29: 60 | F29: SA0710:24 | G29: SWITCH PNL | H29: SA0710 RED
A30: SA0710:13 | B30: VBUSC | C30: RED | D30: 16R | E30: 60 | F30: SA0710:14 | G30: SWITCH PNL
A31: SA0710:16 | B31: VGENA | C31: RED | D31: 16R | E31: 60 | F31: SA0710:28 | G31: SWITCH PNL
A32: SA0710:17 | B32: VGENC | C32: RED | D32: 16R | E32: 60 | F32: SA0710:18 | G32: SWITCH PNL
A33: SA0710:22 | B33: VBUSB | C33: RED | D33: 16R | E33: 60 | F33: SA0710:23 | G33: SWITCH PNL
A34: SA0710:26 | B34: VGENB | C34: RED | D34: 16R | E34: 60 | F34: SA0710:27 | G34: SWITCH PNL
A35: SA0710:28 | B35: VGENA | C35: RED | D35: 16R | E35: 60 | F35: SA0770:18 | G35: SWITCH PNL
A37: SA0770:14 | B37: VGENB | C37: RED | D37: 16R | E37: 60 | F37: SA0770:28 | G37: SWITCH PNL | H37: SA0770 RED
A39: SA0740:12 | B39: PA07033 | C39: BLU | D39: 16B | E39: 60 | F39: SA0740:22 | G39: SWITCH PNL | H39: SA0740 RED
A40: SA0740:13 | B40: SA074013 | C40: BLU | D40: 16B | E40: 60 | F40: SA0740:23 | G40: SWITCH PNL
A41: SA0740:14 | B41: PA07037 | C41: BLU | D41: 16B | E41: 60 | F41: SA0740:24 | G41: SWITCH PNL
A43: SA0710:16 | B43: VGENA | C43: RED | D43: 16R | E43: 120 | F43: TM0102:1 | G43: TRANSFORMER | H43: SA0710-TRAN.
A44: SA0710:17 | B44: VGENC | C44: RED | D44: 16R | E44: 120 | F44: TM0102:3 | G44: TRANSFORMER
A45: SA0710:26 | B45: VGENB | C45: RED | D45: 16R | E45: 120 | F45: TM0102:2 | G45: TRANSFORMER
A47: SA0770:13 | B47: TM01024 | C47: RED | D47: 16R | E47: 120 | F47: TM0102:4 | G47: TRANSFORMER | H47: SA0770-TRAN.
A48: SA0770:17 | B48: TM01025 | C48: RED | D48: 16R | E48: 120 | F48: TM0102:5 | G48: TRANSFORMER
A49: SA0770:23 | B49: TM01027 | C49: RED | D49: 16R | E49: 120 | F49: TM0102:7 | G49: TRANSFORMER
A50: SA0770:27 | B50: TM01026 | C50: RED | D50: 16R | E50: 120 | F50: TM0102:6 | G50: TRANSFORMER
A52: HL0701: | B52: KA9602NC | C52: WHT | D52: 16 | E52: 240 | F52: XT0343:3 | G52: GEN PNL | H52: HL0701-GEN
A54: HL0702: | B54: KA0330A1 | C54: WHT | D54: 16 | E54: 240 | F54: XT0343:4 | G54: GEN PNL | H54: HL0702-GEN
...

Sheet TCP_S
A1: TCP (DON’T DELETE)
A3: Project # | B3: J1640
A4: Project Name | B4: TALOS EW1003 PRINCE
A5: Revision | B5: 0.1
A7: Controls DE | B7: D.JOHN
A8: Phone:
A9: Controls ME | B9: A.ABENGOZA
A10: Phone:
A12: From | G12: To
A13: Device ID | B13: Wire No. | C13: Wire ID | D13: Gauge/Size | E13: Length | F13: Device ID | G13: Location | H13: Bundle Name
A14: SB0400:21 | B14: TCP18B1 | C14: WHT | D14: 20 | E14: 220 | F14: AF0081:37 | G14: A PNL | H14: SB-A
A15: SB0400:22 | B15: TCP18B2 | C15: WHT | D15: 20 | E15: 220 | F15: AF0081:05 | G15: A PNL
A17: AF0202:COM | B17: -0V1 | C17: WHT | D17: 14 | E17: 80 | F17: XT0562:1 | G17: PWR DIST RAIL | H17: AU/AF
A18: AU0200:COM | B18: -0V1 | C18: WHT | D18: 14 | E18: 80 | F18: XT0562:1 | G18: PWR DIST RAIL
A19: AU0200:V+ | B19: FU0200 | C19: WHT | D19: 14 | E19: 80 | F19: FU0200:LD | G19: PWR DIST RAIL
A20: AF0202:V+ | B20: FU0201 | C20: WHT | D20: 14 | E20: 80 | F20: FU0201:LD | G20: PWR DIST RAIL

Sheet Bundle Tag Info
A1: TALOS EW1003 #2
A2: J1640
A3: Rev. 0.1
A6: PWR DIST RAIL | B6: FS CONT. | C6: TURB VIB | D6: GEN VIB | E6: FS PNL | F6: PLC | G6: A PNL | H6: B PNL | I6: GEN PNL | J6: METER PNL | K6: SWITCH PNL | L6: TCP | M6: Panel Name | N6: Panel Name | O6: Panel Name | P6: Panel Name | Q6: Panel Name | R6: Panel Name | S6: Panel Name | T6: Panel Name | U6: Panel Name | V6: Panel Name | W6: Panel Name | X6: Panel Name | Y6: Panel Name | Z6: Panel Name | AA6: Panel Name | AB6: Panel Name | AC6: Panel Name | AD6: Panel Name
A7: AT0680 | B7: AT0170 | C7: 1444S | D7: AU/AF | E7: AT | F7: UV-A | G7: PC0470 | H7: AU/AF | I7: AT RED | J7: PA0703 | K7: SA0700 | L7: SB-A
A8: FU/XT | B8: KA | C8: FU | D8: KA A1/A2 | E8: KA A1/A2 | G8: AU/AF | H8: KA A1 | I8: AT BLU | J8: PV0700-SWITCH | K8: HL0701 | L8: AU/AF
A9: XT-A | B9: AT-FS PNL | C9: XT-A PNL | D9: FU/XT | E9: KA | G9: KA A1 | H9: KA A2 | I9: AT0140 | J9: PA0703 R-SWITCH | K9: HL0703 RED
A10: XT-B | B10: UV-FS PNL | D10: AF-GEN | E10: FU/XT | G10: KA A2 | H10: KA | I10: AU/AF | J10: PF0701-SWITCH | K10: HL0704 RED
B11: KA-FS PNL | D11: XT-GEN | E11: KA-A | G11: KA | H11: FU/XT | I11: KA A1 | J11: PA0700-SWITCH | K11: SA0700 RED
B12: KA-A | E12: KA-B | G12: KT R/S | H12: XT-GEN | I12: KA A2 | J12: PA0703 B-SWITCH | K12: SA0710 RED
B13: XT-A | E13: XT-B | G13: KT L/S | I13: KA | J13: PA0703-GEN | K13: SA0770 RED
B14: AT0170-B | G14: FU/XT | I14: KA RED | J14: PA0771-GEN | K14: SA0740 RED
B15: XT-B | G15: AF-B | I15: FU/XT | J15: PF0701-GEN | K15: SA0710-TRAN.
G16: KA A1/A2-B | I16: XT RED | K16: SA0770-TRAN.
G17: KA-B | K17: HL0701-GEN
G18: KT-B | K18: HL0702-GEN
G19: FU/XT-B | K19: SA0700-GEN
G20: XT-GEN | K20: SA0701-GEN
K21: HL0703 R-GEN
K22: HL0704 R-GEN
K23: SA0700 R-GEN
K24: SA0710 R-GEN
K25: SA0740 B-GEN
K26: SA0770 R-GEN

Sheet Bundle Tags2
A1: =IF('Bundle Tag Info'!A6<>"Panel Name",'Bundle Tag Info'!A6,"") -> PWR DIST RAIL | B1: =IF('Bundle Tag Info'!B6<>"Panel Name",'Bundle Tag Info'!B6,"") -> FS CONT. | C1: =IF('Bundle Tag Info'!C6<>"Panel Name",'Bundle Tag Info'!C6,"") -> TURB VIB | D1: =IF('Bundle Tag Info'!D6<>"Panel Name",'Bundle Tag Info'!D6,"") -> GEN VIB | E1: =IF('Bundle Tag Info'!E6<>"Panel Name",'Bundle Tag Info'!E6,"") -> FS PNL | F1: =IF('Bundle Tag Info'!F6<>"Panel Name",'Bundle Tag Info'!F6,"") -> PLC | G1: =IF('Bundle Tag Info'!G6<>"Panel Name",'Bundle Tag Info'!G6,"") -> A PNL | H1: =IF('Bundle Tag Info'!H6<>"Panel Name",'Bundle Tag Info'!H6,"") -> B PNL | ... AD1: =IF('Bundle Tag Info'!AD6<>"Panel Name",'Bundle Tag Info'!AD6,"")
A2: =IF('Bundle Tag Info'!A$7<>"",CONCATENATE('Bundle Tag Info'!$A$1," ",CHAR(10),'Bundle Tag Info'!$A$2," ",'Bundle Tag Info'!$A$3,CHAR(10),'Bundle Tag Info'!A$6,CHAR(10),'Bundle Tag Info'!A$7),"") -> TALOS EW1003 #2 J1640 Rev. 0.1 PWR DIST RAIL AT0680 | B2: =IF('Bundle Tag Info'!B$7<>"",CONCATENATE('Bundle Tag Info'!$A$1," ",CHAR(10),'Bundle Tag Info'!$A$2," ",'Bundle Tag Info'!$A$3,CHAR(10),'Bundle Tag Info'!B$6,CHAR(10),'Bundle Tag Info'!B$7),"") -> TALOS EW1003 #2 J1640 Rev. 0.1 FS CONT. AT0170 | C2: =IF('Bundle Tag Info'!C$7<>"",CONCATENATE('Bundle Tag Info'!$A$1," ",CHAR(10),'Bundle Tag Info'!$A$2," ",'Bundle Tag Info'!$A$3,CHAR(10),'Bundle Tag Info'!C$6,CHAR(10),'Bundle Tag Info'!C$7),"") -> TALOS EW1003 #2 J1640 Rev. 0.1 TURB VIB 1444S | D2: =IF('Bundle Tag Info'!D$7<>"",CONCATENATE('Bundle Tag Info'!$A$1," ",CHAR(10),'Bundle Tag Info'!$A$2," ",'Bundle Tag Info'!$A$3,CHAR(10),'Bundle Tag Info'!D$6,CHAR(10),'Bundle Tag Info'!D$7),"") -> TALOS EW1003 #2 J1640 Rev. 0.1 GEN VIB AU/AF | E2: =IF('Bundle Tag Info'!E$7<>"",CONCATENATE('Bundle Tag Info'!$A$1," ",CHAR(10),'Bundle Tag Info'!$A$2," ",'Bundle Tag Info'!$A$3,CHAR(10),'Bundle Tag Info'!E$6,CHAR(10),'Bundle Tag Info'!E$7),"") -> TALOS EW1003 #2 J1640 Rev. 0.1 FS PNL AT | F2: =IF('Bundle Tag Info'!F$7<>"",CONCATENATE('Bundle Tag Info'!$A$1," ",CHAR(10),'Bundle Tag Info'!$A$2," ",'Bundle Tag Info'!$A$3,CHAR(10),'Bundle Tag Info'!F$6,CHAR(10),'Bundle Tag Info'!F$7),"") -> TALOS EW1003 #2 J1640 Rev. 0.1 PLC UV-A | G2: =IF('Bundle Tag Info'!G$7<>"",CONCATENATE('Bundle Tag Info'!$A$1," ",CHAR(10),'Bundle Tag Info'!$A$2," ",'Bundle Tag Info'!$A$3,CHAR(10),'Bundle Tag Info'!G$6,CHAR(10),'Bundle Tag Info'!G$7),"") -> TALOS EW1003 #2 J1640 Rev. 0.1 A PNL PC0470 | H2: =IF('Bundle Tag Info'!H$7<>"",CONCATENATE('Bundle Tag Info'!$A$1," ",CHAR(10),'Bundle Tag Info'!$A$2," ",'Bundle Tag Info'!$A$3,CHAR(10),'Bundle Tag Info'!H$6,CHAR(10),'Bundle Tag Info'!H$7),"") -> TALOS EW1003 #2 J1640 Rev. 0.1 B PNL AU/AF | ... AD2: =IF('Bundle Tag Info'!AD$7<>"",CONCATENATE('Bundle Tag Info'!$A$1," ",CHAR(10),'Bundle Tag Info'!$A$2," ",'Bundle Tag Info'!$A$3,CHAR(10),'Bundle Tag Info'!AD$6,CHAR(10),'Bundle Tag Info'!AD$7),"")
A3: =IF('Bundle Tag Info'!A$8<>"",CONCATENATE('Bundle Tag Info'!$A$1," ",CHAR(10),'Bundle Tag Info'!$A$2," ",'Bundle Tag Info'!$A$3,CHAR(10),'Bundle Tag Info'!A$6,CHAR(10),'Bundle Tag Info'!A$8),"") -> TALOS EW1003 #2 J1640 Rev. 0.1 PWR DIST RAIL FU/XT | B3: =IF('Bundle Tag Info'!B$8<>"",CONCATENATE('Bundle Tag Info'!$A$1," ",CHAR(10),'Bundle Tag Info'!$A$2," ",'Bundle Tag Info'!$A$3,CHAR(10),'Bundle Tag Info'!B$6,CHAR(10),'Bundle Tag Info'!B$8),"") -> TALOS EW1003 #2 J1640 Rev. 0.1 FS CONT. KA | C3: =IF('Bundle Tag Info'!C$8<>"",CONCATENATE('Bundle Tag Info'!$A$1," ",CHAR(10),'Bundle Tag Info'!$A$2," ",'Bundle Tag Info'!$A$3,CHAR(10),'Bundle Tag Info'!C$6,CHAR(10),'Bundle Tag Info'!C$8),"") -> TALOS EW1003 #2 J1640 Rev. 0.1 TURB VIB FU | D3: =IF('Bundle Tag Info'!D$8<>"",CONCATENATE('Bundle Tag Info'!$A$1," ",CHAR(10),'Bundle Tag Info'!$A$2," ",'Bundle Tag Info'!$A$3,CHAR(10),'Bundle Tag Info'!D$6,CHAR(10),'Bundle Tag Info'!D$8),"") -> TALOS EW1003 #2 J1640 Rev. 0.1 GEN VIB KA A1/A2 | E3: =IF('Bundle Tag Info'!E$8<>"",CONCATENATE('Bundle Tag Info'!$A$1," ",CHAR(10),'Bundle Tag Info'!$A$2," ",'Bundle Tag Info'!$A$3,CHAR(10),'Bundle Tag Info'!E$6,CHAR(10),'Bundle Tag Info'!E$8),"") -> TALOS EW1003 #2 J1640 Rev. 0.1 FS PNL KA A1/A2 | F3: =IF('Bundle Tag Info'!F$8<>"",CONCATENATE('Bundle Tag Info'!$A$1," ",CHAR(10),'Bundle Tag Info'!$A$2," ",'Bundle Tag Info'!$A$3,CHAR(10),'Bundle Tag Info'!F$6,CHAR(10),'Bundle Tag Info'!F$8),"") | G3: =IF('Bundle Tag Info'!G$8<>"",CONCATENATE('Bundle Tag Info'!$A$1," ",CHAR(10),'Bundle Tag Info'!$A$2," ",'Bundle Tag Info'!$A$3,CHAR(10),'Bundle Tag Info'!G$6,CHAR(10),'Bundle Tag Info'!G$8),"") -> TALOS EW1003 #2 J1640 Rev. 0.1 A PNL AU/AF | H3: =IF('Bundle Tag Info'!H$8<>"",CONCATENATE('Bundle Tag Info'!$A$1," ",CHAR(10),'Bundle Tag Info'!$A$2," ",'Bundle Tag Info'!$A$3,CHAR(10),'Bundle Tag Info'!H$6,CHAR(10),'Bundle Tag Info'!H$8),"") -> TALOS EW1003 #2 J1640 Rev. 0.1 B PNL KA A1 | ... AD3: =IF('Bundle Tag Info'!AD$8<>"",CONCATENATE('Bundle Tag Info'!$A$1," ",CHAR(10),'Bundle Tag Info'!$A$2," ",'Bundle Tag Info'!$A$3,CHAR(10),'Bundle Tag Info'!AD$6,CHAR(10),'Bundle Tag Info'!AD$8),"")
A4: =IF('Bundle Tag Info'!A$9<>"",CONCATENATE('Bundle Tag Info'!$A$1," ",CHAR(10),'Bundle Tag Info'!$A$2," ",'Bundle Tag Info'!$A$3,CHAR(10),'Bundle Tag Info'!A$6,CHAR(10),'Bundle Tag Info'!A$9),"") -> TALOS EW1003 #2 J1640 Rev. 0.1 PWR DIST RAIL XT-A | B4: =IF('Bundle Tag Info'!B$9<>"",CONCATENATE('Bundle Tag Info'!$A$1," ",CHAR(10),'Bundle Tag Info'!$A$2," ",'Bundle Tag Info'!$A$3,CHAR(10),'Bundle Tag Info'!B$6,CHAR(10),'Bundle Tag Info'!B$9),"") -> TALOS EW1003 #2 J1640 Rev. 0.1 FS CONT. AT-FS PNL | C4: =IF('Bundle Tag Info'!C$9<>"",CONCATENATE('Bundle Tag Info'!$A$1," ",CHAR(10),'Bundle Tag Info'!$A$2," ",'Bundle Tag Info'!$A$3,CHAR(10),'Bundle Tag Info'!C$6,CHAR(10),'Bundle Tag Info'!C$9),"") -> TALOS EW1003 #2 J1640 Rev. 0.1 TURB VIB XT-A PNL | D4: =IF('Bundle Tag Info'!D$9<>"",CONCATENATE('Bundle Tag Info'!$A$1," ",CHAR(10),'Bundle Tag Info'!$A$2," ",'Bundle Tag Info'!$A$3,CHAR(10),'Bundle Tag Info'!D$6,CHAR(10),'Bundle Tag Info'!D$9),"") -> TALOS EW1003 #2 J1640 Rev. 0.1 GEN VIB FU/XT | E4: =IF('Bundle Tag Info'!E$9<>"",CONCATENATE('Bundle Tag Info'!$A$1," ",CHAR(10),'Bundle Tag Info'!$A$2," ",'Bundle Tag Info'!$A$3,CHAR(10),'Bundle Tag Info'!E$6,CHAR(10),'Bundle Tag Info'!E$9),"") -> TALOS EW1003 #2 J1640 Rev. 0.1 FS PNL KA | F4: =IF('Bundle Tag Info'!F$9<>"",CONCATENATE('Bundle Tag Info'!$A$1," ",CHAR(10),'Bundle Tag Info'!$A$2," ",'Bundle Tag Info'!$A$3,CHAR(10),'Bundle Tag Info'!F$6,CHAR(10),'Bundle Tag Info'!F$9),"") | G4: =IF('Bundle Tag Info'!G$9<>"",CONCATENATE('Bundle Tag Info'!$A$1," ",CHAR(10),'Bundle Tag Info'!$A$2," ",'Bundle Tag Info'!$A$3,CHAR(10),'Bundle Tag Info'!G$6,CHAR(10),'Bundle Tag Info'!G$9),"") -> TALOS EW1003 #2 J1640 Rev. 0.1 A PNL KA A1 | H4: =IF('Bundle Tag Info'!H$9<>"",CONCATENATE('Bundle Tag Info'!$A$1," ",CHAR(10),'Bundle Tag Info'!$A$2," ",'Bundle Tag Info'!$A$3,CHAR(10),'Bundle Tag Info'!H$6,CHAR(10),'Bundle Tag Info'!H$9),"") -> TALOS EW1003 #2 J1640 Rev. 0.1 B PNL KA A2 | ... AD4: =IF('Bundle Tag Info'!AD$9<>"",CONCATENATE('Bundle Tag Info'!$A$1," ",CHAR(10),'Bundle Tag Info'!$A$2," ",'Bundle Tag Info'!$A$3,CHAR(10),'Bundle Tag Info'!AD$6,CHAR(10),'Bundle Tag Info'!AD$9),"")
A5: =IF('Bundle Tag Info'!A$10<>"",CONCATENATE('Bundle Tag Info'!$A$1," ",CHAR(10),'Bundle Tag Info'!$A$2," ",'Bundle Tag Info'!$A$3,CHAR(10),'Bundle Tag Info'!A$6,CHAR(10),'Bundle Tag Info'!A$10),"") -> TALOS EW1003 #2 J1640 Rev. 0.1 PWR DIST RAIL XT-B | B5: =IF('Bundle Tag Info'!B$10<>"",CONCATENATE('Bundle Tag Info'!$A$1," ",CHAR(10),'Bundle Tag Info'!$A$2," ",'Bundle Tag Info'!$A$3,CHAR(10),'Bundle Tag Info'!B$6,CHAR(10),'Bundle Tag Info'!B$10),"") -> TALOS EW1003 #2 J1640 Rev. 0.1 FS CONT. UV-FS PNL | C5: =IF('Bundle Tag Info'!C$10<>"",CONCATENATE('Bundle Tag Info'!$A$1," ",CHAR(10),'Bundle Tag Info'!$A$2," ",'Bundle Tag Info'!$A$3,CHAR(10),'Bundle Tag Info'!C$6,CHAR(10),'Bundle Tag Info'!C$10),"") | D5: =IF('Bundle Tag Info'!D$10<>"",CONCATENATE('Bundle Tag Info'!$A$1," ",CHAR(10),'Bundle Tag Info'!$A$2," ",'Bundle Tag Info'!$A$3,CHAR(10),'Bundle Tag Info'!D$6,CHAR(10),'Bundle Tag Info'!D$10),"") -> TALOS EW1003 #2 J1640 Rev. 0.1 GEN VIB AF-GEN | E5: =IF('Bundle Tag Info'!E$10<>"",CONCATENATE('Bundle Tag Info'!$A$1," ",CHAR(10),'Bundle Tag Info'!$A$2," ",'Bundle Tag Info'!$A$3,CHAR(10),'Bundle Tag Info'!E$6,CHAR(10),'Bundle Tag Info'!E$10),"") -> TALOS EW1003 #2 J1640 Rev. 0.1 FS PNL FU/XT | F5: =IF('Bundle Tag Info'!F$10<>"",CONCATENATE('Bundle Tag Info'!$A$1," ",CHAR(10),'Bundle Tag Info'!$A$2," ",'Bundle Tag Info'!$A$3,CHAR(10),'Bundle Tag Info'!F$6,CHAR(10),'Bundle Tag Info'!F$10),"") | G5: =IF('Bundle Tag Info'!G$10<>"",CONCATENATE('Bundle Tag Info'!$A$1," ",CHAR(10),'Bundle Tag Info'!$A$2," ",'Bundle Tag Info'!$A$3,CHAR(10),'Bundle Tag Info'!G$6,CHAR(10),'Bundle Tag Info'!G$10),"") -> TALOS EW1003 #2 J1640 Rev. 0.1 A PNL KA A2 | H5: =IF('Bundle Tag Info'!H$10<>"",CONCATENATE('Bundle Tag Info'!$A$1," ",CHAR(10),'Bundle Tag Info'!$A$2," ",'Bundle Tag Info'!$A$3,CHAR(10),'Bundle Tag Info'!H$6,CHAR(10),'Bundle Tag Info'!H$10),"") -> TALOS EW1003 #2 J1640 Rev. 0.1 B PNL KA | ... AD5: =IF('Bundle Tag Info'!AD$10<>"",CONCATENATE('Bundle Tag Info'!$A$1," ",CHAR(10),'Bundle Tag Info'!$A$2," ",'Bundle Tag Info'!$A$3,CHAR(10),'Bundle Tag Info'!AD$6,CHAR(10),'Bundle Tag Info'!AD$10),"")
A6: =IF('Bundle Tag Info'!A$11<>"",CONCATENATE('Bundle Tag Info'!$A$1," ",CHAR(10),'Bundle Tag Info'!$A$2," ",'Bundle Tag Info'!$A$3,CHAR(10),'Bundle Tag Info'!A$6,CHAR(10),'Bundle Tag Info'!A$11),"") | B6: =IF('Bundle Tag Info'!B$11<>"",CONCATENATE('Bundle Tag Info'!$A$1," ",CHAR(10),'Bundle Tag Info'!$A$2," ",'Bundle Tag Info'!$A$3,CHAR(10),'Bundle Tag Info'!B$6,CHAR(10),'Bundle Tag Info'!B$11),"") -> TALOS EW1003 #2 J1640 Rev. 0.1 FS CONT. KA-FS PNL | C6: =IF('Bundle Tag Info'!C$11<>"",CONCATENATE('Bundle Tag Info'!$A$1," ",CHAR(10),'Bundle Tag Info'!$A$2," ",'Bundle Tag Info'!$A$3,CHAR(10),'Bundle Tag Info'!C$6,CHAR(10),'Bundle Tag Info'!C$11),"") | D6: =IF('Bundle Tag Info'!D$11<>"",CONCATENATE('Bundle Tag Info'!$A$1," ",CHAR(10),'Bundle Tag Info'!$A$2," ",'Bundle Tag Info'!$A$3,CHAR(10),'Bundle Tag Info'!D$6,CHAR(10),'Bundle Tag Info'!D$11),"") -> TALOS EW1003 #2 J1640 Rev. 0.1 GEN VIB XT-GEN | E6: =IF('Bundle Tag Info'!E$11<>"",CONCATENATE('Bundle Tag Info'!$A$1," ",CHAR(10),'Bundle Tag Info'!$A$2," ",'Bundle Tag Info'!$A$3,CHAR(10),'Bundle Tag Info'!E$6,CHAR(10),'Bundle Tag Info'!E$11),"") -> TALOS EW1003 #2 J1640 Rev. 0.1 FS PNL KA-A | F6: =IF('Bundle Tag Info'!F$11<>"",CONCATENATE('Bundle Tag Info'!$A$1," ",CHAR(10),'Bundle Tag Info'!$A$2," ",'Bundle Tag Info'!$A$3,CHAR(10),'Bundle Tag Info'!F$6,CHAR(10),'Bundle Tag Info'!F$11),"") | G6: =IF('Bundle Tag Info'!G$11<>"",CONCATENATE('Bundle Tag Info'!$A$1," ",CHAR(10),'Bundle Tag Info'!$A$2," ",'Bundle Tag Info'!$A$3,CHAR(10),'Bundle Tag Info'!G$6,CHAR(10),'Bundle Tag Info'!G$11),"") -> TALOS EW1003 #2 J1640 Rev. 0.1 A PNL KA | H6: =IF('Bundle Tag Info'!H$11<>"",CONCATENATE('Bundle Tag Info'!$A$1," ",CHAR(10),'Bundle Tag Info'!$A$2," ",'Bundle Tag Info'!$A$3,CHAR(10),'Bundle Tag Info'!H$6,CHAR(10),'Bundle Tag Info'!H$11),"") -> TALOS EW1003 #2 J1640 Rev. 0.1 B PNL FU/XT | ... AD6: =IF('Bundle Tag Info'!AD$11<>"",CONCATENATE('Bundle Tag Info'!$A$1," ",CHAR(10),'Bundle Tag Info'!$A$2," ",'Bundle Tag Info'!$A$3,CHAR(10),'Bundle Tag Info'!AD$6,CHAR(10),'Bundle Tag Info'!AD$11),"")
A7: =IF('Bundle Tag Info'!A$12<>"",CONCATENATE('Bundle Tag Info'!$A$1," ",CHAR(10),'Bundle Tag Info'!$A$2," ",'Bundle Tag Info'!$A$3,CHAR(10),'Bundle Tag Info'!A$6,CHAR(10),'Bundle Tag Info'!A$12),"") | B7: =IF('Bundle Tag Info'!B$12<>"",CONCATENATE('Bundle Tag Info'!$A$1," ",CHAR(10),'Bundle Tag Info'!$A$2," ",'Bundle Tag Info'!$A$3,CHAR(10),'Bundle Tag Info'!B$6,CHAR(10),'Bundle Tag Info'!B$12),"") -> TALOS EW1003 #2 J1640 Rev. 0.1 FS CONT. KA-A | C7: =IF('Bundle Tag Info'!C$12<>"",CONCATENATE('Bundle Tag Info'!$A$1," ",CHAR(10),'Bundle Tag Info'!$A$2," ",'Bundle Tag Info'!$A$3,CHAR(10),'Bundle Tag Info'!C$6,CHAR(10),'Bundle Tag Info'!C$12),"") | D7: =IF('Bundle Tag Info'!D$12<>"",CONCATENATE('Bundle Tag Info'!$A$1," ",CHAR(10),'Bundle Tag Info'!$A$2," ",'Bundle Tag Info'!$A$3,CHAR(10),'Bundle Tag Info'!D$6,CHAR(10),'Bundle Tag Info'!D$12),"") | E7: =IF('Bundle Tag Info'!E$12<>"",CONCATENATE('Bundle Tag Info'!$A$1," ",CHAR(10),'Bundle Tag Info'!$A$2," ",'Bundle Tag Info'!$A$3,CHAR(10),'Bundle Tag Info'!E$6,CHAR(10),'Bundle Tag Info'!E$12),"") -> TALOS EW1003 #2 J1640 Rev. 0.1 FS PNL KA-B | F7: =IF('Bundle Tag Info'!F$12<>"",CONCATENATE('Bundle Tag Info'!$A$1," ",CHAR(10),'Bundle Tag Info'!$A$2," ",'Bundle Tag Info'!$A$3,CHAR(10),'Bundle Tag Info'!F$6,CHAR(10),'Bundle Tag Info'!F$12),"") | G7: =IF('Bundle Tag Info'!G$12<>"",CONCATENATE('Bundle Tag Info'!$A$1," ",CHAR(10),'Bundle Tag Info'!$A$2," ",'Bundle Tag Info'!$A$3,CHAR(10),'Bundle Tag Info'!G$6,CHAR(10),'Bundle Tag Info'!G$12),"") -> TALOS EW1003 #2 J1640 Rev. 0.1 A PNL KT R/S | H7: =IF('Bundle Tag Info'!H$12<>"",CONCATENATE('Bundle Tag Info'!$A$1," ",CHAR(10),'Bundle Tag Info'!$A$2," ",'Bundle Tag Info'!$A$3,CHAR(10),'Bundle Tag Info'!H$6,CHAR(10),'Bundle Tag Info'!H$12),"") -> TALOS EW1003 #2 J1640 Rev. 0.1 B PNL XT-GEN | ... AD7: =IF('Bundle Tag Info'!AD$12<>"",CONCATENATE('Bundle Tag Info'!$A$1," ",CHAR(10),'Bundle Tag Info'!$A$2," ",'Bundle Tag Info'!$A$3,CHAR(10),'Bundle Tag Info'!AD$6,CHAR(10),'Bundle Tag Info'!AD$12),"")
A8: =IF('Bundle Tag Info'!A$13<>"",CONCATENATE('Bundle Tag Info'!$A$1," ",CHAR(10),'Bundle Tag Info'!$A$2," ",'Bundle Tag Info'!$A$3,CHAR(10),'Bundle Tag Info'!A$6,CHAR(10),'Bundle Tag Info'!A$13),"") | B8: =IF('Bundle Tag Info'!B$13<>"",CONCATENATE('Bundle Tag Info'!$A$1," ",CHAR(10),'Bundle Tag Info'!$A$2," ",'Bundle Tag Info'!$A$3,CHAR(10),'Bundle Tag Info'!B$6,CHAR(10),'Bundle Tag Info'!B$13),"") -> TALOS EW1003 #2 J1640 Rev. 0.1 FS CONT. XT-A | C8: =IF('Bundle Tag Info'!C$13<>"",CONCATENATE('Bundle Tag Info'!$A$1," ",CHAR(10),'Bundle Tag Info'!$A$2," ",'Bundle Tag Info'!$A$3,CHAR(10),'Bundle Tag Info'!C$6,CHAR(10),'Bundle Tag Info'!C$13),"") | D8: =IF('Bundle Tag Info'!D$13<>"",CONCATENATE('Bundle Tag Info'!$A$1," ",CHAR(10),'Bundle Tag Info'!$A$2," ",'Bundle Tag Info'!$A$3,CHAR(10),'Bundle Tag Info'!D$6,CHAR(10),'Bundle Tag Info'!D$13),"") | E8: =IF('Bundle Tag Info'!E$13<>"",CONCATENATE('Bundle Tag Info'!$A$1," ",CHAR(10),'Bundle Tag Info'!$A$2," ",'Bundle Tag Info'!$A$3,CHAR(10),'Bundle Tag Info'!E$6,CHAR(10),'Bundle Tag Info'!E$13),"") -> TALOS EW1003 #2 J1640 Rev. 0.1 FS PNL XT-B | F8: =IF('Bundle Tag Info'!F$13<>"",CONCATENATE('Bundle Tag Info'!$A$1," ",CHAR(10),'Bundle Tag Info'!$A$2," ",'Bundle Tag Info'!$A$3,CHAR(10),'Bundle Tag Info'!F$6,CHAR(10),'Bundle Tag Info'!F$13),"") | G8: =IF('Bundle Tag Info'!G$13<>"",CONCATENATE('Bundle Tag Info'!$A$1," ",CHAR(10),'Bundle Tag Info'!$A$2," ",'Bundle Tag Info'!$A$3,CHAR(10),'Bundle Tag Info'!G$6,CHAR(10),'Bundle Tag Info'!G$13),"") -> TALOS EW1003 #2 J1640 Rev. 0.1 A PNL KT L/S | H8: =IF('Bundle Tag Info'!H$13<>"",CONCATENATE('Bundle Tag Info'!$A$1," ",CHAR(10),'Bundle Tag Info'!$A$2," ",'Bundle Tag Info'!$A$3,CHAR(10),'Bundle Tag Info'!H$6,CHAR(10),'Bundle Tag Info'!H$13),"") | ... AD8: =IF('Bundle Tag Info'!AD$13<>"",CONCATENATE('Bundle Tag Info'!$A$1," ",CHAR(10),'Bundle Tag Info'!$A$2," ",'Bundle Tag Info'!$A$3,CHAR(10),'Bundle Tag Info'!AD$6,CHAR(10),'Bundle Tag Info'!AD$13),"")
A9: =IF('Bundle Tag Info'!A$14<>"",CONCATENATE('Bundle Tag Info'!$A$1," ",CHAR(10),'Bundle Tag Info'!$A$2," ",'Bundle Tag Info'!$A$3,CHAR(10),'Bundle Tag Info'!A$6,CHAR(10),'Bundle Tag Info'!A$14),"") | B9: =IF('Bundle Tag Info'!B$14<>"",CONCATENATE('Bundle Tag Info'!$A$1," ",CHAR(10),'Bundle Tag Info'!$A$2," ",'Bundle Tag Info'!$A$3,CHAR(10),'Bundle Tag Info'!B$6,CHAR(10),'Bundle Tag Info'!B$14),"") -> TALOS EW1003 #2 J1640 Rev. 0.1 FS CONT. AT0170-B | C9: =IF('Bundle Tag Info'!C$14<>"",CONCATENATE('Bundle Tag Info'!$A$1," ",CHAR(10),'Bundle Tag Info'!$A$2," ",'Bundle Tag Info'!$A$3,CHAR(10),'Bundle Tag Info'!C$6,CHAR(10),'Bundle Tag Info'!C$14),"") | D9: =IF('Bundle Tag Info'!D$14<>"",CONCATENATE('Bundle Tag Info'!$A$1," ",CHAR(10),'Bundle Tag Info'!$A$2," ",'Bundle Tag Info'!$A$3,CHAR(10),'Bundle Tag Info'!D$6,CHAR(10),'Bundle Tag Info'!D$14),"") | E9: =IF('Bundle Tag Info'!E$14<>"",CONCATENATE('Bundle Tag Info'!$A$1," ",CHAR(10),'Bundle Tag Info'!$A$2," ",'Bundle Tag Info'!$A$3,CHAR(10),'Bundle Tag Info'!E$6,CHAR(10),'Bundle Tag Info'!E$14),"") | F9: =IF('Bundle Tag Info'!F$14<>"",CONCATENATE('Bundle Tag Info'!$A$1," ",CHAR(10),'Bundle Tag Info'!$A$2," ",'Bundle Tag Info'!$A$3,CHAR(10),'Bundle Tag Info'!F$6,CHAR(10),'Bundle Tag Info'!F$14),"") | G9: =IF('Bundle Tag Info'!G$14<>"",CONCATENATE('Bundle Tag Info'!$A$1," ",CHAR(10),'Bundle Tag Info'!$A$2," ",'Bundle Tag Info'!$A$3,CHAR(10),'Bundle Tag Info'!G$6,CHAR(10),'Bundle Tag Info'!G$14),"") -> TALOS EW1003 #2 J1640 Rev. 0.1 A PNL FU/XT | H9: =IF('Bundle Tag Info'!H$14<>"",CONCATENATE('Bundle Tag Info'!$A$1," ",CHAR(10),'Bundle Tag Info'!$A$2," ",'Bundle Tag Info'!$A$3,CHAR(10),'Bundle Tag Info'!H$6,CHAR(10),'Bundle Tag Info'!H$14),"") | ... AD9: =IF('Bundle Tag Info'!AD$14<>"",CONCATENATE('Bundle Tag Info'!$A$1," ",CHAR(10),'Bundle Tag Info'!$A$2," ",'Bundle Tag Info'!$A$3,CHAR(10),'Bundle Tag Info'!AD$6,CHAR(10),'Bundle Tag Info'!AD$14),"")
