Workbook

Sheet Blue Labels
A1: (SHT 1) LER 1 | B1: (SHT 2) LER 1 ESTOP | C1: (SHT 3) LER,PNL,REAR | D1: (SHT 4) LER,PNL,LFT
A2: EL0273 | B2: SB0500 | C2: FU7040 | D2: XT1036
A3: ZS0273 | C3: BA7040 | D3: XT0136
A4: FG0273 | C4: BA7041 | D4: KA0210
C5: BA7042 | D5: KA0211
C6: BA7140 | D6: KA0212
C7: BA7141 | D7: KA0213
C8: FU0103 | D8: KA0215
C9: FU0104 | D9: KA0216
C10: FU0105 | D10: KA0217
C11: FU0106 | D11: KA0218
C12: XT0090 | D12: KA0600
C13: GR1033 | D13: KA0601
C14: KA0530 | D14: KA0602
C15: KA0531 | D15: KA0603
C16: KA0532 | D16: KA0604
... C45: PEG0260 | D45: KA0271
D46: KA0607
D47: KA0608
D48: KA0610
D49: KA0611
D50: KA0612
D51: KA0613
D52: KA0291
D53: KA0292
D54: KA0293
D55: KA0391
D56: KA0392
D57: KA0393
... D59: GR0265

Sheet White Labels
A1: (SHT 4) LER,PNL,LFT - (SHT 3) LER,PNL,REAR | B1: (SHT 3) LER,PNL,REAR
A2: AF0109G | B2: IEG02601
A3: IEG02603
A4: IEG02604G

Sheet Heat Shrink Labels

Sheet LER 1
A1: LER 1
A2: LER 1 RIO CONSOLE
A3: Project # | B3: 4M037
A4: Project Name | B4: Bayrunner Pipeline
A5: Revision | B5: 0.1
A7: Controls DE | B7: ALEX. JEZEQUEL
A8: Phone:
A9: Controls ME | B9: HECTOR, MEDRANO
A10: Phone:
A12: From | G12: To
A13: Device ID | B13: Cable (W) Conductor (SC) Jumper Clip (JC) | C13: Wire No. | D13: Wire ID | E13: Gauge/Size | F13: Page/Zone | G13: Device ID | H13: Location | I13: Page/Zone
A14: EL0273:B1 | B14: SC | C14: ZS0273 | D14: WHT | E14: 14 | F14: 5.C3 | G14: ZS0273:2 | H14: LER 1 | I14: 5.C2 | M14: USED
A15: EL0273:W1 | B15: SC | C15: 0V1 | D15: WHT | E15: 14 | F15: 5.C3 | G15: XT0262:4 | H15: LER,PNL,REAR | I15: 5.C4 | M15: USED
A16: ZS0273:1 | B16: SC | C16: FU0273 | D16: WHT | E16: 14 | F16: 5.C2 | G16: FU0273:LD | H16: LER,PNL,REAR | I16: 5.C2 | M16: USED
F18: SolarTools ver. 24.0.84.24712 (Jul 31, 2025)
A19: Report date: 2/13/2026 1:25 PM

Sheet LER 1 ESTOP
A1: LER 1 ESTOP
A2: LER 1 RIO CONSOLE ESTOP DOOR PANEL
A3: Project # | B3: 4M037
A4: Project Name | B4: Bayrunner Pipeline
A5: Revision | B5: 0.1
A7: Controls DE | B7: ALEX. JEZEQUEL
A8: Phone:
A9: Controls ME | B9: HECTOR, MEDRANO
A10: Phone:
A12: From | G12: To
A13: Device ID | B13: Cable (W) Conductor (SC) Jumper Clip (JC) | C13: Wire No. | D13: Wire ID | E13: Gauge/Size | F13: Page/Zone | G13: Device ID | H13: Location | I13: Page/Zone
A14: SB0500:B1-11 | B14: SC | C14: SB0500B111 | D14: WHT | E14: 20 | F14: 8.D5 | G14: XT1036:3 | H14: LER,PNL,LFT | I14: 8.D6 | M14: USED
A15: SB0500:B1-12 | B15: SC | C15: SB0500B112 | D15: WHT | E15: 20 | F15: 8.D5 | G15: XT1036:4 | H15: LER,PNL,LFT | I15: 8.D6 | M15: USED
A16: SB0500:B2-11 | B16: SC | C16: ESTOP2 | D16: WHT | E16: 20 | F16: 8.D5 | G16: XT1036:1 | H16: LER,PNL,LFT | I16: 8.D5 | M16: USED
A17: SB0500:B2-12 | B17: SC | C17: ESTOP3 | D17: WHT | E17: 20 | F17: 8.D5 | G17: XT1036:2 | H17: LER,PNL,LFT | I17: 8.D5 | M17: USED
F19: SolarTools ver. 24.0.84.24712 (Jul 31, 2025)
A20: Report date: 2/13/2026 1:25 PM

Sheet LER,PNL,LFT
A1: LER,PNL,LFT
A2: LER 1 RIO CONSOLE PANEL^LEFT SIDE PANEL
A3: Project # | B3: 4M037
A4: Project Name | B4: Bayrunner Pipeline
A5: Revision | B5: 0.1
A7: Controls DE | B7: ALEX. JEZEQUEL
A8: Phone:
A9: Controls ME | B9: HECTOR, MEDRANO
A10: Phone:
A12: From | G12: To
A13: Device ID | B13: Cable (W) Conductor (SC) Jumper Clip (JC) | C13: Wire No. | D13: Wire ID | E13: Gauge/Size | F13: Page/Zone | G13: Device ID | H13: Location | I13: Page/Zone
A14: XT0100:1 | B14: JC | C14: 0V1 | D14: CLIP | E14: --- | F14: 6.B1 | G14: XT0100:2 | H14: LER,PNL,LFT | I14: 6.B1 | M14: USED
A15: XT0100:2 | B15: JC | C15: 0V1 | D15: CLIP | E15: --- | F15: 6.B1 | G15: XT0100:3 | H15: LER,PNL,LFT | I15: 6.B1 | M15: USED
A16: XT0536:1 | B16: JC | C16: FU0190 | D16: CLIP | E16: --- | F16: 7.A2 | G16: XT0536:2 | H16: LER,PNL,LFT | I16: 7.B2 | M16: USED
A17: XT0536:10 | B17: JC | C17: KA023624 | D17: CLIP | E17: --- | F17: 7.A3 | G17: XT0536:11 | H17: LER,PNL,LFT | I17: 7.A4 | M17: USED
A18: XT0536:2 | B18: JC | C18: FU0190 | D18: CLIP | E18: --- | F18: 7.B2 | G18: XT0536:3 | H18: LER,PNL,LFT | I18: 7.B2 | M18: USED
A19: XT0536:3 | B19: JC | C19: FU0190 | D19: CLIP | E19: --- | F19: 7.B2 | G19: XT0536:4 | H19: LER,PNL,LFT | I19: 7.C2 | M19: USED
A20: XT0536:5 | B20: JC | C20: 0V1 | D20: CLIP | E20: --- | F20: 7.A6 | G20: XT0536:6 | H20: LER,PNL,LFT | I20: 7.B6 | M20: USED
A21: XT0536:6 | B21: JC | C21: 0V1 | D21: CLIP | E21: --- | F21: 7.B6 | G21: XT0536:7 | H21: LER,PNL,LFT | I21: 7.B6 | M21: USED
A22: XT0536:7 | B22: JC | C22: 0V1 | D22: CLIP | E22: --- | F22: 7.B6 | G22: XT0536:8 | H22: LER,PNL,LFT | I22: 7.C6 | M22: USED
A23: KA0600:A1 | B23: SC | C23: KA0600A1 | D23: WHT | E23: 20 | F23: 26.C7 | G23: AF0101:00 | H23: LER,PNL,LFT | I23: 26.C6 | M23: USED
A24: KA0601:A1 | B24: SC | C24: KA0601A1 | D24: WHT | E24: 20 | F24: 23.B7 | G24: AF0101:02 | H24: LER,PNL,LFT | I24: 23.B6 | M24: USED
A25: KA0602:A1 | B25: SC | C25: KA0602A1 | D25: WHT | E25: 20 | F25: 24.B7 | G25: AF0101:04 | H25: LER,PNL,LFT | I25: 24.B6 | M25: USED
... A165: KT0555:A1 | B165: SC | C165: ZSC11712 | D165: WHT | E165: 20 | F165: 14.B5 | G165: XT0265:20 | H165: LER,PNL,LFT | I165: 14.B5 | M165: USED
A166: VD0231:--1N4005/1 | B166: SC | C166: KA021521 | D166: LEAD | F166: 9.C4 | G166: XT0136:4 | H166: LER,PNL,LFT | I166: 9.C4 | M166: USED
A167: VD0231:+-1N4005/1 | B167: SC | C167: KT055416 | D167: LEAD | F167: 9.C4 | G167: XT0136:3 | H167: LER,PNL,LFT | I167: 9.C3 | M167: USED
A168: VD0232:--1N4005/1 | B168: SC | C168: KA021521 | D168: LEAD | F168: 9.C4 | G168: XT0136:6 | H168: LER,PNL,LFT | I168: 9.C4 | M168: USED
A169: VD0232:+-1N4005/1 | B169: SC | C169: KT055516 | D169: LEAD | F169: 9.C4 | G169: XT0136:5 | H169: LER,PNL,LFT | I169: 9.C3 | M169: USED
A170: VD0233:--1N4005/1 | B170: SC | C170: SVC11611 | D170: LEAD | F170: 12.B5 | G170: XT0265:15 | H170: LER,PNL,LFT | I170: 12.C5 | M170: USED
A171: VD0233:+-1N4005/1 | B171: SC | C171: KA021521 | D171: LEAD | F171: 12.B5 | G171: XT0265:13 | H171: LER,PNL,LFT | I171: 12.B6 | M171: USED
A172: VD0234:--1N4005/1 | B172: SC | C172: SVC11611 | D172: LEAD | F172: 12.C5 | G172: XT0265:15 | H172: LER,PNL,LFT | I172: 12.C5 | M172: USED
A173: VD0234:+-1N4005/1 | B173: SC | C173: 011210 | D173: LEAD | F173: 12.C5 | G173: XT0265:14 | H173: LER,PNL,LFT | I173: 12.C6 | M173: USED
A174: VD0235:--1N4005/1 | B174: SC | C174: SVC11711 | D174: LEAD | F174: 14.B5 | G174: XT0265:23 | H174: LER,PNL,LFT | I174: 14.C5 | M174: USED
A175: VD0235:+-1N4005/1 | B175: SC | C175: KA021521 | D175: LEAD | F175: 14.B5 | G175: XT0265:21 | H175: LER,PNL,LFT | I175: 14.B6 | M175: USED
A176: VD0236:--1N4005/1 | B176: SC | C176: SVC11711 | D176: LEAD | F176: 14.C5 | G176: XT0265:23 | H176: LER,PNL,LFT | I176: 14.C5 | M176: USED
A177: VD0236:+-1N4005/1 | B177: SC | C177: 011214 | D177: LEAD | F177: 14.C5 | G177: XT0265:22 | H177: LER,PNL,LFT | I177: 14.C6 | M177: USED
... A185: VD0240:+-1N4005/1 | B185: SC | C185: KA021621 | D185: LEAD | F185: 15.A5 | G185: XT0265:7 | H185: LER,PNL,LFT | I185: 15.A6 | M185: USED
A186: XT0136:4 | B186: SC | C186: KA021521 | D186: WHT | E186: 20 | F186: 9.C4 | G186: XT0136:7 | H186: LER,PNL,LFT | I186: 9.C5 | M186: USED
A187: XT0136:6 | B187: SC | C187: KA021521 | D187: WHT | E187: 20 | F187: 9.C4 | G187: XT0265:21 | H187: LER,PNL,LFT | I187: 14.B6 | M187: USED
A188: XT0136:7 | B188: SC | C188: KA021521 | D188: WHT | E188: 20 | F188: 9.C5 | G188: XT0136:6 | H188: LER,PNL,LFT | I188: 9.C4 | M188: USED
...

Sheet LER,PNL,REAR
A1: LER,PNL,REAR
A2: LER 1 RIO CONSOLE REAR PANEL
A3: Project # | B3: 4M037
A4: Project Name | B4: Bayrunner Pipeline
A5: Revision | B5: 0.1
A7: Controls DE | B7: ALEX. JEZEQUEL
A8: Phone:
A9: Controls ME | B9: HECTOR, MEDRANO
A10: Phone:
A12: From | G12: To
A13: Device ID | B13: Cable (W) Conductor (SC) Jumper Clip (JC) | C13: Wire No. | D13: Wire ID | E13: Gauge/Size | F13: Page/Zone | G13: Device ID | H13: Location | I13: Page/Zone
A14: XT0025:2 | B14: JC | C14: 010300 | D14: CLIP | E14: --- | F14: 4.B6 | G14: XT0025:4 | H14: LER,PNL,REAR | I14: 4.B6 | M14: USED
A15: XT0090:1 | B15: JC | C15: 0V1 | D15: CLIP | E15: --- | F15: 6.C2 | G15: XT0090:2 | H15: LER,PNL,REAR | I15: 6.C2 | M15: USED
A16: XT0090:2 | B16: JC | C16: 0V1 | D16: CLIP | E16: --- | F16: 6.C2 | G16: XT0090:3 | H16: LER,PNL,REAR | I16: 6.D2 | M16: USED
A17: XT0090:3 | B17: JC | C17: 0V1 | D17: CLIP | E17: --- | F17: 6.D2 | G17: XT0090:4 | H17: LER,PNL,REAR | I17: 6.D2 | M17: USED
A18: XT0261:1 | B18: JC | C18: FU0260 | D18: CLIP | E18: --- | F18: 5.A4 | G18: XT0261:2 | H18: LER,PNL,REAR | I18: 5.A4 | M18: USED
A19: XT0261:2 | B19: JC | C19: FU0260 | D19: CLIP | E19: --- | F19: 5.A4 | G19: XT0261:3 | H19: LER,PNL,REAR | I19: 5.B4 | M19: USED
A20: XT0261:3 | B20: JC | C20: FU0260 | D20: CLIP | E20: --- | F20: 5.B4 | G20: XT0261:4 | H20: LER,PNL,REAR | I20: 5.B4 | M20: USED
A21: XT0261:4 | B21: JC | C21: FU0260 | D21: CLIP | E21: --- | F21: 5.B4 | G21: XT0261:5 | H21: LER,PNL,REAR | I21: 5.B4 | M21: USED
A22: XT0262:1 | B22: JC | C22: 0V1 | D22: CLIP | E22: --- | F22: 5.C4 | G22: XT0262:2 | H22: LER,PNL,REAR | I22: 5.C4 | M22: USED
A23: XT0262:2 | B23: JC | C23: 0V1 | D23: CLIP | E23: --- | F23: 5.C4 | G23: XT0262:3 | H23: LER,PNL,REAR | I23: 5.C4 | M23: USED
A24: XT0262:3 | B24: JC | C24: 0V1 | D24: CLIP | E24: --- | F24: 5.C4 | G24: XT0262:4 | H24: LER,PNL,REAR | I24: 5.C4 | M24: USED
A25: XT0262:4 | B25: JC | C25: 0V1 | D25: CLIP | E25: --- | F25: 5.C4 | G25: XT0262:5 | H25: LER,PNL,REAR | I25: 5.C4 | M25: USED
... A160: BA7141:RJ45 | B160: WC0010L2 | C160: AU0100L2 | D160: ENET | E160: CABLE | F160: 3.B3 | G160: AU0100:L2 | H160: LER,PNL,LFT | I160: 6.A2 | M160: USED
F162: SolarTools ver. 24.0.84.24712 (Jul 31, 2025)
A163: Report date: 2/13/2026 1:25 PM

Sheet Panel Errors
A1: Panel Errors
A3: Project # | B3: 4M037
A4: Project Name | B4: Bayrunner Pipeline
A5: Revision | B5: 0.1
A7: Controls DE | B7: ALEX. JEZEQUEL
A8: Phone:
A9: Controls ME | B9: HECTOR, MEDRANO
A10: Phone:
A12: From | H12: To
A13: Device ID | B13: Location | C13: Cable (W) Conductor (SC) Jumper Clip (JC) | D13: Wire ID | E13: Wire No. | F13: Gauge/Size | G13: Page/Zone | H13: Device ID | I13: Location | J13: Page/Zone
A14: XT0536:11 | B14: LER,PNL,LFT | C14: SC | E14: KA023624 | G14: 7.A4 | H14: CCSCPNOESD:1 | I14: PANEL | J14: 7.A4
A15: XT0536:12 | B15: LER,PNL,LFT | C15: SC | E15: KA023621 | G15: 7.A4 | H15: CCSCPNOESD:2 | I15: PANEL | J15: 7.A4
A16: XT0536:3 | B16: LER,PNL,LFT | C16: SC | E16: FU0190 | G16: 7.B2 | H16: CCSCPBACKUP:1 | I16: PANEL | J16: 7.B3
A17: CCSCPBACKUP-2:1 | B17: PANEL | C17: SC | E17: KA024324 | G17: 7.B5 | H17: XT0536:15 | I17: LER,PNL,LFT | J17: 7.B5
A18: CCSCPCONTACTIVE:1 | B18: PANEL | C18: SC | E18: FU0190 | G18: 7.C2 | H18: XT0536:4 | I18: LER,PNL,LFT | J18: 7.C2
A19: CCSCPCONTACTIVE:2 | B19: PANEL | C19: SC | E19: KA022914 | G19: 7.C2 | H19: XT0536:9 | I19: LER,PNL,LFT | J19: 7.C3
A21: Report date: 2/13/2026 1:25 PM | E21: SolarTools ver. 24.0.84.24712 (Jul 31, 2025)

Sheet Cable Part Numbers
A1: Cable Part Numbers | D1: SolarTools ver. 24.0.84.24712 (Jul 31, 2025)
A2: Project # | B2: 4M037
D3: Report date: 2/13/2026 1:25 PM
A4: Project Name | B4: Bayrunner Pipeline
A6: Revision | B6: 0.1
A8: Controls DE | B8: ALEX. JEZEQUEL
A9: Phone:
A10: Controls ME | B10: HECTOR, MEDRANO
A11: Phone:
A13: Device ID | C13: Part Number | E13: Description
A14: WC0010L1 | C14: 1302073-36 | E14: CABLE, COMMUNICATION CABLE - 36 INCHES
A15: WC0010L2 | C15: 1302073-36 | E15: CABLE, COMMUNICATION CABLE - 36 INCHES
A16: WC7041 | C16: 1302073-36 | E16: CABLE, ETHERNET - 36 INCHES
A17: WC7042 | C17: 1302073-36 | E17: CABLE, ETHERNET - 36 INCHES

Sheet Part Number List
A1: Part Number List | C1: SolarTools ver. 24.0.84.24712 (Jul 31, 2025)
A2: Project # | B2: 4M037
C3: Report date: 2/13/2026 1:25 PM
A4: Project Name | B4: Bayrunner Pipeline
A6: Revision | B6: 0.1
A8: Controls DE | B8: ALEX. JEZEQUEL
A9: Phone:
A10: Controls ME | B10: HECTOR, MEDRANO
A11: Phone:
A13: Device ID | B13: Part Number | C13: Description | D13: Location
A14: EL0273 | B14: 1015796,1022899,1024594-100 | C14: LIGHT, LED, WHITE | D14: LER 1
A15: ZS0273 | B15: 1113474-1 | C15: LIMIT SWITCH, LER RIO 1 CONSOLE DOOR OPEN | D15: LER 1
A17: SB0500 | B17: 2380746-4 | C17: PUSHBUTTON SWITCH, LER1 EMERGENCY STOP | D17: LER 1 ESTOP
A19: AF0101 | B19: 2684693-17,2684693-25 | C19: 5094-OB8XT, 8 DISCRETE OUTPUT | D19: LER,PNL,LFT
A20: AF0102 | B20: 2684693-17,2684693-23 | C20: 5094-IB16XT, 16 DISCRETE INPUT | D20: LER,PNL,LFT
A21: AF0103 | B21: 2684693-19,2684693-33 | C21: 5094-IY8XT, 8 ANALOG INPUT,TC/RTD/I&V | D21: LER,PNL,LFT
A22: AF0104 | B22: 2684693-18,2684693-28 | C22: 5094-IB16SXT, 16 DISCRETE INPUT, S | D22: LER,PNL,LFT
A23: AF0105 | B23: 2684693-17,2684693-23 | C23: 5094-IB16XT, 16 DISCRETE INPUT | D23: LER,PNL,LFT
A24: AF0106 | B24: 2684693-17,2684693-23 | C24: 5094-IB16XT, 16 DISCRETE INPUT | D24: LER,PNL,LFT
A25: AF0107 | B25: 2684693-17,2684693-23 | C25: 5094-IB16XT, 16 DISCRETE INPUT | D25: LER,PNL,LFT
A26: AF0108 | B26: 2684693-17,2684693-23 | C26: 5094-IB16XT, 16 DISCRETE INPUT | D26: LER,PNL,LFT
... A140: VD0240 | B140: 1066738-10 | C140: DIODE, 15 pF | D140: PANEL

Sheet DOOR_S
A1: DOOR
A2: LER 1 RIO CONSOLE ESTOP DOOR PANEL
A3: Project # | B3: 4M037
A4: Project Name | B4: Bayrunner Pipeline
A5: Revision | B5: 0.1
A7: Controls DE | B7: ALEX. JEZEQUEL
A8: Phone:
A9: Controls ME | B9: HECTOR, MEDRANO
A10: Phone:
A12: From | G12: To
A13: Device ID | B13: Wire No. | C13: Wire ID | D13: Gauge/Size | E13: Length | F13: Device ID | G13: Location | H13: Bundle Name
A14: SB0500:B2-11 | B14: ESTOP2 | C14: WHT | D14: 20 | E14: 240 | F14: XT1036:1 | G14: LEFT PNL | H14: SB0500
A15: SB0500:B2-12 | B15: ESTOP3 | C15: WHT | D15: 20 | E15: 240 | F15: XT1036:2 | G15: LEFT PNL
A16: SB0500:B1-11 | B16: SB0500B111 | C16: WHT | D16: 20 | E16: 240 | F16: XT1036:3 | G16: LEFT PNL
A17: SB0500:B1-12 | B17: SB0500B112 | C17: WHT | D17: 20 | E17: 240 | F17: XT1036:4 | G17: LEFT PNL

Sheet LEFT PNL_S
A1: LEFT PANEL
A2: LER 1 RIO CONSOLE PANEL^LEFT SIDE PANEL
A3: Project # | B3: 4M037
A4: Project Name | B4: Bayrunner Pipeline
A5: Revision | B5: 0.1
A7: Controls DE | B7: ALEX. JEZEQUEL
A8: Phone:
A9: Controls ME | B9: HECTOR, MEDRANO
A10: Phone:
A12: From | G12: To
A13: Device ID | B13: Wire No. | C13: Wire ID | D13: Gauge/Size | E13: Length | F13: Device ID | G13: Location | H13: Bundle Name
A14: AF0112:10 | B14: -011210 | C14: WHT | D14: 20 | E14: 60 | F14: XT0265:14 | G14: LEFT PNL | H14: AF/AU
A15: AF0112:14 | B15: -011214 | C15: WHT | D15: 20 | E15: 60 | F15: XT0265:22 | G15: LEFT PNL
A16: AF0104:39 | B16: SB0500B111 | C16: WHT | D16: 20 | E16: 60 | F16: XT1036:3 | G16: LEFT PNL
A17: AF0104:07 | B17: SB0500B112 | C17: WHT | D17: 20 | E17: 60 | F17: XT1036:4 | G17: LEFT PNL
A18: AF0112:16 | B18: SV101N | C18: WHT | D18: 20 | E18: 60 | F18: XT0265:4 | G18: LEFT PNL
A19: AF0112:20 | B19: SV1022 | C19: WHT | D19: 20 | E19: 60 | F19: XT0265:8 | G19: LEFT PNL
A20: AF0112:26 | B20: SVC11612 | C20: WHT | D20: 20 | E20: 60 | F20: XT0265:16 | G20: LEFT PNL
A21: AF0112:30 | B21: SVC11712 | C21: WHT | D21: 20 | E21: 60 | F21: XT0265:24 | G21: LEFT PNL
A22: AF0112:24 | B22: SVO1161N | C22: WHT | D22: 20 | E22: 60 | F22: XT0265:10 | G22: LEFT PNL
A23: AF0112:28 | B23: SVO11712 | C23: WHT | D23: 20 | E23: 60 | F23: XT0265:18 | G23: LEFT PNL
A24: AF0108:33 | B24: ZSC11611 | C24: WHT | D24: 20 | E24: 60 | F24: XT0265:11 | G24: LEFT PNL
A25: AF0108:01 | B25: ZSC11612 | C25: WHT | D25: 20 | E25: 60 | F25: XT0265:12 | G25: LEFT PNL
A26: AF0102:38 | B26: ZSC11711 | C26: WHT | D26: 20 | E26: 80 | F26: XT0265:19 | G26: LEFT PNL
... A34: AF0102:V+ | B34: FU0102 | C34: WHT | D34: 14 | E34: 80 | F34: FU0102:LD | G34: LEFT PNL
A36: KA0060:A1 | B36: -010110 | C36: WHT | D36: 20 | E36: 100 | F36: AF0101:10 | G36: LEFT PNL | H36: KA A1
A37: KA0215:A1 | B37: KA022914 | C37: WHT | D37: 20 | E37: 60 | F37: XT0136:9 | G37: LEFT PNL
A38: KA0291:A1 | B38: KA0291A1 | C38: WHT | D38: 20 | E38: 60 | F38: AF0113:01 | G38: LEFT PNL
A39: KA0391:A1 | B39: KA0391A1 | C39: WHT | D39: 20 | E39: 60 | F39: AF0113:02 | G39: LEFT PNL
A40: KA0210:A1 | B40: KA053114 | C40: WHT | D40: 20 | E40: 60 | F40: XT0136:10 | G40: LEFT PNL
A41: KA0600:A1 | B41: KA0600A1 | C41: WHT | D41: 20 | E41: 80 | F41: AF0101:00 | G41: LEFT PNL
A42: KA0601:A1 | B42: KA0601A1 | C42: WHT | D42: 20 | E42: 80 | F42: AF0101:02 | G42: LEFT PNL
A43: KA0602:A1 | B43: KA0602A1 | C43: WHT | D43: 20 | E43: 80 | F43: AF0101:04 | G43: LEFT PNL
A44: KA0603:A1 | B44: KA0603A1 | C44: WHT | D44: 20 | E44: 100 | F44: AF0111:10 | G44: LEFT PNL
A45: KA0604:A1 | B45: KA0604A1 | C45: WHT | D45: 20 | E45: 100 | F45: AF0111:12 | G45: LEFT PNL
A46: KA0605:A1 | B46: KA0605A1 | C46: WHT | D46: 20 | E46: 100 | F46: AF0111:14 | G46: LEFT PNL
A47: KA0610:A1 | B47: KA0610A1 | C47: WHT | D47: 20 | E47: 100 | F47: AF0111:00 | G47: LEFT PNL
A48: KA0611:A1 | B48: KA0611A1 | C48: WHT | D48: 20 | E48: 100 | F48: AF0111:02 | G48: LEFT PNL
A50: KA0060:A2 | B50: -010126 | C50: WHT | D50: 20 | E50: 100 | F50: AF0101:26 | G50: LEFT PNL | H50: KA A2
A51: KA0210:A2 | B51: -0V1 | C51: WHT | D51: 20 | E51: 60 | F51: XT0136:2 | G51: LEFT PNL
...

Sheet REAR PNL_S
A1: REAR PANEL
A2: LER 1 RIO CONSOLE REAR PANEL
A3: Project # | B3: 4M037
A4: Project Name | B4: Bayrunner Pipeline
A5: Revision | B5: 0.1
A7: Controls DE | B7: ALEX. JEZEQUEL
A8: Phone:
A9: Controls ME | B9: HECTOR, MEDRANO
A10: Phone:
A12: From | G12: To
A13: Device ID | B13: Wire No. | C13: Wire ID | D13: Gauge/Size | E13: Length | F13: Device ID | G13: Location | H13: Bundle Name
A14: KA0530:21 | B14: FU0190 | C14: WHT | D14: 20 | E14: 60 | F14: KA0540:11 | G14: REAR PNL | H14: KA
A15: KA0530:24 | B15: KA053024 | C15: WHT | D15: 20 | E15: 60 | F15: KA0540:14 | G15: REAR PNL
A17: BA7040:0V | B17: -0V1 | C17: WHT | D17: 16 | E17: 80 | F17: XT0262:3 | G17: REAR PNL | H17: BA
A18: BA7041:V1(-) | B18: -0V1 | C18: WHT | D18: 16 | E18: 80 | F18: XT0262:5 | G18: REAR PNL
A19: BA7042:V1(-) | B19: -0V1 | C19: WHT | D19: 16 | E19: 80 | F19: XT0262:5 | G19: REAR PNL
A20: BA7140:V1(-) | B20: -0V1 | C20: WHT | D20: 16 | E20: 80 | F20: XT0262:5 | G20: REAR PNL
A21: BA7141:V1(-) | B21: -0V1 | C21: WHT | D21: 16 | E21: 80 | F21: XT0262:5 | G21: REAR PNL
A22: BA7042:V1(+) | B22: FU0262 | C22: WHT | D22: 16 | E22: 80 | F22: FU0262:LD | G22: REAR PNL
A23: BA7141:V1(+) | B23: FU0263 | C23: WHT | D23: 16 | E23: 80 | F23: FU0263:LD | G23: REAR PNL
A24: BA7040:P1 | B24: FU7040 | C24: WHT | D24: 16 | E24: 80 | F24: FU7040:LD | G24: REAR PNL
A26: FU0262:LD | B26: FU0262 | C26: WHT | D26: 16 | E26: 80 | F26: BA7041:V1(+) | G26: REAR PNL | H26: FU
A27: FU0263:LD | B27: FU0263 | C27: WHT | D27: 16 | E27: 80 | F27: BA7140:V1(+) | G27: REAR PNL
A29: FU0103:LI | B29: FU0260 | C29: WHT | D29: 14 | E29: 60 | F29: XT0261:2 | G29: REAR PNL
A30: FU0190:LI | B30: FU0260 | C30: WHT | D30: 14 | E30: 60 | F30: XT0261:3 | G30: REAR PNL
A31: FU0260:LD | B31: FU0260 | C31: WHT | D31: 14 | E31: 60 | F31: XT0261:1 | G31: REAR PNL
A32: FU0262:LI | B32: FU0260 | C32: WHT | D32: 14 | E32: 60 | F32: XT0261:4 | G32: REAR PNL
A33: FU0263:LI | B33: FU0260 | C33: WHT | D33: 14 | E33: 60 | F33: XT0261:5 | G33: REAR PNL
A34: FU0264:LI | B34: FU0260 | C34: WHT | D34: 14 | E34: 60 | F34: XT0261:5 | G34: REAR PNL
A35: FU0273:LI | B35: FU0260 | C35: WHT | D35: 14 | E35: 60 | F35: XT0261:3 | G35: REAR PNL
A36: FU7040:LI | B36: FU0260 | C36: WHT | D36: 14 | E36: 60 | F36: XT0261:1 | G36: REAR PNL
A38: XT0025:5 | B38: -0V1 | C38: WHT | D38: 14 | E38: 60 | F38: XT0262:1 | G38: REAR PNL | H38: XT
A39: XT0025:6 | B39: -0V1 | C39: WHT | D39: 14 | E39: 60 | F39: XT0262:2 | G39: REAR PNL
A40: XT0260:1 | B40: -0V1 | C40: WHT | D40: 14 | E40: 60 | F40: XT0262:1 | G40: REAR PNL
A41: XT0262:2 | B41: -0V1 | C41: WHT | D41: 14 | E41: 60 | F41: XT0090:1 | G41: REAR PNL
A43: XT1032:4 | B43: -0V1 | C43: WHT | D43: 12 | E43: 60 | F43: XT0025:3 | G43: REAR PNL
A44: XT0025:1 | B44: VD10324 | C44: WHT | D44: 12 | E44: 60 | F44: XT1032:5 | G44: REAR PNL
A46: QS1032:LI-4 | B46: QS1032N | C46: WHT | D46: 12 | E46: 60 | F46: XT1011:3 | G46: REAR PNL | H46: QS
A47: QS1033:LI-4 | B47: QS1032N | C47: WHT | D47: 12 | E47: 60 | F47: XT1011:4 | G47: REAR PNL
A48: QS1032:LI-2 | B48: QS1032P | C48: WHT | D48: 12 | E48: 60 | F48: XT1011:1 | G48: REAR PNL
...

Sheet Bundle Tag Info
A1: WP-ADSC STA
A2: 4M037
A3: Rev 0.1
A6: DOOR | B6: LEFT PNL | C6: REAR PNL | D6: Panel Name | E6: Panel Name | F6: Panel Name | G6: Panel Name | H6: Panel Name | I6: Panel Name | J6: Panel Name | K6: Panel Name | L6: Panel Name | M6: Panel Name | N6: Panel Name | O6: Panel Name | P6: Panel Name | Q6: Panel Name | R6: Panel Name | S6: Panel Name | T6: Panel Name | U6: Panel Name | V6: Panel Name | W6: Panel Name | X6: Panel Name | Y6: Panel Name | Z6: Panel Name | AA6: Panel Name | AB6: Panel Name | AC6: Panel Name | AD6: Panel Name
A7: SB0500 | B7: AF/AU | C7: KA
B8: KA A1 | C8: BA
B9: KA A2 | C9: FU
B10: KA | C10: XT
B11: KT | C11: QS
B12: XT
B13: AF-REAR
B14: KA-REAR
B15: XT/FU-REAR

Sheet Bundle Tags2
A1: =IF('Bundle Tag Info'!A6<>"Panel Name",'Bundle Tag Info'!A6,"") -> DOOR | B1: =IF('Bundle Tag Info'!B6<>"Panel Name",'Bundle Tag Info'!B6,"") -> LEFT PNL | C1: =IF('Bundle Tag Info'!C6<>"Panel Name",'Bundle Tag Info'!C6,"") -> REAR PNL | D1: =IF('Bundle Tag Info'!D6<>"Panel Name",'Bundle Tag Info'!D6,"") | E1: =IF('Bundle Tag Info'!E6<>"Panel Name",'Bundle Tag Info'!E6,"") | F1: =IF('Bundle Tag Info'!F6<>"Panel Name",'Bundle Tag Info'!F6,"") | G1: =IF('Bundle Tag Info'!G6<>"Panel Name",'Bundle Tag Info'!G6,"") | H1: =IF('Bundle Tag Info'!H6<>"Panel Name",'Bundle Tag Info'!H6,"") | ... AD1: =IF('Bundle Tag Info'!AD6<>"Panel Name",'Bundle Tag Info'!AD6,"")
A2: =IF('Bundle Tag Info'!A$7<>"",CONCATENATE('Bundle Tag Info'!$A$1," ",CHAR(10),'Bundle Tag Info'!$A$2," ",'Bundle Tag Info'!$A$3,CHAR(10),'Bundle Tag Info'!A$6,CHAR(10),'Bundle Tag Info'!A$7),"") -> WP-ADSC STA 4M037 Rev 0.1 DOOR SB0500 | B2: =IF('Bundle Tag Info'!B$7<>"",CONCATENATE('Bundle Tag Info'!$A$1," ",CHAR(10),'Bundle Tag Info'!$A$2," ",'Bundle Tag Info'!$A$3,CHAR(10),'Bundle Tag Info'!B$6,CHAR(10),'Bundle Tag Info'!B$7),"") -> WP-ADSC STA 4M037 Rev 0.1 LEFT PNL AF/AU | C2: =IF('Bundle Tag Info'!C$7<>"",CONCATENATE('Bundle Tag Info'!$A$1," ",CHAR(10),'Bundle Tag Info'!$A$2," ",'Bundle Tag Info'!$A$3,CHAR(10),'Bundle Tag Info'!C$6,CHAR(10),'Bundle Tag Info'!C$7),"") -> WP-ADSC STA 4M037 Rev 0.1 REAR PNL KA | D2: =IF('Bundle Tag Info'!D$7<>"",CONCATENATE('Bundle Tag Info'!$A$1," ",CHAR(10),'Bundle Tag Info'!$A$2," ",'Bundle Tag Info'!$A$3,CHAR(10),'Bundle Tag Info'!D$6,CHAR(10),'Bundle Tag Info'!D$7),"") | E2: =IF('Bundle Tag Info'!E$7<>"",CONCATENATE('Bundle Tag Info'!$A$1," ",CHAR(10),'Bundle Tag Info'!$A$2," ",'Bundle Tag Info'!$A$3,CHAR(10),'Bundle Tag Info'!E$6,CHAR(10),'Bundle Tag Info'!E$7),"") | F2: =IF('Bundle Tag Info'!F$7<>"",CONCATENATE('Bundle Tag Info'!$A$1," ",CHAR(10),'Bundle Tag Info'!$A$2," ",'Bundle Tag Info'!$A$3,CHAR(10),'Bundle Tag Info'!F$6,CHAR(10),'Bundle Tag Info'!F$7),"") | G2: =IF('Bundle Tag Info'!G$7<>"",CONCATENATE('Bundle Tag Info'!$A$1," ",CHAR(10),'Bundle Tag Info'!$A$2," ",'Bundle Tag Info'!$A$3,CHAR(10),'Bundle Tag Info'!G$6,CHAR(10),'Bundle Tag Info'!G$7),"") | H2: =IF('Bundle Tag Info'!H$7<>"",CONCATENATE('Bundle Tag Info'!$A$1," ",CHAR(10),'Bundle Tag Info'!$A$2," ",'Bundle Tag Info'!$A$3,CHAR(10),'Bundle Tag Info'!H$6,CHAR(10),'Bundle Tag Info'!H$7),"") | ... AD2: =IF('Bundle Tag Info'!AD$7<>"",CONCATENATE('Bundle Tag Info'!$A$1," ",CHAR(10),'Bundle Tag Info'!$A$2," ",'Bundle Tag Info'!$A$3,CHAR(10),'Bundle Tag Info'!AD$6,CHAR(10),'Bundle Tag Info'!AD$7),"")
A3: =IF('Bundle Tag Info'!A$8<>"",CONCATENATE('Bundle Tag Info'!$A$1," ",CHAR(10),'Bundle Tag Info'!$A$2," ",'Bundle Tag Info'!$A$3,CHAR(10),'Bundle Tag Info'!A$6,CHAR(10),'Bundle Tag Info'!A$8),"") | B3: =IF('Bundle Tag Info'!B$8<>"",CONCATENATE('Bundle Tag Info'!$A$1," ",CHAR(10),'Bundle Tag Info'!$A$2," ",'Bundle Tag Info'!$A$3,CHAR(10),'Bundle Tag Info'!B$6,CHAR(10),'Bundle Tag Info'!B$8),"") -> WP-ADSC STA 4M037 Rev 0.1 LEFT PNL KA A1 | C3: =IF('Bundle Tag Info'!C$8<>"",CONCATENATE('Bundle Tag Info'!$A$1," ",CHAR(10),'Bundle Tag Info'!$A$2," ",'Bundle Tag Info'!$A$3,CHAR(10),'Bundle Tag Info'!C$6,CHAR(10),'Bundle Tag Info'!C$8),"") -> WP-ADSC STA 4M037 Rev 0.1 REAR PNL BA | D3: =IF('Bundle Tag Info'!D$8<>"",CONCATENATE('Bundle Tag Info'!$A$1," ",CHAR(10),'Bundle Tag Info'!$A$2," ",'Bundle Tag Info'!$A$3,CHAR(10),'Bundle Tag Info'!D$6,CHAR(10),'Bundle Tag Info'!D$8),"") | E3: =IF('Bundle Tag Info'!E$8<>"",CONCATENATE('Bundle Tag Info'!$A$1," ",CHAR(10),'Bundle Tag Info'!$A$2," ",'Bundle Tag Info'!$A$3,CHAR(10),'Bundle Tag Info'!E$6,CHAR(10),'Bundle Tag Info'!E$8),"") | F3: =IF('Bundle Tag Info'!F$8<>"",CONCATENATE('Bundle Tag Info'!$A$1," ",CHAR(10),'Bundle Tag Info'!$A$2," ",'Bundle Tag Info'!$A$3,CHAR(10),'Bundle Tag Info'!F$6,CHAR(10),'Bundle Tag Info'!F$8),"") | G3: =IF('Bundle Tag Info'!G$8<>"",CONCATENATE('Bundle Tag Info'!$A$1," ",CHAR(10),'Bundle Tag Info'!$A$2," ",'Bundle Tag Info'!$A$3,CHAR(10),'Bundle Tag Info'!G$6,CHAR(10),'Bundle Tag Info'!G$8),"") | H3: =IF('Bundle Tag Info'!H$8<>"",CONCATENATE('Bundle Tag Info'!$A$1," ",CHAR(10),'Bundle Tag Info'!$A$2," ",'Bundle Tag Info'!$A$3,CHAR(10),'Bundle Tag Info'!H$6,CHAR(10),'Bundle Tag Info'!H$8),"") | ... AD3: =IF('Bundle Tag Info'!AD$8<>"",CONCATENATE('Bundle Tag Info'!$A$1," ",CHAR(10),'Bundle Tag Info'!$A$2," ",'Bundle Tag Info'!$A$3,CHAR(10),'Bundle Tag Info'!AD$6,CHAR(10),'Bundle Tag Info'!AD$8),"")
A4: =IF('Bundle Tag Info'!A$9<>"",CONCATENATE('Bundle Tag Info'!$A$1," ",CHAR(10),'Bundle Tag Info'!$A$2," ",'Bundle Tag Info'!$A$3,CHAR(10),'Bundle Tag Info'!A$6,CHAR(10),'Bundle Tag Info'!A$9),"") | B4: =IF('Bundle Tag Info'!B$9<>"",CONCATENATE('Bundle Tag Info'!$A$1," ",CHAR(10),'Bundle Tag Info'!$A$2," ",'Bundle Tag Info'!$A$3,CHAR(10),'Bundle Tag Info'!B$6,CHAR(10),'Bundle Tag Info'!B$9),"") -> WP-ADSC STA 4M037 Rev 0.1 LEFT PNL KA A2 | C4: =IF('Bundle Tag Info'!C$9<>"",CONCATENATE('Bundle Tag Info'!$A$1," ",CHAR(10),'Bundle Tag Info'!$A$2," ",'Bundle Tag Info'!$A$3,CHAR(10),'Bundle Tag Info'!C$6,CHAR(10),'Bundle Tag Info'!C$9),"") -> WP-ADSC STA 4M037 Rev 0.1 REAR PNL FU | D4: =IF('Bundle Tag Info'!D$9<>"",CONCATENATE('Bundle Tag Info'!$A$1," ",CHAR(10),'Bundle Tag Info'!$A$2," ",'Bundle Tag Info'!$A$3,CHAR(10),'Bundle Tag Info'!D$6,CHAR(10),'Bundle Tag Info'!D$9),"") | E4: =IF('Bundle Tag Info'!E$9<>"",CONCATENATE('Bundle Tag Info'!$A$1," ",CHAR(10),'Bundle Tag Info'!$A$2," ",'Bundle Tag Info'!$A$3,CHAR(10),'Bundle Tag Info'!E$6,CHAR(10),'Bundle Tag Info'!E$9),"") | F4: =IF('Bundle Tag Info'!F$9<>"",CONCATENATE('Bundle Tag Info'!$A$1," ",CHAR(10),'Bundle Tag Info'!$A$2," ",'Bundle Tag Info'!$A$3,CHAR(10),'Bundle Tag Info'!F$6,CHAR(10),'Bundle Tag Info'!F$9),"") | G4: =IF('Bundle Tag Info'!G$9<>"",CONCATENATE('Bundle Tag Info'!$A$1," ",CHAR(10),'Bundle Tag Info'!$A$2," ",'Bundle Tag Info'!$A$3,CHAR(10),'Bundle Tag Info'!G$6,CHAR(10),'Bundle Tag Info'!G$9),"") | H4: =IF('Bundle Tag Info'!H$9<>"",CONCATENATE('Bundle Tag Info'!$A$1," ",CHAR(10),'Bundle Tag Info'!$A$2," ",'Bundle Tag Info'!$A$3,CHAR(10),'Bundle Tag Info'!H$6,CHAR(10),'Bundle Tag Info'!H$9),"") | ... AD4: =IF('Bundle Tag Info'!AD$9<>"",CONCATENATE('Bundle Tag Info'!$A$1," ",CHAR(10),'Bundle Tag Info'!$A$2," ",'Bundle Tag Info'!$A$3,CHAR(10),'Bundle Tag Info'!AD$6,CHAR(10),'Bundle Tag Info'!AD$9),"")
A5: =IF('Bundle Tag Info'!A$10<>"",CONCATENATE('Bundle Tag Info'!$A$1," ",CHAR(10),'Bundle Tag Info'!$A$2," ",'Bundle Tag Info'!$A$3,CHAR(10),'Bundle Tag Info'!A$6,CHAR(10),'Bundle Tag Info'!A$10),"") | B5: =IF('Bundle Tag Info'!B$10<>"",CONCATENATE('Bundle Tag Info'!$A$1," ",CHAR(10),'Bundle Tag Info'!$A$2," ",'Bundle Tag Info'!$A$3,CHAR(10),'Bundle Tag Info'!B$6,CHAR(10),'Bundle Tag Info'!B$10),"") -> WP-ADSC STA 4M037 Rev 0.1 LEFT PNL KA | C5: =IF('Bundle Tag Info'!C$10<>"",CONCATENATE('Bundle Tag Info'!$A$1," ",CHAR(10),'Bundle Tag Info'!$A$2," ",'Bundle Tag Info'!$A$3,CHAR(10),'Bundle Tag Info'!C$6,CHAR(10),'Bundle Tag Info'!C$10),"") -> WP-ADSC STA 4M037 Rev 0.1 REAR PNL XT | D5: =IF('Bundle Tag Info'!D$10<>"",CONCATENATE('Bundle Tag Info'!$A$1," ",CHAR(10),'Bundle Tag Info'!$A$2," ",'Bundle Tag Info'!$A$3,CHAR(10),'Bundle Tag Info'!D$6,CHAR(10),'Bundle Tag Info'!D$10),"") | E5: =IF('Bundle Tag Info'!E$10<>"",CONCATENATE('Bundle Tag Info'!$A$1," ",CHAR(10),'Bundle Tag Info'!$A$2," ",'Bundle Tag Info'!$A$3,CHAR(10),'Bundle Tag Info'!E$6,CHAR(10),'Bundle Tag Info'!E$10),"") | F5: =IF('Bundle Tag Info'!F$10<>"",CONCATENATE('Bundle Tag Info'!$A$1," ",CHAR(10),'Bundle Tag Info'!$A$2," ",'Bundle Tag Info'!$A$3,CHAR(10),'Bundle Tag Info'!F$6,CHAR(10),'Bundle Tag Info'!F$10),"") | G5: =IF('Bundle Tag Info'!G$10<>"",CONCATENATE('Bundle Tag Info'!$A$1," ",CHAR(10),'Bundle Tag Info'!$A$2," ",'Bundle Tag Info'!$A$3,CHAR(10),'Bundle Tag Info'!G$6,CHAR(10),'Bundle Tag Info'!G$10),"") | H5: =IF('Bundle Tag Info'!H$10<>"",CONCATENATE('Bundle Tag Info'!$A$1," ",CHAR(10),'Bundle Tag Info'!$A$2," ",'Bundle Tag Info'!$A$3,CHAR(10),'Bundle Tag Info'!H$6,CHAR(10),'Bundle Tag Info'!H$10),"") | ... AD5: =IF('Bundle Tag Info'!AD$10<>"",CONCATENATE('Bundle Tag Info'!$A$1," ",CHAR(10),'Bundle Tag Info'!$A$2," ",'Bundle Tag Info'!$A$3,CHAR(10),'Bundle Tag Info'!AD$6,CHAR(10),'Bundle Tag Info'!AD$10),"")
A6: =IF('Bundle Tag Info'!A$11<>"",CONCATENATE('Bundle Tag Info'!$A$1," ",CHAR(10),'Bundle Tag Info'!$A$2," ",'Bundle Tag Info'!$A$3,CHAR(10),'Bundle Tag Info'!A$6,CHAR(10),'Bundle Tag Info'!A$11),"") | B6: =IF('Bundle Tag Info'!B$11<>"",CONCATENATE('Bundle Tag Info'!$A$1," ",CHAR(10),'Bundle Tag Info'!$A$2," ",'Bundle Tag Info'!$A$3,CHAR(10),'Bundle Tag Info'!B$6,CHAR(10),'Bundle Tag Info'!B$11),"") -> WP-ADSC STA 4M037 Rev 0.1 LEFT PNL KT | C6: =IF('Bundle Tag Info'!C$11<>"",CONCATENATE('Bundle Tag Info'!$A$1," ",CHAR(10),'Bundle Tag Info'!$A$2," ",'Bundle Tag Info'!$A$3,CHAR(10),'Bundle Tag Info'!C$6,CHAR(10),'Bundle Tag Info'!C$11),"") -> WP-ADSC STA 4M037 Rev 0.1 REAR PNL QS | D6: =IF('Bundle Tag Info'!D$11<>"",CONCATENATE('Bundle Tag Info'!$A$1," ",CHAR(10),'Bundle Tag Info'!$A$2," ",'Bundle Tag Info'!$A$3,CHAR(10),'Bundle Tag Info'!D$6,CHAR(10),'Bundle Tag Info'!D$11),"") | E6: =IF('Bundle Tag Info'!E$11<>"",CONCATENATE('Bundle Tag Info'!$A$1," ",CHAR(10),'Bundle Tag Info'!$A$2," ",'Bundle Tag Info'!$A$3,CHAR(10),'Bundle Tag Info'!E$6,CHAR(10),'Bundle Tag Info'!E$11),"") | F6: =IF('Bundle Tag Info'!F$11<>"",CONCATENATE('Bundle Tag Info'!$A$1," ",CHAR(10),'Bundle Tag Info'!$A$2," ",'Bundle Tag Info'!$A$3,CHAR(10),'Bundle Tag Info'!F$6,CHAR(10),'Bundle Tag Info'!F$11),"") | G6: =IF('Bundle Tag Info'!G$11<>"",CONCATENATE('Bundle Tag Info'!$A$1," ",CHAR(10),'Bundle Tag Info'!$A$2," ",'Bundle Tag Info'!$A$3,CHAR(10),'Bundle Tag Info'!G$6,CHAR(10),'Bundle Tag Info'!G$11),"") | H6: =IF('Bundle Tag Info'!H$11<>"",CONCATENATE('Bundle Tag Info'!$A$1," ",CHAR(10),'Bundle Tag Info'!$A$2," ",'Bundle Tag Info'!$A$3,CHAR(10),'Bundle Tag Info'!H$6,CHAR(10),'Bundle Tag Info'!H$11),"") | ... AD6: =IF('Bundle Tag Info'!AD$11<>"",CONCATENATE('Bundle Tag Info'!$A$1," ",CHAR(10),'Bundle Tag Info'!$A$2," ",'Bundle Tag Info'!$A$3,CHAR(10),'Bundle Tag Info'!AD$6,CHAR(10),'Bundle Tag Info'!AD$11),"")
A7: =IF('Bundle Tag Info'!A$12<>"",CONCATENATE('Bundle Tag Info'!$A$1," ",CHAR(10),'Bundle Tag Info'!$A$2," ",'Bundle Tag Info'!$A$3,CHAR(10),'Bundle Tag Info'!A$6,CHAR(10),'Bundle Tag Info'!A$12),"") | B7: =IF('Bundle Tag Info'!B$12<>"",CONCATENATE('Bundle Tag Info'!$A$1," ",CHAR(10),'Bundle Tag Info'!$A$2," ",'Bundle Tag Info'!$A$3,CHAR(10),'Bundle Tag Info'!B$6,CHAR(10),'Bundle Tag Info'!B$12),"") -> WP-ADSC STA 4M037 Rev 0.1 LEFT PNL XT | C7: =IF('Bundle Tag Info'!C$12<>"",CONCATENATE('Bundle Tag Info'!$A$1," ",CHAR(10),'Bundle Tag Info'!$A$2," ",'Bundle Tag Info'!$A$3,CHAR(10),'Bundle Tag Info'!C$6,CHAR(10),'Bundle Tag Info'!C$12),"") | D7: =IF('Bundle Tag Info'!D$12<>"",CONCATENATE('Bundle Tag Info'!$A$1," ",CHAR(10),'Bundle Tag Info'!$A$2," ",'Bundle Tag Info'!$A$3,CHAR(10),'Bundle Tag Info'!D$6,CHAR(10),'Bundle Tag Info'!D$12),"") | E7: =IF('Bundle Tag Info'!E$12<>"",CONCATENATE('Bundle Tag Info'!$A$1," ",CHAR(10),'Bundle Tag Info'!$A$2," ",'Bundle Tag Info'!$A$3,CHAR(10),'Bundle Tag Info'!E$6,CHAR(10),'Bundle Tag Info'!E$12),"") | F7: =IF('Bundle Tag Info'!F$12<>"",CONCATENATE('Bundle Tag Info'!$A$1," ",CHAR(10),'Bundle Tag Info'!$A$2," ",'Bundle Tag Info'!$A$3,CHAR(10),'Bundle Tag Info'!F$6,CHAR(10),'Bundle Tag Info'!F$12),"") | G7: =IF('Bundle Tag Info'!G$12<>"",CONCATENATE('Bundle Tag Info'!$A$1," ",CHAR(10),'Bundle Tag Info'!$A$2," ",'Bundle Tag Info'!$A$3,CHAR(10),'Bundle Tag Info'!G$6,CHAR(10),'Bundle Tag Info'!G$12),"") | H7: =IF('Bundle Tag Info'!H$12<>"",CONCATENATE('Bundle Tag Info'!$A$1," ",CHAR(10),'Bundle Tag Info'!$A$2," ",'Bundle Tag Info'!$A$3,CHAR(10),'Bundle Tag Info'!H$6,CHAR(10),'Bundle Tag Info'!H$12),"") | ... AD7: =IF('Bundle Tag Info'!AD$12<>"",CONCATENATE('Bundle Tag Info'!$A$1," ",CHAR(10),'Bundle Tag Info'!$A$2," ",'Bundle Tag Info'!$A$3,CHAR(10),'Bundle Tag Info'!AD$6,CHAR(10),'Bundle Tag Info'!AD$12),"")
A8: =IF('Bundle Tag Info'!A$13<>"",CONCATENATE('Bundle Tag Info'!$A$1," ",CHAR(10),'Bundle Tag Info'!$A$2," ",'Bundle Tag Info'!$A$3,CHAR(10),'Bundle Tag Info'!A$6,CHAR(10),'Bundle Tag Info'!A$13),"") | B8: =IF('Bundle Tag Info'!B$13<>"",CONCATENATE('Bundle Tag Info'!$A$1," ",CHAR(10),'Bundle Tag Info'!$A$2," ",'Bundle Tag Info'!$A$3,CHAR(10),'Bundle Tag Info'!B$6,CHAR(10),'Bundle Tag Info'!B$13),"") -> WP-ADSC STA 4M037 Rev 0.1 LEFT PNL AF-REAR | C8: =IF('Bundle Tag Info'!C$13<>"",CONCATENATE('Bundle Tag Info'!$A$1," ",CHAR(10),'Bundle Tag Info'!$A$2," ",'Bundle Tag Info'!$A$3,CHAR(10),'Bundle Tag Info'!C$6,CHAR(10),'Bundle Tag Info'!C$13),"") | D8: =IF('Bundle Tag Info'!D$13<>"",CONCATENATE('Bundle Tag Info'!$A$1," ",CHAR(10),'Bundle Tag Info'!$A$2," ",'Bundle Tag Info'!$A$3,CHAR(10),'Bundle Tag Info'!D$6,CHAR(10),'Bundle Tag Info'!D$13),"") | E8: =IF('Bundle Tag Info'!E$13<>"",CONCATENATE('Bundle Tag Info'!$A$1," ",CHAR(10),'Bundle Tag Info'!$A$2," ",'Bundle Tag Info'!$A$3,CHAR(10),'Bundle Tag Info'!E$6,CHAR(10),'Bundle Tag Info'!E$13),"") | F8: =IF('Bundle Tag Info'!F$13<>"",CONCATENATE('Bundle Tag Info'!$A$1," ",CHAR(10),'Bundle Tag Info'!$A$2," ",'Bundle Tag Info'!$A$3,CHAR(10),'Bundle Tag Info'!F$6,CHAR(10),'Bundle Tag Info'!F$13),"") | G8: =IF('Bundle Tag Info'!G$13<>"",CONCATENATE('Bundle Tag Info'!$A$1," ",CHAR(10),'Bundle Tag Info'!$A$2," ",'Bundle Tag Info'!$A$3,CHAR(10),'Bundle Tag Info'!G$6,CHAR(10),'Bundle Tag Info'!G$13),"") | H8: =IF('Bundle Tag Info'!H$13<>"",CONCATENATE('Bundle Tag Info'!$A$1," ",CHAR(10),'Bundle Tag Info'!$A$2," ",'Bundle Tag Info'!$A$3,CHAR(10),'Bundle Tag Info'!H$6,CHAR(10),'Bundle Tag Info'!H$13),"") | ... AD8: =IF('Bundle Tag Info'!AD$13<>"",CONCATENATE('Bundle Tag Info'!$A$1," ",CHAR(10),'Bundle Tag Info'!$A$2," ",'Bundle Tag Info'!$A$3,CHAR(10),'Bundle Tag Info'!AD$6,CHAR(10),'Bundle Tag Info'!AD$13),"")
A9: =IF('Bundle Tag Info'!A$14<>"",CONCATENATE('Bundle Tag Info'!$A$1," ",CHAR(10),'Bundle Tag Info'!$A$2," ",'Bundle Tag Info'!$A$3,CHAR(10),'Bundle Tag Info'!A$6,CHAR(10),'Bundle Tag Info'!A$14),"") | B9: =IF('Bundle Tag Info'!B$14<>"",CONCATENATE('Bundle Tag Info'!$A$1," ",CHAR(10),'Bundle Tag Info'!$A$2," ",'Bundle Tag Info'!$A$3,CHAR(10),'Bundle Tag Info'!B$6,CHAR(10),'Bundle Tag Info'!B$14),"") -> WP-ADSC STA 4M037 Rev 0.1 LEFT PNL KA-REAR | C9: =IF('Bundle Tag Info'!C$14<>"",CONCATENATE('Bundle Tag Info'!$A$1," ",CHAR(10),'Bundle Tag Info'!$A$2," ",'Bundle Tag Info'!$A$3,CHAR(10),'Bundle Tag Info'!C$6,CHAR(10),'Bundle Tag Info'!C$14),"") | D9: =IF('Bundle Tag Info'!D$14<>"",CONCATENATE('Bundle Tag Info'!$A$1," ",CHAR(10),'Bundle Tag Info'!$A$2," ",'Bundle Tag Info'!$A$3,CHAR(10),'Bundle Tag Info'!D$6,CHAR(10),'Bundle Tag Info'!D$14),"") | E9: =IF('Bundle Tag Info'!E$14<>"",CONCATENATE('Bundle Tag Info'!$A$1," ",CHAR(10),'Bundle Tag Info'!$A$2," ",'Bundle Tag Info'!$A$3,CHAR(10),'Bundle Tag Info'!E$6,CHAR(10),'Bundle Tag Info'!E$14),"") | F9: =IF('Bundle Tag Info'!F$14<>"",CONCATENATE('Bundle Tag Info'!$A$1," ",CHAR(10),'Bundle Tag Info'!$A$2," ",'Bundle Tag Info'!$A$3,CHAR(10),'Bundle Tag Info'!F$6,CHAR(10),'Bundle Tag Info'!F$14),"") | G9: =IF('Bundle Tag Info'!G$14<>"",CONCATENATE('Bundle Tag Info'!$A$1," ",CHAR(10),'Bundle Tag Info'!$A$2," ",'Bundle Tag Info'!$A$3,CHAR(10),'Bundle Tag Info'!G$6,CHAR(10),'Bundle Tag Info'!G$14),"") | H9: =IF('Bundle Tag Info'!H$14<>"",CONCATENATE('Bundle Tag Info'!$A$1," ",CHAR(10),'Bundle Tag Info'!$A$2," ",'Bundle Tag Info'!$A$3,CHAR(10),'Bundle Tag Info'!H$6,CHAR(10),'Bundle Tag Info'!H$14),"") | ... AD9: =IF('Bundle Tag Info'!AD$14<>"",CONCATENATE('Bundle Tag Info'!$A$1," ",CHAR(10),'Bundle Tag Info'!$A$2," ",'Bundle Tag Info'!$A$3,CHAR(10),'Bundle Tag Info'!AD$6,CHAR(10),'Bundle Tag Info'!AD$14),"")
A10: =IF('Bundle Tag Info'!A$15<>"",CONCATENATE('Bundle Tag Info'!$A$1," ",CHAR(10),'Bundle Tag Info'!$A$2," ",'Bundle Tag Info'!$A$3,CHAR(10),'Bundle Tag Info'!A$6,CHAR(10),'Bundle Tag Info'!A$15),"") | B10: =IF('Bundle Tag Info'!B$15<>"",CONCATENATE('Bundle Tag Info'!$A$1," ",CHAR(10),'Bundle Tag Info'!$A$2," ",'Bundle Tag Info'!$A$3,CHAR(10),'Bundle Tag Info'!B$6,CHAR(10),'Bundle Tag Info'!B$15),"") -> WP-ADSC STA 4M037 Rev 0.1 LEFT PNL XT/FU-REAR | C10: =IF('Bundle Tag Info'!C$15<>"",CONCATENATE('Bundle Tag Info'!$A$1," ",CHAR(10),'Bundle Tag Info'!$A$2," ",'Bundle Tag Info'!$A$3,CHAR(10),'Bundle Tag Info'!C$6,CHAR(10),'Bundle Tag Info'!C$15),"") | D10: =IF('Bundle Tag Info'!D$15<>"",CONCATENATE('Bundle Tag Info'!$A$1," ",CHAR(10),'Bundle Tag Info'!$A$2," ",'Bundle Tag Info'!$A$3,CHAR(10),'Bundle Tag Info'!D$6,CHAR(10),'Bundle Tag Info'!D$15),"") | E10: =IF('Bundle Tag Info'!E$15<>"",CONCATENATE('Bundle Tag Info'!$A$1," ",CHAR(10),'Bundle Tag Info'!$A$2," ",'Bundle Tag Info'!$A$3,CHAR(10),'Bundle Tag Info'!E$6,CHAR(10),'Bundle Tag Info'!E$15),"") | F10: =IF('Bundle Tag Info'!F$15<>"",CONCATENATE('Bundle Tag Info'!$A$1," ",CHAR(10),'Bundle Tag Info'!$A$2," ",'Bundle Tag Info'!$A$3,CHAR(10),'Bundle Tag Info'!F$6,CHAR(10),'Bundle Tag Info'!F$15),"") | G10: =IF('Bundle Tag Info'!G$15<>"",CONCATENATE('Bundle Tag Info'!$A$1," ",CHAR(10),'Bundle Tag Info'!$A$2," ",'Bundle Tag Info'!$A$3,CHAR(10),'Bundle Tag Info'!G$6,CHAR(10),'Bundle Tag Info'!G$15),"") | H10: =IF('Bundle Tag Info'!H$15<>"",CONCATENATE('Bundle Tag Info'!$A$1," ",CHAR(10),'Bundle Tag Info'!$A$2," ",'Bundle Tag Info'!$A$3,CHAR(10),'Bundle Tag Info'!H$6,CHAR(10),'Bundle Tag Info'!H$15),"") | ... AD10: =IF('Bundle Tag Info'!AD$15<>"",CONCATENATE('Bundle Tag Info'!$A$1," ",CHAR(10),'Bundle Tag Info'!$A$2," ",'Bundle Tag Info'!$A$3,CHAR(10),'Bundle Tag Info'!AD$6,CHAR(10),'Bundle Tag Info'!AD$15),"")
A11: =IF('Bundle Tag Info'!A$16<>"",CONCATENATE('Bundle Tag Info'!$A$1," ",CHAR(10),'Bundle Tag Info'!$A$2," ",'Bundle Tag Info'!$A$3,CHAR(10),'Bundle Tag Info'!A$6,CHAR(10),'Bundle Tag Info'!A$16),"") | B11: =IF('Bundle Tag Info'!B$16<>"",CONCATENATE('Bundle Tag Info'!$A$1," ",CHAR(10),'Bundle Tag Info'!$A$2," ",'Bundle Tag Info'!$A$3,CHAR(10),'Bundle Tag Info'!B$6,CHAR(10),'Bundle Tag Info'!B$16),"") | C11: =IF('Bundle Tag Info'!C$16<>"",CONCATENATE('Bundle Tag Info'!$A$1," ",CHAR(10),'Bundle Tag Info'!$A$2," ",'Bundle Tag Info'!$A$3,CHAR(10),'Bundle Tag Info'!C$6,CHAR(10),'Bundle Tag Info'!C$16),"") | D11: =IF('Bundle Tag Info'!D$16<>"",CONCATENATE('Bundle Tag Info'!$A$1," ",CHAR(10),'Bundle Tag Info'!$A$2," ",'Bundle Tag Info'!$A$3,CHAR(10),'Bundle Tag Info'!D$6,CHAR(10),'Bundle Tag Info'!D$16),"") | E11: =IF('Bundle Tag Info'!E$16<>"",CONCATENATE('Bundle Tag Info'!$A$1," ",CHAR(10),'Bundle Tag Info'!$A$2," ",'Bundle Tag Info'!$A$3,CHAR(10),'Bundle Tag Info'!E$6,CHAR(10),'Bundle Tag Info'!E$16),"") | F11: =IF('Bundle Tag Info'!F$16<>"",CONCATENATE('Bundle Tag Info'!$A$1," ",CHAR(10),'Bundle Tag Info'!$A$2," ",'Bundle Tag Info'!$A$3,CHAR(10),'Bundle Tag Info'!F$6,CHAR(10),'Bundle Tag Info'!F$16),"") | G11: =IF('Bundle Tag Info'!G$16<>"",CONCATENATE('Bundle Tag Info'!$A$1," ",CHAR(10),'Bundle Tag Info'!$A$2," ",'Bundle Tag Info'!$A$3,CHAR(10),'Bundle Tag Info'!G$6,CHAR(10),'Bundle Tag Info'!G$16),"") | H11: =IF('Bundle Tag Info'!H$16<>"",CONCATENATE('Bundle Tag Info'!$A$1," ",CHAR(10),'Bundle Tag Info'!$A$2," ",'Bundle Tag Info'!$A$3,CHAR(10),'Bundle Tag Info'!H$6,CHAR(10),'Bundle Tag Info'!H$16),"") | ... AD11: =IF('Bundle Tag Info'!AD$16<>"",CONCATENATE('Bundle Tag Info'!$A$1," ",CHAR(10),'Bundle Tag Info'!$A$2," ",'Bundle Tag Info'!$A$3,CHAR(10),'Bundle Tag Info'!AD$6,CHAR(10),'Bundle Tag Info'!AD$16),"")
A12: =IF('Bundle Tag Info'!A$17<>"",CONCATENATE('Bundle Tag Info'!$A$1," ",CHAR(10),'Bundle Tag Info'!$A$2," ",'Bundle Tag Info'!$A$3,CHAR(10),'Bundle Tag Info'!A$6,CHAR(10),'Bundle Tag Info'!A$17),"") | B12: =IF('Bundle Tag Info'!B$17<>"",CONCATENATE('Bundle Tag Info'!$A$1," ",CHAR(10),'Bundle Tag Info'!$A$2," ",'Bundle Tag Info'!$A$3,CHAR(10),'Bundle Tag Info'!B$6,CHAR(10),'Bundle Tag Info'!B$17),"") | C12: =IF('Bundle Tag Info'!C$17<>"",CONCATENATE('Bundle Tag Info'!$A$1," ",CHAR(10),'Bundle Tag Info'!$A$2," ",'Bundle Tag Info'!$A$3,CHAR(10),'Bundle Tag Info'!C$6,CHAR(10),'Bundle Tag Info'!C$17),"") | D12: =IF('Bundle Tag Info'!D$17<>"",CONCATENATE('Bundle Tag Info'!$A$1," ",CHAR(10),'Bundle Tag Info'!$A$2," ",'Bundle Tag Info'!$A$3,CHAR(10),'Bundle Tag Info'!D$6,CHAR(10),'Bundle Tag Info'!D$17),"") | E12: =IF('Bundle Tag Info'!E$17<>"",CONCATENATE('Bundle Tag Info'!$A$1," ",CHAR(10),'Bundle Tag Info'!$A$2," ",'Bundle Tag Info'!$A$3,CHAR(10),'Bundle Tag Info'!E$6,CHAR(10),'Bundle Tag Info'!E$17),"") | F12: =IF('Bundle Tag Info'!F$17<>"",CONCATENATE('Bundle Tag Info'!$A$1," ",CHAR(10),'Bundle Tag Info'!$A$2," ",'Bundle Tag Info'!$A$3,CHAR(10),'Bundle Tag Info'!F$6,CHAR(10),'Bundle Tag Info'!F$17),"") | G12: =IF('Bundle Tag Info'!G$17<>"",CONCATENATE('Bundle Tag Info'!$A$1," ",CHAR(10),'Bundle Tag Info'!$A$2," ",'Bundle Tag Info'!$A$3,CHAR(10),'Bundle Tag Info'!G$6,CHAR(10),'Bundle Tag Info'!G$17),"") | H12: =IF('Bundle Tag Info'!H$17<>"",CONCATENATE('Bundle Tag Info'!$A$1," ",CHAR(10),'Bundle Tag Info'!$A$2," ",'Bundle Tag Info'!$A$3,CHAR(10),'Bundle Tag Info'!H$6,CHAR(10),'Bundle Tag Info'!H$17),"") | ... AD12: =IF('Bundle Tag Info'!AD$17<>"",CONCATENATE('Bundle Tag Info'!$A$1," ",CHAR(10),'Bundle Tag Info'!$A$2," ",'Bundle Tag Info'!$A$3,CHAR(10),'Bundle Tag Info'!AD$6,CHAR(10),'Bundle Tag Info'!AD$17),"")
A13: =IF('Bundle Tag Info'!A$18<>"",CONCATENATE('Bundle Tag Info'!$A$1," ",CHAR(10),'Bundle Tag Info'!$A$2," ",'Bundle Tag Info'!$A$3,CHAR(10),'Bundle Tag Info'!A$6,CHAR(10),'Bundle Tag Info'!A$18),"") | B13: =IF('Bundle Tag Info'!B$18<>"",CONCATENATE('Bundle Tag Info'!$A$1," ",CHAR(10),'Bundle Tag Info'!$A$2," ",'Bundle Tag Info'!$A$3,CHAR(10),'Bundle Tag Info'!B$6,CHAR(10),'Bundle Tag Info'!B$18),"") | C13: =IF('Bundle Tag Info'!C$18<>"",CONCATENATE('Bundle Tag Info'!$A$1," ",CHAR(10),'Bundle Tag Info'!$A$2," ",'Bundle Tag Info'!$A$3,CHAR(10),'Bundle Tag Info'!C$6,CHAR(10),'Bundle Tag Info'!C$18),"") | D13: =IF('Bundle Tag Info'!D$18<>"",CONCATENATE('Bundle Tag Info'!$A$1," ",CHAR(10),'Bundle Tag Info'!$A$2," ",'Bundle Tag Info'!$A$3,CHAR(10),'Bundle Tag Info'!D$6,CHAR(10),'Bundle Tag Info'!D$18),"") | E13: =IF('Bundle Tag Info'!E$18<>"",CONCATENATE('Bundle Tag Info'!$A$1," ",CHAR(10),'Bundle Tag Info'!$A$2," ",'Bundle Tag Info'!$A$3,CHAR(10),'Bundle Tag Info'!E$6,CHAR(10),'Bundle Tag Info'!E$18),"") | F13: =IF('Bundle Tag Info'!F$18<>"",CONCATENATE('Bundle Tag Info'!$A$1," ",CHAR(10),'Bundle Tag Info'!$A$2," ",'Bundle Tag Info'!$A$3,CHAR(10),'Bundle Tag Info'!F$6,CHAR(10),'Bundle Tag Info'!F$18),"") | G13: =IF('Bundle Tag Info'!G$18<>"",CONCATENATE('Bundle Tag Info'!$A$1," ",CHAR(10),'Bundle Tag Info'!$A$2," ",'Bundle Tag Info'!$A$3,CHAR(10),'Bundle Tag Info'!G$6,CHAR(10),'Bundle Tag Info'!G$18),"") | H13: =IF('Bundle Tag Info'!H$18<>"",CONCATENATE('Bundle Tag Info'!$A$1," ",CHAR(10),'Bundle Tag Info'!$A$2," ",'Bundle Tag Info'!$A$3,CHAR(10),'Bundle Tag Info'!H$6,CHAR(10),'Bundle Tag Info'!H$18),"") | ... AD13: =IF('Bundle Tag Info'!AD$18<>"",CONCATENATE('Bundle Tag Info'!$A$1," ",CHAR(10),'Bundle Tag Info'!$A$2," ",'Bundle Tag Info'!$A$3,CHAR(10),'Bundle Tag Info'!AD$6,CHAR(10),'Bundle Tag Info'!AD$18),"")
A14: =IF('Bundle Tag Info'!A$19<>"",CONCATENATE('Bundle Tag Info'!$A$1," ",CHAR(10),'Bundle Tag Info'!$A$2," ",'Bundle Tag Info'!$A$3,CHAR(10),'Bundle Tag Info'!A$6,CHAR(10),'Bundle Tag Info'!A$19),"") | B14: =IF('Bundle Tag Info'!B$19<>"",CONCATENATE('Bundle Tag Info'!$A$1," ",CHAR(10),'Bundle Tag Info'!$A$2," ",'Bundle Tag Info'!$A$3,CHAR(10),'Bundle Tag Info'!B$6,CHAR(10),'Bundle Tag Info'!B$19),"") | C14: =IF('Bundle Tag Info'!C$19<>"",CONCATENATE('Bundle Tag Info'!$A$1," ",CHAR(10),'Bundle Tag Info'!$A$2," ",'Bundle Tag Info'!$A$3,CHAR(10),'Bundle Tag Info'!C$6,CHAR(10),'Bundle Tag Info'!C$19),"") | D14: =IF('Bundle Tag Info'!D$19<>"",CONCATENATE('Bundle Tag Info'!$A$1," ",CHAR(10),'Bundle Tag Info'!$A$2," ",'Bundle Tag Info'!$A$3,CHAR(10),'Bundle Tag Info'!D$6,CHAR(10),'Bundle Tag Info'!D$19),"") | E14: =IF('Bundle Tag Info'!E$19<>"",CONCATENATE('Bundle Tag Info'!$A$1," ",CHAR(10),'Bundle Tag Info'!$A$2," ",'Bundle Tag Info'!$A$3,CHAR(10),'Bundle Tag Info'!E$6,CHAR(10),'Bundle Tag Info'!E$19),"") | F14: =IF('Bundle Tag Info'!F$19<>"",CONCATENATE('Bundle Tag Info'!$A$1," ",CHAR(10),'Bundle Tag Info'!$A$2," ",'Bundle Tag Info'!$A$3,CHAR(10),'Bundle Tag Info'!F$6,CHAR(10),'Bundle Tag Info'!F$19),"") | G14: =IF('Bundle Tag Info'!G$19<>"",CONCATENATE('Bundle Tag Info'!$A$1," ",CHAR(10),'Bundle Tag Info'!$A$2," ",'Bundle Tag Info'!$A$3,CHAR(10),'Bundle Tag Info'!G$6,CHAR(10),'Bundle Tag Info'!G$19),"") | H14: =IF('Bundle Tag Info'!H$19<>"",CONCATENATE('Bundle Tag Info'!$A$1," ",CHAR(10),'Bundle Tag Info'!$A$2," ",'Bundle Tag Info'!$A$3,CHAR(10),'Bundle Tag Info'!H$6,CHAR(10),'Bundle Tag Info'!H$19),"") | ... AD14: =IF('Bundle Tag Info'!AD$19<>"",CONCATENATE('Bundle Tag Info'!$A$1," ",CHAR(10),'Bundle Tag Info'!$A$2," ",'Bundle Tag Info'!$A$3,CHAR(10),'Bundle Tag Info'!AD$6,CHAR(10),'Bundle Tag Info'!AD$19),"")
A15: =IF('Bundle Tag Info'!A$20<>"",CONCATENATE('Bundle Tag Info'!$A$1," ",CHAR(10),'Bundle Tag Info'!$A$2," ",'Bundle Tag Info'!$A$3,CHAR(10),'Bundle Tag Info'!A$6,CHAR(10),'Bundle Tag Info'!A$20),"") | B15: =IF('Bundle Tag Info'!B$20<>"",CONCATENATE('Bundle Tag Info'!$A$1," ",CHAR(10),'Bundle Tag Info'!$A$2," ",'Bundle Tag Info'!$A$3,CHAR(10),'Bundle Tag Info'!B$6,CHAR(10),'Bundle Tag Info'!B$20),"") | C15: =IF('Bundle Tag Info'!C$20<>"",CONCATENATE('Bundle Tag Info'!$A$1," ",CHAR(10),'Bundle Tag Info'!$A$2," ",'Bundle Tag Info'!$A$3,CHAR(10),'Bundle Tag Info'!C$6,CHAR(10),'Bundle Tag Info'!C$20),"") | D15: =IF('Bundle Tag Info'!D$20<>"",CONCATENATE('Bundle Tag Info'!$A$1," ",CHAR(10),'Bundle Tag Info'!$A$2," ",'Bundle Tag Info'!$A$3,CHAR(10),'Bundle Tag Info'!D$6,CHAR(10),'Bundle Tag Info'!D$20),"") | E15: =IF('Bundle Tag Info'!E$20<>"",CONCATENATE('Bundle Tag Info'!$A$1," ",CHAR(10),'Bundle Tag Info'!$A$2," ",'Bundle Tag Info'!$A$3,CHAR(10),'Bundle Tag Info'!E$6,CHAR(10),'Bundle Tag Info'!E$20),"") | F15: =IF('Bundle Tag Info'!F$20<>"",CONCATENATE('Bundle Tag Info'!$A$1," ",CHAR(10),'Bundle Tag Info'!$A$2," ",'Bundle Tag Info'!$A$3,CHAR(10),'Bundle Tag Info'!F$6,CHAR(10),'Bundle Tag Info'!F$20),"") | G15: =IF('Bundle Tag Info'!G$20<>"",CONCATENATE('Bundle Tag Info'!$A$1," ",CHAR(10),'Bundle Tag Info'!$A$2," ",'Bundle Tag Info'!$A$3,CHAR(10),'Bundle Tag Info'!G$6,CHAR(10),'Bundle Tag Info'!G$20),"") | H15: =IF('Bundle Tag Info'!H$20<>"",CONCATENATE('Bundle Tag Info'!$A$1," ",CHAR(10),'Bundle Tag Info'!$A$2," ",'Bundle Tag Info'!$A$3,CHAR(10),'Bundle Tag Info'!H$6,CHAR(10),'Bundle Tag Info'!H$20),"") | ... AD15: =IF('Bundle Tag Info'!AD$20<>"",CONCATENATE('Bundle Tag Info'!$A$1," ",CHAR(10),'Bundle Tag Info'!$A$2," ",'Bundle Tag Info'!$A$3,CHAR(10),'Bundle Tag Info'!AD$6,CHAR(10),'Bundle Tag Info'!AD$20),"")
A16: =IF('Bundle Tag Info'!A$21<>"",CONCATENATE('Bundle Tag Info'!$A$1," ",CHAR(10),'Bundle Tag Info'!$A$2," ",'Bundle Tag Info'!$A$3,CHAR(10),'Bundle Tag Info'!A$6,CHAR(10),'Bundle Tag Info'!A$21),"") | B16: =IF('Bundle Tag Info'!B$21<>"",CONCATENATE('Bundle Tag Info'!$A$1," ",CHAR(10),'Bundle Tag Info'!$A$2," ",'Bundle Tag Info'!$A$3,CHAR(10),'Bundle Tag Info'!B$6,CHAR(10),'Bundle Tag Info'!B$21),"") | C16: =IF('Bundle Tag Info'!C$21<>"",CONCATENATE('Bundle Tag Info'!$A$1," ",CHAR(10),'Bundle Tag Info'!$A$2," ",'Bundle Tag Info'!$A$3,CHAR(10),'Bundle Tag Info'!C$6,CHAR(10),'Bundle Tag Info'!C$21),"") | D16: =IF('Bundle Tag Info'!D$21<>"",CONCATENATE('Bundle Tag Info'!$A$1," ",CHAR(10),'Bundle Tag Info'!$A$2," ",'Bundle Tag Info'!$A$3,CHAR(10),'Bundle Tag Info'!D$6,CHAR(10),'Bundle Tag Info'!D$21),"") | E16: =IF('Bundle Tag Info'!E$21<>"",CONCATENATE('Bundle Tag Info'!$A$1," ",CHAR(10),'Bundle Tag Info'!$A$2," ",'Bundle Tag Info'!$A$3,CHAR(10),'Bundle Tag Info'!E$6,CHAR(10),'Bundle Tag Info'!E$21),"") | F16: =IF('Bundle Tag Info'!F$21<>"",CONCATENATE('Bundle Tag Info'!$A$1," ",CHAR(10),'Bundle Tag Info'!$A$2," ",'Bundle Tag Info'!$A$3,CHAR(10),'Bundle Tag Info'!F$6,CHAR(10),'Bundle Tag Info'!F$21),"") | G16: =IF('Bundle Tag Info'!G$21<>"",CONCATENATE('Bundle Tag Info'!$A$1," ",CHAR(10),'Bundle Tag Info'!$A$2," ",'Bundle Tag Info'!$A$3,CHAR(10),'Bundle Tag Info'!G$6,CHAR(10),'Bundle Tag Info'!G$21),"") | H16: =IF('Bundle Tag Info'!H$21<>"",CONCATENATE('Bundle Tag Info'!$A$1," ",CHAR(10),'Bundle Tag Info'!$A$2," ",'Bundle Tag Info'!$A$3,CHAR(10),'Bundle Tag Info'!H$6,CHAR(10),'Bundle Tag Info'!H$21),"") | ... AD16: =IF('Bundle Tag Info'!AD$21<>"",CONCATENATE('Bundle Tag Info'!$A$1," ",CHAR(10),'Bundle Tag Info'!$A$2," ",'Bundle Tag Info'!$A$3,CHAR(10),'Bundle Tag Info'!AD$6,CHAR(10),'Bundle Tag Info'!AD$21),"")
A17: =IF('Bundle Tag Info'!A$22<>"",CONCATENATE('Bundle Tag Info'!$A$1," ",CHAR(10),'Bundle Tag Info'!$A$2," ",'Bundle Tag Info'!$A$3,CHAR(10),'Bundle Tag Info'!A$6,CHAR(10),'Bundle Tag Info'!A$22),"") | B17: =IF('Bundle Tag Info'!B$22<>"",CONCATENATE('Bundle Tag Info'!$A$1," ",CHAR(10),'Bundle Tag Info'!$A$2," ",'Bundle Tag Info'!$A$3,CHAR(10),'Bundle Tag Info'!B$6,CHAR(10),'Bundle Tag Info'!B$22),"") | C17: =IF('Bundle Tag Info'!C$22<>"",CONCATENATE('Bundle Tag Info'!$A$1," ",CHAR(10),'Bundle Tag Info'!$A$2," ",'Bundle Tag Info'!$A$3,CHAR(10),'Bundle Tag Info'!C$6,CHAR(10),'Bundle Tag Info'!C$22),"") | D17: =IF('Bundle Tag Info'!D$22<>"",CONCATENATE('Bundle Tag Info'!$A$1," ",CHAR(10),'Bundle Tag Info'!$A$2," ",'Bundle Tag Info'!$A$3,CHAR(10),'Bundle Tag Info'!D$6,CHAR(10),'Bundle Tag Info'!D$22),"") | E17: =IF('Bundle Tag Info'!E$22<>"",CONCATENATE('Bundle Tag Info'!$A$1," ",CHAR(10),'Bundle Tag Info'!$A$2," ",'Bundle Tag Info'!$A$3,CHAR(10),'Bundle Tag Info'!E$6,CHAR(10),'Bundle Tag Info'!E$22),"") | F17: =IF('Bundle Tag Info'!F$22<>"",CONCATENATE('Bundle Tag Info'!$A$1," ",CHAR(10),'Bundle Tag Info'!$A$2," ",'Bundle Tag Info'!$A$3,CHAR(10),'Bundle Tag Info'!F$6,CHAR(10),'Bundle Tag Info'!F$22),"") | G17: =IF('Bundle Tag Info'!G$22<>"",CONCATENATE('Bundle Tag Info'!$A$1," ",CHAR(10),'Bundle Tag Info'!$A$2," ",'Bundle Tag Info'!$A$3,CHAR(10),'Bundle Tag Info'!G$6,CHAR(10),'Bundle Tag Info'!G$22),"") | H17: =IF('Bundle Tag Info'!H$22<>"",CONCATENATE('Bundle Tag Info'!$A$1," ",CHAR(10),'Bundle Tag Info'!$A$2," ",'Bundle Tag Info'!$A$3,CHAR(10),'Bundle Tag Info'!H$6,CHAR(10),'Bundle Tag Info'!H$22),"") | ... AD17: =IF('Bundle Tag Info'!AD$22<>"",CONCATENATE('Bundle Tag Info'!$A$1," ",CHAR(10),'Bundle Tag Info'!$A$2," ",'Bundle Tag Info'!$A$3,CHAR(10),'Bundle Tag Info'!AD$6,CHAR(10),'Bundle Tag Info'!AD$22),"")
A18: =IF('Bundle Tag Info'!A$23<>"",CONCATENATE('Bundle Tag Info'!$A$1," ",CHAR(10),'Bundle Tag Info'!$A$2," ",'Bundle Tag Info'!$A$3,CHAR(10),'Bundle Tag Info'!A$6,CHAR(10),'Bundle Tag Info'!A$23),"") | B18: =IF('Bundle Tag Info'!B$23<>"",CONCATENATE('Bundle Tag Info'!$A$1," ",CHAR(10),'Bundle Tag Info'!$A$2," ",'Bundle Tag Info'!$A$3,CHAR(10),'Bundle Tag Info'!B$6,CHAR(10),'Bundle Tag Info'!B$23),"") | C18: =IF('Bundle Tag Info'!C$23<>"",CONCATENATE('Bundle Tag Info'!$A$1," ",CHAR(10),'Bundle Tag Info'!$A$2," ",'Bundle Tag Info'!$A$3,CHAR(10),'Bundle Tag Info'!C$6,CHAR(10),'Bundle Tag Info'!C$23),"") | D18: =IF('Bundle Tag Info'!D$23<>"",CONCATENATE('Bundle Tag Info'!$A$1," ",CHAR(10),'Bundle Tag Info'!$A$2," ",'Bundle Tag Info'!$A$3,CHAR(10),'Bundle Tag Info'!D$6,CHAR(10),'Bundle Tag Info'!D$23),"") | E18: =IF('Bundle Tag Info'!E$23<>"",CONCATENATE('Bundle Tag Info'!$A$1," ",CHAR(10),'Bundle Tag Info'!$A$2," ",'Bundle Tag Info'!$A$3,CHAR(10),'Bundle Tag Info'!E$6,CHAR(10),'Bundle Tag Info'!E$23),"") | F18: =IF('Bundle Tag Info'!F$23<>"",CONCATENATE('Bundle Tag Info'!$A$1," ",CHAR(10),'Bundle Tag Info'!$A$2," ",'Bundle Tag Info'!$A$3,CHAR(10),'Bundle Tag Info'!F$6,CHAR(10),'Bundle Tag Info'!F$23),"") | G18: =IF('Bundle Tag Info'!G$23<>"",CONCATENATE('Bundle Tag Info'!$A$1," ",CHAR(10),'Bundle Tag Info'!$A$2," ",'Bundle Tag Info'!$A$3,CHAR(10),'Bundle Tag Info'!G$6,CHAR(10),'Bundle Tag Info'!G$23),"") | H18: =IF('Bundle Tag Info'!H$23<>"",CONCATENATE('Bundle Tag Info'!$A$1," ",CHAR(10),'Bundle Tag Info'!$A$2," ",'Bundle Tag Info'!$A$3,CHAR(10),'Bundle Tag Info'!H$6,CHAR(10),'Bundle Tag Info'!H$23),"") | ... AD18: =IF('Bundle Tag Info'!AD$23<>"",CONCATENATE('Bundle Tag Info'!$A$1," ",CHAR(10),'Bundle Tag Info'!$A$2," ",'Bundle Tag Info'!$A$3,CHAR(10),'Bundle Tag Info'!AD$6,CHAR(10),'Bundle Tag Info'!AD$23),"")
A19: =IF('Bundle Tag Info'!A$24<>"",CONCATENATE('Bundle Tag Info'!$A$1," ",CHAR(10),'Bundle Tag Info'!$A$2," ",'Bundle Tag Info'!$A$3,CHAR(10),'Bundle Tag Info'!A$6,CHAR(10),'Bundle Tag Info'!A$24),"") | B19: =IF('Bundle Tag Info'!B$24<>"",CONCATENATE('Bundle Tag Info'!$A$1," ",CHAR(10),'Bundle Tag Info'!$A$2," ",'Bundle Tag Info'!$A$3,CHAR(10),'Bundle Tag Info'!B$6,CHAR(10),'Bundle Tag Info'!B$24),"") | C19: =IF('Bundle Tag Info'!C$24<>"",CONCATENATE('Bundle Tag Info'!$A$1," ",CHAR(10),'Bundle Tag Info'!$A$2," ",'Bundle Tag Info'!$A$3,CHAR(10),'Bundle Tag Info'!C$6,CHAR(10),'Bundle Tag Info'!C$24),"") | D19: =IF('Bundle Tag Info'!D$24<>"",CONCATENATE('Bundle Tag Info'!$A$1," ",CHAR(10),'Bundle Tag Info'!$A$2," ",'Bundle Tag Info'!$A$3,CHAR(10),'Bundle Tag Info'!D$6,CHAR(10),'Bundle Tag Info'!D$24),"") | E19: =IF('Bundle Tag Info'!E$24<>"",CONCATENATE('Bundle Tag Info'!$A$1," ",CHAR(10),'Bundle Tag Info'!$A$2," ",'Bundle Tag Info'!$A$3,CHAR(10),'Bundle Tag Info'!E$6,CHAR(10),'Bundle Tag Info'!E$24),"") | F19: =IF('Bundle Tag Info'!F$24<>"",CONCATENATE('Bundle Tag Info'!$A$1," ",CHAR(10),'Bundle Tag Info'!$A$2," ",'Bundle Tag Info'!$A$3,CHAR(10),'Bundle Tag Info'!F$6,CHAR(10),'Bundle Tag Info'!F$24),"") | G19: =IF('Bundle Tag Info'!G$24<>"",CONCATENATE('Bundle Tag Info'!$A$1," ",CHAR(10),'Bundle Tag Info'!$A$2," ",'Bundle Tag Info'!$A$3,CHAR(10),'Bundle Tag Info'!G$6,CHAR(10),'Bundle Tag Info'!G$24),"") | H19: =IF('Bundle Tag Info'!H$24<>"",CONCATENATE('Bundle Tag Info'!$A$1," ",CHAR(10),'Bundle Tag Info'!$A$2," ",'Bundle Tag Info'!$A$3,CHAR(10),'Bundle Tag Info'!H$6,CHAR(10),'Bundle Tag Info'!H$24),"") | ... AD19: =IF('Bundle Tag Info'!AD$24<>"",CONCATENATE('Bundle Tag Info'!$A$1," ",CHAR(10),'Bundle Tag Info'!$A$2," ",'Bundle Tag Info'!$A$3,CHAR(10),'Bundle Tag Info'!AD$6,CHAR(10),'Bundle Tag Info'!AD$24),"")
A20: =IF('Bundle Tag Info'!A$25<>"",CONCATENATE('Bundle Tag Info'!$A$1," ",CHAR(10),'Bundle Tag Info'!$A$2," ",'Bundle Tag Info'!$A$3,CHAR(10),'Bundle Tag Info'!A$6,CHAR(10),'Bundle Tag Info'!A$25),"") | B20: =IF('Bundle Tag Info'!B$25<>"",CONCATENATE('Bundle Tag Info'!$A$1," ",CHAR(10),'Bundle Tag Info'!$A$2," ",'Bundle Tag Info'!$A$3,CHAR(10),'Bundle Tag Info'!B$6,CHAR(10),'Bundle Tag Info'!B$25),"") | C20: =IF('Bundle Tag Info'!C$25<>"",CONCATENATE('Bundle Tag Info'!$A$1," ",CHAR(10),'Bundle Tag Info'!$A$2," ",'Bundle Tag Info'!$A$3,CHAR(10),'Bundle Tag Info'!C$6,CHAR(10),'Bundle Tag Info'!C$25),"") | D20: =IF('Bundle Tag Info'!D$25<>"",CONCATENATE('Bundle Tag Info'!$A$1," ",CHAR(10),'Bundle Tag Info'!$A$2," ",'Bundle Tag Info'!$A$3,CHAR(10),'Bundle Tag Info'!D$6,CHAR(10),'Bundle Tag Info'!D$25),"") | E20: =IF('Bundle Tag Info'!E$25<>"",CONCATENATE('Bundle Tag Info'!$A$1," ",CHAR(10),'Bundle Tag Info'!$A$2," ",'Bundle Tag Info'!$A$3,CHAR(10),'Bundle Tag Info'!E$6,CHAR(10),'Bundle Tag Info'!E$25),"") | F20: =IF('Bundle Tag Info'!F$25<>"",CONCATENATE('Bundle Tag Info'!$A$1," ",CHAR(10),'Bundle Tag Info'!$A$2," ",'Bundle Tag Info'!$A$3,CHAR(10),'Bundle Tag Info'!F$6,CHAR(10),'Bundle Tag Info'!F$25),"") | G20: =IF('Bundle Tag Info'!G$25<>"",CONCATENATE('Bundle Tag Info'!$A$1," ",CHAR(10),'Bundle Tag Info'!$A$2," ",'Bundle Tag Info'!$A$3,CHAR(10),'Bundle Tag Info'!G$6,CHAR(10),'Bundle Tag Info'!G$25),"") | H20: =IF('Bundle Tag Info'!H$25<>"",CONCATENATE('Bundle Tag Info'!$A$1," ",CHAR(10),'Bundle Tag Info'!$A$2," ",'Bundle Tag Info'!$A$3,CHAR(10),'Bundle Tag Info'!H$6,CHAR(10),'Bundle Tag Info'!H$25),"") | ... AD20: =IF('Bundle Tag Info'!AD$25<>"",CONCATENATE('Bundle Tag Info'!$A$1," ",CHAR(10),'Bundle Tag Info'!$A$2," ",'Bundle Tag Info'!$A$3,CHAR(10),'Bundle Tag Info'!AD$6,CHAR(10),'Bundle Tag Info'!AD$25),"")
A21: =IF('Bundle Tag Info'!A$26<>"",CONCATENATE('Bundle Tag Info'!$A$1," ",CHAR(10),'Bundle Tag Info'!$A$2," ",'Bundle Tag Info'!$A$3,CHAR(10),'Bundle Tag Info'!A$6,CHAR(10),'Bundle Tag Info'!A$26),"") | B21: =IF('Bundle Tag Info'!B$26<>"",CONCATENATE('Bundle Tag Info'!$A$1," ",CHAR(10),'Bundle Tag Info'!$A$2," ",'Bundle Tag Info'!$A$3,CHAR(10),'Bundle Tag Info'!B$6,CHAR(10),'Bundle Tag Info'!B$26),"") | C21: =IF('Bundle Tag Info'!C$26<>"",CONCATENATE('Bundle Tag Info'!$A$1," ",CHAR(10),'Bundle Tag Info'!$A$2," ",'Bundle Tag Info'!$A$3,CHAR(10),'Bundle Tag Info'!C$6,CHAR(10),'Bundle Tag Info'!C$26),"") | D21: =IF('Bundle Tag Info'!D$26<>"",CONCATENATE('Bundle Tag Info'!$A$1," ",CHAR(10),'Bundle Tag Info'!$A$2," ",'Bundle Tag Info'!$A$3,CHAR(10),'Bundle Tag Info'!D$6,CHAR(10),'Bundle Tag Info'!D$26),"") | E21: =IF('Bundle Tag Info'!E$26<>"",CONCATENATE('Bundle Tag Info'!$A$1," ",CHAR(10),'Bundle Tag Info'!$A$2," ",'Bundle Tag Info'!$A$3,CHAR(10),'Bundle Tag Info'!E$6,CHAR(10),'Bundle Tag Info'!E$26),"") | F21: =IF('Bundle Tag Info'!F$26<>"",CONCATENATE('Bundle Tag Info'!$A$1," ",CHAR(10),'Bundle Tag Info'!$A$2," ",'Bundle Tag Info'!$A$3,CHAR(10),'Bundle Tag Info'!F$6,CHAR(10),'Bundle Tag Info'!F$26),"") | G21: =IF('Bundle Tag Info'!G$26<>"",CONCATENATE('Bundle Tag Info'!$A$1," ",CHAR(10),'Bundle Tag Info'!$A$2," ",'Bundle Tag Info'!$A$3,CHAR(10),'Bundle Tag Info'!G$6,CHAR(10),'Bundle Tag Info'!G$26),"") | H21: =IF('Bundle Tag Info'!H$26<>"",CONCATENATE('Bundle Tag Info'!$A$1," ",CHAR(10),'Bundle Tag Info'!$A$2," ",'Bundle Tag Info'!$A$3,CHAR(10),'Bundle Tag Info'!H$6,CHAR(10),'Bundle Tag Info'!H$26),"") | ... AD21: =IF('Bundle Tag Info'!AD$26<>"",CONCATENATE('Bundle Tag Info'!$A$1," ",CHAR(10),'Bundle Tag Info'!$A$2," ",'Bundle Tag Info'!$A$3,CHAR(10),'Bundle Tag Info'!AD$6,CHAR(10),'Bundle Tag Info'!AD$26),"")
