Workbook

Sheet Blue Labels
A1: (SHT 1) CONSOLE | B1: (SHT 10) PLC PANEL | C1: (SHT 11) PANEL A | D1: (SHT 12) PANEL B | E1: (SHT 13) ISOLATOR PANEL | F1: (SHT 14) GENERATOR PANEL | G1: (SHT 15) ORBIT 60 | H1: (SHT 16) VIBRATION DOOR PANEL | I1: (SHT 17) JB70 | J1: (SHT 18) JB70 LEFT RAIL | K1: (SHT 19) JB70 RIGHT RAIL | L1: (SHT 2) CONSOLE | M1: (SHT 20) JB70 | N1: (SHT 21) JB72 | O1: (SHT 22) JB4 | P1: (SHT 23) GROUNDING BOX | Q1: (SHT 4) TCP | R1: (SHT 5) PWR DISTRIBUTION RAIL | S1: (SHT 6) REDUNDANT POWER SUPPLY | T1: (SHT 7) BLANK PANEL | U1: (SHT 8) GENERATOR VIBRATION PANEL | V1: (SHT 9) CUSTOMER^PANEL
A2: AT0190K | B2: UV0600 | C2: XT0137 | D2: FU0003 | E2: FU0272 | F2: AT0140 | G2: AR0610 | H2: AF0450 | I2: HL0171 | J2: XTFGA | K2: FU1100 | L2: EL0273 | M2: IEG1100 | N2: FU0317 | O2: UA1240 | P2: IEG0010 | Q2: HL0411 | R2: AT0680 | S2: UJ0031 | T2: GR0170 | U2: KA0181 | V2: GR0290
A3: AT0190 | B3: AT0600 | C3: XT0136 | D3: FU0004 | E3: UV0271 | F3: FU0332 | G3: AP0629 | H3: XT0400 | I3: HL0172 | J3: GR1101 | K3: XTFGB | L3: EL0271 | M3: AP1100 | N3: FU0318 | O3: UA1241 | Q3: HL0410 | R3: XT0680 | S3: QS0031 | T3: GR0171 | U3: KA0182 | V3: GR0292
B4: AP0601 | C4: FU0080 | D4: FU0101 | E4: UAI0741 | F4: FU0333 | G4: AP0628 | I4: HL0173 | K4: GR1100 | L4: HA0273 | M4: BA0001 | N4: FU0319 | O4: UA1250 | Q4: HL0409 | R4: FU0560 | S4: GR0030 | U4: KA0183 | V4: IEG0130
B5: AP0602 | C5: XT0080 | D5: XT0002 | E5: UAI0742 | F5: FU0334 | G5: AP0627 | I5: SB0471 | L5: ZS0273 | M5: BA0002 | N5: XT0833 | O5: UA1251 | Q5: HL0408 | R5: FU0680 | S5: XT0033 | U5: KA7921 | V5: GR0291
B6: AP0603 | C6: XT0081 | D6: XT0005 | E6: UAI0743 | F6: FU0335 | G6: AP0626 | I6: SB0473 | L6: ZS0271 | M6: FU0001 | N6: XT0834 | O6: UA1272 | Q6: HL0407 | R6: FU0200 | S6: FU0031 | U6: KA7922
B7: AP0604 | C7: XT0085 | D7: XT0240 | E7: UAI0744 | F7: KA0185 | G7: AP0625 | I7: SB0474 | L7: FG0000 | M7: GR1235 | N7: XT0835 | O7: UA1273 | Q7: SB0400 | R7: FU0201 | S7: GR0031 | U7: KA7923
B8: AP0605 | C8: AU0080 | D8: XT0071 | E8: UAI0745 | F8: KA0310 | G8: AP0624 | I8: SA0170 | M8: FU0002 | N8: XT0836 | O8: GR1250 | Q8: HL0406 | R8: FU0190 | U8: FU0701
B9: AP0606 | C9: AF0081 | D9: XT0070 | E9: UAI0746 | F9: KA0330 | G9: AP0623 | I9: SB0170 | M9: XT0001 | N9: XT0837 | Q9: HL0405 | R9: FU0273 | U9: FU0702
B10: AP0607 | C10: AF0082 | D10: FU0070 | E10: UAI0747 | F10: KA0331 | G10: AP0622 | I10: SH0470 | M10: XT0815 | N10: XT0838 | Q10: HL0404 | R10: XT0560 | U10: FU0110
B11: AP0608 | C11: AF0083 | D11: AU0070 | E11: UAI0750 | F11: KA0332 | G11: AP0621 | I11: SH0471 | M11: UA1210 | N11: GR4142 | Q11: HL0403 | R11: XT0561 | U11: FU0113
B12: AP0609 | C12: AF0084 | D12: FU0071 | E12: UAI0751 | F12: KA0333 | G12: AP0620 | I12: SH0472 | M12: UA1211 | N12: XT0831 | Q12: HL0402 | R12: XT0562 | U12: XT0110
B13: AR0600 | C13: AF0085 | D13: AF0071 | E13: UAI0752 | F13: KA0335 | G13: AP0619 | I13: AT1100 | M13: UA1220 | N13: XT0832 | Q13: HL0401 | R13: XT0563 | U13: KA0186
B14: BA1200 | C14: AF0086 | D14: AF0072 | E14: UAI0753 | F14: KA0336 | G14: AP0618 | I14: SA0472 | M14: UA1221 | N14: XTFGC | Q14: HL0400 | U14: KA0187
B15: BA1201 | C15: AF0087 | D15: AF0073 | E15: UAI0754 | F15: XT0332 | G15: AP0617 | I15: HA0472 | M15: UA1230 | N15: GR4141 | Q15: SH0412 | U15: KA0188
B16: BA1202 | C16: AF0088 | D16: AF0074 | E16: UAI0755 | F16: XT0334 | G16: AP0616 | I16: SA0471 | M16: UA1231 | N16: GR4181 | Q16: SH0411 | U16: KA0189
B17: BA0004 | C17: KA0176 | D17: AF0075 | E17: UAI0756 | F17: XT0335 | G17: AP0615 | I17: SB0472 | M17: UA1262 | Q17: SH0405 | U17: GR0110
B18: BA0003 | C18: KA0177 | D18: AF0076 | E18: UAI0757 | F18: XT0336 | G18: AP0614 | M18: UA1263 | Q18: SH0404 | U18: AP0290
B19: BA0011 | C19: XT0171 | D19: AF0077 | E19: UAI0760 | F19: XT0337 | G19: AP0613 | M19: FU1211 | Q19: SA0400 | U19: AP0291
B20: GR0234 | C20: KA4360 | D20: GR0233 | E20: UAI0770 | F20: XT0313 | G20: AP0612 | M20: FU1101 | Q20: SH0410 | U20: XT0130
C21: KA4361 | D21: XT0237 | E21: UAI0771 | F21: FU0313 | G21: UV0610 | M21: XT1211 | Q21: SH0409 | U21: XT0180
C22: KA4362 | D22: XT0236 | E22: UAI0772 | F22: FU0314 | G22: UV0611 | M22: BA1211 | Q22: SH0401 | U22: FU0180
C23: KA6200 | D23: XT0235 | E23: UAI0773 | F23: FU0315 | M23: BA1100 | Q23: SH0400 | U23: FU0181
C24: GR0134 | D24: XT0233 | E24: UAI0774 | F24: XT0360 | M24: GR1232 | Q24: XT0564 | U24: FU0290
C25: AU0090 | D25: FU0210 | E25: UAI0775 | F25: XT0362 | M25: XT0810 | Q25: AU0200 | U25: FU0291
C26: AF0091 | D26: FU0211 | E26: UAI0776 | F26: XT0370 | M26: XT0811 | Q26: XT0201 | U26: XT0290
C27: AF0092 | D27: FU0212 | E27: UAI0777 | F27: GR0141 | M27: XT0820 | Q27: GR0200 | U27: FU2108
C28: AF0093 | D28: FU0050 | E28: UAI0836 | F28: XT0340 | M28: XT0821 | Q28: SB0408 | U28: FU2220
C29: AF0094 | D29: FU0051 | E29: UAI1100 | F29: XT0341 | M29: XT0822 | Q29: SB0407 | U29: XT0681
C30: AF0095 | D30: FU0052 | E30: UAI1110 | F30: XT0342 | M30: XT0825 | Q30: SH0408 | U30: XT0682
C31: AF0096 | D31: FU0053 | E31: UAI1111 | F31: XT0343 | M31: XT1213 | Q31: SB0405 | U31: XT0291
C32: AF0097 | D32: FU0054 | E32: UAI1112 | F32: KA0180 | M32: XT1214 | Q32: SB0406 | U32: GR0181
C33: XT0091 | D33: FU0055 | E33: UAI1170 | F33: XT0351 | M33: XT0824 | Q33: SA0401 | U33: AU0180
C34: KA0110 | D34: FU0060 | E34: UAI1204 | F34: XT0352 | M34: GR1233 | Q34: SB0404 | U34: AF0181
... C39: KA0130 | D39: XT0060 | E39: UAI1221 | F39: FU0120 | M39: XT0808 | Q39: AF0202 | U39: GR0180
C40: KA0131 | D40: KA1020 | E40: UV0272 | F40: FU0121 | M40: XT0809
C41: KA0132 | D41: AF0068 | E41: UAI1230 | F41: FU0122 | M41: RR0175A
C42: KA0141 | D42: AF0067 | E42: UAI1231 | F42: FU0130 | M42: RR0175I
C43: KA0133 | D43: AF0066 | E43: UAI1240 | F43: KA0121 | M43: RR0175D
C44: KA0134 | D44: AF0065 | E44: UAI1241 | F44: KA0123 | M44: RR0175M
...

Sheet White Labels
A1: (SHT 7) BLANK PANEL | B1: (SHT 9) CUSTOMER^PANEL - (SHT 14) GENERATOR PANEL | C1: (SHT 9) CUSTOMER^PANEL - (SHT 8) GENERATOR VIBRATION PANEL | D1: (SHT 9) CUSTOMER^PANEL - (SHT 23) GROUNDING BOX | E1: (SHT 9) CUSTOMER^PANEL - (SHT 13) ISOLATOR PANEL | F1: (SHT 9) CUSTOMER^PANEL - (SHT 15) ORBIT 60 | G1: (SHT 9) CUSTOMER^PANEL - (SHT 16) VIBRATION DOOR PANEL | H1: (SHT 14) GENERATOR PANEL | I1: (SHT 14) GENERATOR PANEL - (SHT 11) PANEL A | J1: (SHT 14) GENERATOR PANEL - (SHT 12) PANEL B | K1: (SHT 8) GENERATOR VIBRATION PANEL | L1: (SHT 8) GENERATOR VIBRATION PANEL - (SHT 12) PANEL B | M1: (SHT 23) GROUNDING BOX - (SHT 11) PANEL A | N1: (SHT 23) GROUNDING BOX - (SHT 12) PANEL B | O1: (SHT 13) ISOLATOR PANEL - (SHT 12) PANEL B | P1: (SHT 17) JB70 | Q1: (SHT 20) JB70 | R1: (SHT 21) JB72 | S1: (SHT 11) PANEL A | T1: (SHT 11) PANEL A - (SHT 12) PANEL B | U1: (SHT 12) PANEL B | V1: (SHT 12) PANEL B - (SHT 10) PLC PANEL | W1: (SHT 12) PANEL B - (SHT 4) TCP | X1: (SHT 10) PLC PANEL | Y1: (SHT 5) PWR DISTRIBUTION RAIL - (SHT 4) TCP | Z1: (SHT 4) TCP | AA1: (SHT 16) VIBRATION DOOR PANEL
A2: GR0171 | B2: AT0140LS(S) | C2: IEG01303 | D2: IEG0130G | E2: IEG01307 | F2: UV0610SHLD | G2: IEG01308 | H2: AF0123G | I2: PEG0140G | J2: GR0120 | K2: AU0180GND | L2: AP0291G | M2: IEG00104 | N2: IEG0230G | O2: IEG023014 | P2: AT1100G | Q2: GR1232 | R2: WC8401 | S2: 0V2 | T2: IEG023011 | U2: AF0055G | V2: IEG02301 | W2: IEG02308 | X2: UV0600G | Y2: 0V | Z2: AU0200GND | AA2: XT04001
B3: IEG01301 | C3: IEG01304 | F3: UV0611SHLD | H3: AU0120GND | L3: IEG02306 | M3: IEG00105 | Q3: IEG12001 | S3: AF0083G | T3: IEG02302 | U3: AF0064G | V3: IEG023012 | Y3: 0V1
H4: EXCS | Q4: IEG12002 | S4: AF0084G | U4: AF0065G | Y4: ESTOPA
H5: FU0122 | Q5: IEG12004 | S5: AF0085G | U5: AF0066G | Y5: ESTOPB
H6: PEG01405 | S6: AF0086G | U6: AF0071G | Y6: FU0139
H7: PMGS | S7: AF0094G | U7: AF0072G | Y7: FU0200
H8: VBUSN | S8: AF0096G | U8: AF0073G | Y8: FU0201
H9: WC8101 | S9: AU0080GND | U9: AF0074G | Y9: KA023612
H10: WC8102 | S10: AU0090GND | U10: AF0075G | Y10: KA0241A1
H11: WC8201 | U11: AU0050GND | Y11: TCP18B1
H12: WC8301 | U12: AU0060GND | Y12: TCP18B2
U13: AU0070GND
U14: IEG023010
U15: IEG023013
U16: IEG02303
U17: IEG02304
U18: IEG02305
U19: IEG02307

Sheet Heat Shrink Labels
A1: (SHT 14) GENERATOR PANEL | B1: (SHT 14) GENERATOR PANEL - (SHT 8) GENERATOR VIBRATION PANEL | C1: (SHT 14) GENERATOR PANEL - (SHT 13) ISOLATOR PANEL | D1: (SHT 8) GENERATOR VIBRATION PANEL | E1: (SHT 8) GENERATOR VIBRATION PANEL - (SHT 11) PANEL A | F1: (SHT 8) GENERATOR VIBRATION PANEL - (SHT 12) PANEL B | G1: (SHT 13) ISOLATOR PANEL - (SHT 15) ORBIT 60 | H1: (SHT 13) ISOLATOR PANEL - (SHT 11) PANEL A | I1: (SHT 13) ISOLATOR PANEL - (SHT 12) PANEL B | J1: (SHT 13) ISOLATOR PANEL - (SHT 16) VIBRATION DOOR PANEL | K1: (SHT 20) JB70
A2: WC8009 | B2: WC029101 | C2: WC2170 | D2: WTXRX1 | E2: WC029003 | F2: WC029001 | G2: WC1203 | H2: WC2110 | I2: WC2100 | J2: WC4649 | K2: WC4524
B3: WC029102 | C3: WC2270 | D3: WTXRX2 | E3: WC029004 | F3: WC029002 | G3: WC1304 | H3: WC2126 | I3: WC2101
B4: WC029103 | C4: WC2370 | E4: WC029005 | F4: WC029009 | G4: WC1305 | H4: WC2127 | I4: WC2102
B5: WC029104 | C5: WC2470 | E5: WC029006 | F5: WC029014 | G5: WC1306 | H5: WC2128 | I5: WC2103
B6: WC029105 | C6: WC2570 | E6: WC029007 | F6: WC029015 | G6: WC1327 | H6: WC2137 | I6: WC2104
B7: WC029106 | C7: WC2670 | E7: WC029008 | F7: WC029016 | G7: WC1328 | H7: WC2153 | I7: WC2105
C8: WC2770 | E8: WC029010 | F8: WC029017 | G8: WC1329 | H8: WC2154 | I8: WC2129
C9: WC2870 | E9: WC029011 | F9: WC029018 | G9: WC1330 | H9: WC2155 | I9: WC2201
E10: WC029012 | F10: WC029019 | G10: WC1331 | H10: WC2156 | I10: WC2202
E11: WC029013 | F11: WC029020 | G11: WC1332 | H11: WC2157 | I11: WC2203
E12: WC029023 | F12: WC029021 | G12: WC1333 | H12: WC2161 | I12: WC2204
E13: WC029024 | F13: WC029022 | G13: WC1334 | H13: WC2162 | I13: WC2205
E14: WC029025 | F14: WC029027 | G14: WC1335 | H14: WC2180 | I14: WC2301
E15: WC029026 | F15: WC029028 | G15: WC1336 | H15: WC2181 | I15: WC2302
E16: WC029029 | F16: WC029031 | G16: WC1337 | H16: WC2182 | I16: WC2303
E17: WC029030 | F17: WC029109 | G17: WC1338 | H17: WC2206 | I17: WC2304
E18: WC029032 | F18: WC029110 | G18: WC1339 | H18: WC2207 | I18: WC2305
E19: WC029107 | F19: WC029111 | G19: WC1340 | H19: WC2306 | I19: WC2401
E20: WC029108 | F20: WC029112 | G20: WC1341 | H20: WC2406 | I20: WC2402
F21: WC029113 | G21: WC1342 | H21: WC3320 | I21: WC2403
F22: WC029114 | G22: WC1343 | H22: WC3321 | I22: WC2404
F23: WC029115 | G23: WC1344 | H23: WC6670 | I23: WC2405
F24: WC029118 | G24: WC1345
F25: WC029119 | G25: WC1346
F26: WC029120
F27: WC029121
F28: WC029122

Sheet BLANK PANEL
A1: BLANK PANEL
A3: Project # | B3: 4M401
A4: Project Name | B4: FPSO GTG GENERATORS
A5: Revision | B5: C.2
A7: Controls DE | B7: J. SHORTER
A8: Phone: | B8: 0
A9: Controls ME
A10: Phone:
A12: From | G12: To
A13: Device ID | B13: Cable (W) Conductor (SC) Jumper Clip (JC) | C13: Wire No. | D13: Wire ID | E13: Gauge/Size | F13: Page/Zone | G13: Device ID | H13: Location | I13: Page/Zone
A14: GR0170: | B14: SC | C14: GR0170 | D14: GRN/YEL | E14: 14 | F14: 5.B5 | G14: FRAME | H14: BLANK PANEL | I14: 5.B4 | M14: USED
A15: GR0171: | B15: SC | C15: GR0171 | D15: GRN/YEL | E15: 14 | F15: 5.B5 | G15: FG0001:1 | H15: BLANK PANEL | I15: 5.B4 | M15: USED
F17: SolarTools ver. 24.0.84.24712 (Jul 31, 2025)
A18: Report date: 2/20/2026 3:00 PM

Sheet CONSOLE
A1: CONSOLE
A2: CONTROL CONSOLE & CONTROL CONSOLE (DOOR PANELS)
A3: Project # | B3: 4M401
A4: Project Name | B4: FPSO GTG GENERATORS
A5: Revision | B5: C.2
A7: Controls DE | B7: J. SHORTER
A8: Phone: | B8: 0
A9: Controls ME
A10: Phone:
A12: From | G12: To
A13: Device ID | B13: Cable (W) Conductor (SC) Jumper Clip (JC) | C13: Wire No. | D13: Wire ID | E13: Gauge/Size | F13: Page/Zone | G13: Device ID | H13: Location | I13: Page/Zone
A14: AT0190:GND | B14: SC | C14: AT0190G | D14: GRN/YEL | E14: 14 | F14: 13.B4 | G14: FRAME | H14: CONSOLE | I14: 13.C3 | M14: USED
A15: AT0190:USB1 | B15: SC | C15: AT0190K | D15: CABLE | E15: USB | F15: 13.B4 | G15: AT0190K:KI | H15: CONSOLE | I15: 13.C5 | M15: USED
A16: EL0271:B1 | B16: SC | C16: EL0273B | D16: WHT | E16: 14 | F16: 13.B6 | G16: EL0273:B2 | H16: CONSOLE | I16: 13.B4 | M16: USED
A17: EL0271:B2 | B17: SC | C17: ZS0271 | D17: WHT | E17: 14 | F17: 13.B6 | G17: ZS0271:2 | H17: CONSOLE | I17: 13.B6 | M17: USED
A18: EL0271:W1 | B18: SC | C18: EL0273W | D18: WHT | E18: 14 | F18: 13.B6 | G18: EL0273:W2 | H18: CONSOLE | I18: 13.B4 | M18: USED
A19: EL0273:B1 | B19: SC | C19: ZS0273 | D19: WHT | E19: 14 | F19: 13.B4 | G19: ZS0273:2 | H19: CONSOLE | I19: 13.B4 | M19: USED
A20: AT0190:NEG | B20: SC | C20: 0V1 | D20: WHT | E20: 14 | F20: 13.B4 | G20: XT0562:2 | H20: PWR DISTRIBUTION RAIL | I20: 13.B2 | M20: USED
A21: AT0190:POS | B21: SC | C21: FU0190 | D21: WHT | E21: 14 | F21: 13.B4 | G21: FU0190:LD | H21: PWR DISTRIBUTION RAIL | I21: 13.C3 | M21: USED
A22: EL0273:W1 | B22: SC | C22: 0V1 | D22: WHT | E22: 14 | F22: 13.B4 | G22: XT0562:1 | H22: PWR DISTRIBUTION RAIL | I22: 13.B2 | M22: USED
A23: ZS0271:1 | B23: SC | C23: FU0273 | D23: WHT | E23: 14 | F23: 13.B6 | G23: FU0273:LD | H23: PWR DISTRIBUTION RAIL | I23: 13.B3 | M23: USED
A24: ZS0273:1 | B24: SC | C24: FU0273 | D24: WHT | E24: 14 | F24: 13.B4 | G24: FU0273:LD | H24: PWR DISTRIBUTION RAIL | I24: 13.B3 | M24: USED
A25: AT0190:ENET | B25: WC0019 | C25: AT0190E | D25: ENET | E25: CABLE | F25: 13.B4 | G25: AT0680:LAN2 | H25: PWR DISTRIBUTION RAIL | I25: 8.B4 | M25: USED
... A27: HA0273:(-) | B27: WC5540 | C27: HA0273N | D27: WHT | E27: 16 | F27: 16.A1 | G27: AF0202:55 | H27: TCP | I27: 16.A3 | M27: USED
F29: SolarTools ver. 24.0.84.24712 (Jul 31, 2025)
A30: Report date: 2/20/2026 3:00 PM

Sheet CUSTOMER^PANEL
A1: CUSTOMER^PANEL
A3: Project # | B3: 4M401
A4: Project Name | B4: FPSO GTG GENERATORS
A5: Revision | B5: C.2
A7: Controls DE | B7: J. SHORTER
A8: Phone: | B8: 0
A9: Controls ME
A10: Phone:
A12: From | G12: To
A13: Device ID | B13: Cable (W) Conductor (SC) Jumper Clip (JC) | C13: Wire No. | D13: Wire ID | E13: Gauge/Size | F13: Page/Zone | G13: Device ID | H13: Location | I13: Page/Zone
A14: GR0290: | B14: SC | C14: GR0290 | D14: GRN/YEL | E14: 14 | F14: 9.C1 | G14: FRAME | H14: CUSTOMER^PANEL | I14: 9.C2 | M14: USED
A15: GR0291: | B15: SC | C15: GR0291 | D15: GRN/YEL | E15: 14 | F15: 9.C1 | G15: FRAME | H15: CUSTOMER^PANEL | I15: 9.C2 | M15: USED
A16: GR0292: | B16: SC | C16: GR0292 | D16: GRN/YEL | E16: 14 | F16: 9.C1 | G16: FRAME | H16: CUSTOMER^PANEL | I16: 9.C2 | M16: USED
A17: IEG0130:00 | B17: SC | C17: AT0140LS(S) | D17: GRN | E17: 14 | F17: 123.C6 | G17: XT0337:18 | H17: GENERATOR PANEL | I17: 123.C4 | M17: USED
A18: IEG0130:1 | B18: SC | C18: IEG01301 | D18: GRN | E18: 14 | F18: 28.D3 | G18: AF0123:SH | H18: GENERATOR PANEL | I18: 28.D3 | M18: USED
A19: IEG0130:3 | B19: SC | C19: IEG01303 | D19: GRN | E19: 14 | F19: 13.D7 | G19: AF0184:SH | H19: GENERATOR VIBRATION PANEL | I19: 13.D6 | M19: USED
A20: IEG0130:4 | B20: SC | C20: IEG01304 | D20: GRN | E20: 14 | F20: 5.B4 | G20: GR0180: | H20: GENERATOR VIBRATION PANEL | I20: 5.B5 | M20: USED
A21: IEG0130:0 | B21: SC | C21: IEG0130G | D21: GRN | E21: 8 | F21: 5.B2 | G21: IEG0010:2 | H21: GROUNDING BOX | I21: 5.B2 | M21: USED
A22: IEG0130:7 | B22: SC | C22: IEG01307 | D22: GRN | E22: 14 | F22: 51.A5 | G22: UV0272:IE | H22: ISOLATOR PANEL | I22: 51.A5 | M22: USED
A23: IEG0130:5 | B23: SC | C23: UV0610SHLD | D23: GRN | E23: 14 | F23: 24.B5 | G23: UV0610:SHLD | H23: ORBIT 60 | I23: 24.A1 | M23: USED
A24: IEG0130:6 | B24: SC | C24: UV0611SHLD | D24: GRN | E24: 14 | F24: 24.C5 | G24: UV0611:SHLD | H24: ORBIT 60 | I24: 24.B1 | M24: USED
A25: IEG0130:8 | B25: SC | C25: IEG01308 | D25: GRN | E25: 14 | F25: 26.C4 | G25: XT0400:3 | H25: VIBRATION DOOR PANEL | I25: 26.C4 | M25: USED
F27: SolarTools ver. 24.0.84.24712 (Jul 31, 2025)
A28: Report date: 2/20/2026 3:00 PM

Sheet GENERATOR PANEL
A1: GENERATOR PANEL
A2: CONTROL CONSOLE (GENERATOR PANEL)
A3: Project # | B3: 4M401
A4: Project Name | B4: FPSO GTG GENERATORS
A5: Revision | B5: C.2
A7: Controls DE | B7: J. SHORTER
A8: Phone: | B8: 0
A9: Controls ME
A10: Phone:
A12: From | G12: To
A13: Device ID | B13: Cable (W) Conductor (SC) Jumper Clip (JC) | C13: Wire No. | D13: Wire ID | E13: Gauge/Size | F13: Page/Zone | G13: Device ID | H13: Location | I13: Page/Zone
A14: XT0120:1 | B14: JC | C14: 0V | D14: CLIP | E14: --- | F14: 28.D1 | G14: XT0120:2 | H14: GENERATOR PANEL | I14: 28.D1 | M14: USED
A15: XT0336:2 | B15: JC | C15: 0V | D15: CLIP | E15: --- | F15: 27.C4 | G15: XT0336:3 | H15: GENERATOR PANEL | I15: 27.C4 | M15: USED
A16: XT0336:3 | B16: JC | C16: 0V | D16: CLIP | E16: --- | F16: 27.C4 | G16: XT0336:4 | H16: GENERATOR PANEL | I16: 27.D4 | M16: USED
A17: XT0351:1 | B17: JC | C17: VBUSA | D17: CLIP | E17: --- | F17: 119.B4 | G17: XT0351:2 | H17: GENERATOR PANEL | I17: 119.B4 | M17: USED
A18: XT0351:11 | B18: JC | C18: VGEN-B | D18: CLIP | E18: --- | F18: 119.C4 | G18: XT0351:12 | H18: GENERATOR PANEL | I18: 119.D4 | M18: USED
A19: XT0351:13 | B19: JC | C19: VGEN-C | D19: CLIP | E19: --- | F19: 119.D4 | G19: XT0351:14 | H19: GENERATOR PANEL | I19: 119.D4 | M19: USED
A20: XT0351:3 | B20: JC | C20: VBUSB | D20: CLIP | E20: --- | F20: 119.B4 | G20: XT0351:4 | H20: GENERATOR PANEL | I20: 119.B4 | M20: USED
A21: XT0351:5 | B21: JC | C21: VBUSC | D21: CLIP | E21: --- | F21: 119.B4 | G21: XT0351:6 | H21: GENERATOR PANEL | I21: 119.B4 | M21: USED
A22: XT0351:7 | B22: JC | C22: VBUSN | D22: CLIP | E22: --- | F22: 119.B4 | G22: XT0351:8 | H22: GENERATOR PANEL | I22: 119.B4 | M22: USED
A23: XT0351:9 | B23: JC | C23: VGEN-A | D23: CLIP | E23: --- | F23: 119.C4 | G23: XT0351:10 | H23: GENERATOR PANEL | I23: 119.C4 | M23: USED
A24: XT0370:1 | B24: JC | C24: EXC1 | D24: CLIP | E24: --- | F24: 120.C4 | G24: XT0370:2 | H24: GENERATOR PANEL | I24: 120.C5 | M24: USED
A25: XT0370:4 | B25: JC | C25: EXC2 | D25: CLIP | E25: --- | F25: 120.D4 | G25: XT0370:3 | H25: GENERATOR PANEL | I25: 120.D5 | M25: USED
... A229: AT0140:P2 | B229: WC0014 | C229: AT0140L2 | D229: ENET | E229: CABLE | F229: 30.D5 | G229: AU0200:L1 | H229: TCP | I229: 13.A3 | M229: USED
F231: SolarTools ver. 24.0.84.24712 (Jul 31, 2025)
A232: Report date: 2/20/2026 3:00 PM

Sheet GENERATOR VIBRATION PANEL
A1: GENERATOR VIBRATION PANEL
A2: CONTROL CONSOLE^(GENERATOR VIBRATION PANEL)
A3: Project # | B3: 4M401
A4: Project Name | B4: FPSO GTG GENERATORS
A5: Revision | B5: C.2
A7: Controls DE | B7: J. SHORTER
A8: Phone: | B8: 0
A9: Controls ME
A10: Phone:
A12: From | G12: To
A13: Device ID | B13: Cable (W) Conductor (SC) Jumper Clip (JC) | C13: Wire No. | D13: Wire ID | E13: Gauge/Size | F13: Page/Zone | G13: Device ID | H13: Location | I13: Page/Zone
A14: XT0110:3 | B14: JC | C14: 0V | D14: CLIP | E14: --- | F14: 24.B6 | G14: XT0110:4 | H14: GENERATOR VIBRATION PANEL | I14: 24.C6 | M14: USED
A15: XT0130:3 | B15: JC | C15: 0V | D15: CLIP | E15: --- | F15: 28.A5 | G15: XT0130:2 | H15: GENERATOR VIBRATION PANEL | I15: 28.A5 | M15: USED
A16: XT0180:1 | B16: JC | C16: 0V1 | D16: CLIP | E16: --- | F16: 13.D2 | G16: XT0180:2 | H16: GENERATOR VIBRATION PANEL | I16: 13.D2 | M16: USED
A17: XT0290:1 | B17: JC | C17: FU0137 | D17: CLIP | E17: --- | F17: 9.B6 | G17: XT0290:2 | H17: GENERATOR VIBRATION PANEL | I17: 9.B6 | M17: USED
A18: XT0290:4 | B18: JC | C18: 0V | D18: CLIP | E18: --- | F18: 9.B6 | G18: XT0290:5 | H18: GENERATOR VIBRATION PANEL | I18: 9.B6 | M18: USED
A19: AF0182:01 | B19: SC | C19: JP3 | D19: VIO | E19: 20 | F19: 41.A7 | G19: AF0182:33 | H19: GENERATOR VIBRATION PANEL | I19: 41.A7 | M19: USED
A20: AF0182:07 | B20: SC | C20: JP4 | D20: VIO | E20: 20 | F20: 148.A7 | G20: AF0182:39 | H20: GENERATOR VIBRATION PANEL | I20: 148.A7 | M20: USED
A21: AF0182:14 | B21: SC | C21: JP7 | D21: VIO | E21: 20 | F21: 34.C7 | G21: AF0182:46 | H21: GENERATOR VIBRATION PANEL | I21: 34.C7 | M21: USED
A22: AF0182:15 | B22: SC | C22: JP6 | D22: VIO | E22: 20 | F22: 148.B7 | G22: AF0182:47 | H22: GENERATOR VIBRATION PANEL | I22: 148.B7 | M22: USED
A23: KA0181:A1 | B23: SC | C23: 018102 | D23: WHT | E23: 20 | F23: 148.C7 | G23: AF0181:02 | H23: GENERATOR VIBRATION PANEL | I23: 148.C5 | M23: USED
A24: KA0183:A1 | B24: SC | C24: 018106 | D24: WHT | E24: 20 | F24: 148.D7 | G24: AF0181:06 | H24: GENERATOR VIBRATION PANEL | I24: 148.D5 | M24: USED
A25: KA7923:A1 | B25: SC | C25: KA7923A1 | D25: WHT | E25: 20 | F25: 36.D6 | G25: AF0181:08 | H25: GENERATOR VIBRATION PANEL | I25: 36.D6 | M25: USED
... A271: XT0110:3 | B271: SC | C271: 0V | D271: WHT | E271: 20 | F271: 24.B6 | G271: AF0450:53 | H271: VIBRATION DOOR PANEL | I271: 26.A3 | M271: USED
F273: SolarTools ver. 24.0.84.24712 (Jul 31, 2025)
A274: Report date: 2/20/2026 3:00 PM

Sheet GROUNDING BOX
A1: GROUNDING BOX
A3: Project # | B3: 4M401
A4: Project Name | B4: FPSO GTG GENERATORS
A5: Revision | B5: C.2
A7: Controls DE | B7: J. SHORTER
A8: Phone: | B8: 0
A9: Controls ME
A10: Phone:
A12: From | G12: To
A13: Device ID | B13: Cable (W) Conductor (SC) Jumper Clip (JC) | C13: Wire No. | D13: Wire ID | E13: Gauge/Size | F13: Page/Zone | G13: Device ID | H13: Location | I13: Page/Zone
A14: IEG0010:2 | B14: SC | C14: IEG0130G | D14: GRN | E14: 8 | F14: 5.B2 | G14: IEG0130:0 | H14: CUSTOMER^PANEL | I14: 5.B2 | M14: USED
A15: IEG0010:4 | B15: SC | C15: IEG00104 | D15: GRN | E15: 14 | F15: 5.A3 | G15: GR0133: | H15: PANEL A | I15: 5.A4 | M15: USED
A16: IEG0010:5 | B16: SC | C16: IEG00105 | D16: GRN | E16: 14 | F16: 5.A3 | G16: GR0134: | H16: PANEL A | I16: 5.A4 | M16: USED
A17: IEG0010:1 | B17: SC | C17: IEG0230G | D17: GRN | E17: 8 | F17: 5.B2 | G17: IEG0230:0 | H17: PANEL B | I17: 5.B2 | M17: USED
F19: SolarTools ver. 24.0.84.24712 (Jul 31, 2025)
A20: Report date: 2/20/2026 2:59 PM

Sheet ISOLATOR PANEL
A1: ISOLATOR PANEL
A2: CONTROL CONSOLE (ISOLATOR PANEL)
A3: Project # | B3: 4M401
A4: Project Name | B4: FPSO GTG GENERATORS
A5: Revision | B5: C.2
A7: Controls DE | B7: J. SHORTER
A8: Phone: | B8: 0
A9: Controls ME
A10: Phone:
A12: From | G12: To
A13: Device ID | B13: Cable (W) Conductor (SC) Jumper Clip (JC) | C13: Wire No. | D13: Wire ID | E13: Gauge/Size | F13: Page/Zone | G13: Device ID | H13: Location | I13: Page/Zone
A14: FU0272:LD | B14: SC | C14: UV0271P | D14: WHT | E14: 14 | F14: 51.A6 | G14: UV0271:8+ | H14: ISOLATOR PANEL | I14: 51.A5 | M14: USED
A15: GR0272: | B15: SC | C15: GR0272 | D15: GRN/YEL | E15: 14 | F15: 51.A6 | G15: FRAME | H15: ISOLATOR PANEL | I15: 51.A7 | M15: USED
A16: GR0273: | B16: SC | C16: GR0273 | D16: GRN/YEL | E16: 14 | F16: 51.A6 | G16: FRAME | H16: ISOLATOR PANEL | I16: 51.A7 | M16: USED
A17: UAI0836:1 | B17: SC | C17: TE61103 | D17: WHT | E17: 20 | F17: 137.C5 | G17: UAI0836:2 | H17: ISOLATOR PANEL | I17: 137.C5 | M17: USED
A18: UAI0842:1 | B18: SC | C18: TE26453 | D18: WHT | E18: 20 | F18: 84.D5 | G18: UAI0842:2 | H18: ISOLATOR PANEL | I18: 84.D5 | M18: USED
A19: UAI0851:1 | B19: SC | C19: TE66003 | D19: WHT | E19: 20 | F19: 133.A5 | G19: UAI0851:2 | H19: ISOLATOR PANEL | I19: 133.A5 | M19: USED
A20: UAI1100:1 | B20: SC | C20: AP11003 | D20: WHT | E20: 20 | F20: 51.A5 | G20: UAI1100:2 | H20: ISOLATOR PANEL | I20: 51.A5 | M20: USED
A21: UAI1110:1 | B21: SC | C21: TE11103 | D21: WHT | E21: 20 | F21: 50.A5 | G21: UAI1110:2 | H21: ISOLATOR PANEL | I21: 50.A5 | M21: USED
A22: UAI1111:1 | B22: SC | C22: TE11113 | D22: WHT | E22: 20 | F22: 50.A5 | G22: UAI1111:2 | H22: ISOLATOR PANEL | I22: 50.A5 | M22: USED
A23: UAI1112:1 | B23: SC | C23: TE11123 | D23: WHT | E23: 20 | F23: 50.B5 | G23: UAI1112:2 | H23: ISOLATOR PANEL | I23: 50.B5 | M23: USED
A24: UAI1170:1 | B24: SC | C24: AP11703 | D24: WHT | E24: 20 | F24: 54.C5 | G24: UAI1170:2 | H24: ISOLATOR PANEL | I24: 54.C5 | M24: USED
A25: UAI1204:2 | B25: SC | C25: UAI12042 | D25: WHT | E25: 20 | F25: 92.D5 | G25: UAI1204:3 | H25: ISOLATOR PANEL | I25: 92.D5 | M25: USED
... A315: FLOATING | B315: WC4649 | C315: UAI1520S | D315: SH | E315: 20 | F315: 60.A6 | G315: AF0450:23 | H315: VIBRATION DOOR PANEL | I315: 60.A7 | M315: USED
F317: SolarTools ver. 24.0.84.24712 (Jul 31, 2025)
A318: Report date: 2/20/2026 2:59 PM

Sheet JB4
A1: JB4
A2: POWER TURBINE PROXIMITOR BOX (JB4)
A3: Project # | B3: 4M401
A4: Project Name | B4: FPSO GTG GENERATORS
A5: Revision | B5: C.2
A7: Controls DE | B7: J. SHORTER
A8: Phone: | B8: 0
A9: Controls ME
A10: Phone:
A12: From | G12: To
A13: Device ID | B13: Cable (W) Conductor (SC) Jumper Clip (JC) | C13: Wire No. | D13: Wire ID | E13: Gauge/Size | F13: Page/Zone | G13: Device ID | H13: Location | I13: Page/Zone
A14: GR1250: | B14: SC | C14: GR1250 | D14: GRN/YEL | E14: 14 | F14: 92.D3 | G14: FRAME | H14: JB4 | I14: 92.D3 | M14: USED
F16: SolarTools ver. 24.0.84.24712 (Jul 31, 2025)
A17: Report date: 2/20/2026 2:59 PM

Sheet JB70
A1: JB70
A3: Project # | B3: 4M401
A4: Project Name | B4: FPSO GTG GENERATORS
A5: Revision | B5: C.2
A7: Controls DE | B7: J. SHORTER
A8: Phone: | B8: 0
A9: Controls ME
A10: Phone:
A12: From | G12: To
A13: Device ID | B13: Cable (W) Conductor (SC) Jumper Clip (JC) | C13: Wire No. | D13: Wire ID | E13: Gauge/Size | F13: Page/Zone | G13: Device ID | H13: Location | I13: Page/Zone
A14: XT0001:3 | B14: JC | C14: FU0210 | D14: CLIP | E14: --- | F14: 3.B3 | G14: XT0001:4 | H14: JB70 | I14: 3.B3 | M14: USED
A15: XT0001:5 | B15: JC | C15: 0V | D15: CLIP | E15: --- | F15: 3.B3 | G15: XT0001:6 | H15: JB70 | I15: 3.B3 | M15: USED
A16: AT1100:GND | B16: SC | C16: AT1100G | D16: GRN/YEL | E16: 14 | F16: 40.D3 | G16: XT0800:41 | H16: JB70 | I16: 40.D4 | M16: USED
A17: AT1100:NEG | B17: SC | C17: 0V | D17: WHT | E17: 14 | F17: 40.D3 | G17: XT0800:40 | H17: JB70 | I17: 40.D4 | M17: USED
A18: BA0001:V1(-) | B18: SC | C18: 0V | D18: WHT | E18: 16 | F18: 3.A2 | G18: XT0001:2 | H18: JB70 | I18: 3.A3 | M18: USED
A19: BA0001:V1(+) | B19: SC | C19: FU0001 | D19: WHT | E19: 16 | F19: 3.A2 | G19: FU0001:LD | H19: JB70 | I19: 3.A3 | M19: USED
A20: BA0002:V1(-) | B20: SC | C20: 0V | D20: WHT | E20: 16 | F20: 3.B2 | G20: XT0001:5 | H20: JB70 | I20: 3.B3 | M20: USED
A21: BA0002:V1(+) | B21: SC | C21: FU0002 | D21: WHT | E21: 16 | F21: 3.B2 | G21: FU0002:LD | H21: JB70 | I21: 3.B3 | M21: USED
A22: BA1100:NEG | B22: SC | C22: 0V | D22: WHT | E22: 16 | F22: 40.D1 | G22: XT1211:2 | H22: JB70 | I22: 40.D4 | M22: USED
A23: BA1100:POS | B23: SC | C23: FU1101LD | D23: WHT | E23: 16 | F23: 40.D1 | G23: FU1101:LD | H23: JB70 | I23: 40.C2 | M23: USED
A24: BA1211:NEG | B24: SC | C24: 0V | D24: WHT | E24: 16 | F24: 40.B1 | G24: XT1211:2 | H24: JB70 | I24: 40.D4 | M24: USED
A25: BA1211:POS | B25: SC | C25: FU1211LD | D25: WHT | E25: 16 | F25: 40.B1 | G25: FU1211:LD | H25: JB70 | I25: 40.B2 | M25: USED
... A111: XT0800:39 | B111: SC | C111: FU0136 | D111: WHT | E111: 14 | F111: 40.D4 | G111: FU1100:LI | H111: JB70 RIGHT RAIL | I111: 40.D3 | M111: USED
F113: SolarTools ver. 24.0.84.24712 (Jul 31, 2025)
A114: Report date: 2/20/2026 2:59 PM

Sheet JB70 LEFT RAIL
A1: JB70 LEFT RAIL
A2: JB70 (LEFT RAIL)
A3: Project # | B3: 4M401
A4: Project Name | B4: FPSO GTG GENERATORS
A5: Revision | B5: C.2
A7: Controls DE | B7: J. SHORTER
A8: Phone: | B8: 0
A9: Controls ME
A10: Phone:
A12: From | G12: To
A13: Device ID | B13: Cable (W) Conductor (SC) Jumper Clip (JC) | C13: Wire No. | D13: Wire ID | E13: Gauge/Size | F13: Page/Zone | G13: Device ID | H13: Location | I13: Page/Zone
A14: GR1101: | B14: SC | C14: GR1101 | D14: GRN/YEL | E14: 14 | F14: 5.A6 | G14: FRAME | H14: JB70 LEFT RAIL | I14: 5.A6 | M14: USED
F16: SolarTools ver. 24.0.84.24712 (Jul 31, 2025)
A17: Report date: 2/20/2026 2:59 PM

Sheet JB70 RIGHT RAIL
A1: JB70 RIGHT RAIL
A2: JB70 (RIGHT RAIL)
A3: Project # | B3: 4M401
A4: Project Name | B4: FPSO GTG GENERATORS
A5: Revision | B5: C.2
A7: Controls DE | B7: J. SHORTER
A8: Phone: | B8: 0
A9: Controls ME
A10: Phone:
A12: From | G12: To
A13: Device ID | B13: Cable (W) Conductor (SC) Jumper Clip (JC) | C13: Wire No. | D13: Wire ID | E13: Gauge/Size | F13: Page/Zone | G13: Device ID | H13: Location | I13: Page/Zone
A14: GR1100: | B14: SC | C14: GR1100 | D14: GRN/YEL | E14: 14 | F14: 5.A6 | G14: FRAME | H14: JB70 RIGHT RAIL | I14: 5.A7 | M14: USED
A15: FU1100:LD | B15: SC | C15: FU1100 | D15: WHT | E15: 14 | F15: 40.D3 | G15: AT1100:POS | H15: JB70 | I15: 40.D3 | M15: USED
A16: FU1100:LI | B16: SC | C16: FU0136 | D16: WHT | E16: 14 | F16: 40.D3 | G16: XT0800:39 | H16: JB70 | I16: 40.D4 | M16: USED
F18: SolarTools ver. 24.0.84.24712 (Jul 31, 2025)
A19: Report date: 2/20/2026 2:59 PM

Sheet JB72
A1: JB72
A3: Project # | B3: 4M401
A4: Project Name | B4: FPSO GTG GENERATORS
A5: Revision | B5: C.2
A7: Controls DE | B7: J. SHORTER
A8: Phone: | B8: 0
A9: Controls ME
A10: Phone:
A12: From | G12: To
A13: Device ID | B13: Cable (W) Conductor (SC) Jumper Clip (JC) | C13: Wire No. | D13: Wire ID | E13: Gauge/Size | F13: Page/Zone | G13: Device ID | H13: Location | I13: Page/Zone
A14: GR4141: | B14: SC | C14: GR4141 | D14: GRN/YEL | E14: 14 | F14: 5.C6 | G14: FRAME | H14: JB72 | I14: 5.C7 | M14: USED
A15: GR4142: | B15: SC | C15: GR4142 | D15: GRN/YEL | E15: 14 | F15: 5.C6 | G15: FRAME | H15: JB72 | I15: 5.C7 | M15: USED
A16: GR4181: | B16: SC | C16: GR4181 | D16: GRN/YEL | E16: 14 | F16: 5.C6 | G16: FRAME | H16: JB72 | I16: 5.C6 | M16: USED
A17: FU0319:LI | B17: WC8401 | C17: PMG1 | D17: RED | E17: 12 | F17: 120.C3 | G17: XT0833:1 | H17: JB72 | I17: 120.C3 | M17: USED
A18: FU0317:LI | B18: WC8401 | C18: PMG2 | D18: WHT | E18: 12 | F18: 120.C3 | G18: XT0833:2 | H18: JB72 | I18: 120.C3 | M18: USED
A19: FU0318:LI | B19: WC8401 | C19: PMG3 | D19: BLK | E19: 12 | F19: 120.C3 | G19: XT0833:3 | H19: JB72 | I19: 120.C3 | M19: USED
A20: XT0833:6 | B20: WC8401 | C20: PMGS | D20: SH | E20: 12 | F20: 120.C3 | G20: XT0833:4 | H20: JB72 | I20: 120.C3 | M20: USED
F22: SolarTools ver. 24.0.84.24712 (Jul 31, 2025)
A23: Report date: 2/20/2026 2:59 PM

Sheet ORBIT 60
A1: ORBIT 60
A3: Project # | B3: 4M401
A4: Project Name | B4: FPSO GTG GENERATORS
A5: Revision | B5: C.2
A7: Controls DE | B7: J. SHORTER
A8: Phone: | B8: 0
A9: Controls ME
A10: Phone:
A12: From | G12: To
A13: Device ID | B13: Cable (W) Conductor (SC) Jumper Clip (JC) | C13: Wire No. | D13: Wire ID | E13: Gauge/Size | F13: Page/Zone | G13: Device ID | H13: Location | I13: Page/Zone
A14: UV0610:P.E. | B14: SC | C14: UV0610G | D14: GRN/YEL | E14: 14 | F14: 24.A1 | G14: FRAME | H14: ORBIT 60 | I14: 24.B5 | M14: USED
A15: UV0611:P.E. | B15: SC | C15: UV0611G | D15: GRN/YEL | E15: 14 | F15: 24.B1 | G15: FRAME | H15: ORBIT 60 | I15: 24.C5 | M15: USED
A16: UV0610:SHLD | B16: SC | C16: UV0610SHLD | D16: GRN | E16: 14 | F16: 24.A1 | G16: IEG0130:5 | H16: CUSTOMER^PANEL | I16: 24.B5 | M16: USED
A17: UV0611:SHLD | B17: SC | C17: UV0611SHLD | D17: GRN | E17: 14 | F17: 24.B1 | G17: IEG0130:6 | H17: CUSTOMER^PANEL | I17: 24.C5 | M17: USED
A18: UV0610:+DC | B18: SC | C18: FU0701 | D18: WHT | E18: 14 | F18: 24.A1 | G18: FU0701:LD | H18: GENERATOR VIBRATION PANEL | I18: 24.B5 | M18: USED
A19: UV0610:COM | B19: SC | C19: 0V | D19: WHT | E19: 16 | F19: 24.A1 | G19: XT0110:3 | H19: GENERATOR VIBRATION PANEL | I19: 24.B6 | M19: USED
A20: UV0611:+DC | B20: SC | C20: FU0702 | D20: WHT | E20: 14 | F20: 24.B1 | G20: FU0702:LD | H20: GENERATOR VIBRATION PANEL | I20: 24.B5 | M20: USED
A21: UV0611:COM | B21: SC | C21: 0V | D21: WHT | E21: 16 | F21: 24.B1 | G21: XT0110:3 | H21: GENERATOR VIBRATION PANEL | I21: 24.B6 | M21: USED
A22: AP0624:SIG4 | B22: WC1203 | C22: UAI12147 | D22: RED | E22: 20 | F22: 93.A6 | G22: UAI1214:7 | H22: ISOLATOR PANEL | I22: 93.A5 | M22: USED
A23: AP0624:COM4 | B23: WC1203 | C23: UAI12148 | D23: BLK | E23: 20 | F23: 93.A6 | G23: UAI1214:8 | H23: ISOLATOR PANEL | I23: 93.A5 | M23: USED
A24: AP0624:SHLD4 | B24: WC1203 | C24: UAI1214S | D24: SH | E24: 20 | F24: 93.A6 | G24: FLOATING | H24: ISOLATOR PANEL | I24: 93.A6 | M24: USED
A25: AP0624:SIG1 | B25: WC1304 | C25: UAI47657 | D25: RED | E25: 20 | F25: 94.C6 | G25: UAI4765:7 | H25: ISOLATOR PANEL | I25: 94.C5 | M25: USED
... A102: AP0615:PORT A | B102: WC0601 | C102: AP0601ENET | D102: ENET | E102: CABLE | F102: 24.A1 | G102: AP0601:ENET | H102: PLC PANEL | I102: 24.A5 | M102: USED
F104: SolarTools ver. 24.0.84.24712 (Jul 31, 2025)
A105: Report date: 2/20/2026 2:59 PM

Sheet PANEL A
A1: PANEL A
A2: CONTROL CONSOLE (UNIT PANEL A)
A3: Project # | B3: 4M401
A4: Project Name | B4: FPSO GTG GENERATORS
A5: Revision | B5: C.2
A7: Controls DE | B7: J. SHORTER
A8: Phone: | B8: 0
A9: Controls ME
A10: Phone:
A12: From | G12: To
A13: Device ID | B13: Cable (W) Conductor (SC) Jumper Clip (JC) | C13: Wire No. | D13: Wire ID | E13: Gauge/Size | F13: Page/Zone | G13: Device ID | H13: Location | I13: Page/Zone
A14: XT0011:2 | B14: JC | C14: 523NEG | D14: CLIP | E14: --- | F14: 17.C3 | G14: XT0011:3 | H14: PANEL A | I14: 17.C3 | M14: USED
A15: XT0011:3 | B15: JC | C15: 523NEG | D15: CLIP | E15: --- | F15: 17.C3 | G15: XT0011:4 | H15: PANEL A | I15: 17.C3 | M15: USED
A16: XT0011:4 | B16: JC | C16: 523NEG | D16: CLIP | E16: --- | F16: 17.C3 | G16: XT0011:5 | H16: PANEL A | I16: 17.C3 | M16: USED
A17: XT0032:1 | B17: JC | C17: 24V | D17: CLIP | E17: --- | F17: 17.C5 | G17: XT0032:2 | H17: PANEL A | I17: 17.C5 | M17: USED
A18: XT0032:3 | B18: JC | C18: 0V | D18: CLIP | E18: --- | F18: 17.C5 | G18: XT0032:4 | H18: PANEL A | I18: 17.C5 | M18: USED
A19: XT0080:1 | B19: JC | C19: 0V | D19: CLIP | E19: --- | F19: 10.B1 | G19: XT0080:2 | H19: PANEL A | I19: 10.B1 | M19: USED
A20: XT0080:2 | B20: JC | C20: 0V | D20: CLIP | E20: --- | F20: 10.B1 | G20: XT0080:3 | H20: PANEL A | I20: 10.B1 | M20: USED
A21: XT0081:1 | B21: JC | C21: 0V | D21: CLIP | E21: --- | F21: 10.D1 | G21: XT0081:2 | H21: PANEL A | I21: 10.D1 | M21: USED
A22: XT0134:1 | B22: JC | C22: 0V | D22: CLIP | E22: --- | F22: 18.B3 | G22: XT0134:2 | H22: PANEL A | I22: 18.B3 | M22: USED
A23: XT0134:2 | B23: JC | C23: 0V | D23: CLIP | E23: --- | F23: 18.B3 | G23: XT0134:3 | H23: PANEL A | I23: 18.B3 | M23: USED
A24: XT0134:3 | B24: JC | C24: 0V | D24: CLIP | E24: --- | F24: 18.B3 | G24: XT0134:4 | H24: PANEL A | I24: 18.B3 | M24: USED
A25: XT0135:1 | B25: JC | C25: 0V | D25: CLIP | E25: --- | F25: 18.B4 | G25: XT0135:2 | H25: PANEL A | I25: 18.B4 | M25: USED
... A534: AU0090:L1 | B534: WC0045 | C534: AF0450L2 | D534: ENET | E534: CABLE | F534: 10.C1 | G534: AF0450:L2 | H534: VIBRATION DOOR PANEL | I534: 26.C3 | M534: USED
F536: SolarTools ver. 24.0.84.24712 (Jul 31, 2025)
A537: Report date: 2/20/2026 2:59 PM

Sheet PANEL B
A1: PANEL B
A2: CONTROL CONSOLE (UNIT PANEL B)
A3: Project # | B3: 4M401
A4: Project Name | B4: FPSO GTG GENERATORS
A5: Revision | B5: C.2
A7: Controls DE | B7: J. SHORTER
A8: Phone: | B8: 0
A9: Controls ME
A10: Phone:
A12: From | G12: To
A13: Device ID | B13: Cable (W) Conductor (SC) Jumper Clip (JC) | C13: Wire No. | D13: Wire ID | E13: Gauge/Size | F13: Page/Zone | G13: Device ID | H13: Location | I13: Page/Zone
A14: XT0002:3 | B14: JC | C14: FU0210 | D14: CLIP | E14: --- | F14: 3.C5 | G14: XT0002:4 | H14: PANEL B | I14: 3.D5 | M14: USED
A15: XT0002:5 | B15: JC | C15: 0V | D15: CLIP | E15: --- | F15: 3.D5 | G15: XT0002:6 | H15: PANEL B | I15: 3.D5 | M15: USED
A16: XT0050:1 | B16: JC | C16: 0V | D16: CLIP | E16: --- | F16: 12.B1 | G16: XT0050:2 | H16: PANEL B | I16: 12.B1 | M16: USED
A17: XT0050:2 | B17: JC | C17: 0V | D17: CLIP | E17: --- | F17: 12.B1 | G17: XT0050:3 | H17: PANEL B | I17: 12.B1 | M17: USED
A18: XT0060:1 | B18: JC | C18: 0V | D18: CLIP | E18: --- | F18: 11.D1 | G18: XT0060:2 | H18: PANEL B | I18: 11.D1 | M18: USED
A19: XT0233:1 | B19: JC | C19: FU0210 | D19: CLIP | E19: --- | F19: 18.C4 | G19: XT0233:2 | H19: PANEL B | I19: 18.C4 | M19: USED
A20: XT0233:2 | B20: JC | C20: FU0210 | D20: CLIP | E20: --- | F20: 18.C4 | G20: XT0233:3 | H20: PANEL B | I20: 18.C4 | M20: USED
A21: XT0235:1 | B21: JC | C21: 0V | D21: CLIP | E21: --- | F21: 18.D4 | G21: XT0235:2 | H21: PANEL B | I21: 18.D4 | M21: USED
A22: XT0235:2 | B22: JC | C22: 0V | D22: CLIP | E22: --- | F22: 18.D4 | G22: XT0235:3 | H22: PANEL B | I22: 18.D4 | M22: USED
A23: XT0240:11 | B23: JC | C23: FU0139 | D23: CLIP | E23: --- | F23: 21.C4 | G23: XT0240:12 | H23: PANEL B | I23: 21.C4 | M23: USED
A24: XT0240:12 | B24: JC | C24: FU0139 | D24: CLIP | E24: --- | F24: 21.C4 | G24: XT0240:17 | H24: PANEL B | I24: 21.D4 | M24: USED
A25: XT0240:9 | B25: JC | C25: 0V | D25: CLIP | E25: --- | F25: 21.D3 | G25: XT0240:10 | H25: PANEL B | I25: 21.D3 | M25: USED
... A449: IEG0230:8 | B449: SC | C449: IEG02308 | D449: GRN | E449: 14 | F449: 13.A2 | G449: GR0200: | H449: TCP | I449: 13.A3 | M449: USED
A451: Report date: 2/20/2026 2:59 PM | F451: SolarTools ver. 24.0.84.24712 (Jul 31, 2025)

Sheet PLC PANEL
A1: PLC PANEL
A2: CONTROL CONSOLE (UNIT PANEL A)
A3: Project # | B3: 4M401
A4: Project Name | B4: FPSO GTG GENERATORS
A5: Revision | B5: C.2
A7: Controls DE | B7: J. SHORTER
A8: Phone: | B8: 0
A9: Controls ME
A10: Phone:
A12: From | G12: To
A13: Device ID | B13: Cable (W) Conductor (SC) Jumper Clip (JC) | C13: Wire No. | D13: Wire ID | E13: Gauge/Size | F13: Page/Zone | G13: Device ID | H13: Location | I13: Page/Zone
A14: AR0600:IE1 | B14: SC | C14: UV0600G | D14: GRN | E14: 14 | F14: 6.A1 | G14: UV0600:GND | H14: PLC PANEL | I14: 6.B2 | M14: USED
A15: AP0602:L2 | B15: WC0001 | C15: AP0602L2 | D15: ENET | E15: CABLE | F15: 6.A3 | G15: AP0603:L1 | H15: PLC PANEL | I15: 6.A3 | M15: USED
A16: AP0607:ENET | B16: WC1200 | C16: AP0607ENET | D16: ENET | E16: CABLE | F16: 4.C6 | G16: BA1200:RJ45 | H16: PLC PANEL | I16: 4.C6 | M16: USED
A17: AP0606:ENET | B17: WC1201 | C17: AP0606ENET | D17: ENET | E17: CABLE | F17: 4.C6 | G17: BA1201:RJ45 | H17: PLC PANEL | I17: 4.B6 | M17: USED
A18: AP0604:ENET | B18: WC1202 | C18: AP0604ENET | D18: ENET | E18: CABLE | F18: 4.B6 | G18: BA1202:RJ45 | H18: PLC PANEL | I18: 4.A6 | M18: USED
A19: AP0602:L1 | B19: WC9003 | C19: BA0003RJ45 | D19: ENET | E19: CABLE | F19: 6.A3 | G19: BA0003:RJ45 | H19: PLC PANEL | I19: 3.D6 | M19: USED
A20: AP0601:ENET | B20: WC0601 | C20: AP0601ENET | D20: ENET | E20: CABLE | F20: 24.A5 | G20: AP0615:PORT A | H20: ORBIT 60 | I20: 24.A1 | M20: USED
A21: BA1200:V1(-) | B21: SC | C21: 0V | D21: WHT | E21: 16 | F21: 4.C6 | G21: XT0135:3 | H21: PANEL A | I21: 18.B4 | M21: USED
A22: BA1200:V1(+) | B22: SC | C22: FU0137 | D22: WHT | E22: 16 | F22: 4.C6 | G22: XT0139:4 | H22: PANEL A | I22: 18.A4 | M22: USED
A23: BA1201:V1(-) | B23: SC | C23: 0V | D23: WHT | E23: 16 | F23: 4.B6 | G23: XT0135:3 | H23: PANEL A | I23: 18.B4 | M23: USED
A24: BA1201:V1(+) | B24: SC | C24: FU0137 | D24: WHT | E24: 16 | F24: 4.B6 | G24: XT0139:4 | H24: PANEL A | I24: 18.A4 | M24: USED
A25: BA1202:V1(-) | B25: SC | C25: 0V | D25: WHT | E25: 16 | F25: 4.A6 | G25: XT0135:4 | H25: PANEL A | I25: 18.B4 | M25: USED
... A40: AP0603:L2 | B40: WC0003 | C40: AP0603L2 | D40: ENET | E40: CABLE | F40: 6.A3 | G40: AF0450:L1 | H40: VIBRATION DOOR PANEL | I40: 26.C3 | M40: USED
F42: SolarTools ver. 24.0.84.24712 (Jul 31, 2025)
A43: Report date: 2/20/2026 2:59 PM

Sheet PWR DISTRIBUTION RAIL
A1: PWR DISTRIBUTION RAIL
A2: CONTROL CONSOLE DOOR (PWR DIST RAIL)
A3: Project # | B3: 4M401
A4: Project Name | B4: FPSO GTG GENERATORS
A5: Revision | B5: C.2
A7: Controls DE | B7: J. SHORTER
A8: Phone: | B8: 0
A9: Controls ME
A10: Phone:
A12: From | G12: To
A13: Device ID | B13: Cable (W) Conductor (SC) Jumper Clip (JC) | C13: Wire No. | D13: Wire ID | E13: Gauge/Size | F13: Page/Zone | G13: Device ID | H13: Location | I13: Page/Zone
A14: XT0561:2 | B14: JC | C14: FU0200LI | D14: CLIP | E14: --- | F14: 13.A2 | G14: XT0561:1 | H14: PWR DISTRIBUTION RAIL | I14: 13.A2 | M14: USED
A15: XT0562:1 | B15: JC | C15: 0V1 | D15: CLIP | E15: --- | F15: 13.B2 | G15: XT0562:2 | H15: PWR DISTRIBUTION RAIL | I15: 13.B2 | M15: USED
A16: XT0562:2 | B16: JC | C16: 0V1 | D16: CLIP | E16: --- | F16: 13.B2 | G16: XT0562:3 | H16: PWR DISTRIBUTION RAIL | I16: 13.B2 | M16: USED
A17: XT0560:2 | B17: SC | C17: JW0 | D17: CLIP | E17: -- | F17: 13.B2 | G17: XT0562:1 | H17: PWR DISTRIBUTION RAIL | I17: 13.B2 | M17: USED
A18: AT0680:NEG | B18: SC | C18: 0V | D18: WHT | E18: 14 | F18: 8.B4 | G18: XT0680:2 | H18: PWR DISTRIBUTION RAIL | I18: 8.B3 | M18: USED
A19: AT0680:POS | B19: SC | C19: AT0680POS | D19: WHT | E19: 14 | F19: 8.B4 | G19: XT0680:1 | H19: PWR DISTRIBUTION RAIL | I19: 8.B3 | M19: USED
A20: FU0190:LI | B20: SC | C20: FU0200LI | D20: WHT | E20: 14 | F20: 13.C3 | G20: FU0273:LI | H20: PWR DISTRIBUTION RAIL | I20: 13.B3 | M20: USED
A21: FU0200:LI | B21: SC | C21: FU0200LI | D21: WHT | E21: 14 | F21: 13.A3 | G21: FU0201:LI | H21: PWR DISTRIBUTION RAIL | I21: 13.B3 | M21: USED
A22: FU0200:LI | B22: SC | C22: FU0200LI | D22: WHT | E22: 14 | F22: 13.A3 | G22: XT0561:1 | H22: PWR DISTRIBUTION RAIL | I22: 13.A2 | M22: USED
A23: FU0201:LI | B23: SC | C23: FU0200LI | D23: WHT | E23: 14 | F23: 13.B3 | G23: FU0273:LI | H23: PWR DISTRIBUTION RAIL | I23: 13.B3 | M23: USED
A24: FU0560:LD | B24: SC | C24: FU0200LI | D24: WHT | E24: 14 | F24: 13.A2 | G24: XT0561:1 | H24: PWR DISTRIBUTION RAIL | I24: 13.A2 | M24: USED
A25: FU0560:LI | B25: SC | C25: FU0136 | D25: WHT | E25: 12 | F25: 13.A2 | G25: XT0560:1 | H25: PWR DISTRIBUTION RAIL | I25: 13.A2 | M25: USED
... A61: XT0563:9 | B61: SC | C61: TCP18B2 | D61: WHT | E61: 20 | F61: 15.D6 | G61: SB0400:22 | H61: TCP | I61: 15.D5 | M61: USED
F63: SolarTools ver. 24.0.84.24712 (Jul 31, 2025)
A64: Report date: 2/20/2026 2:59 PM

Sheet REDUNDANT POWER SUPPLY
A1: REDUNDANT POWER SUPPLY
A2: CONTROL CONSOLE^(REDUNDANT POWER SUPPLY)
A3: Project # | B3: 4M401
A4: Project Name | B4: FPSO GTG GENERATORS
A5: Revision | B5: C.2
A7: Controls DE | B7: J. SHORTER
A8: Phone: | B8: 0
A9: Controls ME
A10: Phone:
A12: From | G12: To
A13: Device ID | B13: Cable (W) Conductor (SC) Jumper Clip (JC) | C13: Wire No. | D13: Wire ID | E13: Gauge/Size | F13: Page/Zone | G13: Device ID | H13: Location | I13: Page/Zone
A14: XT0033:2 | B14: JC | C14: 24V | D14: CLIP | E14: --- | F14: 17.D5 | G14: XT0033:1 | H14: REDUNDANT POWER SUPPLY | I14: 17.D5 | M14: USED
A15: XT0033:4 | B15: JC | C15: 0V | D15: CLIP | E15: --- | F15: 17.D5 | G15: XT0033:3 | H15: REDUNDANT POWER SUPPLY | I15: 17.D5 | M15: USED
A16: FU0031:LD | B16: SC | C16: 24V | D16: WHT | E16: 10 | F16: 17.D5 | G16: XT0033:1 | H16: REDUNDANT POWER SUPPLY | I16: 17.D5 | M16: USED
A17: FU0031:LI | B17: SC | C17: 24V2 | D17: WHT | E17: 10 | F17: 17.D5 | G17: UJ0031:OUT(+) | H17: REDUNDANT POWER SUPPLY | I17: 17.D4 | M17: USED
A18: GR0030: | B18: SC | C18: GR0030 | D18: GRN/YEL | E18: 14 | F18: 17.D3 | G18: FRAME | H18: REDUNDANT POWER SUPPLY | I18: 17.D3 | M18: USED
A19: GR0031: | B19: SC | C19: GR0031 | D19: GRN/YEL | E19: 14 | F19: 17.D3 | G19: FRAME | H19: REDUNDANT POWER SUPPLY | I19: 17.D3 | M19: USED
A20: QS0031:LD-1 | B20: SC | C20: UJ0031P | D20: WHT | E20: 12 | F20: 17.D3 | G20: UJ0031:+ | H20: REDUNDANT POWER SUPPLY | I20: 17.D4 | M20: USED
A21: QS0031:LD-3 | B21: SC | C21: UJ0031N | D21: WHT | E21: 12 | F21: 17.D3 | G21: UJ0031:- | H21: REDUNDANT POWER SUPPLY | I21: 17.D4 | M21: USED
A22: UJ0031:G | B22: SC | C22: UJ0031G | D22: GRN/YEL | E22: 12 | F22: 17.D4 | G22: FRAME | H22: REDUNDANT POWER SUPPLY | I22: 17.D4 | M22: USED
A23: UJ0031:OUT(-) | B23: SC | C23: 0V | D23: WHT | E23: 10 | F23: 17.D4 | G23: XT0033:4 | H23: REDUNDANT POWER SUPPLY | I23: 17.D5 | M23: USED
A24: QS0031:LI-2 | B24: SC | C24: QS00311 | D24: WHT | E24: 12 | F24: 17.D3 | G24: XT0012:1 | H24: PANEL A | I24: 17.D3 | M24: USED
A25: QS0031:LI-4 | B25: SC | C25: QS00312 | D25: WHT | E25: 12 | F25: 17.D3 | G25: XT0012:2 | H25: PANEL A | I25: 17.D3 | M25: USED
... A34: XT0033:3 | B34: SC | C34: 0V | D34: WHT | E34: 14 | F34: 17.D5 | G34: XT0134:1 | H34: PANEL A | I34: 18.B3 | M34: USED
F36: SolarTools ver. 24.0.84.24712 (Jul 31, 2025)
A37: Report date: 2/20/2026 2:59 PM

Sheet TCP
A1: TCP
A2: CONTROL CONSOLE DOOR^(TURBINE CONTROL PANEL)
A3: Project # | B3: 4M401
A4: Project Name | B4: FPSO GTG GENERATORS
A5: Revision | B5: C.2
A7: Controls DE | B7: J. SHORTER
A8: Phone: | B8: 0
A9: Controls ME
A10: Phone:
A12: From | G12: To
A13: Device ID | B13: Cable (W) Conductor (SC) Jumper Clip (JC) | C13: Wire No. | D13: Wire ID | E13: Gauge/Size | F13: Page/Zone | G13: Device ID | H13: Location | I13: Page/Zone
A14: AF0201:00 | B14: SC | C14: TCP13NO | D14: WHT | E14: 20 | F14: 15.A3 | G14: SH0400:NO | H14: TCP | I14: 15.A1 | M14: USED
A15: AF0201:01 | B15: SC | C15: TCP14NO | D15: WHT | E15: 20 | F15: 15.A3 | G15: SH0401:NO | H15: TCP | I15: 15.A1 | M15: USED
A16: AF0201:02 | B16: SC | C16: TCP15NO | D16: WHT | E16: 20 | F16: 15.B3 | G16: SH0409:NO | H16: TCP | I16: 15.B1 | M16: USED
A17: AF0201:03 | B17: SC | C17: TCP16NO | D17: WHT | E17: 20 | F17: 15.B3 | G17: SH0410:NO | H17: TCP | I17: 15.B1 | M17: USED
A18: AF0201:04 | B18: SC | C18: TCP17A2 | D18: WHT | E18: 20 | F18: 15.C3 | G18: SA0400:14 | H18: TCP | I18: 15.C1 | M18: USED
A19: AF0201:05 | B19: SC | C19: TCP17B2 | D19: WHT | E19: 20 | F19: 15.C3 | G19: SA0400:22 | H19: TCP | I19: 15.C1 | M19: USED
A20: AF0201:08 | B20: SC | C20: TCP23NC | D20: WHT | E20: 20 | F20: 15.D3 | G20: SB0401:NC | H20: TCP | I20: 15.D1 | M20: USED
A21: AF0201:09 | B21: SC | C21: TCP24NO | D21: WHT | E21: 20 | F21: 15.D3 | G21: SB0402:NO | H21: TCP | I21: 15.D1 | M21: USED
A22: AF0201:10 | B22: SC | C22: TCP25NO | D22: WHT | E22: 20 | F22: 15.A6 | G22: SB0403:NO | H22: TCP | I22: 15.A5 | M22: USED
A23: AF0201:11 | B23: SC | C23: TCP26NO | D23: WHT | E23: 20 | F23: 15.A7 | G23: SB0404:NO | H23: TCP | I23: 15.A5 | M23: USED
A24: AF0201:12 | B24: SC | C24: TCP29NO | D24: WHT | E24: 20 | F24: 16.D3 | G24: SB0405:NO | H24: TCP | I24: 16.D1 | M24: USED
A25: AF0201:13 | B25: SC | C25: TCP28NC | D25: WHT | E25: 20 | F25: 16.C3 | G25: SB0406:NC | H25: TCP | I25: 16.C1 | M25: USED
... A161: XT0564:1 B2 | B161: SC | C161: KA023612 | D161: WHT | E161: 20 | F161: 15.B5 | G161: XT0563:3 | H161: PWR DISTRIBUTION RAIL | I161: 15.B6 | M161: USED
F163: SolarTools ver. 24.0.84.24712 (Jul 31, 2025)
A164: Report date: 2/20/2026 2:59 PM

Sheet VIBRATION DOOR PANEL
A1: VIBRATION DOOR PANEL
A3: Project # | B3: 4M401
A4: Project Name | B4: FPSO GTG GENERATORS
A5: Revision | B5: C.2
A7: Controls DE | B7: J. SHORTER
A8: Phone: | B8: 0
A9: Controls ME
A10: Phone:
A12: From | G12: To
A13: Device ID | B13: Cable (W) Conductor (SC) Jumper Clip (JC) | C13: Wire No. | D13: Wire ID | E13: Gauge/Size | F13: Page/Zone | G13: Device ID | H13: Location | I13: Page/Zone
A14: AF0450:32 | B14: SC | C14: XT04001 | D14: GRN | E14: 16 | F14: 26.A3 | G14: XT0400:1 | H14: VIBRATION DOOR PANEL | I14: 26.B4 | M14: USED
A15: XT0400:3 | B15: SC | C15: IEG01308 | D15: GRN | E15: 14 | F15: 26.C4 | G15: IEG0130:8 | H15: CUSTOMER^PANEL | I15: 26.C4 | M15: USED
A16: AF0450:53 | B16: SC | C16: 0V | D16: WHT | E16: 20 | F16: 26.A3 | G16: XT0110:3 | H16: GENERATOR VIBRATION PANEL | I16: 24.B6 | M16: USED
A17: AF0450:55 | B17: SC | C17: FU0113 | D17: WHT | E17: 16 | F17: 26.A3 | G17: XT0110:2 | H17: GENERATOR VIBRATION PANEL | I17: 24.A6 | M17: USED
A18: AF0450:06 | B18: WC4649 | C18: UAI152012 | D18: RED | E18: 20 | F18: 60.A7 | G18: UAI1520:11 | H18: ISOLATOR PANEL | I18: 60.A5 | M18: USED
A19: AF0450:08 | B19: WC4649 | C19: UAI152011 | D19: BLK | E19: 20 | F19: 60.A7 | G19: UAI1520:12 | H19: ISOLATOR PANEL | I19: 60.A5 | M19: USED
A20: AF0450:23 | B20: WC4649 | C20: UAI1520S | D20: SH | E20: 20 | F20: 60.A7 | G20: FLOATING | H20: ISOLATOR PANEL | I20: 60.A6 | M20: USED
A21: AF0450:L2 | B21: WC0045 | C21: AF0450L2 | D21: ENET | E21: CABLE | F21: 26.C3 | G21: AU0090:L1 | H21: PANEL A | I21: 10.C1 | M21: USED
A22: AF0450:L1 | B22: WC0003 | C22: AP0603L2 | D22: ENET | E22: CABLE | F22: 26.C3 | G22: AP0603:L2 | H22: PLC PANEL | I22: 6.A3 | M22: USED
F24: SolarTools ver. 24.0.84.24712 (Jul 31, 2025)
A25: Report date: 2/20/2026 2:59 PM

Sheet Panel Errors
A1: Panel Errors
A3: Project # | B3: 4M401
A4: Project Name | B4: FPSO GTG GENERATORS
A5: Revision | B5: C.2
A7: Controls DE | B7: J. SHORTER
A8: Phone: | B8: 0
A9: Controls ME
A10: Phone:
A12: From | H12: To
A13: Device ID | B13: Location | C13: Cable (W) Conductor (SC) Jumper Clip (JC) | D13: Wire ID | E13: Wire No. | F13: Gauge/Size | G13: Page/Zone | H13: Device ID | I13: Location | J13: Page/Zone
A16: Report date: 2/20/2026 2:59 PM | E16: SolarTools ver. 24.0.84.24712 (Jul 31, 2025)

Sheet Cable Part Numbers
A1: Cable Part Numbers | D1: SolarTools ver. 24.0.84.24712 (Jul 31, 2025)
A2: Project # | B2: 4M401
D3: Report date: 2/20/2026 3:02 PM
A4: Project Name | B4: FPSO GTG GENERATORS
A6: Revision | B6: C.2
A8: Controls DE | B8: J. SHORTER
A9: Phone: | B9: 0
A10: Controls ME
A11: Phone:
A13: Device ID | C13: Part Number | E13: Description
A14: WC4524 | C14: 1022941-12 | E14: TPE, 1 PAIR TWISTED SHIELDED
A15: WC5072 | C15: PART OF 1103208-100 | E15: CABLE, 2 CONDUCTOR UNSHIELDED PART OF HORN
A17: WC0001 | C17: 1302073-36 | E17: CABLE, ETHERNET - 36 INCHES
A18: WC0003 | C18: 1302073-36 | E18: CABLE, ETHERNET - 36 INCHES
A19: WC0005 | C19: 1302073-36 | E19: CABLE, COMMUNICATION CABLE - 36 INCHES
A20: WC0006 | C20: 1302073-36 | E20: CABLE, ETHERNET - 36 INCHES
A21: WC0007 | C21: 1302073-36 | E21: CABLE, ETHERNET - 36 INCHES
A22: WC0008 | C22: 1302073-36 | E22: CABLE, ETHERNET - 36 INCHES
A23: WC0009 | C23: 1302073-36 | E23: CABLE, ETHERNET - 36 INCHES
A24: WC0010 | C24: 1302073-36 | E24: CABLE, ETHERNET - 36 INCHES
A25: WC0012 | C25: 1302073-36 | E25: CABLE, ETHERNET - 36 INCHES
... A177: WTXRX2 | C177: 1022941-12 | E177: TPE, 1 PAIR TWISTED SHIELDED

Sheet Part Number List
A1: Part Number List | C1: SolarTools ver. 24.0.84.24712 (Jul 31, 2025)
A2: Project # | B2: 4M401
C3: Report date: 2/20/2026 3:01 PM
A4: Project Name | B4: FPSO GTG GENERATORS
A6: Revision | B6: C.2
A8: Controls DE | B8: J. SHORTER
A9: Phone: | B9: 0
A10: Controls ME
A11: Phone:
A13: Device ID | B13: Part Number | C13: Description | D13: Location
A14: GR0170 | B14: 903849C1 | C14: RAIL GROUND, DIN RAIL GROUNDING | D14: BLANK PANEL
A15: GR0171 | B15: 903849C1 | C15: RAIL GROUND, DIN RAIL GROUNDING | D15: BLANK PANEL
A17: AT0190 | B17: 1577354-5100 | C17: WORKSTATION, PANEL COMPUTER, TT4000 | D17: CONSOLE
A18: AT0190K | B18: 1068334 | C18: KEYBOARD, TYPING INTERFACE | D18: CONSOLE
A19: EL0271 | B19: 1022899 | C19: LIGHT, LED, WHITE | D19: CONSOLE
A20: EL0273 | B20: 1022899,1024595-100 | C20: LIGHT, LED, WHITE | D20: CONSOLE
A21: HA0273 | B21: 1113568-200 | C21: HORN, AUDIBLE ALARM | D21: CONSOLE
A22: ZS0271 | B22: 1113474-1,22650R1,22690R1,23523R1,24556R1,915786C1 | C22: LIMIT SWITCH, CONSOLE DOOR OPEN | D22: CONSOLE
A23: ZS0273 | B23: [2]1113474-1,22650R1,22690R1,23523R1,24556R1,915786C1 | C23: LIMIT SWITCH, CONSOLE DOOR OPEN | D23: CONSOLE
A25: GR0290 | B25: 903849C1 | C25: RAIL GROUND, DIN RAIL GROUNDING | D25: CUSTOMER^PANEL
A26: GR0291 | B26: 903849C1 | C26: RAIL GROUND, DIN RAIL GROUNDING | D26: CUSTOMER^PANEL
... A617: XT0400 | B617: 1066730-1,1066730-2,1066730-67 | C617: TERMINAL STRIP, 4 CONDUCTOR | D617: VIBRATION DOOR PANEL

Sheet JB70_S
A1: JB70
A3: Project # | B3: 4M401
A4: Project Name | B4: FPSO GTG GENERATORS
A5: Revision | B5: C.2
A7: Controls DE | B7: J. SHORTER
A8: Phone: | B8: 0
A9: Controls ME
A10: Phone:
A12: From | G12: To
A13: Device ID | B13: Wire No. | C13: Wire ID | D13: Gauge/Size | E13: Length | F13: Device ID | G13: Location | H13: Bundle Name
A14: AT1100:NEG | B14: -0V | C14: WHT | D14: 14 | E14: 240 | F14: XT0800:40 | G14: A PNL | H14: AT1100
A15: AT1100:POS | B15: FU1100 | C15: WHT | D15: 14 | E15: 180 | F15: FU1100:LD | G15: JB70 R/RAIL
A17: HL0171:X1 | B17: HL0171X1 | C17: WHT | D17: 20 | E17: 200 | F17: RR0175A: -10K OHM | G17: A PNL | H17: HL0171
A18: HL0171:X2 | B18: HL0171X2 | C18: WHT | D18: 20 | E18: 200 | F18: VD0175A:--1N4005/1 | G18: A PNL
A20: HL0172:X1 | B20: HL0172X1 | C20: WHT | D20: 20 | E20: 200 | F20: RR0175I: -10K OHM | G20: A PNL | H20: HL0172
A21: HL0172:X2 | B21: HL0172X2 | C21: WHT | D21: 20 | E21: 200 | F21: VD0175I:--1N4005/1 | G21: A PNL
A23: HL0173:X1 | B23: HL0173X1 | C23: WHT | D23: 20 | E23: 200 | F23: RR0175D: -10K OHM | G23: A PNL | H23: HL0173
A24: HL0173:X2 | B24: HL0173X2 | C24: WHT | D24: 20 | E24: 200 | F24: VD0175D:--1N4005/1 | G24: A PNL
A26: SA0170:B1-13 | B26: SA0170B113 | C26: WHT | D26: 20 | E26: 200 | F26: XT0811:1 | G26: A PNL | H26: SA0170
A27: SA0170:B1-14 | B27: SA0170B114 | C27: WHT | D27: 20 | E27: 200 | F27: XT0811:2 | G27: A PNL
A28: SA0170:B2-13 | B28: SA0170B213 | C28: WHT | D28: 20 | E28: 200 | F28: XT0811:32 | G28: A PNL
A29: SA0170:B2-14 | B29: SA0170B214 | C29: WHT | D29: 20 | E29: 200 | F29: XT0811:33 | G29: A PNL
A31: SB0170:13 | B31: SB017013 | C31: WHT | D31: 20 | E31: 200 | F31: RR0175M: -10K OHM | G31: A PNL | H31: SB0170
A32: SB0170:14 | B32: SB017014 | C32: WHT | D32: 20 | E32: 200 | F32: RR0175M: -10K OHM | G32: A PNL
A34: SB0471:11 | B34: SB047111 | C34: WHT | D34: 20 | E34: 240 | F34: XT0800:21 | G34: A PNL | H34: SB0471
A35: SB0471:12 | B35: SB047112 | C35: WHT | D35: 20 | E35: 240 | F35: XT0800:22 | G35: A PNL
A37: SB0473:13 | B37: SB047313 | C37: WHT | D37: 20 | E37: 240 | F37: XT0800:23 | G37: A PNL | H37: SB0473
A38: SB0473:14 | B38: SB047314 | C38: WHT | D38: 20 | E38: 240 | F38: XT0800:24 | G38: A PNL
A40: SB0474:13 | B40: SB047413 | C40: WHT | D40: 20 | E40: 240 | F40: XT0800:25 | G40: A PNL | H40: SB0474
A41: SB0474:14 | B41: SB047414 | C41: WHT | D41: 20 | E41: 240 | F41: XT0800:26 | G41: A PNL
A43: SB0472:B1-12 | B43: ESTOP | C43: WHT | D43: 20 | E43: 240 | F43: XT0800:32 | G43: A PNL | H43: SB0472
A44: SB0472:B1-11 | B44: ESTOPA | C44: WHT | D44: 20 | E44: 240 | F44: XT0800:31 | G44: A PNL
A45: SB0472:B2-11 | B45: SB0472B11 | C45: WHT | D45: 20 | E45: 240 | F45: XT0800:33 | G45: A PNL
A46: SB0472:B2-12 | B46: SB0472B12 | C46: WHT | D46: 20 | E46: 240 | F46: XT0800:34 | G46: A PNL
A48: SH0470:11 | B48: SH047011 | C48: WHT | D48: 20 | E48: 240 | F48: XT0800:7 | G48: A PNL | H48: SH0470
A49: SH0470:12 | B49: SH047012 | C49: WHT | D49: 20 | E49: 240 | F49: XT0800:8 | G49: A PNL
A50: SH0470:13 | B50: SH047013 | C50: WHT | D50: 20 | E50: 240 | F50: XT0800:9 | G50: A PNL
A51: SH0470:14 | B51: SH047014 | C51: WHT | D51: 20 | E51: 240 | F51: XT0800:10 | G51: A PNL
A52: SH0470:X1 | B52: SH0470X1 | C52: WHT | D52: 20 | E52: 240 | F52: XT0800:12 | G52: A PNL
A53: SH0470:X2 | B53: SH0470X2 | C53: WHT | D53: 20 | E53: 240 | F53: XT0800:11 | G53: A PNL
...

Sheet JB70 RIGHT RAIL_S
A1: JB70 RIGHT RAIL
A2: JB70 (RIGHT RAIL)
A3: Project # | B3: 4M401
A4: Project Name | B4: FPSO GTG GENERATORS
A5: Revision | B5: C.2
A7: Controls DE | B7: J. SHORTER
A8: Phone: | B8: 0
A9: Controls ME
A10: Phone:
A12: From | G12: To
A13: Device ID | B13: Wire No. | C13: Wire ID | D13: Gauge/Size | E13: Length | F13: Device ID | G13: Location | H13: Bundle Name
A14: FU1100:LI | B14: FU0136 | C14: WHT | D14: 14 | E14: 180 | F14: XT0800:39 | G14: A PNL | H14: FU-A

Sheet A PNL_S
A1: A PANEL
A3: Project # | B3: 4M401
A4: Project Name | B4: FPSO GTG GENERATORS
A5: Revision | B5: C.2
A7: Controls DE | B7: J. SHORTER
A8: Phone: | B8: 0
A9: Controls ME
A10: Phone:
A12: From | G12: To
A13: Device ID | B13: Wire No. | C13: Wire ID | D13: Gauge/Size | E13: Length | F13: Device ID | G13: Location | H13: Bundle Name
A14: RR0175A: -10K OHM | B14: VD0175A | C14: WHT | D14: 20 | E14: 60 | F14: VD0175A:+-1N4005/1 | G14: A PNL | H14: RR0175
A15: RR0175D: -10K OHM | B15: VD0175D | C15: WHT | D15: 20 | E15: 60 | F15: VD0175D:+-1N4005/1 | G15: A PNL
A16: RR0175I: -10K OHM | B16: VD0175I | C16: WHT | D16: 20 | E16: 60 | F16: VD0175I:+-1N4005/1 | G16: A PNL
A18: UA1200:J1-9 | B18: -0V | C18: WHT | D18: 20 | E18: 120 | F18: XT0805:17 | G18: A PNL | H18: UA1200
A19: UA1200:J1-10 | B19: FU0212 | C19: WHT | D19: 20 | E19: 120 | F19: XT0805:16 | G19: A PNL
A20: UA1200:J2-2 | B20: FU0212 | C20: WHT | D20: 20 | E20: 120 | F20: XT0805:15 | G20: A PNL
A21: UA1200:J1-8 | B21: UA1200J | C21: WHT | D21: 20 | E21: 60 | F21: UA1200:J3-5 | G21: A PNL
A22: UA1200:J1-4 | B22: UA1200J14 | C22: WHT | D22: 20 | E22: 120 | F22: XT0805:10 | G22: A PNL
A23: UA1200:J1-5 | B23: UA1200J15 | C23: WHT | D23: 20 | E23: 120 | F23: XT0805:11 | G23: A PNL
A24: UA1200:J2-1 | B24: UA1200J21 | C24: WHT | D24: 20 | E24: 120 | F24: XT0805:14 | G24: A PNL
A25: UA1200:J2-6 | B25: UA1200J26 | C25: WHT | D25: 20 | E25: 120 | F25: XT0805:12 | G25: A PNL
A26: UA1200:J2-7 | B26: UA1200J27 | C26: WHT | D26: 20 | E26: 120 | F26: XT0805:13 | G26: A PNL
A28: XT0800:40 | B28: -0V | C28: WHT | D28: 14 | E28: 180 | F28: XT1211:2 | G28: B PNL | H28: XT-B
A29: XT0800:39 | B29: FU0136 | C29: WHT | D29: 14 | E29: 180 | F29: XT1211:1 | G29: B PNL

Sheet B PNL_S
A1: B PANEL
A3: Project # | B3: 4M401
A4: Project Name | B4: FPSO GTG GENERATORS
A5: Revision | B5: C.2
A7: Controls DE | B7: J. SHORTER
A8: Phone: | B8: 0
A9: Controls ME
A10: Phone:
A12: From | G12: To
A13: Device ID | B13: Wire No. | C13: Wire ID | D13: Gauge/Size | E13: Length | F13: Device ID | G13: Location | H13: Bundle Name
A14: BA0001:V1(-) | B14: -0V | C14: WHT | D14: 16 | E14: 60 | F14: XT0001:2 | G14: B PNL | H14: BA
A15: BA0002:V1(-) | B15: -0V | C15: WHT | D15: 16 | E15: 60 | F15: XT0001:5 | G15: B PNL
A16: BA1100:NEG | B16: -0V | C16: WHT | D16: 16 | E16: 60 | F16: XT1211:2 | G16: B PNL
A17: BA1211:NEG | B17: -0V | C17: WHT | D17: 16 | E17: 60 | F17: XT1211:2 | G17: B PNL
A18: BA0001:V1(+) | B18: FU0001 | C18: WHT | D18: 16 | E18: 60 | F18: FU0001:LD | G18: B PNL
A19: BA0002:V1(+) | B19: FU0002 | C19: WHT | D19: 16 | E19: 60 | F19: FU0002:LD | G19: B PNL
A20: BA1100:POS | B20: FU1101LD | C20: WHT | D20: 16 | E20: 60 | F20: FU1101:LD | G20: B PNL
A21: BA1211:POS | B21: FU1211LD | C21: WHT | D21: 16 | E21: 60 | F21: FU1211:LD | G21: B PNL
A23: FU0001:LI | B23: FU0210 | C23: WHT | D23: 16 | E23: 60 | F23: XT0001:1 | G23: B PNL | H23: FU
A24: FU0002:LI | B24: FU0210 | C24: WHT | D24: 16 | E24: 60 | F24: XT0001:4 | G24: B PNL
A26: FU1101:LI | B26: FU0136 | C26: WHT | D26: 14 | E26: 60 | F26: XT1211:1 | G26: B PNL
A27: FU1211:LI | B27: FU0136 | C27: WHT | D27: 14 | E27: 60 | F27: XT1211:1 | G27: B PNL

Sheet Bundle Tag Info
A1: SHL-GMG NTB #2
A2: 4M401
A3: Rev C.2
A6: JB70 | B6: JB70 R/RAIL | C6: A PNL | D6: B PNL | E6: Panel Name | F6: Panel Name | G6: Panel Name | H6: Panel Name | I6: Panel Name | J6: Panel Name | K6: Panel Name | L6: Panel Name | M6: Panel Name | N6: Panel Name | O6: Panel Name | P6: Panel Name | Q6: Panel Name | R6: Panel Name | S6: Panel Name | T6: Panel Name | U6: Panel Name | V6: Panel Name | W6: Panel Name | X6: Panel Name | Y6: Panel Name | Z6: Panel Name | AA6: Panel Name | AB6: Panel Name | AC6: Panel Name | AD6: Panel Name
A7: AT1100 | B7: FU-A | C7: RR0175 | D7: BA
A8: HL0171 | C8: UA1200 | D8: FU
A9: HL0172 | C9: XT-B
A10: HL0173
A11: SA0170
A12: SB0170
A13: SB0471
A14: SB0473
A15: SB0474
A16: SB0472
A17: SH0470
A18: SH0471
A19: SH0472
A20: SA0471
A21: SA0472

Sheet Bundle Tags2
A1: =IF('Bundle Tag Info'!A6<>"Panel Name",'Bundle Tag Info'!A6,"") -> JB70 | B1: =IF('Bundle Tag Info'!B6<>"Panel Name",'Bundle Tag Info'!B6,"") -> JB70 R/RAIL | C1: =IF('Bundle Tag Info'!C6<>"Panel Name",'Bundle Tag Info'!C6,"") -> A PNL | D1: =IF('Bundle Tag Info'!D6<>"Panel Name",'Bundle Tag Info'!D6,"") -> B PNL | E1: =IF('Bundle Tag Info'!E6<>"Panel Name",'Bundle Tag Info'!E6,"") | F1: =IF('Bundle Tag Info'!F6<>"Panel Name",'Bundle Tag Info'!F6,"") | G1: =IF('Bundle Tag Info'!G6<>"Panel Name",'Bundle Tag Info'!G6,"") | H1: =IF('Bundle Tag Info'!H6<>"Panel Name",'Bundle Tag Info'!H6,"") | ... AD1: =IF('Bundle Tag Info'!AD6<>"Panel Name",'Bundle Tag Info'!AD6,"")
