Workbook

Sheet Blue Labels
A1: (SHT 1) CONSOLE | B1: (SHT 10) PANEL B | C1: (SHT 11) ISOLATOR PANEL | D1: (SHT 12) CC COMPRESSOR | E1: (SHT 13) CC BLANK #1 | F1: (SHT 14) CC BLANK #2 | G1: (SHT 15) CC BLANK #3 | H1: (SHT 16) FIRE SYSTEM CONTROLLER PANEL | I1: (SHT 17) TURBINE VIBRATION PANEL | J1: (SHT 18) JB70 | K1: (SHT 19) JB70 LEFT RAIL | L1: (SHT 2) CONSOLE | M1: (SHT 20) JB70 RIGHT RAIL | N1: (SHT 21) JB70 | O1: (SHT 22) JB73 | P1: (SHT 23) JB352 | Q1: (SHT 24) JB78 | R1: (SHT 25) MEDIA CONVERTER | S1: (SHT 26) JB4 PANEL | T1: (SHT 4) TCP | U1: (SHT 5) PWR DISTRIBUTION RAIL | V1: (SHT 6) FIRE SYSTEM | W1: (SHT 7) BOP PANEL | X1: (SHT 8) PLC PANEL | Y1: (SHT 9) PANEL A
A2: EL0271 | B2: XT0573 | C2: FU0274 | D2: AF0500 | E2: GR0673 | F2: GR0674 | G2: GR0014 | H2: UV0170 | I2: FU0110 | J2: HL0171 | K2: XTFGA | L2: AT0190K | M2: FU1100 | N2: BA0001 | O2: XT0841 | P2: UA4473 | Q2: XT0831 | R2: GR1123 | S2: UA1240 | T2: HL0411 | U2: AT0680 | V2: FU0170 | W2: IEG0257 | X2: XT0290 | Y2: FU0210
A3: EL0272 | B3: XT0235 | C3: FU0272 | D3: AF0510 | E3: GR0012 | F3: GR0013 | G3: GR0675 | H3: AT0170 | I3: FU0113 | J3: HL0172 | K3: GR1101 | L3: AT0190 | M3: XTFGB | N3: BA0002 | O3: XT0847 | P3: UA4461 | Q3: GR1321 | R3: BA0005 | S3: UA1241 | T3: HL0410 | U3: FU0680 | V3: KA6510 | W3: FU0140 | X3: XT0291 | Y3: FU0211
A4: EL0273 | B4: XT0136 | C4: UAI1520 | D4: AF0520 | E4: IEG0430 | H4: KA0172 | I4: XT0110 | J4: HL0173 | M4: GR1100 | N4: FU0001 | O4: XT0486 | P4: UA4460 | Q4: UA4740 | R4: BA0006 | S4: UA1250 | T4: HL0409 | U4: XT0680 | V4: KA6511 | W4: FU0141 | X4: FU0291 | Y4: FU0212
A5: HA0273 | B5: FU0060 | C5: UAI1214 | D5: XT0500 | E5: PEG0330 | H5: KA0174 | I5: GR0110 | J5: SB0471 | N5: GR1235 | O5: UA4750 | P5: UA4471 | Q5: UA4741 | R5: FU0005 | S5: UA1251 | T5: HL0408 | U5: FU0560 | V5: XT0170 | W5: FU0142 | X5: FU0290 | Y5: FU0010
A6: ZS0273 | B6: FU0061 | C6: UAI4460 | D6: AF0900 | H6: GR0171 | I6: IEG0110 | J6: SB0473 | N6: FU0002 | O6: UA4751 | P6: UA4470 | Q6: UA4753 | R6: FU0006 | S6: UA1272 | T6: HL0407 | U6: XT0560 | V6: XT0172 | W6: FU0143 | X6: XT0232 | Y6: FU0139
A7: ZS0271 | B7: FU0062 | C7: UAI4461 | D7: AF0910 | I7: AF0400 | J7: SB0474 | N7: XT0001 | O7: UA4759 | P7: UA4462 | Q7: UA4752 | R7: XT0003 | S7: UA1273 | T7: SB0400 | U7: XT0561 | V7: GR0170 | W7: AU0140 | X7: XT0002 | Y7: FU0072
A8: FG0001 | B8: FU0063 | C8: UAI4462 | D8: AF0920 | I8: AF0410 | J8: SA0170 | N8: XT0815 | O8: UA4770 | P8: GR4460 | Q8: UA4760 | R8: GR1125 | S8: GR1250 | T8: HL0406 | U8: FU0200 | V8: AT0175 | W8: AF0141 | X8: XT0005 | Y8: FU0090
A9: FG0000 | B9: FU0064 | C9: UAI0800 | D9: AF0940 | I9: AF0420 | J9: SB0170 | N9: XT1211 | O9: UA4771 | Q9: UA4761 | R9: IEG1123 | T9: HL0405 | U9: FU0201 | V9: AT0177 | W9: AF0142 | X9: FU0003 | Y9: FU0091
B10: XT0060 | C10: UAI0836 | D10: AF1211 | I10: AF0430 | J10: SH0470 | N10: FU1211 | O10: XT0830 | Q10: UA4773 | T10: HL0404 | U10: FU0190 | V10: AT0179 | W10: AF0143 | X10: FU0004 | Y10: FU0092
B11: KA3502 | C11: UAI0846 | D11: AF1210 | I11: AF0450 | J11: SH0471 | N11: BA1211 | O11: GR4121 | Q11: XTFGD | T11: HL0403 | U11: FU0273 | V11: AT0181 | W11: AF0144 | X11: FU0020 | Y11: FU0093
B12: XT0571 | C12: UAI0890 | D12: AF1209 | I12: XT0400 | J12: SH0472 | N12: BA1100 | O12: XTFGC | Q12: GR1322 | T12: HL0402 | U12: XT0562 | V12: GR0172 | W12: AF0145 | X12: FU0101 | Y12: FU9130
B13: KA1020 | C13: UAI1100 | D13: AF1208 | J13: AT1100 | N13: FU1101 | O13: XT0840 | T13: HL0401 | W13: AF0146 | X13: EDW100 | Y13: XT0233
B14: AF0068 | C14: UAI1110 | D14: AF1207 | J14: HA0472 | N14: GR1232 | O14: GR4123 | T14: HL0400 | W14: GR0180 | X14: GR0290 | Y14: KA0135
B15: AF0067 | C15: UAI1111 | D15: AF1206 | J15: SA0471 | N15: XT0810 | O15: XT0844 | T15: SH0407 | W15: FU0570 | X15: UV0600 | Y15: KA0140
B16: AF0066 | C16: UAI1112 | D16: AF1205 | J16: SA0474 | N16: XT0811 | O16: XT0845 | T16: SH0406 | W16: XT0570 | X16: AT0600 | Y16: KA1306
B17: AF0065 | C17: UAI4470 | D17: AF1204 | J17: SB0472 | N17: XT1212 | O17: XT0843 | T17: SH0405 | W17: XT0140 | X17: AP0602 | Y17: KA3103
B18: AF0064 | C18: UAI4471 | D18: AF1203 | N18: XT0821 | O18: XT0842 | T18: SH0404 | W18: XT0180 | X18: AP0603 | Y18: KA6211
B19: AF0063 | C19: UAI4473 | D19: AF1202 | N19: XT0822 | O19: GR4124 | T19: SH0410 | W19: KA0535 | X19: AP0609 | Y19: KA6212
B20: AF0062 | C20: UAI4434 | D20: AF1201 | N20: XT0825 | T20: SH0409 | W20: KA0536 | X20: AP0291 | Y20: KA6241
B21: AF0061 | C21: UAI4437 | D21: AU1200 | N21: XT0824 | T21: SH0401 | W21: KA0531 | X21: AR0600 | Y21: KA3500
B22: AU0060 | C22: UAI4438 | D22: AF0322 | N22: GR1233 | T22: SH0400 | W22: KA0532 | X22: AP0601 | Y22: GR0133
B23: XT0081 | C23: UAI1170 | D23: AF0321 | N23: IEG1200 | T23: SB0408 | W23: KA0533 | X23: AP0604 | Y23: FU0032
B24: XT0135 | C24: UAI1260 | D24: AU0320 | N24: XT0805 | T24: SB0407 | W24: KA0534 | X24: AP0605 | Y24: XT0032
B25: XT0139 | C25: UAI1265 | D25: GR0120 | N25: XT0807 | T25: SH0408 | W25: KA0537 | X25: AP0606 | Y25: XT0085
B26: KA2160 | C26: UAI1270 | D26: KA0120 | N26: XT0808 | T26: SB0405 | W26: KA0540 | X26: AP0607 | Y26: XT0080
B27: KA2161 | C27: UAI2120 | D27: KA4401 | N27: XT0809 | T27: SB0406 | W27: KA0541 | X27: AP0608 | Y27: FU0080
B28: KA9130 | C28: UAI3100 | D28: FU0133 | N28: RR0175A | T28: SA0401 | W28: KA0550 | X28: AP0290 | Y28: FU0031
B29: GR0231 | C29: UAI3200 | D29: FU0310 | N29: RR0175I | T29: SB0404 | W29: KA0551 | X29: BA0003 | Y29: FU0136
B30: FU0070 | C30: UAI3510 | D30: FU0313 | N30: RR0175D | T30: SB0403 | W30: KA0554 | X30: BA0004 | Y30: FU0137
B31: FU0071 | C31: UAI3520 | D31: FU0320 | N31: RR0175M | T31: SB0402 | W31: KA0181 | X31: BA0011 | Y31: FU2108
... B35: AF0072 | C35: UAI4413 | D35: XT0905 | N35: VD0175D | T35: XT0563 | W35: KA0542 | X35: GR0234 | Y35: GR0134
B36: AF0073 | C36: UAI4414 | D36: XT0900 | N36: UA1210 | T36: AU0200 | W36: KA0543 | Y36: UJ0131
B37: AF0074 | C37: UAI4417 | D37: XT0310 | N37: UA1211 | T37: AF0201 | W37: KA1801 | Y37: UJ0031
B38: AF0075 | C38: UAI4418 | D38: XT0121 | N38: UA1220 | T38: AF0202 | W38: KA1901 | Y38: AF0088
B39: AF0076 | C39: UAI4433 | D39: XT0520 | N39: UA1221 | T39: XT0201 | W39: XT0574 | Y39: AF0087
B40: AF0077 | C40: UV0274 | D40: XT0130 | N40: UA1230 | T40: GR0200 | W40: XT0141 | Y40: AF0086
B41: XT0237 | C41: UV0275 | D41: GR0320 | N41: UA1231 | W41: KT0571 | Y41: AF0085
B42: KA2163 | C42: UAI1771 | D42: IEG0250 | N42: UA1262 | W42: KT0573 | Y42: AF0084
B43: KA0224 | C43: UAI4740 | N43: UA1263 | W43: KT0574 | Y43: AF0083
...

Sheet White Labels
A1: (SHT 7) BOP PANEL | B1: (SHT 7) BOP PANEL - (SHT 10) PANEL B | C1: (SHT 13) CC BLANK #1 | D1: (SHT 13) CC BLANK #1 - (SHT 9) PANEL A | E1: (SHT 13) CC BLANK #1 - (SHT 10) PANEL B | F1: (SHT 14) CC BLANK #2 | G1: (SHT 15) CC BLANK #3 | H1: (SHT 12) CC COMPRESSOR | I1: (SHT 12) CC COMPRESSOR - (SHT 11) ISOLATOR PANEL | J1: (SHT 12) CC COMPRESSOR - (SHT 10) PANEL B | K1: (SHT 11) ISOLATOR PANEL - (SHT 9) PANEL A | L1: (SHT 18) JB70 | M1: (SHT 21) JB70 | N1: (SHT 25) MEDIA CONVERTER | O1: (SHT 9) PANEL A | P1: (SHT 9) PANEL A - (SHT 10) PANEL B | Q1: (SHT 9) PANEL A - (SHT 8) PLC PANEL | R1: (SHT 9) PANEL A - (SHT 4) TCP | S1: (SHT 10) PANEL B | T1: (SHT 10) PANEL B - (SHT 17) TURBINE VIBRATION PANEL | U1: (SHT 8) PLC PANEL | V1: (SHT 5) PWR DISTRIBUTION RAIL - (SHT 4) TCP | W1: (SHT 4) TCP | X1: (SHT 17) TURBINE VIBRATION PANEL
A2: AF0143G | B2: IEG02575 | C2: GR0012 | D2: PEG0330G | E2: IEG0430G | F2: GR0013 | G2: GR0014 | H2: AF1203G | I2: IEG02507 | J2: IEG0250G | K2: IEG023014 | L2: AT1100G | M2: GR1232 | N2: GR1125 | O2: AF0083G | P2: IEG02304 | Q2: AP0290SH-OUT | R2: IEG02308 | S2: AF0064G | T2: IEG0110G | U2: UV0600G | V2: 0V1 | W2: AU0200G | X2: IEG01101
A3: AF0144G | B3: IEG02576 | C3: GR0673 | F3: GR0674 | G3: GR0675 | H3: AF1204G | I3: IEG02508 | K3: IEG02306 | M3: IEG12001 | N3: IEG11231 | O3: AF0084G | P3: IEG02305 | Q3: AP0291SH-OUT | S3: AF0065G | V3: FU0200 | X3: XT04001
A4: AU0140G | B4: IEG0257G | H4: AF1205G | K4: IEG02307 | M4: IEG12004 | O4: AF0085G | P4: IEG0230G | Q4: IEG02301 | S4: AF0066G | V4: FU0201 | X4: XT04002
A5: AU0180G | H5: AF1206G | O5: AF0086G | P5: KA9130A2 | Q5: IEG023012 | S5: AF0071G
A6: GR0181 | H6: AF1208G | O6: AF0094G | S6: AF0072G
A7: IEG02571 | H7: AF1209G | O7: AF0096G | S7: AF0073G
A8: IEG02572 | H8: AF1210G | O8: AF0097G | S8: AF0074G
A9: IEG02573 | H9: AU0320G | O9: AU0080G | S9: AF0075G
A10: IEG02574 | H10: AU1200G | O10: AU0090G | S10: AU0060G
H11: IEG02501 | O11: IEG023011 | S11: AU0070G
H12: IEG02502 | O12: IEG023013
H13: IEG02503 | O13: IEG02302
H14: IEG02504 | O14: IEG02303
H15: IEG02505
H16: IEG02506
H17: XT05001
H18: XT09001
H19: XT09002

Sheet Heat Shrink Labels
A1: (SHT 7) BOP PANEL - (SHT 8) PLC PANEL | B1: (SHT 12) CC COMPRESSOR - (SHT 11) ISOLATOR PANEL | C1: (SHT 12) CC COMPRESSOR - (SHT 8) PLC PANEL | D1: (SHT 6) FIRE SYSTEM | E1: (SHT 6) FIRE SYSTEM - (SHT 16) FIRE SYSTEM CONTROLLER PANEL | F1: (SHT 11) ISOLATOR PANEL - (SHT 9) PANEL A | G1: (SHT 11) ISOLATOR PANEL - (SHT 10) PANEL B | H1: (SHT 11) ISOLATOR PANEL - (SHT 17) TURBINE VIBRATION PANEL | I1: (SHT 18) JB70 | J1: (SHT 9) PANEL A - (SHT 8) PLC PANEL | K1: (SHT 10) PANEL B - (SHT 8) PLC PANEL | L1: (SHT 8) PLC PANEL
A2: WC029118 | B2: WC1307 | C2: W029126 | D2: WC5500 | E2: WC5018 | F2: W2130 | G2: WC2100 | H2: WC1203 | I2: WC4524 | J2: WC029003 | K2: WC029001 | L2: WTXRX1
A3: WC029119 | B3: WC1308 | C3: WC029101 | D3: WC8066 | E3: WC8069 | F3: WC2110 | G3: WC2101 | H3: WC1327 | J3: WC029004 | K3: WC029002 | L3: WTXRX2
A4: WC6100 | B4: WC1310 | C4: WC029102 | D4: WC8068 | F4: WC2126 | G4: WC2102 | H4: WC1328 | J4: WC029005 | K4: WC029009
A5: WC7100 | B5: WC1311 | C5: WC029103 | D5: WC8085 | F5: WC2127 | G5: WC2103 | H5: WC1329 | J5: WC029006 | K5: WC029014
A6: WC7101 | B6: WC1312 | C6: WC029104 | F6: WC2128 | G6: WC2104 | H6: WC1330 | J6: WC029007 | K6: WC029015
B7: WC1313 | C7: WC029105 | F7: WC2153 | G7: WC2105 | H7: WC1331 | J7: WC029008 | K7: WC029016
B8: WC1314 | C8: WC029106 | F8: WC2154 | G8: WC2129 | H8: WC1332 | J8: WC029010 | K8: WC029017
B9: WC1318 | C9: WC029107 | F9: WC2155 | G9: WC2201 | H9: WC1333 | J9: WC029011 | K9: WC029018
B10: WC1319 | C10: WC029108 | F10: WC2156 | G10: WC2202 | H10: WC1334 | J10: WC029012 | K10: WC029019
B11: WC1320 | C11: WC029109 | F11: WC2157 | G11: WC2203 | H11: WC1335 | J11: WC029013 | K11: WC029020
B12: WC1321 | C12: WC029110 | F12: WC2161 | G12: WC2204 | H12: WC1336 | J12: WC029023 | K12: WC029021
B13: WC1322 | C13: WC029111 | F13: WC2162 | G13: WC2205 | H13: WC1337 | J13: WC029024 | K13: WC029022
B14: WC1323 | C14: WC029112 | F14: WC2180 | G14: WC2301 | H14: WC1338 | J14: WC029026 | K14: WC029025
B15: WC1352 | C15: WC029113 | F15: WC2181 | G15: WC2302 | H15: WC1339 | J15: WC029027 | K15: WC029030
B16: WC1353 | C16: WC029114 | F16: WC2182 | G16: WC2303 | H16: WC1340 | J16: WC029028
B17: WC1354 | C17: WC029120 | F17: WC2206 | G17: WC2304 | H17: WC1341 | J17: WC029029
B18: WC1355 | C18: WC029121 | F18: WC2207 | G18: WC2305 | H18: WC4749 | J18: WC029115
B19: WC1356 | C19: WC029122 | F19: WC2306 | G19: WC2401 | J19: WC029116
B20: WC1357 | C20: WC029127 | F20: WC2406 | G20: WC2402 | J20: WC029117
B21: WC2139 | C21: WC2123 | G21: WC2403
B22: WC2140 | C22: WC4293 | G22: WC2404
B23: WC2141 | G23: WC2405
B24: WC2142
B25: WC2143
B26: WC2144
B27: WC2145
B28: WC2308
B29: WC2603
B30: WC2604
B31: WC2605
B32: WC2607
B33: WC2614
B34: WC2615
B35: WC2700
... B37: WC4638

Sheet Panel Errors
A1: Panel Errors
A3: Project # | B3: 4M511
A4: Project Name | B4: ENI - KUTEI NORTH HUB - FPSO
A5: Revision | B5: B
A7: Controls DE | B7: BARRAZA, PAUL
A8: Phone: | B8: 0
A9: Controls ME
A10: Phone:
A12: From | H12: To
A13: Device ID | B13: Location | C13: Cable (W) Conductor (SC) Jumper Clip (JC) | D13: Wire ID | E13: Wire No. | F13: Gauge/Size | G13: Page/Zone | H13: Device ID | I13: Location | J13: Page/Zone
A14: GR1321: | B14: PANEL | C14: SC | D14: GRN/YEL | E14: GR1321 | F14: 14 | G14: 91.D5 | H14: FRAME | I14: PANEL | J14: 91.D6
A15: GR1322: | B15: PANEL | C15: SC | D15: GRN/YEL | E15: GR1322 | F15: 14 | G15: 91.D6 | H15: FRAME | I15: PANEL | J15: 91.D6
E17: SolarTools ver. 24.0.84.24712 (Jul 31, 2025)
A18: Report date: 3/23/2026 6:08 PM

Sheet Cable Part Numbers
A1: Cable Part Numbers | D1: SolarTools ver. 24.0.84.24712 (Jul 31, 2025)
A2: Project # | B2: 4M511
D3: Report date: 3/23/2026 6:09 PM
A4: Project Name | B4: ENI - KUTEI NORTH HUB - FPSO
A6: Revision | B6: B
A8: Controls DE | B8: BARRAZA, PAUL
A9: Phone: | B9: 0
A10: Controls ME
A11: Phone:
A13: Device ID | C13: Part Number | E13: Description
A14: WC4524 | C14: 1022941-12 | E14: TPE, 1 PAIR TWISTED SHIELDED
A15: WC5072 | C15: PART OF 1103208-100 | E15: CABLE, 2 CONDUCTOR UNSHIELDED PART OF HORN
A17: W029126 | C17: 1022941-12 | E17: TPE, 1 PAIR TWISTED SHIELDED
A18: W2130 | C18: 1022941-13 | E18: TPE, 1 TRIAD TWISTED SHIELDED
A19: WC0001 | C19: 1302073-36 | E19: CABLE, ETHERNET - 36 INCHES
A20: WC0003 | C20: 1302073-36 | E20: CABLE, ETHERNET - 36 INCHES
A21: WC0007 | C21: 1302073-36 | E21: CABLE, ETHERNET - 36 INCHES
A22: WC0008 | C22: 1302073-36 | E22: CABLE, ETHERNET - 36 INCHES
A23: WC0009 | C23: 1302073-36 | E23: CABLE, ETHERNET - 36 INCHES
A24: WC0010 | C24: 1302073-36 | E24: CABLE, ETHERNET - 36 INCHES
A25: WC0012 | C25: 1302073-36 | E25: CABLE, COMMUNICATION CABLE - 36 INCHES
... A217: WTXRX2 | C217: 1022941-12 | E217: TPE, 1 PAIR TWISTED SHIELDED

Sheet Part Number List
A1: Part Number List | C1: SolarTools ver. 24.0.84.24712 (Jul 31, 2025)
A2: Project # | B2: 4M511
C3: Report date: 3/23/2026 6:09 PM
A4: Project Name | B4: ENI - KUTEI NORTH HUB - FPSO
A6: Revision | B6: B
A8: Controls DE | B8: BARRAZA, PAUL
A9: Phone: | B9: 0
A10: Controls ME
A11: Phone:
A13: Device ID | B13: Part Number | C13: Description | D13: Location
A14: AF0141 | B14: 2684693-17,2684693-25 | C14: 5094-OB8XT, 8 DISCRETE OUTPUT | D14: BOP PANEL
A15: AF0142 | B15: 2684693-17,2684693-23 | C15: 5094-IB16XT, 16 DISCRETE INPUT | D15: BOP PANEL
A16: AF0143 | B16: 2684693-18,2684693-56 | C16: 5094-IF8IHXT, 8 ANALOG INPUT, ISOLATED | D16: BOP PANEL
A17: AF0144 | B17: 2684693-18,2684693-27 | C17: 5094-OF8IHXT, 8 ANALOG OUTPUT, ISOLATED | D17: BOP PANEL
A18: AF0145 | B18: 2684693-19,2684693-33 | C18: 5094-IY8XT, 8 ANALOG INPUT, TC/RTD/ I&V | D18: BOP PANEL
A19: AF0146 | B19: 2684693-17,2684693-25 | C19: 5094-OB8XT, 8 DISCRETE OUTPUT | D19: BOP PANEL
A20: AF0181 | B20: 2684693-17,2684693-25 | C20: 5094-OB8XT, 8 DISCRETE OUTPUT | D20: BOP PANEL
A21: AF0182 | B21: 2684693-17,2684693-23 | C21: 5094-IB16XT, 16 DISCRETE INPUT | D21: BOP PANEL
A22: AF0183 | B22: 2684693-18,2684693-28 | C22: 5094-IB16SXT, 16 DISCRETE INPUT, S | D22: BOP PANEL
A23: AF0184 | B23: 2684693-18,2684693-55 | C23: 5094-OB16SXT, 16 DISCRETE OUTPUT, S | D23: BOP PANEL
A24: AF0185 | B24: 2684693-18,2684693-56 | C24: 5094-IF8IHXT, 8 ANALOG INPUT, ISOLATED | D24: BOP PANEL
... A332: XT0821 | B332: 1066730-50,1066730-51,1067996-82 | C332: TERMINAL STRIP, 4 CONDUCTOR | D332: JB70
A333: XT0822 | B333: 1066730-50,1066730-51,1067996-82 | D333: JB70
A334: XT0822 | B334: 1066730-50,1066730-51,1067996-82 | D334: JB70
A335: XT0822 | B335: 1066730-50,1066730-51,1067996-82 | C335: TERMINAL STRIP, 4 CONDUCTOR | D335: JB70
A336: XT0822 | B336: 1066730-50,1066730-51,1067996-82 | C336: TERMINAL STRIP, 4 CONDUCTOR | D336: JB70
A337: XT0824 | B337: 1066730-50,1066730-51,1067996-11 | C337: TERMINAL STRIP, 4 CONDUCTOR | D337: JB70
A338: XT0825 | B338: 1066730-50,1066730-51,1067996-82 | C338: TERMINAL STRIP, 4 CONDUCTOR | D338: JB70
A339: XT1211 | B339: 1066730-7,1066730-8,1067996-4 | C339: TERMINAL BLOCK, SPRING, 4 CONDUCTOR,30-12 AWG (0.05-3.31 MM2),NON-IS | D339: JB70
A340: XT1212 | B340: 1066730-50,1066730-51,1067996-82 | C340: TERMINAL STRIP, 4 CONDUCTOR | D340: JB70
A341: XT1213 | B341: 1066730-7,1066730-8,1067996-82 | C341: TERMINAL BLOCK, SPRING, 4 CONDUCTOR,30-12 AWG (0.05-3.31 MM2),NON-IS | D341: JB70
A342: XT1521 | B342: 1066730-50,1066730-51,1067996-4 | C342: TERMINAL STRIP, 4 CONDUCTOR | D342: JB70
A343: XTFG1520 | B343: FRAME_GROUND | C343: GROUND, FRAME/CHASSIS GROUNDING | D343: JB70
A345: GR1101 | B345: [2]903849C1 | C345: RAIL GROUND, DIN RAIL GROUNDING | D345: JB70 LEFT RAIL
A347: FU1100 | B347: 1043265-1,1043265-5 | C347: FUSE, 10A | D347: JB70 RIGHT RAIL
A348: GR1100 | B348: 903849C1 | C348: RAIL GROUND, DIN RAIL GROUNDING | D348: JB70 RIGHT RAIL
... A668: XT0400 | B668: [2]1066730-1,[2]1066730-2,1066730-67,1066730-7,1066730-8,1067996-4 | C668: TERMINAL STRIP, 4 CONDUCTOR | D668: TURBINE VIBRATION PANEL

Sheet JB70_S
A1: JB70
A3: Project # | B3: 4M511
A4: Project Name | B4: ENI - KUTEI NORTH HUB - FPSO
A5: Revision | B5: B
A7: Controls DE | B7: BARRAZA, PAUL
A8: Phone: | B8: 0
A9: Controls ME
A10: Phone:
A12: From | G12: To
A13: Device ID | B13: Wire No. | C13: Wire ID | D13: Gauge/Size | E13: Length | F13: Device ID | G13: Location | H13: Bundle Name
A14: AT1100:NEG | B14: -0V | C14: WHT | D14: 14 | E14: 220 | F14: XT0800:40 | G14: A PANEL | H14: AT1100
A15: AT1100:POS | B15: FU1100 | C15: WHT | D15: 14 | E15: 160 | F15: FU1100:LD | G15: JB70 RIGHT RAIL
A17: HL0171:X1 | B17: HL0171X1 | C17: WHT | D17: 20 | E17: 220 | F17: RR0175A: -10K OHM | G17: A PANEL | H17: HL0171
A18: HL0171:X2 | B18: HL0171X2 | C18: WHT | D18: 20 | E18: 220 | F18: VD0175A:--1N4005/1 | G18: A PANEL
A20: HL0172:X1 | B20: HL0172X1 | C20: WHT | D20: 20 | E20: 220 | F20: RR0175I: -10K OHM | G20: A PANEL | H20: HL0172
A21: HL0172:X2 | B21: HL0172X2 | C21: WHT | D21: 20 | E21: 220 | F21: VD0175I:--1N4005/1 | G21: A PANEL
A23: HL0173:X1 | B23: HL0173X1 | C23: WHT | D23: 20 | E23: 220 | F23: RR0175D: -10K OHM | G23: A PANEL | H23: HL0173
A24: HL0173:X2 | B24: HL0173X2 | C24: WHT | D24: 20 | E24: 220 | F24: VD0175D:--1N4005/1 | G24: A PANEL
A26: SB0170:13 | B26: SB017013 | C26: WHT | D26: 20 | E26: 220 | F26: RR0175M: -10K OHM | G26: A PANEL | H26: SB0170
A27: SB0170:14 | B27: SB017014 | C27: WHT | D27: 20 | E27: 220 | F27: RR0175M: -10K OHM | G27: A PANEL
A29: SA0170:B2-13 | B29: AT01754P1 | C29: WHT | D29: 20 | E29: 220 | F29: XT0811:19 | G29: A PANEL | H29: SA0170
A30: SA0170:B1-13 | B30: SA0170B113 | C30: WHT | D30: 20 | E30: 220 | F30: XT0811:3 | G30: A PANEL
A31: SA0170:B1-14 | B31: SA0170B114 | C31: WHT | D31: 20 | E31: 220 | F31: XT0811:4 | G31: A PANEL
A32: SA0170:B2-14 | B32: SA0170B214 | C32: WHT | D32: 20 | E32: 220 | F32: XT0811:20 | G32: A PANEL
A34: SA0471:B1-13 | B34: SA0471B113 | C34: WHT | D34: 20 | E34: 220 | F34: XT0800:29 | G34: A PANEL | H34: SA0471
A35: SA0471:B1-14 | B35: SA0471B114 | C35: WHT | D35: 20 | E35: 220 | F35: XT0800:30 | G35: A PANEL
A36: SA0471:B2-13 | B36: SA0471B213 | C36: WHT | D36: 20 | E36: 220 | F36: XT0800:27 | G36: A PANEL
A37: SA0471:B2-14 | B37: SA0471B214 | C37: WHT | D37: 20 | E37: 220 | F37: XT0800:28 | G37: A PANEL
A39: SA0474:B2-13 | B39: SA0474B113 | C39: WHT | D39: 20 | E39: 220 | F39: XT0800:35 | G39: A PANEL | H39: SA0474
A40: SA0474:B2-14 | B40: SA0474B114 | C40: WHT | D40: 20 | E40: 220 | F40: XT0800:36 | G40: A PANEL
A41: SA0474:B1-13 | B41: SA0474B213 | C41: WHT | D41: 20 | E41: 220 | F41: XT0800:37 | G41: A PANEL
A42: SA0474:B1-14 | B42: SA0474B214 | C42: WHT | D42: 20 | E42: 220 | F42: XT0800:38 | G42: A PANEL
A44: SB0471:11 | B44: SB047111 | C44: WHT | D44: 20 | E44: 220 | F44: XT0800:21 | G44: A PANEL | H44: SB0471
A45: SB0471:12 | B45: SB047112 | C45: WHT | D45: 20 | E45: 220 | F45: XT0800:22 | G45: A PANEL
A47: SB0472:B1-12 | B47: ESTOP | C47: WHT | D47: 20 | E47: 220 | F47: XT0800:32 | G47: A PANEL | H47: SB0472
A48: SB0472:B1-11 | B48: ESTOPA | C48: WHT | D48: 20 | E48: 220 | F48: XT0800:31 | G48: A PANEL
A49: SB0472:B2-11 | B49: SB0472B11 | C49: WHT | D49: 20 | E49: 220 | F49: XT0800:33 | G49: A PANEL
A50: SB0472:B2-12 | B50: SB0472B12 | C50: WHT | D50: 20 | E50: 220 | F50: XT0800:34 | G50: A PANEL
A52: SB0473:13 | B52: SB047313 | C52: WHT | D52: 20 | E52: 220 | F52: XT0800:23 | G52: A PANEL | H52: SB0473
A53: SB0473:14 | B53: SB047314 | C53: WHT | D53: 20 | E53: 220 | F53: XT0800:24 | G53: A PANEL
...

Sheet JB70 RIGHT RAIL_S
A1: JB70 RIGHT RAIL
A2: JB70 (RIGHT RAIL)
A3: Project # | B3: 4M511
A4: Project Name | B4: ENI - KUTEI NORTH HUB - FPSO
A5: Revision | B5: B
A7: Controls DE | B7: BARRAZA, PAUL
A8: Phone: | B8: 0
A9: Controls ME
A10: Phone:
A12: From | G12: To
A13: Device ID | B13: Wire No. | C13: Wire ID | D13: Gauge/Size | E13: Length | F13: Device ID | G13: Location | H13: Bundle Name
A14: FU1100:LI | B14: FU0136 | C14: WHT | D14: 14 | E14: 180 | F14: XT0800:39 | G14: A PNL | H14: FU-A

Sheet A PANEL_S
A1: A PANEL JB70
A3: Project # | B3: 4M511
A4: Project Name | B4: ENI - KUTEI NORTH HUB - FPSO
A5: Revision | B5: B
A7: Controls DE | B7: BARRAZA, PAUL
A8: Phone: | B8: 0
A9: Controls ME
A10: Phone:
A12: From | G12: To
A13: Device ID | B13: Wire No. | C13: Wire ID | D13: Gauge/Size | E13: Length | F13: Device ID | G13: Location | H13: Bundle Name
A14: RR0175A: -10K OHM | B14: VD0175A | C14: WHT | D14: 20 | E14: 60 | F14: VD0175A:+-1N4005/1 | G14: A PNL | H14: RR
A15: RR0175D: -10K OHM | B15: VD0175D | C15: WHT | D15: 20 | E15: 60 | F15: VD0175D:+-1N4005/1 | G15: A PNL
A16: RR0175I: -10K OHM | B16: VD0175I | C16: WHT | D16: 20 | E16: 60 | F16: VD0175I:+-1N4005/1 | G16: A PNL
A18: UA1200:J1-9 | B18: -0V | C18: WHT | D18: 20 | E18: 100 | F18: XT0805:17 | G18: A PNL | H18: UA1200
A19: UA1200:J1-10 | B19: FU0212 | C19: WHT | D19: 20 | E19: 100 | F19: XT0805:16 | G19: A PNL
A20: UA1200:J2-2 | B20: FU0212 | C20: WHT | D20: 20 | E20: 100 | F20: XT0805:15 | G20: A PNL
A21: UA1200:J1-8 | B21: UA1200J | C21: WHT | D21: 20 | E21: 60 | F21: UA1200:J3-5 | G21: A PNL
A22: UA1200:J1-4 | B22: UA1200J14 | C22: WHT | D22: 20 | E22: 100 | F22: XT0805:10 | G22: A PNL
A23: UA1200:J1-5 | B23: UA1200J15 | C23: WHT | D23: 20 | E23: 100 | F23: XT0805:11 | G23: A PNL
A24: UA1200:J2-1 | B24: UA1200J21 | C24: WHT | D24: 20 | E24: 100 | F24: XT0805:14 | G24: A PNL
A25: UA1200:J2-6 | B25: UA1200J26 | C25: WHT | D25: 20 | E25: 100 | F25: XT0805:12 | G25: A PNL
A26: UA1200:J2-7 | B26: UA1200J27 | C26: WHT | D26: 20 | E26: 100 | F26: XT0805:13 | G26: A PNL
A28: XT0800:40 | B28: -0V | C28: WHT | D28: 14 | E28: 160 | F28: XT1211:2 | G28: B PNL | H28: XT-B
A29: XT0800:39 | B29: FU0136 | C29: WHT | D29: 14 | E29: 160 | F29: XT1211:1 | G29: B PNL

Sheet B PANEL_S
A1: B PANEL JB70
A3: Project # | B3: 4M511
A4: Project Name | B4: ENI - KUTEI NORTH HUB - FPSO
A5: Revision | B5: B
A7: Controls DE | B7: BARRAZA, PAUL
A8: Phone: | B8: 0
A9: Controls ME
A10: Phone:
A12: From | G12: To
A13: Device ID | B13: Wire No. | C13: Wire ID | D13: Gauge/Size | E13: Length | F13: Device ID | G13: Location | H13: Bundle Name
A14: BA0001:V1(-) | B14: -0V | C14: WHT | D14: 16 | E14: 60 | F14: XT0001:2 | G14: B PANEL | H14: BA
A15: BA0002:V1(-) | B15: -0V | C15: WHT | D15: 16 | E15: 60 | F15: XT0001:5 | G15: B PANEL
A16: BA1100:NEG | B16: -0V | C16: WHT | D16: 16 | E16: 60 | F16: XT1211:2 | G16: B PANEL
A17: BA1211:NEG | B17: -0V | C17: WHT | D17: 16 | E17: 60 | F17: XT1211:2 | G17: B PANEL
A18: BA0001:V1(+) | B18: FU0001 | C18: WHT | D18: 16 | E18: 60 | F18: FU0001:LD | G18: B PANEL
A19: BA0002:V1(+) | B19: FU0002 | C19: WHT | D19: 16 | E19: 60 | F19: FU0002:LD | G19: B PANEL
A20: BA1100:POS | B20: FU1101LD | C20: WHT | D20: 16 | E20: 60 | F20: FU1101:LD | G20: B PANEL
A21: BA1211:POS | B21: FU1211LD | C21: WHT | D21: 16 | E21: 60 | F21: FU1211:LD | G21: B PANEL
A23: FU0001:LI | B23: FU0210 | C23: WHT | D23: 16 | E23: 60 | F23: XT0001:1 | G23: B PANEL | H23: FU
A24: FU0002:LI | B24: FU0210 | C24: WHT | D24: 16 | E24: 60 | F24: XT0001:4 | G24: B PANEL
A26: FU1101:LI | B26: FU0136 | C26: WHT | D26: 14 | E26: 60 | F26: XT1211:1 | G26: B PANEL
A27: FU1211:LI | B27: FU0136 | C27: WHT | D27: 14 | E27: 60 | F27: XT1211:1 | G27: B PANEL

Sheet MEDIA CONV._S
A1: MEDIA CONVERTER
A3: Project # | B3: 4M511
A4: Project Name | B4: ENI - KUTEI NORTH HUB - FPSO
A5: Revision | B5: B
A7: Controls DE | B7: BARRAZA, PAUL
A8: Phone: | B8: 0
A9: Controls ME
A10: Phone:
A12: From | G12: To
A13: Device ID | B13: Wire No. | C13: Wire ID | D13: Gauge/Size | E13: Length | F13: Device ID | G13: Location | H13: Bundle Name
A14: BA0005:V1(-) | B14: -0V | C14: WHT | D14: 16 | E14: 60 | F14: XT0003:2 | G14: MEDIA CONV | H14: BA/FU
A15: BA0006:V1(-) | B15: -0V | C15: WHT | D15: 16 | E15: 60 | F15: XT0003:4 | G15: MEDIA CONV
A16: BA0005:V1(+) | B16: FU0005 | C16: WHT | D16: 16 | E16: 60 | F16: FU0005:LD | G16: MEDIA CONV
A17: BA0006:V1(+) | B17: FU0006 | C17: WHT | D17: 16 | E17: 60 | F17: FU0006:LD | G17: MEDIA CONV
A19: FU0005:LI | B19: FU0210 | C19: WHT | D19: 16 | E19: 60 | F19: XT0003:1 | G19: MEDIA CONV
A20: FU0006:LI | B20: FU0210 | C20: WHT | D20: 16 | E20: 60 | F20: XT0003:3 | G20: MEDIA CONV

Sheet Bundle Tag Info
A1: ENI-K #2
A2: 4M511
A3: REV B
A6: JB70 | B6: JB70 R/RAIL | C6: JB70 A | D6: JB70 B | E6: MED CONV | F6: Panel Name | G6: Panel Name | H6: Panel Name | I6: Panel Name | J6: Panel Name | K6: Panel Name | L6: Panel Name | M6: Panel Name | N6: Panel Name | O6: Panel Name | P6: Panel Name | Q6: Panel Name | R6: Panel Name | S6: Panel Name | T6: Panel Name | U6: Panel Name | V6: Panel Name | W6: Panel Name | X6: Panel Name | Y6: Panel Name | Z6: Panel Name | AA6: Panel Name | AB6: Panel Name | AC6: Panel Name | AD6: Panel Name
A7: AT1100 | B7: FU-A | C7: RR | D7: BA | E7: BA/FU
A8: HL0171 | C8: UA1200 | D8: FU
A9: HL0172 | C9: XT-B
A10: HL0173
A11: SB0170
A12: SA0170
A13: SA0471
A14: SA0474
A15: SB0471
A16: SB0472
A17: SB0473
A18: SB0474
A19: SH0470
A20: SH0471
A21: SH0472

Sheet Bundle Tags2
A1: =IF('Bundle Tag Info'!A6<>"Panel Name",'Bundle Tag Info'!A6,"") -> JB70 | B1: =IF('Bundle Tag Info'!B6<>"Panel Name",'Bundle Tag Info'!B6,"") -> JB70 R/RAIL | C1: =IF('Bundle Tag Info'!C6<>"Panel Name",'Bundle Tag Info'!C6,"") -> JB70 A | D1: =IF('Bundle Tag Info'!D6<>"Panel Name",'Bundle Tag Info'!D6,"") -> JB70 B | E1: =IF('Bundle Tag Info'!E6<>"Panel Name",'Bundle Tag Info'!E6,"") -> MED CONV | F1: =IF('Bundle Tag Info'!F6<>"Panel Name",'Bundle Tag Info'!F6,"") | G1: =IF('Bundle Tag Info'!G6<>"Panel Name",'Bundle Tag Info'!G6,"") | H1: =IF('Bundle Tag Info'!H6<>"Panel Name",'Bundle Tag Info'!H6,"") | ... AD1: =IF('Bundle Tag Info'!AD6<>"Panel Name",'Bundle Tag Info'!AD6,"")
A2: =IF('Bundle Tag Info'!A$7<>"",CONCATENATE('Bundle Tag Info'!$A$1," ",CHAR(10),'Bundle Tag Info'!$A$2," ",'Bundle Tag Info'!$A$3,CHAR(10),'Bundle Tag Info'!A$6,CHAR(10),'Bundle Tag Info'!A$7),"") -> ENI-K #2 4M511 REV B JB70 AT1100 | B2: =IF('Bundle Tag Info'!B$7<>"",CONCATENATE('Bundle Tag Info'!$A$1," ",CHAR(10),'Bundle Tag Info'!$A$2," ",'Bundle Tag Info'!$A$3,CHAR(10),'Bundle Tag Info'!B$6,CHAR(10),'Bundle Tag Info'!B$7),"") -> ENI-K #2 4M511 REV B JB70 R/RAIL FU-A | C2: =IF('Bundle Tag Info'!C$7<>"",CONCATENATE('Bundle Tag Info'!$A$1," ",CHAR(10),'Bundle Tag Info'!$A$2," ",'Bundle Tag Info'!$A$3,CHAR(10),'Bundle Tag Info'!C$6,CHAR(10),'Bundle Tag Info'!C$7),"") -> ENI-K #2 4M511 REV B JB70 A RR | D2: =IF('Bundle Tag Info'!D$7<>"",CONCATENATE('Bundle Tag Info'!$A$1," ",CHAR(10),'Bundle Tag Info'!$A$2," ",'Bundle Tag Info'!$A$3,CHAR(10),'Bundle Tag Info'!D$6,CHAR(10),'Bundle Tag Info'!D$7),"") -> ENI-K #2 4M511 REV B JB70 B BA | E2: =IF('Bundle Tag Info'!E$7<>"",CONCATENATE('Bundle Tag Info'!$A$1," ",CHAR(10),'Bundle Tag Info'!$A$2," ",'Bundle Tag Info'!$A$3,CHAR(10),'Bundle Tag Info'!E$6,CHAR(10),'Bundle Tag Info'!E$7),"") -> ENI-K #2 4M511 REV B MED CONV BA/FU | F2: =IF('Bundle Tag Info'!F$7<>"",CONCATENATE('Bundle Tag Info'!$A$1," ",CHAR(10),'Bundle Tag Info'!$A$2," ",'Bundle Tag Info'!$A$3,CHAR(10),'Bundle Tag Info'!F$6,CHAR(10),'Bundle Tag Info'!F$7),"") | G2: =IF('Bundle Tag Info'!G$7<>"",CONCATENATE('Bundle Tag Info'!$A$1," ",CHAR(10),'Bundle Tag Info'!$A$2," ",'Bundle Tag Info'!$A$3,CHAR(10),'Bundle Tag Info'!G$6,CHAR(10),'Bundle Tag Info'!G$7),"") | H2: =IF('Bundle Tag Info'!H$7<>"",CONCATENATE('Bundle Tag Info'!$A$1," ",CHAR(10),'Bundle Tag Info'!$A$2," ",'Bundle Tag Info'!$A$3,CHAR(10),'Bundle Tag Info'!H$6,CHAR(10),'Bundle Tag Info'!H$7),"") | ... AD2: =IF('Bundle Tag Info'!AD$7<>"",CONCATENATE('Bundle Tag Info'!$A$1," ",CHAR(10),'Bundle Tag Info'!$A$2," ",'Bundle Tag Info'!$A$3,CHAR(10),'Bundle Tag Info'!AD$6,CHAR(10),'Bundle Tag Info'!AD$7),"")
A3: =IF('Bundle Tag Info'!A$8<>"",CONCATENATE('Bundle Tag Info'!$A$1," ",CHAR(10),'Bundle Tag Info'!$A$2," ",'Bundle Tag Info'!$A$3,CHAR(10),'Bundle Tag Info'!A$6,CHAR(10),'Bundle Tag Info'!A$8),"") -> ENI-K #2 4M511 REV B JB70 HL0171 | B3: =IF('Bundle Tag Info'!B$8<>"",CONCATENATE('Bundle Tag Info'!$A$1," ",CHAR(10),'Bundle Tag Info'!$A$2," ",'Bundle Tag Info'!$A$3,CHAR(10),'Bundle Tag Info'!B$6,CHAR(10),'Bundle Tag Info'!B$8),"") | C3: =IF('Bundle Tag Info'!C$8<>"",CONCATENATE('Bundle Tag Info'!$A$1," ",CHAR(10),'Bundle Tag Info'!$A$2," ",'Bundle Tag Info'!$A$3,CHAR(10),'Bundle Tag Info'!C$6,CHAR(10),'Bundle Tag Info'!C$8),"") -> ENI-K #2 4M511 REV B JB70 A UA1200 | D3: =IF('Bundle Tag Info'!D$8<>"",CONCATENATE('Bundle Tag Info'!$A$1," ",CHAR(10),'Bundle Tag Info'!$A$2," ",'Bundle Tag Info'!$A$3,CHAR(10),'Bundle Tag Info'!D$6,CHAR(10),'Bundle Tag Info'!D$8),"") -> ENI-K #2 4M511 REV B JB70 B FU | E3: =IF('Bundle Tag Info'!E$8<>"",CONCATENATE('Bundle Tag Info'!$A$1," ",CHAR(10),'Bundle Tag Info'!$A$2," ",'Bundle Tag Info'!$A$3,CHAR(10),'Bundle Tag Info'!E$6,CHAR(10),'Bundle Tag Info'!E$8),"") | F3: =IF('Bundle Tag Info'!F$8<>"",CONCATENATE('Bundle Tag Info'!$A$1," ",CHAR(10),'Bundle Tag Info'!$A$2," ",'Bundle Tag Info'!$A$3,CHAR(10),'Bundle Tag Info'!F$6,CHAR(10),'Bundle Tag Info'!F$8),"") | G3: =IF('Bundle Tag Info'!G$8<>"",CONCATENATE('Bundle Tag Info'!$A$1," ",CHAR(10),'Bundle Tag Info'!$A$2," ",'Bundle Tag Info'!$A$3,CHAR(10),'Bundle Tag Info'!G$6,CHAR(10),'Bundle Tag Info'!G$8),"") | H3: =IF('Bundle Tag Info'!H$8<>"",CONCATENATE('Bundle Tag Info'!$A$1," ",CHAR(10),'Bundle Tag Info'!$A$2," ",'Bundle Tag Info'!$A$3,CHAR(10),'Bundle Tag Info'!H$6,CHAR(10),'Bundle Tag Info'!H$8),"") | ... AD3: =IF('Bundle Tag Info'!AD$8<>"",CONCATENATE('Bundle Tag Info'!$A$1," ",CHAR(10),'Bundle Tag Info'!$A$2," ",'Bundle Tag Info'!$A$3,CHAR(10),'Bundle Tag Info'!AD$6,CHAR(10),'Bundle Tag Info'!AD$8),"")
A4: =IF('Bundle Tag Info'!A$9<>"",CONCATENATE('Bundle Tag Info'!$A$1," ",CHAR(10),'Bundle Tag Info'!$A$2," ",'Bundle Tag Info'!$A$3,CHAR(10),'Bundle Tag Info'!A$6,CHAR(10),'Bundle Tag Info'!A$9),"") -> ENI-K #2 4M511 REV B JB70 HL0172 | B4: =IF('Bundle Tag Info'!B$9<>"",CONCATENATE('Bundle Tag Info'!$A$1," ",CHAR(10),'Bundle Tag Info'!$A$2," ",'Bundle Tag Info'!$A$3,CHAR(10),'Bundle Tag Info'!B$6,CHAR(10),'Bundle Tag Info'!B$9),"") | C4: =IF('Bundle Tag Info'!C$9<>"",CONCATENATE('Bundle Tag Info'!$A$1," ",CHAR(10),'Bundle Tag Info'!$A$2," ",'Bundle Tag Info'!$A$3,CHAR(10),'Bundle Tag Info'!C$6,CHAR(10),'Bundle Tag Info'!C$9),"") -> ENI-K #2 4M511 REV B JB70 A XT-B | D4: =IF('Bundle Tag Info'!D$9<>"",CONCATENATE('Bundle Tag Info'!$A$1," ",CHAR(10),'Bundle Tag Info'!$A$2," ",'Bundle Tag Info'!$A$3,CHAR(10),'Bundle Tag Info'!D$6,CHAR(10),'Bundle Tag Info'!D$9),"") | E4: =IF('Bundle Tag Info'!E$9<>"",CONCATENATE('Bundle Tag Info'!$A$1," ",CHAR(10),'Bundle Tag Info'!$A$2," ",'Bundle Tag Info'!$A$3,CHAR(10),'Bundle Tag Info'!E$6,CHAR(10),'Bundle Tag Info'!E$9),"") | F4: =IF('Bundle Tag Info'!F$9<>"",CONCATENATE('Bundle Tag Info'!$A$1," ",CHAR(10),'Bundle Tag Info'!$A$2," ",'Bundle Tag Info'!$A$3,CHAR(10),'Bundle Tag Info'!F$6,CHAR(10),'Bundle Tag Info'!F$9),"") | G4: =IF('Bundle Tag Info'!G$9<>"",CONCATENATE('Bundle Tag Info'!$A$1," ",CHAR(10),'Bundle Tag Info'!$A$2," ",'Bundle Tag Info'!$A$3,CHAR(10),'Bundle Tag Info'!G$6,CHAR(10),'Bundle Tag Info'!G$9),"") | H4: =IF('Bundle Tag Info'!H$9<>"",CONCATENATE('Bundle Tag Info'!$A$1," ",CHAR(10),'Bundle Tag Info'!$A$2," ",'Bundle Tag Info'!$A$3,CHAR(10),'Bundle Tag Info'!H$6,CHAR(10),'Bundle Tag Info'!H$9),"") | ... AD4: =IF('Bundle Tag Info'!AD$9<>"",CONCATENATE('Bundle Tag Info'!$A$1," ",CHAR(10),'Bundle Tag Info'!$A$2," ",'Bundle Tag Info'!$A$3,CHAR(10),'Bundle Tag Info'!AD$6,CHAR(10),'Bundle Tag Info'!AD$9),"")
A5: =IF('Bundle Tag Info'!A$10<>"",CONCATENATE('Bundle Tag Info'!$A$1," ",CHAR(10),'Bundle Tag Info'!$A$2," ",'Bundle Tag Info'!$A$3,CHAR(10),'Bundle Tag Info'!A$6,CHAR(10),'Bundle Tag Info'!A$10),"") -> ENI-K #2 4M511 REV B JB70 HL0173 | B5: =IF('Bundle Tag Info'!B$10<>"",CONCATENATE('Bundle Tag Info'!$A$1," ",CHAR(10),'Bundle Tag Info'!$A$2," ",'Bundle Tag Info'!$A$3,CHAR(10),'Bundle Tag Info'!B$6,CHAR(10),'Bundle Tag Info'!B$10),"") | C5: =IF('Bundle Tag Info'!C$10<>"",CONCATENATE('Bundle Tag Info'!$A$1," ",CHAR(10),'Bundle Tag Info'!$A$2," ",'Bundle Tag Info'!$A$3,CHAR(10),'Bundle Tag Info'!C$6,CHAR(10),'Bundle Tag Info'!C$10),"") | D5: =IF('Bundle Tag Info'!D$10<>"",CONCATENATE('Bundle Tag Info'!$A$1," ",CHAR(10),'Bundle Tag Info'!$A$2," ",'Bundle Tag Info'!$A$3,CHAR(10),'Bundle Tag Info'!D$6,CHAR(10),'Bundle Tag Info'!D$10),"") | E5: =IF('Bundle Tag Info'!E$10<>"",CONCATENATE('Bundle Tag Info'!$A$1," ",CHAR(10),'Bundle Tag Info'!$A$2," ",'Bundle Tag Info'!$A$3,CHAR(10),'Bundle Tag Info'!E$6,CHAR(10),'Bundle Tag Info'!E$10),"") | F5: =IF('Bundle Tag Info'!F$10<>"",CONCATENATE('Bundle Tag Info'!$A$1," ",CHAR(10),'Bundle Tag Info'!$A$2," ",'Bundle Tag Info'!$A$3,CHAR(10),'Bundle Tag Info'!F$6,CHAR(10),'Bundle Tag Info'!F$10),"") | G5: =IF('Bundle Tag Info'!G$10<>"",CONCATENATE('Bundle Tag Info'!$A$1," ",CHAR(10),'Bundle Tag Info'!$A$2," ",'Bundle Tag Info'!$A$3,CHAR(10),'Bundle Tag Info'!G$6,CHAR(10),'Bundle Tag Info'!G$10),"") | H5: =IF('Bundle Tag Info'!H$10<>"",CONCATENATE('Bundle Tag Info'!$A$1," ",CHAR(10),'Bundle Tag Info'!$A$2," ",'Bundle Tag Info'!$A$3,CHAR(10),'Bundle Tag Info'!H$6,CHAR(10),'Bundle Tag Info'!H$10),"") | ... AD5: =IF('Bundle Tag Info'!AD$10<>"",CONCATENATE('Bundle Tag Info'!$A$1," ",CHAR(10),'Bundle Tag Info'!$A$2," ",'Bundle Tag Info'!$A$3,CHAR(10),'Bundle Tag Info'!AD$6,CHAR(10),'Bundle Tag Info'!AD$10),"")
A6: =IF('Bundle Tag Info'!A$11<>"",CONCATENATE('Bundle Tag Info'!$A$1," ",CHAR(10),'Bundle Tag Info'!$A$2," ",'Bundle Tag Info'!$A$3,CHAR(10),'Bundle Tag Info'!A$6,CHAR(10),'Bundle Tag Info'!A$11),"") -> ENI-K #2 4M511 REV B JB70 SB0170 | B6: =IF('Bundle Tag Info'!B$11<>"",CONCATENATE('Bundle Tag Info'!$A$1," ",CHAR(10),'Bundle Tag Info'!$A$2," ",'Bundle Tag Info'!$A$3,CHAR(10),'Bundle Tag Info'!B$6,CHAR(10),'Bundle Tag Info'!B$11),"") | C6: =IF('Bundle Tag Info'!C$11<>"",CONCATENATE('Bundle Tag Info'!$A$1," ",CHAR(10),'Bundle Tag Info'!$A$2," ",'Bundle Tag Info'!$A$3,CHAR(10),'Bundle Tag Info'!C$6,CHAR(10),'Bundle Tag Info'!C$11),"") | D6: =IF('Bundle Tag Info'!D$11<>"",CONCATENATE('Bundle Tag Info'!$A$1," ",CHAR(10),'Bundle Tag Info'!$A$2," ",'Bundle Tag Info'!$A$3,CHAR(10),'Bundle Tag Info'!D$6,CHAR(10),'Bundle Tag Info'!D$11),"") | E6: =IF('Bundle Tag Info'!E$11<>"",CONCATENATE('Bundle Tag Info'!$A$1," ",CHAR(10),'Bundle Tag Info'!$A$2," ",'Bundle Tag Info'!$A$3,CHAR(10),'Bundle Tag Info'!E$6,CHAR(10),'Bundle Tag Info'!E$11),"") | F6: =IF('Bundle Tag Info'!F$11<>"",CONCATENATE('Bundle Tag Info'!$A$1," ",CHAR(10),'Bundle Tag Info'!$A$2," ",'Bundle Tag Info'!$A$3,CHAR(10),'Bundle Tag Info'!F$6,CHAR(10),'Bundle Tag Info'!F$11),"") | G6: =IF('Bundle Tag Info'!G$11<>"",CONCATENATE('Bundle Tag Info'!$A$1," ",CHAR(10),'Bundle Tag Info'!$A$2," ",'Bundle Tag Info'!$A$3,CHAR(10),'Bundle Tag Info'!G$6,CHAR(10),'Bundle Tag Info'!G$11),"") | H6: =IF('Bundle Tag Info'!H$11<>"",CONCATENATE('Bundle Tag Info'!$A$1," ",CHAR(10),'Bundle Tag Info'!$A$2," ",'Bundle Tag Info'!$A$3,CHAR(10),'Bundle Tag Info'!H$6,CHAR(10),'Bundle Tag Info'!H$11),"") | ... AD6: =IF('Bundle Tag Info'!AD$11<>"",CONCATENATE('Bundle Tag Info'!$A$1," ",CHAR(10),'Bundle Tag Info'!$A$2," ",'Bundle Tag Info'!$A$3,CHAR(10),'Bundle Tag Info'!AD$6,CHAR(10),'Bundle Tag Info'!AD$11),"")
A7: =IF('Bundle Tag Info'!A$12<>"",CONCATENATE('Bundle Tag Info'!$A$1," ",CHAR(10),'Bundle Tag Info'!$A$2," ",'Bundle Tag Info'!$A$3,CHAR(10),'Bundle Tag Info'!A$6,CHAR(10),'Bundle Tag Info'!A$12),"") -> ENI-K #2 4M511 REV B JB70 SA0170 | B7: =IF('Bundle Tag Info'!B$12<>"",CONCATENATE('Bundle Tag Info'!$A$1," ",CHAR(10),'Bundle Tag Info'!$A$2," ",'Bundle Tag Info'!$A$3,CHAR(10),'Bundle Tag Info'!B$6,CHAR(10),'Bundle Tag Info'!B$12),"") | C7: =IF('Bundle Tag Info'!C$12<>"",CONCATENATE('Bundle Tag Info'!$A$1," ",CHAR(10),'Bundle Tag Info'!$A$2," ",'Bundle Tag Info'!$A$3,CHAR(10),'Bundle Tag Info'!C$6,CHAR(10),'Bundle Tag Info'!C$12),"") | D7: =IF('Bundle Tag Info'!D$12<>"",CONCATENATE('Bundle Tag Info'!$A$1," ",CHAR(10),'Bundle Tag Info'!$A$2," ",'Bundle Tag Info'!$A$3,CHAR(10),'Bundle Tag Info'!D$6,CHAR(10),'Bundle Tag Info'!D$12),"") | E7: =IF('Bundle Tag Info'!E$12<>"",CONCATENATE('Bundle Tag Info'!$A$1," ",CHAR(10),'Bundle Tag Info'!$A$2," ",'Bundle Tag Info'!$A$3,CHAR(10),'Bundle Tag Info'!E$6,CHAR(10),'Bundle Tag Info'!E$12),"") | F7: =IF('Bundle Tag Info'!F$12<>"",CONCATENATE('Bundle Tag Info'!$A$1," ",CHAR(10),'Bundle Tag Info'!$A$2," ",'Bundle Tag Info'!$A$3,CHAR(10),'Bundle Tag Info'!F$6,CHAR(10),'Bundle Tag Info'!F$12),"") | G7: =IF('Bundle Tag Info'!G$12<>"",CONCATENATE('Bundle Tag Info'!$A$1," ",CHAR(10),'Bundle Tag Info'!$A$2," ",'Bundle Tag Info'!$A$3,CHAR(10),'Bundle Tag Info'!G$6,CHAR(10),'Bundle Tag Info'!G$12),"") | H7: =IF('Bundle Tag Info'!H$12<>"",CONCATENATE('Bundle Tag Info'!$A$1," ",CHAR(10),'Bundle Tag Info'!$A$2," ",'Bundle Tag Info'!$A$3,CHAR(10),'Bundle Tag Info'!H$6,CHAR(10),'Bundle Tag Info'!H$12),"") | ... AD7: =IF('Bundle Tag Info'!AD$12<>"",CONCATENATE('Bundle Tag Info'!$A$1," ",CHAR(10),'Bundle Tag Info'!$A$2," ",'Bundle Tag Info'!$A$3,CHAR(10),'Bundle Tag Info'!AD$6,CHAR(10),'Bundle Tag Info'!AD$12),"")
A8: =IF('Bundle Tag Info'!A$13<>"",CONCATENATE('Bundle Tag Info'!$A$1," ",CHAR(10),'Bundle Tag Info'!$A$2," ",'Bundle Tag Info'!$A$3,CHAR(10),'Bundle Tag Info'!A$6,CHAR(10),'Bundle Tag Info'!A$13),"") -> ENI-K #2 4M511 REV B JB70 SA0471 | B8: =IF('Bundle Tag Info'!B$13<>"",CONCATENATE('Bundle Tag Info'!$A$1," ",CHAR(10),'Bundle Tag Info'!$A$2," ",'Bundle Tag Info'!$A$3,CHAR(10),'Bundle Tag Info'!B$6,CHAR(10),'Bundle Tag Info'!B$13),"") | C8: =IF('Bundle Tag Info'!C$13<>"",CONCATENATE('Bundle Tag Info'!$A$1," ",CHAR(10),'Bundle Tag Info'!$A$2," ",'Bundle Tag Info'!$A$3,CHAR(10),'Bundle Tag Info'!C$6,CHAR(10),'Bundle Tag Info'!C$13),"") | D8: =IF('Bundle Tag Info'!D$13<>"",CONCATENATE('Bundle Tag Info'!$A$1," ",CHAR(10),'Bundle Tag Info'!$A$2," ",'Bundle Tag Info'!$A$3,CHAR(10),'Bundle Tag Info'!D$6,CHAR(10),'Bundle Tag Info'!D$13),"") | E8: =IF('Bundle Tag Info'!E$13<>"",CONCATENATE('Bundle Tag Info'!$A$1," ",CHAR(10),'Bundle Tag Info'!$A$2," ",'Bundle Tag Info'!$A$3,CHAR(10),'Bundle Tag Info'!E$6,CHAR(10),'Bundle Tag Info'!E$13),"") | F8: =IF('Bundle Tag Info'!F$13<>"",CONCATENATE('Bundle Tag Info'!$A$1," ",CHAR(10),'Bundle Tag Info'!$A$2," ",'Bundle Tag Info'!$A$3,CHAR(10),'Bundle Tag Info'!F$6,CHAR(10),'Bundle Tag Info'!F$13),"") | G8: =IF('Bundle Tag Info'!G$13<>"",CONCATENATE('Bundle Tag Info'!$A$1," ",CHAR(10),'Bundle Tag Info'!$A$2," ",'Bundle Tag Info'!$A$3,CHAR(10),'Bundle Tag Info'!G$6,CHAR(10),'Bundle Tag Info'!G$13),"") | H8: =IF('Bundle Tag Info'!H$13<>"",CONCATENATE('Bundle Tag Info'!$A$1," ",CHAR(10),'Bundle Tag Info'!$A$2," ",'Bundle Tag Info'!$A$3,CHAR(10),'Bundle Tag Info'!H$6,CHAR(10),'Bundle Tag Info'!H$13),"") | ... AD8: =IF('Bundle Tag Info'!AD$13<>"",CONCATENATE('Bundle Tag Info'!$A$1," ",CHAR(10),'Bundle Tag Info'!$A$2," ",'Bundle Tag Info'!$A$3,CHAR(10),'Bundle Tag Info'!AD$6,CHAR(10),'Bundle Tag Info'!AD$13),"")
A9: =IF('Bundle Tag Info'!A$14<>"",CONCATENATE('Bundle Tag Info'!$A$1," ",CHAR(10),'Bundle Tag Info'!$A$2," ",'Bundle Tag Info'!$A$3,CHAR(10),'Bundle Tag Info'!A$6,CHAR(10),'Bundle Tag Info'!A$14),"") -> ENI-K #2 4M511 REV B JB70 SA0474 | B9: =IF('Bundle Tag Info'!B$14<>"",CONCATENATE('Bundle Tag Info'!$A$1," ",CHAR(10),'Bundle Tag Info'!$A$2," ",'Bundle Tag Info'!$A$3,CHAR(10),'Bundle Tag Info'!B$6,CHAR(10),'Bundle Tag Info'!B$14),"") | C9: =IF('Bundle Tag Info'!C$14<>"",CONCATENATE('Bundle Tag Info'!$A$1," ",CHAR(10),'Bundle Tag Info'!$A$2," ",'Bundle Tag Info'!$A$3,CHAR(10),'Bundle Tag Info'!C$6,CHAR(10),'Bundle Tag Info'!C$14),"") | D9: =IF('Bundle Tag Info'!D$14<>"",CONCATENATE('Bundle Tag Info'!$A$1," ",CHAR(10),'Bundle Tag Info'!$A$2," ",'Bundle Tag Info'!$A$3,CHAR(10),'Bundle Tag Info'!D$6,CHAR(10),'Bundle Tag Info'!D$14),"") | E9: =IF('Bundle Tag Info'!E$14<>"",CONCATENATE('Bundle Tag Info'!$A$1," ",CHAR(10),'Bundle Tag Info'!$A$2," ",'Bundle Tag Info'!$A$3,CHAR(10),'Bundle Tag Info'!E$6,CHAR(10),'Bundle Tag Info'!E$14),"") | F9: =IF('Bundle Tag Info'!F$14<>"",CONCATENATE('Bundle Tag Info'!$A$1," ",CHAR(10),'Bundle Tag Info'!$A$2," ",'Bundle Tag Info'!$A$3,CHAR(10),'Bundle Tag Info'!F$6,CHAR(10),'Bundle Tag Info'!F$14),"") | G9: =IF('Bundle Tag Info'!G$14<>"",CONCATENATE('Bundle Tag Info'!$A$1," ",CHAR(10),'Bundle Tag Info'!$A$2," ",'Bundle Tag Info'!$A$3,CHAR(10),'Bundle Tag Info'!G$6,CHAR(10),'Bundle Tag Info'!G$14),"") | H9: =IF('Bundle Tag Info'!H$14<>"",CONCATENATE('Bundle Tag Info'!$A$1," ",CHAR(10),'Bundle Tag Info'!$A$2," ",'Bundle Tag Info'!$A$3,CHAR(10),'Bundle Tag Info'!H$6,CHAR(10),'Bundle Tag Info'!H$14),"") | ... AD9: =IF('Bundle Tag Info'!AD$14<>"",CONCATENATE('Bundle Tag Info'!$A$1," ",CHAR(10),'Bundle Tag Info'!$A$2," ",'Bundle Tag Info'!$A$3,CHAR(10),'Bundle Tag Info'!AD$6,CHAR(10),'Bundle Tag Info'!AD$14),"")
A10: =IF('Bundle Tag Info'!A$15<>"",CONCATENATE('Bundle Tag Info'!$A$1," ",CHAR(10),'Bundle Tag Info'!$A$2," ",'Bundle Tag Info'!$A$3,CHAR(10),'Bundle Tag Info'!A$6,CHAR(10),'Bundle Tag Info'!A$15),"") -> ENI-K #2 4M511 REV B JB70 SB0471 | B10: =IF('Bundle Tag Info'!B$15<>"",CONCATENATE('Bundle Tag Info'!$A$1," ",CHAR(10),'Bundle Tag Info'!$A$2," ",'Bundle Tag Info'!$A$3,CHAR(10),'Bundle Tag Info'!B$6,CHAR(10),'Bundle Tag Info'!B$15),"") | C10: =IF('Bundle Tag Info'!C$15<>"",CONCATENATE('Bundle Tag Info'!$A$1," ",CHAR(10),'Bundle Tag Info'!$A$2," ",'Bundle Tag Info'!$A$3,CHAR(10),'Bundle Tag Info'!C$6,CHAR(10),'Bundle Tag Info'!C$15),"") | D10: =IF('Bundle Tag Info'!D$15<>"",CONCATENATE('Bundle Tag Info'!$A$1," ",CHAR(10),'Bundle Tag Info'!$A$2," ",'Bundle Tag Info'!$A$3,CHAR(10),'Bundle Tag Info'!D$6,CHAR(10),'Bundle Tag Info'!D$15),"") | E10: =IF('Bundle Tag Info'!E$15<>"",CONCATENATE('Bundle Tag Info'!$A$1," ",CHAR(10),'Bundle Tag Info'!$A$2," ",'Bundle Tag Info'!$A$3,CHAR(10),'Bundle Tag Info'!E$6,CHAR(10),'Bundle Tag Info'!E$15),"") | F10: =IF('Bundle Tag Info'!F$15<>"",CONCATENATE('Bundle Tag Info'!$A$1," ",CHAR(10),'Bundle Tag Info'!$A$2," ",'Bundle Tag Info'!$A$3,CHAR(10),'Bundle Tag Info'!F$6,CHAR(10),'Bundle Tag Info'!F$15),"") | G10: =IF('Bundle Tag Info'!G$15<>"",CONCATENATE('Bundle Tag Info'!$A$1," ",CHAR(10),'Bundle Tag Info'!$A$2," ",'Bundle Tag Info'!$A$3,CHAR(10),'Bundle Tag Info'!G$6,CHAR(10),'Bundle Tag Info'!G$15),"") | H10: =IF('Bundle Tag Info'!H$15<>"",CONCATENATE('Bundle Tag Info'!$A$1," ",CHAR(10),'Bundle Tag Info'!$A$2," ",'Bundle Tag Info'!$A$3,CHAR(10),'Bundle Tag Info'!H$6,CHAR(10),'Bundle Tag Info'!H$15),"") | ... AD10: =IF('Bundle Tag Info'!AD$15<>"",CONCATENATE('Bundle Tag Info'!$A$1," ",CHAR(10),'Bundle Tag Info'!$A$2," ",'Bundle Tag Info'!$A$3,CHAR(10),'Bundle Tag Info'!AD$6,CHAR(10),'Bundle Tag Info'!AD$15),"")
A11: =IF('Bundle Tag Info'!A$16<>"",CONCATENATE('Bundle Tag Info'!$A$1," ",CHAR(10),'Bundle Tag Info'!$A$2," ",'Bundle Tag Info'!$A$3,CHAR(10),'Bundle Tag Info'!A$6,CHAR(10),'Bundle Tag Info'!A$16),"") -> ENI-K #2 4M511 REV B JB70 SB0472 | B11: =IF('Bundle Tag Info'!B$16<>"",CONCATENATE('Bundle Tag Info'!$A$1," ",CHAR(10),'Bundle Tag Info'!$A$2," ",'Bundle Tag Info'!$A$3,CHAR(10),'Bundle Tag Info'!B$6,CHAR(10),'Bundle Tag Info'!B$16),"") | C11: =IF('Bundle Tag Info'!C$16<>"",CONCATENATE('Bundle Tag Info'!$A$1," ",CHAR(10),'Bundle Tag Info'!$A$2," ",'Bundle Tag Info'!$A$3,CHAR(10),'Bundle Tag Info'!C$6,CHAR(10),'Bundle Tag Info'!C$16),"") | D11: =IF('Bundle Tag Info'!D$16<>"",CONCATENATE('Bundle Tag Info'!$A$1," ",CHAR(10),'Bundle Tag Info'!$A$2," ",'Bundle Tag Info'!$A$3,CHAR(10),'Bundle Tag Info'!D$6,CHAR(10),'Bundle Tag Info'!D$16),"") | E11: =IF('Bundle Tag Info'!E$16<>"",CONCATENATE('Bundle Tag Info'!$A$1," ",CHAR(10),'Bundle Tag Info'!$A$2," ",'Bundle Tag Info'!$A$3,CHAR(10),'Bundle Tag Info'!E$6,CHAR(10),'Bundle Tag Info'!E$16),"") | F11: =IF('Bundle Tag Info'!F$16<>"",CONCATENATE('Bundle Tag Info'!$A$1," ",CHAR(10),'Bundle Tag Info'!$A$2," ",'Bundle Tag Info'!$A$3,CHAR(10),'Bundle Tag Info'!F$6,CHAR(10),'Bundle Tag Info'!F$16),"") | G11: =IF('Bundle Tag Info'!G$16<>"",CONCATENATE('Bundle Tag Info'!$A$1," ",CHAR(10),'Bundle Tag Info'!$A$2," ",'Bundle Tag Info'!$A$3,CHAR(10),'Bundle Tag Info'!G$6,CHAR(10),'Bundle Tag Info'!G$16),"") | H11: =IF('Bundle Tag Info'!H$16<>"",CONCATENATE('Bundle Tag Info'!$A$1," ",CHAR(10),'Bundle Tag Info'!$A$2," ",'Bundle Tag Info'!$A$3,CHAR(10),'Bundle Tag Info'!H$6,CHAR(10),'Bundle Tag Info'!H$16),"") | ... AD11: =IF('Bundle Tag Info'!AD$16<>"",CONCATENATE('Bundle Tag Info'!$A$1," ",CHAR(10),'Bundle Tag Info'!$A$2," ",'Bundle Tag Info'!$A$3,CHAR(10),'Bundle Tag Info'!AD$6,CHAR(10),'Bundle Tag Info'!AD$16),"")
A12: =IF('Bundle Tag Info'!A$17<>"",CONCATENATE('Bundle Tag Info'!$A$1," ",CHAR(10),'Bundle Tag Info'!$A$2," ",'Bundle Tag Info'!$A$3,CHAR(10),'Bundle Tag Info'!A$6,CHAR(10),'Bundle Tag Info'!A$17),"") -> ENI-K #2 4M511 REV B JB70 SB0473 | B12: =IF('Bundle Tag Info'!B$17<>"",CONCATENATE('Bundle Tag Info'!$A$1," ",CHAR(10),'Bundle Tag Info'!$A$2," ",'Bundle Tag Info'!$A$3,CHAR(10),'Bundle Tag Info'!B$6,CHAR(10),'Bundle Tag Info'!B$17),"") | C12: =IF('Bundle Tag Info'!C$17<>"",CONCATENATE('Bundle Tag Info'!$A$1," ",CHAR(10),'Bundle Tag Info'!$A$2," ",'Bundle Tag Info'!$A$3,CHAR(10),'Bundle Tag Info'!C$6,CHAR(10),'Bundle Tag Info'!C$17),"") | D12: =IF('Bundle Tag Info'!D$17<>"",CONCATENATE('Bundle Tag Info'!$A$1," ",CHAR(10),'Bundle Tag Info'!$A$2," ",'Bundle Tag Info'!$A$3,CHAR(10),'Bundle Tag Info'!D$6,CHAR(10),'Bundle Tag Info'!D$17),"") | E12: =IF('Bundle Tag Info'!E$17<>"",CONCATENATE('Bundle Tag Info'!$A$1," ",CHAR(10),'Bundle Tag Info'!$A$2," ",'Bundle Tag Info'!$A$3,CHAR(10),'Bundle Tag Info'!E$6,CHAR(10),'Bundle Tag Info'!E$17),"") | F12: =IF('Bundle Tag Info'!F$17<>"",CONCATENATE('Bundle Tag Info'!$A$1," ",CHAR(10),'Bundle Tag Info'!$A$2," ",'Bundle Tag Info'!$A$3,CHAR(10),'Bundle Tag Info'!F$6,CHAR(10),'Bundle Tag Info'!F$17),"") | G12: =IF('Bundle Tag Info'!G$17<>"",CONCATENATE('Bundle Tag Info'!$A$1," ",CHAR(10),'Bundle Tag Info'!$A$2," ",'Bundle Tag Info'!$A$3,CHAR(10),'Bundle Tag Info'!G$6,CHAR(10),'Bundle Tag Info'!G$17),"") | H12: =IF('Bundle Tag Info'!H$17<>"",CONCATENATE('Bundle Tag Info'!$A$1," ",CHAR(10),'Bundle Tag Info'!$A$2," ",'Bundle Tag Info'!$A$3,CHAR(10),'Bundle Tag Info'!H$6,CHAR(10),'Bundle Tag Info'!H$17),"") | ... AD12: =IF('Bundle Tag Info'!AD$17<>"",CONCATENATE('Bundle Tag Info'!$A$1," ",CHAR(10),'Bundle Tag Info'!$A$2," ",'Bundle Tag Info'!$A$3,CHAR(10),'Bundle Tag Info'!AD$6,CHAR(10),'Bundle Tag Info'!AD$17),"")
A13: =IF('Bundle Tag Info'!A$18<>"",CONCATENATE('Bundle Tag Info'!$A$1," ",CHAR(10),'Bundle Tag Info'!$A$2," ",'Bundle Tag Info'!$A$3,CHAR(10),'Bundle Tag Info'!A$6,CHAR(10),'Bundle Tag Info'!A$18),"") -> ENI-K #2 4M511 REV B JB70 SB0474 | B13: =IF('Bundle Tag Info'!B$18<>"",CONCATENATE('Bundle Tag Info'!$A$1," ",CHAR(10),'Bundle Tag Info'!$A$2," ",'Bundle Tag Info'!$A$3,CHAR(10),'Bundle Tag Info'!B$6,CHAR(10),'Bundle Tag Info'!B$18),"") | C13: =IF('Bundle Tag Info'!C$18<>"",CONCATENATE('Bundle Tag Info'!$A$1," ",CHAR(10),'Bundle Tag Info'!$A$2," ",'Bundle Tag Info'!$A$3,CHAR(10),'Bundle Tag Info'!C$6,CHAR(10),'Bundle Tag Info'!C$18),"") | D13: =IF('Bundle Tag Info'!D$18<>"",CONCATENATE('Bundle Tag Info'!$A$1," ",CHAR(10),'Bundle Tag Info'!$A$2," ",'Bundle Tag Info'!$A$3,CHAR(10),'Bundle Tag Info'!D$6,CHAR(10),'Bundle Tag Info'!D$18),"") | E13: =IF('Bundle Tag Info'!E$18<>"",CONCATENATE('Bundle Tag Info'!$A$1," ",CHAR(10),'Bundle Tag Info'!$A$2," ",'Bundle Tag Info'!$A$3,CHAR(10),'Bundle Tag Info'!E$6,CHAR(10),'Bundle Tag Info'!E$18),"") | F13: =IF('Bundle Tag Info'!F$18<>"",CONCATENATE('Bundle Tag Info'!$A$1," ",CHAR(10),'Bundle Tag Info'!$A$2," ",'Bundle Tag Info'!$A$3,CHAR(10),'Bundle Tag Info'!F$6,CHAR(10),'Bundle Tag Info'!F$18),"") | G13: =IF('Bundle Tag Info'!G$18<>"",CONCATENATE('Bundle Tag Info'!$A$1," ",CHAR(10),'Bundle Tag Info'!$A$2," ",'Bundle Tag Info'!$A$3,CHAR(10),'Bundle Tag Info'!G$6,CHAR(10),'Bundle Tag Info'!G$18),"") | H13: =IF('Bundle Tag Info'!H$18<>"",CONCATENATE('Bundle Tag Info'!$A$1," ",CHAR(10),'Bundle Tag Info'!$A$2," ",'Bundle Tag Info'!$A$3,CHAR(10),'Bundle Tag Info'!H$6,CHAR(10),'Bundle Tag Info'!H$18),"") | ... AD13: =IF('Bundle Tag Info'!AD$18<>"",CONCATENATE('Bundle Tag Info'!$A$1," ",CHAR(10),'Bundle Tag Info'!$A$2," ",'Bundle Tag Info'!$A$3,CHAR(10),'Bundle Tag Info'!AD$6,CHAR(10),'Bundle Tag Info'!AD$18),"")
A14: =IF('Bundle Tag Info'!A$19<>"",CONCATENATE('Bundle Tag Info'!$A$1," ",CHAR(10),'Bundle Tag Info'!$A$2," ",'Bundle Tag Info'!$A$3,CHAR(10),'Bundle Tag Info'!A$6,CHAR(10),'Bundle Tag Info'!A$19),"") -> ENI-K #2 4M511 REV B JB70 SH0470 | B14: =IF('Bundle Tag Info'!B$19<>"",CONCATENATE('Bundle Tag Info'!$A$1," ",CHAR(10),'Bundle Tag Info'!$A$2," ",'Bundle Tag Info'!$A$3,CHAR(10),'Bundle Tag Info'!B$6,CHAR(10),'Bundle Tag Info'!B$19),"") | C14: =IF('Bundle Tag Info'!C$19<>"",CONCATENATE('Bundle Tag Info'!$A$1," ",CHAR(10),'Bundle Tag Info'!$A$2," ",'Bundle Tag Info'!$A$3,CHAR(10),'Bundle Tag Info'!C$6,CHAR(10),'Bundle Tag Info'!C$19),"") | D14: =IF('Bundle Tag Info'!D$19<>"",CONCATENATE('Bundle Tag Info'!$A$1," ",CHAR(10),'Bundle Tag Info'!$A$2," ",'Bundle Tag Info'!$A$3,CHAR(10),'Bundle Tag Info'!D$6,CHAR(10),'Bundle Tag Info'!D$19),"") | E14: =IF('Bundle Tag Info'!E$19<>"",CONCATENATE('Bundle Tag Info'!$A$1," ",CHAR(10),'Bundle Tag Info'!$A$2," ",'Bundle Tag Info'!$A$3,CHAR(10),'Bundle Tag Info'!E$6,CHAR(10),'Bundle Tag Info'!E$19),"") | F14: =IF('Bundle Tag Info'!F$19<>"",CONCATENATE('Bundle Tag Info'!$A$1," ",CHAR(10),'Bundle Tag Info'!$A$2," ",'Bundle Tag Info'!$A$3,CHAR(10),'Bundle Tag Info'!F$6,CHAR(10),'Bundle Tag Info'!F$19),"") | G14: =IF('Bundle Tag Info'!G$19<>"",CONCATENATE('Bundle Tag Info'!$A$1," ",CHAR(10),'Bundle Tag Info'!$A$2," ",'Bundle Tag Info'!$A$3,CHAR(10),'Bundle Tag Info'!G$6,CHAR(10),'Bundle Tag Info'!G$19),"") | H14: =IF('Bundle Tag Info'!H$19<>"",CONCATENATE('Bundle Tag Info'!$A$1," ",CHAR(10),'Bundle Tag Info'!$A$2," ",'Bundle Tag Info'!$A$3,CHAR(10),'Bundle Tag Info'!H$6,CHAR(10),'Bundle Tag Info'!H$19),"") | ... AD14: =IF('Bundle Tag Info'!AD$19<>"",CONCATENATE('Bundle Tag Info'!$A$1," ",CHAR(10),'Bundle Tag Info'!$A$2," ",'Bundle Tag Info'!$A$3,CHAR(10),'Bundle Tag Info'!AD$6,CHAR(10),'Bundle Tag Info'!AD$19),"")
A15: =IF('Bundle Tag Info'!A$20<>"",CONCATENATE('Bundle Tag Info'!$A$1," ",CHAR(10),'Bundle Tag Info'!$A$2," ",'Bundle Tag Info'!$A$3,CHAR(10),'Bundle Tag Info'!A$6,CHAR(10),'Bundle Tag Info'!A$20),"") -> ENI-K #2 4M511 REV B JB70 SH0471 | B15: =IF('Bundle Tag Info'!B$20<>"",CONCATENATE('Bundle Tag Info'!$A$1," ",CHAR(10),'Bundle Tag Info'!$A$2," ",'Bundle Tag Info'!$A$3,CHAR(10),'Bundle Tag Info'!B$6,CHAR(10),'Bundle Tag Info'!B$20),"") | C15: =IF('Bundle Tag Info'!C$20<>"",CONCATENATE('Bundle Tag Info'!$A$1," ",CHAR(10),'Bundle Tag Info'!$A$2," ",'Bundle Tag Info'!$A$3,CHAR(10),'Bundle Tag Info'!C$6,CHAR(10),'Bundle Tag Info'!C$20),"") | D15: =IF('Bundle Tag Info'!D$20<>"",CONCATENATE('Bundle Tag Info'!$A$1," ",CHAR(10),'Bundle Tag Info'!$A$2," ",'Bundle Tag Info'!$A$3,CHAR(10),'Bundle Tag Info'!D$6,CHAR(10),'Bundle Tag Info'!D$20),"") | E15: =IF('Bundle Tag Info'!E$20<>"",CONCATENATE('Bundle Tag Info'!$A$1," ",CHAR(10),'Bundle Tag Info'!$A$2," ",'Bundle Tag Info'!$A$3,CHAR(10),'Bundle Tag Info'!E$6,CHAR(10),'Bundle Tag Info'!E$20),"") | F15: =IF('Bundle Tag Info'!F$20<>"",CONCATENATE('Bundle Tag Info'!$A$1," ",CHAR(10),'Bundle Tag Info'!$A$2," ",'Bundle Tag Info'!$A$3,CHAR(10),'Bundle Tag Info'!F$6,CHAR(10),'Bundle Tag Info'!F$20),"") | G15: =IF('Bundle Tag Info'!G$20<>"",CONCATENATE('Bundle Tag Info'!$A$1," ",CHAR(10),'Bundle Tag Info'!$A$2," ",'Bundle Tag Info'!$A$3,CHAR(10),'Bundle Tag Info'!G$6,CHAR(10),'Bundle Tag Info'!G$20),"") | H15: =IF('Bundle Tag Info'!H$20<>"",CONCATENATE('Bundle Tag Info'!$A$1," ",CHAR(10),'Bundle Tag Info'!$A$2," ",'Bundle Tag Info'!$A$3,CHAR(10),'Bundle Tag Info'!H$6,CHAR(10),'Bundle Tag Info'!H$20),"") | ... AD15: =IF('Bundle Tag Info'!AD$20<>"",CONCATENATE('Bundle Tag Info'!$A$1," ",CHAR(10),'Bundle Tag Info'!$A$2," ",'Bundle Tag Info'!$A$3,CHAR(10),'Bundle Tag Info'!AD$6,CHAR(10),'Bundle Tag Info'!AD$20),"")
A16: =IF('Bundle Tag Info'!A$21<>"",CONCATENATE('Bundle Tag Info'!$A$1," ",CHAR(10),'Bundle Tag Info'!$A$2," ",'Bundle Tag Info'!$A$3,CHAR(10),'Bundle Tag Info'!A$6,CHAR(10),'Bundle Tag Info'!A$21),"") -> ENI-K #2 4M511 REV B JB70 SH0472 | B16: =IF('Bundle Tag Info'!B$21<>"",CONCATENATE('Bundle Tag Info'!$A$1," ",CHAR(10),'Bundle Tag Info'!$A$2," ",'Bundle Tag Info'!$A$3,CHAR(10),'Bundle Tag Info'!B$6,CHAR(10),'Bundle Tag Info'!B$21),"") | C16: =IF('Bundle Tag Info'!C$21<>"",CONCATENATE('Bundle Tag Info'!$A$1," ",CHAR(10),'Bundle Tag Info'!$A$2," ",'Bundle Tag Info'!$A$3,CHAR(10),'Bundle Tag Info'!C$6,CHAR(10),'Bundle Tag Info'!C$21),"") | D16: =IF('Bundle Tag Info'!D$21<>"",CONCATENATE('Bundle Tag Info'!$A$1," ",CHAR(10),'Bundle Tag Info'!$A$2," ",'Bundle Tag Info'!$A$3,CHAR(10),'Bundle Tag Info'!D$6,CHAR(10),'Bundle Tag Info'!D$21),"") | E16: =IF('Bundle Tag Info'!E$21<>"",CONCATENATE('Bundle Tag Info'!$A$1," ",CHAR(10),'Bundle Tag Info'!$A$2," ",'Bundle Tag Info'!$A$3,CHAR(10),'Bundle Tag Info'!E$6,CHAR(10),'Bundle Tag Info'!E$21),"") | F16: =IF('Bundle Tag Info'!F$21<>"",CONCATENATE('Bundle Tag Info'!$A$1," ",CHAR(10),'Bundle Tag Info'!$A$2," ",'Bundle Tag Info'!$A$3,CHAR(10),'Bundle Tag Info'!F$6,CHAR(10),'Bundle Tag Info'!F$21),"") | G16: =IF('Bundle Tag Info'!G$21<>"",CONCATENATE('Bundle Tag Info'!$A$1," ",CHAR(10),'Bundle Tag Info'!$A$2," ",'Bundle Tag Info'!$A$3,CHAR(10),'Bundle Tag Info'!G$6,CHAR(10),'Bundle Tag Info'!G$21),"") | H16: =IF('Bundle Tag Info'!H$21<>"",CONCATENATE('Bundle Tag Info'!$A$1," ",CHAR(10),'Bundle Tag Info'!$A$2," ",'Bundle Tag Info'!$A$3,CHAR(10),'Bundle Tag Info'!H$6,CHAR(10),'Bundle Tag Info'!H$21),"") | ... AD16: =IF('Bundle Tag Info'!AD$21<>"",CONCATENATE('Bundle Tag Info'!$A$1," ",CHAR(10),'Bundle Tag Info'!$A$2," ",'Bundle Tag Info'!$A$3,CHAR(10),'Bundle Tag Info'!AD$6,CHAR(10),'Bundle Tag Info'!AD$21),"")
A17: =IF('Bundle Tag Info'!A$22<>"",CONCATENATE('Bundle Tag Info'!$A$1," ",CHAR(10),'Bundle Tag Info'!$A$2," ",'Bundle Tag Info'!$A$3,CHAR(10),'Bundle Tag Info'!A$6,CHAR(10),'Bundle Tag Info'!A$22),"") | B17: =IF('Bundle Tag Info'!B$22<>"",CONCATENATE('Bundle Tag Info'!$A$1," ",CHAR(10),'Bundle Tag Info'!$A$2," ",'Bundle Tag Info'!$A$3,CHAR(10),'Bundle Tag Info'!B$6,CHAR(10),'Bundle Tag Info'!B$22),"") | C17: =IF('Bundle Tag Info'!C$22<>"",CONCATENATE('Bundle Tag Info'!$A$1," ",CHAR(10),'Bundle Tag Info'!$A$2," ",'Bundle Tag Info'!$A$3,CHAR(10),'Bundle Tag Info'!C$6,CHAR(10),'Bundle Tag Info'!C$22),"") | D17: =IF('Bundle Tag Info'!D$22<>"",CONCATENATE('Bundle Tag Info'!$A$1," ",CHAR(10),'Bundle Tag Info'!$A$2," ",'Bundle Tag Info'!$A$3,CHAR(10),'Bundle Tag Info'!D$6,CHAR(10),'Bundle Tag Info'!D$22),"") | E17: =IF('Bundle Tag Info'!E$22<>"",CONCATENATE('Bundle Tag Info'!$A$1," ",CHAR(10),'Bundle Tag Info'!$A$2," ",'Bundle Tag Info'!$A$3,CHAR(10),'Bundle Tag Info'!E$6,CHAR(10),'Bundle Tag Info'!E$22),"") | F17: =IF('Bundle Tag Info'!F$22<>"",CONCATENATE('Bundle Tag Info'!$A$1," ",CHAR(10),'Bundle Tag Info'!$A$2," ",'Bundle Tag Info'!$A$3,CHAR(10),'Bundle Tag Info'!F$6,CHAR(10),'Bundle Tag Info'!F$22),"") | G17: =IF('Bundle Tag Info'!G$22<>"",CONCATENATE('Bundle Tag Info'!$A$1," ",CHAR(10),'Bundle Tag Info'!$A$2," ",'Bundle Tag Info'!$A$3,CHAR(10),'Bundle Tag Info'!G$6,CHAR(10),'Bundle Tag Info'!G$22),"") | H17: =IF('Bundle Tag Info'!H$22<>"",CONCATENATE('Bundle Tag Info'!$A$1," ",CHAR(10),'Bundle Tag Info'!$A$2," ",'Bundle Tag Info'!$A$3,CHAR(10),'Bundle Tag Info'!H$6,CHAR(10),'Bundle Tag Info'!H$22),"") | ... AD17: =IF('Bundle Tag Info'!AD$22<>"",CONCATENATE('Bundle Tag Info'!$A$1," ",CHAR(10),'Bundle Tag Info'!$A$2," ",'Bundle Tag Info'!$A$3,CHAR(10),'Bundle Tag Info'!AD$6,CHAR(10),'Bundle Tag Info'!AD$22),"")
A18: =IF('Bundle Tag Info'!A$23<>"",CONCATENATE('Bundle Tag Info'!$A$1," ",CHAR(10),'Bundle Tag Info'!$A$2," ",'Bundle Tag Info'!$A$3,CHAR(10),'Bundle Tag Info'!A$6,CHAR(10),'Bundle Tag Info'!A$23),"") | B18: =IF('Bundle Tag Info'!B$23<>"",CONCATENATE('Bundle Tag Info'!$A$1," ",CHAR(10),'Bundle Tag Info'!$A$2," ",'Bundle Tag Info'!$A$3,CHAR(10),'Bundle Tag Info'!B$6,CHAR(10),'Bundle Tag Info'!B$23),"") | C18: =IF('Bundle Tag Info'!C$23<>"",CONCATENATE('Bundle Tag Info'!$A$1," ",CHAR(10),'Bundle Tag Info'!$A$2," ",'Bundle Tag Info'!$A$3,CHAR(10),'Bundle Tag Info'!C$6,CHAR(10),'Bundle Tag Info'!C$23),"") | D18: =IF('Bundle Tag Info'!D$23<>"",CONCATENATE('Bundle Tag Info'!$A$1," ",CHAR(10),'Bundle Tag Info'!$A$2," ",'Bundle Tag Info'!$A$3,CHAR(10),'Bundle Tag Info'!D$6,CHAR(10),'Bundle Tag Info'!D$23),"") | E18: =IF('Bundle Tag Info'!E$23<>"",CONCATENATE('Bundle Tag Info'!$A$1," ",CHAR(10),'Bundle Tag Info'!$A$2," ",'Bundle Tag Info'!$A$3,CHAR(10),'Bundle Tag Info'!E$6,CHAR(10),'Bundle Tag Info'!E$23),"") | F18: =IF('Bundle Tag Info'!F$23<>"",CONCATENATE('Bundle Tag Info'!$A$1," ",CHAR(10),'Bundle Tag Info'!$A$2," ",'Bundle Tag Info'!$A$3,CHAR(10),'Bundle Tag Info'!F$6,CHAR(10),'Bundle Tag Info'!F$23),"") | G18: =IF('Bundle Tag Info'!G$23<>"",CONCATENATE('Bundle Tag Info'!$A$1," ",CHAR(10),'Bundle Tag Info'!$A$2," ",'Bundle Tag Info'!$A$3,CHAR(10),'Bundle Tag Info'!G$6,CHAR(10),'Bundle Tag Info'!G$23),"") | H18: =IF('Bundle Tag Info'!H$23<>"",CONCATENATE('Bundle Tag Info'!$A$1," ",CHAR(10),'Bundle Tag Info'!$A$2," ",'Bundle Tag Info'!$A$3,CHAR(10),'Bundle Tag Info'!H$6,CHAR(10),'Bundle Tag Info'!H$23),"") | ... AD18: =IF('Bundle Tag Info'!AD$23<>"",CONCATENATE('Bundle Tag Info'!$A$1," ",CHAR(10),'Bundle Tag Info'!$A$2," ",'Bundle Tag Info'!$A$3,CHAR(10),'Bundle Tag Info'!AD$6,CHAR(10),'Bundle Tag Info'!AD$23),"")
