Workbook

Sheet JB70 DOOR_S
A1: CONTROL,JB70;TT6
A2: DOOR
A3: Project # | B3: 4M082
A4: Project Name | B4: STEEL REEF BURKE LLC
A5: Revision | B5: C
A7: Controls DE | B7: J. UNGER
A8: Phone:
A9: Controls ME
A10: Phone:
A12: From | G12: To
A13: Device ID | B13: Wire No. | C13: Wire ID | D13: Gauge/Size | E13: Length | F13: Device ID | G13: Location | H13: Bundle Name
A14: AT1100:NEG | B14: -0V | C14: WHT | D14: 14 | E14: 180 | F14: XT0111:22 | G14: JB70 RIGHT RAIL | H14: AT1100
A16: AT1100:POS | B16: FU1100 | C16: WHT | D16: 14 | E16: 200 | F16: FU1100:LD | G16: B
A18: SA0471:B1-13 | B18: SA0471B113 | C18: WHT | D18: 20 | E18: 240 | F18: AF0087:40 | G18: A | H18: SA0471
A19: SA0471:B1-14 | B19: SA0471B114 | C19: WHT | D19: 20 | E19: 240 | F19: AF0087:08 | G19: A
A20: SA0471:B2-13 | B20: SA0471B213 | C20: WHT | D20: 20 | E20: 240 | F20: AF0087:39 | G20: A
A21: SA0471:B2-14 | B21: SA0471B214 | C21: WHT | D21: 20 | E21: 240 | F21: AF0087:07 | G21: A
A23: SA0472:B1-13 | B23: SA0472B113 | C23: WHT | D23: 20 | E23: 240 | F23: AF0091:47 | G23: A | H23: SA0472
A24: SA0472:B1-14 | B24: SA0472B114 | C24: WHT | D24: 20 | E24: 240 | F24: AF0091:15 | G24: A
A25: SA0472:B2-13 | B25: SA0472B213 | C25: WHT | D25: 20 | E25: 240 | F25: AF0091:46 | G25: A
A26: SA0472:B2-14 | B26: SA0472B214 | C26: WHT | D26: 20 | E26: 240 | F26: AF0091:14 | G26: A
A28: SA0473:11 | B28: SA047311 | C28: WHT | D28: 20 | E28: 240 | F28: AF0087:37 | G28: A | H28: SA0473
A29: SA0473:12 | B29: SA047312 | C29: WHT | D29: 20 | E29: 240 | F29: AF0087:05 | G29: A
A30: SA0473:13 | B30: SA047313 | C30: WHT | D30: 20 | E30: 240 | F30: AF0087:38 | G30: A
A31: SA0473:14 | B31: SA047314 | C31: WHT | D31: 20 | E31: 240 | F31: AF0087:06 | G31: A
A33: SB0471:11 | B33: SB047111 | C33: WHT | D33: 20 | E33: 240 | F33: AF0087:34 | G33: A | H33: SB0471
A34: SB0471:12 | B34: SB047112 | C34: WHT | D34: 20 | E34: 240 | F34: AF0087:02 | G34: A
A36: SB0472:B1-12 | B36: ESTOPA | C36: WHT | D36: 20 | E36: 180 | F36: XT0111:20 | G36: JB70 RIGHT RAIL | H36: SB0472
A37: SB0472:B1-11 | B37: ESTOPB | C37: WHT | D37: 20 | E37: 180 | F37: XT0111:19 | G37: JB70 RIGHT RAIL
A39: SB0472:B2-11 | B39: SB0472B211 | C39: WHT | D39: 20 | E39: 240 | F39: AF0081:36 | G39: A
A40: SB0472:B2-12 | B40: SB0472B212 | C40: WHT | D40: 20 | E40: 240 | F40: AF0081:04 | G40: A
A42: SB0473:13 | B42: SB047313 | C42: WHT | D42: 20 | E42: 240 | F42: AF0087:35 | G42: A | H42: SB0473
A43: SB0473:14 | B43: SB047314 | C43: WHT | D43: 20 | E43: 240 | F43: AF0087:03 | G43: A
A45: SB0474:13 | B45: SB047413 | C45: WHT | D45: 20 | E45: 240 | F45: AF0087:36 | G45: A | H45: SB0474
A46: SB0474:14 | B46: SB047414 | C46: WHT | D46: 20 | E46: 240 | F46: AF0087:04 | G46: A
A48: SH0470:11 | B48: SH047011 | C48: WHT | D48: 20 | E48: 180 | F48: XT0111:7 | G48: JB70 RIGHT RAIL | H48: SH0470
A49: SH0470:12 | B49: SH047012 | C49: WHT | D49: 20 | E49: 180 | F49: XT0111:8 | G49: JB70 RIGHT RAIL
A50: SH0470:13 | B50: SH047013 | C50: WHT | D50: 20 | E50: 180 | F50: XT0111:9 | G50: JB70 RIGHT RAIL
A51: SH0470:14 | B51: SH047014 | C51: WHT | D51: 20 | E51: 180 | F51: XT0111:10 | G51: JB70 RIGHT RAIL
A52: SH0470:X1 | B52: SH0470X1 | C52: WHT | D52: 20 | E52: 180 | F52: XT0111:12 | G52: JB70 RIGHT RAIL
...

Sheet JB70 R RAIL_S
A1: JB70 RIGHT RAIL
A3: Project # | B3: 4M082
A4: Project Name | B4: STEEL REEF BURKE LLC
A5: Revision | B5: C
A7: Controls DE | B7: J. UNGER
A8: Phone:
A9: Controls ME
A10: Phone:
A12: From | G12: To
A13: Device ID | B13: Wire No. | C13: Wire ID | D13: Gauge/Size | E13: Length | F13: Device ID | G13: Location | H13: Bundle Name
A14: XT0111:20 | B14: ESTOPA | C14: WHT | D14: 20 | E14: 200 | F14: XT0089:4 | G14: A | H14: XT
A15: XT0111:19 | B15: ESTOPB | C15: WHT | D15: 20 | E15: 200 | F15: XT0089:3 | G15: A
A16: XT0111:15 | B16: FU0139 | C16: WHT | D16: 20 | E16: 200 | F16: XT0081:6 | G16: A
A17: XT0111:24 | B17: HA047201 | C17: WHT | D17: 20 | E17: 200 | F17: AF0092:28 | G17: A
A18: XT0111:23 | B18: HA047202 | C18: WHT | D18: 20 | E18: 200 | F18: AF0092:12 | G18: A
A19: XT0111:16 | B19: KA0241A1 | C19: WHT | D19: 20 | E19: 200 | F19: XT0081:7 | G19: A
A20: XT0111:7 | B20: SH047011 | C20: WHT | D20: 20 | E20: 200 | F20: AF0087:33 | G20: A
A21: XT0111:8 | B21: SH047012 | C21: WHT | D21: 20 | E21: 200 | F21: AF0087:01 | G21: A
A22: XT0111:12 | B22: SH0470X1 | C22: WHT | D22: 20 | E22: 200 | F22: AF0093:22 | G22: A
A23: XT0111:11 | B23: SH0470X2 | C23: WHT | D23: 20 | E23: 200 | F23: AF0093:06 | G23: A
A24: XT0111:3 | B24: SH047113 | C24: WHT | D24: 20 | E24: 200 | F24: AF0087:32 | G24: A
A25: XT0111:4 | B25: SH047114 | C25: WHT | D25: 20 | E25: 200 | F25: AF0087:00 | G25: A
A26: XT0111:6 | B26: SH0471X1 | C26: WHT | D26: 20 | E26: 200 | F26: AF0093:31 | G26: A
... A33: XT0111:21 | B33: FU0136 | C33: WHT | D33: 14 | E33: 200 | F33: XT0002:6 | G33: A
A35: XT0111:21 | B35: FU0136 | C35: WHT | D35: 16 | E35: 180 | F35: FU0291:LI | G35: B | H35: XT-B
A36: XT0111:21 | B36: FU0136 | C36: WHT | D36: 16 | E36: 180 | F36: FU1100:LI | G36: B
A38: XT0111:22 | B38: -0V | C38: WHT | D38: 14 | E38: 180 | F38: UV0291:24V(-) | G38: B

Sheet PLC_S
A1: JB70 PLC PANEL
A3: Project # | B3: 4M082
A4: Project Name | B4: STEEL REEF BURKE LLC
A5: Revision | B5: C
A7: Controls DE | B7: J. UNGER
A8: Phone:
A9: Controls ME
A10: Phone:
A12: From | G12: To
A13: Device ID | B13: Wire No. | C13: Wire ID | D13: Gauge/Size | E13: Length | F13: Device ID | G13: Location | H13: Bundle Name
A14: BA0001:V1(+) | B14: FU0021 | C14: WHT | D14: 16 | E14: 60 | F14: FU0021:LD | G14: PLC | H14: BA
A15: BA0002:V1(+) | B15: FU0022 | C15: WHT | D15: 16 | E15: 60 | F15: FU0022:LD | G15: PLC
A17: AT0680:NEG | B17: -0V | C17: WHT | D17: 14 | E17: 60 | F17: XT0680:2 | G17: PLC | H17: AT
A18: AT0680:POS | B18: AT0680POS | C18: WHT | D18: 14 | E18: 60 | F18: XT0680:1 | G18: PLC
A20: FU0010:LD | B20: FU0010 | C20: WHT | D20: 14 | E20: 60 | F20: UV0600:(+) | G20: PLC | H20: FU
A21: FU0680:LD | B21: AT0680POS | C21: WHT | D21: 14 | E21: 60 | F21: XT0680:1 | G21: PLC
A23: UV0600:(-) | B23: -0V | C23: WHT | D23: 14 | E23: 80 | F23: XT0003:4 | G23: A | H23: FU/UV-A
A24: FU0010:LI | B24: FU0136 | C24: WHT | D24: 14 | E24: 80 | F24: XT0002:4 | G24: A
A26: BA0001:V1(-) | B26: -0V | C26: WHT | D26: 16 | E26: 80 | F26: XT0051:5 | G26: B | H26: BA-B
A27: BA0002:V1(-) | B27: -0V | C27: WHT | D27: 16 | E27: 80 | F27: XT0051:6 | G27: B
A29: FU0021:LI | B29: FU0136 | C29: WHT | D29: 16 | E29: 80 | F29: XT0051:1 | G29: B | H29: FU/XT-B
A30: FU0022:LI | B30: FU0136 | C30: WHT | D30: 16 | E30: 80 | F30: XT0051:2 | G30: B
A31: FU0680:LI | B31: FU0136 | C31: WHT | D31: 16 | E31: 80 | F31: XT0051:4 | G31: B
A33: XT0680:2 | B33: -0V | C33: WHT | D33: 14 | E33: 80 | F33: XT0051:8 | G33: B

Sheet A_S
A1: JB70 PANEL A
A3: Project # | B3: 4M082
A4: Project Name | B4: STEEL REEF BURKE LLC
A5: Revision | B5: C
A7: Controls DE | B7: J. UNGER
A8: Phone:
A9: Controls ME
A10: Phone:
A12: From | G12: To
A13: Device ID | B13: Wire No. | C13: Wire ID | D13: Gauge/Size | E13: Length | F13: Device ID | G13: Location | H13: Bundle Name
A14: AF0086:12 | B14: FT21082 | C14: WHT | D14: 20 | E14: 60 | F14: XT0050:2 | G14: A | H14: AF/AU080s
A15: AF0081:00 | B15: UA1200J21 | C15: WHT | D15: 20 | E15: 80 | F15: XT0089:20 | G15: A
A17: AF0086:28 | B17: -0V | C17: WHT | D17: 16 | E17: 60 | F17: XT0050:3 | G17: A
A18: AU0080:COM | B18: -0V | C18: WHT | D18: 16 | E18: 60 | F18: XT0080:1 | G18: A
A19: AF0083:COM | B19: AF0083N | C19: WHT | D19: 16 | E19: 60 | F19: AF0084:COM | G19: A
A20: AF0083:V+ | B20: AF0083P | C20: WHT | D20: 16 | E20: 60 | F20: AF0084:V+ | G20: A
A21: AF0086:60 | B21: FT2108S | C21: WHT | D21: 16 | E21: 60 | F21: XT0050:4 | G21: A
A22: AU0080:V+ | B22: FU0081 | C22: WHT | D22: 16 | E22: 60 | F22: FU0081:LD | G22: A
A24: AF0094:05 | B24: -0V | C24: WHT | D24: 20 | E24: 80 | F24: XT0082:5 | G24: A | H24: AF/AU090s
A25: AF0094:07 | B25: -0V | C25: WHT | D25: 20 | E25: 80 | F25: XT0082:5 | G25: A
A27: AF0092:COM | B27: -0V | C27: WHT | D27: 16 | E27: 80 | F27: XT0080:2 | G27: A
A28: AF0093:COM | B28: -0V | C28: WHT | D28: 16 | E28: 80 | F28: XT0080:3 | G28: A
A29: AF0095:COM | B29: -0V | C29: WHT | D29: 16 | E29: 80 | F29: XT0080:4 | G29: A
A30: AU0090:COM | B30: -0V | C30: WHT | D30: 16 | E30: 60 | F30: XT0080:2 | G30: A
A31: AF0091:COM | B31: AF0091N | C31: WHT | D31: 16 | E31: 60 | F31: AF0094:COM | G31: A
A32: AF0091:V+ | B32: AF0091P | C32: WHT | D32: 16 | E32: 60 | F32: AF0094:V+ | G32: A
A33: AU0090:V+ | B33: FU0090 | C33: WHT | D33: 16 | E33: 60 | F33: FU0090:LD | G33: A
A34: AF0092:V+ | B34: FU0091 | C34: WHT | D34: 16 | E34: 60 | F34: FU0091:LD | G34: A
A35: AF0093:V+ | B35: FU0092 | C35: WHT | D35: 16 | E35: 60 | F35: FU0092:LD | G35: A
A36: AF0095:V+ | B36: FU0093 | C36: WHT | D36: 16 | E36: 60 | F36: FU0093:LD | G36: A
A38: FU0139:LD | B38: FU0139 | C38: WHT | D38: 16 | E38: 60 | F38: XT0081:1 | G38: A | H38: FU
A39: FU0387:LD | B39: FU0387 | C39: WHT | D39: 16 | E39: 60 | F39: XT0089:17 | G39: A
A40: FU0389:LD | B40: FU0389 | C40: WHT | D40: 16 | E40: 60 | F40: XT0089:21 | G40: A
A42: FU0081:LI | B42: FU0080 | C42: WHT | D42: 14 | E42: 60 | F42: FU0080:LD | G42: A
A43: FU0081:LI | B43: FU0080 | C43: WHT | D43: 14 | E43: 60 | F43: FU0090:LI | G43: A
A45: FU0137:LI | B45: FU0136 | C45: WHT | D45: 12 | E45: 80 | F45: XT0002:2 | G45: A
A46: FU0080:LI | B46: FU0137 | C46: WHT | D46: 12 | E46: 60 | F46: FU0137:LD | G46: A
A47: FU0080:LI | B47: FU0137 | C47: WHT | D47: 12 | E47: 60 | F47: FU0139:LI | G47: A
A49: KA3330:A1 | B49: -009201 | C49: WHT | D49: 20 | E49: 60 | F49: AF0092:01 | G49: A | H49: KA A1
A50: KA3331:A1 | B50: -009203 | C50: WHT | D50: 20 | E50: 60 | F50: AF0092:03 | G50: A
...

Sheet B_S
A1: JB70 PANEL B
A3: Project # | B3: 4M082
A4: Project Name | B4: STEEL REEF BURKE LLC
A5: Revision | B5: C
A7: Controls DE | B7: J. UNGER
A8: Phone:
A9: Controls ME
A10: Phone:
A12: From | G12: To
A13: Device ID | B13: Wire No. | C13: Wire ID | D13: Gauge/Size | E13: Length | F13: Device ID | G13: Location | H13: Bundle Name
A14: AF0061:COM | B14: -0V | C14: WHT | D14: 16 | E14: 100 | F14: XT0060:2 | G14: B | H14: AF/AU060s
A15: AF0062:COM | B15: -0V | C15: WHT | D15: 16 | E15: 100 | F15: XT0060:3 | G15: B
A16: AF0067:COM | B16: -0V | C16: WHT | D16: 16 | E16: 80 | F16: XT0060:3 | G16: B
A17: AU0060:COM | B17: -0V | C17: WHT | D17: 16 | E17: 100 | F17: XT0060:2 | G17: B
A18: AF0066:COM | B18: AF0066N | C18: WHT | D18: 16 | E18: 60 | F18: AF0068:COM | G18: B
A19: AF0066:V+ | B19: AF0066P | C19: WHT | D19: 16 | E19: 60 | F19: AF0068:V+ | G19: B
A20: AF0063:COM | B20: AU0060N | C20: WHT | D20: 16 | E20: 60 | F20: AU0060:COM | G20: B
A21: AF0063:V+ | B21: AU0060P | C21: WHT | D21: 16 | E21: 60 | F21: AU0060:V+ | G21: B
A22: AU0060:V+ | B22: FU0061 | C22: WHT | D22: 16 | E22: 80 | F22: FU0061:LD | G22: B
A23: AF0061:V+ | B23: FU0062 | C23: WHT | D23: 16 | E23: 80 | F23: FU0062:LD | G23: B
A24: AF0062:V+ | B24: FU0063 | C24: WHT | D24: 16 | E24: 80 | F24: FU0063:LD | G24: B
A25: AF0067:V+ | B25: FU0064 | C25: WHT | D25: 16 | E25: 60 | F25: FU0064:LD | G25: B
A27: AF0076:COM | B27: -0V | C27: WHT | D27: 16 | E27: 80 | F27: XT0060:4 | G27: B | H27: AF/AU070s
A28: AU0070:COM | B28: -0V | C28: WHT | D28: 16 | E28: 60 | F28: XT0060:4 | G28: B
A29: AU0070:V+ | B29: FU0070 | C29: WHT | D29: 16 | E29: 60 | F29: FU0070:LD | G29: B
A30: AF0076:V+ | B30: FU0076 | C30: WHT | D30: 16 | E30: 80 | F30: FU0076:LD | G30: B
A32: AF0410:53 | B32: -0V | C32: WHT | D32: 16 | E32: 60 | F32: XT0401:2 | G32: B | H32: 1444s
A33: AF0410:54 | B33: -0V | C33: WHT | D33: 16 | E33: 60 | F33: AF0420:53 | G33: B
A34: AF0420:54 | B34: -0V | C34: WHT | D34: 16 | E34: 60 | F34: AF0450:53 | G34: B
A35: AF0410:55 | B35: FU0410 | C35: WHT | D35: 16 | E35: 60 | F35: FU0410:LD | G35: B
A36: AF0410:56 | B36: FU0410 | C36: WHT | D36: 16 | E36: 60 | F36: AF0420:55 | G36: B
A37: AF0420:56 | B37: FU0410 | C37: WHT | D37: 16 | E37: 60 | F37: AF0450:55 | G37: B
A39: BA0003:V1(-) | B39: -0V | C39: WHT | D39: 16 | E39: 60 | F39: XT0051:7 | G39: B | H39: BA
A40: BA0011:V1(-) | B40: -0V | C40: WHT | D40: 16 | E40: 60 | F40: XT0051:7 | G40: B
A41: BA1100:NEG | B41: BA1100N | C41: WHT | D41: 16 | E41: 60 | F41: UV0291:OUT1(-) | G41: B
A42: BA0003:V1(+) | B42: FU0023 | C42: WHT | D42: 16 | E42: 60 | F42: FU0023:LD | G42: B
A43: BA0011:V1(+) | B43: FU0031 | C43: WHT | D43: 16 | E43: 60 | F43: FU0031:LD | G43: B
A44: BA1100:POS | B44: FU1101LD | C44: WHT | D44: 16 | E44: 60 | F44: FU1101:LD | G44: B
A46: FU0031:LI | B46: FU0136 | C46: WHT | D46: 16 | E46: 60 | F46: XT0051:3 | G46: B | H46: FU
A47: FU0291:LD | B47: FU0291LD | C47: WHT | D47: 16 | E47: 60 | F47: UV0291:24V(+) | G47: B
...

Sheet JB72 L RAIL_S
A1: JB72 LEFT RAIL
A3: Project # | B3: 4M082
A4: Project Name | B4: STEEL REEF BURKE LLC
A5: Revision | B5: C
A7: Controls DE | B7: J. UNGER
A8: Phone:
A9: Controls ME
A10: Phone:
A12: From | G12: To
A13: Device ID | B13: Wire No. | C13: Wire ID | D13: Gauge/Size | E13: Length | F13: Device ID | G13: Location | H13: Bundle Name
A14: AF0181:26 | B14: -018126 | C14: WHT | D14: 20 | E14: 60 | F14: XT0181:2 | G14: JB72 L RAIL | H14: AF/AU180s
A16: AF0181:COM | B16: -0V | C16: WHT | D16: 16 | E16: 60 | F16: XT0180:1 | G16: JB72 L RAIL
A17: AU0180:COM | B17: -0V | C17: WHT | D17: 16 | E17: 60 | F17: XT0180:1 | G17: JB72 L RAIL
A18: AF0182:COM | B18: AU0180N | C18: WHT | D18: 16 | E18: 60 | F18: AU0180:COM | G18: JB72 L RAIL
A19: AF0182:V+ | B19: AU0180P | C19: WHT | D19: 16 | E19: 60 | F19: AU0180:V+ | G19: JB72 L RAIL
A20: AU0180:V+ | B20: FU0180 | C20: WHT | D20: 16 | E20: 60 | F20: FU0180:LD | G20: JB72 L RAIL
A21: AF0181:V+ | B21: FU0181 | C21: WHT | D21: 16 | E21: 60 | F21: FU0181:LD | G21: JB72 L RAIL
A23: BA0120:V1(-) | B23: -0V | C23: WHT | D23: 16 | E23: 60 | F23: XT1207:2 | G23: JB72 L RAIL | H23: BA
A24: BA0121:V1(-) | B24: -0V | C24: WHT | D24: 16 | E24: 60 | F24: XT1207:2 | G24: JB72 L RAIL
A25: BA0120:V1(+) | B25: FU0133LD | C25: WHT | D25: 16 | E25: 60 | F25: FU0133:LD | G25: JB72 L RAIL
A26: BA0121:V1(+) | B26: FU0134LD | C26: WHT | D26: 16 | E26: 60 | F26: FU0134:LD | G26: JB72 L RAIL
A28: FU0133:LI | B28: FU0332 | C28: WHT | D28: 16 | E28: 120 | F28: XT1207:1 | G28: JB72 L RAIL | H28: FU
A29: FU0134:LI | B29: FU0332 | C29: WHT | D29: 16 | E29: 120 | F29: XT1207:1 | G29: JB72 L RAIL
A31: FU0180:LI | B31: FU0182 | C31: WHT | D31: 14 | E31: 120 | F31: FU0182:LD | G31: JB72 L RAIL
A33: KA0180:A1 | B33: -018100 | C33: WHT | D33: 20 | E33: 120 | F33: AF0181:00 | G33: JB72 L RAIL | H33: KA A1/A2
A34: KA0185:A1 | B34: -018110 | C34: WHT | D34: 20 | E34: 120 | F34: AF0181:10 | G34: JB72 L RAIL
A35: KA0181:A1 | B35: KA0181A1 | C35: WHT | D35: 20 | E35: 120 | F35: AF0181:02 | G35: JB72 L RAIL
A37: KA0180:A2 | B37: -018116 | C37: WHT | D37: 20 | E37: 120 | F37: AF0181:16 | G37: JB72 L RAIL
A38: KA0181:A2 | B38: KA0181A2 | C38: WHT | D38: 20 | E38: 120 | F38: AF0181:18 | G38: JB72 L RAIL
A39: KA0185:A2 | B39: KA0185A2 | C39: WHT | D39: 20 | E39: 120 | F39: XT0181:1 | G39: JB72 L RAIL
A41: KA0185:11 | B41: KA018511 | C41: WHT | D41: 20 | E41: 200 | F41: XT0338:3 | G41: GEN | H41: KA-GEN
A42: KA0185:14 | B42: KA0332A1 | C42: WHT | D42: 20 | E42: 200 | F42: XT0338:4 | G42: GEN
A44: XT0180:1 | B44: -0V | C44: WHT | D44: 14 | E44: 200 | F44: XT0336:3 | G44: GEN | H44: FU/XT-GEN
A45: XT1207:2 | B45: -0V | C45: WHT | D45: 14 | E45: 200 | F45: XT0336:8 | G45: GEN
A46: FU0182:LI | B46: FU0332 | C46: WHT | D46: 14 | E46: 200 | F46: XT0335:3 | G46: GEN
A48: XT1207:1 | B48: FU0332 | C48: WHT | D48: 12 | E48: 200 | F48: XT0335:8 | G48: GEN

Sheet JB72 VIB_S
A1: JB72 VIB PANEL
A3: Project # | B3: 4M082
A4: Project Name | B4: STEEL REEF BURKE LLC
A5: Revision | B5: C
A7: Controls DE | B7: J. UNGER
A8: Phone:
A9: Controls ME
A10: Phone:
A12: From | G12: To
A13: Device ID | B13: Wire No. | C13: Wire ID | D13: Gauge/Size | E13: Length | F13: Device ID | G13: Location | H13: Bundle Name
A14: AF0510:53 | B14: -0V | C14: WHT | D14: 16 | E14: 60 | F14: XT0501:2 | G14: JB72 VIB | H14: 1444s
A15: AF0510:55 | B15: FU0510 | C15: WHT | D15: 16 | E15: 60 | F15: FU0510:LD | G15: JB72 VIB
A17: XT0501:1 | B17: -0V | C17: WHT | D17: 14 | E17: 120 | F17: XT0336:3 | G17: GEN | H17: FU/XT-GEN
A18: FU0510:LI | B18: FU0332 | C18: WHT | D18: 14 | E18: 120 | F18: XT0335:3 | G18: GEN

Sheet JB72 GEN_S
A1: JB72 GEN PANEL
A3: Project # | B3: 4M082
A4: Project Name | B4: STEEL REEF BURKE LLC
A5: Revision | B5: C
A7: Controls DE | B7: J. UNGER
A8: Phone:
A9: Controls ME
A10: Phone:
A12: From | G12: To
A13: Device ID | B13: Wire No. | C13: Wire ID | D13: Gauge/Size | E13: Length | F13: Device ID | G13: Location | H13: Bundle Name
A14: AF0121:COM | B14: -0V | C14: WHT | D14: 16 | E14: 60 | F14: XT0120:2 | G14: GEN | H14: AF/AU120s
A15: AU0120:COM | B15: -0V | C15: WHT | D15: 16 | E15: 60 | F15: XT0120:2 | G15: GEN
A16: AF0122:COM | B16: AU0120N | C16: WHT | D16: 16 | E16: 60 | F16: AU0120:COM | G16: GEN
A17: AF0122:V+ | B17: AU0120P | C17: WHT | D17: 16 | E17: 60 | F17: AU0120:V+ | G17: GEN
A18: AU0120:V+ | B18: FU0120 | C18: WHT | D18: 16 | E18: 80 | F18: FU0120:LD | G18: GEN
A19: AF0121:V+ | B19: FU0121 | C19: WHT | D19: 16 | E19: 80 | F19: FU0121:LD | G19: GEN
A21: AT0140:FLT 29 | B21: KA0310A2 | C21: WHT | D21: 20 | E21: 60 | F21: KA0310:A2 | G21: GEN | H21: AT
A23: AT0140:3 EX-D(-) | B23: -0V | C23: WHT | D23: 16 | E23: 60 | F23: XT0336:6 | G23: GEN
A24: AT0140:BAT(-) 48 | B24: -0V | C24: WHT | D24: 16 | E24: 60 | F24: XT0336:6 | G24: GEN
A25: AT0140:FLT 30 | B25: -0V | C25: WHT | D25: 16 | E25: 60 | F25: XT0336:6 | G25: GEN
A26: AT0140:BAT(+) 47 | B26: FU0334 | C26: WHT | D26: 16 | E26: 60 | F26: XT0339:1 | G26: GEN
A27: AT0140:4 EX-D(+) | B27: KA012314 | C27: WHT | D27: 16 | E27: 60 | F27: KA0123:14 | G27: GEN
A29: AT0140:17 VBUS-A | B29: VBUSA | C29: RED | D29: 16R | E29: 120 | F29: XT0351:2 | G29: GEN | H29: AT RED
A30: AT0140:18 VBUS-B | B30: VBUSB | C30: RED | D30: 16R | E30: 120 | F30: XT0351:3 | G30: GEN
A31: AT0140:19 VBUS-C | B31: VBUSC | C31: RED | D31: 16R | E31: 120 | F31: XT0351:5 | G31: GEN
A32: AT0140:13 VGEN-A | B32: VGENA | C32: RED | D32: 16R | E32: 120 | F32: XT0351:9 | G32: GEN
A33: AT0140:14 VGEN-B | B33: VGENB | C33: RED | D33: 16R | E33: 120 | F33: XT0351:11 | G33: GEN
A34: AT0140:15 VGEN-C | B34: VGENC | C34: RED | D34: 16R | E34: 120 | F34: XT0351:13 | G34: GEN
A36: AT0140:36 I1(+) | B36: MCTA | C36: BLU | D36: 12B | E36: 120 | F36: XT0352:1 | G36: GEN | H36: AT BLU
A37: AT0140:37 I1(-) | B37: MCTAN | C37: BLU | D37: 12B | E37: 120 | F37: XT0352:10 | G37: GEN
A38: AT0140:38 I2(+) | B38: MCTB | C38: BLU | D38: 12B | E38: 120 | F38: XT0352:2 | G38: GEN
A39: AT0140:39 I2(-) | B39: MCTBN | C39: BLU | D39: 12B | E39: 120 | F39: XT0352:9 | G39: GEN
A40: AT0140:40 I3(+) | B40: MCTC | C40: BLU | D40: 12B | E40: 120 | F40: XT0352:3 | G40: GEN
A41: AT0140:41 I3(-) | B41: MCTCN | C41: BLU | D41: 12B | E41: 120 | F41: XT0352:8 | G41: GEN
A43: KA0121:A1 | B43: -012101 | C43: WHT | D43: 20 | E43: 60 | F43: AF0121:01 | G43: GEN | H43: KA A1
A44: KA0128:A1 | B44: -012108 | C44: WHT | D44: 20 | E44: 60 | F44: AF0121:08 | G44: GEN
A45: KA0310:A1 | B45: FU0334 | C45: WHT | D45: 20 | E45: 60 | F45: XT0339:1 | G45: GEN
A46: KA0123:A1 | B46: KA0123A1 | C46: WHT | D46: 20 | E46: 80 | F46: AF0121:03 | G46: GEN
A47: KA0123:A1 | B47: KA0123A1 | C47: WHT | D47: 20 | E47: 80 | F47: KA0313:2 | G47: GEN
A48: KA0330:A1 | B48: KA0330A1 | C48: WHT | D48: 20 | E48: 60 | F48: XT0338:5 | G48: GEN
...

Sheet JB1123_S
A1: JB1123 FO PANEL
A3: Project # | B3: 4M082
A4: Project Name | B4: STEEL REEF BURKE LLC
A5: Revision | B5: C
A7: Controls DE | B7: J. UNGER
A8: Phone:
A9: Controls ME
A10: Phone:
A12: From | G12: To
A13: Device ID | B13: Wire No. | C13: Wire ID | D13: Gauge/Size | E13: Length | F13: Device ID | G13: Location | H13: Bundle Name
A14: BA0005:V1(-) | B14: -0V | C14: WHT | D14: 16 | E14: 60 | F14: XT1123:2 | G14: JB1123 | H14: FU/BA
A15: BA0006:V1(-) | B15: -0V | C15: WHT | D15: 16 | E15: 60 | F15: XT1123:2 | G15: JB1123
A16: BA0005:V1(+) | B16: FU1123 | C16: WHT | D16: 16 | E16: 60 | F16: FU1123:LD | G16: JB1123
A17: BA0006:V1(+) | B17: FU1124 | C17: WHT | D17: 16 | E17: 60 | F17: FU1124:LD | G17: JB1123
A19: FU1123:LI | B19: FU0136 | C19: WHT | D19: 16 | E19: 60 | F19: XT1123:1 | G19: JB1123
A20: FU1124:LI | B20: FU0136 | C20: WHT | D20: 16 | E20: 60 | F20: XT1123:1 | G20: JB1123

Sheet MCC RAIL_S
A1: MCC RAIL
A3: Project # | B3: 4M082
A4: Project Name | B4: STEEL REEF BURKE LLC
A5: Revision | B5: C
A7: Controls DE | B7: J. UNGER
A8: Phone:
A9: Controls ME
A10: Phone:
A12: From | G12: To
A13: Device ID | B13: Wire No. | C13: Wire ID | D13: Gauge/Size | E13: Length | F13: Device ID | G13: Location | H13: Bundle Name
A14: AF0112:V+ | B14: FU0111 | C14: WHT | D14: 16 | E14: 100 | F14: FU0111:LD | G14: MCC RAIL | H14: AF/AU110s
A16: AF0112:COM | B16: -0V | C16: WHT | D16: 14 | E16: 100 | F16: XT0100:2 | G16: MCC RAIL
A17: AU0110:V+ | B17: FU0110 | C17: WHT | D17: 14 | E17: 100 | F17: FU0110:LD | G17: MCC RAIL
A19: BA0110:V1(-) | B19: -0V | C19: WHT | D19: 16 | E19: 60 | F19: XT1124:4 | G19: MCC RAIL | H19: BA
A20: BA0111:V1(-) | B20: -0V | C20: WHT | D20: 16 | E20: 60 | F20: XT1124:5 | G20: MCC RAIL
A21: BA0112:V1(-) | B21: -0V | C21: WHT | D21: 16 | E21: 60 | F21: XT1124:8 | G21: MCC RAIL
A22: BA0110:V1(+) | B22: FU1110 | C22: WHT | D22: 16 | E22: 60 | F22: FU1110:LD | G22: MCC RAIL
A23: BA0111:V1(+) | B23: FU1111 | C23: WHT | D23: 16 | E23: 60 | F23: FU1111:LD | G23: MCC RAIL
A24: BA0112:V1(+) | B24: FU1112 | C24: WHT | D24: 16 | E24: 60 | F24: FU1112:LD | G24: MCC RAIL
A26: KA7000:A1 | B26: -011100 | C26: WHT | D26: 20 | E26: 60 | F26: AF0111:00 | G26: MCC RAIL | H26: KA A1
A27: KA7001:A1 | B27: -011101 | C27: WHT | D27: 20 | E27: 60 | F27: AF0111:01 | G27: MCC RAIL
A28: KA7002:A1 | B28: -011102 | C28: WHT | D28: 20 | E28: 60 | F28: AF0111:02 | G28: MCC RAIL
A29: KA7003:A1 | B29: -011103 | C29: WHT | D29: 20 | E29: 60 | F29: AF0111:03 | G29: MCC RAIL
A30: KA7004:A1 | B30: -011104 | C30: WHT | D30: 20 | E30: 60 | F30: AF0111:04 | G30: MCC RAIL
A31: KA7005:A1 | B31: -011105 | C31: WHT | D31: 20 | E31: 60 | F31: AF0111:05 | G31: MCC RAIL
A32: KA7006:A1 | B32: -011106 | C32: WHT | D32: 20 | E32: 60 | F32: AF0111:06 | G32: MCC RAIL
A33: KA7007:A1 | B33: -011107 | C33: WHT | D33: 20 | E33: 60 | F33: AF0111:07 | G33: MCC RAIL
A34: KA7009:A1 | B34: -011109 | C34: WHT | D34: 20 | E34: 60 | F34: AF0111:09 | G34: MCC RAIL
A35: KA7010:A1 | B35: -011110 | C35: WHT | D35: 20 | E35: 60 | F35: AF0111:10 | G35: MCC RAIL
A36: KA7011:A1 | B36: -011111 | C36: WHT | D36: 20 | E36: 60 | F36: AF0111:11 | G36: MCC RAIL
A37: KA7012:A1 | B37: -011112 | C37: WHT | D37: 20 | E37: 60 | F37: AF0111:12 | G37: MCC RAIL
A38: KA7013:A1 | B38: -011113 | C38: WHT | D38: 20 | E38: 60 | F38: AF0111:13 | G38: MCC RAIL
A40: KA7000:A2 | B40: -011116 | C40: WHT | D40: 20 | E40: 60 | F40: AF0111:16 | G40: MCC RAIL | H40: KA A2
A41: KA7001:A2 | B41: -011117 | C41: WHT | D41: 20 | E41: 60 | F41: AF0111:17 | G41: MCC RAIL
A42: KA7002:A2 | B42: -011118 | C42: WHT | D42: 20 | E42: 60 | F42: AF0111:18 | G42: MCC RAIL
A43: KA7003:A2 | B43: -011119 | C43: WHT | D43: 20 | E43: 60 | F43: AF0111:19 | G43: MCC RAIL
A44: KA7004:A2 | B44: -011120 | C44: WHT | D44: 20 | E44: 60 | F44: AF0111:20 | G44: MCC RAIL
A45: KA7005:A2 | B45: -011121 | C45: WHT | D45: 20 | E45: 60 | F45: AF0111:21 | G45: MCC RAIL
A46: KA7006:A2 | B46: -011122 | C46: WHT | D46: 20 | E46: 60 | F46: AF0111:22 | G46: MCC RAIL
A47: KA7007:A2 | B47: -011123 | C47: WHT | D47: 20 | E47: 60 | F47: AF0111:23 | G47: MCC RAIL
...

Sheet Bundle Tag Info
A1: Project Name and Unit #
A2: PD #
A3: Revision
A6: Panel Name | B6: Panel Name | C6: Panel Name | D6: Panel Name | E6: Panel Name | F6: Panel Name | G6: Panel Name | H6: Panel Name | I6: Panel Name | J6: Panel Name | K6: Panel Name | L6: Panel Name | M6: Panel Name | N6: Panel Name | O6: Panel Name | P6: Panel Name | Q6: Panel Name | R6: Panel Name | S6: Panel Name | T6: Panel Name | U6: Panel Name | V6: Panel Name | W6: Panel Name | X6: Panel Name | Y6: Panel Name | Z6: Panel Name | AA6: Panel Name | AB6: Panel Name | AC6: Panel Name | AD6: Panel Name
A7: Insert
A8: Tag Names
A9: Here

Sheet Bundle Tags2
A1: =IF('Bundle Tag Info'!A6<>"Panel Name",'Bundle Tag Info'!A6,"") | B1: =IF('Bundle Tag Info'!B6<>"Panel Name",'Bundle Tag Info'!B6,"") | C1: =IF('Bundle Tag Info'!C6<>"Panel Name",'Bundle Tag Info'!C6,"") | D1: =IF('Bundle Tag Info'!D6<>"Panel Name",'Bundle Tag Info'!D6,"") | E1: =IF('Bundle Tag Info'!E6<>"Panel Name",'Bundle Tag Info'!E6,"") | F1: =IF('Bundle Tag Info'!F6<>"Panel Name",'Bundle Tag Info'!F6,"") | G1: =IF('Bundle Tag Info'!G6<>"Panel Name",'Bundle Tag Info'!G6,"") | H1: =IF('Bundle Tag Info'!H6<>"Panel Name",'Bundle Tag Info'!H6,"") | ... AD1: =IF('Bundle Tag Info'!AD6<>"Panel Name",'Bundle Tag Info'!AD6,"")
A2: =IF('Bundle Tag Info'!A$7<>"",CONCATENATE('Bundle Tag Info'!$A$1," ",CHAR(10),'Bundle Tag Info'!$A$2," ",'Bundle Tag Info'!$A$3,CHAR(10),'Bundle Tag Info'!A$6,CHAR(10),'Bundle Tag Info'!A$7),"") -> Project Name and Unit # PD # Revision Panel Name Insert | B2: =IF('Bundle Tag Info'!B$7<>"",CONCATENATE('Bundle Tag Info'!$A$1," ",CHAR(10),'Bundle Tag Info'!$A$2," ",'Bundle Tag Info'!$A$3,CHAR(10),'Bundle Tag Info'!B$6,CHAR(10),'Bundle Tag Info'!B$7),"") | C2: =IF('Bundle Tag Info'!C$7<>"",CONCATENATE('Bundle Tag Info'!$A$1," ",CHAR(10),'Bundle Tag Info'!$A$2," ",'Bundle Tag Info'!$A$3,CHAR(10),'Bundle Tag Info'!C$6,CHAR(10),'Bundle Tag Info'!C$7),"") | D2: =IF('Bundle Tag Info'!D$7<>"",CONCATENATE('Bundle Tag Info'!$A$1," ",CHAR(10),'Bundle Tag Info'!$A$2," ",'Bundle Tag Info'!$A$3,CHAR(10),'Bundle Tag Info'!D$6,CHAR(10),'Bundle Tag Info'!D$7),"") | E2: =IF('Bundle Tag Info'!E$7<>"",CONCATENATE('Bundle Tag Info'!$A$1," ",CHAR(10),'Bundle Tag Info'!$A$2," ",'Bundle Tag Info'!$A$3,CHAR(10),'Bundle Tag Info'!E$6,CHAR(10),'Bundle Tag Info'!E$7),"") | F2: =IF('Bundle Tag Info'!F$7<>"",CONCATENATE('Bundle Tag Info'!$A$1," ",CHAR(10),'Bundle Tag Info'!$A$2," ",'Bundle Tag Info'!$A$3,CHAR(10),'Bundle Tag Info'!F$6,CHAR(10),'Bundle Tag Info'!F$7),"") | G2: =IF('Bundle Tag Info'!G$7<>"",CONCATENATE('Bundle Tag Info'!$A$1," ",CHAR(10),'Bundle Tag Info'!$A$2," ",'Bundle Tag Info'!$A$3,CHAR(10),'Bundle Tag Info'!G$6,CHAR(10),'Bundle Tag Info'!G$7),"") | H2: =IF('Bundle Tag Info'!H$7<>"",CONCATENATE('Bundle Tag Info'!$A$1," ",CHAR(10),'Bundle Tag Info'!$A$2," ",'Bundle Tag Info'!$A$3,CHAR(10),'Bundle Tag Info'!H$6,CHAR(10),'Bundle Tag Info'!H$7),"") | ... AD2: =IF('Bundle Tag Info'!AD$7<>"",CONCATENATE('Bundle Tag Info'!$A$1," ",CHAR(10),'Bundle Tag Info'!$A$2," ",'Bundle Tag Info'!$A$3,CHAR(10),'Bundle Tag Info'!AD$6,CHAR(10),'Bundle Tag Info'!AD$7),"")
A3: =IF('Bundle Tag Info'!A$8<>"",CONCATENATE('Bundle Tag Info'!$A$1," ",CHAR(10),'Bundle Tag Info'!$A$2," ",'Bundle Tag Info'!$A$3,CHAR(10),'Bundle Tag Info'!A$6,CHAR(10),'Bundle Tag Info'!A$8),"") -> Project Name and Unit # PD # Revision Panel Name Tag Names | B3: =IF('Bundle Tag Info'!B$8<>"",CONCATENATE('Bundle Tag Info'!$A$1," ",CHAR(10),'Bundle Tag Info'!$A$2," ",'Bundle Tag Info'!$A$3,CHAR(10),'Bundle Tag Info'!B$6,CHAR(10),'Bundle Tag Info'!B$8),"") | C3: =IF('Bundle Tag Info'!C$8<>"",CONCATENATE('Bundle Tag Info'!$A$1," ",CHAR(10),'Bundle Tag Info'!$A$2," ",'Bundle Tag Info'!$A$3,CHAR(10),'Bundle Tag Info'!C$6,CHAR(10),'Bundle Tag Info'!C$8),"") | D3: =IF('Bundle Tag Info'!D$8<>"",CONCATENATE('Bundle Tag Info'!$A$1," ",CHAR(10),'Bundle Tag Info'!$A$2," ",'Bundle Tag Info'!$A$3,CHAR(10),'Bundle Tag Info'!D$6,CHAR(10),'Bundle Tag Info'!D$8),"") | E3: =IF('Bundle Tag Info'!E$8<>"",CONCATENATE('Bundle Tag Info'!$A$1," ",CHAR(10),'Bundle Tag Info'!$A$2," ",'Bundle Tag Info'!$A$3,CHAR(10),'Bundle Tag Info'!E$6,CHAR(10),'Bundle Tag Info'!E$8),"") | F3: =IF('Bundle Tag Info'!F$8<>"",CONCATENATE('Bundle Tag Info'!$A$1," ",CHAR(10),'Bundle Tag Info'!$A$2," ",'Bundle Tag Info'!$A$3,CHAR(10),'Bundle Tag Info'!F$6,CHAR(10),'Bundle Tag Info'!F$8),"") | G3: =IF('Bundle Tag Info'!G$8<>"",CONCATENATE('Bundle Tag Info'!$A$1," ",CHAR(10),'Bundle Tag Info'!$A$2," ",'Bundle Tag Info'!$A$3,CHAR(10),'Bundle Tag Info'!G$6,CHAR(10),'Bundle Tag Info'!G$8),"") | H3: =IF('Bundle Tag Info'!H$8<>"",CONCATENATE('Bundle Tag Info'!$A$1," ",CHAR(10),'Bundle Tag Info'!$A$2," ",'Bundle Tag Info'!$A$3,CHAR(10),'Bundle Tag Info'!H$6,CHAR(10),'Bundle Tag Info'!H$8),"") | ... AD3: =IF('Bundle Tag Info'!AD$8<>"",CONCATENATE('Bundle Tag Info'!$A$1," ",CHAR(10),'Bundle Tag Info'!$A$2," ",'Bundle Tag Info'!$A$3,CHAR(10),'Bundle Tag Info'!AD$6,CHAR(10),'Bundle Tag Info'!AD$8),"")
A4: =IF('Bundle Tag Info'!A$9<>"",CONCATENATE('Bundle Tag Info'!$A$1," ",CHAR(10),'Bundle Tag Info'!$A$2," ",'Bundle Tag Info'!$A$3,CHAR(10),'Bundle Tag Info'!A$6,CHAR(10),'Bundle Tag Info'!A$9),"") -> Project Name and Unit # PD # Revision Panel Name Here | B4: =IF('Bundle Tag Info'!B$9<>"",CONCATENATE('Bundle Tag Info'!$A$1," ",CHAR(10),'Bundle Tag Info'!$A$2," ",'Bundle Tag Info'!$A$3,CHAR(10),'Bundle Tag Info'!B$6,CHAR(10),'Bundle Tag Info'!B$9),"") | C4: =IF('Bundle Tag Info'!C$9<>"",CONCATENATE('Bundle Tag Info'!$A$1," ",CHAR(10),'Bundle Tag Info'!$A$2," ",'Bundle Tag Info'!$A$3,CHAR(10),'Bundle Tag Info'!C$6,CHAR(10),'Bundle Tag Info'!C$9),"") | D4: =IF('Bundle Tag Info'!D$9<>"",CONCATENATE('Bundle Tag Info'!$A$1," ",CHAR(10),'Bundle Tag Info'!$A$2," ",'Bundle Tag Info'!$A$3,CHAR(10),'Bundle Tag Info'!D$6,CHAR(10),'Bundle Tag Info'!D$9),"") | E4: =IF('Bundle Tag Info'!E$9<>"",CONCATENATE('Bundle Tag Info'!$A$1," ",CHAR(10),'Bundle Tag Info'!$A$2," ",'Bundle Tag Info'!$A$3,CHAR(10),'Bundle Tag Info'!E$6,CHAR(10),'Bundle Tag Info'!E$9),"") | F4: =IF('Bundle Tag Info'!F$9<>"",CONCATENATE('Bundle Tag Info'!$A$1," ",CHAR(10),'Bundle Tag Info'!$A$2," ",'Bundle Tag Info'!$A$3,CHAR(10),'Bundle Tag Info'!F$6,CHAR(10),'Bundle Tag Info'!F$9),"") | G4: =IF('Bundle Tag Info'!G$9<>"",CONCATENATE('Bundle Tag Info'!$A$1," ",CHAR(10),'Bundle Tag Info'!$A$2," ",'Bundle Tag Info'!$A$3,CHAR(10),'Bundle Tag Info'!G$6,CHAR(10),'Bundle Tag Info'!G$9),"") | H4: =IF('Bundle Tag Info'!H$9<>"",CONCATENATE('Bundle Tag Info'!$A$1," ",CHAR(10),'Bundle Tag Info'!$A$2," ",'Bundle Tag Info'!$A$3,CHAR(10),'Bundle Tag Info'!H$6,CHAR(10),'Bundle Tag Info'!H$9),"") | ... AD4: =IF('Bundle Tag Info'!AD$9<>"",CONCATENATE('Bundle Tag Info'!$A$1," ",CHAR(10),'Bundle Tag Info'!$A$2," ",'Bundle Tag Info'!$A$3,CHAR(10),'Bundle Tag Info'!AD$6,CHAR(10),'Bundle Tag Info'!AD$9),"")
A5: =IF('Bundle Tag Info'!A$10<>"",CONCATENATE('Bundle Tag Info'!$A$1," ",CHAR(10),'Bundle Tag Info'!$A$2," ",'Bundle Tag Info'!$A$3,CHAR(10),'Bundle Tag Info'!A$6,CHAR(10),'Bundle Tag Info'!A$10),"") | B5: =IF('Bundle Tag Info'!B$10<>"",CONCATENATE('Bundle Tag Info'!$A$1," ",CHAR(10),'Bundle Tag Info'!$A$2," ",'Bundle Tag Info'!$A$3,CHAR(10),'Bundle Tag Info'!B$6,CHAR(10),'Bundle Tag Info'!B$10),"") | C5: =IF('Bundle Tag Info'!C$10<>"",CONCATENATE('Bundle Tag Info'!$A$1," ",CHAR(10),'Bundle Tag Info'!$A$2," ",'Bundle Tag Info'!$A$3,CHAR(10),'Bundle Tag Info'!C$6,CHAR(10),'Bundle Tag Info'!C$10),"") | D5: =IF('Bundle Tag Info'!D$10<>"",CONCATENATE('Bundle Tag Info'!$A$1," ",CHAR(10),'Bundle Tag Info'!$A$2," ",'Bundle Tag Info'!$A$3,CHAR(10),'Bundle Tag Info'!D$6,CHAR(10),'Bundle Tag Info'!D$10),"") | E5: =IF('Bundle Tag Info'!E$10<>"",CONCATENATE('Bundle Tag Info'!$A$1," ",CHAR(10),'Bundle Tag Info'!$A$2," ",'Bundle Tag Info'!$A$3,CHAR(10),'Bundle Tag Info'!E$6,CHAR(10),'Bundle Tag Info'!E$10),"") | F5: =IF('Bundle Tag Info'!F$10<>"",CONCATENATE('Bundle Tag Info'!$A$1," ",CHAR(10),'Bundle Tag Info'!$A$2," ",'Bundle Tag Info'!$A$3,CHAR(10),'Bundle Tag Info'!F$6,CHAR(10),'Bundle Tag Info'!F$10),"") | G5: =IF('Bundle Tag Info'!G$10<>"",CONCATENATE('Bundle Tag Info'!$A$1," ",CHAR(10),'Bundle Tag Info'!$A$2," ",'Bundle Tag Info'!$A$3,CHAR(10),'Bundle Tag Info'!G$6,CHAR(10),'Bundle Tag Info'!G$10),"") | H5: =IF('Bundle Tag Info'!H$10<>"",CONCATENATE('Bundle Tag Info'!$A$1," ",CHAR(10),'Bundle Tag Info'!$A$2," ",'Bundle Tag Info'!$A$3,CHAR(10),'Bundle Tag Info'!H$6,CHAR(10),'Bundle Tag Info'!H$10),"") | ... AD5: =IF('Bundle Tag Info'!AD$10<>"",CONCATENATE('Bundle Tag Info'!$A$1," ",CHAR(10),'Bundle Tag Info'!$A$2," ",'Bundle Tag Info'!$A$3,CHAR(10),'Bundle Tag Info'!AD$6,CHAR(10),'Bundle Tag Info'!AD$10),"")
A6: =IF('Bundle Tag Info'!A$11<>"",CONCATENATE('Bundle Tag Info'!$A$1," ",CHAR(10),'Bundle Tag Info'!$A$2," ",'Bundle Tag Info'!$A$3,CHAR(10),'Bundle Tag Info'!A$6,CHAR(10),'Bundle Tag Info'!A$11),"") | B6: =IF('Bundle Tag Info'!B$11<>"",CONCATENATE('Bundle Tag Info'!$A$1," ",CHAR(10),'Bundle Tag Info'!$A$2," ",'Bundle Tag Info'!$A$3,CHAR(10),'Bundle Tag Info'!B$6,CHAR(10),'Bundle Tag Info'!B$11),"") | C6: =IF('Bundle Tag Info'!C$11<>"",CONCATENATE('Bundle Tag Info'!$A$1," ",CHAR(10),'Bundle Tag Info'!$A$2," ",'Bundle Tag Info'!$A$3,CHAR(10),'Bundle Tag Info'!C$6,CHAR(10),'Bundle Tag Info'!C$11),"") | D6: =IF('Bundle Tag Info'!D$11<>"",CONCATENATE('Bundle Tag Info'!$A$1," ",CHAR(10),'Bundle Tag Info'!$A$2," ",'Bundle Tag Info'!$A$3,CHAR(10),'Bundle Tag Info'!D$6,CHAR(10),'Bundle Tag Info'!D$11),"") | E6: =IF('Bundle Tag Info'!E$11<>"",CONCATENATE('Bundle Tag Info'!$A$1," ",CHAR(10),'Bundle Tag Info'!$A$2," ",'Bundle Tag Info'!$A$3,CHAR(10),'Bundle Tag Info'!E$6,CHAR(10),'Bundle Tag Info'!E$11),"") | F6: =IF('Bundle Tag Info'!F$11<>"",CONCATENATE('Bundle Tag Info'!$A$1," ",CHAR(10),'Bundle Tag Info'!$A$2," ",'Bundle Tag Info'!$A$3,CHAR(10),'Bundle Tag Info'!F$6,CHAR(10),'Bundle Tag Info'!F$11),"") | G6: =IF('Bundle Tag Info'!G$11<>"",CONCATENATE('Bundle Tag Info'!$A$1," ",CHAR(10),'Bundle Tag Info'!$A$2," ",'Bundle Tag Info'!$A$3,CHAR(10),'Bundle Tag Info'!G$6,CHAR(10),'Bundle Tag Info'!G$11),"") | H6: =IF('Bundle Tag Info'!H$11<>"",CONCATENATE('Bundle Tag Info'!$A$1," ",CHAR(10),'Bundle Tag Info'!$A$2," ",'Bundle Tag Info'!$A$3,CHAR(10),'Bundle Tag Info'!H$6,CHAR(10),'Bundle Tag Info'!H$11),"") | ... AD6: =IF('Bundle Tag Info'!AD$11<>"",CONCATENATE('Bundle Tag Info'!$A$1," ",CHAR(10),'Bundle Tag Info'!$A$2," ",'Bundle Tag Info'!$A$3,CHAR(10),'Bundle Tag Info'!AD$6,CHAR(10),'Bundle Tag Info'!AD$11),"")
A7: =IF('Bundle Tag Info'!A$12<>"",CONCATENATE('Bundle Tag Info'!$A$1," ",CHAR(10),'Bundle Tag Info'!$A$2," ",'Bundle Tag Info'!$A$3,CHAR(10),'Bundle Tag Info'!A$6,CHAR(10),'Bundle Tag Info'!A$12),"") | B7: =IF('Bundle Tag Info'!B$12<>"",CONCATENATE('Bundle Tag Info'!$A$1," ",CHAR(10),'Bundle Tag Info'!$A$2," ",'Bundle Tag Info'!$A$3,CHAR(10),'Bundle Tag Info'!B$6,CHAR(10),'Bundle Tag Info'!B$12),"") | C7: =IF('Bundle Tag Info'!C$12<>"",CONCATENATE('Bundle Tag Info'!$A$1," ",CHAR(10),'Bundle Tag Info'!$A$2," ",'Bundle Tag Info'!$A$3,CHAR(10),'Bundle Tag Info'!C$6,CHAR(10),'Bundle Tag Info'!C$12),"") | D7: =IF('Bundle Tag Info'!D$12<>"",CONCATENATE('Bundle Tag Info'!$A$1," ",CHAR(10),'Bundle Tag Info'!$A$2," ",'Bundle Tag Info'!$A$3,CHAR(10),'Bundle Tag Info'!D$6,CHAR(10),'Bundle Tag Info'!D$12),"") | E7: =IF('Bundle Tag Info'!E$12<>"",CONCATENATE('Bundle Tag Info'!$A$1," ",CHAR(10),'Bundle Tag Info'!$A$2," ",'Bundle Tag Info'!$A$3,CHAR(10),'Bundle Tag Info'!E$6,CHAR(10),'Bundle Tag Info'!E$12),"") | F7: =IF('Bundle Tag Info'!F$12<>"",CONCATENATE('Bundle Tag Info'!$A$1," ",CHAR(10),'Bundle Tag Info'!$A$2," ",'Bundle Tag Info'!$A$3,CHAR(10),'Bundle Tag Info'!F$6,CHAR(10),'Bundle Tag Info'!F$12),"") | G7: =IF('Bundle Tag Info'!G$12<>"",CONCATENATE('Bundle Tag Info'!$A$1," ",CHAR(10),'Bundle Tag Info'!$A$2," ",'Bundle Tag Info'!$A$3,CHAR(10),'Bundle Tag Info'!G$6,CHAR(10),'Bundle Tag Info'!G$12),"") | H7: =IF('Bundle Tag Info'!H$12<>"",CONCATENATE('Bundle Tag Info'!$A$1," ",CHAR(10),'Bundle Tag Info'!$A$2," ",'Bundle Tag Info'!$A$3,CHAR(10),'Bundle Tag Info'!H$6,CHAR(10),'Bundle Tag Info'!H$12),"") | ... AD7: =IF('Bundle Tag Info'!AD$12<>"",CONCATENATE('Bundle Tag Info'!$A$1," ",CHAR(10),'Bundle Tag Info'!$A$2," ",'Bundle Tag Info'!$A$3,CHAR(10),'Bundle Tag Info'!AD$6,CHAR(10),'Bundle Tag Info'!AD$12),"")
A8: =IF('Bundle Tag Info'!A$13<>"",CONCATENATE('Bundle Tag Info'!$A$1," ",CHAR(10),'Bundle Tag Info'!$A$2," ",'Bundle Tag Info'!$A$3,CHAR(10),'Bundle Tag Info'!A$6,CHAR(10),'Bundle Tag Info'!A$13),"") | B8: =IF('Bundle Tag Info'!B$13<>"",CONCATENATE('Bundle Tag Info'!$A$1," ",CHAR(10),'Bundle Tag Info'!$A$2," ",'Bundle Tag Info'!$A$3,CHAR(10),'Bundle Tag Info'!B$6,CHAR(10),'Bundle Tag Info'!B$13),"") | C8: =IF('Bundle Tag Info'!C$13<>"",CONCATENATE('Bundle Tag Info'!$A$1," ",CHAR(10),'Bundle Tag Info'!$A$2," ",'Bundle Tag Info'!$A$3,CHAR(10),'Bundle Tag Info'!C$6,CHAR(10),'Bundle Tag Info'!C$13),"") | D8: =IF('Bundle Tag Info'!D$13<>"",CONCATENATE('Bundle Tag Info'!$A$1," ",CHAR(10),'Bundle Tag Info'!$A$2," ",'Bundle Tag Info'!$A$3,CHAR(10),'Bundle Tag Info'!D$6,CHAR(10),'Bundle Tag Info'!D$13),"") | E8: =IF('Bundle Tag Info'!E$13<>"",CONCATENATE('Bundle Tag Info'!$A$1," ",CHAR(10),'Bundle Tag Info'!$A$2," ",'Bundle Tag Info'!$A$3,CHAR(10),'Bundle Tag Info'!E$6,CHAR(10),'Bundle Tag Info'!E$13),"") | F8: =IF('Bundle Tag Info'!F$13<>"",CONCATENATE('Bundle Tag Info'!$A$1," ",CHAR(10),'Bundle Tag Info'!$A$2," ",'Bundle Tag Info'!$A$3,CHAR(10),'Bundle Tag Info'!F$6,CHAR(10),'Bundle Tag Info'!F$13),"") | G8: =IF('Bundle Tag Info'!G$13<>"",CONCATENATE('Bundle Tag Info'!$A$1," ",CHAR(10),'Bundle Tag Info'!$A$2," ",'Bundle Tag Info'!$A$3,CHAR(10),'Bundle Tag Info'!G$6,CHAR(10),'Bundle Tag Info'!G$13),"") | H8: =IF('Bundle Tag Info'!H$13<>"",CONCATENATE('Bundle Tag Info'!$A$1," ",CHAR(10),'Bundle Tag Info'!$A$2," ",'Bundle Tag Info'!$A$3,CHAR(10),'Bundle Tag Info'!H$6,CHAR(10),'Bundle Tag Info'!H$13),"") | ... AD8: =IF('Bundle Tag Info'!AD$13<>"",CONCATENATE('Bundle Tag Info'!$A$1," ",CHAR(10),'Bundle Tag Info'!$A$2," ",'Bundle Tag Info'!$A$3,CHAR(10),'Bundle Tag Info'!AD$6,CHAR(10),'Bundle Tag Info'!AD$13),"")
A9: =IF('Bundle Tag Info'!A$14<>"",CONCATENATE('Bundle Tag Info'!$A$1," ",CHAR(10),'Bundle Tag Info'!$A$2," ",'Bundle Tag Info'!$A$3,CHAR(10),'Bundle Tag Info'!A$6,CHAR(10),'Bundle Tag Info'!A$14),"") | B9: =IF('Bundle Tag Info'!B$14<>"",CONCATENATE('Bundle Tag Info'!$A$1," ",CHAR(10),'Bundle Tag Info'!$A$2," ",'Bundle Tag Info'!$A$3,CHAR(10),'Bundle Tag Info'!B$6,CHAR(10),'Bundle Tag Info'!B$14),"") | C9: =IF('Bundle Tag Info'!C$14<>"",CONCATENATE('Bundle Tag Info'!$A$1," ",CHAR(10),'Bundle Tag Info'!$A$2," ",'Bundle Tag Info'!$A$3,CHAR(10),'Bundle Tag Info'!C$6,CHAR(10),'Bundle Tag Info'!C$14),"") | D9: =IF('Bundle Tag Info'!D$14<>"",CONCATENATE('Bundle Tag Info'!$A$1," ",CHAR(10),'Bundle Tag Info'!$A$2," ",'Bundle Tag Info'!$A$3,CHAR(10),'Bundle Tag Info'!D$6,CHAR(10),'Bundle Tag Info'!D$14),"") | E9: =IF('Bundle Tag Info'!E$14<>"",CONCATENATE('Bundle Tag Info'!$A$1," ",CHAR(10),'Bundle Tag Info'!$A$2," ",'Bundle Tag Info'!$A$3,CHAR(10),'Bundle Tag Info'!E$6,CHAR(10),'Bundle Tag Info'!E$14),"") | F9: =IF('Bundle Tag Info'!F$14<>"",CONCATENATE('Bundle Tag Info'!$A$1," ",CHAR(10),'Bundle Tag Info'!$A$2," ",'Bundle Tag Info'!$A$3,CHAR(10),'Bundle Tag Info'!F$6,CHAR(10),'Bundle Tag Info'!F$14),"") | G9: =IF('Bundle Tag Info'!G$14<>"",CONCATENATE('Bundle Tag Info'!$A$1," ",CHAR(10),'Bundle Tag Info'!$A$2," ",'Bundle Tag Info'!$A$3,CHAR(10),'Bundle Tag Info'!G$6,CHAR(10),'Bundle Tag Info'!G$14),"") | H9: =IF('Bundle Tag Info'!H$14<>"",CONCATENATE('Bundle Tag Info'!$A$1," ",CHAR(10),'Bundle Tag Info'!$A$2," ",'Bundle Tag Info'!$A$3,CHAR(10),'Bundle Tag Info'!H$6,CHAR(10),'Bundle Tag Info'!H$14),"") | ... AD9: =IF('Bundle Tag Info'!AD$14<>"",CONCATENATE('Bundle Tag Info'!$A$1," ",CHAR(10),'Bundle Tag Info'!$A$2," ",'Bundle Tag Info'!$A$3,CHAR(10),'Bundle Tag Info'!AD$6,CHAR(10),'Bundle Tag Info'!AD$14),"")
A10: =IF('Bundle Tag Info'!A$15<>"",CONCATENATE('Bundle Tag Info'!$A$1," ",CHAR(10),'Bundle Tag Info'!$A$2," ",'Bundle Tag Info'!$A$3,CHAR(10),'Bundle Tag Info'!A$6,CHAR(10),'Bundle Tag Info'!A$15),"") | B10: =IF('Bundle Tag Info'!B$15<>"",CONCATENATE('Bundle Tag Info'!$A$1," ",CHAR(10),'Bundle Tag Info'!$A$2," ",'Bundle Tag Info'!$A$3,CHAR(10),'Bundle Tag Info'!B$6,CHAR(10),'Bundle Tag Info'!B$15),"") | C10: =IF('Bundle Tag Info'!C$15<>"",CONCATENATE('Bundle Tag Info'!$A$1," ",CHAR(10),'Bundle Tag Info'!$A$2," ",'Bundle Tag Info'!$A$3,CHAR(10),'Bundle Tag Info'!C$6,CHAR(10),'Bundle Tag Info'!C$15),"") | D10: =IF('Bundle Tag Info'!D$15<>"",CONCATENATE('Bundle Tag Info'!$A$1," ",CHAR(10),'Bundle Tag Info'!$A$2," ",'Bundle Tag Info'!$A$3,CHAR(10),'Bundle Tag Info'!D$6,CHAR(10),'Bundle Tag Info'!D$15),"") | E10: =IF('Bundle Tag Info'!E$15<>"",CONCATENATE('Bundle Tag Info'!$A$1," ",CHAR(10),'Bundle Tag Info'!$A$2," ",'Bundle Tag Info'!$A$3,CHAR(10),'Bundle Tag Info'!E$6,CHAR(10),'Bundle Tag Info'!E$15),"") | F10: =IF('Bundle Tag Info'!F$15<>"",CONCATENATE('Bundle Tag Info'!$A$1," ",CHAR(10),'Bundle Tag Info'!$A$2," ",'Bundle Tag Info'!$A$3,CHAR(10),'Bundle Tag Info'!F$6,CHAR(10),'Bundle Tag Info'!F$15),"") | G10: =IF('Bundle Tag Info'!G$15<>"",CONCATENATE('Bundle Tag Info'!$A$1," ",CHAR(10),'Bundle Tag Info'!$A$2," ",'Bundle Tag Info'!$A$3,CHAR(10),'Bundle Tag Info'!G$6,CHAR(10),'Bundle Tag Info'!G$15),"") | H10: =IF('Bundle Tag Info'!H$15<>"",CONCATENATE('Bundle Tag Info'!$A$1," ",CHAR(10),'Bundle Tag Info'!$A$2," ",'Bundle Tag Info'!$A$3,CHAR(10),'Bundle Tag Info'!H$6,CHAR(10),'Bundle Tag Info'!H$15),"") | ... AD10: =IF('Bundle Tag Info'!AD$15<>"",CONCATENATE('Bundle Tag Info'!$A$1," ",CHAR(10),'Bundle Tag Info'!$A$2," ",'Bundle Tag Info'!$A$3,CHAR(10),'Bundle Tag Info'!AD$6,CHAR(10),'Bundle Tag Info'!AD$15),"")
A11: =IF('Bundle Tag Info'!A$16<>"",CONCATENATE('Bundle Tag Info'!$A$1," ",CHAR(10),'Bundle Tag Info'!$A$2," ",'Bundle Tag Info'!$A$3,CHAR(10),'Bundle Tag Info'!A$6,CHAR(10),'Bundle Tag Info'!A$16),"") | B11: =IF('Bundle Tag Info'!B$16<>"",CONCATENATE('Bundle Tag Info'!$A$1," ",CHAR(10),'Bundle Tag Info'!$A$2," ",'Bundle Tag Info'!$A$3,CHAR(10),'Bundle Tag Info'!B$6,CHAR(10),'Bundle Tag Info'!B$16),"") | C11: =IF('Bundle Tag Info'!C$16<>"",CONCATENATE('Bundle Tag Info'!$A$1," ",CHAR(10),'Bundle Tag Info'!$A$2," ",'Bundle Tag Info'!$A$3,CHAR(10),'Bundle Tag Info'!C$6,CHAR(10),'Bundle Tag Info'!C$16),"") | D11: =IF('Bundle Tag Info'!D$16<>"",CONCATENATE('Bundle Tag Info'!$A$1," ",CHAR(10),'Bundle Tag Info'!$A$2," ",'Bundle Tag Info'!$A$3,CHAR(10),'Bundle Tag Info'!D$6,CHAR(10),'Bundle Tag Info'!D$16),"") | E11: =IF('Bundle Tag Info'!E$16<>"",CONCATENATE('Bundle Tag Info'!$A$1," ",CHAR(10),'Bundle Tag Info'!$A$2," ",'Bundle Tag Info'!$A$3,CHAR(10),'Bundle Tag Info'!E$6,CHAR(10),'Bundle Tag Info'!E$16),"") | F11: =IF('Bundle Tag Info'!F$16<>"",CONCATENATE('Bundle Tag Info'!$A$1," ",CHAR(10),'Bundle Tag Info'!$A$2," ",'Bundle Tag Info'!$A$3,CHAR(10),'Bundle Tag Info'!F$6,CHAR(10),'Bundle Tag Info'!F$16),"") | G11: =IF('Bundle Tag Info'!G$16<>"",CONCATENATE('Bundle Tag Info'!$A$1," ",CHAR(10),'Bundle Tag Info'!$A$2," ",'Bundle Tag Info'!$A$3,CHAR(10),'Bundle Tag Info'!G$6,CHAR(10),'Bundle Tag Info'!G$16),"") | H11: =IF('Bundle Tag Info'!H$16<>"",CONCATENATE('Bundle Tag Info'!$A$1," ",CHAR(10),'Bundle Tag Info'!$A$2," ",'Bundle Tag Info'!$A$3,CHAR(10),'Bundle Tag Info'!H$6,CHAR(10),'Bundle Tag Info'!H$16),"") | ... AD11: =IF('Bundle Tag Info'!AD$16<>"",CONCATENATE('Bundle Tag Info'!$A$1," ",CHAR(10),'Bundle Tag Info'!$A$2," ",'Bundle Tag Info'!$A$3,CHAR(10),'Bundle Tag Info'!AD$6,CHAR(10),'Bundle Tag Info'!AD$16),"")
A12: =IF('Bundle Tag Info'!A$17<>"",CONCATENATE('Bundle Tag Info'!$A$1," ",CHAR(10),'Bundle Tag Info'!$A$2," ",'Bundle Tag Info'!$A$3,CHAR(10),'Bundle Tag Info'!A$6,CHAR(10),'Bundle Tag Info'!A$17),"") | B12: =IF('Bundle Tag Info'!B$17<>"",CONCATENATE('Bundle Tag Info'!$A$1," ",CHAR(10),'Bundle Tag Info'!$A$2," ",'Bundle Tag Info'!$A$3,CHAR(10),'Bundle Tag Info'!B$6,CHAR(10),'Bundle Tag Info'!B$17),"") | C12: =IF('Bundle Tag Info'!C$17<>"",CONCATENATE('Bundle Tag Info'!$A$1," ",CHAR(10),'Bundle Tag Info'!$A$2," ",'Bundle Tag Info'!$A$3,CHAR(10),'Bundle Tag Info'!C$6,CHAR(10),'Bundle Tag Info'!C$17),"") | D12: =IF('Bundle Tag Info'!D$17<>"",CONCATENATE('Bundle Tag Info'!$A$1," ",CHAR(10),'Bundle Tag Info'!$A$2," ",'Bundle Tag Info'!$A$3,CHAR(10),'Bundle Tag Info'!D$6,CHAR(10),'Bundle Tag Info'!D$17),"") | E12: =IF('Bundle Tag Info'!E$17<>"",CONCATENATE('Bundle Tag Info'!$A$1," ",CHAR(10),'Bundle Tag Info'!$A$2," ",'Bundle Tag Info'!$A$3,CHAR(10),'Bundle Tag Info'!E$6,CHAR(10),'Bundle Tag Info'!E$17),"") | F12: =IF('Bundle Tag Info'!F$17<>"",CONCATENATE('Bundle Tag Info'!$A$1," ",CHAR(10),'Bundle Tag Info'!$A$2," ",'Bundle Tag Info'!$A$3,CHAR(10),'Bundle Tag Info'!F$6,CHAR(10),'Bundle Tag Info'!F$17),"") | G12: =IF('Bundle Tag Info'!G$17<>"",CONCATENATE('Bundle Tag Info'!$A$1," ",CHAR(10),'Bundle Tag Info'!$A$2," ",'Bundle Tag Info'!$A$3,CHAR(10),'Bundle Tag Info'!G$6,CHAR(10),'Bundle Tag Info'!G$17),"") | H12: =IF('Bundle Tag Info'!H$17<>"",CONCATENATE('Bundle Tag Info'!$A$1," ",CHAR(10),'Bundle Tag Info'!$A$2," ",'Bundle Tag Info'!$A$3,CHAR(10),'Bundle Tag Info'!H$6,CHAR(10),'Bundle Tag Info'!H$17),"") | ... AD12: =IF('Bundle Tag Info'!AD$17<>"",CONCATENATE('Bundle Tag Info'!$A$1," ",CHAR(10),'Bundle Tag Info'!$A$2," ",'Bundle Tag Info'!$A$3,CHAR(10),'Bundle Tag Info'!AD$6,CHAR(10),'Bundle Tag Info'!AD$17),"")
A13: =IF('Bundle Tag Info'!A$18<>"",CONCATENATE('Bundle Tag Info'!$A$1," ",CHAR(10),'Bundle Tag Info'!$A$2," ",'Bundle Tag Info'!$A$3,CHAR(10),'Bundle Tag Info'!A$6,CHAR(10),'Bundle Tag Info'!A$18),"") | B13: =IF('Bundle Tag Info'!B$18<>"",CONCATENATE('Bundle Tag Info'!$A$1," ",CHAR(10),'Bundle Tag Info'!$A$2," ",'Bundle Tag Info'!$A$3,CHAR(10),'Bundle Tag Info'!B$6,CHAR(10),'Bundle Tag Info'!B$18),"") | C13: =IF('Bundle Tag Info'!C$18<>"",CONCATENATE('Bundle Tag Info'!$A$1," ",CHAR(10),'Bundle Tag Info'!$A$2," ",'Bundle Tag Info'!$A$3,CHAR(10),'Bundle Tag Info'!C$6,CHAR(10),'Bundle Tag Info'!C$18),"") | D13: =IF('Bundle Tag Info'!D$18<>"",CONCATENATE('Bundle Tag Info'!$A$1," ",CHAR(10),'Bundle Tag Info'!$A$2," ",'Bundle Tag Info'!$A$3,CHAR(10),'Bundle Tag Info'!D$6,CHAR(10),'Bundle Tag Info'!D$18),"") | E13: =IF('Bundle Tag Info'!E$18<>"",CONCATENATE('Bundle Tag Info'!$A$1," ",CHAR(10),'Bundle Tag Info'!$A$2," ",'Bundle Tag Info'!$A$3,CHAR(10),'Bundle Tag Info'!E$6,CHAR(10),'Bundle Tag Info'!E$18),"") | F13: =IF('Bundle Tag Info'!F$18<>"",CONCATENATE('Bundle Tag Info'!$A$1," ",CHAR(10),'Bundle Tag Info'!$A$2," ",'Bundle Tag Info'!$A$3,CHAR(10),'Bundle Tag Info'!F$6,CHAR(10),'Bundle Tag Info'!F$18),"") | G13: =IF('Bundle Tag Info'!G$18<>"",CONCATENATE('Bundle Tag Info'!$A$1," ",CHAR(10),'Bundle Tag Info'!$A$2," ",'Bundle Tag Info'!$A$3,CHAR(10),'Bundle Tag Info'!G$6,CHAR(10),'Bundle Tag Info'!G$18),"") | H13: =IF('Bundle Tag Info'!H$18<>"",CONCATENATE('Bundle Tag Info'!$A$1," ",CHAR(10),'Bundle Tag Info'!$A$2," ",'Bundle Tag Info'!$A$3,CHAR(10),'Bundle Tag Info'!H$6,CHAR(10),'Bundle Tag Info'!H$18),"") | ... AD13: =IF('Bundle Tag Info'!AD$18<>"",CONCATENATE('Bundle Tag Info'!$A$1," ",CHAR(10),'Bundle Tag Info'!$A$2," ",'Bundle Tag Info'!$A$3,CHAR(10),'Bundle Tag Info'!AD$6,CHAR(10),'Bundle Tag Info'!AD$18),"")
A14: =IF('Bundle Tag Info'!A$19<>"",CONCATENATE('Bundle Tag Info'!$A$1," ",CHAR(10),'Bundle Tag Info'!$A$2," ",'Bundle Tag Info'!$A$3,CHAR(10),'Bundle Tag Info'!A$6,CHAR(10),'Bundle Tag Info'!A$19),"") | B14: =IF('Bundle Tag Info'!B$19<>"",CONCATENATE('Bundle Tag Info'!$A$1," ",CHAR(10),'Bundle Tag Info'!$A$2," ",'Bundle Tag Info'!$A$3,CHAR(10),'Bundle Tag Info'!B$6,CHAR(10),'Bundle Tag Info'!B$19),"") | C14: =IF('Bundle Tag Info'!C$19<>"",CONCATENATE('Bundle Tag Info'!$A$1," ",CHAR(10),'Bundle Tag Info'!$A$2," ",'Bundle Tag Info'!$A$3,CHAR(10),'Bundle Tag Info'!C$6,CHAR(10),'Bundle Tag Info'!C$19),"") | D14: =IF('Bundle Tag Info'!D$19<>"",CONCATENATE('Bundle Tag Info'!$A$1," ",CHAR(10),'Bundle Tag Info'!$A$2," ",'Bundle Tag Info'!$A$3,CHAR(10),'Bundle Tag Info'!D$6,CHAR(10),'Bundle Tag Info'!D$19),"") | E14: =IF('Bundle Tag Info'!E$19<>"",CONCATENATE('Bundle Tag Info'!$A$1," ",CHAR(10),'Bundle Tag Info'!$A$2," ",'Bundle Tag Info'!$A$3,CHAR(10),'Bundle Tag Info'!E$6,CHAR(10),'Bundle Tag Info'!E$19),"") | F14: =IF('Bundle Tag Info'!F$19<>"",CONCATENATE('Bundle Tag Info'!$A$1," ",CHAR(10),'Bundle Tag Info'!$A$2," ",'Bundle Tag Info'!$A$3,CHAR(10),'Bundle Tag Info'!F$6,CHAR(10),'Bundle Tag Info'!F$19),"") | G14: =IF('Bundle Tag Info'!G$19<>"",CONCATENATE('Bundle Tag Info'!$A$1," ",CHAR(10),'Bundle Tag Info'!$A$2," ",'Bundle Tag Info'!$A$3,CHAR(10),'Bundle Tag Info'!G$6,CHAR(10),'Bundle Tag Info'!G$19),"") | H14: =IF('Bundle Tag Info'!H$19<>"",CONCATENATE('Bundle Tag Info'!$A$1," ",CHAR(10),'Bundle Tag Info'!$A$2," ",'Bundle Tag Info'!$A$3,CHAR(10),'Bundle Tag Info'!H$6,CHAR(10),'Bundle Tag Info'!H$19),"") | ... AD14: =IF('Bundle Tag Info'!AD$19<>"",CONCATENATE('Bundle Tag Info'!$A$1," ",CHAR(10),'Bundle Tag Info'!$A$2," ",'Bundle Tag Info'!$A$3,CHAR(10),'Bundle Tag Info'!AD$6,CHAR(10),'Bundle Tag Info'!AD$19),"")
A15: =IF('Bundle Tag Info'!A$20<>"",CONCATENATE('Bundle Tag Info'!$A$1," ",CHAR(10),'Bundle Tag Info'!$A$2," ",'Bundle Tag Info'!$A$3,CHAR(10),'Bundle Tag Info'!A$6,CHAR(10),'Bundle Tag Info'!A$20),"") | B15: =IF('Bundle Tag Info'!B$20<>"",CONCATENATE('Bundle Tag Info'!$A$1," ",CHAR(10),'Bundle Tag Info'!$A$2," ",'Bundle Tag Info'!$A$3,CHAR(10),'Bundle Tag Info'!B$6,CHAR(10),'Bundle Tag Info'!B$20),"") | C15: =IF('Bundle Tag Info'!C$20<>"",CONCATENATE('Bundle Tag Info'!$A$1," ",CHAR(10),'Bundle Tag Info'!$A$2," ",'Bundle Tag Info'!$A$3,CHAR(10),'Bundle Tag Info'!C$6,CHAR(10),'Bundle Tag Info'!C$20),"") | D15: =IF('Bundle Tag Info'!D$20<>"",CONCATENATE('Bundle Tag Info'!$A$1," ",CHAR(10),'Bundle Tag Info'!$A$2," ",'Bundle Tag Info'!$A$3,CHAR(10),'Bundle Tag Info'!D$6,CHAR(10),'Bundle Tag Info'!D$20),"") | E15: =IF('Bundle Tag Info'!E$20<>"",CONCATENATE('Bundle Tag Info'!$A$1," ",CHAR(10),'Bundle Tag Info'!$A$2," ",'Bundle Tag Info'!$A$3,CHAR(10),'Bundle Tag Info'!E$6,CHAR(10),'Bundle Tag Info'!E$20),"") | F15: =IF('Bundle Tag Info'!F$20<>"",CONCATENATE('Bundle Tag Info'!$A$1," ",CHAR(10),'Bundle Tag Info'!$A$2," ",'Bundle Tag Info'!$A$3,CHAR(10),'Bundle Tag Info'!F$6,CHAR(10),'Bundle Tag Info'!F$20),"") | G15: =IF('Bundle Tag Info'!G$20<>"",CONCATENATE('Bundle Tag Info'!$A$1," ",CHAR(10),'Bundle Tag Info'!$A$2," ",'Bundle Tag Info'!$A$3,CHAR(10),'Bundle Tag Info'!G$6,CHAR(10),'Bundle Tag Info'!G$20),"") | H15: =IF('Bundle Tag Info'!H$20<>"",CONCATENATE('Bundle Tag Info'!$A$1," ",CHAR(10),'Bundle Tag Info'!$A$2," ",'Bundle Tag Info'!$A$3,CHAR(10),'Bundle Tag Info'!H$6,CHAR(10),'Bundle Tag Info'!H$20),"") | ... AD15: =IF('Bundle Tag Info'!AD$20<>"",CONCATENATE('Bundle Tag Info'!$A$1," ",CHAR(10),'Bundle Tag Info'!$A$2," ",'Bundle Tag Info'!$A$3,CHAR(10),'Bundle Tag Info'!AD$6,CHAR(10),'Bundle Tag Info'!AD$20),"")
A16: =IF('Bundle Tag Info'!A$21<>"",CONCATENATE('Bundle Tag Info'!$A$1," ",CHAR(10),'Bundle Tag Info'!$A$2," ",'Bundle Tag Info'!$A$3,CHAR(10),'Bundle Tag Info'!A$6,CHAR(10),'Bundle Tag Info'!A$21),"") | B16: =IF('Bundle Tag Info'!B$21<>"",CONCATENATE('Bundle Tag Info'!$A$1," ",CHAR(10),'Bundle Tag Info'!$A$2," ",'Bundle Tag Info'!$A$3,CHAR(10),'Bundle Tag Info'!B$6,CHAR(10),'Bundle Tag Info'!B$21),"") | C16: =IF('Bundle Tag Info'!C$21<>"",CONCATENATE('Bundle Tag Info'!$A$1," ",CHAR(10),'Bundle Tag Info'!$A$2," ",'Bundle Tag Info'!$A$3,CHAR(10),'Bundle Tag Info'!C$6,CHAR(10),'Bundle Tag Info'!C$21),"") | D16: =IF('Bundle Tag Info'!D$21<>"",CONCATENATE('Bundle Tag Info'!$A$1," ",CHAR(10),'Bundle Tag Info'!$A$2," ",'Bundle Tag Info'!$A$3,CHAR(10),'Bundle Tag Info'!D$6,CHAR(10),'Bundle Tag Info'!D$21),"") | E16: =IF('Bundle Tag Info'!E$21<>"",CONCATENATE('Bundle Tag Info'!$A$1," ",CHAR(10),'Bundle Tag Info'!$A$2," ",'Bundle Tag Info'!$A$3,CHAR(10),'Bundle Tag Info'!E$6,CHAR(10),'Bundle Tag Info'!E$21),"") | F16: =IF('Bundle Tag Info'!F$21<>"",CONCATENATE('Bundle Tag Info'!$A$1," ",CHAR(10),'Bundle Tag Info'!$A$2," ",'Bundle Tag Info'!$A$3,CHAR(10),'Bundle Tag Info'!F$6,CHAR(10),'Bundle Tag Info'!F$21),"") | G16: =IF('Bundle Tag Info'!G$21<>"",CONCATENATE('Bundle Tag Info'!$A$1," ",CHAR(10),'Bundle Tag Info'!$A$2," ",'Bundle Tag Info'!$A$3,CHAR(10),'Bundle Tag Info'!G$6,CHAR(10),'Bundle Tag Info'!G$21),"") | H16: =IF('Bundle Tag Info'!H$21<>"",CONCATENATE('Bundle Tag Info'!$A$1," ",CHAR(10),'Bundle Tag Info'!$A$2," ",'Bundle Tag Info'!$A$3,CHAR(10),'Bundle Tag Info'!H$6,CHAR(10),'Bundle Tag Info'!H$21),"") | ... AD16: =IF('Bundle Tag Info'!AD$21<>"",CONCATENATE('Bundle Tag Info'!$A$1," ",CHAR(10),'Bundle Tag Info'!$A$2," ",'Bundle Tag Info'!$A$3,CHAR(10),'Bundle Tag Info'!AD$6,CHAR(10),'Bundle Tag Info'!AD$21),"")
A17: =IF('Bundle Tag Info'!A$22<>"",CONCATENATE('Bundle Tag Info'!$A$1," ",CHAR(10),'Bundle Tag Info'!$A$2," ",'Bundle Tag Info'!$A$3,CHAR(10),'Bundle Tag Info'!A$6,CHAR(10),'Bundle Tag Info'!A$22),"") | B17: =IF('Bundle Tag Info'!B$22<>"",CONCATENATE('Bundle Tag Info'!$A$1," ",CHAR(10),'Bundle Tag Info'!$A$2," ",'Bundle Tag Info'!$A$3,CHAR(10),'Bundle Tag Info'!B$6,CHAR(10),'Bundle Tag Info'!B$22),"") | C17: =IF('Bundle Tag Info'!C$22<>"",CONCATENATE('Bundle Tag Info'!$A$1," ",CHAR(10),'Bundle Tag Info'!$A$2," ",'Bundle Tag Info'!$A$3,CHAR(10),'Bundle Tag Info'!C$6,CHAR(10),'Bundle Tag Info'!C$22),"") | D17: =IF('Bundle Tag Info'!D$22<>"",CONCATENATE('Bundle Tag Info'!$A$1," ",CHAR(10),'Bundle Tag Info'!$A$2," ",'Bundle Tag Info'!$A$3,CHAR(10),'Bundle Tag Info'!D$6,CHAR(10),'Bundle Tag Info'!D$22),"") | E17: =IF('Bundle Tag Info'!E$22<>"",CONCATENATE('Bundle Tag Info'!$A$1," ",CHAR(10),'Bundle Tag Info'!$A$2," ",'Bundle Tag Info'!$A$3,CHAR(10),'Bundle Tag Info'!E$6,CHAR(10),'Bundle Tag Info'!E$22),"") | F17: =IF('Bundle Tag Info'!F$22<>"",CONCATENATE('Bundle Tag Info'!$A$1," ",CHAR(10),'Bundle Tag Info'!$A$2," ",'Bundle Tag Info'!$A$3,CHAR(10),'Bundle Tag Info'!F$6,CHAR(10),'Bundle Tag Info'!F$22),"") | G17: =IF('Bundle Tag Info'!G$22<>"",CONCATENATE('Bundle Tag Info'!$A$1," ",CHAR(10),'Bundle Tag Info'!$A$2," ",'Bundle Tag Info'!$A$3,CHAR(10),'Bundle Tag Info'!G$6,CHAR(10),'Bundle Tag Info'!G$22),"") | H17: =IF('Bundle Tag Info'!H$22<>"",CONCATENATE('Bundle Tag Info'!$A$1," ",CHAR(10),'Bundle Tag Info'!$A$2," ",'Bundle Tag Info'!$A$3,CHAR(10),'Bundle Tag Info'!H$6,CHAR(10),'Bundle Tag Info'!H$22),"") | ... AD17: =IF('Bundle Tag Info'!AD$22<>"",CONCATENATE('Bundle Tag Info'!$A$1," ",CHAR(10),'Bundle Tag Info'!$A$2," ",'Bundle Tag Info'!$A$3,CHAR(10),'Bundle Tag Info'!AD$6,CHAR(10),'Bundle Tag Info'!AD$22),"")
A18: =IF('Bundle Tag Info'!A$23<>"",CONCATENATE('Bundle Tag Info'!$A$1," ",CHAR(10),'Bundle Tag Info'!$A$2," ",'Bundle Tag Info'!$A$3,CHAR(10),'Bundle Tag Info'!A$6,CHAR(10),'Bundle Tag Info'!A$23),"") | B18: =IF('Bundle Tag Info'!B$23<>"",CONCATENATE('Bundle Tag Info'!$A$1," ",CHAR(10),'Bundle Tag Info'!$A$2," ",'Bundle Tag Info'!$A$3,CHAR(10),'Bundle Tag Info'!B$6,CHAR(10),'Bundle Tag Info'!B$23),"") | C18: =IF('Bundle Tag Info'!C$23<>"",CONCATENATE('Bundle Tag Info'!$A$1," ",CHAR(10),'Bundle Tag Info'!$A$2," ",'Bundle Tag Info'!$A$3,CHAR(10),'Bundle Tag Info'!C$6,CHAR(10),'Bundle Tag Info'!C$23),"") | D18: =IF('Bundle Tag Info'!D$23<>"",CONCATENATE('Bundle Tag Info'!$A$1," ",CHAR(10),'Bundle Tag Info'!$A$2," ",'Bundle Tag Info'!$A$3,CHAR(10),'Bundle Tag Info'!D$6,CHAR(10),'Bundle Tag Info'!D$23),"") | E18: =IF('Bundle Tag Info'!E$23<>"",CONCATENATE('Bundle Tag Info'!$A$1," ",CHAR(10),'Bundle Tag Info'!$A$2," ",'Bundle Tag Info'!$A$3,CHAR(10),'Bundle Tag Info'!E$6,CHAR(10),'Bundle Tag Info'!E$23),"") | F18: =IF('Bundle Tag Info'!F$23<>"",CONCATENATE('Bundle Tag Info'!$A$1," ",CHAR(10),'Bundle Tag Info'!$A$2," ",'Bundle Tag Info'!$A$3,CHAR(10),'Bundle Tag Info'!F$6,CHAR(10),'Bundle Tag Info'!F$23),"") | G18: =IF('Bundle Tag Info'!G$23<>"",CONCATENATE('Bundle Tag Info'!$A$1," ",CHAR(10),'Bundle Tag Info'!$A$2," ",'Bundle Tag Info'!$A$3,CHAR(10),'Bundle Tag Info'!G$6,CHAR(10),'Bundle Tag Info'!G$23),"") | H18: =IF('Bundle Tag Info'!H$23<>"",CONCATENATE('Bundle Tag Info'!$A$1," ",CHAR(10),'Bundle Tag Info'!$A$2," ",'Bundle Tag Info'!$A$3,CHAR(10),'Bundle Tag Info'!H$6,CHAR(10),'Bundle Tag Info'!H$23),"") | ... AD18: =IF('Bundle Tag Info'!AD$23<>"",CONCATENATE('Bundle Tag Info'!$A$1," ",CHAR(10),'Bundle Tag Info'!$A$2," ",'Bundle Tag Info'!$A$3,CHAR(10),'Bundle Tag Info'!AD$6,CHAR(10),'Bundle Tag Info'!AD$23),"")
A19: =IF('Bundle Tag Info'!A$24<>"",CONCATENATE('Bundle Tag Info'!$A$1," ",CHAR(10),'Bundle Tag Info'!$A$2," ",'Bundle Tag Info'!$A$3,CHAR(10),'Bundle Tag Info'!A$6,CHAR(10),'Bundle Tag Info'!A$24),"") | B19: =IF('Bundle Tag Info'!B$24<>"",CONCATENATE('Bundle Tag Info'!$A$1," ",CHAR(10),'Bundle Tag Info'!$A$2," ",'Bundle Tag Info'!$A$3,CHAR(10),'Bundle Tag Info'!B$6,CHAR(10),'Bundle Tag Info'!B$24),"") | C19: =IF('Bundle Tag Info'!C$24<>"",CONCATENATE('Bundle Tag Info'!$A$1," ",CHAR(10),'Bundle Tag Info'!$A$2," ",'Bundle Tag Info'!$A$3,CHAR(10),'Bundle Tag Info'!C$6,CHAR(10),'Bundle Tag Info'!C$24),"") | D19: =IF('Bundle Tag Info'!D$24<>"",CONCATENATE('Bundle Tag Info'!$A$1," ",CHAR(10),'Bundle Tag Info'!$A$2," ",'Bundle Tag Info'!$A$3,CHAR(10),'Bundle Tag Info'!D$6,CHAR(10),'Bundle Tag Info'!D$24),"") | E19: =IF('Bundle Tag Info'!E$24<>"",CONCATENATE('Bundle Tag Info'!$A$1," ",CHAR(10),'Bundle Tag Info'!$A$2," ",'Bundle Tag Info'!$A$3,CHAR(10),'Bundle Tag Info'!E$6,CHAR(10),'Bundle Tag Info'!E$24),"") | F19: =IF('Bundle Tag Info'!F$24<>"",CONCATENATE('Bundle Tag Info'!$A$1," ",CHAR(10),'Bundle Tag Info'!$A$2," ",'Bundle Tag Info'!$A$3,CHAR(10),'Bundle Tag Info'!F$6,CHAR(10),'Bundle Tag Info'!F$24),"") | G19: =IF('Bundle Tag Info'!G$24<>"",CONCATENATE('Bundle Tag Info'!$A$1," ",CHAR(10),'Bundle Tag Info'!$A$2," ",'Bundle Tag Info'!$A$3,CHAR(10),'Bundle Tag Info'!G$6,CHAR(10),'Bundle Tag Info'!G$24),"") | H19: =IF('Bundle Tag Info'!H$24<>"",CONCATENATE('Bundle Tag Info'!$A$1," ",CHAR(10),'Bundle Tag Info'!$A$2," ",'Bundle Tag Info'!$A$3,CHAR(10),'Bundle Tag Info'!H$6,CHAR(10),'Bundle Tag Info'!H$24),"") | ... AD19: =IF('Bundle Tag Info'!AD$24<>"",CONCATENATE('Bundle Tag Info'!$A$1," ",CHAR(10),'Bundle Tag Info'!$A$2," ",'Bundle Tag Info'!$A$3,CHAR(10),'Bundle Tag Info'!AD$6,CHAR(10),'Bundle Tag Info'!AD$24),"")
A20: =IF('Bundle Tag Info'!A$25<>"",CONCATENATE('Bundle Tag Info'!$A$1," ",CHAR(10),'Bundle Tag Info'!$A$2," ",'Bundle Tag Info'!$A$3,CHAR(10),'Bundle Tag Info'!A$6,CHAR(10),'Bundle Tag Info'!A$25),"") | B20: =IF('Bundle Tag Info'!B$25<>"",CONCATENATE('Bundle Tag Info'!$A$1," ",CHAR(10),'Bundle Tag Info'!$A$2," ",'Bundle Tag Info'!$A$3,CHAR(10),'Bundle Tag Info'!B$6,CHAR(10),'Bundle Tag Info'!B$25),"") | C20: =IF('Bundle Tag Info'!C$25<>"",CONCATENATE('Bundle Tag Info'!$A$1," ",CHAR(10),'Bundle Tag Info'!$A$2," ",'Bundle Tag Info'!$A$3,CHAR(10),'Bundle Tag Info'!C$6,CHAR(10),'Bundle Tag Info'!C$25),"") | D20: =IF('Bundle Tag Info'!D$25<>"",CONCATENATE('Bundle Tag Info'!$A$1," ",CHAR(10),'Bundle Tag Info'!$A$2," ",'Bundle Tag Info'!$A$3,CHAR(10),'Bundle Tag Info'!D$6,CHAR(10),'Bundle Tag Info'!D$25),"") | E20: =IF('Bundle Tag Info'!E$25<>"",CONCATENATE('Bundle Tag Info'!$A$1," ",CHAR(10),'Bundle Tag Info'!$A$2," ",'Bundle Tag Info'!$A$3,CHAR(10),'Bundle Tag Info'!E$6,CHAR(10),'Bundle Tag Info'!E$25),"") | F20: =IF('Bundle Tag Info'!F$25<>"",CONCATENATE('Bundle Tag Info'!$A$1," ",CHAR(10),'Bundle Tag Info'!$A$2," ",'Bundle Tag Info'!$A$3,CHAR(10),'Bundle Tag Info'!F$6,CHAR(10),'Bundle Tag Info'!F$25),"") | G20: =IF('Bundle Tag Info'!G$25<>"",CONCATENATE('Bundle Tag Info'!$A$1," ",CHAR(10),'Bundle Tag Info'!$A$2," ",'Bundle Tag Info'!$A$3,CHAR(10),'Bundle Tag Info'!G$6,CHAR(10),'Bundle Tag Info'!G$25),"") | H20: =IF('Bundle Tag Info'!H$25<>"",CONCATENATE('Bundle Tag Info'!$A$1," ",CHAR(10),'Bundle Tag Info'!$A$2," ",'Bundle Tag Info'!$A$3,CHAR(10),'Bundle Tag Info'!H$6,CHAR(10),'Bundle Tag Info'!H$25),"") | ... AD20: =IF('Bundle Tag Info'!AD$25<>"",CONCATENATE('Bundle Tag Info'!$A$1," ",CHAR(10),'Bundle Tag Info'!$A$2," ",'Bundle Tag Info'!$A$3,CHAR(10),'Bundle Tag Info'!AD$6,CHAR(10),'Bundle Tag Info'!AD$25),"")
