Workbook

Sheet Blue Labels
A1: (SHT 1) CONSOLE | B1: (SHT 2) CONSOLE | C1: (SHT 3) SCS | D1: (SHT 4) RIGHT SIDE PANEL | E1: (SHT 5) BACK PANEL | F1: (SHT 6) LEFT SIDE PANEL
A2: EL0273 | B2: AT0191 | C2: HL1753 | D2: AT0180 | E2: AR0600 | F2: XT0095
A3: HA0273 | B3: AT0190K | C3: HL1733 | D3: XT1211 | E3: AP0606 | F3: FU0273
A4: ZS0273 | B4: AT0190 | C4: HL1593 | D4: XT1212 | E4: AP0605 | F4: XT0273
A5: FG0130 | C5: HL1143 | D5: XT1213 | E5: AP0604 | F5: FU0090
C6: HL1773 | D6: XT1214 | E6: AP0602 | F6: FU0091
C7: HL1751 | D7: XT1221 | E7: AP0601 | F7: FU0092
C8: HL1731 | D8: XT1222 | E8: AT0600 | F8: FU0093
C9: HL1591 | D9: XT1223 | E9: UV0600 | F9: FU0094
C10: HL1141 | D10: XT1224 | E10: AP0603 | F10: FU0095
C11: HL1771 | D11: XT1241 | E11: XT0085 | F11: XT0090
C12: AU0020 | D12: XT1243 | E12: FU0060 | F12: AU0090
C13: AF0021 | D13: GR0203 | E13: AU0060 | F13: AF0091
C14: GR0120 | D14: FU1201 | E14: AF0061 | F14: AF0092
C15: SB1283 | D15: FU1202 | E15: AF0062 | F15: AF0093
C16: SB1293 | D16: XT1201 | E16: AF0063 | F16: AF0094
C17: SB1113 | D17: XT1202 | E17: AF0064 | F17: AF0095
... C26: HL1754 | D26: GR0202 | E26: AF0047 | F26: KA0001
C27: HL1734 | E27: GR0110 | F27: KA0002
C28: HL1594 | E28: BA0010 | F28: KA0003
C29: HL1144 | E29: BA0009 | F29: KA0004
C30: HL1774 | E30: BA0001 | F30: KA0005
C31: HL1752 | E31: BA0002 | F31: KA0006
C32: HL1732 | E32: BA0011 | F32: KA0007
C33: HL1592 | E33: BA0012 | F33: KA0008
C34: HL1142 | E34: BA0013 | F34: KA0009
C35: HL1772 | E35: BA0014 | F35: KA0010
C36: SB1284 | E36: BA0019 | F36: KA0011
C37: SB1294 | E37: FU0101 | F37: KA0012
C38: SB1114 | E38: FU0102 | F38: KA0013
... C53: WC0020 | E53: GR0111 | F53: KA0048
E54: BA0606 | F54: KA0141
E55: BA1215 | F55: KA0142
E56: AT0680 | F56: KA0143
E57: FU0680 | F57: KA0144
E58: GR0135 | F58: KA0145
E59: XT0680 | F59: KA0146
E60: XT0138 | F60: KA0147
E61: XT0139 | F61: KA0148
E62: XT0134 | F62: KA5760
...

Sheet White Labels
A1: (SHT 5) BACK PANEL | B1: (SHT 5) BACK PANEL - (SHT 6) LEFT SIDE PANEL | C1: (SHT 6) LEFT SIDE PANEL | D1: (SHT 6) LEFT SIDE PANEL - (SHT 3) SCS | E1: (SHT 4) RIGHT SIDE PANEL
A2: 0V | B2: AU0040G | C2: AU0090G | D2: AU0020G | E2: AT0180FG
A3: AF0061G | B3: AU0050G | C3: GR0134 | D3: GR0120 | E3: FGPT1N
A4: AF0062G | B4: GR0110 | D4: GR0121 | E4: FGPT3N
A5: AF0063G | B5: GR0111
A6: AU0060G | B6: GR0135
A7: UV0600G | B7: IEG01301
B8: IEG013013

Sheet Heat Shrink Labels

Sheet BACK PANEL
A1: BACK PANEL
A2: ASSY,BACK PANEL,CONSOLE
A3: Project # | B3: 4N298
A4: Project Name | B4: P66 Iron Mesa PMS
A5: Revision | B5: B
A7: Controls DE | B7: Akanksha Maddi
A8: Phone: | B8: 9254814160
A9: Controls ME
A10: Phone:
A12: From | G12: To
A13: Device ID | B13: Cable (W) Conductor (SC) Jumper Clip (JC) | C13: Wire No. | D13: Wire ID | E13: Gauge/Size | F13: Page/Zone | G13: Device ID | H13: Location | I13: Page/Zone
A14: XT0134:1 | B14: JC | C14: 0V | D14: CLIP | E14: --- | F14: 6.C3 | G14: XT0134:2 | H14: BACK PANEL | I14: 6.C3 | M14: USED
A15: XT0134:2 | B15: JC | C15: 0V | D15: CLIP | E15: --- | F15: 6.C3 | G15: XT0134:3 | H15: BACK PANEL | I15: 6.C3 | M15: USED
A16: XT0134:3 | B16: JC | C16: 0V | D16: CLIP | E16: --- | F16: 6.C3 | G16: XT0134:4 | H16: BACK PANEL | I16: 6.C3 | M16: USED
A17: XT0135:1 | B17: JC | C17: 0V | D17: CLIP | E17: --- | F17: 6.C4 | G17: XT0135:2 | H17: BACK PANEL | I17: 6.C4 | M17: USED
A18: XT0135:2 | B18: JC | C18: 0V | D18: CLIP | E18: --- | F18: 6.C4 | G18: XT0135:3 | H18: BACK PANEL | I18: 6.C4 | M18: USED
A19: XT0135:3 | B19: JC | C19: 0V | D19: CLIP | E19: --- | F19: 6.C4 | G19: XT0135:4 | H19: BACK PANEL | I19: 6.C4 | M19: USED
A20: XT0135:4 | B20: JC | C20: 0V | D20: CLIP | E20: --- | F20: 6.C4 | G20: XT0135:5 | H20: BACK PANEL | I20: 6.D4 | M20: USED
A21: XT0135:5 | B21: JC | C21: 0V | D21: CLIP | E21: --- | F21: 6.D4 | G21: XT0135:6 | H21: BACK PANEL | I21: 6.D4 | M21: USED
A22: XT0138:1 | B22: JC | C22: FU0136 | D22: CLIP | E22: --- | F22: 6.A3 | G22: XT0138:2 | H22: BACK PANEL | I22: 6.A3 | M22: USED
A23: XT0138:2 | B23: JC | C23: FU0136 | D23: CLIP | E23: --- | F23: 6.A3 | G23: XT0138:3 | H23: BACK PANEL | I23: 6.B3 | M23: USED
A24: XT0138:3 | B24: JC | C24: FU0136 | D24: CLIP | E24: --- | F24: 6.B3 | G24: XT0138:4 | H24: BACK PANEL | I24: 6.B3 | M24: USED
A25: XT0139:1 | B25: JC | C25: FU0137 | D25: CLIP | E25: --- | F25: 6.A4 | G25: XT0139:2 | H25: BACK PANEL | I25: 6.A4 | M25: USED
... A193: AU0040:L1 | B193: WC0002 | C193: AU0020L2 | D193: ENET | E193: CABLE | F193: 12.A2 | G193: AU0020:L2 | H193: SCS | I193: 11.C2 | M193: USED
F195: SolarTools ver. 24.0.84.24712 (Jul 31, 2025)
A196: Report date: 3/9/2026 7:07 AM

Sheet CONSOLE
A1: CONSOLE
A2: ASSEMBLY CONSOLE & CONSOLE DOORS ONE BAY
A3: Project # | B3: 4N298
A4: Project Name | B4: P66 Iron Mesa PMS
A5: Revision | B5: B
A7: Controls DE | B7: Akanksha Maddi
A8: Phone: | B8: 9254814160
A9: Controls ME
A10: Phone:
A12: From | G12: To
A13: Device ID | B13: Cable (W) Conductor (SC) Jumper Clip (JC) | C13: Wire No. | D13: Wire ID | E13: Gauge/Size | F13: Page/Zone | G13: Device ID | H13: Location | I13: Page/Zone
A14: AT0190:DVI | B14: SC | C14: AT0190D | D14: CABLE | E14: DVI | F14: 17.B4 | G14: AT0191:DVI | H14: CONSOLE | I14: 17.A3 | M14: USED
A15: AT0190:GND | B15: SC | C15: AT0190G | D15: GRN/YEL | E15: 14 | F15: 17.B4 | G15: FRAME | H15: CONSOLE | I15: 17.C3 | M15: USED
A16: AT0190:PS2 | B16: SC | C16: AT0190K | D16: CABLE | E16: USB | F16: 17.B4 | G16: AT0190K:KI | H16: CONSOLE | I16: 17.B5 | M16: USED
A17: AT0190:PS2 | B17: SC | C17: AT0190U | D17: CABLE | E17: USB | F17: 17.B4 | G17: AT0191:USB | H17: CONSOLE | I17: 17.A3 | M17: USED
A18: AT0191:GND | B18: SC | C18: AT0191G | D18: GRN/YEL | E18: 14 | F18: 17.A3 | G18: FRAME | H18: CONSOLE | I18: 17.B3 | M18: USED
A19: EL0273:B1 | B19: SC | C19: ZS0273 | D19: WHT | E19: 14 | F19: 6.D3 | G19: ZS0273:2 | H19: CONSOLE | I19: 6.D2 | M19: USED
A20: AT0190:ENET2 | B20: WC0060 | C20: AT0680LAN2 | D20: ENET | E20: CABLE | F20: 17.B4 | G20: AT0680:LAN2 | H20: BACK PANEL | I20: 8.A4 | M20: USED
A21: AT0190:NEG | B21: SC | C21: 0V | D21: WHT | E21: 14 | F21: 17.B4 | G21: XT0262:3 | H21: LEFT SIDE PANEL | I21: 7.C4 | M21: USED
A22: AT0190:POS | B22: SC | C22: FU0190 | D22: WHT | E22: 14 | F22: 17.B4 | G22: FU0190:LD | H22: LEFT SIDE PANEL | I22: 7.B5 | M22: USED
A23: AT0191:NEG | B23: SC | C23: 0V | D23: WHT | E23: 14 | F23: 17.A3 | G23: XT0262:3 | H23: LEFT SIDE PANEL | I23: 7.C4 | M23: USED
A24: AT0191:POS | B24: SC | C24: FU0190 | D24: WHT | E24: 14 | F24: 17.A3 | G24: FU0190:LD | H24: LEFT SIDE PANEL | I24: 7.B5 | M24: USED
A25: EL0273:W1 | B25: SC | C25: 0V | D25: WHT | E25: 14 | F25: 6.D3 | G25: XT0273:1 | H25: LEFT SIDE PANEL | I25: 6.D2 | M25: USED
... A28: HA0273:(-) | B28: WC5540 | C28: HA0273N | D28: WHT | E28: 16 | F28: 19.A5 | G28: AF0022:37 | H28: SCS | I28: 19.A6 | M28: USED
F30: SolarTools ver. 24.0.84.24712 (Jul 31, 2025)
A31: Report date: 3/9/2026 7:07 AM

Sheet LEFT SIDE PANEL
A1: LEFT SIDE PANEL
A2: ASSY,LEFT SIDE PANEL,CONSOLE
A3: Project # | B3: 4N298
A4: Project Name | B4: P66 Iron Mesa PMS
A5: Revision | B5: B
A7: Controls DE | B7: Akanksha Maddi
A8: Phone: | B8: 9254814160
A9: Controls ME
A10: Phone:
A12: From | G12: To
A13: Device ID | B13: Cable (W) Conductor (SC) Jumper Clip (JC) | C13: Wire No. | D13: Wire ID | E13: Gauge/Size | F13: Page/Zone | G13: Device ID | H13: Location | I13: Page/Zone
A14: XT0090:3 | B14: JC | C14: 0V | D14: CLIP | E14: --- | F14: 14.A5 | G14: XT0090:2 | H14: LEFT SIDE PANEL | I14: 14.B5 | M14: USED
A15: XT0090:4 | B15: JC | C15: 0V | D15: CLIP | E15: --- | F15: 14.A5 | G15: XT0090:3 | H15: LEFT SIDE PANEL | I15: 14.A5 | M15: USED
A16: XT0090:5 | B16: JC | C16: 0V | D16: CLIP | E16: --- | F16: 14.A5 | G16: XT0090:4 | H16: LEFT SIDE PANEL | I16: 14.A5 | M16: USED
A17: XT0090:6 | B17: JC | C17: 0V | D17: CLIP | E17: --- | F17: 14.A5 | G17: XT0090:5 | H17: LEFT SIDE PANEL | I17: 14.A5 | M17: USED
A18: XT0261:1 | B18: JC | C18: FU0260 | D18: CLIP | E18: --- | F18: 7.A4 | G18: XT0261:2 | H18: LEFT SIDE PANEL | I18: 7.A4 | M18: USED
A19: XT0261:2 | B19: JC | C19: FU0260 | D19: CLIP | E19: --- | F19: 7.A4 | G19: XT0261:3 | H19: LEFT SIDE PANEL | I19: 7.B4 | M19: USED
A20: XT0261:3 | B20: JC | C20: FU0260 | D20: CLIP | E20: --- | F20: 7.B4 | G20: XT0261:4 | H20: LEFT SIDE PANEL | I20: 7.B4 | M20: USED
A21: XT0262:1 | B21: JC | C21: 0V | D21: CLIP | E21: --- | F21: 7.C4 | G21: XT0262:2 | H21: LEFT SIDE PANEL | I21: 7.C4 | M21: USED
A22: XT0262:2 | B22: JC | C22: 0V | D22: CLIP | E22: --- | F22: 7.C4 | G22: XT0262:3 | H22: LEFT SIDE PANEL | I22: 7.C4 | M22: USED
A23: XT0262:3 | B23: JC | C23: 0V | D23: CLIP | E23: --- | F23: 7.C4 | G23: XT0262:4 | H23: LEFT SIDE PANEL | I23: 7.C4 | M23: USED
A24: KA5760:A1 | B24: SC | C24: 009104 | D24: WHT | E24: 16 | F24: 57.C6 | G24: AF0091:04 | H24: LEFT SIDE PANEL | I24: 57.C6 | M24: USED
A25: KA0043:A1 | B25: SC | C25: KA0043A1 | D25: WHT | E25: 20 | F25: 51.C7 | G25: AF0091:07 | H25: LEFT SIDE PANEL | I25: 51.C6 | M25: USED
... A173: XT0262:2 | B173: SC | C173: 0V | D173: WHT | E173: 14 | F173: 7.C4 | G173: AU0020:COM | H173: SCS | I173: 11.C2 | M173: USED
F175: SolarTools ver. 24.0.84.24712 (Jul 31, 2025)
A176: Report date: 3/9/2026 7:07 AM

Sheet RIGHT SIDE PANEL
A1: RIGHT SIDE PANEL
A2: ASSY,RIGHT SIDE PANEL,CONSOLE
A3: Project # | B3: 4N298
A4: Project Name | B4: P66 Iron Mesa PMS
A5: Revision | B5: B
A7: Controls DE | B7: Akanksha Maddi
A8: Phone: | B8: 9254814160
A9: Controls ME
A10: Phone:
A12: From | G12: To
A13: Device ID | B13: Cable (W) Conductor (SC) Jumper Clip (JC) | C13: Wire No. | D13: Wire ID | E13: Gauge/Size | F13: Page/Zone | G13: Device ID | H13: Location | I13: Page/Zone
A14: XT1201:1 | B14: JC | C14: FU1201 | D14: CLIP | E14: --- | F14: 15.B2 | G14: XT1201:2 | H14: RIGHT SIDE PANEL | I14: 15.C2 | M14: USED
A15: XT1201:2 | B15: JC | C15: FU1201 | D15: CLIP | E15: --- | F15: 15.C2 | G15: XT1201:3 | H15: RIGHT SIDE PANEL | I15: 15.C2 | M15: USED
A16: XT1201:3 | B16: JC | C16: FU1201 | D16: CLIP | E16: --- | F16: 15.C2 | G16: XT1201:4 | H16: RIGHT SIDE PANEL | I16: 15.C2 | M16: USED
A17: XT1201:4 | B17: JC | C17: FU1201 | D17: CLIP | E17: --- | F17: 15.C2 | G17: XT1201:5 | H17: RIGHT SIDE PANEL | I17: 15.C2 | M17: USED
A18: XT1202:1 | B18: JC | C18: 0V | D18: CLIP | E18: --- | F18: 15.C2 | G18: XT1202:2 | H18: RIGHT SIDE PANEL | I18: 15.D2 | M18: USED
A19: XT1202:2 | B19: JC | C19: 0V | D19: CLIP | E19: --- | F19: 15.D2 | G19: XT1202:3 | H19: RIGHT SIDE PANEL | I19: 15.D2 | M19: USED
A20: XT1202:3 | B20: JC | C20: 0V | D20: CLIP | E20: --- | F20: 15.D2 | G20: XT1202:4 | H20: RIGHT SIDE PANEL | I20: 15.D2 | M20: USED
A21: XT1202:4 | B21: JC | C21: 0V | D21: CLIP | E21: --- | F21: 15.D2 | G21: XT1202:5 | H21: RIGHT SIDE PANEL | I21: 15.D2 | M21: USED
A22: XT1203:1 | B22: JC | C22: KA120114 | D22: CLIP | E22: --- | F22: 15.B3 | G22: XT1203:2 | H22: RIGHT SIDE PANEL | I22: 15.C3 | M22: USED
A23: XT1203:2 | B23: JC | C23: KA120114 | D23: CLIP | E23: --- | F23: 15.C3 | G23: XT1203:3 | H23: RIGHT SIDE PANEL | I23: 15.C3 | M23: USED
A24: XT1203:3 | B24: JC | C24: KA120114 | D24: CLIP | E24: --- | F24: 15.C3 | G24: XT1203:4 | H24: RIGHT SIDE PANEL | I24: 15.C3 | M24: USED
A25: XT1203:4 | B25: JC | C25: KA120114 | D25: CLIP | E25: --- | F25: 15.C3 | G25: XT1203:5 | H25: RIGHT SIDE PANEL | I25: 15.C3 | M25: USED
... A146: AT0180:P2 | B146: WC0009 | C146: AU0090L2 | D146: ENET | E146: CABLE | F146: 15.B3 | G146: AU0090:L2 | H146: LEFT SIDE PANEL | I146: 14.B2 | M146: USED
F148: SolarTools ver. 24.0.84.24712 (Jul 31, 2025)
A149: Report date: 3/9/2026 7:07 AM

Sheet SCS
A1: SCS
A2: ASSEMBLY,SCS PANEL
A3: Project # | B3: 4N298
A4: Project Name | B4: P66 Iron Mesa PMS
A5: Revision | B5: B
A7: Controls DE | B7: Akanksha Maddi
A8: Phone: | B8: 9254814160
A9: Controls ME
A10: Phone:
A12: From | G12: To
A13: Device ID | B13: Cable (W) Conductor (SC) Jumper Clip (JC) | C13: Wire No. | D13: Wire ID | E13: Gauge/Size | F13: Page/Zone | G13: Device ID | H13: Location | I13: Page/Zone
A14: AF0021:00 | B14: SC | C14: SB1261NO | D14: WHT | E14: 20 | F14: 20.A7 | G14: SB1261:NO | H14: SCS | I14: 20.A4 | M14: USED
A15: AF0021:01 | B15: SC | C15: SB1271NO | D15: WHT | E15: 20 | F15: 20.B7 | G15: SB1271:NO | H15: SCS | I15: 20.B4 | M15: USED
A16: AF0021:02 | B16: SC | C16: SB1111NO | D16: WHT | E16: 20 | F16: 20.B7 | G16: SB1111:NO | H16: SCS | I16: 20.B4 | M16: USED
A17: AF0021:03 | B17: SC | C17: SB1281NO | D17: WHT | E17: 20 | F17: 20.C7 | G17: SB1281:NO | H17: SCS | I17: 20.C4 | M17: USED
A18: AF0021:04 | B18: SC | C18: SB1291NO | D18: WHT | E18: 20 | F18: 20.D7 | G18: SB1291:NO | H18: SCS | I18: 20.D4 | M18: USED
A19: AF0021:05 | B19: SC | C19: SB0402NO | D19: WHT | E19: 20 | F19: 19.B3 | G19: SB0402:NO | H19: SCS | I19: 19.B2 | M19: USED
A20: AF0021:06 | B20: SC | C20: SA050012 | D20: WHT | E20: 20 | F20: 19.A3 | G20: SA0500:12 | H20: SCS | I20: 19.A2 | M20: USED
A21: AF0021:07 | B21: SC | C21: SA050014 | D21: WHT | E21: 20 | F21: 19.A3 | G21: SA0500:14 | H21: SCS | I21: 19.A2 | M21: USED
A22: AF0021:08 | B22: SC | C22: SH0418NO | D22: WHT | E22: 20 | F22: 19.A6 | G22: SH0418:NO | H22: SCS | I22: 19.A5 | M22: USED
A23: AF0021:09 | B23: SC | C23: SB1262NO | D23: WHT | E23: 20 | F23: 21.A7 | G23: SB1262:NO | H23: SCS | I23: 21.A4 | M23: USED
A24: AF0021:10 | B24: SC | C24: SB1272NO | D24: WHT | E24: 20 | F24: 21.B7 | G24: SB1272:NO | H24: SCS | I24: 21.B4 | M24: USED
A25: AF0021:11 | B25: SC | C25: SB1112NO | D25: WHT | E25: 20 | F25: 21.B7 | G25: SB1112:NO | H25: SCS | I25: 21.B4 | M25: USED
... A165: XT0260:1 | B165: SC | C165: 0V | D165: WHT | E165: 12 | F165: 7.C3 | G165: XT0262:1 | H165: LEFT SIDE PANEL | I165: 7.C4 | M165: USED
F167: SolarTools ver. 24.0.84.24712 (Jul 31, 2025)
A168: Report date: 3/9/2026 7:07 AM

Sheet Panel Errors
A1: Panel Errors
A3: Project # | B3: 4N298
A4: Project Name | B4: P66 Iron Mesa PMS
A5: Revision | B5: B
A7: Controls DE | B7: Akanksha Maddi
A8: Phone: | B8: 9254814160
A9: Controls ME
A10: Phone:
A12: From | H12: To
A13: Device ID | B13: Location | C13: Cable (W) Conductor (SC) Jumper Clip (JC) | D13: Wire ID | E13: Wire No. | F13: Gauge/Size | G13: Page/Zone | H13: Device ID | I13: Location | J13: Page/Zone
A16: Report date: 3/9/2026 7:07 AM | E16: SolarTools ver. 24.0.84.24712 (Jul 31, 2025)

Sheet Cable Part Numbers
A1: Cable Part Numbers | D1: SolarTools ver. 24.0.84.24712 (Jul 31, 2025)
A2: Project # | B2: 4N298
D3: Report date: 3/9/2026 7:07 AM
A4: Project Name | B4: P66 Iron Mesa PMS
A6: Revision | B6: B
A8: Controls DE | B8: Akanksha Maddi
A9: Phone: | B9: 9254814160
A10: Controls ME
A11: Phone:
A13: Device ID | C13: Part Number | E13: Description
A14: W0682 | C14: 1302073-36 | E14: CABLE, ETHERNET - 36 INCHES
A15: WC0001 | C15: 1302073-36 | E15: CABLE, COMMUNICATION CABLE - 36 INCHES
A16: WC0002 | C16: 1302073-36 | E16: CABLE, COMMUNICATION CABLE - 36 INCHES
A17: WC0004 | C17: 1302073-36 | E17: CABLE, COMMUNICATION CABLE - 36 INCHES
A18: WC0005 | C18: 1302073-36 | E18: CABLE, COMMUNICATION CABLE - 36 INCHES
A19: WC0006 | C19: 1302073-36 | E19: CABLE, COMMUNICATION CABLE - 36 INCHES
A20: WC0009 | C20: 1302073-36 | E20: CABLE, COMMUNICATION CABLE - 36 INCHES
A21: WC0018 | C21: 1302073-36 | E21: CABLE, COMMUNICATION CABLE - 36 INCHES
A22: WC0060 | C22: 1302073-36 | E22: CABLE, ETHERNET - 36 INCHES
A23: WC0680 | C23: 1302073-36 | E23: CABLE, COMMUNICATION CABLE - 36 INCHES
A24: WC5540 | C24: PART OF 1113568-200 | E24: CABLE, 2 CONDUCTOR TRIMMED SHIELD PART OF HORN
... A27: WC0020 | C27: 2684693-54 | E27: CABLE, EXTENSION, BACKPLANE

Sheet Part Number List
A1: Part Number List | C1: SolarTools ver. 24.0.84.24712 (Jul 31, 2025)
A2: Project # | B2: 4N298
C3: Report date: 3/9/2026 7:07 AM
A4: Project Name | B4: P66 Iron Mesa PMS
A6: Revision | B6: B
A8: Controls DE | B8: Akanksha Maddi
A9: Phone: | B9: 9254814160
A10: Controls ME
A11: Phone:
A13: Device ID | B13: Part Number | C13: Description | D13: Location
A14: AF0041 | B14: 2684693-17,2684693-23 | C14: 5094-IB16XT, 16 DISCRETE INPUT | D14: BACK PANEL
A15: AF0042 | B15: 2684693-17,2684693-23 | C15: 5094-IB16XT, 16 DISCRETE INPUT | D15: BACK PANEL
A16: AF0043 | B16: 2684693-17,2684693-23 | C16: 5094-IB16XT, 16 DISCRETE INPUT | D16: BACK PANEL
A17: AF0044 | B17: 2684693-17,2684693-23 | C17: 5094-IB16XT, 16 DISCRETE INPUT | D17: BACK PANEL
A18: AF0045 | B18: 2684693-17,2684693-23 | C18: 5094-IB16XT, 16 DISCRETE INPUT | D18: BACK PANEL
A19: AF0046 | B19: 2684693-17,2684693-23 | C19: 5094-IB16XT, 16 DISCRETE INPUT | D19: BACK PANEL
A20: AF0047 | B20: 2684693-17,2684693-23 | C20: 5094-IB16XT, 16 DISCRETE INPUT | D20: BACK PANEL
A21: AF0051 | B21: 2684693-17,2684693-23 | C21: 5094-IB16XT, 16 DISCRETE INPUT | D21: BACK PANEL
A22: AF0052 | B22: 2684693-17,2684693-23 | C22: 5094-IB16XT, 16 DISCRETE INPUT | D22: BACK PANEL
A23: AF0053 | B23: 2684693-17,2684693-23 | C23: 5094-IB16XT, 16 DISCRETE INPUT | D23: BACK PANEL
A24: AF0061 | B24: 2684693-19,2684693-33 | C24: 5094-IY8XT, 8 ANALOG INPUT,TC/RTD/I&V | D24: BACK PANEL
... A275: SH0418 | B275: 964902C1 | C275: LIGHTED SWITCH, LAMP TEST | D275: SCS
A276: WC0020 | B276: 2684693-54 | D276: SCS
A277: XT0137 | B277: 1066730-7,1066730-8,1067996-4 | C277: TERMINAL BLOCK, SPRING, 4 CONDUCTOR,30-12 AWG (0.05-3.31 MM2),NON-IS | D277: SCS
A278: XT0260 | B278: 1066730-7,1067996-4 | C278: TERMINAL BLOCK, SPRING, 4 CONDUCTOR,30-12 AWG (0.05-3.31 MM2),NON-IS | D278: SCS

Sheet SCS_S
A1: SCS
A2: ASSEMBLY,SCS PANEL
A3: Project # | B3: 4N298
A4: Project Name | B4: P66 Iron Mesa PMS
A5: Revision | B5: B
A7: Controls DE | B7: Akanksha Maddi
A8: Phone: | B8: 9254814160
A9: Controls ME
A10: Phone:
A12: From | G12: To
A13: Device ID | B13: Wire No. | C13: Wire ID | D13: Gauge/Size | E13: Length | F13: Device ID | G13: Location | H13: Bundle Name
A14: AF0021:01 | B14: SB1271NO | C14: WHT | D14: 20 | E14: 60 | F14: SB1271:NO | G14: SCS | H14: SB TOP
A15: AF0021:33 | B15: SB1271C | C15: WHT | D15: 20 | E15: 60 | F15: SB1271:C | G15: SCS
A17: AF0021:00 | B17: SB1261NO | C17: WHT | D17: 20 | E17: 60 | F17: SB1261:NO | G17: SCS
A18: AF0021:32 | B18: SB1261C | C18: WHT | D18: 20 | E18: 60 | F18: SB1261:C | G18: SCS
A20: AF0021:02 | B20: SB1111NO | C20: WHT | D20: 20 | E20: 60 | F20: SB1111:NO | G20: SCS
A21: AF0021:34 | B21: SB1111C | C21: WHT | D21: 20 | E21: 60 | F21: SB1111:C | G21: SCS
A23: AF0021:04 | B23: SB1291NO | C23: WHT | D23: 20 | E23: 60 | F23: SB1291:NO | G23: SCS
A24: AF0021:36 | B24: SB1291C | C24: WHT | D24: 20 | E24: 60 | F24: SB1291:C | G24: SCS
A26: AF0021:03 | B26: SB1281NO | C26: WHT | D26: 20 | E26: 60 | F26: SB1281:NO | G26: SCS
A27: AF0021:35 | B27: SB1281C | C27: WHT | D27: 20 | E27: 60 | F27: SB1281:C | G27: SCS
A29: AF0021:17 | B29: SB1273NO | C29: WHT | D29: 20 | E29: 80 | F29: SB1273:NO | G29: SCS
A30: AF0021:49 | B30: SB1273C | C30: WHT | D30: 20 | E30: 80 | F30: SB1273:C | G30: SCS
A32: AF0021:16 | B32: SB1263NO | C32: WHT | D32: 20 | E32: 80 | F32: SB1263:NO | G32: SCS
... A42: AF0021:51 | B42: SB1283C | C42: WHT | D42: 20 | E42: 80 | F42: SB1283:C | G42: SCS
A44: AF0021:05 | B44: SB0402NO | C44: WHT | D44: 20 | E44: 60 | F44: SB0402:NO | G44: SCS | H44: SB0402
A45: AF0021:37 | B45: SB0402C | C45: WHT | D45: 20 | E45: 60 | F45: SB0402:C | G45: SCS
A47: AF0021:06 | B47: SA050012 | C47: WHT | D47: 20 | E47: 60 | F47: SA0500:12 | G47: SCS | H47: SA0500
A48: AF0021:07 | B48: SA050014 | C48: WHT | D48: 20 | E48: 60 | F48: SA0500:14 | G48: SCS
A49: AF0021:38 | B49: SA050011 | C49: WHT | D49: 20 | E49: 60 | F49: SA0500:11 | G49: SCS
A50: AF0021:39 | B50: SA050013 | C50: WHT | D50: 20 | E50: 60 | F50: SA0500:13 | G50: SCS
A52: AF0021:08 | B52: SH0418NO | C52: WHT | D52: 20 | E52: 80 | F52: SH0418:NO | G52: SCS | H52: SH0418
A53: AF0021:40 | B53: SH0418C | C53: WHT | D53: 20 | E53: 80 | F53: SH0418:C | G53: SCS
A54: AF0022:11 | B54: SH0418AP | C54: WHT | D54: 20 | E54: 80 | F54: SH0418:A+ | G54: SCS
A55: AF0022:17 | B55: SH0418BP | C55: WHT | D55: 20 | E55: 80 | F55: SH0418:B+ | G55: SCS
A56: AF0022:43 | B56: SH0418A | C56: WHT | D56: 20 | E56: 80 | F56: SH0418:A | G56: SCS
A57: AF0022:49 | B57: SH0418B | C57: WHT | D57: 20 | E57: 80 | F57: SH0418:B | G57: SCS
A59: AF0021:10 | B59: SB1272NO | C59: WHT | D59: 20 | E59: 80 | F59: SB1272:NO | G59: SCS | H59: SB BOTTOM
A60: AF0021:42 | B60: SB1272C | C60: WHT | D60: 20 | E60: 80 | F60: SB1272:C | G60: SCS
A62: AF0021:09 | B62: SB1262NO | C62: WHT | D62: 20 | E62: 80 | F62: SB1262:NO | G62: SCS
...

Sheet RIGHT SIDE PANEL_S
A1: RIGHT SIDE PANEL
A2: ASSY,RIGHT SIDE PANEL,CONSOLE
A3: Project # | B3: 4N298
A4: Project Name | B4: P66 Iron Mesa PMS
A5: Revision | B5: B
A7: Controls DE | B7: Akanksha Maddi
A8: Phone: | B8: 9254814160
A9: Controls ME
A10: Phone:
A12: From | G12: To
A13: Device ID | B13: Wire No. | C13: Wire ID | D13: Gauge/Size | E13: Length | F13: Device ID | G13: Location | H13: Bundle Name
A14: AT0180:48 BAT(-) | B14: -0V | C14: WHT | D14: 14 | E14: 80 | F14: XT1202:2 | G14: RIGHT SIDE PANEL | H14: AT0180
A15: AT0180:47 BAT(+) | B15: FU1202 | C15: WHT | D15: 14 | E15: 80 | F15: FU1202:LD | G15: RIGHT SIDE PANEL
A17: AT0180:20 VBUS-N | B17: FGPT1N | C17: RED | D17: 16 | E17: 100 | F17: XT1213:1 | G17: RIGHT SIDE PANEL
A18: AT0180:16 VGEN-N | B18: FGPT3N | C18: RED | D18: 16 | E18: 100 | F18: XT1224:1 | G18: RIGHT SIDE PANEL
A19: AT0180:17 VBUS-A | B19: PT1A | C19: RED | D19: 16 | E19: 100 | F19: XT1214:1 | G19: RIGHT SIDE PANEL
A20: AT0180:18 VBUS-B | B20: PT1B | C20: RED | D20: 16 | E20: 100 | F20: XT1211:1 | G20: RIGHT SIDE PANEL
A21: AT0180:19 VBUS-C | B21: PT1C | C21: RED | D21: 16 | E21: 100 | F21: XT1212:1 | G21: RIGHT SIDE PANEL
A22: AT0180:13 VGEN-A | B22: PT2A | C22: RED | D22: 16 | E22: 100 | F22: XT1221:1 | G22: RIGHT SIDE PANEL
A23: AT0180:14 VGEN-B | B23: PT2B | C23: RED | D23: 16 | E23: 100 | F23: XT1222:1 | G23: RIGHT SIDE PANEL
A24: AT0180:15 VGEN-C | B24: PT2C | C24: RED | D24: 16 | E24: 100 | F24: XT1223:1 | G24: RIGHT SIDE PANEL
A26: KA1201:11 | B26: FU1201 | C26: WHT | D26: 20 | E26: 60 | F26: XT1201:1 | G26: RIGHT SIDE PANEL | H26: KA'S
A27: KA1201:14 | B27: KA120114 | C27: WHT | D27: 20 | E27: 60 | F27: XT1203:1 | G27: RIGHT SIDE PANEL
A28: KA1242:A1 | B28: KA120114 | C28: WHT | D28: 20 | E28: 60 | F28: XT1203:1 | G28: RIGHT SIDE PANEL
A29: KA1241:11 | B29: KA124111 | C29: WHT | D29: 20 | E29: 60 | F29: XT1261:2 | G29: RIGHT SIDE PANEL
A30: KA1241:14 | B30: KA124114 | C30: WHT | D30: 20 | E30: 60 | F30: XT1261:1 | G30: RIGHT SIDE PANEL
A31: KA1241:A1 | B31: KA1241A1 | C31: WHT | D31: 20 | E31: 60 | F31: KA1242:21 | G31: RIGHT SIDE PANEL
A32: KA1242:A2 | B32: KA1242A2 | C32: WHT | D32: 20 | E32: 60 | F32: XT1261:3 | G32: RIGHT SIDE PANEL
A34: KA1201:A2 | B34: -0V | C34: WHT | D34: 14 | E34: 60 | F34: XT1202:1 | G34: RIGHT SIDE PANEL
A35: KA1241:A2 | B35: -0V | C35: WHT | D35: 14 | E35: 60 | F35: XT1204:1 | G35: RIGHT SIDE PANEL
A37: XT1213:1 | B37: FGPT1N | C37: RED | D37: 16 | E37: 60 | F37: XT1214:2 | G37: RIGHT SIDE PANEL | H37: XT'S
A38: XT1214:2 | B38: FGPT1N | C38: RED | D38: 16 | E38: 60 | F38: XT1241:7 | G38: RIGHT SIDE PANEL
A39: XT1224:4 | B39: FGPT3N | C39: RED | D39: 16 | E39: 60 | F39: XT1243:7 | G39: RIGHT SIDE PANEL
A40: XT1213:2 | B40: PT1A | C40: RED | D40: 16 | E40: 60 | F40: XT1241:5 | G40: RIGHT SIDE PANEL
A41: XT1214:1 | B41: PT1A | C41: RED | D41: 16 | E41: 60 | F41: XT1213:2 | G41: RIGHT SIDE PANEL
A42: XT1211:2 | B42: PT1B | C42: RED | D42: 16 | E42: 60 | F42: XT1241:1 | G42: RIGHT SIDE PANEL
A43: XT1212:2 | B43: PT1C | C43: RED | D43: 16 | E43: 60 | F43: XT1241:3 | G43: RIGHT SIDE PANEL
A44: XT1221:4 | B44: PT2A | C44: RED | D44: 16 | E44: 60 | F44: XT1243:1 | G44: RIGHT SIDE PANEL
A45: XT1222:4 | B45: PT2B | C45: RED | D45: 16 | E45: 60 | F45: XT1243:3 | G45: RIGHT SIDE PANEL
A46: XT1223:4 | B46: PT2C | C46: RED | D46: 16 | E46: 60 | F46: XT1243:5 | G46: RIGHT SIDE PANEL
...

Sheet LEFT SIDE PANEL_S
A1: LEFT SIDE PANEL
A2: ASSY,LEFT SIDE PANEL,CONSOLE
A3: Project # | B3: 4N298
A4: Project Name | B4: P66 Iron Mesa PMS
A5: Revision | B5: B
A7: Controls DE | B7: Akanksha Maddi
A8: Phone: | B8: 9254814160
A9: Controls ME
A10: Phone:
A12: From | G12: To
A13: Device ID | B13: Wire No. | C13: Wire ID | D13: Gauge/Size | E13: Length | F13: Device ID | G13: Location | H13: Bundle Name
A14: KA0001:A1 | B14: KA0001A1 | C14: WHT | D14: 20 | E14: 60 | F14: AF0092:00 | G14: LEFT SIDE PANEL | H14: KA:A1
A15: KA0002:A1 | B15: KA0002A1 | C15: WHT | D15: 20 | E15: 60 | F15: AF0092:01 | G15: LEFT SIDE PANEL
A16: KA0003:A1 | B16: KA0003A1 | C16: WHT | D16: 20 | E16: 60 | F16: AF0092:02 | G16: LEFT SIDE PANEL
A17: KA0004:A1 | B17: KA0004A1 | C17: WHT | D17: 20 | E17: 60 | F17: AF0092:03 | G17: LEFT SIDE PANEL
A18: KA0005:A1 | B18: KA0005A1 | C18: WHT | D18: 20 | E18: 60 | F18: AF0092:04 | G18: LEFT SIDE PANEL
A19: KA0006:A1 | B19: KA0006A1 | C19: WHT | D19: 20 | E19: 60 | F19: AF0092:05 | G19: LEFT SIDE PANEL
A20: KA0007:A1 | B20: KA0007A1 | C20: WHT | D20: 20 | E20: 60 | F20: AF0092:06 | G20: LEFT SIDE PANEL
A21: KA0008:A1 | B21: KA0008A1 | C21: WHT | D21: 20 | E21: 60 | F21: AF0092:07 | G21: LEFT SIDE PANEL
A22: KA0009:A1 | B22: KA0009A1 | C22: WHT | D22: 20 | E22: 60 | F22: AF0092:08 | G22: LEFT SIDE PANEL
A23: KA0010:A1 | B23: KA0010A1 | C23: WHT | D23: 20 | E23: 60 | F23: AF0092:09 | G23: LEFT SIDE PANEL
A24: KA0011:A1 | B24: KA0011A1 | C24: WHT | D24: 20 | E24: 60 | F24: AF0093:00 | G24: LEFT SIDE PANEL
A25: KA0012:A1 | B25: KA0012A1 | C25: WHT | D25: 20 | E25: 60 | F25: AF0093:01 | G25: LEFT SIDE PANEL
A26: KA0013:A1 | B26: KA0013A1 | C26: WHT | D26: 20 | E26: 60 | F26: AF0093:02 | G26: LEFT SIDE PANEL
... A59: KA5760:A1 | B59: -009104 | C59: WHT | D59: 16 | E59: 60 | F59: AF0091:04 | G59: LEFT SIDE PANEL
A61: KA0001:A2 | B61: KA0001A2 | C61: WHT | D61: 20 | E61: 60 | F61: AF0092:16 | G61: LEFT SIDE PANEL | H61: KA:A2
A62: KA0002:A2 | B62: KA0002A2 | C62: WHT | D62: 20 | E62: 60 | F62: AF0092:17 | G62: LEFT SIDE PANEL
A63: KA0003:A2 | B63: KA0003A2 | C63: WHT | D63: 20 | E63: 60 | F63: AF0092:18 | G63: LEFT SIDE PANEL
A64: KA0004:A2 | B64: KA0004A2 | C64: WHT | D64: 20 | E64: 60 | F64: AF0092:19 | G64: LEFT SIDE PANEL
A65: KA0005:A2 | B65: KA0005A2 | C65: WHT | D65: 20 | E65: 60 | F65: AF0092:20 | G65: LEFT SIDE PANEL
A66: KA0006:A2 | B66: KA0006A2 | C66: WHT | D66: 20 | E66: 60 | F66: AF0092:21 | G66: LEFT SIDE PANEL
A67: KA0007:A2 | B67: KA0007A2 | C67: WHT | D67: 20 | E67: 60 | F67: AF0092:22 | G67: LEFT SIDE PANEL
A68: KA0008:A2 | B68: KA0008A2 | C68: WHT | D68: 20 | E68: 60 | F68: AF0092:23 | G68: LEFT SIDE PANEL
A69: KA0009:A2 | B69: KA0009A2 | C69: WHT | D69: 20 | E69: 60 | F69: AF0092:24 | G69: LEFT SIDE PANEL
A70: KA0010:A2 | B70: KA0010A2 | C70: WHT | D70: 20 | E70: 60 | F70: AF0092:25 | G70: LEFT SIDE PANEL
A71: KA0011:A2 | B71: KA0011A2 | C71: WHT | D71: 20 | E71: 60 | F71: AF0093:16 | G71: LEFT SIDE PANEL
A72: KA0012:A2 | B72: KA0012A2 | C72: WHT | D72: 20 | E72: 60 | F72: AF0093:17 | G72: LEFT SIDE PANEL
A73: KA0013:A2 | B73: KA0013A2 | C73: WHT | D73: 20 | E73: 60 | F73: AF0093:18 | G73: LEFT SIDE PANEL
... A106: KA5760:A2 | B106: -009120 | C106: WHT | D106: 16 | E106: 60 | F106: AF0091:20 | G106: LEFT SIDE PANEL
A108: AF0091:COM | B108: -0V | C108: WHT | D108: 14 | E108: 60 | F108: XT0090:3 | G108: LEFT SIDE PANEL | H108: AF90
...

Sheet CONSOLE_S
A1: CONSOLE
A2: ASSEMBLY CONSOLE & CONSOLE DOORS ONE BAY
A3: Project # | B3: 4N298
A4: Project Name | B4: P66 Iron Mesa PMS
A5: Revision | B5: B
A7: Controls DE | B7: Akanksha Maddi
A8: Phone: | B8: 9254814160
A9: Controls ME
A10: Phone:
A12: From | G12: To
A13: Device ID | B13: Wire No. | C13: Wire ID | D13: Gauge/Size | E13: Length | F13: Device ID | G13: Location | H13: Bundle Name
A14: AT0190:NEG | B14: -0V | C14: WHT | D14: 14 | E14: 180 | F14: XT0262:3 | G14: LEFT SIDE PANEL | H14: HMIS
A15: AT0191:NEG | B15: -0V | C15: WHT | D15: 14 | E15: 180 | F15: XT0262:3 | G15: LEFT SIDE PANEL
A16: AT0190:POS | B16: FU0190 | C16: WHT | D16: 14 | E16: 180 | F16: FU0190:LD | G16: LEFT SIDE PANEL
A17: AT0191:POS | B17: FU0190 | C17: WHT | D17: 14 | E17: 180 | F17: FU0190:LD | G17: LEFT SIDE PANEL

Sheet BACK PANEL_S
A1: BACK PANEL
A2: ASSY,BACK PANEL,CONSOLE
A3: Project # | B3: 4N298
A4: Project Name | B4: P66 Iron Mesa PMS
A5: Revision | B5: B
A7: Controls DE | B7: Akanksha Maddi
A8: Phone: | B8: 9254814160
A9: Controls ME
A10: Phone:
A12: From | G12: To
A13: Device ID | B13: Wire No. | C13: Wire ID | D13: Gauge/Size | E13: Length | F13: Device ID | G13: Location | H13: Bundle Name
A14: AF0061:06 | B14: UJ0131IOUT | C14: WHT | D14: 20 | E14: 60 | F14: UJ0131:IOUT | G14: BACK PANEL | H14: UJ0131
A15: AF0042:42 | B15: UJ0131OK1 | C15: WHT | D15: 20 | E15: 60 | F15: UJ0131:OK1 | G15: BACK PANEL
A16: AF0042:10 | B16: UJ0131OK2 | C16: WHT | D16: 20 | E16: 60 | F16: UJ0131:OK2 | G16: BACK PANEL
A17: AF0061:04 | B17: UJ0131VIN | C17: WHT | D17: 20 | E17: 60 | F17: UJ0131:VIN | G17: BACK PANEL
A19: BA0001:V1(-) | B19: -0V | C19: WHT | D19: 16 | E19: 60 | F19: XT0141:3 | G19: BACK PANEL | H19: BA'S
A20: BA0002:V1(-) | B20: -0V | C20: WHT | D20: 16 | E20: 60 | F20: XT0141:4 | G20: BACK PANEL
A21: BA0009:V1(-) | B21: -0V | C21: WHT | D21: 16 | E21: 60 | F21: XT0141:2 | G21: BACK PANEL
A22: BA0010:V1(-) | B22: -0V | C22: WHT | D22: 16 | E22: 60 | F22: XT0141:1 | G22: BACK PANEL
A23: BA0011:V1(-) | B23: -0V | C23: WHT | D23: 16 | E23: 60 | F23: XT0141:6 | G23: BACK PANEL
A24: BA0012:V1(-) | B24: -0V | C24: WHT | D24: 16 | E24: 60 | F24: XT0141:7 | G24: BACK PANEL
A25: BA0013:V1(-) | B25: -0V | C25: WHT | D25: 16 | E25: 60 | F25: XT0141:8 | G25: BACK PANEL
A26: BA0014:V1(-) | B26: -0V | C26: WHT | D26: 16 | E26: 60 | F26: XT0141:9 | G26: BACK PANEL
A27: BA0019:V1(-) | B27: -0V | C27: WHT | D27: 16 | E27: 60 | F27: XT0141:10 | G27: BACK PANEL
A28: BA0001:V1(+) | B28: BA0001P | C28: WHT | D28: 16 | E28: 60 | F28: FU0101:LD | G28: BACK PANEL
A29: BA0002:V1(+) | B29: BA0002P | C29: WHT | D29: 16 | E29: 60 | F29: FU0102:LD | G29: BACK PANEL
A30: BA0009:V1(+) | B30: BA0009P | C30: WHT | D30: 16 | E30: 60 | F30: FU0109:LD | G30: BACK PANEL
A31: BA0010:V1(+) | B31: BA0010P | C31: WHT | D31: 16 | E31: 60 | F31: FU0110:LD | G31: BACK PANEL
... A42: BA1215:+ | B42: FU1215 | C42: WHT | D42: 16 | E42: 60 | F42: FU1215:LD | G42: BACK PANEL
A44: AF0062:01 | B44: -006201 | C44: WHT | D44: 20 | E44: 60 | F44: XT0085:2 | G44: BACK PANEL | H44: AF60
A45: AF0062:17 | B45: -0V | C45: WHT | D45: 20 | E45: 60 | F45: XT0085:3 | G45: BACK PANEL
A47: AF0061:05 | B47: -0V | C47: WHT | D47: 14 | E47: 60 | F47: XT0135:3 | G47: BACK PANEL
A48: AF0061:07 | B48: -0V | C48: WHT | D48: 14 | E48: 60 | F48: XT0135:4 | G48: BACK PANEL
A49: AU0060:COM | B49: -0V | C49: WHT | D49: 14 | E49: 60 | F49: XT0135:2 | G49: BACK PANEL
A50: AU0060:V+ | B50: FU0060 | C50: WHT | D50: 14 | E50: 60 | F50: FU0060:LD | G50: BACK PANEL
A52: UV0600:(-) | B52: -0V | C52: WHT | D52: 14 | E52: 80 | F52: XT0135:1 | G52: BACK PANEL | H52: UV0600
A53: FU0010:LD | B53: FU0010 | C53: WHT | D53: 14 | E53: 80 | F53: UV0600:(+) | G53: BACK PANEL
A55: AT0680:NEG | B55: -0V | C55: WHT | D55: 14 | E55: 60 | F55: XT0680:2 | G55: BACK PANEL | H55: AT0680
A56: AT0680:POS | B56: AT0680POS | C56: WHT | D56: 14 | E56: 60 | F56: XT0680:1 | G56: BACK PANEL
A58: AU0040:COM | B58: -0V | C58: WHT | D58: 14 | E58: 60 | F58: XT0135:2 | G58: BACK PANEL | H58: AF40/50
...

Sheet Bundle Tag Info
A1: PSX-GLDSC STAT
A2: 4N298
A3: REV.B1
A6: SCS | B6: R/S PNL | C6: L/S PNL | D6: CONSOLE | E6: BACK PNL | F6: Panel Name | G6: Panel Name | H6: Panel Name | I6: Panel Name | J6: Panel Name | K6: Panel Name | L6: Panel Name | M6: Panel Name | N6: Panel Name | O6: Panel Name | P6: Panel Name | Q6: Panel Name | R6: Panel Name | S6: Panel Name | T6: Panel Name | U6: Panel Name | V6: Panel Name | W6: Panel Name | X6: Panel Name | Y6: Panel Name | Z6: Panel Name | AA6: Panel Name | AB6: Panel Name | AC6: Panel Name | AD6: Panel Name
A7: SB TOP | B7: AT0180 | C7: KA:A1 | D7: HMIS | E7: UJ0131
A8: SB0402 | B8: KA'S | C8: KA:A2 | E8: BA'S
A9: SA0500 | B9: XT'S | C9: AF90 | E9: AF60
A10: SH0418 | B10: FU'S | C10: FU'S | E10: UV0600
A11: SB BOTTOM | C11: XT'S | E11: AT0680
A12: SB0403 | C12: TO BACK | E12: AF40/50
A13: HL TOP | C13: TO RIGHT | E13: FU'S
A14: HL BOTTOM | E14: XT'S
A15: SB0403 | E15: QS0011
A16: AF2-L PNL | E16: TO RIGHT
A17: TO BACK PNL

Sheet ALL
A1: ALL
A2: =IF('Bundle Tag Info'!A$7<>"",CONCATENATE('Bundle Tag Info'!$A$1," ",CHAR(10),'Bundle Tag Info'!$A$2," ",'Bundle Tag Info'!$A$3,CHAR(10),'Bundle Tag Info'!A$6,CHAR(10),'Bundle Tag Info'!A$7),"") -> PSX-GLDSC STAT 4N298 REV.B1 SCS SB TOP | F2: =IF('Bundle Tag Info'!F$7<>"",CONCATENATE('Bundle Tag Info'!$A$1," ",CHAR(10),'Bundle Tag Info'!$A$2," ",'Bundle Tag Info'!$A$3,CHAR(10),'Bundle Tag Info'!F$6,CHAR(10),'Bundle Tag Info'!F$7),"") | G2: =IF('Bundle Tag Info'!G$7<>"",CONCATENATE('Bundle Tag Info'!$A$1," ",CHAR(10),'Bundle Tag Info'!$A$2," ",'Bundle Tag Info'!$A$3,CHAR(10),'Bundle Tag Info'!G$6,CHAR(10),'Bundle Tag Info'!G$7),"") | H2: =IF('Bundle Tag Info'!H$7<>"",CONCATENATE('Bundle Tag Info'!$A$1," ",CHAR(10),'Bundle Tag Info'!$A$2," ",'Bundle Tag Info'!$A$3,CHAR(10),'Bundle Tag Info'!H$6,CHAR(10),'Bundle Tag Info'!H$7),"") | I2: =IF('Bundle Tag Info'!I$7<>"",CONCATENATE('Bundle Tag Info'!$A$1," ",CHAR(10),'Bundle Tag Info'!$A$2," ",'Bundle Tag Info'!$A$3,CHAR(10),'Bundle Tag Info'!I$6,CHAR(10),'Bundle Tag Info'!I$7),"") | J2: =IF('Bundle Tag Info'!J$7<>"",CONCATENATE('Bundle Tag Info'!$A$1," ",CHAR(10),'Bundle Tag Info'!$A$2," ",'Bundle Tag Info'!$A$3,CHAR(10),'Bundle Tag Info'!J$6,CHAR(10),'Bundle Tag Info'!J$7),"") | K2: =IF('Bundle Tag Info'!K$7<>"",CONCATENATE('Bundle Tag Info'!$A$1," ",CHAR(10),'Bundle Tag Info'!$A$2," ",'Bundle Tag Info'!$A$3,CHAR(10),'Bundle Tag Info'!K$6,CHAR(10),'Bundle Tag Info'!K$7),"") | L2: =IF('Bundle Tag Info'!L$7<>"",CONCATENATE('Bundle Tag Info'!$A$1," ",CHAR(10),'Bundle Tag Info'!$A$2," ",'Bundle Tag Info'!$A$3,CHAR(10),'Bundle Tag Info'!L$6,CHAR(10),'Bundle Tag Info'!L$7),"") | M2: =IF('Bundle Tag Info'!M$7<>"",CONCATENATE('Bundle Tag Info'!$A$1," ",CHAR(10),'Bundle Tag Info'!$A$2," ",'Bundle Tag Info'!$A$3,CHAR(10),'Bundle Tag Info'!M$6,CHAR(10),'Bundle Tag Info'!M$7),"") | ... AD2: =IF('Bundle Tag Info'!AD$7<>"",CONCATENATE('Bundle Tag Info'!$A$1," ",CHAR(10),'Bundle Tag Info'!$A$2," ",'Bundle Tag Info'!$A$3,CHAR(10),'Bundle Tag Info'!AD$6,CHAR(10),'Bundle Tag Info'!AD$7),"")
A3: =IF('Bundle Tag Info'!A$8<>"",CONCATENATE('Bundle Tag Info'!$A$1," ",CHAR(10),'Bundle Tag Info'!$A$2," ",'Bundle Tag Info'!$A$3,CHAR(10),'Bundle Tag Info'!A$6,CHAR(10),'Bundle Tag Info'!A$8),"") -> PSX-GLDSC STAT 4N298 REV.B1 SCS SB0402 | D3: =IF('Bundle Tag Info'!D$8<>"",CONCATENATE('Bundle Tag Info'!$A$1," ",CHAR(10),'Bundle Tag Info'!$A$2," ",'Bundle Tag Info'!$A$3,CHAR(10),'Bundle Tag Info'!D$6,CHAR(10),'Bundle Tag Info'!D$8),"") | F3: =IF('Bundle Tag Info'!F$8<>"",CONCATENATE('Bundle Tag Info'!$A$1," ",CHAR(10),'Bundle Tag Info'!$A$2," ",'Bundle Tag Info'!$A$3,CHAR(10),'Bundle Tag Info'!F$6,CHAR(10),'Bundle Tag Info'!F$8),"") | G3: =IF('Bundle Tag Info'!G$8<>"",CONCATENATE('Bundle Tag Info'!$A$1," ",CHAR(10),'Bundle Tag Info'!$A$2," ",'Bundle Tag Info'!$A$3,CHAR(10),'Bundle Tag Info'!G$6,CHAR(10),'Bundle Tag Info'!G$8),"") | H3: =IF('Bundle Tag Info'!H$8<>"",CONCATENATE('Bundle Tag Info'!$A$1," ",CHAR(10),'Bundle Tag Info'!$A$2," ",'Bundle Tag Info'!$A$3,CHAR(10),'Bundle Tag Info'!H$6,CHAR(10),'Bundle Tag Info'!H$8),"") | I3: =IF('Bundle Tag Info'!I$8<>"",CONCATENATE('Bundle Tag Info'!$A$1," ",CHAR(10),'Bundle Tag Info'!$A$2," ",'Bundle Tag Info'!$A$3,CHAR(10),'Bundle Tag Info'!I$6,CHAR(10),'Bundle Tag Info'!I$8),"") | J3: =IF('Bundle Tag Info'!J$8<>"",CONCATENATE('Bundle Tag Info'!$A$1," ",CHAR(10),'Bundle Tag Info'!$A$2," ",'Bundle Tag Info'!$A$3,CHAR(10),'Bundle Tag Info'!J$6,CHAR(10),'Bundle Tag Info'!J$8),"") | K3: =IF('Bundle Tag Info'!K$8<>"",CONCATENATE('Bundle Tag Info'!$A$1," ",CHAR(10),'Bundle Tag Info'!$A$2," ",'Bundle Tag Info'!$A$3,CHAR(10),'Bundle Tag Info'!K$6,CHAR(10),'Bundle Tag Info'!K$8),"") | L3: =IF('Bundle Tag Info'!L$8<>"",CONCATENATE('Bundle Tag Info'!$A$1," ",CHAR(10),'Bundle Tag Info'!$A$2," ",'Bundle Tag Info'!$A$3,CHAR(10),'Bundle Tag Info'!L$6,CHAR(10),'Bundle Tag Info'!L$8),"") | M3: =IF('Bundle Tag Info'!M$8<>"",CONCATENATE('Bundle Tag Info'!$A$1," ",CHAR(10),'Bundle Tag Info'!$A$2," ",'Bundle Tag Info'!$A$3,CHAR(10),'Bundle Tag Info'!M$6,CHAR(10),'Bundle Tag Info'!M$8),"") | ... AD3: =IF('Bundle Tag Info'!AD$8<>"",CONCATENATE('Bundle Tag Info'!$A$1," ",CHAR(10),'Bundle Tag Info'!$A$2," ",'Bundle Tag Info'!$A$3,CHAR(10),'Bundle Tag Info'!AD$6,CHAR(10),'Bundle Tag Info'!AD$8),"")
A4: =IF('Bundle Tag Info'!A$9<>"",CONCATENATE('Bundle Tag Info'!$A$1," ",CHAR(10),'Bundle Tag Info'!$A$2," ",'Bundle Tag Info'!$A$3,CHAR(10),'Bundle Tag Info'!A$6,CHAR(10),'Bundle Tag Info'!A$9),"") -> PSX-GLDSC STAT 4N298 REV.B1 SCS SA0500 | D4: =IF('Bundle Tag Info'!D$9<>"",CONCATENATE('Bundle Tag Info'!$A$1," ",CHAR(10),'Bundle Tag Info'!$A$2," ",'Bundle Tag Info'!$A$3,CHAR(10),'Bundle Tag Info'!D$6,CHAR(10),'Bundle Tag Info'!D$9),"") | F4: =IF('Bundle Tag Info'!F$9<>"",CONCATENATE('Bundle Tag Info'!$A$1," ",CHAR(10),'Bundle Tag Info'!$A$2," ",'Bundle Tag Info'!$A$3,CHAR(10),'Bundle Tag Info'!F$6,CHAR(10),'Bundle Tag Info'!F$9),"") | G4: =IF('Bundle Tag Info'!G$9<>"",CONCATENATE('Bundle Tag Info'!$A$1," ",CHAR(10),'Bundle Tag Info'!$A$2," ",'Bundle Tag Info'!$A$3,CHAR(10),'Bundle Tag Info'!G$6,CHAR(10),'Bundle Tag Info'!G$9),"") | H4: =IF('Bundle Tag Info'!H$9<>"",CONCATENATE('Bundle Tag Info'!$A$1," ",CHAR(10),'Bundle Tag Info'!$A$2," ",'Bundle Tag Info'!$A$3,CHAR(10),'Bundle Tag Info'!H$6,CHAR(10),'Bundle Tag Info'!H$9),"") | I4: =IF('Bundle Tag Info'!I$9<>"",CONCATENATE('Bundle Tag Info'!$A$1," ",CHAR(10),'Bundle Tag Info'!$A$2," ",'Bundle Tag Info'!$A$3,CHAR(10),'Bundle Tag Info'!I$6,CHAR(10),'Bundle Tag Info'!I$9),"") | J4: =IF('Bundle Tag Info'!J$9<>"",CONCATENATE('Bundle Tag Info'!$A$1," ",CHAR(10),'Bundle Tag Info'!$A$2," ",'Bundle Tag Info'!$A$3,CHAR(10),'Bundle Tag Info'!J$6,CHAR(10),'Bundle Tag Info'!J$9),"") | K4: =IF('Bundle Tag Info'!K$9<>"",CONCATENATE('Bundle Tag Info'!$A$1," ",CHAR(10),'Bundle Tag Info'!$A$2," ",'Bundle Tag Info'!$A$3,CHAR(10),'Bundle Tag Info'!K$6,CHAR(10),'Bundle Tag Info'!K$9),"") | L4: =IF('Bundle Tag Info'!L$9<>"",CONCATENATE('Bundle Tag Info'!$A$1," ",CHAR(10),'Bundle Tag Info'!$A$2," ",'Bundle Tag Info'!$A$3,CHAR(10),'Bundle Tag Info'!L$6,CHAR(10),'Bundle Tag Info'!L$9),"") | M4: =IF('Bundle Tag Info'!M$9<>"",CONCATENATE('Bundle Tag Info'!$A$1," ",CHAR(10),'Bundle Tag Info'!$A$2," ",'Bundle Tag Info'!$A$3,CHAR(10),'Bundle Tag Info'!M$6,CHAR(10),'Bundle Tag Info'!M$9),"") | ... AD4: =IF('Bundle Tag Info'!AD$9<>"",CONCATENATE('Bundle Tag Info'!$A$1," ",CHAR(10),'Bundle Tag Info'!$A$2," ",'Bundle Tag Info'!$A$3,CHAR(10),'Bundle Tag Info'!AD$6,CHAR(10),'Bundle Tag Info'!AD$9),"")
A5: =IF('Bundle Tag Info'!A$10<>"",CONCATENATE('Bundle Tag Info'!$A$1," ",CHAR(10),'Bundle Tag Info'!$A$2," ",'Bundle Tag Info'!$A$3,CHAR(10),'Bundle Tag Info'!A$6,CHAR(10),'Bundle Tag Info'!A$10),"") -> PSX-GLDSC STAT 4N298 REV.B1 SCS SH0418 | D5: =IF('Bundle Tag Info'!D$10<>"",CONCATENATE('Bundle Tag Info'!$A$1," ",CHAR(10),'Bundle Tag Info'!$A$2," ",'Bundle Tag Info'!$A$3,CHAR(10),'Bundle Tag Info'!D$6,CHAR(10),'Bundle Tag Info'!D$10),"") | F5: =IF('Bundle Tag Info'!F$10<>"",CONCATENATE('Bundle Tag Info'!$A$1," ",CHAR(10),'Bundle Tag Info'!$A$2," ",'Bundle Tag Info'!$A$3,CHAR(10),'Bundle Tag Info'!F$6,CHAR(10),'Bundle Tag Info'!F$10),"") | G5: =IF('Bundle Tag Info'!G$10<>"",CONCATENATE('Bundle Tag Info'!$A$1," ",CHAR(10),'Bundle Tag Info'!$A$2," ",'Bundle Tag Info'!$A$3,CHAR(10),'Bundle Tag Info'!G$6,CHAR(10),'Bundle Tag Info'!G$10),"") | H5: =IF('Bundle Tag Info'!H$10<>"",CONCATENATE('Bundle Tag Info'!$A$1," ",CHAR(10),'Bundle Tag Info'!$A$2," ",'Bundle Tag Info'!$A$3,CHAR(10),'Bundle Tag Info'!H$6,CHAR(10),'Bundle Tag Info'!H$10),"") | I5: =IF('Bundle Tag Info'!I$10<>"",CONCATENATE('Bundle Tag Info'!$A$1," ",CHAR(10),'Bundle Tag Info'!$A$2," ",'Bundle Tag Info'!$A$3,CHAR(10),'Bundle Tag Info'!I$6,CHAR(10),'Bundle Tag Info'!I$10),"") | J5: =IF('Bundle Tag Info'!J$10<>"",CONCATENATE('Bundle Tag Info'!$A$1," ",CHAR(10),'Bundle Tag Info'!$A$2," ",'Bundle Tag Info'!$A$3,CHAR(10),'Bundle Tag Info'!J$6,CHAR(10),'Bundle Tag Info'!J$10),"") | K5: =IF('Bundle Tag Info'!K$10<>"",CONCATENATE('Bundle Tag Info'!$A$1," ",CHAR(10),'Bundle Tag Info'!$A$2," ",'Bundle Tag Info'!$A$3,CHAR(10),'Bundle Tag Info'!K$6,CHAR(10),'Bundle Tag Info'!K$10),"") | L5: =IF('Bundle Tag Info'!L$10<>"",CONCATENATE('Bundle Tag Info'!$A$1," ",CHAR(10),'Bundle Tag Info'!$A$2," ",'Bundle Tag Info'!$A$3,CHAR(10),'Bundle Tag Info'!L$6,CHAR(10),'Bundle Tag Info'!L$10),"") | M5: =IF('Bundle Tag Info'!M$10<>"",CONCATENATE('Bundle Tag Info'!$A$1," ",CHAR(10),'Bundle Tag Info'!$A$2," ",'Bundle Tag Info'!$A$3,CHAR(10),'Bundle Tag Info'!M$6,CHAR(10),'Bundle Tag Info'!M$10),"") | ... AD5: =IF('Bundle Tag Info'!AD$10<>"",CONCATENATE('Bundle Tag Info'!$A$1," ",CHAR(10),'Bundle Tag Info'!$A$2," ",'Bundle Tag Info'!$A$3,CHAR(10),'Bundle Tag Info'!AD$6,CHAR(10),'Bundle Tag Info'!AD$10),"")
A6: =IF('Bundle Tag Info'!A$11<>"",CONCATENATE('Bundle Tag Info'!$A$1," ",CHAR(10),'Bundle Tag Info'!$A$2," ",'Bundle Tag Info'!$A$3,CHAR(10),'Bundle Tag Info'!A$6,CHAR(10),'Bundle Tag Info'!A$11),"") -> PSX-GLDSC STAT 4N298 REV.B1 SCS SB BOTTOM | B6: =IF('Bundle Tag Info'!B$11<>"",CONCATENATE('Bundle Tag Info'!$A$1," ",CHAR(10),'Bundle Tag Info'!$A$2," ",'Bundle Tag Info'!$A$3,CHAR(10),'Bundle Tag Info'!B$6,CHAR(10),'Bundle Tag Info'!B$11),"") | D6: =IF('Bundle Tag Info'!D$11<>"",CONCATENATE('Bundle Tag Info'!$A$1," ",CHAR(10),'Bundle Tag Info'!$A$2," ",'Bundle Tag Info'!$A$3,CHAR(10),'Bundle Tag Info'!D$6,CHAR(10),'Bundle Tag Info'!D$11),"") | F6: =IF('Bundle Tag Info'!F$11<>"",CONCATENATE('Bundle Tag Info'!$A$1," ",CHAR(10),'Bundle Tag Info'!$A$2," ",'Bundle Tag Info'!$A$3,CHAR(10),'Bundle Tag Info'!F$6,CHAR(10),'Bundle Tag Info'!F$11),"") | G6: =IF('Bundle Tag Info'!G$11<>"",CONCATENATE('Bundle Tag Info'!$A$1," ",CHAR(10),'Bundle Tag Info'!$A$2," ",'Bundle Tag Info'!$A$3,CHAR(10),'Bundle Tag Info'!G$6,CHAR(10),'Bundle Tag Info'!G$11),"") | H6: =IF('Bundle Tag Info'!H$11<>"",CONCATENATE('Bundle Tag Info'!$A$1," ",CHAR(10),'Bundle Tag Info'!$A$2," ",'Bundle Tag Info'!$A$3,CHAR(10),'Bundle Tag Info'!H$6,CHAR(10),'Bundle Tag Info'!H$11),"") | I6: =IF('Bundle Tag Info'!I$11<>"",CONCATENATE('Bundle Tag Info'!$A$1," ",CHAR(10),'Bundle Tag Info'!$A$2," ",'Bundle Tag Info'!$A$3,CHAR(10),'Bundle Tag Info'!I$6,CHAR(10),'Bundle Tag Info'!I$11),"") | J6: =IF('Bundle Tag Info'!J$11<>"",CONCATENATE('Bundle Tag Info'!$A$1," ",CHAR(10),'Bundle Tag Info'!$A$2," ",'Bundle Tag Info'!$A$3,CHAR(10),'Bundle Tag Info'!J$6,CHAR(10),'Bundle Tag Info'!J$11),"") | K6: =IF('Bundle Tag Info'!K$11<>"",CONCATENATE('Bundle Tag Info'!$A$1," ",CHAR(10),'Bundle Tag Info'!$A$2," ",'Bundle Tag Info'!$A$3,CHAR(10),'Bundle Tag Info'!K$6,CHAR(10),'Bundle Tag Info'!K$11),"") | L6: =IF('Bundle Tag Info'!L$11<>"",CONCATENATE('Bundle Tag Info'!$A$1," ",CHAR(10),'Bundle Tag Info'!$A$2," ",'Bundle Tag Info'!$A$3,CHAR(10),'Bundle Tag Info'!L$6,CHAR(10),'Bundle Tag Info'!L$11),"") | M6: =IF('Bundle Tag Info'!M$11<>"",CONCATENATE('Bundle Tag Info'!$A$1," ",CHAR(10),'Bundle Tag Info'!$A$2," ",'Bundle Tag Info'!$A$3,CHAR(10),'Bundle Tag Info'!M$6,CHAR(10),'Bundle Tag Info'!M$11),"") | ... AD6: =IF('Bundle Tag Info'!AD$11<>"",CONCATENATE('Bundle Tag Info'!$A$1," ",CHAR(10),'Bundle Tag Info'!$A$2," ",'Bundle Tag Info'!$A$3,CHAR(10),'Bundle Tag Info'!AD$6,CHAR(10),'Bundle Tag Info'!AD$11),"")
A7: =IF('Bundle Tag Info'!A$12<>"",CONCATENATE('Bundle Tag Info'!$A$1," ",CHAR(10),'Bundle Tag Info'!$A$2," ",'Bundle Tag Info'!$A$3,CHAR(10),'Bundle Tag Info'!A$6,CHAR(10),'Bundle Tag Info'!A$12),"") -> PSX-GLDSC STAT 4N298 REV.B1 SCS SB0403 | B7: =IF('Bundle Tag Info'!B$12<>"",CONCATENATE('Bundle Tag Info'!$A$1," ",CHAR(10),'Bundle Tag Info'!$A$2," ",'Bundle Tag Info'!$A$3,CHAR(10),'Bundle Tag Info'!B$6,CHAR(10),'Bundle Tag Info'!B$12),"") | D7: =IF('Bundle Tag Info'!D$12<>"",CONCATENATE('Bundle Tag Info'!$A$1," ",CHAR(10),'Bundle Tag Info'!$A$2," ",'Bundle Tag Info'!$A$3,CHAR(10),'Bundle Tag Info'!D$6,CHAR(10),'Bundle Tag Info'!D$12),"") | F7: =IF('Bundle Tag Info'!F$12<>"",CONCATENATE('Bundle Tag Info'!$A$1," ",CHAR(10),'Bundle Tag Info'!$A$2," ",'Bundle Tag Info'!$A$3,CHAR(10),'Bundle Tag Info'!F$6,CHAR(10),'Bundle Tag Info'!F$12),"") | G7: =IF('Bundle Tag Info'!G$12<>"",CONCATENATE('Bundle Tag Info'!$A$1," ",CHAR(10),'Bundle Tag Info'!$A$2," ",'Bundle Tag Info'!$A$3,CHAR(10),'Bundle Tag Info'!G$6,CHAR(10),'Bundle Tag Info'!G$12),"") | H7: =IF('Bundle Tag Info'!H$12<>"",CONCATENATE('Bundle Tag Info'!$A$1," ",CHAR(10),'Bundle Tag Info'!$A$2," ",'Bundle Tag Info'!$A$3,CHAR(10),'Bundle Tag Info'!H$6,CHAR(10),'Bundle Tag Info'!H$12),"") | I7: =IF('Bundle Tag Info'!I$12<>"",CONCATENATE('Bundle Tag Info'!$A$1," ",CHAR(10),'Bundle Tag Info'!$A$2," ",'Bundle Tag Info'!$A$3,CHAR(10),'Bundle Tag Info'!I$6,CHAR(10),'Bundle Tag Info'!I$12),"") | J7: =IF('Bundle Tag Info'!J$12<>"",CONCATENATE('Bundle Tag Info'!$A$1," ",CHAR(10),'Bundle Tag Info'!$A$2," ",'Bundle Tag Info'!$A$3,CHAR(10),'Bundle Tag Info'!J$6,CHAR(10),'Bundle Tag Info'!J$12),"") | K7: =IF('Bundle Tag Info'!K$12<>"",CONCATENATE('Bundle Tag Info'!$A$1," ",CHAR(10),'Bundle Tag Info'!$A$2," ",'Bundle Tag Info'!$A$3,CHAR(10),'Bundle Tag Info'!K$6,CHAR(10),'Bundle Tag Info'!K$12),"") | L7: =IF('Bundle Tag Info'!L$12<>"",CONCATENATE('Bundle Tag Info'!$A$1," ",CHAR(10),'Bundle Tag Info'!$A$2," ",'Bundle Tag Info'!$A$3,CHAR(10),'Bundle Tag Info'!L$6,CHAR(10),'Bundle Tag Info'!L$12),"") | M7: =IF('Bundle Tag Info'!M$12<>"",CONCATENATE('Bundle Tag Info'!$A$1," ",CHAR(10),'Bundle Tag Info'!$A$2," ",'Bundle Tag Info'!$A$3,CHAR(10),'Bundle Tag Info'!M$6,CHAR(10),'Bundle Tag Info'!M$12),"") | ... AD7: =IF('Bundle Tag Info'!AD$12<>"",CONCATENATE('Bundle Tag Info'!$A$1," ",CHAR(10),'Bundle Tag Info'!$A$2," ",'Bundle Tag Info'!$A$3,CHAR(10),'Bundle Tag Info'!AD$6,CHAR(10),'Bundle Tag Info'!AD$12),"")
A8: =IF('Bundle Tag Info'!A$13<>"",CONCATENATE('Bundle Tag Info'!$A$1," ",CHAR(10),'Bundle Tag Info'!$A$2," ",'Bundle Tag Info'!$A$3,CHAR(10),'Bundle Tag Info'!A$6,CHAR(10),'Bundle Tag Info'!A$13),"") -> PSX-GLDSC STAT 4N298 REV.B1 SCS HL TOP | B8: =IF('Bundle Tag Info'!B$13<>"",CONCATENATE('Bundle Tag Info'!$A$1," ",CHAR(10),'Bundle Tag Info'!$A$2," ",'Bundle Tag Info'!$A$3,CHAR(10),'Bundle Tag Info'!B$6,CHAR(10),'Bundle Tag Info'!B$13),"") | D8: =IF('Bundle Tag Info'!D$13<>"",CONCATENATE('Bundle Tag Info'!$A$1," ",CHAR(10),'Bundle Tag Info'!$A$2," ",'Bundle Tag Info'!$A$3,CHAR(10),'Bundle Tag Info'!D$6,CHAR(10),'Bundle Tag Info'!D$13),"") | F8: =IF('Bundle Tag Info'!F$13<>"",CONCATENATE('Bundle Tag Info'!$A$1," ",CHAR(10),'Bundle Tag Info'!$A$2," ",'Bundle Tag Info'!$A$3,CHAR(10),'Bundle Tag Info'!F$6,CHAR(10),'Bundle Tag Info'!F$13),"") | G8: =IF('Bundle Tag Info'!G$13<>"",CONCATENATE('Bundle Tag Info'!$A$1," ",CHAR(10),'Bundle Tag Info'!$A$2," ",'Bundle Tag Info'!$A$3,CHAR(10),'Bundle Tag Info'!G$6,CHAR(10),'Bundle Tag Info'!G$13),"") | H8: =IF('Bundle Tag Info'!H$13<>"",CONCATENATE('Bundle Tag Info'!$A$1," ",CHAR(10),'Bundle Tag Info'!$A$2," ",'Bundle Tag Info'!$A$3,CHAR(10),'Bundle Tag Info'!H$6,CHAR(10),'Bundle Tag Info'!H$13),"") | I8: =IF('Bundle Tag Info'!I$13<>"",CONCATENATE('Bundle Tag Info'!$A$1," ",CHAR(10),'Bundle Tag Info'!$A$2," ",'Bundle Tag Info'!$A$3,CHAR(10),'Bundle Tag Info'!I$6,CHAR(10),'Bundle Tag Info'!I$13),"") | J8: =IF('Bundle Tag Info'!J$13<>"",CONCATENATE('Bundle Tag Info'!$A$1," ",CHAR(10),'Bundle Tag Info'!$A$2," ",'Bundle Tag Info'!$A$3,CHAR(10),'Bundle Tag Info'!J$6,CHAR(10),'Bundle Tag Info'!J$13),"") | K8: =IF('Bundle Tag Info'!K$13<>"",CONCATENATE('Bundle Tag Info'!$A$1," ",CHAR(10),'Bundle Tag Info'!$A$2," ",'Bundle Tag Info'!$A$3,CHAR(10),'Bundle Tag Info'!K$6,CHAR(10),'Bundle Tag Info'!K$13),"") | L8: =IF('Bundle Tag Info'!L$13<>"",CONCATENATE('Bundle Tag Info'!$A$1," ",CHAR(10),'Bundle Tag Info'!$A$2," ",'Bundle Tag Info'!$A$3,CHAR(10),'Bundle Tag Info'!L$6,CHAR(10),'Bundle Tag Info'!L$13),"") | M8: =IF('Bundle Tag Info'!M$13<>"",CONCATENATE('Bundle Tag Info'!$A$1," ",CHAR(10),'Bundle Tag Info'!$A$2," ",'Bundle Tag Info'!$A$3,CHAR(10),'Bundle Tag Info'!M$6,CHAR(10),'Bundle Tag Info'!M$13),"") | ... AD8: =IF('Bundle Tag Info'!AD$13<>"",CONCATENATE('Bundle Tag Info'!$A$1," ",CHAR(10),'Bundle Tag Info'!$A$2," ",'Bundle Tag Info'!$A$3,CHAR(10),'Bundle Tag Info'!AD$6,CHAR(10),'Bundle Tag Info'!AD$13),"")
A9: =IF('Bundle Tag Info'!A$14<>"",CONCATENATE('Bundle Tag Info'!$A$1," ",CHAR(10),'Bundle Tag Info'!$A$2," ",'Bundle Tag Info'!$A$3,CHAR(10),'Bundle Tag Info'!A$6,CHAR(10),'Bundle Tag Info'!A$14),"") -> PSX-GLDSC STAT 4N298 REV.B1 SCS HL BOTTOM | B9: =IF('Bundle Tag Info'!B$14<>"",CONCATENATE('Bundle Tag Info'!$A$1," ",CHAR(10),'Bundle Tag Info'!$A$2," ",'Bundle Tag Info'!$A$3,CHAR(10),'Bundle Tag Info'!B$6,CHAR(10),'Bundle Tag Info'!B$14),"") | D9: =IF('Bundle Tag Info'!D$14<>"",CONCATENATE('Bundle Tag Info'!$A$1," ",CHAR(10),'Bundle Tag Info'!$A$2," ",'Bundle Tag Info'!$A$3,CHAR(10),'Bundle Tag Info'!D$6,CHAR(10),'Bundle Tag Info'!D$14),"") | F9: =IF('Bundle Tag Info'!F$14<>"",CONCATENATE('Bundle Tag Info'!$A$1," ",CHAR(10),'Bundle Tag Info'!$A$2," ",'Bundle Tag Info'!$A$3,CHAR(10),'Bundle Tag Info'!F$6,CHAR(10),'Bundle Tag Info'!F$14),"") | G9: =IF('Bundle Tag Info'!G$14<>"",CONCATENATE('Bundle Tag Info'!$A$1," ",CHAR(10),'Bundle Tag Info'!$A$2," ",'Bundle Tag Info'!$A$3,CHAR(10),'Bundle Tag Info'!G$6,CHAR(10),'Bundle Tag Info'!G$14),"") | H9: =IF('Bundle Tag Info'!H$14<>"",CONCATENATE('Bundle Tag Info'!$A$1," ",CHAR(10),'Bundle Tag Info'!$A$2," ",'Bundle Tag Info'!$A$3,CHAR(10),'Bundle Tag Info'!H$6,CHAR(10),'Bundle Tag Info'!H$14),"") | I9: =IF('Bundle Tag Info'!I$14<>"",CONCATENATE('Bundle Tag Info'!$A$1," ",CHAR(10),'Bundle Tag Info'!$A$2," ",'Bundle Tag Info'!$A$3,CHAR(10),'Bundle Tag Info'!I$6,CHAR(10),'Bundle Tag Info'!I$14),"") | J9: =IF('Bundle Tag Info'!J$14<>"",CONCATENATE('Bundle Tag Info'!$A$1," ",CHAR(10),'Bundle Tag Info'!$A$2," ",'Bundle Tag Info'!$A$3,CHAR(10),'Bundle Tag Info'!J$6,CHAR(10),'Bundle Tag Info'!J$14),"") | K9: =IF('Bundle Tag Info'!K$14<>"",CONCATENATE('Bundle Tag Info'!$A$1," ",CHAR(10),'Bundle Tag Info'!$A$2," ",'Bundle Tag Info'!$A$3,CHAR(10),'Bundle Tag Info'!K$6,CHAR(10),'Bundle Tag Info'!K$14),"") | L9: =IF('Bundle Tag Info'!L$14<>"",CONCATENATE('Bundle Tag Info'!$A$1," ",CHAR(10),'Bundle Tag Info'!$A$2," ",'Bundle Tag Info'!$A$3,CHAR(10),'Bundle Tag Info'!L$6,CHAR(10),'Bundle Tag Info'!L$14),"") | M9: =IF('Bundle Tag Info'!M$14<>"",CONCATENATE('Bundle Tag Info'!$A$1," ",CHAR(10),'Bundle Tag Info'!$A$2," ",'Bundle Tag Info'!$A$3,CHAR(10),'Bundle Tag Info'!M$6,CHAR(10),'Bundle Tag Info'!M$14),"") | ... AD9: =IF('Bundle Tag Info'!AD$14<>"",CONCATENATE('Bundle Tag Info'!$A$1," ",CHAR(10),'Bundle Tag Info'!$A$2," ",'Bundle Tag Info'!$A$3,CHAR(10),'Bundle Tag Info'!AD$6,CHAR(10),'Bundle Tag Info'!AD$14),"")
A10: =IF('Bundle Tag Info'!A$15<>"",CONCATENATE('Bundle Tag Info'!$A$1," ",CHAR(10),'Bundle Tag Info'!$A$2," ",'Bundle Tag Info'!$A$3,CHAR(10),'Bundle Tag Info'!A$6,CHAR(10),'Bundle Tag Info'!A$15),"") -> PSX-GLDSC STAT 4N298 REV.B1 SCS SB0403 | B10: =IF('Bundle Tag Info'!B$15<>"",CONCATENATE('Bundle Tag Info'!$A$1," ",CHAR(10),'Bundle Tag Info'!$A$2," ",'Bundle Tag Info'!$A$3,CHAR(10),'Bundle Tag Info'!B$6,CHAR(10),'Bundle Tag Info'!B$15),"") | D10: =IF('Bundle Tag Info'!D$15<>"",CONCATENATE('Bundle Tag Info'!$A$1," ",CHAR(10),'Bundle Tag Info'!$A$2," ",'Bundle Tag Info'!$A$3,CHAR(10),'Bundle Tag Info'!D$6,CHAR(10),'Bundle Tag Info'!D$15),"") | F10: =IF('Bundle Tag Info'!F$15<>"",CONCATENATE('Bundle Tag Info'!$A$1," ",CHAR(10),'Bundle Tag Info'!$A$2," ",'Bundle Tag Info'!$A$3,CHAR(10),'Bundle Tag Info'!F$6,CHAR(10),'Bundle Tag Info'!F$15),"") | G10: =IF('Bundle Tag Info'!G$15<>"",CONCATENATE('Bundle Tag Info'!$A$1," ",CHAR(10),'Bundle Tag Info'!$A$2," ",'Bundle Tag Info'!$A$3,CHAR(10),'Bundle Tag Info'!G$6,CHAR(10),'Bundle Tag Info'!G$15),"") | H10: =IF('Bundle Tag Info'!H$15<>"",CONCATENATE('Bundle Tag Info'!$A$1," ",CHAR(10),'Bundle Tag Info'!$A$2," ",'Bundle Tag Info'!$A$3,CHAR(10),'Bundle Tag Info'!H$6,CHAR(10),'Bundle Tag Info'!H$15),"") | I10: =IF('Bundle Tag Info'!I$15<>"",CONCATENATE('Bundle Tag Info'!$A$1," ",CHAR(10),'Bundle Tag Info'!$A$2," ",'Bundle Tag Info'!$A$3,CHAR(10),'Bundle Tag Info'!I$6,CHAR(10),'Bundle Tag Info'!I$15),"") | J10: =IF('Bundle Tag Info'!J$15<>"",CONCATENATE('Bundle Tag Info'!$A$1," ",CHAR(10),'Bundle Tag Info'!$A$2," ",'Bundle Tag Info'!$A$3,CHAR(10),'Bundle Tag Info'!J$6,CHAR(10),'Bundle Tag Info'!J$15),"") | K10: =IF('Bundle Tag Info'!K$15<>"",CONCATENATE('Bundle Tag Info'!$A$1," ",CHAR(10),'Bundle Tag Info'!$A$2," ",'Bundle Tag Info'!$A$3,CHAR(10),'Bundle Tag Info'!K$6,CHAR(10),'Bundle Tag Info'!K$15),"") | L10: =IF('Bundle Tag Info'!L$15<>"",CONCATENATE('Bundle Tag Info'!$A$1," ",CHAR(10),'Bundle Tag Info'!$A$2," ",'Bundle Tag Info'!$A$3,CHAR(10),'Bundle Tag Info'!L$6,CHAR(10),'Bundle Tag Info'!L$15),"") | M10: =IF('Bundle Tag Info'!M$15<>"",CONCATENATE('Bundle Tag Info'!$A$1," ",CHAR(10),'Bundle Tag Info'!$A$2," ",'Bundle Tag Info'!$A$3,CHAR(10),'Bundle Tag Info'!M$6,CHAR(10),'Bundle Tag Info'!M$15),"") | ... AD10: =IF('Bundle Tag Info'!AD$15<>"",CONCATENATE('Bundle Tag Info'!$A$1," ",CHAR(10),'Bundle Tag Info'!$A$2," ",'Bundle Tag Info'!$A$3,CHAR(10),'Bundle Tag Info'!AD$6,CHAR(10),'Bundle Tag Info'!AD$15),"")
A11: =IF('Bundle Tag Info'!A$16<>"",CONCATENATE('Bundle Tag Info'!$A$1," ",CHAR(10),'Bundle Tag Info'!$A$2," ",'Bundle Tag Info'!$A$3,CHAR(10),'Bundle Tag Info'!A$6,CHAR(10),'Bundle Tag Info'!A$16),"") -> PSX-GLDSC STAT 4N298 REV.B1 SCS AF2-L PNL | B11: =IF('Bundle Tag Info'!B$16<>"",CONCATENATE('Bundle Tag Info'!$A$1," ",CHAR(10),'Bundle Tag Info'!$A$2," ",'Bundle Tag Info'!$A$3,CHAR(10),'Bundle Tag Info'!B$6,CHAR(10),'Bundle Tag Info'!B$16),"") | D11: =IF('Bundle Tag Info'!D$16<>"",CONCATENATE('Bundle Tag Info'!$A$1," ",CHAR(10),'Bundle Tag Info'!$A$2," ",'Bundle Tag Info'!$A$3,CHAR(10),'Bundle Tag Info'!D$6,CHAR(10),'Bundle Tag Info'!D$16),"") | F11: =IF('Bundle Tag Info'!F$16<>"",CONCATENATE('Bundle Tag Info'!$A$1," ",CHAR(10),'Bundle Tag Info'!$A$2," ",'Bundle Tag Info'!$A$3,CHAR(10),'Bundle Tag Info'!F$6,CHAR(10),'Bundle Tag Info'!F$16),"") | G11: =IF('Bundle Tag Info'!G$16<>"",CONCATENATE('Bundle Tag Info'!$A$1," ",CHAR(10),'Bundle Tag Info'!$A$2," ",'Bundle Tag Info'!$A$3,CHAR(10),'Bundle Tag Info'!G$6,CHAR(10),'Bundle Tag Info'!G$16),"") | H11: =IF('Bundle Tag Info'!H$16<>"",CONCATENATE('Bundle Tag Info'!$A$1," ",CHAR(10),'Bundle Tag Info'!$A$2," ",'Bundle Tag Info'!$A$3,CHAR(10),'Bundle Tag Info'!H$6,CHAR(10),'Bundle Tag Info'!H$16),"") | I11: =IF('Bundle Tag Info'!I$16<>"",CONCATENATE('Bundle Tag Info'!$A$1," ",CHAR(10),'Bundle Tag Info'!$A$2," ",'Bundle Tag Info'!$A$3,CHAR(10),'Bundle Tag Info'!I$6,CHAR(10),'Bundle Tag Info'!I$16),"") | J11: =IF('Bundle Tag Info'!J$16<>"",CONCATENATE('Bundle Tag Info'!$A$1," ",CHAR(10),'Bundle Tag Info'!$A$2," ",'Bundle Tag Info'!$A$3,CHAR(10),'Bundle Tag Info'!J$6,CHAR(10),'Bundle Tag Info'!J$16),"") | K11: =IF('Bundle Tag Info'!K$16<>"",CONCATENATE('Bundle Tag Info'!$A$1," ",CHAR(10),'Bundle Tag Info'!$A$2," ",'Bundle Tag Info'!$A$3,CHAR(10),'Bundle Tag Info'!K$6,CHAR(10),'Bundle Tag Info'!K$16),"") | L11: =IF('Bundle Tag Info'!L$16<>"",CONCATENATE('Bundle Tag Info'!$A$1," ",CHAR(10),'Bundle Tag Info'!$A$2," ",'Bundle Tag Info'!$A$3,CHAR(10),'Bundle Tag Info'!L$6,CHAR(10),'Bundle Tag Info'!L$16),"") | M11: =IF('Bundle Tag Info'!M$16<>"",CONCATENATE('Bundle Tag Info'!$A$1," ",CHAR(10),'Bundle Tag Info'!$A$2," ",'Bundle Tag Info'!$A$3,CHAR(10),'Bundle Tag Info'!M$6,CHAR(10),'Bundle Tag Info'!M$16),"") | ... AD11: =IF('Bundle Tag Info'!AD$16<>"",CONCATENATE('Bundle Tag Info'!$A$1," ",CHAR(10),'Bundle Tag Info'!$A$2," ",'Bundle Tag Info'!$A$3,CHAR(10),'Bundle Tag Info'!AD$6,CHAR(10),'Bundle Tag Info'!AD$16),"")
A12: =IF('Bundle Tag Info'!A$17<>"",CONCATENATE('Bundle Tag Info'!$A$1," ",CHAR(10),'Bundle Tag Info'!$A$2," ",'Bundle Tag Info'!$A$3,CHAR(10),'Bundle Tag Info'!A$6,CHAR(10),'Bundle Tag Info'!A$17),"") -> PSX-GLDSC STAT 4N298 REV.B1 SCS TO BACK PNL | B12: =IF('Bundle Tag Info'!B$17<>"",CONCATENATE('Bundle Tag Info'!$A$1," ",CHAR(10),'Bundle Tag Info'!$A$2," ",'Bundle Tag Info'!$A$3,CHAR(10),'Bundle Tag Info'!B$6,CHAR(10),'Bundle Tag Info'!B$17),"") | D12: =IF('Bundle Tag Info'!D$17<>"",CONCATENATE('Bundle Tag Info'!$A$1," ",CHAR(10),'Bundle Tag Info'!$A$2," ",'Bundle Tag Info'!$A$3,CHAR(10),'Bundle Tag Info'!D$6,CHAR(10),'Bundle Tag Info'!D$17),"") | E12: =IF('Bundle Tag Info'!E$17<>"",CONCATENATE('Bundle Tag Info'!$A$1," ",CHAR(10),'Bundle Tag Info'!$A$2," ",'Bundle Tag Info'!$A$3,CHAR(10),'Bundle Tag Info'!E$6,CHAR(10),'Bundle Tag Info'!E$17),"") | F12: =IF('Bundle Tag Info'!F$17<>"",CONCATENATE('Bundle Tag Info'!$A$1," ",CHAR(10),'Bundle Tag Info'!$A$2," ",'Bundle Tag Info'!$A$3,CHAR(10),'Bundle Tag Info'!F$6,CHAR(10),'Bundle Tag Info'!F$17),"") | G12: =IF('Bundle Tag Info'!G$17<>"",CONCATENATE('Bundle Tag Info'!$A$1," ",CHAR(10),'Bundle Tag Info'!$A$2," ",'Bundle Tag Info'!$A$3,CHAR(10),'Bundle Tag Info'!G$6,CHAR(10),'Bundle Tag Info'!G$17),"") | H12: =IF('Bundle Tag Info'!H$17<>"",CONCATENATE('Bundle Tag Info'!$A$1," ",CHAR(10),'Bundle Tag Info'!$A$2," ",'Bundle Tag Info'!$A$3,CHAR(10),'Bundle Tag Info'!H$6,CHAR(10),'Bundle Tag Info'!H$17),"") | I12: =IF('Bundle Tag Info'!I$17<>"",CONCATENATE('Bundle Tag Info'!$A$1," ",CHAR(10),'Bundle Tag Info'!$A$2," ",'Bundle Tag Info'!$A$3,CHAR(10),'Bundle Tag Info'!I$6,CHAR(10),'Bundle Tag Info'!I$17),"") | J12: =IF('Bundle Tag Info'!J$17<>"",CONCATENATE('Bundle Tag Info'!$A$1," ",CHAR(10),'Bundle Tag Info'!$A$2," ",'Bundle Tag Info'!$A$3,CHAR(10),'Bundle Tag Info'!J$6,CHAR(10),'Bundle Tag Info'!J$17),"") | K12: =IF('Bundle Tag Info'!K$17<>"",CONCATENATE('Bundle Tag Info'!$A$1," ",CHAR(10),'Bundle Tag Info'!$A$2," ",'Bundle Tag Info'!$A$3,CHAR(10),'Bundle Tag Info'!K$6,CHAR(10),'Bundle Tag Info'!K$17),"") | ... AD12: =IF('Bundle Tag Info'!AD$17<>"",CONCATENATE('Bundle Tag Info'!$A$1," ",CHAR(10),'Bundle Tag Info'!$A$2," ",'Bundle Tag Info'!$A$3,CHAR(10),'Bundle Tag Info'!AD$6,CHAR(10),'Bundle Tag Info'!AD$17),"")
