Workbook

Sheet Blue Labels
A1: (SHT 1) JB70 | B1: (SHT 10) JB73 PANEL | C1: (SHT 12) PROX,HPC | D1: (SHT 13) BOP CTRL^JB74 | E1: (SHT 14) MEDIA CONVERTER | F1: (SHT 2) JB70 LEFT RAIL | G1: (SHT 3) RAIL,RIGHT,JB70 | H1: (SHT 4) PLC PANEL | I1: (SHT 5) PANEL A, JB70 | J1: (SHT 6) PANEL B, JB70 | K1: (SHT 7) PROX,TURB | L1: (SHT 9) RAIL,RIGHT,JB73
A2: AT1100 | B2: WC8058 | C2: UA4460 | D2: KA0535 | E2: FU1123 | F2: XTFGA | G2: AT0680 | H2: UV0600 | I2: AU0090 | J2: AU0060 | K2: UA1210 | L2: XT0845
A3: SB0471 | B3: AF1206 | C3: UA4461 | D3: KA0536 | E3: FU1124 | F3: GR0431 | G3: FU1101 | H3: AP0602 | I3: AF0091 | J3: AF0061 | K3: UA1211 | L3: XTFGE
A4: SB0473 | B4: AF1205 | C4: UA4462 | D4: KA0531 | E4: XT1123 | G4: FU1100 | H4: AP0603 | I4: AF0092 | J4: AF0062 | K4: UA1220 | L4: GR1163
A5: SB0474 | B5: AF1204 | C5: UA4470 | D5: KA0532 | E5: GR1125 | G5: FU0680 | H5: AP0605 | I5: AF0093 | J5: AF0063 | K5: UA1221
A6: SH0470 | B6: AF1203 | C6: UA4471 | D6: KA0533 | E6: BA1123 | G6: FU0291 | H6: AP0606 | I6: AF0094 | J6: AF0064 | K6: UA1230
A7: SH0471 | B7: AF1202 | C7: UA4473 | D7: KA0534 | E7: IEG1123 | G7: BA1100 | H7: AP0608 | I7: AF0095 | J7: AF0065 | K7: UA1231
A8: SH0472 | B8: AF1201 | C8: GR4460 | D8: KA0537 | E8: BA0005 | G8: UV0291 | H8: AR0600 | I8: XT0082 | J8: AF0066 | K8: UA1240
A9: SH1120 | B9: AU1200 | D9: KA0540 | E9: BA0006 | G9: XT0680 | H9: AT0600 | I9: XT0084 | J9: AF0067 | K9: UA1241
A10: SA0471 | B10: GR0161 | D10: KA0541 | E10: GR1123 | G10: XT0291 | H10: AT0601 | I10: XT0003 | J10: AF0068 | K10: GR1210
A11: SA0474 | B11: AF1207 | D11: KA0550 | G11: XT0111 | H11: AP0604 | I11: XT0002 | J11: BA0001 | K11: UA1250
A12: SA0473 | B12: AF1208 | D12: KA0551 | G12: GR0532 | H12: AP0607 | I12: FU0136 | J12: BA0002 | K12: UA1251
A13: HA0472 | B13: AF1209 | D13: KA0554 | H13: AP0609 | I13: KA3103 | J13: BA0009 | K13: UA1262
A14: SB0472 | B14: AF1210 | D14: KA0572 | H14: XT0051 | I14: KA3220 | J14: KA0222 | K14: UA1263
B15: AF1211 | D15: KA0573 | H15: GR0234 | I15: GR0134 | J15: KA0221 | K15: UA1272
B16: FU0120 | D16: XT0572 | H16: BA0070 | I16: FU0139 | J16: KA0224 | K16: UA1273
B17: FU0121 | D17: XT0573 | I17: FU0387 | J17: KA0235 | K17: UA1520
B18: FU0122 | D18: KA6310 | I18: FU0388 | J18: KA0236 | K18: XT1521
B19: GR0163 | D19: GR0181 | I19: FU0389 | J19: KA0237 | K19: XTFGK
B20: IEG0160 | D20: AU0140 | I20: XT0089 | J20: KA0239 | K20: GR1211
B21: FU0510 | D21: AF0141 | I21: KT0140 | J21: KA0240
B22: XT0510 | D22: AF0142 | I22: KT0141 | J22: KA0251
B23: AF0500 | D23: AF0143 | I23: KT0142 | J23: KA0241
B24: AF0510 | D24: AF0144 | I24: KT0143 | J24: KA0242
B25: AF0520 | D25: AF0145 | I25: KT0144 | J25: KA0243
B26: XT0500 | D26: AF0146 | I26: KT0145 | J26: KA0244
B27: XT0120 | D27: FU0146 | I27: KT0146 | J27: KA0245
B28: KA4401 | D28: FU0140 | I28: KA0135 | J28: KA1020
B29: KA0120 | D29: FU0141 | I29: KA0130 | J29: FU0022
B30: KA7120 | D30: FU0142 | I30: KA0131 | J30: FU0021
B31: XT0121 | D31: FU0143 | I31: KA0132 | J31: FU0100
B32: FU0332 | D32: XT0140 | I32: KA0141 | J32: FU0210
... B36: SB0472A | D36: GR0182 | I36: KA0233 | J36: FU0212
D37: IEG0257 | I37: KA0234 | J37: GR0233
D38: AU0180 | I38: KA0133 | J38: XT0400
D39: AF0181 | I39: KA0136 | J39: XT0401
D40: AF0182 | I40: KA0138 | J40: FU0410
D41: AF0183 | I41: KA0134 | J41: AF0400
D42: AF0184 | I42: KA0137 | J42: AF0410
D43: AF0185 | I43: KA2160 | J43: AF0420
...

Sheet White Labels
A1: (SHT 13) BOP CTRL^JB74 | B1: (SHT 1) JB70 - (SHT 5) PANEL A, JB70 | C1: (SHT 10) JB73 PANEL | D1: (SHT 14) MEDIA CONVERTER | E1: (SHT 5) PANEL A, JB70 | F1: (SHT 5) PANEL A, JB70 - (SHT 6) PANEL B, JB70 | G1: (SHT 6) PANEL B, JB70 | H1: (SHT 6) PANEL B, JB70 - (SHT 4) PLC PANEL | I1: (SHT 6) PANEL B, JB70 - (SHT 3) RAIL,RIGHT,JB70 | J1: (SHT 4) PLC PANEL
A2: AF0143SH | B2: AT1100G | C2: AF1204G | D2: GR1125 | E2: AF0083G | F2: IEG00104 | G2: AF0064G | H2: IEG02306 | I2: GR0532 | J2: UV0600G
A3: AF0144SH | C3: AF1205G | D3: IEG11231 | E3: AF0084G | F3: IEG02300 | G3: AF0065G
A4: AU0140G | C4: AF1206G | E4: AF0085G | G4: AF0066G
A5: AU0180G | C5: AF1208G | E5: AU0080G | G5: AF0071G
A6: GR0181 | C6: AF1209G | E6: AU0090G | G6: AF0072G
A7: IEG02571 | C7: AF1210G | E7: IEG001012 | G7: AF0073G
A8: IEG02572 | C8: AF1211G | E8: IEG001013 | G8: AF0074G
A9: IEG02573 | C9: AU1200G | E9: IEG00102 | G9: AF0075G
A10: IEG02575 | C10: IEG01601 | E10: IEG00106 | G10: AU0060G,GRN
C11: IEG01602 | E11: IEG00108 | G11: AU0070G
C12: IEG01603 | G12: IEG02301
C13: IEG01604 | G13: IEG02303
C14: XT05001 | G14: IEG02304
G15: IEG02308
G16: XT04001
G17: XT04002

Sheet Heat Shrink Labels
A1: (SHT 5) PANEL A, JB70 - (SHT 6) PANEL B, JB70
A2: WC4524

Sheet BOP CTRL^JB74
A1: BOP CTRL^JB74
A2: JB74
A3: Project # | B3: 4N091
A4: Project Name
A5: Revision | B5: B
A7: Controls DE | B7: D. KIM
A8: Phone:
A9: Controls ME | B9: A. PLVAN
A10: Phone:
A12: From | G12: To
A13: Device ID | B13: Cable (W) Conductor (SC) Jumper Clip (JC) | C13: Wire No. | D13: Wire ID | E13: Gauge/Size | F13: Page/Zone | G13: Device ID | H13: Location | I13: Page/Zone
A14: XT0140:1 | B14: JC | C14: 0V | D14: CLIP | E14: --- | F14: 31.A1 | G14: XT0140:2 | H14: BOP CTRL^JB74 | I14: 31.B1 | M14: USED
A15: XT0140:2 | B15: JC | C15: 0V | D15: CLIP | E15: --- | F15: 31.B1 | G15: XT0140:3 | H15: BOP CTRL^JB74 | I15: 31.B1 | M15: USED
A16: XT0140:3 | B16: JC | C16: 0V | D16: CLIP | E16: --- | F16: 31.B1 | G16: XT0140:4 | H16: BOP CTRL^JB74 | I16: 31.C1 | M16: USED
A17: XT0140:4 | B17: JC | C17: 0V | D17: CLIP | E17: --- | F17: 31.C1 | G17: XT0140:5 | H17: BOP CTRL^JB74 | I17: 31.D1 | M17: USED
A18: XT0140:5 | B18: JC | C18: 0V | D18: CLIP | E18: --- | F18: 31.D1 | G18: XT0140:6 | H18: BOP CTRL^JB74 | I18: 31.D1 | M18: USED
A19: AF0182:01 | B19: SC | C19: JP4 | D19: VIO | E19: 20 | F19: 33.A7 | G19: AF0182:33 | H19: BOP CTRL^JB74 | I19: 33.A7 | M19: USED
A20: AF0182:02 | B20: SC | C20: JB7,VIO | D20: VIO | E20: 20 | F20: 33.B7 | G20: AF0182:34 | H20: BOP CTRL^JB74 | I20: 33.B7 | M20: USED
A21: AF0182:03 | B21: SC | C21: JP9 | D21: VIO | E21: 20 | F21: 33.B7 | G21: AF0182:35 | H21: BOP CTRL^JB74 | I21: 33.B7 | M21: USED
A22: KA0531:21 | B22: SC | C22: KA053121 | D22: WHT | E22: 20 | F22: 102.A7 | G22: AF0141:00 | H22: BOP CTRL^JB74 | I22: 102.A5 | M22: USED
A23: KA6310:A1 | B23: SC | C23: 014102 | D23: WHT | E23: 20 | F23: 99.B7 | G23: AF0141:02 | H23: BOP CTRL^JB74 | I23: 99.B6 | M23: USED
A24: KA0532:21 | B24: SC | C24: KA053221 | D24: WHT | E24: 20 | F24: 103.A7 | G24: AF0141:04 | H24: BOP CTRL^JB74 | I24: 103.A5 | M24: USED
A25: KA0554:11 | B25: SC | C25: KA055411 | D25: WHT | E25: 20 | F25: 104.C7 | G25: AF0141:12 | H25: BOP CTRL^JB74 | I25: 104.C6 | M25: USED
... A32: AF0141:COM | B32: SC | C32: 0V | D32: WHT | E32: 16 | F32: 31.B2 | G32: XT0140:2 | H32: BOP CTRL^JB74 | I32: 31.B1 | M32: USED
A33: AF0141:J | B33: SC | C33: * | F33: 31.B2 | G33: AF0142:P | H33: BOP CTRL^JB74 | I33: 31.B3 | M33: USED
A34: AF0141:V+ | B34: SC | C34: FU0141 | D34: WHT | E34: 16 | F34: 31.B2 | G34: FU0141:LD | H34: BOP CTRL^JB74 | I34: 31.B1 | M34: USED
A35: AF0142:COM | B35: SC | C35: AF0142N | D35: WHT | E35: 16 | F35: 31.B3 | G35: AF0143:COM | H35: BOP CTRL^JB74 | I35: 31.B3 | M35: USED
A36: AF0142:COM | B36: SC | C36: AU0140N | D36: WHT | E36: 16 | F36: 31.B3 | G36: AU0140:COM | H36: BOP CTRL^JB74 | I36: 31.A2 | M36: USED
A37: AF0142:J | B37: SC | C37: * | F37: 31.B3 | G37: AF0143:P | H37: BOP CTRL^JB74 | I37: 31.B3 | M37: USED
A38: AF0142:V+ | B38: SC | C38: AF0142P | D38: WHT | E38: 16 | F38: 31.B3 | G38: AF0143:V+ | H38: BOP CTRL^JB74 | I38: 31.B3 | M38: USED
A39: AF0142:V+ | B39: SC | C39: AU0140P | D39: WHT | E39: 16 | F39: 31.B3 | G39: AU0140:V+ | H39: BOP CTRL^JB74 | I39: 31.A2 | M39: USED
A40: AF0143:COM | B40: SC | C40: AF0143N | D40: WHT | E40: 16 | F40: 31.B3 | G40: AF0144:COM | H40: BOP CTRL^JB74 | I40: 31.B4 | M40: USED
A41: AF0143:J | B41: SC | C41: * | F41: 31.B3 | G41: AF0144:P | H41: BOP CTRL^JB74 | I41: 31.B4 | M41: USED
A42: AF0143:SH | B42: SC | C42: AF0143SH | D42: GRN | E42: 14 | F42: 31.B3 | G42: AF0144:SH | H42: BOP CTRL^JB74 | I42: 31.B4 | M42: USED
A43: AF0143:SH | B43: SC | C43: AU0140G | D43: GRN | E43: 14 | F43: 31.B3 | G43: AU0140:GND | H43: BOP CTRL^JB74 | I43: 31.A2 | M43: USED
A44: AF0143:V+ | B44: SC | C44: AF0143P | D44: WHT | E44: 16 | F44: 31.B3 | G44: AF0144:V+ | H44: BOP CTRL^JB74 | I44: 31.B4 | M44: USED
A45: AF0144:COM | B45: SC | C45: AF0144N | D45: WHT | E45: 16 | F45: 31.B4 | G45: AF0145:COM | H45: BOP CTRL^JB74 | I45: 31.B5 | M45: USED
A46: AF0144:J | B46: SC | C46: * | F46: 31.B4 | G46: AF0145:P | H46: BOP CTRL^JB74 | I46: 31.B5 | M46: USED
A47: AF0144:SH | B47: SC | C47: AF0144SH | D47: GRN | E47: 14 | F47: 31.B4 | G47: AF0145:SH | H47: BOP CTRL^JB74 | I47: 31.B5 | M47: USED
A48: AF0144:V+ | B48: SC | C48: AF0144P | D48: WHT | E48: 16 | F48: 31.B4 | G48: AF0145:V+ | H48: BOP CTRL^JB74 | I48: 31.B5 | M48: USED
...

Sheet JB70
A1: JB70
A2: CONTROL,JB70
A3: Project # | B3: 4N091
A4: Project Name
A5: Revision | B5: B
A7: Controls DE | B7: D. KIM
A8: Phone:
A9: Controls ME | B9: A. PLVAN
A10: Phone:
A12: From | G12: To
A13: Device ID | B13: Cable (W) Conductor (SC) Jumper Clip (JC) | C13: Wire No. | D13: Wire ID | E13: Gauge/Size | F13: Page/Zone | G13: Device ID | H13: Location | I13: Page/Zone
A14: AT1100:GND | B14: SC | C14: AT1100G | D14: GRN/YEL | E14: 14 | F14: 39.D3 | G14: PEG0130:2 | H14: PANEL A, JB70 | I14: 39.D5 | M14: USED
A15: SA0471:B1-13 | B15: SC | C15: SA0471B113 | D15: WHT | E15: 20 | F15: 37.B1 | G15: AF0087:40 | H15: PANEL A, JB70 | I15: 37.B7 | M15: USED
A16: SA0471:B1-14 | B16: SC | C16: SA0471B114 | D16: WHT | E16: 20 | F16: 37.B1 | G16: AF0087:08 | H16: PANEL A, JB70 | I16: 37.B7 | M16: USED
A17: SA0471:B2-13 | B17: SC | C17: SA0471B213 | D17: WHT | E17: 20 | F17: 37.A1 | G17: AF0087:39 | H17: PANEL A, JB70 | I17: 37.A7 | M17: USED
A18: SA0471:B2-14 | B18: SC | C18: SA0471B214 | D18: WHT | E18: 20 | F18: 37.A1 | G18: AF0087:07 | H18: PANEL A, JB70 | I18: 37.A7 | M18: USED
A19: SA0473:11 | B19: SC | C19: SA047311 | D19: WHT | E19: 20 | F19: 35.D1 | G19: AF0087:37 | H19: PANEL A, JB70 | I19: 35.D7 | M19: USED
A20: SA0473:12 | B20: SC | C20: SA047312 | D20: WHT | E20: 20 | F20: 35.D1 | G20: AF0087:05 | H20: PANEL A, JB70 | I20: 35.D7 | M20: USED
A21: SA0473:13 | B21: SC | C21: SA047313 | D21: WHT | E21: 20 | F21: 35.D1 | G21: AF0087:38 | H21: PANEL A, JB70 | I21: 35.D7 | M21: USED
A22: SA0473:14 | B22: SC | C22: SA047314 | D22: WHT | E22: 20 | F22: 35.D1 | G22: AF0087:06 | H22: PANEL A, JB70 | I22: 35.D7 | M22: USED
A23: SA0474:B1-13 | B23: SC | C23: SA0474B113 | D23: WHT | E23: 20 | F23: 40.C1 | G23: AF0087:45 | H23: PANEL A, JB70 | I23: 40.C7 | M23: USED
A24: SA0474:B1-14 | B24: SC | C24: SA0474B114 | D24: WHT | E24: 20 | F24: 40.C1 | G24: AF0087:13 | H24: PANEL A, JB70 | I24: 40.C7 | M24: USED
A25: SA0474:B2-13 | B25: SC | C25: SA0474B213 | D25: WHT | E25: 20 | F25: 40.C1 | G25: AF0087:44 | H25: PANEL A, JB70 | I25: 40.C7 | M25: USED
... A65: HA0472:BLK-2 | B65: WC5072 | C65: HA047202 | D65: 2 | E65: 18 | F65: 38.A1 | G65: XT0111:23 | H65: RAIL,RIGHT,JB70 | I65: 38.A5 | M65: USED
F67: SolarTools ver. 24.0.84.24712 (Jul 31, 2025)
A68: Report date: 3/5/2026 3:52 PM

Sheet JB70 LEFT RAIL
A1: JB70 LEFT RAIL
A2: JB70 (LEFT RAIL)
A3: Project # | B3: 4N091
A4: Project Name
A5: Revision | B5: B
A7: Controls DE | B7: D. KIM
A8: Phone:
A9: Controls ME | B9: A. PLVAN
A10: Phone:
A12: From | G12: To
A13: Device ID | B13: Cable (W) Conductor (SC) Jumper Clip (JC) | C13: Wire No. | D13: Wire ID | E13: Gauge/Size | F13: Page/Zone | G13: Device ID | H13: Location | I13: Page/Zone
A14: GR0431: | B14: SC | C14: GR0431 | D14: GRN/YEL | E14: 14 | F14: 10.B4 | G14: FRAME | H14: JB70 LEFT RAIL | I14: 10.B3 | M14: USED
F16: SolarTools ver. 24.0.84.24712 (Jul 31, 2025)
A17: Report date: 3/5/2026 3:52 PM

Sheet JB73 PANEL
A1: JB73 PANEL
A2: 0
A3: Project # | B3: 4N091
A4: Project Name
A5: Revision | B5: B
A7: Controls DE | B7: D. KIM
A8: Phone:
A9: Controls ME | B9: A. PLVAN
A10: Phone:
A12: From | G12: To
A13: Device ID | B13: Cable (W) Conductor (SC) Jumper Clip (JC) | C13: Wire No. | D13: Wire ID | E13: Gauge/Size | F13: Page/Zone | G13: Device ID | H13: Location | I13: Page/Zone
A14: XT0120:1 | B14: JC | C14: 0V | D14: CLIP | E14: --- | F14: 28.A1 | G14: XT0120:2 | H14: JB73 PANEL | I14: 28.B1 | M14: USED
A15: XT0120:2 | B15: JC | C15: 0V | D15: CLIP | E15: --- | F15: 28.B1 | G15: XT0120:3 | H15: JB73 PANEL | I15: 28.D1 | M15: USED
A16: XT0121:1 | B16: JC | C16: FU0122 | D16: CLIP | E16: --- | F16: 94.A5 | G16: XT0121:2 | H16: JB73 PANEL | I16: 94.C5 | M16: USED
A17: XT0121:3 | B17: JC | C17: 0V | D17: CLIP | E17: --- | F17: 94.A5 | G17: XT0121:4 | H17: JB73 PANEL | I17: 94.C5 | M17: USED
A18: XT0335:1 | B18: JC | C18: FU0332 | D18: CLIP | E18: --- | F18: 27.A4 | G18: XT0335:2 | H18: JB73 PANEL | I18: 27.A4 | M18: USED
A19: XT0335:2 | B19: JC | C19: FU0332 | D19: CLIP | E19: --- | F19: 27.A4 | G19: XT0335:3 | H19: JB73 PANEL | I19: 27.B4 | M19: USED
A20: XT0335:3 | B20: JC | C20: FU0332 | D20: CLIP | E20: --- | F20: 27.B4 | G20: XT0335:4 | H20: JB73 PANEL | I20: 27.B4 | M20: USED
A21: XT0335:4 | B21: JC | C21: FU0332 | D21: CLIP | E21: --- | F21: 27.B4 | G21: XT0335:5 | H21: JB73 PANEL | I21: 27.B4 | M21: USED
A22: XT0335:5 | B22: JC | C22: FU0332 | D22: CLIP | E22: --- | F22: 27.B4 | G22: XT0335:6 | H22: JB73 PANEL | I22: 27.B4 | M22: USED
A23: XT0335:6 | B23: JC | C23: FU0332 | D23: CLIP | E23: --- | F23: 27.B4 | G23: XT0335:7 | H23: JB73 PANEL | I23: 27.C4 | M23: USED
A24: XT0335:7 | B24: JC | C24: FU0332 | D24: CLIP | E24: --- | F24: 27.C4 | G24: XT0335:8 | H24: JB73 PANEL | I24: 27.C4 | M24: USED
A25: XT0335:8 | B25: JC | C25: FU0332 | D25: CLIP | E25: --- | F25: 27.C4 | G25: XT0335:9 | H25: JB73 PANEL | I25: 27.C4 | M25: USED
... A47: AF1201:COM | B47: SC | C47: 0V | D47: WHT | E47: 16 | F47: 28.B2 | G47: XT0120:2 | H47: JB73 PANEL | I47: 28.B1 | M47: USED
A48: AF1201:J | B48: SC | C48: * | F48: 28.B2 | G48: AF1202:P | H48: JB73 PANEL | I48: 28.B3 | M48: USED
A49: AF1201:P | B49: SC | C49: * | F49: 28.B2 | G49: AU1200:J | H49: JB73 PANEL | I49: 28.A2 | M49: USED
A50: AF1201:V+ | B50: SC | C50: FU0121 | D50: WHT | E50: 16 | F50: 28.B2 | G50: FU0121:LD | H50: JB73 PANEL | I50: 28.B1 | M50: USED
A51: AF1202:COM | B51: SC | C51: AF1203N | D51: WHT | E51: 16 | F51: 28.B3 | G51: AF1203:COM | H51: JB73 PANEL | I51: 28.B3 | M51: USED
A52: AF1202:COM | B52: SC | C52: AF1202N | D52: WHT | E52: 16 | F52: 28.B3 | G52: AU1200:COM | H52: JB73 PANEL | I52: 28.A2 | M52: USED
A53: AF1202:J | B53: SC | C53: * | F53: 28.B3 | G53: AF1203:P | H53: JB73 PANEL | I53: 28.B3 | M53: USED
A54: AF1202:V+ | B54: SC | C54: AF1203P | D54: WHT | E54: 16 | F54: 28.B3 | G54: AF1203:V+ | H54: JB73 PANEL | I54: 28.B3 | M54: USED
A55: AF1202:V+ | B55: SC | C55: AF1202P | D55: WHT | E55: 16 | F55: 28.B3 | G55: AU1200:V+ | H55: JB73 PANEL | I55: 28.A2 | M55: USED
A56: AF1203:COM | B56: SC | C56: AF1204N | D56: WHT | E56: 16 | F56: 28.B3 | G56: AF1204:COM | H56: JB73 PANEL | I56: 28.A4 | M56: USED
A57: AF1203:J | B57: SC | C57: * | F57: 28.B3 | G57: AF1204:P | H57: JB73 PANEL | I57: 28.A4 | M57: USED
A58: AF1203:SH | B58: SC | C58: AF1204G | D58: GRN | E58: 14 | F58: 28.B3 | G58: AF1204:SH | H58: JB73 PANEL | I58: 28.A4 | M58: USED
A59: AF1203:SH | B59: SC | C59: AU1200G | D59: GRN | E59: 14 | F59: 28.B3 | G59: AU1200:GND | H59: JB73 PANEL | I59: 28.A2 | M59: USED
A60: AF1203:V+ | B60: SC | C60: AF1204P | D60: WHT | E60: 16 | F60: 28.B3 | G60: AF1204:V+ | H60: JB73 PANEL | I60: 28.A4 | M60: USED
A61: AF1204:COM | B61: SC | C61: AF1205N | D61: WHT | E61: 16 | F61: 28.A4 | G61: AF1205:COM | H61: JB73 PANEL | I61: 28.A5 | M61: USED
A62: AF1204:J | B62: SC | C62: * | F62: 28.A4 | G62: AF1205:P | H62: JB73 PANEL | I62: 28.A5 | M62: USED
A63: AF1204:SH | B63: SC | C63: AF1205G | D63: GRN | E63: 14 | F63: 28.A4 | G63: AF1205:SH | H63: JB73 PANEL | I63: 28.A5 | M63: USED
...

Sheet MEDIA CONVERTER
A1: MEDIA CONVERTER
A2: VFD MEDIA CONVERTER BOX (JB1123)
A3: Project # | B3: 4N091
A4: Project Name
A5: Revision | B5: B
A7: Controls DE | B7: D. KIM
A8: Phone:
A9: Controls ME | B9: A. PLVAN
A10: Phone:
A12: From | G12: To
A13: Device ID | B13: Cable (W) Conductor (SC) Jumper Clip (JC) | C13: Wire No. | D13: Wire ID | E13: Gauge/Size | F13: Page/Zone | G13: Device ID | H13: Location | I13: Page/Zone
A14: BA0005:V1(-) | B14: SC | C14: JB1123N | D14: WHT | E14: 16 | F14: 9.A4 | G14: XT1123:2 | H14: MEDIA CONVERTER | I14: 9.A6 | M14: USED
A15: BA0005:V1(+) | B15: SC | C15: FU1123 | D15: WHT | E15: 16 | F15: 9.A4 | G15: FU1123:LD | H15: MEDIA CONVERTER | I15: 9.A5 | M15: USED
A16: BA0006:V1(-) | B16: SC | C16: JB1123N | D16: WHT | E16: 16 | F16: 9.B4 | G16: XT1123:2 | H16: MEDIA CONVERTER | I16: 9.A6 | M16: USED
A17: BA0006:V1(+) | B17: SC | C17: FU1124 | D17: WHT | E17: 16 | F17: 9.B4 | G17: FU1124:LD | H17: MEDIA CONVERTER | I17: 9.B5 | M17: USED
A18: FU1123:LI | B18: SC | C18: JB1123P | D18: WHT | E18: 16 | F18: 9.A5 | G18: XT1123:1 | H18: MEDIA CONVERTER | I18: 9.A6 | M18: USED
A19: FU1124:LI | B19: SC | C19: JB1123P | D19: WHT | E19: 16 | F19: 9.B5 | G19: XT1123:1 | H19: MEDIA CONVERTER | I19: 9.A6 | M19: USED
A20: GR1123: | B20: SC | C20: IEG11231 | D20: GRN | E20: 14 | F20: 10.D4 | G20: IEG1123:1 | H20: MEDIA CONVERTER | I20: 10.D3 | M20: USED
A21: GR1125: | B21: SC | C21: GR1125 | D21: GRN/YEL | E21: 14 | F21: 10.D5 | G21: FG1125:1 | H21: MEDIA CONVERTER | I21: 10.D4 | M21: USED
A22: BA0006:RX | B22: WC11231 | C22: BA00706R | D22: BLU-A | E22: FIBER OPTIC | F22: 2.D4 | G22: BA1123:2T | H22: MEDIA CONVERTER | I22: 2.C3 | M22: USED
A23: BA0006:TX | B23: WC11231 | C23: BA00706T | D23: BLU-B | E23: FIBER OPTIC | F23: 2.D4 | G23: BA1123:2R | H23: MEDIA CONVERTER | I23: 2.C3 | M23: USED
A24: BA0005:TX | B24: WC11232 | C24: BA00701R | D24: BLU-A | E24: FIBER OPTIC | F24: 2.D4 | G24: BA1123:6T | H24: MEDIA CONVERTER | I24: 2.C3 | M24: USED
A25: BA0005:RX | B25: WC11232 | C25: BA00701T | D25: BLU-B | E25: FIBER OPTIC | F25: 2.D4 | G25: BA1123:6R | H25: MEDIA CONVERTER | I25: 2.C3 | M25: USED
F27: SolarTools ver. 24.0.84.24712 (Jul 31, 2025)
A28: Report date: 3/5/2026 3:52 PM

Sheet PANEL A, JB70
A1: PANEL A, JB70
A3: Project # | B3: 4N091
A4: Project Name
A5: Revision | B5: B
A7: Controls DE | B7: D. KIM
A8: Phone:
A9: Controls ME | B9: A. PLVAN
A10: Phone:
A12: From | G12: To
A13: Device ID | B13: Cable (W) Conductor (SC) Jumper Clip (JC) | C13: Wire No. | D13: Wire ID | E13: Gauge/Size | F13: Page/Zone | G13: Device ID | H13: Location | I13: Page/Zone
A14: XT0002:1 | B14: JC | C14: FU0136 | D14: CLIP | E14: --- | F14: 12.A4 | G14: XT0002:2 | H14: PANEL A, JB70 | I14: 12.A4 | M14: USED
A15: XT0002:2 | B15: JC | C15: FU0136 | D15: CLIP | E15: --- | F15: 12.A4 | G15: XT0002:3 | H15: PANEL A, JB70 | I15: 12.A4 | M15: USED
A16: XT0002:3 | B16: JC | C16: FU0136 | D16: CLIP | E16: --- | F16: 12.A4 | G16: XT0002:4 | H16: PANEL A, JB70 | I16: 12.A4 | M16: USED
A17: XT0002:4 | B17: JC | C17: FU0136 | D17: CLIP | E17: --- | F17: 12.A4 | G17: XT0002:5 | H17: PANEL A, JB70 | I17: 12.B4 | M17: USED
A18: XT0002:5 | B18: JC | C18: FU0136 | D18: CLIP | E18: --- | F18: 12.B4 | G18: XT0002:6 | H18: PANEL A, JB70 | I18: 12.B4 | M18: USED
A19: XT0002:6 | B19: JC | C19: FU0136 | D19: CLIP | E19: --- | F19: 12.B4 | G19: XT0002:7 | H19: PANEL A, JB70 | I19: 12.B4 | M19: USED
A20: XT0002:7 | B20: JC | C20: FU0136 | D20: CLIP | E20: --- | F20: 12.B4 | G20: XT0002:8 | H20: PANEL A, JB70 | I20: 12.B4 | M20: USED
A21: XT0002:8 | B21: JC | C21: FU0136 | D21: CLIP | E21: --- | F21: 12.B4 | G21: XT0002:9 | H21: PANEL A, JB70 | I21: 12.C4 | M21: USED
A22: XT0002:9 | B22: JC | C22: FU0136 | D22: CLIP | E22: --- | F22: 12.C4 | G22: XT0002:10 | H22: PANEL A, JB70 | I22: 12.C4 | M22: USED
A23: XT0003:1 | B23: JC | C23: 0V | D23: CLIP | E23: --- | F23: 12.A4 | G23: XT0003:2 | H23: PANEL A, JB70 | I23: 12.A4 | M23: USED
A24: XT0003:2 | B24: JC | C24: 0V | D24: CLIP | E24: --- | F24: 12.A4 | G24: XT0003:3 | H24: PANEL A, JB70 | I24: 12.A4 | M24: USED
A25: XT0003:3 | B25: JC | C25: 0V | D25: CLIP | E25: --- | F25: 12.A4 | G25: XT0003:4 | H25: PANEL A, JB70 | I25: 12.B4 | M25: USED
... A64: AF0081:COM | B64: SC | C64: AU0080N | D64: WHT | E64: 16 | F64: 20.A2 | G64: AU0080:COM | H64: PANEL A, JB70 | I64: 20.A1 | M64: USED
A65: AF0081:J | B65: SC | C65: * | F65: 20.A2 | G65: AF0082:P | H65: PANEL A, JB70 | I65: 20.B3 | M65: USED
A66: AF0081:V+ | B66: SC | C66: AF0081P | D66: WHT | E66: 16 | F66: 20.A2 | G66: AF0082:V+ | H66: PANEL A, JB70 | I66: 20.B3 | M66: USED
A67: AF0081:V+ | B67: SC | C67: AU0080P | D67: WHT | E67: 16 | F67: 20.A2 | G67: AU0080:V+ | H67: PANEL A, JB70 | I67: 20.A1 | M67: USED
A68: AF0082:COM | B68: SC | C68: AF0082N | D68: WHT | E68: 16 | F68: 20.B3 | G68: AF0083:COM | H68: PANEL A, JB70 | I68: 20.B3 | M68: USED
A69: AF0082:J | B69: SC | C69: * | F69: 20.B3 | G69: AF0083:P | H69: PANEL A, JB70 | I69: 20.B3 | M69: USED
A70: AF0082:V+ | B70: SC | C70: AF0082P | D70: WHT | E70: 16 | F70: 20.B3 | G70: AF0083:V+ | H70: PANEL A, JB70 | I70: 20.B3 | M70: USED
A71: AF0083:COM | B71: SC | C71: AF0083N | D71: WHT | E71: 16 | F71: 20.B3 | G71: AF0084:COM | H71: PANEL A, JB70 | I71: 20.B4 | M71: USED
A72: AF0083:SH | B72: SC | C72: AF0083G | D72: GRN | E72: 14 | F72: 20.B3 | G72: AF0084:SH | H72: PANEL A, JB70 | I72: 20.B4 | M72: USED
A73: AF0083:SH | B73: SC | C73: AU0080G | D73: GRN | E73: 14 | F73: 20.B3 | G73: AU0080:GND | H73: PANEL A, JB70 | I73: 20.A1 | M73: USED
A74: AF0083:V+ | B74: SC | C74: AF0083P | D74: WHT | E74: 16 | F74: 20.B3 | G74: AF0084:V+ | H74: PANEL A, JB70 | I74: 20.B4 | M74: USED
A75: AF0084:COM | B75: SC | C75: AF0084N | D75: WHT | E75: 16 | F75: 20.B4 | G75: AF0085:COM | H75: PANEL A, JB70 | I75: 20.B4 | M75: USED
A76: AF0084:J | B76: SC | C76: * | F76: 20.B4 | G76: AF0085:P | H76: PANEL A, JB70 | I76: 20.B4 | M76: USED
A77: AF0084:SH | B77: SC | C77: AF0084G | D77: GRN | E77: 14 | F77: 20.B4 | G77: AF0085:SH | H77: PANEL A, JB70 | I77: 20.B4 | M77: USED
A78: AF0084:V+ | B78: SC | C78: AF0084P | D78: WHT | E78: 16 | F78: 20.B4 | G78: AF0085:V+ | H78: PANEL A, JB70 | I78: 20.B4 | M78: USED
A79: AF0085:COM | B79: SC | C79: AF0085N | D79: WHT | E79: 16 | F79: 20.B4 | G79: AF0086:COM | H79: PANEL A, JB70 | I79: 20.B5 | M79: USED
A80: AF0085:J | B80: SC | C80: * | F80: 20.B4 | G80: AF0086:P | H80: PANEL A, JB70 | I80: 20.B5 | M80: USED
A81: AF0085:SH | B81: SC | C81: AF0085G | D81: GRN | E81: 14 | F81: 20.B4 | G81: AF0086:SH | H81: PANEL A, JB70 | I81: 20.B5 | M81: USED
...

Sheet PANEL B, JB70
A1: PANEL B, JB70
A3: Project # | B3: 4N091
A4: Project Name
A5: Revision | B5: B.1_M.1
A7: Controls DE | B7: D. KIM
A8: Phone:
A9: Controls ME | B9: A. PLVAN
A10: Phone:
A12: From | G12: To
A13: Device ID | B13: Cable (W) Conductor (SC) Jumper Clip (JC) | C13: Wire No. | D13: Wire ID | E13: Gauge/Size | F13: Page/Zone | G13: Device ID | H13: Location | I13: Page/Zone
A14: XT0060:1 | B14: JC | C14: 0V | D14: CLIP | E14: --- | F14: 15.A1 | G14: XT0060:2 | H14: PANEL B, JB70 | I14: 15.B1 | M14: USED
A15: XT0060:2 | B15: JC | C15: 0V | D15: CLIP | E15: --- | F15: 15.B1 | G15: XT0060:3 | H15: PANEL B, JB70 | I15: 15.B1 | M15: USED
A16: XT0060:3 | B16: JC | C16: 0V | D16: CLIP | E16: --- | F16: 15.B1 | G16: XT0060:4 | H16: PANEL B, JB70 | I16: 15.C1 | M16: USED
A17: XT0062:1 | B17: JC | C17: 0V | D17: CLIP | E17: --- | F17: 14.A1 | G17: XT0062:2 | H17: PANEL B, JB70 | I17: 14.A1 | M17: USED
A18: XT0401:1 | B18: JC | C18: 0V | D18: CLIP | E18: --- | F18: 16.A1 | G18: XT0401:2 | H18: PANEL B, JB70 | I18: 16.C1 | M18: USED
A19: AF0061:COM | B19: SC | C19: 0V | D19: WHT | E19: 16 | F19: 15.B2 | G19: XT0060:2 | H19: PANEL B, JB70 | I19: 15.B1 | M19: USED
A20: AF0061:J | B20: SC | C20: * | F20: 15.B2 | G20: AF0062:P | H20: PANEL B, JB70 | I20: 15.B3 | M20: USED
A21: AF0061:V+ | B21: SC | C21: FU0062 | D21: WHT | E21: 16 | F21: 15.B2 | G21: FU0062:LD | H21: PANEL B, JB70 | I21: 15.B1 | M21: USED
A22: KA0222:14 | B22: SC | C22: 006200 | D22: WHT | E22: 20 | F22: 63.C7 | G22: AF0062:00 | H22: PANEL B, JB70 | I22: 63.C6 | M22: USED
A23: AF0062:COM | B23: SC | C23: 0V | D23: WHT | E23: 16 | F23: 15.B3 | G23: XT0060:3 | H23: PANEL B, JB70 | I23: 15.B1 | M23: USED
A24: AF0062:J | B24: SC | C24: * | F24: 15.B3 | G24: AF0063:P | H24: PANEL B, JB70 | I24: 15.B3 | M24: USED
A25: AF0062:V+ | B25: SC | C25: FU0063 | D25: WHT | E25: 16 | F25: 15.B3 | G25: FU0063:LD | H25: PANEL B, JB70 | I25: 15.B1 | M25: USED
A26: AF0063:COM | B26: SC | C26: AF0063N | D26: WHT | E26: 16 | F26: 15.B3 | G26: AF0064:COM | H26: PANEL B, JB70 | I26: 15.A4 | M26: USED
A27: AF0063:COM | B27: SC | C27: AU0060N | D27: WHT | E27: 16 | F27: 15.B3 | G27: AU0060:COM | H27: PANEL B, JB70 | I27: 15.A2 | M27: USED
A28: AF0063:J | B28: SC | C28: * | F28: 15.B3 | G28: AF0064:P | H28: PANEL B, JB70 | I28: 15.A4 | M28: USED
A29: AF0063:V+ | B29: SC | C29: AF0063P | D29: WHT | E29: 16 | F29: 15.B3 | G29: AF0064:V+ | H29: PANEL B, JB70 | I29: 15.A4 | M29: USED
A30: AF0063:V+ | B30: SC | C30: AU0060P | D30: WHT | E30: 16 | F30: 15.B3 | G30: AU0060:V+ | H30: PANEL B, JB70 | I30: 15.A2 | M30: USED
A31: AF0064:COM | B31: SC | C31: AF0064N | D31: WHT | E31: 16 | F31: 15.A4 | G31: AF0065:COM | H31: PANEL B, JB70 | I31: 15.A5 | M31: USED
A32: AF0064:J | B32: SC | C32: * | F32: 15.A4 | G32: AF0065:P | H32: PANEL B, JB70 | I32: 15.A5 | M32: USED
A33: AF0064:SH | B33: SC | C33: AF0064G | D33: GRN | E33: 14 | F33: 15.A4 | G33: AF0065:SH | H33: PANEL B, JB70 | I33: 15.A5 | M33: USED
A34: AF0064:SH | B34: SC | C34: AU0060G,GRN | D34: GRN | E34: 14 | F34: 15.A4 | G34: AU0060:GND | H34: PANEL B, JB70 | I34: 15.A2 | M34: USED
A35: AF0064:V+ | B35: SC | C35: AF0064P | D35: WHT | E35: 16 | F35: 15.A4 | G35: AF0065:V+ | H35: PANEL B, JB70 | I35: 15.A5 | M35: USED
A36: AF0065:COM | B36: SC | C36: AF0065N | D36: WHT | E36: 16 | F36: 15.A5 | G36: AF0066:COM | H36: PANEL B, JB70 | I36: 15.B5 | M36: USED
A37: AF0065:J | B37: SC | C37: * | F37: 15.A5 | G37: AF0066:P | H37: PANEL B, JB70 | I37: 15.B5 | M37: USED
A38: AF0065:SH | B38: SC | C38: AF0065G | D38: GRN | E38: 14 | F38: 15.A5 | G38: AF0066:SH | H38: PANEL B, JB70 | I38: 15.B5 | M38: USED
A39: AF0065:V+ | B39: SC | C39: AF0065P | D39: WHT | E39: 16 | F39: 15.A5 | G39: AF0066:V+ | H39: PANEL B, JB70 | I39: 15.B5 | M39: USED
A40: AF0066:COM | B40: SC | C40: AF0066N | D40: WHT | E40: 16 | F40: 15.B5 | G40: AF0068:COM | H40: PANEL B, JB70 | I40: 15.B6 | M40: USED
A41: AF0066:J | B41: SC | C41: * | F41: 15.B5 | G41: AF0067:P | H41: PANEL B, JB70 | I41: 15.B6 | M41: USED
A42: AF0066:SH | B42: SC | C42: AF0066G | D42: GRN | E42: 14 | F42: 15.B5 | G42: AF0068:SH | H42: PANEL B, JB70 | I42: 15.B6 | M42: USED
A43: AF0066:V+ | B43: SC | C43: AF0066P | D43: WHT | E43: 16 | F43: 15.B5 | G43: AF0068:V+ | H43: PANEL B, JB70 | I43: 15.B6 | M43: USED
...

Sheet PLC PANEL
A1: PLC PANEL
A2: JB70
A3: Project # | B3: 4N091
A4: Project Name
A5: Revision | B5: B
A7: Controls DE | B7: D. KIM
A8: Phone:
A9: Controls ME | B9: A. PLVAN
A10: Phone:
A12: From | G12: To
A13: Device ID | B13: Cable (W) Conductor (SC) Jumper Clip (JC) | C13: Wire No. | D13: Wire ID | E13: Gauge/Size | F13: Page/Zone | G13: Device ID | H13: Location | I13: Page/Zone
A14: XT0051:1 | B14: JC | C14: FU0136 | D14: CLIP | E14: --- | F14: 8.A4 | G14: XT0051:2 | H14: PLC PANEL | I14: 8.B4 | M14: USED
A15: XT0051:2 | B15: JC | C15: FU0136 | D15: CLIP | E15: --- | F15: 8.B4 | G15: XT0051:3 | H15: PLC PANEL | I15: 8.B4 | M15: USED
A16: XT0051:3 | B16: JC | C16: FU0136 | D16: CLIP | E16: --- | F16: 8.B4 | G16: XT0051:4 | H16: PLC PANEL | I16: 8.C4 | M16: USED
A17: XT0051:5 | B17: JC | C17: 0V | D17: CLIP | E17: --- | F17: 8.A3 | G17: XT0051:6 | H17: PLC PANEL | I17: 8.B3 | M17: USED
A18: XT0051:6 | B18: JC | C18: 0V | D18: CLIP | E18: --- | F18: 8.B3 | G18: XT0051:7 | H18: PLC PANEL | I18: 8.C3 | M18: USED
A19: XT0051:7 | B19: JC | C19: 0V | D19: CLIP | E19: --- | F19: 8.C3 | G19: XT0051:8 | H19: PLC PANEL | I19: 8.C3 | M19: USED
A20: AR0600:IE1 | B20: SC | C20: UV0600G | D20: GRN | E20: 14 | F20: 5.A1 | G20: UV0600:GND | H20: PLC PANEL | I20: 5.B2 | M20: USED
A21: GR0234: | B21: SC | C21: GR0234 | D21: GRN/YEL | E21: 14 | F21: 10.B4 | G21: FRAME | H21: PLC PANEL | I21: 10.B3 | M21: USED
A22: AP0602:L2 | B22: WC0001 | C22: AP0602L2 | D22: ENET | E22: CABLE | F22: 2.A3 | G22: AP0603:L1 | H22: PLC PANEL | I22: 2.A4 | M22: USED
A23: UV0600:(-) | B23: SC | C23: 0V | D23: WHT | E23: 14 | F23: 5.B2 | G23: XT0003:4 | H23: PANEL A, JB70 | I23: 12.B4 | M23: USED
A24: UV0600:(+) | B24: SC | C24: FU0010 | D24: WHT | E24: 14 | F24: 5.B2 | G24: FU0010:LD | H24: PANEL A, JB70 | I24: 5.B1 | M24: USED
A25: XT0051:1 | B25: SC | C25: FU0136 | D25: WHT | E25: 14 | F25: 8.A4 | G25: XT0002:7 | H25: PANEL A, JB70 | I25: 12.B4 | M25: USED
... A42: AP0609:L1 | B42: WC0680 | C42: AP0609L1 | D42: ENET | E42: CABLE | F42: 3.A6 | G42: AT0680:LAN1 | H42: RAIL,RIGHT,JB70 | I42: 3.A6 | M42: USED
F44: SolarTools ver. 24.0.84.24712 (Jul 31, 2025)
A45: Report date: 3/5/2026 3:51 PM

Sheet PROX,HPC
A1: PROX,HPC
A3: Project # | B3: 4N091
A4: Project Name
A5: Revision | B5: B
A7: Controls DE | B7: D. KIM
A8: Phone:
A9: Controls ME | B9: A. PLVAN
A10: Phone:
A12: From | G12: To
A13: Device ID | B13: Cable (W) Conductor (SC) Jumper Clip (JC) | C13: Wire No. | D13: Wire ID | E13: Gauge/Size | F13: Page/Zone | G13: Device ID | H13: Location | I13: Page/Zone
A14: GR4460: | B14: SC | C14: GR4460 | D14: GRN/YEL | E14: 14 | F14: 11.A6 | G14: FRAME | H14: PROX,HPC | I14: 11.A6 | M14: USED
A16: Report date: 3/5/2026 3:51 PM | F16: SolarTools ver. 24.0.84.24712 (Jul 31, 2025)

Sheet PROX,TURB
A1: PROX,TURB
A3: Project # | B3: 4N091
A4: Project Name
A5: Revision | B5: B
A7: Controls DE | B7: D. KIM
A8: Phone:
A9: Controls ME | B9: A. PLVAN
A10: Phone:
A12: From | G12: To
A13: Device ID | B13: Cable (W) Conductor (SC) Jumper Clip (JC) | C13: Wire No. | D13: Wire ID | E13: Gauge/Size | F13: Page/Zone | G13: Device ID | H13: Location | I13: Page/Zone
A14: GR1210: | B14: SC | C14: GR1210 | D14: GRN/YEL | E14: 14 | F14: 10.A6 | G14: FRAME | H14: PROX,TURB | I14: 10.A6 | M14: USED
A15: GR1211: | B15: SC | C15: GR1211 | D15: GRN/YEL | E15: 14 | F15: 10.A6 | G15: FRAME | H15: PROX,TURB | I15: 10.A6 | M15: USED
F17: SolarTools ver. 24.0.84.24712 (Jul 31, 2025)
A18: Report date: 3/5/2026 3:51 PM

Sheet RAIL,RIGHT,JB70
A1: RAIL,RIGHT,JB70
A2: 0
A3: Project # | B3: 4N091
A4: Project Name
A5: Revision | B5: B
A7: Controls DE | B7: D. KIM
A8: Phone:
A9: Controls ME | B9: A. PLVAN
A10: Phone:
A12: From | G12: To
A13: Device ID | B13: Cable (W) Conductor (SC) Jumper Clip (JC) | C13: Wire No. | D13: Wire ID | E13: Gauge/Size | F13: Page/Zone | G13: Device ID | H13: Location | I13: Page/Zone
A14: AT0680:NEG | B14: SC | C14: 0V | D14: WHT | E14: 14 | F14: 7.A5 | G14: XT0680:2 | H14: RAIL,RIGHT,JB70 | I14: 7.A4 | M14: USED
A15: AT0680:POS | B15: SC | C15: AT0680POS | D15: WHT | E15: 14 | F15: 7.A5 | G15: XT0680:1 | H15: RAIL,RIGHT,JB70 | I15: 7.A4 | M15: USED
A16: BA1100:NEG | B16: SC | C16: UV0271_0V | D16: WHT | E16: 16 | F16: 39.D1 | G16: XT0291:2 | H16: RAIL,RIGHT,JB70 | I16: 39.C2 | M16: USED
A17: BA1100:POS | B17: SC | C17: FU1101 | D17: WHT | E17: 16 | F17: 39.D1 | G17: FU1101:LD | H17: RAIL,RIGHT,JB70 | I17: 39.C2 | M17: USED
A18: FU0291:LD | B18: SC | C18: FU0291 | D18: WHT | E18: 16 | F18: 39.C4 | G18: UV0291:24V(+) | H18: RAIL,RIGHT,JB70 | I18: 39.C3 | M18: USED
A19: FU0291:LI | B19: SC | C19: FU0136 | D19: WHT | E19: 16 | F19: 39.C4 | G19: XT0111:21 | H19: RAIL,RIGHT,JB70 | I19: 39.D5 | M19: USED
A20: FU0680:LD | B20: SC | C20: AT0680POS | D20: WHT | E20: 14 | F20: 7.A4 | G20: XT0680:1 | H20: RAIL,RIGHT,JB70 | I20: 7.A4 | M20: USED
A21: FU1100:LI | B21: SC | C21: FU0136 | D21: WHT | E21: 16 | F21: 39.D3 | G21: XT0111:21 | H21: RAIL,RIGHT,JB70 | I21: 39.D5 | M21: USED
A22: FU1101:LI | B22: SC | C22: UV0271_24V | D22: WHT | E22: 16 | F22: 39.C2 | G22: XT0291:1 | H22: RAIL,RIGHT,JB70 | I22: 39.C2 | M22: USED
A23: UV0291:24V(-) | B23: SC | C23: 0V | D23: WHT | E23: 16 | F23: 39.C3 | G23: XT0111:22 | H23: RAIL,RIGHT,JB70 | I23: 39.D5 | M23: USED
A24: UV0291:OUT1(-) | B24: SC | C24: UV0271_0V | D24: WHT | E24: 16 | F24: 39.C3 | G24: XT0291:2 | H24: RAIL,RIGHT,JB70 | I24: 39.C2 | M24: USED
A25: UV0291:OUT1(+) | B25: SC | C25: UV0271_24V | D25: WHT | E25: 16 | F25: 39.C3 | G25: XT0291:1 | H25: RAIL,RIGHT,JB70 | I25: 39.C2 | M25: USED
... A92: AT0680:LAN1 | B92: WC0680 | C92: AP0609L1 | D92: ENET | E92: CABLE | F92: 3.A6 | G92: AP0609:L1 | H92: PLC PANEL | I92: 3.A6 | M92: USED
F94: SolarTools ver. 24.0.84.24712 (Jul 31, 2025)
A95: Report date: 3/5/2026 3:51 PM

Sheet RAIL,RIGHT,JB73
A1: RAIL,RIGHT,JB73
A2: JB73
A3: Project # | B3: 4N091
A4: Project Name
A5: Revision | B5: B
A7: Controls DE | B7: D. KIM
A8: Phone:
A9: Controls ME | B9: A. PLVAN
A10: Phone:
A12: From | G12: To
A13: Device ID | B13: Cable (W) Conductor (SC) Jumper Clip (JC) | C13: Wire No. | D13: Wire ID | E13: Gauge/Size | F13: Page/Zone | G13: Device ID | H13: Location | I13: Page/Zone
A14: GR1163: | B14: SC | C14: GR1163 | D14: GRN/YEL | E14: 14 | F14: 11.A4 | G14: FRAME | H14: RAIL,RIGHT,JB73 | I14: 11.A3 | M14: USED
F16: SolarTools ver. 24.0.84.24712 (Jul 31, 2025)
A17: Report date: 3/5/2026 3:51 PM

Sheet Panel Errors
A1: Panel Errors
A3: Project # | B3: 4N091
A4: Project Name
A5: Revision | B5: B
A7: Controls DE | B7: D. KIM
A8: Phone:
A9: Controls ME | B9: A. PLVAN
A10: Phone:
A12: From | H12: To
A13: Device ID | B13: Location | C13: Cable (W) Conductor (SC) Jumper Clip (JC) | D13: Wire ID | E13: Wire No. | F13: Gauge/Size | G13: Page/Zone | H13: Device ID | I13: Location | J13: Page/Zone
A16: Report date: 3/5/2026 3:51 PM | E16: SolarTools ver. 24.0.84.24712 (Jul 31, 2025)

Sheet RAIL,RIGHT,JB70_S
A1: RAIL,RIGHT,JB70
A2: 0
A3: Project # | B3: 4N093
A4: Project Name
A5: Revision | B5: B.1_M.1
A7: Controls DE | B7: D. KIM
A8: Phone:
A9: Controls ME | B9: A. PLVAN
A10: Phone:
A12: From | G12: To
A13: Device ID | B13: Wire No. | C13: Wire ID | D13: Gauge/Size | E13: Length | F13: Device ID | G13: Location | H13: Bundle Name
A14: XT0111:19 | B14: SB0472AB211 | C14: WHT | D14: 20 | E14: 60 | F14: XT0111:25 | G14: RAIL,RIGHT | H14: XT
A16: BA1100:NEG | B16: UV0271_0V | C16: WHT | D16: 16 | E16: 120 | F16: XT0291:2 | G16: RAIL,RIGHT | H16: BA1100
A17: BA1100:POS | B17: FU1101 | C17: WHT | D17: 16 | E17: 60 | F17: FU1101:LD | G17: RAIL,RIGHT
A19: FU0291:LD | B19: FU0291 | C19: WHT | D19: 16 | E19: 60 | F19: UV0291:24V(+) | G19: RAIL,RIGHT | H19: FU
A20: FU0291:LI | B20: FU0136 | C20: WHT | D20: 16 | E20: 120 | F20: XT0111:21 | G20: RAIL,RIGHT
A21: FU1100:LI | B21: FU0136 | C21: WHT | D21: 16 | E21: 120 | F21: XT0111:21 | G21: RAIL,RIGHT
A22: FU1101:LI | B22: UV0271_24V | C22: WHT | D22: 16 | E22: 120 | F22: XT0291:1 | G22: RAIL,RIGHT
A24: UV0291:24V(-) | B24: -0V | C24: WHT | D24: 16 | E24: 120 | F24: XT0111:22 | G24: RAIL,RIGHT | H24: UV0291
A25: UV0291:OUT1(-) | B25: UV0271_0V | C25: WHT | D25: 16 | E25: 120 | F25: XT0291:2 | G25: RAIL,RIGHT
A26: UV0291:OUT1(+) | B26: UV0271_24V | C26: WHT | D26: 16 | E26: 120 | F26: XT0291:1 | G26: RAIL,RIGHT
A28: AT0680:NEG | B28: -0V | C28: WHT | D28: 14 | E28: 120 | F28: XT0680:2 | G28: RAIL,RIGHT | H28: AT0680
A29: AT0680:POS | B29: AT0680POS | C29: WHT | D29: 14 | E29: 120 | F29: XT0680:1 | G29: RAIL,RIGHT
A30: FU0680:LD | B30: AT0680POS | C30: WHT | D30: 14 | E30: 120 | F30: XT0680:1 | G30: RAIL,RIGHT
A32: XT0111:30 | B32: SH112014 | C32: WHT | D32: 20 | E32: 180 | F32: AF0087:10 | G32: PANEL A | H32: TO A
A33: XT0111:20 | B33: ESTOPA | C33: WHT | D33: 20 | E33: 180 | F33: XT0089:4 | G33: PANEL A
A34: XT0111:26 | B34: ESTOPB | C34: WHT | D34: 20 | E34: 180 | F34: XT0089:3 | G34: PANEL A
A35: XT0111:15 | B35: FU0139 | C35: WHT | D35: 20 | E35: 180 | F35: XT0081:6 | G35: PANEL A
A36: XT0111:24 | B36: HA047201 | C36: WHT | D36: 20 | E36: 180 | F36: AF0092:28 | G36: PANEL A
A37: XT0111:23 | B37: HA047202 | C37: WHT | D37: 20 | E37: 180 | F37: AF0092:12 | G37: PANEL A
A38: XT0111:16 | B38: KA0241A1 | C38: WHT | D38: 20 | E38: 180 | F38: XT0081:7 | G38: PANEL A
A39: XT0111:28 | B39: SB0472AB112 | C39: WHT | D39: 20 | E39: 180 | F39: AF0081:36 | G39: PANEL A
A40: XT0111:7 | B40: SH047011 | C40: WHT | D40: 20 | E40: 180 | F40: AF0087:33 | G40: PANEL A
A41: XT0111:8 | B41: SH047012 | C41: WHT | D41: 20 | E41: 180 | F41: AF0087:01 | G41: PANEL A
A42: XT0111:12 | B42: SH0470X1 | C42: WHT | D42: 20 | E42: 180 | F42: AF0093:22 | G42: PANEL A
A43: XT0111:11 | B43: SH0470X2 | C43: WHT | D43: 20 | E43: 180 | F43: AF0093:06 | G43: PANEL A
A44: XT0111:3 | B44: SH047113 | C44: WHT | D44: 20 | E44: 180 | F44: AF0087:32 | G44: PANEL A
... A54: XT0111:21 | B54: FU0136 | C54: WHT | D54: 14 | E54: 160 | F54: XT0002:6 | G54: PANEL A
A56: XT0111:34 | B56: SH1120X1 | C56: WHT | D56: 20 | E56: 160 | F56: AF0076:19 | G56: PANEL B | H56: TO B
A57: XT0111:33 | B57: SH1120X2 | C57: WHT | D57: 20 | E57: 160 | F57: AF0076:03 | G57: PANEL B
...

Sheet PLC PANEL_S
A1: PLC PANEL
A2: JB70
A3: Project # | B3: 4N093
A4: Project Name
A5: Revision | B5: B.1_M.1
A7: Controls DE | B7: D. KIM
A8: Phone:
A9: Controls ME | B9: A. PLVAN
A10: Phone:
A12: From | G12: To
A13: Device ID | B13: Wire No. | C13: Wire ID | D13: Gauge/Size | E13: Length | F13: Device ID | G13: Location | H13: Bundle Name
A14: UV0600:(-) | B14: -0V | C14: WHT | D14: 14 | E14: 100 | F14: XT0003:4 | G14: PANEL A | H14: UV-A
A15: UV0600:(+) | B15: FU0010 | C15: WHT | D15: 14 | E15: 100 | F15: FU0010:LD | G15: PANEL A
A17: XT0051:5 | B17: -0V | C17: WHT | D17: 16 | E17: 120 | F17: BA0001:V1(-) | G17: PANEL B | H17: XT0051-OUT
A18: XT0051:6 | B18: -0V | C18: WHT | D18: 16 | E18: 120 | F18: BA0002:V1(-) | G18: PANEL B
A19: XT0051:7 | B19: -0V | C19: WHT | D19: 16 | E19: 120 | F19: BA0009:V1(-) | G19: PANEL B
A20: XT0051:1 | B20: FU0136 | C20: WHT | D20: 16 | E20: 120 | F20: FU0021:LI | G20: PANEL B
A21: XT0051:2 | B21: FU0136 | C21: WHT | D21: 16 | E21: 120 | F21: FU0022:LI | G21: PANEL B
A22: XT0051:3 | B22: FU0136 | C22: WHT | D22: 16 | E22: 120 | F22: FU0029:LI | G22: PANEL B
A24: XT0051:5 | B24: -0V | C24: WHT | D24: 14 | E24: 120 | F24: XT0003:7 | G24: PANEL A
A25: XT0051:1 | B25: FU0136 | C25: WHT | D25: 14 | E25: 120 | F25: XT0002:7 | G25: PANEL A

Sheet PANEL B, JB70_S
A1: PANEL B, JB70
A3: Project # | B3: 4N093
A4: Project Name
A5: Revision | B5: B.1_M.1
A7: Controls DE | B7: D. KIM
A8: Phone:
A9: Controls ME | B9: A. PLVAN
A10: Phone:
A12: From | G12: To
A13: Device ID | B13: Wire No. | C13: Wire ID | D13: Gauge/Size | E13: Length | F13: Device ID | G13: Location | H13: Bundle Name
A14: KA0222:14 | B14: -006200 | C14: WHT | D14: 20 | E14: 60 | F14: AF0062:00 | G14: PANEL B | H14: KA'S
A15: KA0221:11 | B15: -023524 | C15: WHT | D15: 20 | E15: 60 | F15: KA0235:24 | G15: PANEL B
A16: KA0222:11 | B16: -023724 | C16: WHT | D16: 20 | E16: 60 | F16: KA0237:24 | G16: PANEL B
A17: KA0235:14 | B17: KA023514 | C17: WHT | D17: 20 | E17: 100 | F17: AF0076:00 | G17: PANEL B
A18: KA0237:14 | B18: KA023714 | C18: WHT | D18: 20 | E18: 100 | F18: AF0076:01 | G18: PANEL B
A19: KA0239:21 | B19: KA023921 | C19: WHT | D19: 20 | E19: 60 | F19: KA0242:24 | G19: PANEL B
A20: KA0236:24 | B20: KA024114 | C20: WHT | D20: 20 | E20: 60 | F20: KA0241:14 | G20: PANEL B
A21: KA0242:21 | B21: KA024221 | C21: WHT | D21: 20 | E21: 100 | F21: XT0237:1 T2 | G21: PANEL B
A22: KA0243:21 | B22: KA024524 | C22: WHT | D22: 20 | E22: 60 | F22: KA0245:24 | G22: PANEL B
A23: KA0236:21 | B23: UA1200J21 | C23: WHT | D23: 20 | E23: 60 | F23: KA0241:11 | G23: PANEL B
A25: KA1020:14 | B25: FU0100 | C25: WHT | D25: 16 | E25: 60 | F25: FU0100:LD | G25: PANEL B
A26: KA0239:22 | B26: FU0212 | C26: WHT | D26: 16 | E26: 60 | F26: FU0212:LD | G26: PANEL B
A28: KA1020:24 | B28: -0V | C28: WHT | D28: 14 | E28: 100 | F28: XT0062:2 | G28: PANEL B
A30: KA0221:A1 | B30: -007602 | C30: WHT | D30: 20 | E30: 100 | F30: AF0076:02 | G30: PANEL B | H30: KA A1/A2
A31: KA0222:A1 | B31: -007604 | C31: WHT | D31: 20 | E31: 100 | F31: AF0076:04 | G31: PANEL B
A32: KA0224:A1 | B32: -007615 | C32: WHT | D32: 20 | E32: 100 | F32: AF0076:15 | G32: PANEL B
A33: KA1020:A1 | B33: KA1020A1 | C33: WHT | D33: 20 | E33: 100 | F33: AF0076:08 | G33: PANEL B
A35: KA0221:A2 | B35: -007618 | C35: WHT | D35: 20 | E35: 100 | F35: AF0076:18 | G35: PANEL B
A36: KA0222:A2 | B36: -007620 | C36: WHT | D36: 20 | E36: 100 | F36: AF0076:20 | G36: PANEL B
A37: KA0224:A2 | B37: -007631 | C37: WHT | D37: 20 | E37: 100 | F37: AF0076:31 | G37: PANEL B
A38: KA1020:A2 | B38: KA1020A2 | C38: WHT | D38: 20 | E38: 100 | F38: AF0076:24 | G38: PANEL B
A40: AF0061:COM | B40: -0V | C40: WHT | D40: 16 | E40: 60 | F40: XT0060:2 | G40: PANEL B | H40: AF60
A41: AF0062:COM | B41: -0V | C41: WHT | D41: 16 | E41: 60 | F41: XT0060:3 | G41: PANEL B
A42: AF0067:COM | B42: -0V | C42: WHT | D42: 16 | E42: 80 | F42: XT0060:3 | G42: PANEL B
A43: AU0060:COM | B43: -0V | C43: WHT | D43: 16 | E43: 60 | F43: XT0060:2 | G43: PANEL B
A44: AF0066:COM | B44: AF0066N | C44: WHT | D44: 16 | E44: 60 | F44: AF0068:COM | G44: PANEL B
A45: AF0066:V+ | B45: AF0066P | C45: WHT | D45: 16 | E45: 60 | F45: AF0068:V+ | G45: PANEL B
A46: AF0063:COM | B46: AU0060N | C46: WHT | D46: 16 | E46: 60 | F46: AU0060:COM | G46: PANEL B
A47: AF0063:V+ | B47: AU0060P | C47: WHT | D47: 16 | E47: 60 | F47: AU0060:V+ | G47: PANEL B
A48: AU0060:V+ | B48: FU0061 | C48: WHT | D48: 16 | E48: 60 | F48: FU0061:LD | G48: PANEL B
...

Sheet PANEL A, JB70_S
A1: PANEL A, JB70
A3: Project # | B3: 4N093
A4: Project Name
A5: Revision | B5: B.1_M.1
A7: Controls DE | B7: D. KIM
A8: Phone:
A9: Controls ME | B9: A. PLVAN
A10: Phone:
A12: From | G12: To
A13: Device ID | B13: Wire No. | C13: Wire ID | D13: Gauge/Size | E13: Length | F13: Device ID | G13: Location | H13: Bundle Name
A14: AF0081:00 | B14: UA1200J21 | C14: WHT | D14: 20 | E14: 60 | F14: XT0089:20 | G14: PANEL A | H14: AF80
A16: AU0080:COM | B16: -0V | C16: WHT | D16: 16 | E16: 60 | F16: XT0080:1 | G16: PANEL A
A17: AU0080:V+ | B17: FU0081 | C17: WHT | D17: 16 | E17: 60 | F17: FU0081:LD | G17: PANEL A
A19: UA1200:J1-9 | B19: -0V | C19: WHT | D19: 20 | E19: 120 | F19: XT0089:22 | G19: PANEL A | H19: UA1200
A20: UA1200:J1-10 | B20: FU0389 | C20: WHT | D20: 20 | E20: 120 | F20: XT0089:21 | G20: PANEL A
A21: UA1200:J2-2 | B21: FU0389 | C21: WHT | D21: 20 | E21: 120 | F21: XT0089:21 | G21: PANEL A
A22: UA1200:J1-8 | B22: UA1200J | C22: WHT | D22: 20 | E22: 60 | F22: UA1200:J3-5 | G22: PANEL A
A23: UA1200:J2-1 | B23: UA1200J21 | C23: WHT | D23: 20 | E23: 120 | F23: XT0089:20 | G23: PANEL A
A24: KA0130:A2 | B24: UA1200J26 | C24: WHT | D24: 20 | E24: 120 | F24: UA1200:J2-6 | G24: PANEL A
A25: AF0081:19 | B25: UA1200J27 | C25: WHT | D25: 20 | E25: 80 | F25: UA1200:J2-7 | G25: PANEL A
A27: AF0091:09 | B27: UJ0131OK2 | C27: WHT | D27: 20 | E27: 60 | F27: UJ0131:OK2 | G27: PANEL A | H27: UJ0131
A28: AF0091:41 | B28: UJ0131OK1 | C28: WHT | D28: 20 | E28: 60 | F28: UJ0131:OK1 | G28: PANEL A
A29: AF0094:04 | B29: UJ0131VIN | C29: WHT | D29: 20 | E29: 60 | F29: UJ0131:VIN | G29: PANEL A
A30: AF0094:06 | B30: UJ0131IOUT | C30: WHT | D30: 20 | E30: 60 | F30: UJ0131:IOUT | G30: PANEL A
A32: FU0011:LD | B32: UJ0131P | C32: WHT | D32: 12 | E32: 60 | F32: UJ0131:+ | G32: PANEL A
A33: UJ0131:- | B33: -521NEG | C33: WHT | D33: 12 | E33: 60 | F33: XT0011:1 | G33: PANEL A
A35: AF0094:05 | B35: -0V | C35: WHT | D35: 20 | E35: 60 | F35: XT0082:5 | G35: PANEL A | H35: AF90
A36: AF0094:07 | B36: -0V | C36: WHT | D36: 20 | E36: 60 | F36: XT0082:5 | G36: PANEL A
A38: AF0092:COM | B38: -0V | C38: WHT | D38: 16 | E38: 60 | F38: XT0080:2 | G38: PANEL A
A39: AF0093:COM | B39: -0V | C39: WHT | D39: 16 | E39: 60 | F39: XT0080:3 | G39: PANEL A
A40: AF0095:COM | B40: -0V | C40: WHT | D40: 16 | E40: 80 | F40: XT0080:4 | G40: PANEL A
A41: AU0090:COM | B41: -0V | C41: WHT | D41: 16 | E41: 60 | F41: XT0080:2 | G41: PANEL A
A42: AF0091:COM | B42: AF0091N | C42: WHT | D42: 16 | E42: 60 | F42: AF0094:COM | G42: PANEL A
A43: AF0091:V+ | B43: AF0091P | C43: WHT | D43: 16 | E43: 60 | F43: AF0094:V+ | G43: PANEL A
A44: AU0090:V+ | B44: FU0090 | C44: WHT | D44: 16 | E44: 60 | F44: FU0090:LD | G44: PANEL A
A45: AF0092:V+ | B45: FU0091 | C45: WHT | D45: 16 | E45: 60 | F45: FU0091:LD | G45: PANEL A
A46: AF0093:V+ | B46: FU0092 | C46: WHT | D46: 16 | E46: 60 | F46: FU0092:LD | G46: PANEL A
A47: AF0095:V+ | B47: FU0093 | C47: WHT | D47: 16 | E47: 80 | F47: FU0093:LD | G47: PANEL A
A49: KA0135:A2 | B49: -0V | C49: WHT | D49: 20 | E49: 60 | F49: KA0137:A2 | G49: PANEL A | H49: KA:A2
A50: KA0131:A2 | B50: KA0131A2 | C50: WHT | D50: 20 | E50: 100 | F50: AF0081:24 | G50: PANEL A
...

Sheet MEDIA CONVERTER_S
A1: MEDIA CONVERTER
A2: VFD MEDIA CONVERTER BOX (JB1123)
A3: Project # | B3: 4N093
A4: Project Name
A5: Revision | B5: B.1_M.1
A7: Controls DE | B7: D. KIM
A8: Phone:
A9: Controls ME | B9: A. PLVAN
A10: Phone:
A12: From | G12: To
A13: Device ID | B13: Wire No. | C13: Wire ID | D13: Gauge/Size | E13: Length | F13: Device ID | G13: Location | H13: Bundle Name
A14: BA0005:V1(+) | B14: FU1123 | C14: WHT | D14: 16 | E14: 60 | F14: FU1123:LD | G14: MEDIA CONVERTER | H14: BA'S
A15: BA0006:V1(+) | B15: FU1124 | C15: WHT | D15: 16 | E15: 60 | F15: FU1124:LD | G15: MEDIA CONVERTER
A16: BA0005:V1(-) | B16: JB1123N | C16: WHT | D16: 16 | E16: 60 | F16: XT1123:2 | G16: MEDIA CONVERTER
A17: BA0006:V1(-) | B17: JB1123N | C17: WHT | D17: 16 | E17: 60 | F17: XT1123:2 | G17: MEDIA CONVERTER
A19: FU1123:LI | B19: JB1123P | C19: WHT | D19: 16 | E19: 60 | F19: XT1123:1 | G19: MEDIA CONVERTER | H19: FU'S
A20: FU1124:LI | B20: JB1123P | C20: WHT | D20: 16 | E20: 60 | F20: XT1123:1 | G20: MEDIA CONVERTER

Sheet JB73 DOOR
A1: JB73 DOOR
A2: 0
A3: Project # | B3: 4N093
A4: Project Name
A5: Revision | B5: B.1_M.1
A7: Controls DE | B7: D. KIM
A8: Phone:
A9: Controls ME | B9: A. PLVAN
A10: Phone:
A12: From | G12: To
A13: Device ID | B13: Wire No. | C13: Wire ID | D13: Gauge/Size | E13: Length | F13: Device ID | G13: Location | H13: Bundle Name
A14: SB0472A:B2-12 | B14: ESTOPB | C14: WHT | D14: 20 | E14: 240 | F14: XT0121:6 | G14: JB73 PANEL | H14: SB0472A
A15: SB0472A:B1-11 | B15: SB0472AB111 | C15: WHT | D15: 20 | E15: 240 | F15: XT0121:7 | G15: JB73 PANEL
A16: SB0472A:B1-12 | B16: SB0472AB112 | C16: WHT | D16: 20 | E16: 240 | F16: XT0121:8 | G16: JB73 PANEL
A17: SB0472A:B2-11 | B17: SB0472AB211 | C17: WHT | D17: 20 | E17: 240 | F17: XT0121:5 | G17: JB73 PANEL

Sheet HPC CTRL
A1: JB73 PANEL HPC CTRL
A2: 0
A3: Project # | B3: 4N093
A4: Project Name
A5: Revision | B5: B.1_M.1
A7: Controls DE | B7: D. KIM
A8: Phone:
A9: Controls ME | B9: A. PLVAN
A10: Phone:
A12: From | G12: To
A13: Device ID | B13: Wire No. | C13: Wire ID | D13: Gauge/Size | E13: Length | F13: Device ID | G13: Location | H13: Bundle Name
A14: KA0120:A2 | B14: -0V | C14: WHT | D14: 20 | E14: 60 | F14: XT0120:3 | G14: JB73 PANEL | H14: KA'S
A15: KA0120:14 | B15: -120100 | C15: WHT | D15: 20 | E15: 80 | F15: AF1201:00 | G15: JB73 PANEL
A16: KA7120:A2 | B16: -120116 | C16: WHT | D16: 20 | E16: 80 | F16: AF1201:16 | G16: JB73 PANEL
A17: KA4401:22 | B17: -120132 | C17: WHT | D17: 20 | E17: 80 | F17: AF1201:32 | G17: JB73 PANEL
A18: KA4401:14 | B18: -120702 | C18: WHT | D18: 20 | E18: 80 | F18: AF1207:02 | G18: JB73 PANEL
A19: KA4401:A2 | B19: -120718 | C19: WHT | D19: 20 | E19: 80 | F19: AF1207:18 | G19: JB73 PANEL
A20: KA0120:11 | B20: KA012011 | C20: WHT | D20: 20 | E20: 60 | F20: KA7120:A1 | G20: JB73 PANEL
A21: KA0120:12 | B21: KA012012 | C21: WHT | D21: 20 | E21: 60 | F21: KA4401:21 | G21: JB73 PANEL
A22: KA0120:A1 | B22: KA0131A1 | C22: WHT | D22: 20 | E22: 60 | F22: XT0120:4 | G22: JB73 PANEL
A23: KA4401:11 | B23: PS44012 | C23: WHT | D23: 20 | E23: 80 | F23: AF1207:34 | G23: JB73 PANEL
A24: KA4401:11 | B24: PS44012 | C24: WHT | D24: 20 | E24: 60 | F24: XT0120:5 | G24: JB73 PANEL
A25: KA4401:A1 | B25: PS44013 | C25: WHT | D25: 20 | E25: 60 | F25: XT0120:6 | G25: JB73 PANEL
A27: AF0510:53 | B27: -0V | C27: WHT | D27: 16 | E27: 60 | F27: XT0510:2 | G27: JB73 PANEL | H27: AF50
A28: AF0510:54 | B28: -0V | C28: WHT | D28: 16 | E28: 60 | F28: AF0520:53 | G28: JB73 PANEL
A29: AF0510:55 | B29: FU0510 | C29: WHT | D29: 16 | E29: 60 | F29: FU0510:LD | G29: JB73 PANEL
A30: AF0510:56 | B30: FU0510 | C30: WHT | D30: 16 | E30: 60 | F30: AF0520:55 | G30: JB73 PANEL
A32: AF1201:COM | B32: -0V | C32: WHT | D32: 16 | E32: 80 | F32: XT0120:2 | G32: JB73 PANEL | H32: AF12
A33: AU1200:COM | B33: -0V | C33: WHT | D33: 16 | E33: 80 | F33: XT0120:2 | G33: JB73 PANEL
A34: AF1202:COM | B34: AF1202N | C34: WHT | D34: 16 | E34: 60 | F34: AU1200:COM | G34: JB73 PANEL
A35: AF1202:V+ | B35: AF1202P | C35: WHT | D35: 16 | E35: 60 | F35: AU1200:V+ | G35: JB73 PANEL
A36: AF1206:COM | B36: AF1207N | C36: WHT | D36: 16 | E36: 60 | F36: AF1207:COM | G36: JB73 PANEL
A37: AF1206:V+ | B37: AF1207P | C37: WHT | D37: 16 | E37: 60 | F37: AF1207:V+ | G37: JB73 PANEL
A38: AU1200:V+ | B38: FU0120 | C38: WHT | D38: 16 | E38: 80 | F38: FU0120:LD | G38: JB73 PANEL
A39: AF1201:V+ | B39: FU0121 | C39: WHT | D39: 16 | E39: 80 | F39: FU0121:LD | G39: JB73 PANEL
A41: XT0121:3 | B41: -0V | C41: WHT | D41: 14 | E41: 60 | F41: XT0510:2 | G41: JB73 PANEL | H41: XT'S
A42: XT0120:3 | B42: -0V | C42: WHT | D42: 14 | E42: 60 | F42: XT0510:1 | G42: JB73 PANEL
A44: XT0336:2 | B44: -0V | C44: WHT | D44: 12 | E44: 60 | F44: XT0120:1 | G44: JB73 PANEL
A46: FU0120:LI | B46: FU0122 | C46: WHT | D46: 14 | E46: 80 | F46: FU0122:LD | G46: JB73 PANEL | H46: FU'S
A47: FU0121:LI | B47: FU0122 | C47: WHT | D47: 14 | E47: 60 | F47: FU0510:LI | G47: JB73 PANEL
...

Sheet JB70 DOOR
A1: JB70 DOOR
A2: CONTROL,JB70
A3: Project # | B3: 4N093
A4: Project Name
A5: Revision | B5: B.1_M.1
A7: Controls DE | B7: D. KIM
A8: Phone:
A9: Controls ME | B9: A. PLVAN
A10: Phone:
A12: From | G12: To
A13: Device ID | B13: Wire No. | C13: Wire ID | D13: Gauge/Size | E13: Length | F13: Device ID | G13: Location | H13: Bundle Name
A14: SA0471:B1-13 | B14: SA0471B113 | C14: WHT | D14: 20 | E14: 240 | F14: AF0087:40 | G14: PANEL A | H14: SA0471
A15: SA0471:B1-14 | B15: SA0471B114 | C15: WHT | D15: 20 | E15: 240 | F15: AF0087:08 | G15: PANEL A
A16: SA0471:B2-13 | B16: SA0471B213 | C16: WHT | D16: 20 | E16: 240 | F16: AF0087:39 | G16: PANEL A
A17: SA0471:B2-14 | B17: SA0471B214 | C17: WHT | D17: 20 | E17: 240 | F17: AF0087:07 | G17: PANEL A
A19: SA0473:11 | B19: SA047311 | C19: WHT | D19: 20 | E19: 240 | F19: AF0087:37 | G19: PANEL A | H19: SA0473
A20: SA0473:12 | B20: SA047312 | C20: WHT | D20: 20 | E20: 240 | F20: AF0087:05 | G20: PANEL A
A21: SA0473:13 | B21: SA047313 | C21: WHT | D21: 20 | E21: 240 | F21: AF0087:38 | G21: PANEL A
A22: SA0473:14 | B22: SA047314 | C22: WHT | D22: 20 | E22: 240 | F22: AF0087:06 | G22: PANEL A
A24: SA0474:B1-13 | B24: SA0474B113 | C24: WHT | D24: 20 | E24: 240 | F24: AF0087:45 | G24: PANEL A | H24: SA0474
A25: SA0474:B1-14 | B25: SA0474B114 | C25: WHT | D25: 20 | E25: 240 | F25: AF0087:13 | G25: PANEL A
A26: SA0474:B2-13 | B26: SA0474B213 | C26: WHT | D26: 20 | E26: 240 | F26: AF0087:44 | G26: PANEL A
A27: SA0474:B2-14 | B27: SA0474B214 | C27: WHT | D27: 20 | E27: 240 | F27: AF0087:12 | G27: PANEL A
A29: SB0471:11 | B29: SB047111 | C29: WHT | D29: 20 | E29: 240 | F29: AF0087:34 | G29: PANEL A | H29: SB0471
A30: SB0471:12 | B30: SB047112 | C30: WHT | D30: 20 | E30: 240 | F30: AF0087:02 | G30: PANEL A
A32: SB0472:B1-12 | B32: ESTOPA | C32: WHT | D32: 20 | E32: 160 | F32: XT0111:20 | G32: RAIL,RIGHT | H32: SB0472
A33: SB0472:B2-11 | B33: SB0472AB111 | C33: WHT | D33: 20 | E33: 160 | F33: XT0111:27 | G33: RAIL,RIGHT
A34: SB0472:B1-11 | B34: SB0472AB211 | C34: WHT | D34: 20 | E34: 160 | F34: XT0111:19 | G34: RAIL,RIGHT
A35: SB0472:B2-12 | B35: SB0472B212 | C35: WHT | D35: 20 | E35: 240 | F35: AF0081:04 | G35: PANEL A
A37: SB0473:13 | B37: SB047313 | C37: WHT | D37: 20 | E37: 240 | F37: AF0087:35 | G37: PANEL A | H37: SB0473
A38: SB0473:14 | B38: SB047314 | C38: WHT | D38: 20 | E38: 240 | F38: AF0087:03 | G38: PANEL A
A39: SB0474:13 | B39: SB047413 | C39: WHT | D39: 20 | E39: 240 | F39: AF0087:36 | G39: PANEL A
A40: SB0474:14 | B40: SB047414 | C40: WHT | D40: 20 | E40: 240 | F40: AF0087:04 | G40: PANEL A
A42: AT1100:NEG | B42: -0V | C42: WHT | D42: 14 | E42: 160 | F42: XT0111:22 | G42: RAIL,RIGHT | H42: AT1100
A43: AT1100:POS | B43: FU1100 | C43: WHT | D43: 14 | E43: 160 | F43: FU1100:LD | G43: RAIL,RIGHT
A45: SH0470:11 | B45: SH047011 | C45: WHT | D45: 20 | E45: 160 | F45: XT0111:7 | G45: RAIL,RIGHT | H45: SH0470
A46: SH0470:12 | B46: SH047012 | C46: WHT | D46: 20 | E46: 160 | F46: XT0111:8 | G46: RAIL,RIGHT
A47: SH0470:13 | B47: SH047013 | C47: WHT | D47: 20 | E47: 160 | F47: XT0111:9 | G47: RAIL,RIGHT
A48: SH0470:14 | B48: SH047014 | C48: WHT | D48: 20 | E48: 160 | F48: XT0111:10 | G48: RAIL,RIGHT
A49: SH0470:X1 | B49: SH0470X1 | C49: WHT | D49: 20 | E49: 160 | F49: XT0111:12 | G49: RAIL,RIGHT
...

Sheet BOP CTRL^JB74_S
A1: BOP CTRL^JB74
A2: JB74
A3: Project # | B3: 4N093
A4: Project Name
A5: Revision | B5: B.1_M.1
A7: Controls DE | B7: D. KIM
A8: Phone:
A9: Controls ME | B9: A. PLVAN
A10: Phone:
A12: From | G12: To
A13: Device ID | B13: Wire No. | C13: Wire ID | D13: Gauge/Size | E13: Length | F13: Device ID | G13: Location | H13: Bundle Name
A14: AF0141:16 | B14: SV76212 | C14: WHT | D14: 20 | E14: 60 | F14: XT0572:3 | G14: BOP CTRL^JB74 | H14: AF40
A15: AF0141:20 | B15: SV76412 | C15: WHT | D15: 20 | E15: 60 | F15: XT0572:5 | G15: BOP CTRL^JB74
A17: AF0141:COM | B17: -0V | C17: WHT | D17: 16 | E17: 60 | F17: XT0140:2 | G17: BOP CTRL^JB74
A18: AF0146:COM | B18: -0V | C18: WHT | D18: 16 | E18: 60 | F18: XT0140:3 | G18: BOP CTRL^JB74
A19: AU0140:COM | B19: -0V | C19: WHT | D19: 16 | E19: 60 | F19: XT0140:2 | G19: BOP CTRL^JB74
A20: AF0142:COM | B20: AU0140N | C20: WHT | D20: 16 | E20: 60 | F20: AU0140:COM | G20: BOP CTRL^JB74
A21: AF0142:V+ | B21: AU0140P | C21: WHT | D21: 16 | E21: 60 | F21: AU0140:V+ | G21: BOP CTRL^JB74
A22: AU0140:V+ | B22: FU0140 | C22: WHT | D22: 16 | E22: 80 | F22: FU0140:LD | G22: BOP CTRL^JB74
A23: AF0141:V+ | B23: FU0141 | C23: WHT | D23: 16 | E23: 80 | F23: FU0141:LD | G23: BOP CTRL^JB74
A24: AF0146:V+ | B24: FU0142 | C24: WHT | D24: 16 | E24: 80 | F24: FU0142:LD | G24: BOP CTRL^JB74
A26: AF0183:04 | B26: ZSC76212 | C26: WHT | D26: 20 | E26: 60 | F26: XT0572:4 | G26: BOP CTRL^JB74 | H26: AF80
A27: AF0183:05 | B27: ZSC76412 | C27: WHT | D27: 20 | E27: 60 | F27: XT0572:6 | G27: BOP CTRL^JB74
A29: AF0181:COM | B29: -0V | C29: WHT | D29: 16 | E29: 60 | F29: XT0140:4 | G29: BOP CTRL^JB74
A30: AF0184:COM | B30: -0V | C30: WHT | D30: 16 | E30: 60 | F30: XT0140:5 | G30: BOP CTRL^JB74
A31: AU0180:COM | B31: -0V | C31: WHT | D31: 16 | E31: 60 | F31: XT0140:4 | G31: BOP CTRL^JB74
A32: AF0183:COM | B32: AF0183N | C32: WHT | D32: 16 | E32: 60 | F32: AF0185:COM | G32: BOP CTRL^JB74
A33: AF0183:V+ | B33: AF0183P | C33: WHT | D33: 16 | E33: 60 | F33: AF0185:V+ | G33: BOP CTRL^JB74
A34: AF0182:COM | B34: AU0180N | C34: WHT | D34: 16 | E34: 60 | F34: AU0180:COM | G34: BOP CTRL^JB74
A35: AF0182:V+ | B35: AU0180P | C35: WHT | D35: 16 | E35: 60 | F35: AU0180:V+ | G35: BOP CTRL^JB74
A36: AU0180:V+ | B36: FU0180 | C36: WHT | D36: 16 | E36: 80 | F36: FU0180:LD | G36: BOP CTRL^JB74
A37: AF0181:V+ | B37: FU0181 | C37: WHT | D37: 16 | E37: 80 | F37: FU0181:LD | G37: BOP CTRL^JB74
A38: AF0184:V+ | B38: FU0182 | C38: WHT | D38: 16 | E38: 60 | F38: FU0182:LD | G38: BOP CTRL^JB74
A40: KA6310:A1 | B40: -014102 | C40: WHT | D40: 20 | E40: 80 | F40: AF0141:02 | G40: BOP CTRL^JB74 | H40: KA:A1
A41: KA0531:A1 | B41: ESTOP | C41: WHT | D41: 20 | E41: 60 | F41: XT0140:8 | G41: BOP CTRL^JB74
A42: KA0535:A1 | B42: KA0131A1 | C42: WHT | D42: 20 | E42: 60 | F42: XT0140:7 | G42: BOP CTRL^JB74
A43: KA0550:A1 | B43: KA0550A1 | C43: WHT | D43: 20 | E43: 80 | F43: AF0184:00 | G43: BOP CTRL^JB74
A44: KA0551:A1 | B44: KA0551A1 | C44: WHT | D44: 20 | E44: 80 | F44: AF0184:02 | G44: BOP CTRL^JB74
A45: KA0554:A1 | B45: KA0554A1 | C45: WHT | D45: 20 | E45: 80 | F45: AF0184:05 | G45: BOP CTRL^JB74
A46: KA0572:A1 | B46: ZSC76212 | C46: WHT | D46: 20 | E46: 60 | F46: XT0572:4 | G46: BOP CTRL^JB74
...

Sheet Bundle Tag Info
A1: TRP-FA3
A2: 4N093
A3: Rev B.1 M.1
A6: R/RAIL JB70 | B6: PLC | C6: B PNL | D6: A PNL | E6: MEDIA CON | F6: JB73 DOOR | G6: HPC CTRL | H6: JB70 DOOR | I6: BOP | J6: Panel Name | K6: Panel Name | L6: Panel Name | M6: Panel Name | N6: Panel Name | O6: Panel Name | P6: Panel Name | Q6: Panel Name | R6: Panel Name | S6: Panel Name | T6: Panel Name | U6: Panel Name | V6: Panel Name | W6: Panel Name | X6: Panel Name | Y6: Panel Name | Z6: Panel Name | AA6: Panel Name | AB6: Panel Name | AC6: Panel Name | AD6: Panel Name
A7: XT | B7: UV-A | C7: KA'S | D7: AF80 | E7: BA'S | F7: SB0472A | G7: KA'S | H7: SA0471 | I7: AF40
A8: BA1100 | B8: XT0051-OUT | C8: KA A1/A2 | D8: UA1200 | E8: FU'S | G8: AF50 | H8: SA0473 | I8: AF80
A9: FU | C9: AF60 | D9: UJ0131 | G9: AF12 | H9: SA0474 | I9: KA:A1
A10: UV0291 | C10: AF70 | D10: AF90 | G10: XT'S | H10: SB0471 | I10: KA:A2
A11: AT0680 | C11: AF40 | D11: KA:A2 | G11: FU'S | H11: SB0472 | I11: KA'S
A12: TO A | C12: BA'S | D12: KA'S | H12: SB0473 | I12: BA1212
A13: TO B | C13: XT/FU | D13: KA:A1 | H13: AT1100 | I13: FU'S
A14: TO PLC | D14: KT/L | H14: SH0470
D15: KT/R | H15: SH0471
D16: XT | H16: SH0472
D17: FU | H17: SH1120
D18: AF-B
D19: KA-B
D20: UA-B
D21: XT-B

Sheet ALL
A1: ALL
A2: =IF('Bundle Tag Info'!A$7<>"",CONCATENATE('Bundle Tag Info'!$A$1," ",CHAR(10),'Bundle Tag Info'!$A$2," ",'Bundle Tag Info'!$A$3,CHAR(10),'Bundle Tag Info'!A$6,CHAR(10),'Bundle Tag Info'!A$7),"") -> TRP-FA3 4N093 Rev B.1 M.1 R/RAIL JB70 XT | J2: =IF('Bundle Tag Info'!J$7<>"",CONCATENATE('Bundle Tag Info'!$A$1," ",CHAR(10),'Bundle Tag Info'!$A$2," ",'Bundle Tag Info'!$A$3,CHAR(10),'Bundle Tag Info'!J$6,CHAR(10),'Bundle Tag Info'!J$7),"") | K2: =IF('Bundle Tag Info'!K$7<>"",CONCATENATE('Bundle Tag Info'!$A$1," ",CHAR(10),'Bundle Tag Info'!$A$2," ",'Bundle Tag Info'!$A$3,CHAR(10),'Bundle Tag Info'!K$6,CHAR(10),'Bundle Tag Info'!K$7),"") | L2: =IF('Bundle Tag Info'!L$7<>"",CONCATENATE('Bundle Tag Info'!$A$1," ",CHAR(10),'Bundle Tag Info'!$A$2," ",'Bundle Tag Info'!$A$3,CHAR(10),'Bundle Tag Info'!L$6,CHAR(10),'Bundle Tag Info'!L$7),"") | M2: =IF('Bundle Tag Info'!M$7<>"",CONCATENATE('Bundle Tag Info'!$A$1," ",CHAR(10),'Bundle Tag Info'!$A$2," ",'Bundle Tag Info'!$A$3,CHAR(10),'Bundle Tag Info'!M$6,CHAR(10),'Bundle Tag Info'!M$7),"") | N2: =IF('Bundle Tag Info'!N$7<>"",CONCATENATE('Bundle Tag Info'!$A$1," ",CHAR(10),'Bundle Tag Info'!$A$2," ",'Bundle Tag Info'!$A$3,CHAR(10),'Bundle Tag Info'!N$6,CHAR(10),'Bundle Tag Info'!N$7),"") | O2: =IF('Bundle Tag Info'!O$7<>"",CONCATENATE('Bundle Tag Info'!$A$1," ",CHAR(10),'Bundle Tag Info'!$A$2," ",'Bundle Tag Info'!$A$3,CHAR(10),'Bundle Tag Info'!O$6,CHAR(10),'Bundle Tag Info'!O$7),"") | P2: =IF('Bundle Tag Info'!P$7<>"",CONCATENATE('Bundle Tag Info'!$A$1," ",CHAR(10),'Bundle Tag Info'!$A$2," ",'Bundle Tag Info'!$A$3,CHAR(10),'Bundle Tag Info'!P$6,CHAR(10),'Bundle Tag Info'!P$7),"") | Q2: =IF('Bundle Tag Info'!Q$7<>"",CONCATENATE('Bundle Tag Info'!$A$1," ",CHAR(10),'Bundle Tag Info'!$A$2," ",'Bundle Tag Info'!$A$3,CHAR(10),'Bundle Tag Info'!Q$6,CHAR(10),'Bundle Tag Info'!Q$7),"") | ... AD2: =IF('Bundle Tag Info'!AD$7<>"",CONCATENATE('Bundle Tag Info'!$A$1," ",CHAR(10),'Bundle Tag Info'!$A$2," ",'Bundle Tag Info'!$A$3,CHAR(10),'Bundle Tag Info'!AD$6,CHAR(10),'Bundle Tag Info'!AD$7),"")
