Workbook

Sheet Blue Labels
A1: (SHT 1) CONSOLE | B1: (SHT 2) CONSOLE DOORS | C1: (SHT 5) SCS | D1: (SHT 6) LEFT SIDE PANEL | E1: (SHT 7) BACK PNL | F1: (SHT 8) RIGHT SIDE PANEL
A2: EL0273 | B2: AT0191 | C2: SB0402 | D2: IEG0130 | E2: PEG0130 | F2: GR0202
A3: HA0273 | B3: AT0190K | C3: SH0418 | D3: FU0090 | E3: QS0011 | F3: AR0600
A4: ZS0273 | B4: AT0190 | C4: SB0401 | D4: FU0091 | E4: XT0011 | F4: AR0700
A5: FG0130 | C5: XT0137 | D5: FU0092 | E5: QS0012 | F5: AR0800
C6: XT0273 | D6: FU0093 | E6: XT0012 | F6: BA0606
C7: FU0273 | D7: FU0094 | E7: XT0970AC | F7: AP0606
C8: GR0121 | D8: FU0095 | E8: FU9700 | F8: AP0605
C9: SB0400 | D9: XT0090 | E9: FU9701 | F9: AP0604
C10: SB0403 | D10: AU0090 | E10: GR0131 | F10: AP0603
C11: SA0500 | D11: AF0091 | E11: XT09701AC | F11: AP0602
C12: AU0020 | D12: AF0092 | E12: XT09702AC | F12: AP0601
C13: AF0021 | D13: AF0093 | E13: XT09703AC | F13: AT0600
C14: AF0022 | D14: AF0094 | E14: XT09704AC | F14: UV0600
C15: FU0023 | D15: AF0095 | E15: H09700 | F15: AP0706
C16: FU0020 | D16: KA0001 | E16: H09701 | F16: AP0705
C17: GR0120 | D17: KA0002 | E17: H09702 | F17: AP0704
D18: KA0003 | E18: GR0132 | F18: AP0703
D19: KA0004 | E19: XT0138 | F19: AP0702
D20: KA0005 | E20: XT0139 | F20: AP0701
D21: KA0006 | E21: XT0134 | F21: AT0700
D22: KA0007 | E22: XT0135 | F22: UV0700
D23: KA0008 | E23: FU0137 | F23: AP0806
D24: KA0009 | E24: FU0138 | F24: AP0805
D25: KA0010 | E25: FU0260 | F25: AP0804
D26: KA0101 | E26: FU0190 | F26: AP0803
D27: KA0102 | E27: XT0201 | F27: AP0802
D28: KA0103 | E28: XT0260 | F28: AP0800
D29: KA0104 | E29: XT0261 | F29: UV0800
... D50: KA0147 | E50: AF0041 | F50: GR0204
D51: KA0148 | E51: AF0042
D52: KA0081 | E52: AF0043
D53: KA0082 | E53: AF0044
D54: KA0083 | E54: AF0045
D55: KA0084 | E55: AF0046
D56: KA0085 | E56: AF0047
D57: KA0086 | E57: XT0014
D58: KA0087 | E58: XT0015
D59: KA0088 | E59: XT0016
D60: KA7400 | E60: XT0017
...

Sheet White Labels
A1: (SHT 7) BACK PNL | B1: (SHT 7) BACK PNL - (SHT 6) LEFT SIDE PANEL | C1: (SHT 7) BACK PNL - (SHT 5) SCS | D1: (SHT 6) LEFT SIDE PANEL | E1: (SHT 6) LEFT SIDE PANEL - (SHT 8) RIGHT SIDE PANEL | F1: (SHT 6) LEFT SIDE PANEL - (SHT 5) SCS | G1: (SHT 8) RIGHT SIDE PANEL | H1: (SHT 5) SCS
A2: AF0061G | B2: AU0090G | C2: AU0020G | D2: GR0133 | E2: IEG01301 | F2: GR0120 | G2: UV0600G | H2: GR0121
A3: AF0062G | B3: AU0100G | D3: GR0134 | E3: IEG01303 | G3: UV0700G
A4: AF0063G | B4: GR0110 | E4: IEG01304 | G4: UV0800G
A5: AF0064G | B5: GR0111
A6: AF0065G
A7: AF0066G
A8: AU0040G
A9: AU0050G
A10: AU0060G
A11: H09700G
A12: UJ0131G
A13: UJ0231G

Sheet Heat Shrink Labels
A1: (SHT 7) BACK PNL | B1: (SHT 6) LEFT SIDE PANEL
A2: WC0061 | B2: WCGTGACAP
A3: WC0970 | B3: WCGTGBCAP
B4: WCGTGCCAP
B5: WCGTGDCAP
B6: WCGTGFCAP
B7: WCSPINRES

Sheet Panel Errors
A1: Panel Errors
A3: Project # | B3: J1848
A4: Project Name | B4: Woodside Goodwyn LSP
A5: Revision | B5: B.2
A7: Controls DE | B7: B.HALBIG
A8: Phone:
A9: Controls ME | B9: N. CARPENTER
A10: Phone:
A12: From | H12: To
A13: Device ID | B13: Location | C13: Cable (W) Conductor (SC) Jumper Clip (JC) | D13: Wire ID | E13: Wire No. | F13: Gauge/Size | G13: Page/Zone | H13: Device ID | I13: Location | J13: Page/Zone
A16: Report date: 4/15/2026 10:11 AM | E16: SolarTools ver. 24.0.84.24712 (Jul 31, 2025)

Sheet Cable Part Numbers
A1: Cable Part Numbers | D1: SolarTools ver. 24.0.84.24712 (Jul 31, 2025)
A2: Project # | B2: J1848
D3: Report date: 4/15/2026 10:11 AM
A4: Project Name | B4: Woodside Goodwyn LSP
A6: Revision | B6: B.2
A8: Controls DE | B8: B.HALBIG
A9: Phone:
A10: Controls ME | B10: N. CARPENTER
A11: Phone:
A13: Device ID | C13: Part Number | E13: Description
A14: W0702 | C14: 1302073-36 | E14: CABLE, ETHERNET - 36 INCHES
A15: W9700 | C15: CF_CAB0_XXGA | E15: CABLE, SUPPLIED BY OTHERS
A16: WC0002 | C16: 1302073-36 | E16: CABLE, ETHERNET - 36 INCHES
A17: WC0004 | C17: 1302073-36 | E17: CABLE, ETHERNET - 36 INCHES
A18: WC0005 | C18: 1302073-36 | E18: CABLE, ETHERNET - 36 INCHES
A19: WC0006 | C19: 1302073-36 | E19: CABLE, ETHERNET - 36 INCHES
A20: WC0009 | C20: 1302073-36 | E20: CABLE, ETHERNET - 36 INCHES
A21: WC0010 | C21: 1302073-36 | E21: CABLE, ETHERNET - 36 INCHES
A22: WC0060 | C22: 1302073-36 | E22: CABLE, ETHERNET - 36 INCHES
A23: WC00602 | C23: 1302073-36 | E23: CABLE, ETHERNET - 36 INCHES
A24: WC0061 | C24: 1022941-13 | E24: TPE, 1 TRIAD TWISTED SHIELDED
... A46: WCSPINRES | C46: 1022941-12 | E46: TPE, 1 PAIR TWISTED SHIELDED

Sheet Part Number List
A1: Part Number List | C1: SolarTools ver. 24.0.84.24712 (Jul 31, 2025)
A2: Project # | B2: J1848
C3: Report date: 4/15/2026 10:11 AM
A4: Project Name | B4: Woodside Goodwyn LSP
A6: Revision | B6: B.2
A8: Controls DE | B8: B.HALBIG
A9: Phone:
A10: Controls ME | B10: N. CARPENTER
A11: Phone:
A13: Device ID | B13: Part Number | C13: Description | D13: Location
A14: AF0041 | B14: 2684693-12,2684693-23 | C14: 5094-IB16XT, 16 DISCRETE INPUT | D14: BACK PNL
A15: AF0042 | B15: 2684693-12,2684693-23 | C15: 5094-IB16XT, 16 DISCRETE INPUT | D15: BACK PNL
A16: AF0043 | B16: 2684693-12,2684693-23 | C16: 5094-IB16XT, 16 DISCRETE INPUT | D16: BACK PNL
A17: AF0044 | B17: 2684693-12,2684693-23 | C17: 5094-IB16XT, 16 DISCRETE INPUT | D17: BACK PNL
A18: AF0045 | B18: 2684693-12,2684693-23 | C18: 5094-IB16XT, 16 DISCRETE INPUT | D18: BACK PNL
A19: AF0046 | B19: 2684693-12,2684693-23 | C19: 5094-IB16XT, 16 DISCRETE INPUT | D19: BACK PNL
A20: AF0047 | B20: 2684693-12,2684693-23 | C20: 5094-IB16XT, 16 DISCRETE INPUT | D20: BACK PNL
A21: AF0051 | B21: 2684693-12,2684693-23 | C21: 5094-IB16XT, 16 DISCRETE INPUT | D21: BACK PNL
A22: AF0052 | B22: 2684693-12,2684693-23 | C22: 5094-IB16XT, 16 DISCRETE INPUT | D22: BACK PNL
A23: AF0053 | B23: 2684693-12,2684693-23 | C23: 5094-IB16XT, 16 DISCRETE INPUT | D23: BACK PNL
A24: AF0054 | B24: 2684693-12,2684693-23 | C24: 5094-IB16XT, 16 DISCRETE INPUT | D24: BACK PNL
... A255: XT0273 | B255: 1067996-7 | C255: TERMINAL STRIP, 4 CONDUCTOR | D255: SCS

Sheet CONSOLE_S
A1: CONSOLE DOOR
A2: STATION CONSOLE
A3: Project # | B3: J1848
A4: Project Name | B4: Woodside Goodwyn LSP
A5: Revision | B5: B.2
A7: Controls DE | B7: B.HALBIG
A8: Phone:
A9: Controls ME | B9: N. CARPENTER
A10: Phone:
A12: From | G12: To
A13: Device ID | B13: Wire No. | C13: Wire ID | D13: Gauge/Size | E13: Length | F13: Device ID | G13: Location | H13: Bundle Name
A14: AT0191:NEG | B14: -0V | C14: WHT | D14: 14 | E14: 280 | F14: XT0262:3 | G14: BACK PNL | H14: AT-BACK
A15: AT0190:NEG | B15: -0V | C15: WHT | D15: 14 | E15: 340 | F15: XT0262:3 | G15: BACK PNL
A16: AT0191:POS | B16: FU0190 | C16: WHT | D16: 14 | E16: 280 | F16: FU0190:LD | G16: BACK PNL
A17: AT0190:POS | B17: FU0190 | C17: WHT | D17: 14 | E17: 340 | F17: FU0190:LD | G17: BACK PNL

Sheet SCS_S
A1: SCS
A2: STATION CONSOLE
A3: Project # | B3: J1848
A4: Project Name | B4: Woodside Goodwyn LSP
A5: Revision | B5: B.2
A7: Controls DE | B7: B.HALBIG
A8: Phone:
A9: Controls ME | B9: N. CARPENTER
A10: Phone:
A12: From | G12: To
A13: Device ID | B13: Wire No. | C13: Wire ID | D13: Gauge/Size | E13: Length | F13: Device ID | G13: Location | H13: Bundle Name
A14: SB0400:B2-12 | B14: -0V | C14: WHT | D14: 20 | E14: 80 | F14: XT0137:4 | G14: SCS | H14: SB0400
A15: SB0400:B1-11 | B15: FU0138 | C15: WHT | D15: 20 | E15: 80 | F15: XT0137:3 | G15: SCS
A17: SB0403:B1-13 | B17: SB0403B113 | C17: WHT | D17: 20 | E17: 80 | F17: AF0021:46 | G17: SCS | H17: SB0403
A18: SB0403:B1-14 | B18: SB0403B114 | C18: WHT | D18: 20 | E18: 80 | F18: AF0021:14 | G18: SCS
A19: SB0403:B2-13 | B19: SB0403B213 | C19: WHT | D19: 20 | E19: 80 | F19: XT0137:5 | G19: SCS
A20: SB0403:B2-14 | B20: SB0403B214 | C20: WHT | D20: 20 | E20: 80 | F20: XT0137:6 | G20: SCS
A22: SA0500:11 | B22: SA050011 | C22: WHT | D22: 20 | E22: 80 | F22: AF0021:38 | G22: SCS | H22: SA0500
A23: SA0500:12 | B23: SA050012 | C23: WHT | D23: 20 | E23: 80 | F23: AF0021:06 | G23: SCS
A24: SA0500:13 | B24: SA050013 | C24: WHT | D24: 20 | E24: 80 | F24: AF0021:39 | G24: SCS
A25: SA0500:14 | B25: SA050014 | C25: WHT | D25: 20 | E25: 80 | F25: AF0021:07 | G25: SCS
A27: SB0402:C | B27: SB0402C | C27: WHT | D27: 20 | E27: 80 | F27: AF0021:37 | G27: SCS | H27: SB0402
A28: SB0402:NO | B28: SB0402NO | C28: WHT | D28: 20 | E28: 80 | F28: AF0021:05 | G28: SCS
A30: SB0401:C | B30: SB0401C | C30: WHT | D30: 20 | E30: 80 | F30: AF0021:47 | G30: SCS | H30: SB0401
A31: SB0401:NO | B31: SB0401NO | C31: WHT | D31: 20 | E31: 80 | F31: AF0021:15 | G31: SCS
A33: SH0418:A | B33: SH0418A | C33: WHT | D33: 20 | E33: 80 | F33: AF0022:43 | G33: SCS | H33: SH0418
A34: SH0418:A+ | B34: SH0418AP | C34: WHT | D34: 20 | E34: 80 | F34: AF0022:11 | G34: SCS
A35: SH0418:B | B35: SH0418B | C35: WHT | D35: 20 | E35: 80 | F35: AF0022:49 | G35: SCS
A36: SH0418:B+ | B36: SH0418BP | C36: WHT | D36: 20 | E36: 80 | F36: AF0022:17 | G36: SCS
A37: SH0418:C | B37: SH0418C | C37: WHT | D37: 20 | E37: 80 | F37: AF0021:40 | G37: SCS
A38: SH0418:NO | B38: SH0418NO | C38: WHT | D38: 20 | E38: 80 | F38: AF0021:08 | G38: SCS
A40: AU0020:V+ | B40: FU0020 | C40: WHT | D40: 14 | E40: 60 | F40: FU0020:LD | G40: SCS | H40: AU/AF
A41: AF0022:V+ | B41: FU0023 | C41: WHT | D41: 14 | E41: 60 | F41: FU0023:LD | G41: SCS
A43: AF0022:COM | B43: -0V | C43: WHT | D43: 14 | E43: 280 | F43: XT0262:1 | G43: BACK PNL | H43: AU/AF-BACK
A44: AU0020:COM | B44: -0V | C44: WHT | D44: 14 | E44: 280 | F44: XT0262:2 | G44: BACK PNL
A46: XT0137:4 | B46: -0V | C46: WHT | D46: 20 | E46: 280 | F46: XT0135:5 | G46: BACK PNL | H46: FU/XT-BACK
A47: XT0137:3 | B47: FU0138 | C47: WHT | D47: 20 | E47: 280 | F47: FU0138:LD | G47: BACK PNL
A49: XT0273:1 | B49: -0V1 | C49: WHT | D49: 14 | E49: 280 | F49: XT0135:6 | G49: BACK PNL
A50: FU0273:LI | B50: FU0137 | C50: WHT | D50: 14 | E50: 280 | F50: XT0139:6 | G50: BACK PNL
A51: FU0020:LI | B51: FU0260 | C51: WHT | D51: 14 | E51: 280 | F51: XT0261:2 | G51: BACK PNL
...

Sheet LEFT SIDE PANEL_S
A1: LEFT SIDE PANEL
A2: STATION CONSOLE
A3: Project # | B3: J1848
A4: Project Name | B4: Woodside Goodwyn LSP
A5: Revision | B5: B.2
A7: Controls DE | B7: B.HALBIG
A8: Phone:
A9: Controls ME | B9: N. CARPENTER
A10: Phone:
A12: From | G12: To
A13: Device ID | B13: Wire No. | C13: Wire ID | D13: Gauge/Size | E13: Length | F13: Device ID | G13: Location | H13: Bundle Name
A14: AF0091:COM | B14: -0V | C14: WHT | D14: 14 | E14: 60 | F14: XT0090:3 | G14: L/S PNL | H14: AU/AF
A15: AF0092:COM | B15: -0V | C15: WHT | D15: 14 | E15: 60 | F15: XT0090:3 | G15: L/S PNL
A16: AF0093:COM | B16: -0V | C16: WHT | D16: 14 | E16: 60 | F16: XT0090:4 | G16: L/S PNL
A17: AF0094:COM | B17: -0V | C17: WHT | D17: 14 | E17: 60 | F17: XT0090:4 | G17: L/S PNL
A18: AF0095:COM | B18: -0V | C18: WHT | D18: 14 | E18: 60 | F18: XT0090:5 | G18: L/S PNL
A19: AF0101:COM | B19: -0V | C19: WHT | D19: 14 | E19: 60 | F19: XT0100:2 | G19: L/S PNL
A20: AF0102:COM | B20: -0V | C20: WHT | D20: 14 | E20: 60 | F20: XT0100:3 | G20: L/S PNL
A21: AF0103:COM | B21: -0V | C21: WHT | D21: 14 | E21: 60 | F21: XT0100:4 | G21: L/S PNL
A22: AF0104:COM | B22: -0V | C22: WHT | D22: 14 | E22: 60 | F22: XT0100:5 | G22: L/S PNL
A23: AF0105:COM | B23: -0V | C23: WHT | D23: 14 | E23: 60 | F23: XT0100:6 | G23: L/S PNL
A24: AF0106:COM | B24: -0V | C24: WHT | D24: 14 | E24: 60 | F24: XT0100:7 | G24: L/S PNL
A25: AU0090:COM | B25: -0V | C25: WHT | D25: 14 | E25: 60 | F25: XT0090:2 | G25: L/S PNL
A26: AU0100:COM | B26: -0V | C26: WHT | D26: 14 | E26: 60 | F26: XT0100:1 | G26: L/S PNL
... A39: AF0106:V+ | B39: FU0106 | C39: WHT | D39: 14 | E39: 160 | F39: FU0106:LD | G39: L/S PNL
A41: KA0001:A1 | B41: KA0001A1 | C41: WHT | D41: 20 | E41: 60 | F41: AF0092:00 | G41: L/S PNL | H41: KA A1
A42: KA0002:A1 | B42: KA0002A1 | C42: WHT | D42: 20 | E42: 60 | F42: AF0092:01 | G42: L/S PNL
A43: KA0003:A1 | B43: KA0003A1 | C43: WHT | D43: 20 | E43: 60 | F43: AF0092:02 | G43: L/S PNL
A44: KA0004:A1 | B44: KA0004A1 | C44: WHT | D44: 20 | E44: 60 | F44: AF0092:03 | G44: L/S PNL
A45: KA0005:A1 | B45: KA0005A1 | C45: WHT | D45: 20 | E45: 60 | F45: AF0092:04 | G45: L/S PNL
A46: KA0006:A1 | B46: KA0006A1 | C46: WHT | D46: 20 | E46: 60 | F46: AF0092:05 | G46: L/S PNL
A47: KA0007:A1 | B47: KA0007A1 | C47: WHT | D47: 20 | E47: 60 | F47: AF0092:06 | G47: L/S PNL
A48: KA0008:A1 | B48: KA0008A1 | C48: WHT | D48: 20 | E48: 60 | F48: AF0092:07 | G48: L/S PNL
A49: KA0009:A1 | B49: KA0009A1 | C49: WHT | D49: 20 | E49: 60 | F49: AF0092:08 | G49: L/S PNL
A50: KA0010:A1 | B50: KA0010A1 | C50: WHT | D50: 20 | E50: 60 | F50: AF0092:09 | G50: L/S PNL
A51: KA0041:A1 | B51: KA0041A1 | C51: WHT | D51: 20 | E51: 60 | F51: AF0092:14 | G51: L/S PNL
A52: KA0042:A1 | B52: KA0042A1 | C52: WHT | D52: 20 | E52: 60 | F52: AF0092:15 | G52: L/S PNL
A53: KA0043:A1 | B53: KA0043A1 | C53: WHT | D53: 20 | E53: 60 | F53: AF0091:14 | G53: L/S PNL
... A105: KA7800:A1 | B105: KA7800A1 | C105: WHT | D105: 20 | E105: 80 | F105: AF0091:04 | G105: L/S PNL
A107: KA0001:A2 | B107: KA0001A2 | C107: WHT | D107: 20 | E107: 60 | F107: AF0092:16 | G107: L/S PNL | H107: KA A2
...

Sheet BACK PANEL_S
A1: BACK PANEL
A2: STATION CONSOLE
A3: Project # | B3: J1848
A4: Project Name | B4: Woodside Goodwyn LSP
A5: Revision | B5: B.2
A7: Controls DE | B7: B.HALBIG
A8: Phone:
A9: Controls ME | B9: N. CARPENTER
A10: Phone:
A12: From | G12: To
A13: Device ID | B13: Wire No. | C13: Wire ID | D13: Gauge/Size | E13: Length | F13: Device ID | G13: Location | H13: Bundle Name
A14: UJ0131:IOUT | B14: UJ0131IOUT | C14: WHT | D14: 20 | E14: 140 | F14: AF0061:34 | G14: BACK PNL | H14: UJ
A15: UJ0131:IS | B15: UJ0131IS | C15: WHT | D15: 20 | E15: 60 | F15: UJ0231:IS | G15: BACK PNL
A16: UJ0131:OK1 | B16: UJ0131OK1 | C16: WHT | D16: 20 | E16: 60 | F16: AF0042:41 | G16: BACK PNL
A17: UJ0131:OK2 | B17: UJ0131OK2 | C17: WHT | D17: 20 | E17: 60 | F17: AF0042:09 | G17: BACK PNL
A18: UJ0131:VIN | B18: UJ0131VIN | C18: WHT | D18: 20 | E18: 140 | F18: AF0061:00 | G18: BACK PNL
A19: UJ0231:IOUT | B19: UJ0231IOUT | C19: WHT | D19: 20 | E19: 120 | F19: AF0061:06 | G19: BACK PNL
A20: UJ0231:OK1 | B20: UJ0231OK1 | C20: WHT | D20: 20 | E20: 60 | F20: AF0042:42 | G20: BACK PNL
A21: UJ0231:OK2 | B21: UJ0231OK2 | C21: WHT | D21: 20 | E21: 60 | F21: AF0042:10 | G21: BACK PNL
A22: UJ0231:VIN | B22: UJ0231VIN | C22: WHT | D22: 20 | E22: 120 | F22: AF0061:04 | G22: BACK PNL
A24: AF0061:08 | B24: -006108 | C24: WHT | D24: 20 | E24: 80 | F24: XT0015:2 | G24: BACK PNL | H24: AU/AF
A25: AF0045:32 | B25: CB01-CL1 | C25: WHT | D25: 20 | E25: 80 | F25: XT0900:3 | G25: BACK PNL
A26: AF0045:00 | B26: CB01-CL2 | C26: WHT | D26: 20 | E26: 80 | F26: XT0900:4 | G26: BACK PNL
A27: AF0043:32 | B27: CB01-OP1 | C27: WHT | D27: 20 | E27: 80 | F27: XT0900:1 | G27: BACK PNL
A28: AF0043:00 | B28: CB01-OP2 | C28: WHT | D28: 20 | E28: 80 | F28: XT0900:2 | G28: BACK PNL
A29: AF0047:32 | B29: CB01-TR1 | C29: WHT | D29: 20 | E29: 80 | F29: XT0900:5 | G29: BACK PNL
A30: AF0047:00 | B30: CB01-TR2 | C30: WHT | D30: 20 | E30: 80 | F30: XT0900:6 | G30: BACK PNL
A31: AF0045:33 | B31: CB02-CL1 | C31: WHT | D31: 20 | E31: 80 | F31: XT0900:16 | G31: BACK PNL
A32: AF0045:01 | B32: CB02-CL2 | C32: WHT | D32: 20 | E32: 80 | F32: XT0900:17 | G32: BACK PNL
A33: AF0043:33 | B33: CB02-OP1 | C33: WHT | D33: 20 | E33: 80 | F33: XT0900:14 | G33: BACK PNL
A34: AF0043:01 | B34: CB02-OP2 | C34: WHT | D34: 20 | E34: 80 | F34: XT0900:15 | G34: BACK PNL
A35: AF0047:33 | B35: CB02-TR1 | C35: WHT | D35: 20 | E35: 80 | F35: XT0900:18 | G35: BACK PNL
A36: AF0047:01 | B36: CB02-TR2 | C36: WHT | D36: 20 | E36: 80 | F36: XT0900:19 | G36: BACK PNL
... A125: AU0060:V+ | B125: FU0060 | C125: WHT | D125: 14 | E125: 60 | F125: FU0060:LD | G125: BACK PNL
A127: XT0262:5 | B127: -0V | C127: WHT | D127: 20 | E127: 120 | F127: XT0018:1 | G127: BACK PNL | H127: FU/XT
A129: XT0017:1 | B129: -0V | C129: WHT | D129: 14 | E129: 120 | F129: XT0262:5 | G129: BACK PNL
A130: XT0134:1 | B130: -0V | C130: WHT | D130: 14 | E130: 120 | F130: XT0016:3 | G130: BACK PNL
A131: XT0134:1 | B131: -0V | C131: WHT | D131: 14 | E131: 60 | F131: XT0135:1 | G131: BACK PNL
A132: XT0134:2 | B132: -0V | C132: WHT | D132: 14 | E132: 60 | F132: XT0260:1 | G132: BACK PNL
A133: FU0040:LI | B133: FU0137 | C133: WHT | D133: 14 | E133: 160 | F133: XT0139:2 | G133: BACK PNL
...

Sheet RIGHT SIDE PANEL_S
A1: RIGHT SIDE PANEL
A2: STATION CONSOLE
A3: Project # | B3: J1848
A4: Project Name | B4: Woodside Goodwyn LSP
A5: Revision | B5: B.2
A7: Controls DE | B7: B.HALBIG
A8: Phone:
A9: Controls ME | B9: N. CARPENTER
A10: Phone:
A12: From | G12: To
A13: Device ID | B13: Wire No. | C13: Wire ID | D13: Gauge/Size | E13: Length | F13: Device ID | G13: Location | H13: Bundle Name
A14: UV0600:(+) | B14: FU0600 | C14: WHT | D14: 14 | E14: 80 | F14: FU0600:LD | G14: R/S PNL | H14: UV
A15: UV0700:(+) | B15: FU0700 | C15: WHT | D15: 14 | E15: 80 | F15: FU0700:LD | G15: R/S PNL
A16: UV0800:(+) | B16: FU0800 | C16: WHT | D16: 14 | E16: 60 | F16: FU0800:LD | G16: R/S PNL
A18: BA0606DH+:+ | B18: FU0606DH+ | C18: WHT | D18: 20 | E18: 60 | F18: FU0606DH+:LD | G18: R/S PNL | H18: BA0606DH+
A20: BA0606DH+:- | B20: -0V | C20: WHT | D20: 14 | E20: 60 | F20: XT0102:2 | G20: R/S PNL
A22: BA0680:POS | B22: FU0681 | C22: WHT | D22: 20 | E22: 60 | F22: FU0681:LD | G22: R/S PNL | H22: BA0680
A24: BA0680:NEG | B24: -0V | C24: WHT | D24: 14 | E24: 60 | F24: XT0681:2 | G24: R/S PNL
A26: BA0606:- | B26: -0V | C26: WHT | D26: 16 | E26: 60 | F26: XT0102:1 | G26: R/S PNL | H26: BA0606
A27: BA0606:+ | B27: FU0606 | C27: WHT | D27: 16 | E27: 60 | F27: FU0606:LD | G27: R/S PNL
A29: AT0680:NEG | B29: -0V | C29: WHT | D29: 14 | E29: 60 | F29: XT0681:1 | G29: R/S PNL | H29: AT0680
A30: AT0680:POS | B30: FU0680 | C30: WHT | D30: 14 | E30: 60 | F30: FU0680:LD | G30: R/S PNL
A32: FU0606:LI | B32: FU0137 | C32: WHT | D32: 14 | E32: 60 | F32: XT0101:1 | G32: R/S PNL | H32: FU
A33: FU0606DH+:LI | B33: FU0137 | C33: WHT | D33: 14 | E33: 60 | F33: XT0101:2 | G33: R/S PNL
A34: FU0681:LI | B34: FU0137 | C34: WHT | D34: 14 | E34: 60 | F34: XT0680:2 | G34: R/S PNL
A35: FU0680:LI | B35: FU0137 | C35: WHT | D35: 14 | E35: 60 | F35: XT0680:1 | G35: R/S PNL

Sheet Bundle Tag Info
A1: WOODSIDE GOODWYNN #1
A2: J1848
A3: Rev. B.2M1
A6: CONSOLE | B6: SCS | C6: L/S PNL | D6: BACK PNL | E6: R/S PNL
A7: AT-BACK | B7: SB0400 | C7: AU/AF | D7: UJ | E7: UV
B8: SB0403 | C8: KA A1 | D8: AU/AF | E8: BA0606DH+
B9: SA0500 | C9: KA A2 | D9: FU/XT | E9: BA0680
B10: SB0402 | C10: KA | D10: FU/XT RED | E10: BA0606
B11: SB0401 | C11: FU/XT | D11: QS RED | E11: AT0680
B12: SH0418 | C12: KA-BACK | D12: QS | E12: FU
B13: AU/AF | C13: XT-BACK | D13: XT-R/S
B14: AU/AF-BACK
B15: FU/XT-BACK

Sheet Bundle Tags2
A1: =IF('Bundle Tag Info'!A6<>"Panel Name",'Bundle Tag Info'!A6,"") -> CONSOLE | B1: =IF('Bundle Tag Info'!B6<>"Panel Name",'Bundle Tag Info'!B6,"") -> SCS | C1: =IF('Bundle Tag Info'!C6<>"Panel Name",'Bundle Tag Info'!C6,"") -> L/S PNL | D1: =IF('Bundle Tag Info'!D6<>"Panel Name",'Bundle Tag Info'!D6,"") -> BACK PNL | E1: =IF('Bundle Tag Info'!E6<>"Panel Name",'Bundle Tag Info'!E6,"") -> R/S PNL | F1: =IF('Bundle Tag Info'!#REF!<>"Panel Name",'Bundle Tag Info'!#REF!,"") -> #REF! | G1: =IF('Bundle Tag Info'!#REF!<>"Panel Name",'Bundle Tag Info'!#REF!,"") -> #REF! | H1: =IF('Bundle Tag Info'!#REF!<>"Panel Name",'Bundle Tag Info'!#REF!,"") -> #REF! | I1: =IF('Bundle Tag Info'!#REF!<>"Panel Name",'Bundle Tag Info'!#REF!,"") -> #REF! | J1: =IF('Bundle Tag Info'!#REF!<>"Panel Name",'Bundle Tag Info'!#REF!,"") -> #REF! | K1: =IF('Bundle Tag Info'!#REF!<>"Panel Name",'Bundle Tag Info'!#REF!,"") -> #REF! | L1: =IF('Bundle Tag Info'!#REF!<>"Panel Name",'Bundle Tag Info'!#REF!,"") -> #REF! | M1: =IF('Bundle Tag Info'!#REF!<>"Panel Name",'Bundle Tag Info'!#REF!,"") -> #REF! | ... AD1: =IF('Bundle Tag Info'!#REF!<>"Panel Name",'Bundle Tag Info'!#REF!,"") -> #REF!
A2: =IF('Bundle Tag Info'!A$7<>"",CONCATENATE('Bundle Tag Info'!$A$1," ",CHAR(10),'Bundle Tag Info'!$A$2," ",'Bundle Tag Info'!$A$3,CHAR(10),'Bundle Tag Info'!A$6,CHAR(10),'Bundle Tag Info'!A$7),"") -> WOODSIDE GOODWYNN #1 J1848 Rev. B.2M1 CONSOLE AT-BACK | B2: =IF('Bundle Tag Info'!B$7<>"",CONCATENATE('Bundle Tag Info'!$A$1," ",CHAR(10),'Bundle Tag Info'!$A$2," ",'Bundle Tag Info'!$A$3,CHAR(10),'Bundle Tag Info'!B$6,CHAR(10),'Bundle Tag Info'!B$7),"") -> WOODSIDE GOODWYNN #1 J1848 Rev. B.2M1 SCS SB0400 | C2: =IF('Bundle Tag Info'!C$7<>"",CONCATENATE('Bundle Tag Info'!$A$1," ",CHAR(10),'Bundle Tag Info'!$A$2," ",'Bundle Tag Info'!$A$3,CHAR(10),'Bundle Tag Info'!C$6,CHAR(10),'Bundle Tag Info'!C$7),"") -> WOODSIDE GOODWYNN #1 J1848 Rev. B.2M1 L/S PNL AU/AF | D2: =IF('Bundle Tag Info'!D$7<>"",CONCATENATE('Bundle Tag Info'!$A$1," ",CHAR(10),'Bundle Tag Info'!$A$2," ",'Bundle Tag Info'!$A$3,CHAR(10),'Bundle Tag Info'!D$6,CHAR(10),'Bundle Tag Info'!D$7),"") -> WOODSIDE GOODWYNN #1 J1848 Rev. B.2M1 BACK PNL UJ | E2: =IF('Bundle Tag Info'!E$7<>"",CONCATENATE('Bundle Tag Info'!$A$1," ",CHAR(10),'Bundle Tag Info'!$A$2," ",'Bundle Tag Info'!$A$3,CHAR(10),'Bundle Tag Info'!E$6,CHAR(10),'Bundle Tag Info'!E$7),"") -> WOODSIDE GOODWYNN #1 J1848 Rev. B.2M1 R/S PNL UV | F2: =IF('Bundle Tag Info'!#REF!<>"",CONCATENATE('Bundle Tag Info'!$A$1," ",CHAR(10),'Bundle Tag Info'!$A$2," ",'Bundle Tag Info'!$A$3,CHAR(10),'Bundle Tag Info'!#REF!,CHAR(10),'Bundle Tag Info'!#REF!),"") -> #REF! | G2: =IF('Bundle Tag Info'!#REF!<>"",CONCATENATE('Bundle Tag Info'!$A$1," ",CHAR(10),'Bundle Tag Info'!$A$2," ",'Bundle Tag Info'!$A$3,CHAR(10),'Bundle Tag Info'!#REF!,CHAR(10),'Bundle Tag Info'!#REF!),"") -> #REF! | H2: =IF('Bundle Tag Info'!#REF!<>"",CONCATENATE('Bundle Tag Info'!$A$1," ",CHAR(10),'Bundle Tag Info'!$A$2," ",'Bundle Tag Info'!$A$3,CHAR(10),'Bundle Tag Info'!#REF!,CHAR(10),'Bundle Tag Info'!#REF!),"") -> #REF! | I2: =IF('Bundle Tag Info'!#REF!<>"",CONCATENATE('Bundle Tag Info'!$A$1," ",CHAR(10),'Bundle Tag Info'!$A$2," ",'Bundle Tag Info'!$A$3,CHAR(10),'Bundle Tag Info'!#REF!,CHAR(10),'Bundle Tag Info'!#REF!),"") -> #REF! | J2: =IF('Bundle Tag Info'!#REF!<>"",CONCATENATE('Bundle Tag Info'!$A$1," ",CHAR(10),'Bundle Tag Info'!$A$2," ",'Bundle Tag Info'!$A$3,CHAR(10),'Bundle Tag Info'!#REF!,CHAR(10),'Bundle Tag Info'!#REF!),"") -> #REF! | K2: =IF('Bundle Tag Info'!#REF!<>"",CONCATENATE('Bundle Tag Info'!$A$1," ",CHAR(10),'Bundle Tag Info'!$A$2," ",'Bundle Tag Info'!$A$3,CHAR(10),'Bundle Tag Info'!#REF!,CHAR(10),'Bundle Tag Info'!#REF!),"") -> #REF! | L2: =IF('Bundle Tag Info'!#REF!<>"",CONCATENATE('Bundle Tag Info'!$A$1," ",CHAR(10),'Bundle Tag Info'!$A$2," ",'Bundle Tag Info'!$A$3,CHAR(10),'Bundle Tag Info'!#REF!,CHAR(10),'Bundle Tag Info'!#REF!),"") -> #REF! | M2: =IF('Bundle Tag Info'!#REF!<>"",CONCATENATE('Bundle Tag Info'!$A$1," ",CHAR(10),'Bundle Tag Info'!$A$2," ",'Bundle Tag Info'!$A$3,CHAR(10),'Bundle Tag Info'!#REF!,CHAR(10),'Bundle Tag Info'!#REF!),"") -> #REF! | ... AD2: =IF('Bundle Tag Info'!#REF!<>"",CONCATENATE('Bundle Tag Info'!$A$1," ",CHAR(10),'Bundle Tag Info'!$A$2," ",'Bundle Tag Info'!$A$3,CHAR(10),'Bundle Tag Info'!#REF!,CHAR(10),'Bundle Tag Info'!#REF!),"") -> #REF!
A3: =IF('Bundle Tag Info'!A$8<>"",CONCATENATE('Bundle Tag Info'!$A$1," ",CHAR(10),'Bundle Tag Info'!$A$2," ",'Bundle Tag Info'!$A$3,CHAR(10),'Bundle Tag Info'!A$6,CHAR(10),'Bundle Tag Info'!A$8),"") | B3: =IF('Bundle Tag Info'!B$8<>"",CONCATENATE('Bundle Tag Info'!$A$1," ",CHAR(10),'Bundle Tag Info'!$A$2," ",'Bundle Tag Info'!$A$3,CHAR(10),'Bundle Tag Info'!B$6,CHAR(10),'Bundle Tag Info'!B$8),"") -> WOODSIDE GOODWYNN #1 J1848 Rev. B.2M1 SCS SB0403 | C3: =IF('Bundle Tag Info'!C$8<>"",CONCATENATE('Bundle Tag Info'!$A$1," ",CHAR(10),'Bundle Tag Info'!$A$2," ",'Bundle Tag Info'!$A$3,CHAR(10),'Bundle Tag Info'!C$6,CHAR(10),'Bundle Tag Info'!C$8),"") -> WOODSIDE GOODWYNN #1 J1848 Rev. B.2M1 L/S PNL KA A1 | D3: =IF('Bundle Tag Info'!D$8<>"",CONCATENATE('Bundle Tag Info'!$A$1," ",CHAR(10),'Bundle Tag Info'!$A$2," ",'Bundle Tag Info'!$A$3,CHAR(10),'Bundle Tag Info'!D$6,CHAR(10),'Bundle Tag Info'!D$8),"") -> WOODSIDE GOODWYNN #1 J1848 Rev. B.2M1 BACK PNL AU/AF | E3: =IF('Bundle Tag Info'!E$8<>"",CONCATENATE('Bundle Tag Info'!$A$1," ",CHAR(10),'Bundle Tag Info'!$A$2," ",'Bundle Tag Info'!$A$3,CHAR(10),'Bundle Tag Info'!E$6,CHAR(10),'Bundle Tag Info'!E$8),"") -> WOODSIDE GOODWYNN #1 J1848 Rev. B.2M1 R/S PNL BA0606DH+ | F3: =IF('Bundle Tag Info'!#REF!<>"",CONCATENATE('Bundle Tag Info'!$A$1," ",CHAR(10),'Bundle Tag Info'!$A$2," ",'Bundle Tag Info'!$A$3,CHAR(10),'Bundle Tag Info'!#REF!,CHAR(10),'Bundle Tag Info'!#REF!),"") -> #REF! | G3: =IF('Bundle Tag Info'!#REF!<>"",CONCATENATE('Bundle Tag Info'!$A$1," ",CHAR(10),'Bundle Tag Info'!$A$2," ",'Bundle Tag Info'!$A$3,CHAR(10),'Bundle Tag Info'!#REF!,CHAR(10),'Bundle Tag Info'!#REF!),"") -> #REF! | H3: =IF('Bundle Tag Info'!#REF!<>"",CONCATENATE('Bundle Tag Info'!$A$1," ",CHAR(10),'Bundle Tag Info'!$A$2," ",'Bundle Tag Info'!$A$3,CHAR(10),'Bundle Tag Info'!#REF!,CHAR(10),'Bundle Tag Info'!#REF!),"") -> #REF! | I3: =IF('Bundle Tag Info'!#REF!<>"",CONCATENATE('Bundle Tag Info'!$A$1," ",CHAR(10),'Bundle Tag Info'!$A$2," ",'Bundle Tag Info'!$A$3,CHAR(10),'Bundle Tag Info'!#REF!,CHAR(10),'Bundle Tag Info'!#REF!),"") -> #REF! | J3: =IF('Bundle Tag Info'!#REF!<>"",CONCATENATE('Bundle Tag Info'!$A$1," ",CHAR(10),'Bundle Tag Info'!$A$2," ",'Bundle Tag Info'!$A$3,CHAR(10),'Bundle Tag Info'!#REF!,CHAR(10),'Bundle Tag Info'!#REF!),"") -> #REF! | K3: =IF('Bundle Tag Info'!#REF!<>"",CONCATENATE('Bundle Tag Info'!$A$1," ",CHAR(10),'Bundle Tag Info'!$A$2," ",'Bundle Tag Info'!$A$3,CHAR(10),'Bundle Tag Info'!#REF!,CHAR(10),'Bundle Tag Info'!#REF!),"") -> #REF! | L3: =IF('Bundle Tag Info'!#REF!<>"",CONCATENATE('Bundle Tag Info'!$A$1," ",CHAR(10),'Bundle Tag Info'!$A$2," ",'Bundle Tag Info'!$A$3,CHAR(10),'Bundle Tag Info'!#REF!,CHAR(10),'Bundle Tag Info'!#REF!),"") -> #REF! | M3: =IF('Bundle Tag Info'!#REF!<>"",CONCATENATE('Bundle Tag Info'!$A$1," ",CHAR(10),'Bundle Tag Info'!$A$2," ",'Bundle Tag Info'!$A$3,CHAR(10),'Bundle Tag Info'!#REF!,CHAR(10),'Bundle Tag Info'!#REF!),"") -> #REF! | ... AD3: =IF('Bundle Tag Info'!#REF!<>"",CONCATENATE('Bundle Tag Info'!$A$1," ",CHAR(10),'Bundle Tag Info'!$A$2," ",'Bundle Tag Info'!$A$3,CHAR(10),'Bundle Tag Info'!#REF!,CHAR(10),'Bundle Tag Info'!#REF!),"") -> #REF!
A4: =IF('Bundle Tag Info'!A$9<>"",CONCATENATE('Bundle Tag Info'!$A$1," ",CHAR(10),'Bundle Tag Info'!$A$2," ",'Bundle Tag Info'!$A$3,CHAR(10),'Bundle Tag Info'!A$6,CHAR(10),'Bundle Tag Info'!A$9),"") | B4: =IF('Bundle Tag Info'!B$9<>"",CONCATENATE('Bundle Tag Info'!$A$1," ",CHAR(10),'Bundle Tag Info'!$A$2," ",'Bundle Tag Info'!$A$3,CHAR(10),'Bundle Tag Info'!B$6,CHAR(10),'Bundle Tag Info'!B$9),"") -> WOODSIDE GOODWYNN #1 J1848 Rev. B.2M1 SCS SA0500 | C4: =IF('Bundle Tag Info'!C$9<>"",CONCATENATE('Bundle Tag Info'!$A$1," ",CHAR(10),'Bundle Tag Info'!$A$2," ",'Bundle Tag Info'!$A$3,CHAR(10),'Bundle Tag Info'!C$6,CHAR(10),'Bundle Tag Info'!C$9),"") -> WOODSIDE GOODWYNN #1 J1848 Rev. B.2M1 L/S PNL KA A2 | D4: =IF('Bundle Tag Info'!D$9<>"",CONCATENATE('Bundle Tag Info'!$A$1," ",CHAR(10),'Bundle Tag Info'!$A$2," ",'Bundle Tag Info'!$A$3,CHAR(10),'Bundle Tag Info'!D$6,CHAR(10),'Bundle Tag Info'!D$9),"") -> WOODSIDE GOODWYNN #1 J1848 Rev. B.2M1 BACK PNL FU/XT | E4: =IF('Bundle Tag Info'!E$9<>"",CONCATENATE('Bundle Tag Info'!$A$1," ",CHAR(10),'Bundle Tag Info'!$A$2," ",'Bundle Tag Info'!$A$3,CHAR(10),'Bundle Tag Info'!E$6,CHAR(10),'Bundle Tag Info'!E$9),"") -> WOODSIDE GOODWYNN #1 J1848 Rev. B.2M1 R/S PNL BA0680 | F4: =IF('Bundle Tag Info'!#REF!<>"",CONCATENATE('Bundle Tag Info'!$A$1," ",CHAR(10),'Bundle Tag Info'!$A$2," ",'Bundle Tag Info'!$A$3,CHAR(10),'Bundle Tag Info'!#REF!,CHAR(10),'Bundle Tag Info'!#REF!),"") -> #REF! | G4: =IF('Bundle Tag Info'!#REF!<>"",CONCATENATE('Bundle Tag Info'!$A$1," ",CHAR(10),'Bundle Tag Info'!$A$2," ",'Bundle Tag Info'!$A$3,CHAR(10),'Bundle Tag Info'!#REF!,CHAR(10),'Bundle Tag Info'!#REF!),"") -> #REF! | H4: =IF('Bundle Tag Info'!#REF!<>"",CONCATENATE('Bundle Tag Info'!$A$1," ",CHAR(10),'Bundle Tag Info'!$A$2," ",'Bundle Tag Info'!$A$3,CHAR(10),'Bundle Tag Info'!#REF!,CHAR(10),'Bundle Tag Info'!#REF!),"") -> #REF! | I4: =IF('Bundle Tag Info'!#REF!<>"",CONCATENATE('Bundle Tag Info'!$A$1," ",CHAR(10),'Bundle Tag Info'!$A$2," ",'Bundle Tag Info'!$A$3,CHAR(10),'Bundle Tag Info'!#REF!,CHAR(10),'Bundle Tag Info'!#REF!),"") -> #REF! | J4: =IF('Bundle Tag Info'!#REF!<>"",CONCATENATE('Bundle Tag Info'!$A$1," ",CHAR(10),'Bundle Tag Info'!$A$2," ",'Bundle Tag Info'!$A$3,CHAR(10),'Bundle Tag Info'!#REF!,CHAR(10),'Bundle Tag Info'!#REF!),"") -> #REF! | K4: =IF('Bundle Tag Info'!#REF!<>"",CONCATENATE('Bundle Tag Info'!$A$1," ",CHAR(10),'Bundle Tag Info'!$A$2," ",'Bundle Tag Info'!$A$3,CHAR(10),'Bundle Tag Info'!#REF!,CHAR(10),'Bundle Tag Info'!#REF!),"") -> #REF! | L4: =IF('Bundle Tag Info'!#REF!<>"",CONCATENATE('Bundle Tag Info'!$A$1," ",CHAR(10),'Bundle Tag Info'!$A$2," ",'Bundle Tag Info'!$A$3,CHAR(10),'Bundle Tag Info'!#REF!,CHAR(10),'Bundle Tag Info'!#REF!),"") -> #REF! | M4: =IF('Bundle Tag Info'!#REF!<>"",CONCATENATE('Bundle Tag Info'!$A$1," ",CHAR(10),'Bundle Tag Info'!$A$2," ",'Bundle Tag Info'!$A$3,CHAR(10),'Bundle Tag Info'!#REF!,CHAR(10),'Bundle Tag Info'!#REF!),"") -> #REF! | ... AD4: =IF('Bundle Tag Info'!#REF!<>"",CONCATENATE('Bundle Tag Info'!$A$1," ",CHAR(10),'Bundle Tag Info'!$A$2," ",'Bundle Tag Info'!$A$3,CHAR(10),'Bundle Tag Info'!#REF!,CHAR(10),'Bundle Tag Info'!#REF!),"") -> #REF!
A5: =IF('Bundle Tag Info'!A$10<>"",CONCATENATE('Bundle Tag Info'!$A$1," ",CHAR(10),'Bundle Tag Info'!$A$2," ",'Bundle Tag Info'!$A$3,CHAR(10),'Bundle Tag Info'!A$6,CHAR(10),'Bundle Tag Info'!A$10),"") | B5: =IF('Bundle Tag Info'!B$10<>"",CONCATENATE('Bundle Tag Info'!$A$1," ",CHAR(10),'Bundle Tag Info'!$A$2," ",'Bundle Tag Info'!$A$3,CHAR(10),'Bundle Tag Info'!B$6,CHAR(10),'Bundle Tag Info'!B$10),"") -> WOODSIDE GOODWYNN #1 J1848 Rev. B.2M1 SCS SB0402 | C5: =IF('Bundle Tag Info'!C$10<>"",CONCATENATE('Bundle Tag Info'!$A$1," ",CHAR(10),'Bundle Tag Info'!$A$2," ",'Bundle Tag Info'!$A$3,CHAR(10),'Bundle Tag Info'!C$6,CHAR(10),'Bundle Tag Info'!C$10),"") -> WOODSIDE GOODWYNN #1 J1848 Rev. B.2M1 L/S PNL KA | D5: =IF('Bundle Tag Info'!D$10<>"",CONCATENATE('Bundle Tag Info'!$A$1," ",CHAR(10),'Bundle Tag Info'!$A$2," ",'Bundle Tag Info'!$A$3,CHAR(10),'Bundle Tag Info'!D$6,CHAR(10),'Bundle Tag Info'!D$10),"") -> WOODSIDE GOODWYNN #1 J1848 Rev. B.2M1 BACK PNL FU/XT RED | E5: =IF('Bundle Tag Info'!E$10<>"",CONCATENATE('Bundle Tag Info'!$A$1," ",CHAR(10),'Bundle Tag Info'!$A$2," ",'Bundle Tag Info'!$A$3,CHAR(10),'Bundle Tag Info'!E$6,CHAR(10),'Bundle Tag Info'!E$10),"") -> WOODSIDE GOODWYNN #1 J1848 Rev. B.2M1 R/S PNL BA0606 | F5: =IF('Bundle Tag Info'!#REF!<>"",CONCATENATE('Bundle Tag Info'!$A$1," ",CHAR(10),'Bundle Tag Info'!$A$2," ",'Bundle Tag Info'!$A$3,CHAR(10),'Bundle Tag Info'!#REF!,CHAR(10),'Bundle Tag Info'!#REF!),"") -> #REF! | G5: =IF('Bundle Tag Info'!#REF!<>"",CONCATENATE('Bundle Tag Info'!$A$1," ",CHAR(10),'Bundle Tag Info'!$A$2," ",'Bundle Tag Info'!$A$3,CHAR(10),'Bundle Tag Info'!#REF!,CHAR(10),'Bundle Tag Info'!#REF!),"") -> #REF! | H5: =IF('Bundle Tag Info'!#REF!<>"",CONCATENATE('Bundle Tag Info'!$A$1," ",CHAR(10),'Bundle Tag Info'!$A$2," ",'Bundle Tag Info'!$A$3,CHAR(10),'Bundle Tag Info'!#REF!,CHAR(10),'Bundle Tag Info'!#REF!),"") -> #REF! | I5: =IF('Bundle Tag Info'!#REF!<>"",CONCATENATE('Bundle Tag Info'!$A$1," ",CHAR(10),'Bundle Tag Info'!$A$2," ",'Bundle Tag Info'!$A$3,CHAR(10),'Bundle Tag Info'!#REF!,CHAR(10),'Bundle Tag Info'!#REF!),"") -> #REF! | J5: =IF('Bundle Tag Info'!#REF!<>"",CONCATENATE('Bundle Tag Info'!$A$1," ",CHAR(10),'Bundle Tag Info'!$A$2," ",'Bundle Tag Info'!$A$3,CHAR(10),'Bundle Tag Info'!#REF!,CHAR(10),'Bundle Tag Info'!#REF!),"") -> #REF! | K5: =IF('Bundle Tag Info'!#REF!<>"",CONCATENATE('Bundle Tag Info'!$A$1," ",CHAR(10),'Bundle Tag Info'!$A$2," ",'Bundle Tag Info'!$A$3,CHAR(10),'Bundle Tag Info'!#REF!,CHAR(10),'Bundle Tag Info'!#REF!),"") -> #REF! | L5: =IF('Bundle Tag Info'!#REF!<>"",CONCATENATE('Bundle Tag Info'!$A$1," ",CHAR(10),'Bundle Tag Info'!$A$2," ",'Bundle Tag Info'!$A$3,CHAR(10),'Bundle Tag Info'!#REF!,CHAR(10),'Bundle Tag Info'!#REF!),"") -> #REF! | M5: =IF('Bundle Tag Info'!#REF!<>"",CONCATENATE('Bundle Tag Info'!$A$1," ",CHAR(10),'Bundle Tag Info'!$A$2," ",'Bundle Tag Info'!$A$3,CHAR(10),'Bundle Tag Info'!#REF!,CHAR(10),'Bundle Tag Info'!#REF!),"") -> #REF! | ... AD5: =IF('Bundle Tag Info'!#REF!<>"",CONCATENATE('Bundle Tag Info'!$A$1," ",CHAR(10),'Bundle Tag Info'!$A$2," ",'Bundle Tag Info'!$A$3,CHAR(10),'Bundle Tag Info'!#REF!,CHAR(10),'Bundle Tag Info'!#REF!),"") -> #REF!
A6: =IF('Bundle Tag Info'!A$11<>"",CONCATENATE('Bundle Tag Info'!$A$1," ",CHAR(10),'Bundle Tag Info'!$A$2," ",'Bundle Tag Info'!$A$3,CHAR(10),'Bundle Tag Info'!A$6,CHAR(10),'Bundle Tag Info'!A$11),"") | B6: =IF('Bundle Tag Info'!B$11<>"",CONCATENATE('Bundle Tag Info'!$A$1," ",CHAR(10),'Bundle Tag Info'!$A$2," ",'Bundle Tag Info'!$A$3,CHAR(10),'Bundle Tag Info'!B$6,CHAR(10),'Bundle Tag Info'!B$11),"") -> WOODSIDE GOODWYNN #1 J1848 Rev. B.2M1 SCS SB0401 | C6: =IF('Bundle Tag Info'!C$11<>"",CONCATENATE('Bundle Tag Info'!$A$1," ",CHAR(10),'Bundle Tag Info'!$A$2," ",'Bundle Tag Info'!$A$3,CHAR(10),'Bundle Tag Info'!C$6,CHAR(10),'Bundle Tag Info'!C$11),"") -> WOODSIDE GOODWYNN #1 J1848 Rev. B.2M1 L/S PNL FU/XT | D6: =IF('Bundle Tag Info'!D$11<>"",CONCATENATE('Bundle Tag Info'!$A$1," ",CHAR(10),'Bundle Tag Info'!$A$2," ",'Bundle Tag Info'!$A$3,CHAR(10),'Bundle Tag Info'!D$6,CHAR(10),'Bundle Tag Info'!D$11),"") -> WOODSIDE GOODWYNN #1 J1848 Rev. B.2M1 BACK PNL QS RED | E6: =IF('Bundle Tag Info'!E$11<>"",CONCATENATE('Bundle Tag Info'!$A$1," ",CHAR(10),'Bundle Tag Info'!$A$2," ",'Bundle Tag Info'!$A$3,CHAR(10),'Bundle Tag Info'!E$6,CHAR(10),'Bundle Tag Info'!E$11),"") -> WOODSIDE GOODWYNN #1 J1848 Rev. B.2M1 R/S PNL AT0680 | F6: =IF('Bundle Tag Info'!#REF!<>"",CONCATENATE('Bundle Tag Info'!$A$1," ",CHAR(10),'Bundle Tag Info'!$A$2," ",'Bundle Tag Info'!$A$3,CHAR(10),'Bundle Tag Info'!#REF!,CHAR(10),'Bundle Tag Info'!#REF!),"") -> #REF! | G6: =IF('Bundle Tag Info'!#REF!<>"",CONCATENATE('Bundle Tag Info'!$A$1," ",CHAR(10),'Bundle Tag Info'!$A$2," ",'Bundle Tag Info'!$A$3,CHAR(10),'Bundle Tag Info'!#REF!,CHAR(10),'Bundle Tag Info'!#REF!),"") -> #REF! | H6: =IF('Bundle Tag Info'!#REF!<>"",CONCATENATE('Bundle Tag Info'!$A$1," ",CHAR(10),'Bundle Tag Info'!$A$2," ",'Bundle Tag Info'!$A$3,CHAR(10),'Bundle Tag Info'!#REF!,CHAR(10),'Bundle Tag Info'!#REF!),"") -> #REF! | I6: =IF('Bundle Tag Info'!#REF!<>"",CONCATENATE('Bundle Tag Info'!$A$1," ",CHAR(10),'Bundle Tag Info'!$A$2," ",'Bundle Tag Info'!$A$3,CHAR(10),'Bundle Tag Info'!#REF!,CHAR(10),'Bundle Tag Info'!#REF!),"") -> #REF! | J6: =IF('Bundle Tag Info'!#REF!<>"",CONCATENATE('Bundle Tag Info'!$A$1," ",CHAR(10),'Bundle Tag Info'!$A$2," ",'Bundle Tag Info'!$A$3,CHAR(10),'Bundle Tag Info'!#REF!,CHAR(10),'Bundle Tag Info'!#REF!),"") -> #REF! | K6: =IF('Bundle Tag Info'!#REF!<>"",CONCATENATE('Bundle Tag Info'!$A$1," ",CHAR(10),'Bundle Tag Info'!$A$2," ",'Bundle Tag Info'!$A$3,CHAR(10),'Bundle Tag Info'!#REF!,CHAR(10),'Bundle Tag Info'!#REF!),"") -> #REF! | L6: =IF('Bundle Tag Info'!#REF!<>"",CONCATENATE('Bundle Tag Info'!$A$1," ",CHAR(10),'Bundle Tag Info'!$A$2," ",'Bundle Tag Info'!$A$3,CHAR(10),'Bundle Tag Info'!#REF!,CHAR(10),'Bundle Tag Info'!#REF!),"") -> #REF! | M6: =IF('Bundle Tag Info'!#REF!<>"",CONCATENATE('Bundle Tag Info'!$A$1," ",CHAR(10),'Bundle Tag Info'!$A$2," ",'Bundle Tag Info'!$A$3,CHAR(10),'Bundle Tag Info'!#REF!,CHAR(10),'Bundle Tag Info'!#REF!),"") -> #REF! | ... AD6: =IF('Bundle Tag Info'!#REF!<>"",CONCATENATE('Bundle Tag Info'!$A$1," ",CHAR(10),'Bundle Tag Info'!$A$2," ",'Bundle Tag Info'!$A$3,CHAR(10),'Bundle Tag Info'!#REF!,CHAR(10),'Bundle Tag Info'!#REF!),"") -> #REF!
A7: =IF('Bundle Tag Info'!A$12<>"",CONCATENATE('Bundle Tag Info'!$A$1," ",CHAR(10),'Bundle Tag Info'!$A$2," ",'Bundle Tag Info'!$A$3,CHAR(10),'Bundle Tag Info'!A$6,CHAR(10),'Bundle Tag Info'!A$12),"") | B7: =IF('Bundle Tag Info'!B$12<>"",CONCATENATE('Bundle Tag Info'!$A$1," ",CHAR(10),'Bundle Tag Info'!$A$2," ",'Bundle Tag Info'!$A$3,CHAR(10),'Bundle Tag Info'!B$6,CHAR(10),'Bundle Tag Info'!B$12),"") -> WOODSIDE GOODWYNN #1 J1848 Rev. B.2M1 SCS SH0418 | C7: =IF('Bundle Tag Info'!C$12<>"",CONCATENATE('Bundle Tag Info'!$A$1," ",CHAR(10),'Bundle Tag Info'!$A$2," ",'Bundle Tag Info'!$A$3,CHAR(10),'Bundle Tag Info'!C$6,CHAR(10),'Bundle Tag Info'!C$12),"") -> WOODSIDE GOODWYNN #1 J1848 Rev. B.2M1 L/S PNL KA-BACK | D7: =IF('Bundle Tag Info'!D$12<>"",CONCATENATE('Bundle Tag Info'!$A$1," ",CHAR(10),'Bundle Tag Info'!$A$2," ",'Bundle Tag Info'!$A$3,CHAR(10),'Bundle Tag Info'!D$6,CHAR(10),'Bundle Tag Info'!D$12),"") -> WOODSIDE GOODWYNN #1 J1848 Rev. B.2M1 BACK PNL QS | E7: =IF('Bundle Tag Info'!E$12<>"",CONCATENATE('Bundle Tag Info'!$A$1," ",CHAR(10),'Bundle Tag Info'!$A$2," ",'Bundle Tag Info'!$A$3,CHAR(10),'Bundle Tag Info'!E$6,CHAR(10),'Bundle Tag Info'!E$12),"") -> WOODSIDE GOODWYNN #1 J1848 Rev. B.2M1 R/S PNL FU | F7: =IF('Bundle Tag Info'!#REF!<>"",CONCATENATE('Bundle Tag Info'!$A$1," ",CHAR(10),'Bundle Tag Info'!$A$2," ",'Bundle Tag Info'!$A$3,CHAR(10),'Bundle Tag Info'!#REF!,CHAR(10),'Bundle Tag Info'!#REF!),"") -> #REF! | G7: =IF('Bundle Tag Info'!#REF!<>"",CONCATENATE('Bundle Tag Info'!$A$1," ",CHAR(10),'Bundle Tag Info'!$A$2," ",'Bundle Tag Info'!$A$3,CHAR(10),'Bundle Tag Info'!#REF!,CHAR(10),'Bundle Tag Info'!#REF!),"") -> #REF! | H7: =IF('Bundle Tag Info'!#REF!<>"",CONCATENATE('Bundle Tag Info'!$A$1," ",CHAR(10),'Bundle Tag Info'!$A$2," ",'Bundle Tag Info'!$A$3,CHAR(10),'Bundle Tag Info'!#REF!,CHAR(10),'Bundle Tag Info'!#REF!),"") -> #REF! | I7: =IF('Bundle Tag Info'!#REF!<>"",CONCATENATE('Bundle Tag Info'!$A$1," ",CHAR(10),'Bundle Tag Info'!$A$2," ",'Bundle Tag Info'!$A$3,CHAR(10),'Bundle Tag Info'!#REF!,CHAR(10),'Bundle Tag Info'!#REF!),"") -> #REF! | J7: =IF('Bundle Tag Info'!#REF!<>"",CONCATENATE('Bundle Tag Info'!$A$1," ",CHAR(10),'Bundle Tag Info'!$A$2," ",'Bundle Tag Info'!$A$3,CHAR(10),'Bundle Tag Info'!#REF!,CHAR(10),'Bundle Tag Info'!#REF!),"") -> #REF! | K7: =IF('Bundle Tag Info'!#REF!<>"",CONCATENATE('Bundle Tag Info'!$A$1," ",CHAR(10),'Bundle Tag Info'!$A$2," ",'Bundle Tag Info'!$A$3,CHAR(10),'Bundle Tag Info'!#REF!,CHAR(10),'Bundle Tag Info'!#REF!),"") -> #REF! | L7: =IF('Bundle Tag Info'!#REF!<>"",CONCATENATE('Bundle Tag Info'!$A$1," ",CHAR(10),'Bundle Tag Info'!$A$2," ",'Bundle Tag Info'!$A$3,CHAR(10),'Bundle Tag Info'!#REF!,CHAR(10),'Bundle Tag Info'!#REF!),"") -> #REF! | M7: =IF('Bundle Tag Info'!#REF!<>"",CONCATENATE('Bundle Tag Info'!$A$1," ",CHAR(10),'Bundle Tag Info'!$A$2," ",'Bundle Tag Info'!$A$3,CHAR(10),'Bundle Tag Info'!#REF!,CHAR(10),'Bundle Tag Info'!#REF!),"") -> #REF! | ... AD7: =IF('Bundle Tag Info'!#REF!<>"",CONCATENATE('Bundle Tag Info'!$A$1," ",CHAR(10),'Bundle Tag Info'!$A$2," ",'Bundle Tag Info'!$A$3,CHAR(10),'Bundle Tag Info'!#REF!,CHAR(10),'Bundle Tag Info'!#REF!),"") -> #REF!
A8: =IF('Bundle Tag Info'!A$13<>"",CONCATENATE('Bundle Tag Info'!$A$1," ",CHAR(10),'Bundle Tag Info'!$A$2," ",'Bundle Tag Info'!$A$3,CHAR(10),'Bundle Tag Info'!A$6,CHAR(10),'Bundle Tag Info'!A$13),"") | B8: =IF('Bundle Tag Info'!B$13<>"",CONCATENATE('Bundle Tag Info'!$A$1," ",CHAR(10),'Bundle Tag Info'!$A$2," ",'Bundle Tag Info'!$A$3,CHAR(10),'Bundle Tag Info'!B$6,CHAR(10),'Bundle Tag Info'!B$13),"") -> WOODSIDE GOODWYNN #1 J1848 Rev. B.2M1 SCS AU/AF | C8: =IF('Bundle Tag Info'!C$13<>"",CONCATENATE('Bundle Tag Info'!$A$1," ",CHAR(10),'Bundle Tag Info'!$A$2," ",'Bundle Tag Info'!$A$3,CHAR(10),'Bundle Tag Info'!C$6,CHAR(10),'Bundle Tag Info'!C$13),"") -> WOODSIDE GOODWYNN #1 J1848 Rev. B.2M1 L/S PNL XT-BACK | D8: =IF('Bundle Tag Info'!D$13<>"",CONCATENATE('Bundle Tag Info'!$A$1," ",CHAR(10),'Bundle Tag Info'!$A$2," ",'Bundle Tag Info'!$A$3,CHAR(10),'Bundle Tag Info'!D$6,CHAR(10),'Bundle Tag Info'!D$13),"") -> WOODSIDE GOODWYNN #1 J1848 Rev. B.2M1 BACK PNL XT-R/S | E8: =IF('Bundle Tag Info'!E$13<>"",CONCATENATE('Bundle Tag Info'!$A$1," ",CHAR(10),'Bundle Tag Info'!$A$2," ",'Bundle Tag Info'!$A$3,CHAR(10),'Bundle Tag Info'!E$6,CHAR(10),'Bundle Tag Info'!E$13),"") | F8: =IF('Bundle Tag Info'!#REF!<>"",CONCATENATE('Bundle Tag Info'!$A$1," ",CHAR(10),'Bundle Tag Info'!$A$2," ",'Bundle Tag Info'!$A$3,CHAR(10),'Bundle Tag Info'!#REF!,CHAR(10),'Bundle Tag Info'!#REF!),"") -> #REF! | G8: =IF('Bundle Tag Info'!#REF!<>"",CONCATENATE('Bundle Tag Info'!$A$1," ",CHAR(10),'Bundle Tag Info'!$A$2," ",'Bundle Tag Info'!$A$3,CHAR(10),'Bundle Tag Info'!#REF!,CHAR(10),'Bundle Tag Info'!#REF!),"") -> #REF! | H8: =IF('Bundle Tag Info'!#REF!<>"",CONCATENATE('Bundle Tag Info'!$A$1," ",CHAR(10),'Bundle Tag Info'!$A$2," ",'Bundle Tag Info'!$A$3,CHAR(10),'Bundle Tag Info'!#REF!,CHAR(10),'Bundle Tag Info'!#REF!),"") -> #REF! | I8: =IF('Bundle Tag Info'!#REF!<>"",CONCATENATE('Bundle Tag Info'!$A$1," ",CHAR(10),'Bundle Tag Info'!$A$2," ",'Bundle Tag Info'!$A$3,CHAR(10),'Bundle Tag Info'!#REF!,CHAR(10),'Bundle Tag Info'!#REF!),"") -> #REF! | J8: =IF('Bundle Tag Info'!#REF!<>"",CONCATENATE('Bundle Tag Info'!$A$1," ",CHAR(10),'Bundle Tag Info'!$A$2," ",'Bundle Tag Info'!$A$3,CHAR(10),'Bundle Tag Info'!#REF!,CHAR(10),'Bundle Tag Info'!#REF!),"") -> #REF! | K8: =IF('Bundle Tag Info'!#REF!<>"",CONCATENATE('Bundle Tag Info'!$A$1," ",CHAR(10),'Bundle Tag Info'!$A$2," ",'Bundle Tag Info'!$A$3,CHAR(10),'Bundle Tag Info'!#REF!,CHAR(10),'Bundle Tag Info'!#REF!),"") -> #REF! | L8: =IF('Bundle Tag Info'!#REF!<>"",CONCATENATE('Bundle Tag Info'!$A$1," ",CHAR(10),'Bundle Tag Info'!$A$2," ",'Bundle Tag Info'!$A$3,CHAR(10),'Bundle Tag Info'!#REF!,CHAR(10),'Bundle Tag Info'!#REF!),"") -> #REF! | M8: =IF('Bundle Tag Info'!#REF!<>"",CONCATENATE('Bundle Tag Info'!$A$1," ",CHAR(10),'Bundle Tag Info'!$A$2," ",'Bundle Tag Info'!$A$3,CHAR(10),'Bundle Tag Info'!#REF!,CHAR(10),'Bundle Tag Info'!#REF!),"") -> #REF! | ... AD8: =IF('Bundle Tag Info'!#REF!<>"",CONCATENATE('Bundle Tag Info'!$A$1," ",CHAR(10),'Bundle Tag Info'!$A$2," ",'Bundle Tag Info'!$A$3,CHAR(10),'Bundle Tag Info'!#REF!,CHAR(10),'Bundle Tag Info'!#REF!),"") -> #REF!
A9: =IF('Bundle Tag Info'!A$14<>"",CONCATENATE('Bundle Tag Info'!$A$1," ",CHAR(10),'Bundle Tag Info'!$A$2," ",'Bundle Tag Info'!$A$3,CHAR(10),'Bundle Tag Info'!A$6,CHAR(10),'Bundle Tag Info'!A$14),"") | B9: =IF('Bundle Tag Info'!B$14<>"",CONCATENATE('Bundle Tag Info'!$A$1," ",CHAR(10),'Bundle Tag Info'!$A$2," ",'Bundle Tag Info'!$A$3,CHAR(10),'Bundle Tag Info'!B$6,CHAR(10),'Bundle Tag Info'!B$14),"") -> WOODSIDE GOODWYNN #1 J1848 Rev. B.2M1 SCS AU/AF-BACK | C9: =IF('Bundle Tag Info'!C$14<>"",CONCATENATE('Bundle Tag Info'!$A$1," ",CHAR(10),'Bundle Tag Info'!$A$2," ",'Bundle Tag Info'!$A$3,CHAR(10),'Bundle Tag Info'!C$6,CHAR(10),'Bundle Tag Info'!C$14),"") | D9: =IF('Bundle Tag Info'!D$14<>"",CONCATENATE('Bundle Tag Info'!$A$1," ",CHAR(10),'Bundle Tag Info'!$A$2," ",'Bundle Tag Info'!$A$3,CHAR(10),'Bundle Tag Info'!D$6,CHAR(10),'Bundle Tag Info'!D$14),"") | E9: =IF('Bundle Tag Info'!E$14<>"",CONCATENATE('Bundle Tag Info'!$A$1," ",CHAR(10),'Bundle Tag Info'!$A$2," ",'Bundle Tag Info'!$A$3,CHAR(10),'Bundle Tag Info'!E$6,CHAR(10),'Bundle Tag Info'!E$14),"") | F9: =IF('Bundle Tag Info'!#REF!<>"",CONCATENATE('Bundle Tag Info'!$A$1," ",CHAR(10),'Bundle Tag Info'!$A$2," ",'Bundle Tag Info'!$A$3,CHAR(10),'Bundle Tag Info'!#REF!,CHAR(10),'Bundle Tag Info'!#REF!),"") -> #REF! | G9: =IF('Bundle Tag Info'!#REF!<>"",CONCATENATE('Bundle Tag Info'!$A$1," ",CHAR(10),'Bundle Tag Info'!$A$2," ",'Bundle Tag Info'!$A$3,CHAR(10),'Bundle Tag Info'!#REF!,CHAR(10),'Bundle Tag Info'!#REF!),"") -> #REF! | H9: =IF('Bundle Tag Info'!#REF!<>"",CONCATENATE('Bundle Tag Info'!$A$1," ",CHAR(10),'Bundle Tag Info'!$A$2," ",'Bundle Tag Info'!$A$3,CHAR(10),'Bundle Tag Info'!#REF!,CHAR(10),'Bundle Tag Info'!#REF!),"") -> #REF! | I9: =IF('Bundle Tag Info'!#REF!<>"",CONCATENATE('Bundle Tag Info'!$A$1," ",CHAR(10),'Bundle Tag Info'!$A$2," ",'Bundle Tag Info'!$A$3,CHAR(10),'Bundle Tag Info'!#REF!,CHAR(10),'Bundle Tag Info'!#REF!),"") -> #REF! | J9: =IF('Bundle Tag Info'!#REF!<>"",CONCATENATE('Bundle Tag Info'!$A$1," ",CHAR(10),'Bundle Tag Info'!$A$2," ",'Bundle Tag Info'!$A$3,CHAR(10),'Bundle Tag Info'!#REF!,CHAR(10),'Bundle Tag Info'!#REF!),"") -> #REF! | K9: =IF('Bundle Tag Info'!#REF!<>"",CONCATENATE('Bundle Tag Info'!$A$1," ",CHAR(10),'Bundle Tag Info'!$A$2," ",'Bundle Tag Info'!$A$3,CHAR(10),'Bundle Tag Info'!#REF!,CHAR(10),'Bundle Tag Info'!#REF!),"") -> #REF! | L9: =IF('Bundle Tag Info'!#REF!<>"",CONCATENATE('Bundle Tag Info'!$A$1," ",CHAR(10),'Bundle Tag Info'!$A$2," ",'Bundle Tag Info'!$A$3,CHAR(10),'Bundle Tag Info'!#REF!,CHAR(10),'Bundle Tag Info'!#REF!),"") -> #REF! | M9: =IF('Bundle Tag Info'!#REF!<>"",CONCATENATE('Bundle Tag Info'!$A$1," ",CHAR(10),'Bundle Tag Info'!$A$2," ",'Bundle Tag Info'!$A$3,CHAR(10),'Bundle Tag Info'!#REF!,CHAR(10),'Bundle Tag Info'!#REF!),"") -> #REF! | ... AD9: =IF('Bundle Tag Info'!#REF!<>"",CONCATENATE('Bundle Tag Info'!$A$1," ",CHAR(10),'Bundle Tag Info'!$A$2," ",'Bundle Tag Info'!$A$3,CHAR(10),'Bundle Tag Info'!#REF!,CHAR(10),'Bundle Tag Info'!#REF!),"") -> #REF!
A10: =IF('Bundle Tag Info'!A$15<>"",CONCATENATE('Bundle Tag Info'!$A$1," ",CHAR(10),'Bundle Tag Info'!$A$2," ",'Bundle Tag Info'!$A$3,CHAR(10),'Bundle Tag Info'!A$6,CHAR(10),'Bundle Tag Info'!A$15),"") | B10: =IF('Bundle Tag Info'!B$15<>"",CONCATENATE('Bundle Tag Info'!$A$1," ",CHAR(10),'Bundle Tag Info'!$A$2," ",'Bundle Tag Info'!$A$3,CHAR(10),'Bundle Tag Info'!B$6,CHAR(10),'Bundle Tag Info'!B$15),"") -> WOODSIDE GOODWYNN #1 J1848 Rev. B.2M1 SCS FU/XT-BACK | C10: =IF('Bundle Tag Info'!C$15<>"",CONCATENATE('Bundle Tag Info'!$A$1," ",CHAR(10),'Bundle Tag Info'!$A$2," ",'Bundle Tag Info'!$A$3,CHAR(10),'Bundle Tag Info'!C$6,CHAR(10),'Bundle Tag Info'!C$15),"") | D10: =IF('Bundle Tag Info'!D$15<>"",CONCATENATE('Bundle Tag Info'!$A$1," ",CHAR(10),'Bundle Tag Info'!$A$2," ",'Bundle Tag Info'!$A$3,CHAR(10),'Bundle Tag Info'!D$6,CHAR(10),'Bundle Tag Info'!D$15),"") | E10: =IF('Bundle Tag Info'!E$15<>"",CONCATENATE('Bundle Tag Info'!$A$1," ",CHAR(10),'Bundle Tag Info'!$A$2," ",'Bundle Tag Info'!$A$3,CHAR(10),'Bundle Tag Info'!E$6,CHAR(10),'Bundle Tag Info'!E$15),"") | F10: =IF('Bundle Tag Info'!#REF!<>"",CONCATENATE('Bundle Tag Info'!$A$1," ",CHAR(10),'Bundle Tag Info'!$A$2," ",'Bundle Tag Info'!$A$3,CHAR(10),'Bundle Tag Info'!#REF!,CHAR(10),'Bundle Tag Info'!#REF!),"") -> #REF! | G10: =IF('Bundle Tag Info'!#REF!<>"",CONCATENATE('Bundle Tag Info'!$A$1," ",CHAR(10),'Bundle Tag Info'!$A$2," ",'Bundle Tag Info'!$A$3,CHAR(10),'Bundle Tag Info'!#REF!,CHAR(10),'Bundle Tag Info'!#REF!),"") -> #REF! | H10: =IF('Bundle Tag Info'!#REF!<>"",CONCATENATE('Bundle Tag Info'!$A$1," ",CHAR(10),'Bundle Tag Info'!$A$2," ",'Bundle Tag Info'!$A$3,CHAR(10),'Bundle Tag Info'!#REF!,CHAR(10),'Bundle Tag Info'!#REF!),"") -> #REF! | I10: =IF('Bundle Tag Info'!#REF!<>"",CONCATENATE('Bundle Tag Info'!$A$1," ",CHAR(10),'Bundle Tag Info'!$A$2," ",'Bundle Tag Info'!$A$3,CHAR(10),'Bundle Tag Info'!#REF!,CHAR(10),'Bundle Tag Info'!#REF!),"") -> #REF! | J10: =IF('Bundle Tag Info'!#REF!<>"",CONCATENATE('Bundle Tag Info'!$A$1," ",CHAR(10),'Bundle Tag Info'!$A$2," ",'Bundle Tag Info'!$A$3,CHAR(10),'Bundle Tag Info'!#REF!,CHAR(10),'Bundle Tag Info'!#REF!),"") -> #REF! | K10: =IF('Bundle Tag Info'!#REF!<>"",CONCATENATE('Bundle Tag Info'!$A$1," ",CHAR(10),'Bundle Tag Info'!$A$2," ",'Bundle Tag Info'!$A$3,CHAR(10),'Bundle Tag Info'!#REF!,CHAR(10),'Bundle Tag Info'!#REF!),"") -> #REF! | L10: =IF('Bundle Tag Info'!#REF!<>"",CONCATENATE('Bundle Tag Info'!$A$1," ",CHAR(10),'Bundle Tag Info'!$A$2," ",'Bundle Tag Info'!$A$3,CHAR(10),'Bundle Tag Info'!#REF!,CHAR(10),'Bundle Tag Info'!#REF!),"") -> #REF! | M10: =IF('Bundle Tag Info'!#REF!<>"",CONCATENATE('Bundle Tag Info'!$A$1," ",CHAR(10),'Bundle Tag Info'!$A$2," ",'Bundle Tag Info'!$A$3,CHAR(10),'Bundle Tag Info'!#REF!,CHAR(10),'Bundle Tag Info'!#REF!),"") -> #REF! | ... AD10: =IF('Bundle Tag Info'!#REF!<>"",CONCATENATE('Bundle Tag Info'!$A$1," ",CHAR(10),'Bundle Tag Info'!$A$2," ",'Bundle Tag Info'!$A$3,CHAR(10),'Bundle Tag Info'!#REF!,CHAR(10),'Bundle Tag Info'!#REF!),"") -> #REF!
A11: =IF('Bundle Tag Info'!A$16<>"",CONCATENATE('Bundle Tag Info'!$A$1," ",CHAR(10),'Bundle Tag Info'!$A$2," ",'Bundle Tag Info'!$A$3,CHAR(10),'Bundle Tag Info'!A$6,CHAR(10),'Bundle Tag Info'!A$16),"") | B11: =IF('Bundle Tag Info'!B$16<>"",CONCATENATE('Bundle Tag Info'!$A$1," ",CHAR(10),'Bundle Tag Info'!$A$2," ",'Bundle Tag Info'!$A$3,CHAR(10),'Bundle Tag Info'!B$6,CHAR(10),'Bundle Tag Info'!B$16),"") | C11: =IF('Bundle Tag Info'!C$16<>"",CONCATENATE('Bundle Tag Info'!$A$1," ",CHAR(10),'Bundle Tag Info'!$A$2," ",'Bundle Tag Info'!$A$3,CHAR(10),'Bundle Tag Info'!C$6,CHAR(10),'Bundle Tag Info'!C$16),"") | D11: =IF('Bundle Tag Info'!D$16<>"",CONCATENATE('Bundle Tag Info'!$A$1," ",CHAR(10),'Bundle Tag Info'!$A$2," ",'Bundle Tag Info'!$A$3,CHAR(10),'Bundle Tag Info'!D$6,CHAR(10),'Bundle Tag Info'!D$16),"") | E11: =IF('Bundle Tag Info'!E$16<>"",CONCATENATE('Bundle Tag Info'!$A$1," ",CHAR(10),'Bundle Tag Info'!$A$2," ",'Bundle Tag Info'!$A$3,CHAR(10),'Bundle Tag Info'!E$6,CHAR(10),'Bundle Tag Info'!E$16),"") | F11: =IF('Bundle Tag Info'!#REF!<>"",CONCATENATE('Bundle Tag Info'!$A$1," ",CHAR(10),'Bundle Tag Info'!$A$2," ",'Bundle Tag Info'!$A$3,CHAR(10),'Bundle Tag Info'!#REF!,CHAR(10),'Bundle Tag Info'!#REF!),"") -> #REF! | G11: =IF('Bundle Tag Info'!#REF!<>"",CONCATENATE('Bundle Tag Info'!$A$1," ",CHAR(10),'Bundle Tag Info'!$A$2," ",'Bundle Tag Info'!$A$3,CHAR(10),'Bundle Tag Info'!#REF!,CHAR(10),'Bundle Tag Info'!#REF!),"") -> #REF! | H11: =IF('Bundle Tag Info'!#REF!<>"",CONCATENATE('Bundle Tag Info'!$A$1," ",CHAR(10),'Bundle Tag Info'!$A$2," ",'Bundle Tag Info'!$A$3,CHAR(10),'Bundle Tag Info'!#REF!,CHAR(10),'Bundle Tag Info'!#REF!),"") -> #REF! | I11: =IF('Bundle Tag Info'!#REF!<>"",CONCATENATE('Bundle Tag Info'!$A$1," ",CHAR(10),'Bundle Tag Info'!$A$2," ",'Bundle Tag Info'!$A$3,CHAR(10),'Bundle Tag Info'!#REF!,CHAR(10),'Bundle Tag Info'!#REF!),"") -> #REF! | J11: =IF('Bundle Tag Info'!#REF!<>"",CONCATENATE('Bundle Tag Info'!$A$1," ",CHAR(10),'Bundle Tag Info'!$A$2," ",'Bundle Tag Info'!$A$3,CHAR(10),'Bundle Tag Info'!#REF!,CHAR(10),'Bundle Tag Info'!#REF!),"") -> #REF! | K11: =IF('Bundle Tag Info'!#REF!<>"",CONCATENATE('Bundle Tag Info'!$A$1," ",CHAR(10),'Bundle Tag Info'!$A$2," ",'Bundle Tag Info'!$A$3,CHAR(10),'Bundle Tag Info'!#REF!,CHAR(10),'Bundle Tag Info'!#REF!),"") -> #REF! | L11: =IF('Bundle Tag Info'!#REF!<>"",CONCATENATE('Bundle Tag Info'!$A$1," ",CHAR(10),'Bundle Tag Info'!$A$2," ",'Bundle Tag Info'!$A$3,CHAR(10),'Bundle Tag Info'!#REF!,CHAR(10),'Bundle Tag Info'!#REF!),"") -> #REF! | M11: =IF('Bundle Tag Info'!#REF!<>"",CONCATENATE('Bundle Tag Info'!$A$1," ",CHAR(10),'Bundle Tag Info'!$A$2," ",'Bundle Tag Info'!$A$3,CHAR(10),'Bundle Tag Info'!#REF!,CHAR(10),'Bundle Tag Info'!#REF!),"") -> #REF! | ... AD11: =IF('Bundle Tag Info'!#REF!<>"",CONCATENATE('Bundle Tag Info'!$A$1," ",CHAR(10),'Bundle Tag Info'!$A$2," ",'Bundle Tag Info'!$A$3,CHAR(10),'Bundle Tag Info'!#REF!,CHAR(10),'Bundle Tag Info'!#REF!),"") -> #REF!
A12: =IF('Bundle Tag Info'!A$17<>"",CONCATENATE('Bundle Tag Info'!$A$1," ",CHAR(10),'Bundle Tag Info'!$A$2," ",'Bundle Tag Info'!$A$3,CHAR(10),'Bundle Tag Info'!A$6,CHAR(10),'Bundle Tag Info'!A$17),"") | B12: =IF('Bundle Tag Info'!B$17<>"",CONCATENATE('Bundle Tag Info'!$A$1," ",CHAR(10),'Bundle Tag Info'!$A$2," ",'Bundle Tag Info'!$A$3,CHAR(10),'Bundle Tag Info'!B$6,CHAR(10),'Bundle Tag Info'!B$17),"") | C12: =IF('Bundle Tag Info'!C$17<>"",CONCATENATE('Bundle Tag Info'!$A$1," ",CHAR(10),'Bundle Tag Info'!$A$2," ",'Bundle Tag Info'!$A$3,CHAR(10),'Bundle Tag Info'!C$6,CHAR(10),'Bundle Tag Info'!C$17),"") | D12: =IF('Bundle Tag Info'!D$17<>"",CONCATENATE('Bundle Tag Info'!$A$1," ",CHAR(10),'Bundle Tag Info'!$A$2," ",'Bundle Tag Info'!$A$3,CHAR(10),'Bundle Tag Info'!D$6,CHAR(10),'Bundle Tag Info'!D$17),"") | E12: =IF('Bundle Tag Info'!E$17<>"",CONCATENATE('Bundle Tag Info'!$A$1," ",CHAR(10),'Bundle Tag Info'!$A$2," ",'Bundle Tag Info'!$A$3,CHAR(10),'Bundle Tag Info'!E$6,CHAR(10),'Bundle Tag Info'!E$17),"") | F12: =IF('Bundle Tag Info'!#REF!<>"",CONCATENATE('Bundle Tag Info'!$A$1," ",CHAR(10),'Bundle Tag Info'!$A$2," ",'Bundle Tag Info'!$A$3,CHAR(10),'Bundle Tag Info'!#REF!,CHAR(10),'Bundle Tag Info'!#REF!),"") -> #REF! | G12: =IF('Bundle Tag Info'!#REF!<>"",CONCATENATE('Bundle Tag Info'!$A$1," ",CHAR(10),'Bundle Tag Info'!$A$2," ",'Bundle Tag Info'!$A$3,CHAR(10),'Bundle Tag Info'!#REF!,CHAR(10),'Bundle Tag Info'!#REF!),"") -> #REF! | H12: =IF('Bundle Tag Info'!#REF!<>"",CONCATENATE('Bundle Tag Info'!$A$1," ",CHAR(10),'Bundle Tag Info'!$A$2," ",'Bundle Tag Info'!$A$3,CHAR(10),'Bundle Tag Info'!#REF!,CHAR(10),'Bundle Tag Info'!#REF!),"") -> #REF! | I12: =IF('Bundle Tag Info'!#REF!<>"",CONCATENATE('Bundle Tag Info'!$A$1," ",CHAR(10),'Bundle Tag Info'!$A$2," ",'Bundle Tag Info'!$A$3,CHAR(10),'Bundle Tag Info'!#REF!,CHAR(10),'Bundle Tag Info'!#REF!),"") -> #REF! | J12: =IF('Bundle Tag Info'!#REF!<>"",CONCATENATE('Bundle Tag Info'!$A$1," ",CHAR(10),'Bundle Tag Info'!$A$2," ",'Bundle Tag Info'!$A$3,CHAR(10),'Bundle Tag Info'!#REF!,CHAR(10),'Bundle Tag Info'!#REF!),"") -> #REF! | K12: =IF('Bundle Tag Info'!#REF!<>"",CONCATENATE('Bundle Tag Info'!$A$1," ",CHAR(10),'Bundle Tag Info'!$A$2," ",'Bundle Tag Info'!$A$3,CHAR(10),'Bundle Tag Info'!#REF!,CHAR(10),'Bundle Tag Info'!#REF!),"") -> #REF! | L12: =IF('Bundle Tag Info'!#REF!<>"",CONCATENATE('Bundle Tag Info'!$A$1," ",CHAR(10),'Bundle Tag Info'!$A$2," ",'Bundle Tag Info'!$A$3,CHAR(10),'Bundle Tag Info'!#REF!,CHAR(10),'Bundle Tag Info'!#REF!),"") -> #REF! | M12: =IF('Bundle Tag Info'!#REF!<>"",CONCATENATE('Bundle Tag Info'!$A$1," ",CHAR(10),'Bundle Tag Info'!$A$2," ",'Bundle Tag Info'!$A$3,CHAR(10),'Bundle Tag Info'!#REF!,CHAR(10),'Bundle Tag Info'!#REF!),"") -> #REF! | ... AD12: =IF('Bundle Tag Info'!#REF!<>"",CONCATENATE('Bundle Tag Info'!$A$1," ",CHAR(10),'Bundle Tag Info'!$A$2," ",'Bundle Tag Info'!$A$3,CHAR(10),'Bundle Tag Info'!#REF!,CHAR(10),'Bundle Tag Info'!#REF!),"") -> #REF!
A13: =IF('Bundle Tag Info'!A$18<>"",CONCATENATE('Bundle Tag Info'!$A$1," ",CHAR(10),'Bundle Tag Info'!$A$2," ",'Bundle Tag Info'!$A$3,CHAR(10),'Bundle Tag Info'!A$6,CHAR(10),'Bundle Tag Info'!A$18),"") | B13: =IF('Bundle Tag Info'!B$18<>"",CONCATENATE('Bundle Tag Info'!$A$1," ",CHAR(10),'Bundle Tag Info'!$A$2," ",'Bundle Tag Info'!$A$3,CHAR(10),'Bundle Tag Info'!B$6,CHAR(10),'Bundle Tag Info'!B$18),"") | C13: =IF('Bundle Tag Info'!C$18<>"",CONCATENATE('Bundle Tag Info'!$A$1," ",CHAR(10),'Bundle Tag Info'!$A$2," ",'Bundle Tag Info'!$A$3,CHAR(10),'Bundle Tag Info'!C$6,CHAR(10),'Bundle Tag Info'!C$18),"") | D13: =IF('Bundle Tag Info'!D$18<>"",CONCATENATE('Bundle Tag Info'!$A$1," ",CHAR(10),'Bundle Tag Info'!$A$2," ",'Bundle Tag Info'!$A$3,CHAR(10),'Bundle Tag Info'!D$6,CHAR(10),'Bundle Tag Info'!D$18),"") | E13: =IF('Bundle Tag Info'!E$18<>"",CONCATENATE('Bundle Tag Info'!$A$1," ",CHAR(10),'Bundle Tag Info'!$A$2," ",'Bundle Tag Info'!$A$3,CHAR(10),'Bundle Tag Info'!E$6,CHAR(10),'Bundle Tag Info'!E$18),"") | F13: =IF('Bundle Tag Info'!#REF!<>"",CONCATENATE('Bundle Tag Info'!$A$1," ",CHAR(10),'Bundle Tag Info'!$A$2," ",'Bundle Tag Info'!$A$3,CHAR(10),'Bundle Tag Info'!#REF!,CHAR(10),'Bundle Tag Info'!#REF!),"") -> #REF! | G13: =IF('Bundle Tag Info'!#REF!<>"",CONCATENATE('Bundle Tag Info'!$A$1," ",CHAR(10),'Bundle Tag Info'!$A$2," ",'Bundle Tag Info'!$A$3,CHAR(10),'Bundle Tag Info'!#REF!,CHAR(10),'Bundle Tag Info'!#REF!),"") -> #REF! | H13: =IF('Bundle Tag Info'!#REF!<>"",CONCATENATE('Bundle Tag Info'!$A$1," ",CHAR(10),'Bundle Tag Info'!$A$2," ",'Bundle Tag Info'!$A$3,CHAR(10),'Bundle Tag Info'!#REF!,CHAR(10),'Bundle Tag Info'!#REF!),"") -> #REF! | I13: =IF('Bundle Tag Info'!#REF!<>"",CONCATENATE('Bundle Tag Info'!$A$1," ",CHAR(10),'Bundle Tag Info'!$A$2," ",'Bundle Tag Info'!$A$3,CHAR(10),'Bundle Tag Info'!#REF!,CHAR(10),'Bundle Tag Info'!#REF!),"") -> #REF! | J13: =IF('Bundle Tag Info'!#REF!<>"",CONCATENATE('Bundle Tag Info'!$A$1," ",CHAR(10),'Bundle Tag Info'!$A$2," ",'Bundle Tag Info'!$A$3,CHAR(10),'Bundle Tag Info'!#REF!,CHAR(10),'Bundle Tag Info'!#REF!),"") -> #REF! | K13: =IF('Bundle Tag Info'!#REF!<>"",CONCATENATE('Bundle Tag Info'!$A$1," ",CHAR(10),'Bundle Tag Info'!$A$2," ",'Bundle Tag Info'!$A$3,CHAR(10),'Bundle Tag Info'!#REF!,CHAR(10),'Bundle Tag Info'!#REF!),"") -> #REF! | L13: =IF('Bundle Tag Info'!#REF!<>"",CONCATENATE('Bundle Tag Info'!$A$1," ",CHAR(10),'Bundle Tag Info'!$A$2," ",'Bundle Tag Info'!$A$3,CHAR(10),'Bundle Tag Info'!#REF!,CHAR(10),'Bundle Tag Info'!#REF!),"") -> #REF! | M13: =IF('Bundle Tag Info'!#REF!<>"",CONCATENATE('Bundle Tag Info'!$A$1," ",CHAR(10),'Bundle Tag Info'!$A$2," ",'Bundle Tag Info'!$A$3,CHAR(10),'Bundle Tag Info'!#REF!,CHAR(10),'Bundle Tag Info'!#REF!),"") -> #REF! | ... AD13: =IF('Bundle Tag Info'!#REF!<>"",CONCATENATE('Bundle Tag Info'!$A$1," ",CHAR(10),'Bundle Tag Info'!$A$2," ",'Bundle Tag Info'!$A$3,CHAR(10),'Bundle Tag Info'!#REF!,CHAR(10),'Bundle Tag Info'!#REF!),"") -> #REF!
A14: =IF('Bundle Tag Info'!A$19<>"",CONCATENATE('Bundle Tag Info'!$A$1," ",CHAR(10),'Bundle Tag Info'!$A$2," ",'Bundle Tag Info'!$A$3,CHAR(10),'Bundle Tag Info'!A$6,CHAR(10),'Bundle Tag Info'!A$19),"") | B14: =IF('Bundle Tag Info'!B$19<>"",CONCATENATE('Bundle Tag Info'!$A$1," ",CHAR(10),'Bundle Tag Info'!$A$2," ",'Bundle Tag Info'!$A$3,CHAR(10),'Bundle Tag Info'!B$6,CHAR(10),'Bundle Tag Info'!B$19),"") | C14: =IF('Bundle Tag Info'!C$19<>"",CONCATENATE('Bundle Tag Info'!$A$1," ",CHAR(10),'Bundle Tag Info'!$A$2," ",'Bundle Tag Info'!$A$3,CHAR(10),'Bundle Tag Info'!C$6,CHAR(10),'Bundle Tag Info'!C$19),"") | D14: =IF('Bundle Tag Info'!D$19<>"",CONCATENATE('Bundle Tag Info'!$A$1," ",CHAR(10),'Bundle Tag Info'!$A$2," ",'Bundle Tag Info'!$A$3,CHAR(10),'Bundle Tag Info'!D$6,CHAR(10),'Bundle Tag Info'!D$19),"") | E14: =IF('Bundle Tag Info'!E$19<>"",CONCATENATE('Bundle Tag Info'!$A$1," ",CHAR(10),'Bundle Tag Info'!$A$2," ",'Bundle Tag Info'!$A$3,CHAR(10),'Bundle Tag Info'!E$6,CHAR(10),'Bundle Tag Info'!E$19),"") | F14: =IF('Bundle Tag Info'!#REF!<>"",CONCATENATE('Bundle Tag Info'!$A$1," ",CHAR(10),'Bundle Tag Info'!$A$2," ",'Bundle Tag Info'!$A$3,CHAR(10),'Bundle Tag Info'!#REF!,CHAR(10),'Bundle Tag Info'!#REF!),"") -> #REF! | G14: =IF('Bundle Tag Info'!#REF!<>"",CONCATENATE('Bundle Tag Info'!$A$1," ",CHAR(10),'Bundle Tag Info'!$A$2," ",'Bundle Tag Info'!$A$3,CHAR(10),'Bundle Tag Info'!#REF!,CHAR(10),'Bundle Tag Info'!#REF!),"") -> #REF! | H14: =IF('Bundle Tag Info'!#REF!<>"",CONCATENATE('Bundle Tag Info'!$A$1," ",CHAR(10),'Bundle Tag Info'!$A$2," ",'Bundle Tag Info'!$A$3,CHAR(10),'Bundle Tag Info'!#REF!,CHAR(10),'Bundle Tag Info'!#REF!),"") -> #REF! | I14: =IF('Bundle Tag Info'!#REF!<>"",CONCATENATE('Bundle Tag Info'!$A$1," ",CHAR(10),'Bundle Tag Info'!$A$2," ",'Bundle Tag Info'!$A$3,CHAR(10),'Bundle Tag Info'!#REF!,CHAR(10),'Bundle Tag Info'!#REF!),"") -> #REF! | J14: =IF('Bundle Tag Info'!#REF!<>"",CONCATENATE('Bundle Tag Info'!$A$1," ",CHAR(10),'Bundle Tag Info'!$A$2," ",'Bundle Tag Info'!$A$3,CHAR(10),'Bundle Tag Info'!#REF!,CHAR(10),'Bundle Tag Info'!#REF!),"") -> #REF! | K14: =IF('Bundle Tag Info'!#REF!<>"",CONCATENATE('Bundle Tag Info'!$A$1," ",CHAR(10),'Bundle Tag Info'!$A$2," ",'Bundle Tag Info'!$A$3,CHAR(10),'Bundle Tag Info'!#REF!,CHAR(10),'Bundle Tag Info'!#REF!),"") -> #REF! | L14: =IF('Bundle Tag Info'!#REF!<>"",CONCATENATE('Bundle Tag Info'!$A$1," ",CHAR(10),'Bundle Tag Info'!$A$2," ",'Bundle Tag Info'!$A$3,CHAR(10),'Bundle Tag Info'!#REF!,CHAR(10),'Bundle Tag Info'!#REF!),"") -> #REF! | M14: =IF('Bundle Tag Info'!#REF!<>"",CONCATENATE('Bundle Tag Info'!$A$1," ",CHAR(10),'Bundle Tag Info'!$A$2," ",'Bundle Tag Info'!$A$3,CHAR(10),'Bundle Tag Info'!#REF!,CHAR(10),'Bundle Tag Info'!#REF!),"") -> #REF! | ... AD14: =IF('Bundle Tag Info'!#REF!<>"",CONCATENATE('Bundle Tag Info'!$A$1," ",CHAR(10),'Bundle Tag Info'!$A$2," ",'Bundle Tag Info'!$A$3,CHAR(10),'Bundle Tag Info'!#REF!,CHAR(10),'Bundle Tag Info'!#REF!),"") -> #REF!
